File: data/115k_1-3_2 (190321).lvm
LabVIEW Measurement
Writer_Version	2
Reader_Version	2
Separator	Tab
Decimal_Separator	.
Multi_Headings	No
X_Columns	One
Time_Pref	Absolute
Operator	user
Description	Load(N)/Stress(MPa)/Distance A(pixel)/Strain A/Distance B(pixel)/Strain B/Poisson's ratio
Date	2019/03/21
Time	12:58:35.3148044300349900275
***End_of_Header***

Notes	X 값은 오직 다음과 같을 때에만 유효함이 보장됩니다. Dev1/ai0
Channels	7
Samples	1	1	1	1	1	1	1
Date	2019/03/21	2019/03/21	2019/03/21	2019/03/21	2019/03/21	2019/03/21	2019/03/21
Time	13:50:12.814971230034731044	13:50:12.814971230034731044	13:50:12.8149709701538085937	13:50:12.8149709701538085937	13:50:12.8149709701538085937	13:50:12.8149709701538085937	13:50:12.8149709701538085937
Y_Unit_Label	Volts	Volts
X_Dimension	Time	Time	Time	Time	Time	Time	Time
X0	0.0000000000000000E+0	0.0000000000000000E+0	0.0000000000000000E+0	0.0000000000000000E+0	0.0000000000000000E+0	0.0000000000000000E+0	0.0000000000000000E+0
Delta_X	0.000000	0.000000	1.000000	1.000000	1.000000	1.000000	1.000000
***End_of_Header***
X_Value	Dev1/ai0	Dev1/ai0 1	Untitled	Untitled 1	Untitled 2	Untitled 3	Untitled 4	Comment
0.000000	-2.332649E-5	-0.233265	-0.002193	996.150696	0.000000	NaN	NaN
1.499086	3.444320E-5	0.344432	-2.294779E-5	996.127808	0.000000	NaN	NaN
2.999172	-6.820864E-6	-0.068209	-6.353855E-5	996.087402	0.000000	NaN	NaN
4.499257	0.000191	1.912466	0.000346	996.494995	0.000000	NaN	NaN
5.999343	0.000439	4.388310	0.000764	996.911987	0.000000	NaN	NaN
7.499429	0.000315	3.150388	0.001104	997.250183	0.000000	NaN	NaN
8.999515	0.000414	4.140726	0.001338	997.484070	0.000000	NaN	NaN
10.499601	0.000323	3.232916	0.001737	997.881165	0.000000	NaN	NaN
11.999686	0.000439	4.388310	0.001996	998.138611	0.000000	NaN	NaN
13.499772	0.000464	4.635895	0.002118	998.260742	0.000000	NaN	NaN
14.999858	0.000488	4.883479	0.002311	998.453003	0.000000	NaN	NaN
16.499944	0.000381	3.810613	0.002517	998.657593	0.000000	NaN	NaN
17.999029	0.000546	5.461176	0.002598	998.739136	0.000000	NaN	NaN
19.499115	0.000728	7.276795	0.003808	999.944519	0.000000	NaN	NaN
20.999201	0.000670	6.699098	0.003979	1000.114868	0.000000	NaN	NaN
22.499287	0.000686	6.864154	0.004120	1000.254822	0.000000	NaN	NaN
23.999373	0.000851	8.514717	0.004294	1000.428223	0.000000	NaN	NaN
25.499459	0.000827	8.267132	0.004491	1000.624390	0.000000	NaN	NaN
26.999544	0.000901	9.009885	0.004786	1000.918274	0.000000	NaN	NaN
28.499630	0.000909	9.092413	0.005028	1001.159241	0.000000	NaN	NaN
29.999716	0.000967	9.670110	0.005221	1001.351929	0.000000	NaN	NaN
31.499802	0.001091	10.908032	0.005437	1001.566650	0.000000	NaN	NaN
32.999887	0.000893	8.927357	0.005737	1001.865295	0.000000	NaN	NaN
34.499973	0.001050	10.495392	0.005959	1002.086975	0.000000	NaN	NaN
35.999059	0.001173	11.733313	0.006197	1002.323608	0.000000	NaN	NaN
37.499145	0.001281	12.806179	0.007497	1003.618713	0.000000	NaN	NaN
38.999231	0.001223	12.228482	0.007821	1003.941772	0.000000	NaN	NaN
40.499317	0.001404	14.044101	0.008150	1004.269531	0.000000	NaN	NaN
41.999402	0.001495	14.951910	0.008546	1004.664062	0.000000	NaN	NaN
43.499488	0.001545	15.447079	0.008837	1004.953552	0.000000	NaN	NaN
44.999574	0.001602	16.024776	0.009250	1005.365173	0.000000	NaN	NaN
46.499660	0.001669	16.685001	0.009669	1005.782104	0.000000	NaN	NaN
47.999746	0.001627	16.272360	0.010010	1006.121826	0.000000	NaN	NaN
49.499831	0.001850	18.500620	0.010448	1006.558472	0.000000	NaN	NaN
50.999917	0.001644	16.437417	0.010857	1006.965759	0.000000	NaN	NaN
52.500003	0.001908	19.078317	0.011302	1007.409119	0.000000	NaN	NaN
53.999089	0.001974	19.738542	0.011768	1007.873840	0.000000	NaN	NaN
55.499174	0.002048	20.481295	0.012156	1008.259888	0.000000	NaN	NaN
56.999260	0.002081	20.811407	0.012523	1008.625610	0.000000	NaN	NaN
58.499346	0.002213	22.131857	0.013821	1009.918030	0.000000	NaN	NaN
59.999432	0.002197	21.966801	0.013061	1009.161438	0.000000	NaN	NaN
61.499518	0.002263	22.627026	0.013531	1009.629822	0.000000	NaN	NaN
62.999603	0.002263	22.627026	0.014039	1010.135864	0.000000	NaN	NaN
64.499689	0.002403	24.030004	0.014574	1010.668823	0.000000	NaN	NaN
65.999775	0.002362	23.617363	0.015038	1011.130981	0.000000	NaN	NaN
67.499861	0.002568	25.680567	0.015585	1011.675781	0.000000	NaN	NaN
68.999947	0.002502	25.020342	0.016061	1012.150146	0.000000	NaN	NaN
70.499032	0.002386	23.864948	0.016626	1012.712891	0.000000	NaN	NaN
71.999118	0.002585	25.845623	0.017136	1013.220337	0.000000	NaN	NaN
73.499204	0.002618	26.175735	0.017660	1013.742310	0.000000	NaN	NaN
74.999290	0.002576	25.763095	0.018146	1014.226807	0.000000	NaN	NaN
76.499376	0.002626	26.258263	0.018666	1014.744507	0.000000	NaN	NaN
77.999461	0.002741	27.413657	0.019230	1015.306213	0.000000	NaN	NaN
79.499547	0.002799	27.991354	0.019822	1015.896912	0.000000	NaN	NaN
80.999633	0.002783	27.826298	0.020439	1016.511414	0.000000	NaN	NaN
82.499719	0.002873	28.734107	0.021017	1017.086670	0.000000	NaN	NaN
83.999805	0.002857	28.569051	0.021601	1017.668518	0.000000	NaN	NaN
85.499890	0.002939	29.394332	0.022247	1018.311890	0.000000	NaN	NaN
86.999976	0.003014	30.137085	0.022861	1018.923218	0.000000	NaN	NaN
88.499062	0.002890	28.899163	0.023508	1019.567810	0.000000	NaN	NaN
89.999148	0.002972	29.724445	0.024197	1020.254028	0.000000	NaN	NaN
91.499234	0.003055	30.549726	0.024757	1020.812256	0.000000	NaN	NaN
92.999319	0.002948	29.476860	0.025450	1021.503113	0.000000	NaN	NaN
94.499405	0.003113	31.127423	0.026180	1022.229431	0.000000	NaN	NaN
95.999491	0.002972	29.724445	0.026743	1022.790466	0.000000	NaN	NaN
97.499577	0.003071	30.714782	0.027474	1023.518738	0.000000	NaN	NaN
98.999662	0.002931	29.311804	0.028089	1024.131836	0.000000	NaN	NaN
100.499748	0.003047	30.467198	0.028832	1024.871582	0.000000	NaN	NaN
101.999834	0.003088	30.879838	0.029650	1025.687012	0.000000	NaN	NaN
103.499920	0.003088	30.879838	0.030369	1026.402588	0.000000	NaN	NaN
105.000006	0.002956	29.559388	0.031005	1027.036133	0.000000	NaN	NaN
106.499091	0.003179	31.787648	0.031737	1027.765381	0.000000	NaN	NaN
107.999177	0.003138	31.375007	0.032480	1028.505493	0.000000	NaN	NaN
109.499263	0.003038	30.384670	0.033100	1029.123291	0.000000	NaN	NaN
110.999349	0.003146	31.457535	0.033851	1029.871826	0.000000	NaN	NaN
112.499435	0.003088	30.879838	0.034618	1030.635132	0.000000	NaN	NaN
113.999520	0.003146	31.457535	0.035393	1031.407104	0.000000	NaN	NaN
115.499606	0.003014	30.137085	0.036182	1032.193359	0.000000	NaN	NaN
116.999692	0.003146	31.457535	0.036862	1032.871338	0.000000	NaN	NaN
118.499778	0.003171	31.705120	0.037552	1033.558594	0.000000	NaN	NaN
119.999864	0.003220	32.200288	0.038329	1034.331665	0.000000	NaN	NaN
121.499949	0.003113	31.127423	0.039080	1035.079834	0.000000	NaN	NaN
122.999035	0.003195	31.952704	0.039941	1035.937988	0.000000	NaN	NaN
124.499121	0.003171	31.705120	0.040651	1036.645508	0.000000	NaN	NaN
125.999207	0.003129	31.292479	0.041400	1037.391235	0.000000	NaN	NaN
127.499293	0.003154	31.540063	0.042253	1038.241211	0.000000	NaN	NaN
128.999378	0.003187	31.870176	0.042902	1038.887695	0.000000	NaN	NaN
130.499464	0.003187	31.870176	0.043752	1039.734009	0.000000	NaN	NaN
131.999550	0.003171	31.705120	0.044508	1040.487793	0.000000	NaN	NaN
133.499636	0.003286	32.860513	0.045300	1041.276367	0.000000	NaN	NaN
134.999722	0.003237	32.365345	0.046122	1042.094971	0.000000	NaN	NaN
136.499807	0.003204	32.035232	0.046804	1042.774902	0.000000	NaN	NaN
137.999893	0.003195	31.952704	0.047618	1043.585205	0.000000	NaN	NaN
139.499979	0.003138	31.375007	0.048375	1044.339233	0.000000	NaN	NaN
140.999065	0.003311	33.108098	0.049212	1045.172974	0.000000	NaN	NaN
142.499151	0.003253	32.530401	0.049893	1045.851807	0.000000	NaN	NaN
143.999236	0.003286	32.860513	0.050707	1046.661987	0.000000	NaN	NaN
145.499322	0.003311	33.108098	0.051515	1047.467529	0.000000	NaN	NaN
146.999408	0.003261	32.612929	0.052289	1048.238037	0.000000	NaN	NaN
148.499494	0.003327	33.273154	0.053030	1048.976685	0.000000	NaN	NaN
149.999580	0.003369	33.685795	0.053787	1049.730225	0.000000	NaN	NaN
151.499665	0.003270	32.695457	0.054505	1050.445679	0.000000	NaN	NaN
152.999751	0.003220	32.200288	0.055249	1051.187256	0.000000	NaN	NaN
154.499837	0.003228	32.282816	0.055946	1051.881348	0.000000	NaN	NaN
155.999923	0.003270	32.695457	0.056764	1052.696289	0.000000	NaN	NaN
157.500009	0.003228	32.282816	0.057575	1053.503662	0.000000	NaN	NaN
158.999094	0.003344	33.438210	0.058299	1054.225708	0.000000	NaN	NaN
160.499180	0.003336	33.355682	0.059022	1054.945923	0.000000	NaN	NaN
161.999266	0.003476	34.758660	0.059765	1055.685791	0.000000	NaN	NaN
163.499352	0.003212	32.117760	0.060588	1056.505371	0.000000	NaN	NaN
164.999437	0.003286	32.860513	0.061292	1057.207153	0.000000	NaN	NaN
166.499523	0.003278	32.777985	0.062059	1057.970947	0.000000	NaN	NaN
167.999609	0.003385	33.850851	0.062769	1058.677856	0.000000	NaN	NaN
169.499695	0.003443	34.428548	0.063545	1059.451416	0.000000	NaN	NaN
170.999781	0.003451	34.511076	0.064358	1060.260864	0.000000	NaN	NaN
172.499867	0.003311	33.108098	0.065064	1060.964111	0.000000	NaN	NaN
173.999952	0.003360	33.603266	0.065856	1061.752930	0.000000	NaN	NaN
175.499038	0.003484	34.841188	0.066658	1062.551758	0.000000	NaN	NaN
176.999124	0.003352	33.520738	0.067390	1063.280884	0.000000	NaN	NaN
178.652218	0.003443	34.428548	0.068161	1064.049316	0.000000	NaN	NaN
179.999295	0.003319	33.190626	0.068895	1064.780029	0.000000	NaN	NaN
181.499381	0.003451	34.511076	0.069701	1065.583374	0.000000	NaN	NaN
182.999467	0.003303	33.025570	0.070395	1066.274414	0.000000	NaN	NaN
184.499553	0.003402	34.015907	0.071232	1067.108887	0.000000	NaN	NaN
185.999639	0.003344	33.438210	0.071947	1067.820801	0.000000	NaN	NaN
187.499724	0.003336	33.355682	0.072725	1068.596191	0.000000	NaN	NaN
188.999810	0.003583	35.831526	0.073434	1069.302246	0.000000	NaN	NaN
190.499896	0.003567	35.666470	0.074201	1070.066406	0.000000	NaN	NaN
191.999982	0.003426	34.263491	0.074854	1070.716797	0.000000	NaN	NaN
193.499068	0.003426	34.263491	0.075563	1071.423218	0.000000	NaN	NaN
194.999153	0.003501	35.006245	0.076364	1072.220825	0.000000	NaN	NaN
196.499239	0.003459	34.593604	0.077162	1073.015381	0.000000	NaN	NaN
197.999325	0.003575	35.748998	0.077907	1073.757690	0.000000	NaN	NaN
199.499411	0.003377	33.768323	0.078705	1074.552612	0.000000	NaN	NaN
200.999497	0.003435	34.346020	0.079428	1075.273071	0.000000	NaN	NaN
202.499582	0.003517	35.171301	0.080167	1076.009155	0.000000	NaN	NaN
203.999668	0.003459	34.593604	0.080915	1076.754395	0.000000	NaN	NaN
205.499754	0.003550	35.501413	0.081619	1077.455200	0.000000	NaN	NaN
206.999840	0.003558	35.583941	0.082441	1078.274536	0.000000	NaN	NaN
208.499926	0.003525	35.253829	0.083135	1078.965942	0.000000	NaN	NaN
210.000011	0.003459	34.593604	0.083962	1079.789795	0.000000	NaN	NaN
211.499097	0.003509	35.088773	0.084561	1080.386353	0.000000	NaN	NaN
212.999183	0.003418	34.180963	0.085355	1081.177002	0.000000	NaN	NaN
214.499269	0.003426	34.263491	0.086071	1081.890625	0.000000	NaN	NaN
215.999355	0.003517	35.171301	0.086783	1082.599976	0.000000	NaN	NaN
217.499440	0.003525	35.253829	0.087607	1083.420898	0.000000	NaN	NaN
218.999526	0.003591	35.914054	0.088287	1084.098145	0.000000	NaN	NaN
220.499612	0.003600	35.996582	0.089101	1084.908936	0.000000	NaN	NaN
221.999698	0.003418	34.180963	0.089893	1085.697632	0.000000	NaN	NaN
223.499784	0.003484	34.841188	0.090496	1086.298340	0.000000	NaN	NaN
224.999869	0.003484	34.841188	0.091254	1087.053589	0.000000	NaN	NaN
226.499955	0.003699	36.986920	0.091942	1087.738403	0.000000	NaN	NaN
227.999041	0.003633	36.326695	0.092682	1088.475830	0.000000	NaN	NaN
229.499127	0.003501	35.006245	0.093534	1089.324585	0.000000	NaN	NaN
230.999212	0.003575	35.748998	0.094204	1089.992432	0.000000	NaN	NaN
232.499298	0.003608	36.079110	0.094971	1090.755737	0.000000	NaN	NaN
233.999384	0.003558	35.583941	0.095794	1091.575928	0.000000	NaN	NaN
235.499470	0.003633	36.326695	0.096500	1092.278809	0.000000	NaN	NaN
236.999556	0.003608	36.079110	0.097208	1092.984619	0.000000	NaN	NaN
238.499641	0.003509	35.088773	0.097945	1093.719116	0.000000	NaN	NaN
239.999727	0.003657	36.574279	0.098743	1094.513550	0.000000	NaN	NaN
241.499813	0.003583	35.831526	0.099492	1095.259766	0.000000	NaN	NaN
242.999899	0.003600	35.996582	0.100263	1096.027222	0.000000	NaN	NaN
244.499985	0.003550	35.501413	0.100915	1096.677124	0.000000	NaN	NaN
245.999070	0.003723	37.234504	0.101736	1097.494995	0.000000	NaN	NaN
247.499156	0.003699	36.986920	0.102497	1098.253662	0.000000	NaN	NaN
248.999242	0.003707	37.069448	0.103241	1098.994751	0.000000	NaN	NaN
250.499328	0.003682	36.821863	0.104017	1099.767700	0.000000	NaN	NaN
251.999414	0.003682	36.821863	0.104666	1100.413574	0.000000	NaN	NaN
253.499499	0.003600	35.996582	0.105378	1101.122803	0.000000	NaN	NaN
254.999585	0.003707	37.069448	0.106137	1101.878784	0.000000	NaN	NaN
256.499671	0.003641	36.409223	0.106875	1102.614258	0.000000	NaN	NaN
257.999757	0.003690	36.904391	0.107607	1103.343750	0.000000	NaN	NaN
259.499843	0.003666	36.656807	0.108375	1104.108398	0.000000	NaN	NaN
260.999928	0.003756	37.564616	0.109079	1104.810303	0.000000	NaN	NaN
262.500014	0.003649	36.491751	0.109681	1105.409546	0.000000	NaN	NaN
263.999100	0.003773	37.729673	0.110376	1106.101929	0.000000	NaN	NaN
265.499186	0.003690	36.904391	0.111015	1106.738647	0.000000	NaN	NaN
266.999272	0.003699	36.986920	0.111900	1107.619629	0.000000	NaN	NaN
268.499357	0.003649	36.491751	0.112572	1108.289307	0.000000	NaN	NaN
269.999443	0.003839	38.389898	0.113174	1108.889404	0.000000	NaN	NaN
271.499529	0.003600	35.996582	0.114014	1109.725830	0.000000	NaN	NaN
272.999615	0.003889	38.885066	0.114768	1110.477173	0.000000	NaN	NaN
274.499701	0.003872	38.720010	0.115518	1111.223877	0.000000	NaN	NaN
275.999786	0.003814	38.142313	0.116122	1111.825195	0.000000	NaN	NaN
277.499872	0.003922	39.215179	0.116877	1112.577759	0.000000	NaN	NaN
278.999958	0.003822	38.224841	0.117590	1113.287842	0.000000	NaN	NaN
280.499044	0.003756	37.564616	0.118279	1113.974854	0.000000	NaN	NaN
281.999129	0.003847	38.472426	0.119022	1114.714233	0.000000	NaN	NaN
283.499215	0.003789	37.894729	0.119691	1115.380737	0.000000	NaN	NaN
284.999301	0.003773	37.729673	0.120539	1116.226074	0.000000	NaN	NaN
286.499387	0.003831	38.307369	0.121197	1116.880737	0.000000	NaN	NaN
287.999473	0.003806	38.059785	0.121908	1117.589355	0.000000	NaN	NaN
289.499559	0.003930	39.297707	0.122674	1118.352661	0.000000	NaN	NaN
290.999644	0.003889	38.885066	0.123399	1119.074219	0.000000	NaN	NaN
292.499730	0.003649	36.491751	0.124151	1119.823730	0.000000	NaN	NaN
293.999816	0.003905	39.050123	0.124838	1120.508423	0.000000	NaN	NaN
295.499902	0.003781	37.812201	0.125450	1121.118164	0.000000	NaN	NaN
296.999987	0.003839	38.389898	0.126055	1121.720703	0.000000	NaN	NaN
298.499073	0.003913	39.132651	0.126829	1122.491211	0.000000	NaN	NaN
299.999159	0.003773	37.729673	0.127638	1123.297729	0.000000	NaN	NaN
301.499245	0.003905	39.050123	0.128095	1123.752808	0.000000	NaN	NaN
302.999331	0.003666	36.656807	0.129031	1124.684692	0.000000	NaN	NaN
304.499416	0.003839	38.389898	0.129499	1125.151489	0.000000	NaN	NaN
305.999502	0.003814	38.142313	0.130758	1126.404907	0.000000	NaN	NaN
307.499588	0.003938	39.380235	0.131130	1126.776001	0.000000	NaN	NaN
308.999674	0.003789	37.894729	0.131637	1127.281250	0.000000	NaN	NaN
310.499760	0.003707	37.069448	0.132326	1127.967407	0.000000	NaN	NaN
311.999845	0.003707	37.069448	0.132953	1128.591797	0.000000	NaN	NaN
313.499931	0.003963	39.627819	0.133698	1129.333984	0.000000	NaN	NaN
315.000017	0.004021	40.205516	0.134459	1130.091797	0.000000	NaN	NaN
316.499103	0.003889	38.885066	0.135079	1130.709229	0.000000	NaN	NaN
317.999189	0.003715	37.151976	0.135746	1131.373657	0.000000	NaN	NaN
319.499274	0.004012	40.122988	0.136522	1132.146851	0.000000	NaN	NaN
320.999360	0.003897	38.967594	0.137151	1132.773437	0.000000	NaN	NaN
322.499446	0.003831	38.307369	0.137798	1133.417847	0.000000	NaN	NaN
323.999532	0.003905	39.050123	0.138545	1134.161987	0.000000	NaN	NaN
325.499618	0.003822	38.224841	0.139251	1134.866089	0.000000	NaN	NaN
326.999703	0.004045	40.453101	0.140008	1135.619507	0.000000	NaN	NaN
328.499789	0.003930	39.297707	0.140597	1136.206055	0.000000	NaN	NaN
329.999875	0.004078	40.783213	0.141348	1136.954102	0.000000	NaN	NaN
331.499961	0.003905	39.050123	0.142028	1137.632202	0.000000	NaN	NaN
332.999047	0.004062	40.618157	0.142782	1138.383179	0.000000	NaN	NaN
334.499132	0.003955	39.545291	0.143413	1139.011597	0.000000	NaN	NaN
335.999218	0.003946	39.462763	0.144119	1139.714600	0.000000	NaN	NaN
337.499304	0.003955	39.545291	0.144765	1140.358032	0.000000	NaN	NaN
338.999390	0.004012	40.122988	0.145458	1141.048706	0.000000	NaN	NaN
340.499476	0.003905	39.050123	0.146076	1141.664185	0.000000	NaN	NaN
341.999561	0.003897	38.967594	0.146803	1142.389160	0.000000	NaN	NaN
343.499647	0.004045	40.453101	0.147480	1143.062622	0.000000	NaN	NaN
344.999733	0.004021	40.205516	0.148121	1143.702026	0.000000	NaN	NaN
346.499819	0.003880	38.802538	0.148747	1144.324829	0.000000	NaN	NaN
347.999905	0.003955	39.545291	0.149398	1144.973633	0.000000	NaN	NaN
349.499990	0.003930	39.297707	0.150108	1145.681396	0.000000	NaN	NaN
350.999076	0.004128	41.278382	0.150813	1146.383545	0.000000	NaN	NaN
352.499162	0.003971	39.710348	0.151461	1147.028809	0.000000	NaN	NaN
353.999248	0.003979	39.792876	0.152094	1147.659668	0.000000	NaN	NaN
355.499333	0.004029	40.288044	0.152743	1148.305786	0.000000	NaN	NaN
356.999419	0.003971	39.710348	0.153459	1149.018555	0.000000	NaN	NaN
358.499505	0.004062	40.618157	0.154038	1149.595337	0.000000	NaN	NaN
359.999591	0.004029	40.288044	0.154758	1150.313110	0.000000	NaN	NaN
361.499677	0.003988	39.875404	0.155461	1151.013184	0.000000	NaN	NaN
362.999762	0.004062	40.618157	0.156114	1151.663330	0.000000	NaN	NaN
364.499848	0.004111	41.113326	0.156724	1152.271362	0.000000	NaN	NaN
365.999934	0.004078	40.783213	0.157448	1152.992798	0.000000	NaN	NaN
367.499020	0.003872	38.720010	0.158063	1153.604980	0.000000	NaN	NaN
368.999106	0.003872	38.720010	0.158764	1154.304077	0.000000	NaN	NaN
370.499191	0.004161	41.608494	0.159418	1154.955566	0.000000	NaN	NaN
371.999277	0.004128	41.278382	0.160049	1155.583618	0.000000	NaN	NaN
373.499363	0.004095	40.948269	0.160718	1156.250122	0.000000	NaN	NaN
374.999449	0.003996	39.957932	0.161371	1156.900757	0.000000	NaN	NaN
376.499535	0.004087	40.865741	0.161993	1157.520020	0.000000	NaN	NaN
377.999620	0.004078	40.783213	0.162730	1158.254639	0.000000	NaN	NaN
379.499706	0.004144	41.443438	0.163348	1158.870239	0.000000	NaN	NaN
380.999792	0.003922	39.215179	0.163999	1159.518433	0.000000	NaN	NaN
382.499878	0.004087	40.865741	0.164634	1160.151001	0.000000	NaN	NaN
383.999964	0.004252	42.516304	0.165356	1160.870483	0.000000	NaN	NaN
385.499049	0.004153	41.525966	0.165979	1161.490601	0.000000	NaN	NaN
386.999135	0.004153	41.525966	0.166637	1162.145874	0.000000	NaN	NaN
388.499221	0.004153	41.525966	0.167253	1162.759766	0.000000	NaN	NaN
389.999307	0.004070	40.700685	0.167971	1163.475098	0.000000	NaN	NaN
391.499393	0.004136	41.360910	0.168602	1164.104004	0.000000	NaN	NaN
392.999478	0.004120	41.195854	0.169297	1164.796387	0.000000	NaN	NaN
394.499564	0.004169	41.691023	0.169980	1165.476440	0.000000	NaN	NaN
395.999650	0.004161	41.608494	0.170619	1166.113403	0.000000	NaN	NaN
397.499736	0.004210	42.103663	0.171212	1166.703491	0.000000	NaN	NaN
398.999821	0.004243	42.433776	0.171883	1167.372314	0.000000	NaN	NaN
400.499907	0.004128	41.278382	0.172500	1167.986694	0.000000	NaN	NaN
401.999993	0.004004	40.040460	0.173225	1168.708984	0.000000	NaN	NaN
403.499079	0.004260	42.598832	0.173846	1169.328003	0.000000	NaN	NaN
404.999165	0.004326	43.259057	0.174546	1170.024292	0.000000	NaN	NaN
406.499251	0.004326	43.259057	0.175137	1170.613647	0.000000	NaN	NaN
407.999336	0.004276	42.763888	0.175884	1171.357910	0.000000	NaN	NaN
409.499422	0.004177	41.773551	0.176488	1171.958862	0.000000	NaN	NaN
410.999508	0.004095	40.948269	0.177066	1172.535278	0.000000	NaN	NaN
412.499594	0.004202	42.021135	0.177774	1173.240845	0.000000	NaN	NaN
413.999680	0.004210	42.103663	0.178445	1173.908691	0.000000	NaN	NaN
415.499765	0.004351	43.506641	0.178987	1174.448975	0.000000	NaN	NaN
416.999851	0.004252	42.516304	0.179690	1175.149048	0.000000	NaN	NaN
418.499937	0.004326	43.259057	0.180366	1175.822144	0.000000	NaN	NaN
419.999023	0.004128	41.278382	0.181023	1176.477051	0.000000	NaN	NaN
421.499108	0.004202	42.021135	0.181642	1177.093384	0.000000	NaN	NaN
422.999194	0.004153	41.525966	0.182335	1177.783936	0.000000	NaN	NaN
424.499280	0.004161	41.608494	0.182994	1178.440552	0.000000	NaN	NaN
425.999366	0.004425	44.249394	0.183614	1179.057495	0.000000	NaN	NaN
427.499452	0.004169	41.691023	0.184191	1179.633179	0.000000	NaN	NaN
428.999537	0.004425	44.249394	0.184862	1180.301514	0.000000	NaN	NaN
430.499623	0.004309	43.094001	0.185574	1181.010376	0.000000	NaN	NaN
431.999709	0.004351	43.506641	0.186186	1181.620239	0.000000	NaN	NaN
433.499795	0.004285	42.846416	0.186854	1182.285889	0.000000	NaN	NaN
434.999881	0.004392	43.919282	0.187432	1182.860840	0.000000	NaN	NaN
436.499966	0.004293	42.928944	0.188128	1183.555054	0.000000	NaN	NaN
437.999052	0.004466	44.662035	0.188789	1184.213379	0.000000	NaN	NaN
439.499138	0.004342	43.424113	0.189464	1184.885132	0.000000	NaN	NaN
440.999224	0.004285	42.846416	0.190045	1185.463867	0.000000	NaN	NaN
442.499310	0.004252	42.516304	0.190717	1186.133057	0.000000	NaN	NaN
443.999395	0.004334	43.341585	0.191477	1186.890503	0.000000	NaN	NaN
445.499481	0.004466	44.662035	0.192039	1187.450439	0.000000	NaN	NaN
446.999567	0.004318	43.176529	0.192683	1188.091675	0.000000	NaN	NaN
448.499653	0.004359	43.589169	0.193325	1188.731079	0.000000	NaN	NaN
449.999739	0.004375	43.754226	0.193931	1189.335449	0.000000	NaN	NaN
451.499824	0.004136	41.360910	0.194583	1189.984863	0.000000	NaN	NaN
452.999910	0.004260	42.598832	0.195270	1190.668823	0.000000	NaN	NaN
454.499996	0.004318	43.176529	0.195940	1191.336548	0.000000	NaN	NaN
455.999082	0.004334	43.341585	0.196678	1192.071777	0.000000	NaN	NaN
457.499168	0.004408	44.084338	0.197218	1192.609619	0.000000	NaN	NaN
458.999253	0.004252	42.516304	0.197911	1193.300171	0.000000	NaN	NaN
460.499339	0.004507	45.074676	0.198553	1193.939697	0.000000	NaN	NaN
461.999425	0.004417	44.166866	0.199186	1194.570068	0.000000	NaN	NaN
463.499511	0.004384	43.836754	0.199860	1195.241089	0.000000	NaN	NaN
464.999596	0.004400	44.001810	0.200472	1195.851318	0.000000	NaN	NaN
466.499682	0.004342	43.424113	0.201183	1196.559082	0.000000	NaN	NaN
467.999768	0.004318	43.176529	0.201757	1197.131226	0.000000	NaN	NaN
469.499854	0.004334	43.341585	0.202361	1197.732422	0.000000	NaN	NaN
470.999940	0.004367	43.671697	0.203025	1198.394043	0.000000	NaN	NaN
472.499025	0.004384	43.836754	0.203715	1199.081177	0.000000	NaN	NaN
473.999111	0.004351	43.506641	0.204339	1199.703003	0.000000	NaN	NaN
475.499197	0.004524	45.239732	0.205025	1200.386230	0.000000	NaN	NaN
476.999283	0.004417	44.166866	0.205695	1201.053711	0.000000	NaN	NaN
478.499369	0.004450	44.496979	0.206273	1201.629517	0.000000	NaN	NaN
479.999454	0.004450	44.496979	0.206927	1202.281250	0.000000	NaN	NaN
481.499540	0.004458	44.579507	0.207517	1202.868774	0.000000	NaN	NaN
482.999626	0.004532	45.322260	0.208168	1203.517822	0.000000	NaN	NaN
484.499712	0.004516	45.157204	0.208752	1204.098999	0.000000	NaN	NaN
485.999798	0.004458	44.579507	0.209460	1204.804565	0.000000	NaN	NaN
487.499883	0.004351	43.506641	0.210117	1205.458618	0.000000	NaN	NaN
488.999969	0.004507	45.074676	0.210767	1206.106567	0.000000	NaN	NaN
490.499055	0.004375	43.754226	0.211355	1206.692505	0.000000	NaN	NaN
491.999141	0.004458	44.579507	0.211968	1207.302612	0.000000	NaN	NaN
493.499227	0.004342	43.424113	0.212577	1207.908936	0.000000	NaN	NaN
494.999312	0.004458	44.579507	0.213162	1208.492187	0.000000	NaN	NaN
496.499398	0.004334	43.341585	0.213915	1209.242187	0.000000	NaN	NaN
497.999484	0.004425	44.249394	0.214449	1209.773804	0.000000	NaN	NaN
499.499570	0.004441	44.414451	0.215037	1210.359863	0.000000	NaN	NaN
500.999656	0.004598	45.982485	0.215696	1211.016846	0.000000	NaN	NaN
502.499741	0.004433	44.331922	0.216304	1211.622192	0.000000	NaN	NaN
503.999827	0.004598	45.982485	0.216960	1212.275391	0.000000	NaN	NaN
505.499913	0.004499	44.992147	0.217553	1212.866089	0.000000	NaN	NaN
506.999999	0.004400	44.001810	0.218197	1213.507812	0.000000	NaN	NaN
508.499085	0.004466	44.662035	0.218805	1214.113647	0.000000	NaN	NaN
509.999170	0.004458	44.579507	0.219397	1214.702881	0.000000	NaN	NaN
511.499256	0.004450	44.496979	0.220053	1215.356201	0.000000	NaN	NaN
512.999342	0.004516	45.157204	0.220760	1216.061157	0.000000	NaN	NaN
514.499428	0.004450	44.496979	0.221312	1216.610474	0.000000	NaN	NaN
515.999514	0.004433	44.331922	0.221910	1217.206543	0.000000	NaN	NaN
517.499599	0.004615	46.147541	0.222578	1217.872314	0.000000	NaN	NaN
518.999685	0.004714	47.137879	0.223218	1218.509399	0.000000	NaN	NaN
520.499771	0.004532	45.322260	0.223881	1219.170410	0.000000	NaN	NaN
521.999857	0.004516	45.157204	0.224500	1219.786865	0.000000	NaN	NaN
523.499943	0.004607	46.065013	0.225142	1220.426514	0.000000	NaN	NaN
524.999028	0.004615	46.147541	0.225707	1220.988403	0.000000	NaN	NaN
526.499114	0.004565	45.652372	0.226369	1221.648437	0.000000	NaN	NaN
527.999200	0.004524	45.239732	0.226975	1222.251831	0.000000	NaN	NaN
529.499286	0.004714	47.137879	0.227571	1222.845215	0.000000	NaN	NaN
530.999372	0.004557	45.569844	0.228252	1223.524536	0.000000	NaN	NaN
532.499457	0.004598	45.982485	0.228917	1224.186768	0.000000	NaN	NaN
533.999543	0.004648	46.477654	0.229437	1224.704834	0.000000	NaN	NaN
535.499629	0.004640	46.395125	0.230100	1225.364624	0.000000	NaN	NaN
536.999715	0.004598	45.982485	0.230695	1225.957397	0.000000	NaN	NaN
538.499801	0.004623	46.230069	0.231321	1226.581299	0.000000	NaN	NaN
539.999886	0.004706	47.055350	0.232007	1227.264771	0.000000	NaN	NaN
541.499972	0.004483	44.827091	0.232507	1227.762573	0.000000	NaN	NaN
542.999058	0.004565	45.652372	0.233269	1228.521729	0.000000	NaN	NaN
544.499144	0.004565	45.652372	0.233767	1229.018066	0.000000	NaN	NaN
545.999229	0.004648	46.477654	0.234379	1229.627197	0.000000	NaN	NaN
547.499315	0.004590	45.899957	0.235026	1230.271484	0.000000	NaN	NaN
548.999401	0.004681	46.807766	0.235676	1230.919800	0.000000	NaN	NaN
550.499487	0.004640	46.395125	0.236311	1231.552368	0.000000	NaN	NaN
551.999573	0.004648	46.477654	0.236926	1232.165161	0.000000	NaN	NaN
553.499658	0.004763	47.633047	0.237599	1232.835205	0.000000	NaN	NaN
554.999744	0.004706	47.055350	0.238165	1233.399292	0.000000	NaN	NaN
556.499830	0.004747	47.467991	0.238797	1234.028320	0.000000	NaN	NaN
557.999916	0.004739	47.385463	0.239433	1234.661865	0.000000	NaN	NaN
559.500002	0.004755	47.550519	0.240005	1235.231934	0.000000	NaN	NaN
560.999087	0.004640	46.395125	0.240711	1235.935547	0.000000	NaN	NaN
562.499173	0.004706	47.055350	0.241261	1236.483276	0.000000	NaN	NaN
563.999259	0.004656	46.560182	0.241911	1237.130859	0.000000	NaN	NaN
565.499345	0.004631	46.312597	0.242466	1237.683472	0.000000	NaN	NaN
566.999431	0.004631	46.312597	0.242984	1238.199219	0.000000	NaN	NaN
568.499516	0.004730	47.302935	0.243653	1238.865601	0.000000	NaN	NaN
569.999602	0.004689	46.890294	0.244241	1239.451172	0.000000	NaN	NaN
571.499688	0.004796	47.963160	0.244856	1240.064209	0.000000	NaN	NaN
572.999774	0.005382	53.822656	0.245455	1240.660767	0.000000	NaN	NaN
574.499860	0.004763	47.633047	0.246094	1241.297607	0.000000	NaN	NaN
575.999945	0.004780	47.798104	0.246591	1241.792603	0.000000	NaN	NaN
577.499031	0.004796	47.963160	0.247252	1242.451050	0.000000	NaN	NaN
578.999117	0.004747	47.467991	0.247809	1243.005981	0.000000	NaN	NaN
580.499203	0.004763	47.633047	0.248424	1243.618896	0.000000	NaN	NaN
581.999289	0.004805	48.045688	0.249071	1244.263428	0.000000	NaN	NaN
583.499374	0.004590	45.899957	0.249617	1244.806641	0.000000	NaN	NaN
584.999460	0.004673	46.725238	0.250253	1245.440186	0.000000	NaN	NaN
586.499546	0.004706	47.055350	0.250894	1246.078979	0.000000	NaN	NaN
587.999632	0.004747	47.467991	0.251461	1246.643677	0.000000	NaN	NaN
589.499718	0.004747	47.467991	0.252005	1247.185181	0.000000	NaN	NaN
590.999803	0.004805	48.045688	0.252645	1247.823242	0.000000	NaN	NaN
592.499889	0.004854	48.540857	0.253215	1248.391357	0.000000	NaN	NaN
593.999975	0.004796	47.963160	0.253839	1249.012939	0.000000	NaN	NaN
595.499061	0.004755	47.550519	0.254512	1249.683350	0.000000	NaN	NaN
596.999146	0.005019	50.191419	0.255131	1250.299438	0.000000	NaN	NaN
598.499232	0.004805	48.045688	0.255739	1250.905396	0.000000	NaN	NaN
599.999318	0.004772	47.715575	0.256346	1251.509644	0.000000	NaN	NaN
601.499404	0.004862	48.623385	0.256949	1252.110718	0.000000	NaN	NaN
602.999490	0.004739	47.385463	0.257611	1252.770142	0.000000	NaN	NaN
604.499575	0.004706	47.055350	0.258283	1253.439209	0.000000	NaN	NaN
605.999661	0.004821	48.210744	0.258855	1254.009155	0.000000	NaN	NaN
607.499747	0.004796	47.963160	0.259554	1254.705933	0.000000	NaN	NaN
608.999833	0.004821	48.210744	0.260063	1255.212769	0.000000	NaN	NaN
610.499919	0.004772	47.715575	0.260647	1255.794800	0.000000	NaN	NaN
612.000004	0.004755	47.550519	0.261338	1256.482666	0.000000	NaN	NaN
613.499090	0.004871	48.705913	0.261909	1257.051880	0.000000	NaN	NaN
614.999176	0.004780	47.798104	0.262519	1257.659302	0.000000	NaN	NaN
616.499262	0.004829	48.293272	0.263151	1258.288818	0.000000	NaN	NaN
617.999348	0.004912	49.118554	0.263814	1258.948975	0.000000	NaN	NaN
619.499433	0.004780	47.798104	0.264385	1259.518311	0.000000	NaN	NaN
620.999519	0.004920	49.201082	0.265005	1260.135986	0.000000	NaN	NaN
622.499605	0.004920	49.201082	0.265672	1260.800293	0.000000	NaN	NaN
623.999691	0.004904	49.036025	0.266245	1261.370972	0.000000	NaN	NaN
625.499777	0.004895	48.953497	0.266885	1262.008057	0.000000	NaN	NaN
626.999862	0.004788	47.880632	0.267488	1262.608887	0.000000	NaN	NaN
628.499948	0.004887	48.870969	0.268117	1263.235962	0.000000	NaN	NaN
629.999034	0.004994	49.943835	0.268723	1263.839478	0.000000	NaN	NaN
631.499120	0.004862	48.623385	0.269333	1264.446899	0.000000	NaN	NaN
632.999206	0.004920	49.201082	0.269981	1265.092407	0.000000	NaN	NaN
634.499291	0.004755	47.550519	0.270580	1265.688721	0.000000	NaN	NaN
635.999377	0.004920	49.201082	0.271170	1266.277222	0.000000	NaN	NaN
637.499463	0.004953	49.531194	0.271811	1266.914917	0.000000	NaN	NaN
638.999549	0.004912	49.118554	0.272486	1267.587524	0.000000	NaN	NaN
640.499635	0.004920	49.201082	0.273021	1268.120850	0.000000	NaN	NaN
641.999720	0.004978	49.778778	0.273655	1268.752319	0.000000	NaN	NaN
643.499806	0.004887	48.870969	0.274290	1269.385254	0.000000	NaN	NaN
644.999892	0.004986	49.861307	0.274890	1269.982788	0.000000	NaN	NaN
646.499978	0.004912	49.118554	0.275524	1270.613647	0.000000	NaN	NaN
647.999064	0.004904	49.036025	0.276099	1271.186768	0.000000	NaN	NaN
649.499149	0.005003	50.026363	0.276768	1271.853516	0.000000	NaN	NaN
650.999235	0.004945	49.448666	0.277318	1272.400757	0.000000	NaN	NaN
652.499321	0.004953	49.531194	0.277900	1272.981201	0.000000	NaN	NaN
653.999407	0.005036	50.356475	0.278413	1273.491821	0.000000	NaN	NaN
655.499493	0.004961	49.613722	0.279084	1274.160278	0.000000	NaN	NaN
656.999578	0.004970	49.696250	0.279749	1274.823120	0.000000	NaN	NaN
658.499664	0.005011	50.108891	0.280267	1275.338623	0.000000	NaN	NaN
659.999750	0.004994	49.943835	0.280962	1276.031372	0.000000	NaN	NaN
661.499836	0.004986	49.861307	0.281507	1276.574097	0.000000	NaN	NaN
662.999922	0.004978	49.778778	0.282132	1277.196289	0.000000	NaN	NaN
664.500007	0.005003	50.026363	0.282701	1277.763672	0.000000	NaN	NaN
665.999093	0.005060	50.604060	0.283382	1278.441406	0.000000	NaN	NaN
667.499179	0.005011	50.108891	0.283993	1279.050171	0.000000	NaN	NaN
668.999265	0.005069	50.686588	0.284462	1279.517334	0.000000	NaN	NaN
670.499350	0.005052	50.521532	0.285153	1280.205811	0.000000	NaN	NaN
671.999436	0.005011	50.108891	0.285730	1280.780884	0.000000	NaN	NaN
673.499522	0.004994	49.943835	0.286436	1281.484131	0.000000	NaN	NaN
674.999608	0.004978	49.778778	0.286953	1281.999512	0.000000	NaN	NaN
676.499694	0.004945	49.448666	0.287590	1282.633545	0.000000	NaN	NaN
677.999779	0.004945	49.448666	0.288206	1283.247314	0.000000	NaN	NaN
679.499865	0.004895	48.953497	0.288806	1283.845093	0.000000	NaN	NaN
680.999951	0.005003	50.026363	0.289469	1284.505127	0.000000	NaN	NaN
682.499037	0.004912	49.118554	0.290032	1285.066284	0.000000	NaN	NaN
683.999123	0.005135	51.346813	0.290597	1285.629028	0.000000	NaN	NaN
685.499208	0.005077	50.769116	0.291161	1286.191284	0.000000	NaN	NaN
686.999294	0.005044	50.439003	0.291801	1286.828491	0.000000	NaN	NaN
688.499380	0.005126	51.264285	0.292511	1287.535400	0.000000	NaN	NaN
689.999466	0.004994	49.943835	0.293053	1288.075195	0.000000	NaN	NaN
691.499552	0.005052	50.521532	0.293744	1288.764404	0.000000	NaN	NaN
692.999637	0.005060	50.604060	0.294335	1289.352783	0.000000	NaN	NaN
694.499723	0.004994	49.943835	0.294806	1289.822021	0.000000	NaN	NaN
695.999809	0.005118	51.181757	0.295456	1290.469727	0.000000	NaN	NaN
697.499895	0.005052	50.521532	0.296073	1291.083618	0.000000	NaN	NaN
698.999981	0.005027	50.273947	0.296705	1291.713379	0.000000	NaN	NaN
700.499066	0.005085	50.851644	0.297248	1292.254639	0.000000	NaN	NaN
701.999152	0.005126	51.264285	0.297896	1292.899536	0.000000	NaN	NaN
703.499238	0.005019	50.191419	0.298492	1293.493530	0.000000	NaN	NaN
704.999324	0.005093	50.934172	0.299033	1294.032837	0.000000	NaN	NaN
706.499410	0.004953	49.531194	0.299668	1294.664917	0.000000	NaN	NaN
707.999495	0.005044	50.439003	0.300250	1295.244629	0.000000	NaN	NaN
709.499581	0.005077	50.769116	0.300856	1295.848999	0.000000	NaN	NaN
710.999667	0.005151	51.511869	0.301485	1296.474976	0.000000	NaN	NaN
712.499753	0.004945	49.448666	0.302037	1297.025269	0.000000	NaN	NaN
713.999839	0.005093	50.934172	0.302618	1297.604248	0.000000	NaN	NaN
715.499924	0.005135	51.346813	0.303289	1298.272095	0.000000	NaN	NaN
717.000010	0.005085	50.851644	0.303778	1298.759155	0.000000	NaN	NaN
718.499096	0.005027	50.273947	0.304549	1299.526978	0.000000	NaN	NaN
719.999182	0.004961	49.613722	0.304980	1299.956665	0.000000	NaN	NaN
721.499267	0.005060	50.604060	0.305653	1300.626709	0.000000	NaN	NaN
722.999353	0.004970	49.696250	0.306266	1301.238037	0.000000	NaN	NaN
724.499439	0.005102	51.016700	0.306757	1301.726562	0.000000	NaN	NaN
725.999525	0.005143	51.429341	0.307400	1302.367310	0.000000	NaN	NaN
727.499611	0.005102	51.016700	0.307910	1302.875122	0.000000	NaN	NaN
728.999696	0.005060	50.604060	0.308470	1303.433350	0.000000	NaN	NaN
730.499782	0.005044	50.439003	0.309099	1304.059570	0.000000	NaN	NaN
731.999868	0.004912	49.118554	0.309697	1304.655884	0.000000	NaN	NaN
733.499954	0.005019	50.191419	0.310384	1305.340210	0.000000	NaN	NaN
734.999040	0.005044	50.439003	0.310984	1305.937866	0.000000	NaN	NaN
736.499125	0.005060	50.604060	0.311458	1306.410034	0.000000	NaN	NaN
737.999211	0.005176	51.759453	0.312040	1306.989258	0.000000	NaN	NaN
739.499297	0.005102	51.016700	0.312666	1307.613525	0.000000	NaN	NaN
740.999383	0.005225	52.254622	0.313327	1308.271729	0.000000	NaN	NaN
742.499469	0.005093	50.934172	0.313887	1308.829468	0.000000	NaN	NaN
743.999554	0.005085	50.851644	0.314521	1309.461304	0.000000	NaN	NaN
745.499640	0.005044	50.439003	0.315026	1309.963867	0.000000	NaN	NaN
746.999726	0.005036	50.356475	0.315546	1310.481689	0.000000	NaN	NaN
748.499812	0.005184	51.841982	0.316152	1311.085815	0.000000	NaN	NaN
749.999898	0.005126	51.264285	0.316832	1311.763062	0.000000	NaN	NaN
751.499983	0.005044	50.439003	0.317452	1312.380981	0.000000	NaN	NaN
752.999069	0.005036	50.356475	0.317993	1312.919556	0.000000	NaN	NaN
754.499155	0.005118	51.181757	0.318464	1313.388672	0.000000	NaN	NaN
755.999241	0.005085	50.851644	0.319062	1313.984619	0.000000	NaN	NaN
757.499327	0.004928	49.283610	0.319621	1314.541260	0.000000	NaN	NaN
758.999412	0.005085	50.851644	0.320137	1315.055786	0.000000	NaN	NaN
760.499498	0.005234	52.337150	0.320821	1315.736328	0.000000	NaN	NaN
761.999584	0.005283	52.832319	0.321378	1316.291382	0.000000	NaN	NaN
763.499670	0.005102	51.016700	0.321922	1316.833862	0.000000	NaN	NaN
764.999755	0.005069	50.686588	0.322458	1317.367798	0.000000	NaN	NaN
766.499841	0.005069	50.686588	0.322904	1317.812012	0.000000	NaN	NaN
767.999927	0.005044	50.439003	0.323528	1318.433472	0.000000	NaN	NaN
769.500013	0.005069	50.686588	0.324172	1319.074463	0.000000	NaN	NaN
770.999099	0.005151	51.511869	0.324658	1319.558838	0.000000	NaN	NaN
772.499185	0.005027	50.273947	0.325262	1320.160522	0.000000	NaN	NaN
773.999270	0.005118	51.181757	0.325785	1320.681641	0.000000	NaN	NaN
775.499356	0.005011	50.108891	0.326374	1321.268677	0.000000	NaN	NaN
776.999442	0.005036	50.356475	0.326934	1321.826294	0.000000	NaN	NaN
778.499528	0.005052	50.521532	0.327611	1322.500854	0.000000	NaN	NaN
779.999614	0.005126	51.264285	0.328144	1323.031982	0.000000	NaN	NaN
781.499699	0.005217	52.172094	0.328685	1323.570190	0.000000	NaN	NaN
782.999785	0.005036	50.356475	0.329307	1324.190308	0.000000	NaN	NaN
784.499871	0.005044	50.439003	0.329857	1324.738159	0.000000	NaN	NaN
785.999957	0.005102	51.016700	0.330408	1325.286865	0.000000	NaN	NaN
787.499042	0.004986	49.861307	0.330973	1325.849854	0.000000	NaN	NaN
788.999128	0.005036	50.356475	0.331610	1326.484619	0.000000	NaN	NaN
790.499214	0.005118	51.181757	0.332239	1327.110352	0.000000	NaN	NaN
791.999300	0.005036	50.356475	0.332830	1327.699829	0.000000	NaN	NaN
793.499386	0.005027	50.273947	0.333443	1328.310181	0.000000	NaN	NaN
794.999471	0.005118	51.181757	0.333939	1328.804443	0.000000	NaN	NaN
796.499557	0.005052	50.521532	0.334539	1329.402344	0.000000	NaN	NaN
797.999643	0.005027	50.273947	0.335080	1329.941040	0.000000	NaN	NaN
799.499729	0.005019	50.191419	0.335799	1330.657227	0.000000	NaN	NaN
800.999815	0.005027	50.273947	0.336337	1331.193237	0.000000	NaN	NaN
802.499900	0.004895	48.953497	0.336949	1331.802490	0.000000	NaN	NaN
803.999986	0.005085	50.851644	0.337412	1332.264282	0.000000	NaN	NaN
805.499072	0.005003	50.026363	0.338019	1332.868286	0.000000	NaN	NaN
806.999158	0.005011	50.108891	0.338686	1333.532593	0.000000	NaN	NaN
808.499244	0.005044	50.439003	0.339309	1334.153931	0.000000	NaN	NaN
809.999329	0.004986	49.861307	0.339876	1334.718506	0.000000	NaN	NaN
811.499415	0.004953	49.531194	0.340575	1335.415161	0.000000	NaN	NaN
812.999501	0.004937	49.366138	0.341120	1335.958130	0.000000	NaN	NaN
814.499587	0.005011	50.108891	0.341727	1336.562744	0.000000	NaN	NaN
815.999673	0.004937	49.366138	0.342384	1337.216309	0.000000	NaN	NaN
817.499758	0.004879	48.788441	0.343069	1337.899170	0.000000	NaN	NaN
818.999844	0.004871	48.705913	0.343676	1338.504028	0.000000	NaN	NaN
820.499930	0.004912	49.118554	0.344331	1339.156372	0.000000	NaN	NaN
822.000016	0.004961	49.613722	0.345068	1339.890381	0.000000	NaN	NaN
823.499102	0.004846	48.458329	0.345721	1340.541382	0.000000	NaN	NaN
824.999187	0.004904	49.036025	0.346501	1341.318359	0.000000	NaN	NaN
826.499273	0.004673	46.725238	0.347253	1342.066895	0.000000	NaN	NaN
827.999359	0.004846	48.458329	0.347938	1342.749023	0.000000	NaN	NaN
829.499445	0.004722	47.220407	0.348756	1343.564087	0.000000	NaN	NaN
830.999530	0.004730	47.302935	0.349461	1344.266846	0.000000	NaN	NaN
832.499616	0.004730	47.302935	0.350389	1345.190918	0.000000	NaN	NaN
833.999702	0.004598	45.982485	0.351186	1345.985107	0.000000	NaN	NaN
835.499788	0.004664	46.642710	0.352243	1347.037720	0.000000	NaN	NaN
836.999874	0.004524	45.239732	0.353193	1347.984497	0.000000	NaN	NaN
838.499960	0.004549	45.487316	0.354252	1349.039551	0.000000	NaN	NaN
839.999045	0.004598	45.982485	0.355265	1350.047852	0.000000	NaN	NaN
841.499131	0.004499	44.992147	0.356404	1351.182861	0.000000	NaN	NaN
842.999217	0.004433	44.331922	0.357581	1352.355103	0.000000	NaN	NaN
844.499303	0.004400	44.001810	0.358867	1353.636475	0.000000	NaN	NaN
845.999388	0.004260	42.598832	0.360258	1355.022217	0.000000	NaN	NaN
847.499474	0.004120	41.195854	0.361676	1356.434692	0.000000	NaN	NaN
848.999560	0.004021	40.205516	0.363366	1358.117676	0.000000	NaN	NaN
850.499646	0.004012	40.122988	0.365129	1359.874268	0.000000	NaN	NaN
851.999732	0.003831	38.307369	0.367163	1361.900024	0.000000	NaN	NaN
853.499817	0.003550	35.501413	0.369358	1364.086548	0.000000	NaN	NaN
854.999903	0.003435	34.346020	0.372091	1366.809570	0.000000	NaN	NaN
856.499989	0.003005	30.054557	0.375117	1369.823608	0.000000	NaN	NaN
857.999075	0.002131	21.306576	0.379637	1374.326416	0.000000	NaN	NaN
859.499161	-0.000304	-3.039221	0.428227	1422.728882	0.000000	NaN	NaN
860.999246	-0.000378	-3.781974	0.100498	1096.261841	0.000000	NaN	NaN
862.499332	-0.000254	-2.544052	0.110684	1106.408203	0.000000	NaN	NaN
863.999418	-0.000238	-2.378996	0.116331	1112.034058	0.000000	NaN	NaN
865.499504	-0.000188	-1.883827	0.119960	1115.648804	0.000000	NaN	NaN
866.499561	-0.000155	-1.553715	0.454225	1448.627563	0.000000	NaN	NaN