File: data/115k_1-3_1 (190321).lvm
LabVIEW Measurement
Writer_Version	2
Reader_Version	2
Separator	Tab
Decimal_Separator	.
Multi_Headings	No
X_Columns	One
Time_Pref	Absolute
Operator	user
Description	Load(N)/Stress(MPa)/Distance A(pixel)/Strain A/Distance B(pixel)/Strain B/Poisson's ratio
Date	2019/03/21
Time	12:58:35.3148044300349900275
***End_of_Header***

Notes	X 값은 오직 다음과 같을 때에만 유효함이 보장됩니다. Dev1/ai0
Channels	7
Samples	1	1	1	1	1	1	1
Date	2019/03/21	2019/03/21	2019/03/21	2019/03/21	2019/03/21	2019/03/21	2019/03/21
Time	13:24:29.3146881300349900877	13:24:29.3146881300349900877	13:24:29.3146882057189941406	13:24:29.3146882057189941406	13:24:29.3146882057189941406	13:24:29.3146882057189941406	13:24:29.3146882057189941406
Y_Unit_Label	Volts	Volts
X_Dimension	Time	Time	Time	Time	Time	Time	Time
X0	0.0000000000000000E+0	0.0000000000000000E+0	0.0000000000000000E+0	0.0000000000000000E+0	0.0000000000000000E+0	0.0000000000000000E+0	0.0000000000000000E+0
Delta_X	0.000000	0.000000	1.000000	1.000000	1.000000	1.000000	1.000000
***End_of_Header***
X_Value	Dev1/ai0	Dev1/ai0 1	Untitled	Untitled 1	Untitled 2	Untitled 3	Untitled 4	Comment
0.000000	-0.000172	-1.718771	0.006234	998.340149	0.000000	NaN	NaN
1.500086	-6.459055E-5	-0.645906	1.847744E-5	998.358582	0.000000	NaN	NaN
3.000172	-6.459055E-5	-0.645906	1.215935E-5	998.352234	0.000000	NaN	NaN
4.500257	-6.820864E-6	-0.068209	0.000204	998.544067	0.000000	NaN	NaN
5.999343	0.000175	1.747410	0.000763	999.102173	0.000000	NaN	NaN
7.499429	0.000142	1.417298	0.001135	999.473389	0.000000	NaN	NaN
8.999515	0.000249	2.490163	0.001710	1000.047607	0.000000	NaN	NaN
10.499600	0.000166	1.664882	0.001335	999.673279	0.000000	NaN	NaN
11.999686	0.000299	2.985332	0.001666	1000.003662	0.000000	NaN	NaN
13.499772	0.000340	3.397973	0.001810	1000.146851	0.000000	NaN	NaN
14.999858	0.000323	3.232916	0.002252	1000.588196	0.000000	NaN	NaN
16.499944	0.000422	4.223254	0.002488	1000.823608	0.000000	NaN	NaN
18.000030	0.000629	6.286457	0.002753	1001.088623	0.000000	NaN	NaN
19.500115	0.000670	6.699098	0.003139	1001.474121	0.000000	NaN	NaN
21.000201	0.000744	7.441851	0.003434	1001.768860	0.000000	NaN	NaN
22.500287	0.000719	7.194267	0.003924	1002.257996	0.000000	NaN	NaN
23.999373	0.000959	9.587582	0.004240	1002.572693	0.000000	NaN	NaN
25.499458	0.001017	10.165279	0.004500	1002.832336	0.000000	NaN	NaN
26.999544	0.000959	9.587582	0.004240	1002.572937	0.000000	NaN	NaN
28.499630	0.001041	10.412863	0.004636	1002.968445	0.000000	NaN	NaN
29.999716	0.001165	11.650785	0.005836	1004.166077	0.000000	NaN	NaN
31.499802	0.001289	12.888707	0.006125	1004.455322	0.000000	NaN	NaN
32.999887	0.001272	12.723651	0.006573	1004.902161	0.000000	NaN	NaN
34.499973	0.001338	13.383876	0.007052	1005.380310	0.000000	NaN	NaN
36.000059	0.001380	13.796517	0.007388	1005.715942	0.000000	NaN	NaN
37.500145	0.001586	15.859720	0.007895	1006.221619	0.000000	NaN	NaN
39.000231	0.001536	15.364551	0.008257	1006.583740	0.000000	NaN	NaN
40.499316	0.001586	15.859720	0.008729	1007.054871	0.000000	NaN	NaN
41.999402	0.001718	17.180170	0.009396	1007.720764	0.000000	NaN	NaN
43.499488	0.001801	18.005451	0.009652	1007.976440	0.000000	NaN	NaN
44.999574	0.001941	19.408429	0.010266	1008.589417	0.000000	NaN	NaN
46.499660	0.001809	18.087979	0.010688	1009.010132	0.000000	NaN	NaN
47.999745	0.002056	20.563823	0.011210	1009.531738	0.000000	NaN	NaN
49.499831	0.002065	20.646351	0.011646	1009.966858	0.000000	NaN	NaN
50.999917	0.002089	20.893935	0.012134	1010.454468	0.000000	NaN	NaN
52.500003	0.002147	21.471632	0.012667	1010.985718	0.000000	NaN	NaN
54.000089	0.002098	20.976463	0.013133	1011.451477	0.000000	NaN	NaN
55.500174	0.002230	22.296913	0.013528	1011.845398	0.000000	NaN	NaN
57.000260	0.002271	22.709554	0.014036	1012.353027	0.000000	NaN	NaN
58.499346	0.002411	24.112532	0.014338	1012.654663	0.000000	NaN	NaN
59.999432	0.002378	23.782420	0.015010	1013.324707	0.000000	NaN	NaN
61.499517	0.002576	25.763095	0.015524	1013.838257	0.000000	NaN	NaN
62.999603	0.002543	25.432982	0.016143	1014.456665	0.000000	NaN	NaN
64.499689	0.002593	25.928151	0.016720	1015.032410	0.000000	NaN	NaN
65.999775	0.002626	26.258263	0.017411	1015.722229	0.000000	NaN	NaN
67.499861	0.002667	26.670904	0.017935	1016.245239	0.000000	NaN	NaN
68.999946	0.002725	27.248601	0.018520	1016.829834	0.000000	NaN	NaN
70.500032	0.002725	27.248601	0.019286	1017.594421	0.000000	NaN	NaN
72.000118	0.002774	27.743770	0.019874	1018.181641	0.000000	NaN	NaN
73.500204	0.002898	28.981692	0.020582	1018.887695	0.000000	NaN	NaN
75.000290	0.002931	29.311804	0.021303	1019.607422	0.000000	NaN	NaN
76.499375	0.002915	29.146748	0.021936	1020.239441	0.000000	NaN	NaN
77.999461	0.002989	29.889501	0.022562	1020.865112	0.000000	NaN	NaN
79.499547	0.002981	29.806973	0.023782	1022.082886	0.000000	NaN	NaN
80.999633	0.003071	30.714782	0.024420	1022.719116	0.000000	NaN	NaN
82.499719	0.003030	30.302142	0.025162	1023.460266	0.000000	NaN	NaN
83.999804	0.003030	30.302142	0.025766	1024.063843	0.000000	NaN	NaN
85.499890	0.003080	30.797310	0.026550	1024.845947	0.000000	NaN	NaN
86.999976	0.003146	31.457535	0.027337	1025.631958	0.000000	NaN	NaN
88.500062	0.003179	31.787648	0.028051	1026.344604	0.000000	NaN	NaN
90.000148	0.003146	31.457535	0.028765	1027.057007	0.000000	NaN	NaN
91.500233	0.003154	31.540063	0.029511	1027.802002	0.000000	NaN	NaN
92.999319	0.003038	30.384670	0.030259	1028.548950	0.000000	NaN	NaN
94.499405	0.003195	31.952704	0.031091	1029.379883	0.000000	NaN	NaN
95.999491	0.003096	30.962367	0.031783	1030.070312	0.000000	NaN	NaN
97.499577	0.003030	30.302142	0.032457	1030.743164	0.000000	NaN	NaN
98.999662	0.003237	32.365345	0.033420	1031.704346	0.000000	NaN	NaN
100.499748	0.003253	32.530401	0.034202	1032.485107	0.000000	NaN	NaN
101.999834	0.003146	31.457535	0.034960	1033.242554	0.000000	NaN	NaN
103.499920	0.003294	32.943041	0.035819	1034.099731	0.000000	NaN	NaN
105.000006	0.003369	33.685795	0.036538	1034.817871	0.000000	NaN	NaN
106.500091	0.003154	31.540063	0.037442	1035.719604	0.000000	NaN	NaN
108.000177	0.003195	31.952704	0.038300	1036.576660	0.000000	NaN	NaN
109.500263	0.003303	33.025570	0.038958	1037.233765	0.000000	NaN	NaN
110.999349	0.003286	32.860513	0.039912	1038.186035	0.000000	NaN	NaN
112.499435	0.003253	32.530401	0.040793	1039.065186	0.000000	NaN	NaN
113.999520	0.003336	33.355682	0.041576	1039.846802	0.000000	NaN	NaN
115.499606	0.003270	32.695457	0.042251	1040.520752	0.000000	NaN	NaN
116.999692	0.003228	32.282816	0.043298	1041.565918	0.000000	NaN	NaN
118.499778	0.003303	33.025570	0.044102	1042.368652	0.000000	NaN	NaN
119.999864	0.003294	32.943041	0.045005	1043.270630	0.000000	NaN	NaN
121.499949	0.003418	34.180963	0.045809	1044.073486	0.000000	NaN	NaN
123.000035	0.003212	32.117760	0.046544	1044.806885	0.000000	NaN	NaN
124.500121	0.003443	34.428548	0.047500	1045.761475	0.000000	NaN	NaN
126.000207	0.003344	33.438210	0.048203	1046.463501	0.000000	NaN	NaN
127.500293	0.003294	32.943041	0.049005	1047.263672	0.000000	NaN	NaN
128.999378	0.003352	33.520738	0.049908	1048.165527	0.000000	NaN	NaN
130.499464	0.003369	33.685795	0.050471	1048.727539	0.000000	NaN	NaN
131.999550	0.003443	34.428548	0.051439	1049.693848	0.000000	NaN	NaN
133.499636	0.003443	34.428548	0.052431	1050.684448	0.000000	NaN	NaN
134.999721	0.003426	34.263491	0.053081	1051.332886	0.000000	NaN	NaN
136.499807	0.003311	33.108098	0.053879	1052.129761	0.000000	NaN	NaN
137.999893	0.003352	33.520738	0.054733	1052.981812	0.000000	NaN	NaN
139.499979	0.003402	34.015907	0.055604	1053.851685	0.000000	NaN	NaN
141.000065	0.003459	34.593604	0.056153	1054.400269	0.000000	NaN	NaN
142.500150	0.003501	35.006245	0.057082	1055.327637	0.000000	NaN	NaN
144.000236	0.003402	34.015907	0.057727	1055.971191	0.000000	NaN	NaN
145.499322	0.003393	33.933379	0.058558	1056.801147	0.000000	NaN	NaN
146.999408	0.003476	34.758660	0.059422	1057.663452	0.000000	NaN	NaN
148.499494	0.003468	34.676132	0.060218	1058.457764	0.000000	NaN	NaN
149.999580	0.003377	33.768323	0.061049	1059.288086	0.000000	NaN	NaN
151.499665	0.003377	33.768323	0.061748	1059.985718	0.000000	NaN	NaN
152.999751	0.003459	34.593604	0.062590	1060.826660	0.000000	NaN	NaN
154.499837	0.003542	35.418885	0.063457	1061.692017	0.000000	NaN	NaN
155.999923	0.003426	34.263491	0.064166	1062.399292	0.000000	NaN	NaN
157.500008	0.003435	34.346020	0.064996	1063.227905	0.000000	NaN	NaN
159.000094	0.003501	35.006245	0.065725	1063.955811	0.000000	NaN	NaN
160.500180	0.003501	35.006245	0.066635	1064.864746	0.000000	NaN	NaN
162.000266	0.003476	34.758660	0.067552	1065.780029	0.000000	NaN	NaN
163.499352	0.003501	35.006245	0.068270	1066.496460	0.000000	NaN	NaN
164.999437	0.003517	35.171301	0.069049	1067.274902	0.000000	NaN	NaN
166.499523	0.003352	33.520738	0.069832	1068.056030	0.000000	NaN	NaN
167.999609	0.003591	35.914054	0.070700	1068.922974	0.000000	NaN	NaN
169.499695	0.003369	33.685795	0.071318	1069.539795	0.000000	NaN	NaN
170.999781	0.003509	35.088773	0.072167	1070.387207	0.000000	NaN	NaN
172.499866	0.003443	34.428548	0.073030	1071.248535	0.000000	NaN	NaN
173.999952	0.003385	33.850851	0.073705	1071.922485	0.000000	NaN	NaN
175.500038	0.003459	34.593604	0.074592	1072.807861	0.000000	NaN	NaN
177.000124	0.003567	35.666470	0.075341	1073.555908	0.000000	NaN	NaN
178.500210	0.003534	35.336357	0.076092	1074.305908	0.000000	NaN	NaN
180.000295	0.003509	35.088773	0.076995	1075.207275	0.000000	NaN	NaN
181.499381	0.003583	35.831526	0.077719	1075.929932	0.000000	NaN	NaN
182.999467	0.003525	35.253829	0.078589	1076.798950	0.000000	NaN	NaN
184.499553	0.003600	35.996582	0.079124	1077.333008	0.000000	NaN	NaN
185.999639	0.003608	36.079110	0.080158	1078.364624	0.000000	NaN	NaN
187.499724	0.003616	36.161638	0.080838	1079.044067	0.000000	NaN	NaN
188.999810	0.003550	35.501413	0.081472	1079.676758	0.000000	NaN	NaN
190.499896	0.003600	35.996582	0.082175	1080.378662	0.000000	NaN	NaN
191.999982	0.003468	34.676132	0.082665	1080.868408	0.000000	NaN	NaN
193.500067	0.003534	35.336357	0.083320	1081.521851	0.000000	NaN	NaN
195.000153	0.003591	35.914054	0.084963	1083.161743	0.000000	NaN	NaN
196.500239	0.003649	36.491751	0.085815	1084.012817	0.000000	NaN	NaN
197.999325	0.003641	36.409223	0.086473	1084.669312	0.000000	NaN	NaN
199.499411	0.003567	35.666470	0.087306	1085.501587	0.000000	NaN	NaN
200.999496	0.003492	34.923716	0.087931	1086.125610	0.000000	NaN	NaN
202.499582	0.003641	36.409223	0.088758	1086.951172	0.000000	NaN	NaN
203.999668	0.003600	35.996582	0.089459	1087.650757	0.000000	NaN	NaN
205.499754	0.003542	35.418885	0.090345	1088.535522	0.000000	NaN	NaN
206.999840	0.003657	36.574279	0.091070	1089.258911	0.000000	NaN	NaN
208.499925	0.003558	35.583941	0.091794	1089.981689	0.000000	NaN	NaN
210.000011	0.003657	36.574279	0.092599	1090.785156	0.000000	NaN	NaN
211.500097	0.003690	36.904391	0.093258	1091.443481	0.000000	NaN	NaN
213.000183	0.003657	36.574279	0.094055	1092.239258	0.000000	NaN	NaN
214.500269	0.003707	37.069448	0.094902	1093.084717	0.000000	NaN	NaN
215.999354	0.003666	36.656807	0.095503	1093.684692	0.000000	NaN	NaN
217.499440	0.003740	37.399560	0.096240	1094.420654	0.000000	NaN	NaN
218.999526	0.003591	35.914054	0.096856	1095.034912	0.000000	NaN	NaN
220.499612	0.003732	37.317032	0.097813	1095.990479	0.000000	NaN	NaN
221.999698	0.003723	37.234504	0.098526	1096.702148	0.000000	NaN	NaN
223.499783	0.003616	36.161638	0.099330	1097.505005	0.000000	NaN	NaN
224.999869	0.003748	37.482088	0.099939	1098.113037	0.000000	NaN	NaN
226.499955	0.003723	37.234504	0.100794	1098.966675	0.000000	NaN	NaN
228.000041	0.003723	37.234504	0.101442	1099.613892	0.000000	NaN	NaN
229.500127	0.003740	37.399560	0.102172	1100.342529	0.000000	NaN	NaN
231.000212	0.003740	37.399560	0.102922	1101.091675	0.000000	NaN	NaN
232.500298	0.003682	36.821863	0.103650	1101.818604	0.000000	NaN	NaN
233.999384	0.003756	37.564616	0.104483	1102.649292	0.000000	NaN	NaN
235.499470	0.003798	37.977257	0.105099	1103.264771	0.000000	NaN	NaN
236.999556	0.003798	37.977257	0.105985	1104.149658	0.000000	NaN	NaN
238.499641	0.003765	37.647144	0.106693	1104.856323	0.000000	NaN	NaN
239.999727	0.003756	37.564616	0.107494	1105.655762	0.000000	NaN	NaN
241.499813	0.003798	37.977257	0.108131	1106.291626	0.000000	NaN	NaN
242.999899	0.003674	36.739335	0.108979	1107.138428	0.000000	NaN	NaN
244.499985	0.003806	38.059785	0.109506	1107.664429	0.000000	NaN	NaN
246.000070	0.003781	37.812201	0.110274	1108.431396	0.000000	NaN	NaN
247.500156	0.003756	37.564616	0.111070	1109.226074	0.000000	NaN	NaN
249.000242	0.003715	37.151976	0.111971	1110.125244	0.000000	NaN	NaN
250.499328	0.003748	37.482088	0.112513	1110.666748	0.000000	NaN	NaN
251.999414	0.003831	38.307369	0.113227	1111.379150	0.000000	NaN	NaN
253.499499	0.003905	39.050123	0.113968	1112.118652	0.000000	NaN	NaN
254.999585	0.003732	37.317032	0.114731	1112.880615	0.000000	NaN	NaN
256.499671	0.003789	37.894729	0.115501	1113.649170	0.000000	NaN	NaN
257.999757	0.003773	37.729673	0.116349	1114.495605	0.000000	NaN	NaN
259.499842	0.003847	38.472426	0.116886	1115.031738	0.000000	NaN	NaN
260.999928	0.003839	38.389898	0.117568	1115.713379	0.000000	NaN	NaN
262.500014	0.003847	38.472426	0.118372	1116.515381	0.000000	NaN	NaN
264.000100	0.003699	36.986920	0.119032	1117.174683	0.000000	NaN	NaN
265.500186	0.003723	37.234504	0.119722	1117.863525	0.000000	NaN	NaN
267.000271	0.003707	37.069448	0.120401	1118.541626	0.000000	NaN	NaN
268.499357	0.003905	39.050123	0.121181	1119.319946	0.000000	NaN	NaN
269.999443	0.003889	38.885066	0.121989	1120.126343	0.000000	NaN	NaN
271.499529	0.003839	38.389898	0.122540	1120.676514	0.000000	NaN	NaN
272.999615	0.003814	38.142313	0.123396	1121.531494	0.000000	NaN	NaN
274.499700	0.003798	37.977257	0.124137	1122.270874	0.000000	NaN	NaN
275.999786	0.003847	38.472426	0.124730	1122.863037	0.000000	NaN	NaN
277.499872	0.003922	39.215179	0.125584	1123.715942	0.000000	NaN	NaN
278.999958	0.003913	39.132651	0.126266	1124.396240	0.000000	NaN	NaN
280.500044	0.003839	38.389898	0.126960	1125.089722	0.000000	NaN	NaN
282.000130	0.003855	38.554954	0.127631	1125.759766	0.000000	NaN	NaN
283.500215	0.003930	39.297707	0.128380	1126.506714	0.000000	NaN	NaN
285.000301	0.003963	39.627819	0.128997	1127.122803	0.000000	NaN	NaN
286.499387	0.003847	38.472426	0.129742	1127.867187	0.000000	NaN	NaN
287.999473	0.003889	38.885066	0.130412	1128.535278	0.000000	NaN	NaN
289.499558	0.003880	38.802538	0.131169	1129.291138	0.000000	NaN	NaN
290.999644	0.003938	39.380235	0.131808	1129.929077	0.000000	NaN	NaN
292.499730	0.003889	38.885066	0.132471	1130.591675	0.000000	NaN	NaN
293.999816	0.003880	38.802538	0.133222	1131.340820	0.000000	NaN	NaN
295.499902	0.003831	38.307369	0.134016	1132.133545	0.000000	NaN	NaN
296.999987	0.003773	37.729673	0.134596	1132.712402	0.000000	NaN	NaN
298.500073	0.003864	38.637482	0.135359	1133.474487	0.000000	NaN	NaN
300.000159	0.003988	39.875404	0.136140	1134.254517	0.000000	NaN	NaN
301.500245	0.003971	39.710348	0.136661	1134.773926	0.000000	NaN	NaN
302.999330	0.003963	39.627819	0.137544	1135.656128	0.000000	NaN	NaN
304.499416	0.004045	40.453101	0.138171	1136.282227	0.000000	NaN	NaN
305.999502	0.004161	41.608494	0.138929	1137.038940	0.000000	NaN	NaN
307.499588	0.003963	39.627819	0.139607	1137.715454	0.000000	NaN	NaN
308.999674	0.003963	39.627819	0.140327	1138.434204	0.000000	NaN	NaN
310.499759	0.004062	40.618157	0.141051	1139.156860	0.000000	NaN	NaN
311.999845	0.004087	40.865741	0.141756	1139.860718	0.000000	NaN	NaN
313.499931	0.004078	40.783213	0.142457	1140.560303	0.000000	NaN	NaN
315.000017	0.004021	40.205516	0.143267	1141.369507	0.000000	NaN	NaN
316.500103	0.003988	39.875404	0.144002	1142.103271	0.000000	NaN	NaN
318.000188	0.004078	40.783213	0.144552	1142.651978	0.000000	NaN	NaN
319.500274	0.004045	40.453101	0.145294	1143.393066	0.000000	NaN	NaN
320.999360	0.004070	40.700685	0.146079	1144.176514	0.000000	NaN	NaN
322.499446	0.003988	39.875404	0.146758	1144.854736	0.000000	NaN	NaN
323.999532	0.004062	40.618157	0.147416	1145.511597	0.000000	NaN	NaN
325.499617	0.004103	41.030798	0.148058	1146.151978	0.000000	NaN	NaN
326.999703	0.004103	41.030798	0.148793	1146.885742	0.000000	NaN	NaN
328.499789	0.004194	41.938607	0.149529	1147.621216	0.000000	NaN	NaN
329.999875	0.004087	40.865741	0.150128	1148.219116	0.000000	NaN	NaN
331.499961	0.004078	40.783213	0.150841	1148.930542	0.000000	NaN	NaN
333.000046	0.004095	40.948269	0.151603	1149.691528	0.000000	NaN	NaN
334.500132	0.004062	40.618157	0.152267	1150.354492	0.000000	NaN	NaN
336.000218	0.004087	40.865741	0.152973	1151.058960	0.000000	NaN	NaN
337.499304	0.004037	40.370573	0.153679	1151.764282	0.000000	NaN	NaN
338.999390	0.003971	39.710348	0.154419	1152.502563	0.000000	NaN	NaN
340.499475	0.004120	41.195854	0.155088	1153.171143	0.000000	NaN	NaN
341.999561	0.004111	41.113326	0.155791	1153.872803	0.000000	NaN	NaN
343.499647	0.004095	40.948269	0.156492	1154.572266	0.000000	NaN	NaN
344.999733	0.004235	42.351247	0.157120	1155.199829	0.000000	NaN	NaN
346.499819	0.004144	41.443438	0.157884	1155.962524	0.000000	NaN	NaN
347.999904	0.004219	42.186191	0.158556	1156.632935	0.000000	NaN	NaN
349.499990	0.004128	41.278382	0.159137	1157.213013	0.000000	NaN	NaN
351.000076	0.004136	41.360910	0.159987	1158.061401	0.000000	NaN	NaN
352.500162	0.004169	41.691023	0.160670	1158.743286	0.000000	NaN	NaN
354.000248	0.004153	41.525966	0.161291	1159.363159	0.000000	NaN	NaN
355.499333	0.004136	41.360910	0.161992	1160.063354	0.000000	NaN	NaN
356.999419	0.004169	41.691023	0.162673	1160.743286	0.000000	NaN	NaN
358.499505	0.004268	42.681360	0.163436	1161.504761	0.000000	NaN	NaN
359.999591	0.004087	40.865741	0.164096	1162.163940	0.000000	NaN	NaN
361.499677	0.004111	41.113326	0.164808	1162.874756	0.000000	NaN	NaN
362.999762	0.004144	41.443438	0.165385	1163.450684	0.000000	NaN	NaN
364.499848	0.004260	42.598832	0.166144	1164.208374	0.000000	NaN	NaN
365.999934	0.004136	41.360910	0.166830	1164.893433	0.000000	NaN	NaN
367.500020	0.004219	42.186191	0.167492	1165.553711	0.000000	NaN	NaN
369.000106	0.004070	40.700685	0.168157	1166.217896	0.000000	NaN	NaN
370.500191	0.004227	42.268719	0.168800	1166.860474	0.000000	NaN	NaN
372.000277	0.004227	42.268719	0.169377	1167.435791	0.000000	NaN	NaN
373.499363	0.004202	42.021135	0.170097	1168.154297	0.000000	NaN	NaN
374.999449	0.004268	42.681360	0.170740	1168.796997	0.000000	NaN	NaN
376.499534	0.004260	42.598832	0.171472	1169.527100	0.000000	NaN	NaN
377.999620	0.004120	41.195854	0.172029	1170.083496	0.000000	NaN	NaN
379.499706	0.004177	41.773551	0.172802	1170.854980	0.000000	NaN	NaN
380.999792	0.004342	43.424113	0.173396	1171.448364	0.000000	NaN	NaN
382.499878	0.004260	42.598832	0.174166	1172.217285	0.000000	NaN	NaN
383.999963	0.004276	42.763888	0.174762	1172.811768	0.000000	NaN	NaN
385.500049	0.004276	42.763888	0.175475	1173.524292	0.000000	NaN	NaN
387.000135	0.004243	42.433776	0.176179	1174.226562	0.000000	NaN	NaN
388.500221	0.004318	43.176529	0.176858	1174.904419	0.000000	NaN	NaN
389.999307	0.004334	43.341585	0.177457	1175.502319	0.000000	NaN	NaN
391.499392	0.004334	43.341585	0.178074	1176.118774	0.000000	NaN	NaN
392.999478	0.004235	42.351247	0.178867	1176.910767	0.000000	NaN	NaN
394.499564	0.004351	43.506641	0.179490	1177.531860	0.000000	NaN	NaN
395.999650	0.004219	42.186191	0.180055	1178.096802	0.000000	NaN	NaN
397.499736	0.004334	43.341585	0.180721	1178.761597	0.000000	NaN	NaN
398.999821	0.004450	44.496979	0.181429	1179.467896	0.000000	NaN	NaN
400.499907	0.004293	42.928944	0.182027	1180.065186	0.000000	NaN	NaN
401.999993	0.004384	43.836754	0.182607	1180.643799	0.000000	NaN	NaN
403.500079	0.004276	42.763888	0.183300	1181.336060	0.000000	NaN	NaN
405.000165	0.004450	44.496979	0.183995	1182.029785	0.000000	NaN	NaN
406.500250	0.004367	43.671697	0.184652	1182.686035	0.000000	NaN	NaN
407.999336	0.004293	42.928944	0.185298	1183.330200	0.000000	NaN	NaN
409.499422	0.004318	43.176529	0.185926	1183.957275	0.000000	NaN	NaN
410.999508	0.004384	43.836754	0.186616	1184.645996	0.000000	NaN	NaN
412.499594	0.004367	43.671697	0.187234	1185.263062	0.000000	NaN	NaN
413.999679	0.004268	42.681360	0.187846	1185.874634	0.000000	NaN	NaN
415.499765	0.004285	42.846416	0.188597	1186.624390	0.000000	NaN	NaN
416.999851	0.004483	44.827091	0.189298	1187.323608	0.000000	NaN	NaN
418.499937	0.004293	42.928944	0.189853	1187.878052	0.000000	NaN	NaN
420.000023	0.004474	44.744563	0.190539	1188.562988	0.000000	NaN	NaN
421.500108	0.004441	44.414451	0.191215	1189.237793	0.000000	NaN	NaN
423.000194	0.004458	44.579507	0.191827	1189.849121	0.000000	NaN	NaN
424.500280	0.004408	44.084338	0.192413	1190.433594	0.000000	NaN	NaN
425.999366	0.004400	44.001810	0.193142	1191.161377	0.000000	NaN	NaN
427.499451	0.004392	43.919282	0.193924	1191.941895	0.000000	NaN	NaN
428.999537	0.004425	44.249394	0.194401	1192.418457	0.000000	NaN	NaN
430.499623	0.004417	44.166866	0.194961	1192.977539	0.000000	NaN	NaN
431.999709	0.004375	43.754226	0.195568	1193.583862	0.000000	NaN	NaN
433.499795	0.004318	43.176529	0.196367	1194.380981	0.000000	NaN	NaN
434.999881	0.004491	44.909619	0.197095	1195.108398	0.000000	NaN	NaN
436.499966	0.004507	45.074676	0.197666	1195.677979	0.000000	NaN	NaN
438.000052	0.004524	45.239732	0.198300	1196.311157	0.000000	NaN	NaN
439.500138	0.004483	44.827091	0.198834	1196.843872	0.000000	NaN	NaN
441.000224	0.004425	44.249394	0.199497	1197.506226	0.000000	NaN	NaN
442.499309	0.004540	45.404788	0.200219	1198.226318	0.000000	NaN	NaN
443.999395	0.004408	44.084338	0.200831	1198.838135	0.000000	NaN	NaN
445.499481	0.004623	46.230069	0.201362	1199.367676	0.000000	NaN	NaN
446.999567	0.004458	44.579507	0.201965	1199.970337	0.000000	NaN	NaN
448.499653	0.004573	45.734901	0.202632	1200.636108	0.000000	NaN	NaN
449.999738	0.004524	45.239732	0.203317	1201.319458	0.000000	NaN	NaN
451.499824	0.004375	43.754226	0.204025	1202.026611	0.000000	NaN	NaN
452.999910	0.004648	46.477654	0.204679	1202.679321	0.000000	NaN	NaN
454.499996	0.004285	42.846416	0.205255	1203.254761	0.000000	NaN	NaN
456.000082	0.004483	44.827091	0.205863	1203.861084	0.000000	NaN	NaN
457.500167	0.004483	44.827091	0.206735	1204.732544	0.000000	NaN	NaN
459.000253	0.004532	45.322260	0.207211	1205.206909	0.000000	NaN	NaN
460.499339	0.004524	45.239732	0.207924	1205.918701	0.000000	NaN	NaN
461.999425	0.004458	44.579507	0.208577	1206.571289	0.000000	NaN	NaN
463.499511	0.004565	45.652372	0.209204	1207.196655	0.000000	NaN	NaN
464.999596	0.004507	45.074676	0.210019	1208.010742	0.000000	NaN	NaN
466.499682	0.004557	45.569844	0.210642	1208.632568	0.000000	NaN	NaN
467.999768	0.004549	45.487316	0.211222	1209.211792	0.000000	NaN	NaN
469.499854	0.004640	46.395125	0.211884	1209.872559	0.000000	NaN	NaN
470.999940	0.004640	46.395125	0.212489	1210.475952	0.000000	NaN	NaN
472.500025	0.004631	46.312597	0.213176	1211.162842	0.000000	NaN	NaN
474.000111	0.004689	46.890294	0.213737	1211.722778	0.000000	NaN	NaN
475.500197	0.004499	44.992147	0.214463	1212.446655	0.000000	NaN	NaN
477.000283	0.004540	45.404788	0.215181	1213.163696	0.000000	NaN	NaN
478.499369	0.004706	47.055350	0.215823	1213.805298	0.000000	NaN	NaN
479.999454	0.004582	45.817429	0.216406	1214.386597	0.000000	NaN	NaN
481.499540	0.004722	47.220407	0.217122	1215.101318	0.000000	NaN	NaN
482.999626	0.004648	46.477654	0.217770	1215.748291	0.000000	NaN	NaN
484.499712	0.004697	46.972822	0.218152	1216.130493	0.000000	NaN	NaN
485.999798	0.004640	46.395125	0.218941	1216.918091	0.000000	NaN	NaN
487.499883	0.004631	46.312597	0.219690	1217.665649	0.000000	NaN	NaN
488.999969	0.004648	46.477654	0.220301	1218.275391	0.000000	NaN	NaN
490.500055	0.004689	46.890294	0.220814	1218.787231	0.000000	NaN	NaN
492.000141	0.004689	46.890294	0.221510	1219.482422	0.000000	NaN	NaN
493.500227	0.004664	46.642710	0.222206	1220.177368	0.000000	NaN	NaN
494.999312	0.004722	47.220407	0.222845	1220.815674	0.000000	NaN	NaN
496.499398	0.004598	45.982485	0.223463	1221.432617	0.000000	NaN	NaN
497.999484	0.004796	47.963160	0.224111	1222.078735	0.000000	NaN	NaN
499.499570	0.004747	47.467991	0.224703	1222.670288	0.000000	NaN	NaN
500.999656	0.004648	46.477654	0.225499	1223.464355	0.000000	NaN	NaN
502.499741	0.004673	46.725238	0.226054	1224.019409	0.000000	NaN	NaN
503.999827	0.004640	46.395125	0.226833	1224.796997	0.000000	NaN	NaN
505.499913	0.004739	47.385463	0.227289	1225.251709	0.000000	NaN	NaN
506.999999	0.004722	47.220407	0.228080	1226.041992	0.000000	NaN	NaN
508.500084	0.004590	45.899957	0.228685	1226.645752	0.000000	NaN	NaN
510.000170	0.004664	46.642710	0.229353	1227.312622	0.000000	NaN	NaN
511.500256	0.004681	46.807766	0.229923	1227.881836	0.000000	NaN	NaN
512.999342	0.004747	47.467991	0.230569	1228.526733	0.000000	NaN	NaN
514.499428	0.004714	47.137879	0.231214	1229.170166	0.000000	NaN	NaN
515.999514	0.004829	48.293272	0.231822	1229.777100	0.000000	NaN	NaN
517.499599	0.004747	47.467991	0.232414	1230.368408	0.000000	NaN	NaN
518.999685	0.004697	46.972822	0.233048	1231.001465	0.000000	NaN	NaN
520.499771	0.004730	47.302935	0.233739	1231.690674	0.000000	NaN	NaN
521.999857	0.004763	47.633047	0.234305	1232.256348	0.000000	NaN	NaN
523.499942	0.004796	47.963160	0.235062	1233.012085	0.000000	NaN	NaN
525.000028	0.004664	46.642710	0.235678	1233.627441	0.000000	NaN	NaN
526.500114	0.004796	47.963160	0.236341	1234.289307	0.000000	NaN	NaN
528.000200	0.004755	47.550519	0.237008	1234.954834	0.000000	NaN	NaN
529.500286	0.004788	47.880632	0.237745	1235.690186	0.000000	NaN	NaN
530.999371	0.004763	47.633047	0.238253	1236.197632	0.000000	NaN	NaN
532.499457	0.004970	49.696250	0.238989	1236.932983	0.000000	NaN	NaN
533.999543	0.004796	47.963160	0.239540	1237.482178	0.000000	NaN	NaN
535.499629	0.004755	47.550519	0.240279	1238.220215	0.000000	NaN	NaN
536.999715	0.004747	47.467991	0.240876	1238.816162	0.000000	NaN	NaN
538.499800	0.004780	47.798104	0.241452	1239.391357	0.000000	NaN	NaN
539.999886	0.004763	47.633047	0.242175	1240.112671	0.000000	NaN	NaN
541.499972	0.004813	48.128216	0.242907	1240.843750	0.000000	NaN	NaN
543.000058	0.004945	49.448666	0.243364	1241.299805	0.000000	NaN	NaN
544.500144	0.004904	49.036025	0.243953	1241.888184	0.000000	NaN	NaN
546.000229	0.004796	47.963160	0.244769	1242.702393	0.000000	NaN	NaN
547.499315	0.004854	48.540857	0.245277	1243.210205	0.000000	NaN	NaN
548.999401	0.004697	46.972822	0.246038	1243.969849	0.000000	NaN	NaN
550.499487	0.004862	48.623385	0.246565	1244.495728	0.000000	NaN	NaN
551.999572	0.004862	48.623385	0.247110	1245.039673	0.000000	NaN	NaN
553.499658	0.004945	49.448666	0.247925	1245.853394	0.000000	NaN	NaN
554.999744	0.004788	47.880632	0.248558	1246.485107	0.000000	NaN	NaN
556.499830	0.004755	47.550519	0.249118	1247.044312	0.000000	NaN	NaN
557.999916	0.004747	47.467991	0.249682	1247.607666	0.000000	NaN	NaN
559.500001	0.004862	48.623385	0.250428	1248.352051	0.000000	NaN	NaN
561.000087	0.004928	49.283610	0.251115	1249.038574	0.000000	NaN	NaN
562.500173	0.004862	48.623385	0.251628	1249.550293	0.000000	NaN	NaN
564.000259	0.004945	49.448666	0.252513	1250.434204	0.000000	NaN	NaN
565.499345	0.004813	48.128216	0.252897	1250.817749	0.000000	NaN	NaN
566.999431	0.004945	49.448666	0.253555	1251.474487	0.000000	NaN	NaN
568.499516	0.004854	48.540857	0.254177	1252.095703	0.000000	NaN	NaN
569.999602	0.004813	48.128216	0.254960	1252.876709	0.000000	NaN	NaN
571.499688	0.004920	49.201082	0.255552	1253.468140	0.000000	NaN	NaN
572.999774	0.004945	49.448666	0.256138	1254.052979	0.000000	NaN	NaN
574.499859	0.004871	48.705913	0.256944	1254.857910	0.000000	NaN	NaN
575.999945	0.005060	50.604060	0.257540	1255.452271	0.000000	NaN	NaN
577.500031	0.005003	50.026363	0.258094	1256.005859	0.000000	NaN	NaN
579.000117	0.004970	49.696250	0.258721	1256.631958	0.000000	NaN	NaN
580.500203	0.004879	48.788441	0.259607	1257.516479	0.000000	NaN	NaN
582.000289	0.004879	48.788441	0.260119	1258.027344	0.000000	NaN	NaN
583.499374	0.005019	50.191419	0.260715	1258.622681	0.000000	NaN	NaN
584.999460	0.004928	49.283610	0.261378	1259.284058	0.000000	NaN	NaN
586.499546	0.004970	49.696250	0.262028	1259.933716	0.000000	NaN	NaN
587.999632	0.004879	48.788441	0.262629	1260.533203	0.000000	NaN	NaN
589.499717	0.004970	49.696250	0.263355	1261.258545	0.000000	NaN	NaN
590.999803	0.004920	49.201082	0.263941	1261.842651	0.000000	NaN	NaN
592.499889	0.004887	48.870969	0.264544	1262.445557	0.000000	NaN	NaN
593.999975	0.004928	49.283610	0.265179	1263.078857	0.000000	NaN	NaN
595.500061	0.004928	49.283610	0.265891	1263.789673	0.000000	NaN	NaN
597.000146	0.004986	49.861307	0.266453	1264.350952	0.000000	NaN	NaN
598.500232	0.004920	49.201082	0.267056	1264.953369	0.000000	NaN	NaN
599.999318	0.004920	49.201082	0.267707	1265.602783	0.000000	NaN	NaN
601.499404	0.004961	49.613722	0.268326	1266.220703	0.000000	NaN	NaN
602.999490	0.004994	49.943835	0.268970	1266.863403	0.000000	NaN	NaN
604.499575	0.004920	49.201082	0.269562	1267.454834	0.000000	NaN	NaN
605.999661	0.004912	49.118554	0.270267	1268.158447	0.000000	NaN	NaN
607.499747	0.004937	49.366138	0.271006	1268.896118	0.000000	NaN	NaN
608.999833	0.005093	50.934172	0.271533	1269.422485	0.000000	NaN	NaN
610.499919	0.004945	49.448666	0.272347	1270.235107	0.000000	NaN	NaN
612.000004	0.004994	49.943835	0.272943	1270.829956	0.000000	NaN	NaN
613.500090	0.004953	49.531194	0.273665	1271.550659	0.000000	NaN	NaN
615.000176	0.004920	49.201082	0.274188	1272.073486	0.000000	NaN	NaN
616.500262	0.005093	50.934172	0.274859	1272.743408	0.000000	NaN	NaN
617.999347	0.004945	49.448666	0.275536	1273.418701	0.000000	NaN	NaN
619.499433	0.005003	50.026363	0.276067	1273.948730	0.000000	NaN	NaN
620.999519	0.005052	50.521532	0.276714	1274.595093	0.000000	NaN	NaN
622.499605	0.005003	50.026363	0.277541	1275.420532	0.000000	NaN	NaN
623.999691	0.004953	49.531194	0.278173	1276.051147	0.000000	NaN	NaN
625.499776	0.004937	49.366138	0.278723	1276.600220	0.000000	NaN	NaN
626.999862	0.005143	51.429341	0.279321	1277.197388	0.000000	NaN	NaN
628.499948	0.005044	50.439003	0.279920	1277.795776	0.000000	NaN	NaN
630.000034	0.005275	52.749791	0.280655	1278.529663	0.000000	NaN	NaN
631.500120	0.004829	48.293272	0.281180	1279.053833	0.000000	NaN	NaN
633.000205	0.004961	49.613722	0.281873	1279.745728	0.000000	NaN	NaN
634.500291	0.004887	48.870969	0.282482	1280.352783	0.000000	NaN	NaN
635.999377	0.005151	51.511869	0.283181	1281.051147	0.000000	NaN	NaN
637.499463	0.005019	50.191419	0.283912	1281.781250	0.000000	NaN	NaN
638.999549	0.004986	49.861307	0.284496	1282.363647	0.000000	NaN	NaN
640.499634	0.005019	50.191419	0.285136	1283.003296	0.000000	NaN	NaN
641.999720	0.004937	49.366138	0.285724	1283.590210	0.000000	NaN	NaN
643.499806	0.005019	50.191419	0.286390	1284.254883	0.000000	NaN	NaN
644.999892	0.005052	50.521532	0.287035	1284.898193	0.000000	NaN	NaN
646.499978	0.005126	51.264285	0.287587	1285.450073	0.000000	NaN	NaN
648.000064	0.005077	50.769116	0.288353	1286.214355	0.000000	NaN	NaN
649.500149	0.005143	51.429341	0.288859	1286.719238	0.000000	NaN	NaN
651.000235	0.005102	51.016700	0.289731	1287.590576	0.000000	NaN	NaN
652.499321	0.005184	51.841982	0.290295	1288.153076	0.000000	NaN	NaN
653.999407	0.005110	51.099228	0.290977	1288.833862	0.000000	NaN	NaN
655.499492	0.005225	52.254622	0.291554	1289.410400	0.000000	NaN	NaN
656.999578	0.005069	50.686588	0.292355	1290.210083	0.000000	NaN	NaN
658.499664	0.005118	51.181757	0.292968	1290.821533	0.000000	NaN	NaN
659.999750	0.005250	52.502206	0.293435	1291.288208	0.000000	NaN	NaN
661.499836	0.005209	52.089566	0.294187	1292.038818	0.000000	NaN	NaN
662.999921	0.005201	52.007038	0.294915	1292.765747	0.000000	NaN	NaN
664.500007	0.005126	51.264285	0.295623	1293.472046	0.000000	NaN	NaN
666.000093	0.005011	50.108891	0.296191	1294.039551	0.000000	NaN	NaN
667.500179	0.004994	49.943835	0.296788	1294.635132	0.000000	NaN	NaN
669.000265	0.005003	50.026363	0.297642	1295.488159	0.000000	NaN	NaN
670.499350	0.005135	51.346813	0.298189	1296.034546	0.000000	NaN	NaN
671.999436	0.005019	50.191419	0.298860	1296.703735	0.000000	NaN	NaN
673.499522	0.005135	51.346813	0.299508	1297.350708	0.000000	NaN	NaN
674.999608	0.005052	50.521532	0.300189	1298.030518	0.000000	NaN	NaN
676.499693	0.005143	51.429341	0.300712	1298.553467	0.000000	NaN	NaN
677.999779	0.005151	51.511869	0.301632	1299.471558	0.000000	NaN	NaN
679.499865	0.005060	50.604060	0.302172	1300.010376	0.000000	NaN	NaN
680.999951	0.005234	52.337150	0.302906	1300.743042	0.000000	NaN	NaN
682.500037	0.005201	52.007038	0.303376	1301.212158	0.000000	NaN	NaN
684.000122	0.005044	50.439003	0.304182	1302.017334	0.000000	NaN	NaN
685.500208	0.005036	50.356475	0.304713	1302.546875	0.000000	NaN	NaN
687.000294	0.005184	51.841982	0.305272	1303.105957	0.000000	NaN	NaN
688.499380	0.005184	51.841982	0.306107	1303.938599	0.000000	NaN	NaN
689.999466	0.005135	51.346813	0.306808	1304.639404	0.000000	NaN	NaN
691.499551	0.005027	50.273947	0.307551	1305.380737	0.000000	NaN	NaN
692.999637	0.005225	52.254622	0.308097	1305.926025	0.000000	NaN	NaN
694.499723	0.005258	52.584735	0.308823	1306.650879	0.000000	NaN	NaN
695.999809	0.005102	51.016700	0.309451	1307.277344	0.000000	NaN	NaN
697.499895	0.005192	51.924510	0.310153	1307.978149	0.000000	NaN	NaN
698.999980	0.005225	52.254622	0.310804	1308.628052	0.000000	NaN	NaN
700.500066	0.005242	52.419678	0.311338	1309.161255	0.000000	NaN	NaN
702.000152	0.005201	52.007038	0.312048	1309.870605	0.000000	NaN	NaN
703.500238	0.005176	51.759453	0.312925	1310.745850	0.000000	NaN	NaN
704.999324	0.005316	53.162431	0.313516	1311.335815	0.000000	NaN	NaN
706.499409	0.005209	52.089566	0.314095	1311.914185	0.000000	NaN	NaN
707.999495	0.005258	52.584735	0.314789	1312.606445	0.000000	NaN	NaN
709.499581	0.005184	51.841982	0.315576	1313.392090	0.000000	NaN	NaN
710.999667	0.005291	52.914847	0.316262	1314.077148	0.000000	NaN	NaN
712.499753	0.005217	52.172094	0.317006	1314.819702	0.000000	NaN	NaN
713.999838	0.005168	51.676925	0.317668	1315.480957	0.000000	NaN	NaN
715.499924	0.005267	52.667263	0.318252	1316.064209	0.000000	NaN	NaN
717.000010	0.005168	51.676925	0.319023	1316.833374	0.000000	NaN	NaN
718.500096	0.005291	52.914847	0.319686	1317.495239	0.000000	NaN	NaN
720.000182	0.005184	51.841982	0.320424	1318.232544	0.000000	NaN	NaN
721.500267	0.005341	53.410016	0.321160	1318.967407	0.000000	NaN	NaN
722.999353	0.005225	52.254622	0.321560	1319.366699	0.000000	NaN	NaN
724.499439	0.005275	52.749791	0.322352	1320.156616	0.000000	NaN	NaN
725.999525	0.005424	54.235297	0.323023	1320.826782	0.000000	NaN	NaN
727.499611	0.005225	52.254622	0.323758	1321.560913	0.000000	NaN	NaN
728.999696	0.005242	52.419678	0.324469	1322.270264	0.000000	NaN	NaN
730.499782	0.005291	52.914847	0.325105	1322.905518	0.000000	NaN	NaN
731.999868	0.005308	53.079903	0.325863	1323.662109	0.000000	NaN	NaN
733.499954	0.005242	52.419678	0.326710	1324.508057	0.000000	NaN	NaN
735.000040	0.005382	53.822656	0.327253	1325.049561	0.000000	NaN	NaN
736.500125	0.005324	53.244960	0.328089	1325.885010	0.000000	NaN	NaN
738.000211	0.005267	52.667263	0.328697	1326.491943	0.000000	NaN	NaN
739.500297	0.005267	52.667263	0.329513	1327.306274	0.000000	NaN	NaN
740.999383	0.005291	52.914847	0.330037	1327.828857	0.000000	NaN	NaN
742.499468	0.005341	53.410016	0.331027	1328.817261	0.000000	NaN	NaN
743.999554	0.005085	50.851644	0.331420	1329.210449	0.000000	NaN	NaN
745.499640	0.005316	53.162431	0.332134	1329.923096	0.000000	NaN	NaN
746.999726	0.005176	51.759453	0.332740	1330.527710	0.000000	NaN	NaN
748.499812	0.005176	51.759453	0.333561	1331.347778	0.000000	NaN	NaN
749.999897	0.005234	52.337150	0.334268	1332.053589	0.000000	NaN	NaN
751.499983	0.005300	52.997375	0.335180	1332.963501	0.000000	NaN	NaN
753.000069	0.005225	52.254622	0.335741	1333.523560	0.000000	NaN	NaN
754.500155	0.005308	53.079903	0.336331	1334.112427	0.000000	NaN	NaN
756.000241	0.005382	53.822656	0.337048	1334.828613	0.000000	NaN	NaN
757.499326	0.005258	52.584735	0.337768	1335.547363	0.000000	NaN	NaN
758.999412	0.005209	52.089566	0.338336	1336.114136	0.000000	NaN	NaN
760.499498	0.005217	52.172094	0.339021	1336.798096	0.000000	NaN	NaN
761.999584	0.005250	52.502206	0.339562	1337.338257	0.000000	NaN	NaN
763.499670	0.005168	51.676925	0.340142	1337.917725	0.000000	NaN	NaN
764.999755	0.005291	52.914847	0.340912	1338.686523	0.000000	NaN	NaN
766.499841	0.005308	53.079903	0.341671	1339.443726	0.000000	NaN	NaN
767.999927	0.005291	52.914847	0.342396	1340.167358	0.000000	NaN	NaN
769.500013	0.005407	54.070241	0.342958	1340.728638	0.000000	NaN	NaN
771.000099	0.005349	53.492544	0.343634	1341.403442	0.000000	NaN	NaN
772.500184	0.005275	52.749791	0.344432	1342.200806	0.000000	NaN	NaN
774.000270	0.005234	52.337150	0.345032	1342.799805	0.000000	NaN	NaN
775.499356	0.005209	52.089566	0.345539	1343.306030	0.000000	NaN	NaN
776.999442	0.005102	51.016700	0.346426	1344.191406	0.000000	NaN	NaN
778.499528	0.005250	52.502206	0.346966	1344.729736	0.000000	NaN	NaN
779.999613	0.005176	51.759453	0.347834	1345.597046	0.000000	NaN	NaN
781.499699	0.005192	51.924510	0.348444	1346.206299	0.000000	NaN	NaN
782.999785	0.005217	52.172094	0.349084	1346.844971	0.000000	NaN	NaN
784.499871	0.005349	53.492544	0.349705	1347.464233	0.000000	NaN	NaN
785.999957	0.005258	52.584735	0.350279	1348.037598	0.000000	NaN	NaN
787.500042	0.005052	50.521532	0.350940	1348.697876	0.000000	NaN	NaN
789.000128	0.005176	51.759453	0.351696	1349.452637	0.000000	NaN	NaN
790.500214	0.005077	50.769116	0.352504	1350.259521	0.000000	NaN	NaN
792.000300	0.005250	52.502206	0.352832	1350.586792	0.000000	NaN	NaN
793.499385	0.005110	51.099228	0.353498	1351.250977	0.000000	NaN	NaN
794.999471	0.005151	51.511869	0.354328	1352.079590	0.000000	NaN	NaN
796.499557	0.005135	51.346813	0.354787	1352.538452	0.000000	NaN	NaN
797.999643	0.005143	51.429341	0.355394	1353.144775	0.000000	NaN	NaN
799.499729	0.005126	51.264285	0.356231	1353.979614	0.000000	NaN	NaN
800.999814	0.005135	51.346813	0.356773	1354.520630	0.000000	NaN	NaN
802.499900	0.005102	51.016700	0.357139	1354.886841	0.000000	NaN	NaN
803.999986	0.005102	51.016700	0.358076	1355.821899	0.000000	NaN	NaN
805.500072	0.005036	50.356475	0.358840	1356.584839	0.000000	NaN	NaN
807.000158	0.005019	50.191419	0.359267	1357.010986	0.000000	NaN	NaN
808.500243	0.004978	49.778778	0.359982	1357.724121	0.000000	NaN	NaN
809.999329	0.004994	49.943835	0.360684	1358.425415	0.000000	NaN	NaN
811.499415	0.005036	50.356475	0.361091	1358.831787	0.000000	NaN	NaN
812.999501	0.005019	50.191419	0.361621	1359.360596	0.000000	NaN	NaN
814.499587	0.004978	49.778778	0.362573	1360.311035	0.000000	NaN	NaN
815.999672	0.005143	51.429341	0.362961	1360.698364	0.000000	NaN	NaN
817.499758	0.004805	48.045688	0.363596	1361.332520	0.000000	NaN	NaN
818.999844	0.004895	48.953497	0.364097	1361.833252	0.000000	NaN	NaN
820.499930	0.004829	48.293272	0.364584	1362.318604	0.000000	NaN	NaN
822.000016	0.004879	48.788441	0.365153	1362.886597	0.000000	NaN	NaN
823.500101	0.004895	48.953497	0.365702	1363.435547	0.000000	NaN	NaN
825.000187	0.004829	48.293272	0.366246	1363.978149	0.000000	NaN	NaN
826.500273	0.004640	46.395125	0.366616	1364.347290	0.000000	NaN	NaN
827.999359	0.004730	47.302935	0.367059	1364.790283	0.000000	NaN	NaN
829.499445	0.004598	45.982485	0.367455	1365.185425	0.000000	NaN	NaN
830.999530	0.004631	46.312597	0.368106	1365.835083	0.000000	NaN	NaN
832.499616	0.004615	46.147541	0.368073	1365.802368	0.000000	NaN	NaN
833.999702	0.004458	44.579507	0.368659	1366.386719	0.000000	NaN	NaN
835.499788	0.004433	44.331922	0.369155	1366.882446	0.000000	NaN	NaN
836.999874	0.004285	42.846416	0.369514	1367.240845	0.000000	NaN	NaN
838.499959	0.004549	45.487316	0.370102	1367.827515	0.000000	NaN	NaN
840.000045	0.004392	43.919282	0.370137	1367.862915	0.000000	NaN	NaN
841.500131	0.004243	42.433776	0.370653	1368.378052	0.000000	NaN	NaN
843.000217	0.004153	41.525966	0.370906	1368.630005	0.000000	NaN	NaN
844.499303	0.004037	40.370573	0.371219	1368.942627	0.000000	NaN	NaN
845.999388	0.004012	40.122988	0.371199	1368.923340	0.000000	NaN	NaN
847.499474	0.003988	39.875404	0.371557	1369.280518	0.000000	NaN	NaN
848.999560	0.003864	38.637482	0.371926	1369.648560	0.000000	NaN	NaN
850.499646	0.003839	38.389898	0.371768	1369.491455	0.000000	NaN	NaN
851.999732	0.003657	36.574279	0.372018	1369.740112	0.000000	NaN	NaN
853.499817	0.003732	37.317032	0.372113	1369.835327	0.000000	NaN	NaN
854.999903	0.003435	34.346020	0.372359	1370.081299	0.000000	NaN	NaN
856.499989	0.003501	35.006245	0.372335	1370.057129	0.000000	NaN	NaN
858.000075	0.003294	32.943041	0.372555	1370.277100	0.000000	NaN	NaN
859.500161	0.003096	30.962367	0.372534	1370.255981	0.000000	NaN	NaN
861.000246	0.003171	31.705120	0.372510	1370.232056	0.000000	NaN	NaN
862.499332	0.003047	30.467198	0.372555	1370.276978	0.000000	NaN	NaN
863.999418	0.002981	29.806973	0.372582	1370.303711	0.000000	NaN	NaN
865.499504	0.002923	29.229276	0.372318	1370.039795	0.000000	NaN	NaN
866.999589	0.002675	26.753432	0.372454	1370.176270	0.000000	NaN	NaN
868.499675	0.002725	27.248601	0.372492	1370.213867	0.000000	NaN	NaN
869.999761	0.002486	24.855285	0.372445	1370.166748	0.000000	NaN	NaN
871.499847	0.002386	23.864948	0.372785	1370.506104	0.000000	NaN	NaN
872.999933	0.002180	21.801745	0.373255	1370.975220	0.000000	NaN	NaN
874.500018	0.001966	19.656014	0.374240	1371.959351	0.000000	NaN	NaN
876.000104	0.001545	15.447079	0.376063	1373.779419	0.000000	NaN	NaN
877.500190	-0.000238	-2.378996	0.400298	1397.973755	0.000000	NaN	NaN
879.000276	-0.000254	-2.544052	0.409161	1406.821777	0.000000	NaN	NaN
880.499362	-0.000131	-1.306131	0.413397	1411.050537	0.000000	NaN	NaN