File: data/115k_1-3_3 (190321).lvm
LabVIEW Measurement
Writer_Version	2
Reader_Version	2
Separator	Tab
Decimal_Separator	.
Multi_Headings	No
X_Columns	One
Time_Pref	Absolute
Operator	user
Description	Load(N)/Stress(MPa)/Distance A(pixel)/Strain A/Distance B(pixel)/Strain B/Poisson's ratio
Date	2019/03/21
Time	12:58:35.3148044300349900275
***End_of_Header***

Notes	X 값은 오직 다음과 같을 때에만 유효함이 보장됩니다. Dev1/ai0
Channels	7
Samples	1	1	1	1	1	1	1
Date	2019/03/21	2019/03/21	2019/03/21	2019/03/21	2019/03/21	2019/03/21	2019/03/21
Time	14:13:48.3149332300349899608	14:13:48.3149332300349899608	14:13:48.3149333000183105469	14:13:48.3149333000183105469	14:13:48.3149333000183105469	14:13:48.3149333000183105469	14:13:48.3149333000183105469
Y_Unit_Label	Volts	Volts
X_Dimension	Time	Time	Time	Time	Time	Time	Time
X0	0.0000000000000000E+0	0.0000000000000000E+0	0.0000000000000000E+0	0.0000000000000000E+0	0.0000000000000000E+0	0.0000000000000000E+0	0.0000000000000000E+0
Delta_X	0.000000	0.000000	1.000000	1.000000	1.000000	1.000000	1.000000
***End_of_Header***
X_Value	Dev1/ai0	Dev1/ai0 1	Untitled	Untitled 1	Untitled 2	Untitled 3	Untitled 4	Comment
0.000000	-8.934899E-5	-0.893490	3.528595E-5	984.030579	0.000000	NaN	NaN
1.499086	7.570726E-5	0.757073	6.675720E-6	984.002502	0.000000	NaN	NaN
2.999172	-1.507368E-5	-0.150737	-4.845858E-5	983.948242	0.000000	NaN	NaN
4.499257	0.000216	2.160051	0.000341	984.331360	0.000000	NaN	NaN
5.999343	0.000133	1.334770	0.000796	984.779175	0.000000	NaN	NaN
7.499429	0.000166	1.664882	0.001214	985.190430	0.000000	NaN	NaN
8.999515	0.000315	3.150388	0.001481	985.453125	0.000000	NaN	NaN
10.499600	0.000348	3.480501	0.001775	985.742859	0.000000	NaN	NaN
11.999686	0.000513	5.131063	0.002066	986.028748	0.000000	NaN	NaN
13.499772	0.000521	5.213591	0.002270	986.229980	0.000000	NaN	NaN
14.999858	0.000521	5.213591	0.002535	986.489990	0.000000	NaN	NaN
16.499944	0.000645	6.451513	0.002798	986.748840	0.000000	NaN	NaN
18.001030	0.000620	6.203929	0.002926	986.875427	0.000000	NaN	NaN
19.499115	0.000785	7.854492	0.003207	987.151245	0.000000	NaN	NaN
20.999201	0.000719	7.194267	0.003517	987.457031	0.000000	NaN	NaN
22.499287	0.000860	8.597245	0.003793	987.728699	0.000000	NaN	NaN
23.999373	0.000868	8.679773	0.004001	987.932800	0.000000	NaN	NaN
25.499458	0.000901	9.009885	0.004313	988.239685	0.000000	NaN	NaN
26.999544	0.001124	11.238145	0.004568	988.490784	0.000000	NaN	NaN
28.499630	0.001116	11.155617	0.004875	988.792480	0.000000	NaN	NaN
29.999716	0.001173	11.733313	0.005290	989.200867	0.000000	NaN	NaN
31.499802	0.001264	12.641123	0.005592	989.498352	0.000000	NaN	NaN
32.999887	0.001363	13.631460	0.005951	989.851990	0.000000	NaN	NaN
34.499973	0.001421	14.209157	0.006377	990.271362	0.000000	NaN	NaN
35.999059	0.001503	15.034438	0.006799	990.686340	0.000000	NaN	NaN
37.499145	0.001751	17.510282	0.007210	991.090698	0.000000	NaN	NaN
38.999231	0.001693	16.932585	0.007603	991.476868	0.000000	NaN	NaN
40.499316	0.001751	17.510282	0.008028	991.895020	0.000000	NaN	NaN
41.999402	0.001784	17.840395	0.008575	992.433899	0.000000	NaN	NaN
43.499488	0.002098	20.976463	0.009151	993.000793	0.000000	NaN	NaN
44.999574	0.001949	19.490957	0.009617	993.459290	0.000000	NaN	NaN
46.499660	0.002106	21.058992	0.009980	993.816589	0.000000	NaN	NaN
47.999745	0.002139	21.389104	0.010426	994.255371	0.000000	NaN	NaN
49.499831	0.002197	21.966801	0.010857	994.679382	0.000000	NaN	NaN
50.999917	0.002279	22.792082	0.011347	995.161255	0.000000	NaN	NaN
52.500003	0.002420	24.195060	0.011722	995.530273	0.000000	NaN	NaN
53.999089	0.002378	23.782420	0.012083	995.885071	0.000000	NaN	NaN
55.499174	0.002560	25.598038	0.012459	996.255737	0.000000	NaN	NaN
56.999260	0.002651	26.505848	0.012798	996.588806	0.000000	NaN	NaN
58.499346	0.002601	26.010679	0.013245	997.029419	0.000000	NaN	NaN
59.999432	0.002708	27.083545	0.013643	997.420410	0.000000	NaN	NaN
61.499518	0.002783	27.826298	0.013688	997.464600	0.000000	NaN	NaN
62.999603	0.002807	28.073882	0.014264	998.031677	0.000000	NaN	NaN
64.499689	0.002807	28.073882	0.015425	999.173950	0.000000	NaN	NaN
65.999775	0.002915	29.146748	0.015652	999.397644	0.000000	NaN	NaN
67.499861	0.002981	29.806973	0.016300	1000.034912	0.000000	NaN	NaN
69.001947	0.003055	30.549726	0.016889	1000.614990	0.000000	NaN	NaN
70.500032	0.003022	30.219613	0.017483	1001.199463	0.000000	NaN	NaN
71.999118	0.003129	31.292479	0.018107	1001.813049	0.000000	NaN	NaN
73.499204	0.003171	31.705120	0.018655	1002.352539	0.000000	NaN	NaN
74.999290	0.003154	31.540063	0.019325	1003.012146	0.000000	NaN	NaN
76.499375	0.003204	32.035232	0.020015	1003.690063	0.000000	NaN	NaN
77.999461	0.003220	32.200288	0.020676	1004.341187	0.000000	NaN	NaN
79.499547	0.003270	32.695457	0.021382	1005.035828	0.000000	NaN	NaN
80.999633	0.003286	32.860513	0.022113	1005.755066	0.000000	NaN	NaN
82.499719	0.003237	32.365345	0.022767	1006.398621	0.000000	NaN	NaN
84.000805	0.003385	33.850851	0.023529	1007.148621	0.000000	NaN	NaN
85.499890	0.003369	33.685795	0.024128	1007.737610	0.000000	NaN	NaN
86.999976	0.003327	33.273154	0.024876	1008.473816	0.000000	NaN	NaN
88.499062	0.003369	33.685795	0.025611	1009.196716	0.000000	NaN	NaN
89.999148	0.003344	33.438210	0.026213	1009.789673	0.000000	NaN	NaN
91.499233	0.003426	34.263491	0.026955	1010.519714	0.000000	NaN	NaN
92.999319	0.003492	34.923716	0.027692	1011.245056	0.000000	NaN	NaN
94.499405	0.003534	35.336357	0.028466	1012.005859	0.000000	NaN	NaN
95.999491	0.003360	33.603266	0.029307	1012.834351	0.000000	NaN	NaN
97.499577	0.003435	34.346020	0.029939	1013.456177	0.000000	NaN	NaN
99.000663	0.003501	35.006245	0.030649	1014.154236	0.000000	NaN	NaN
100.499748	0.003369	33.685795	0.031401	1014.894287	0.000000	NaN	NaN
101.999834	0.003525	35.253829	0.032101	1015.582764	0.000000	NaN	NaN
103.499920	0.003509	35.088773	0.032880	1016.349792	0.000000	NaN	NaN
105.000006	0.003674	36.739335	0.033595	1017.053650	0.000000	NaN	NaN
106.499091	0.003600	35.996582	0.034329	1017.775818	0.000000	NaN	NaN
107.999177	0.003509	35.088773	0.035029	1018.464233	0.000000	NaN	NaN
109.499263	0.003525	35.253829	0.035750	1019.174194	0.000000	NaN	NaN
110.999349	0.003657	36.574279	0.036564	1019.974854	0.000000	NaN	NaN
112.499435	0.003641	36.409223	0.037408	1020.805359	0.000000	NaN	NaN
113.999520	0.003674	36.739335	0.038159	1021.543701	0.000000	NaN	NaN
115.499606	0.003600	35.996582	0.038899	1022.272156	0.000000	NaN	NaN
116.999692	0.003657	36.574279	0.039590	1022.952576	0.000000	NaN	NaN
118.499778	0.003558	35.583941	0.040397	1023.746338	0.000000	NaN	NaN
119.999864	0.003666	36.656807	0.041131	1024.468384	0.000000	NaN	NaN
121.499949	0.003600	35.996582	0.042029	1025.351807	0.000000	NaN	NaN
123.000035	0.003649	36.491751	0.042647	1025.960571	0.000000	NaN	NaN
124.499121	0.003707	37.069448	0.043385	1026.686401	0.000000	NaN	NaN
125.999207	0.003748	37.482088	0.044129	1027.418945	0.000000	NaN	NaN
127.499292	0.003633	36.326695	0.044923	1028.199829	0.000000	NaN	NaN
128.999378	0.003591	35.914054	0.045721	1028.985229	0.000000	NaN	NaN
130.499464	0.003715	37.151976	0.046482	1029.733643	0.000000	NaN	NaN
132.000550	0.003798	37.977257	0.047323	1030.561401	0.000000	NaN	NaN
133.499636	0.003641	36.409223	0.048116	1031.341919	0.000000	NaN	NaN
134.999721	0.003732	37.317032	0.048856	1032.070435	0.000000	NaN	NaN
136.499807	0.003682	36.821863	0.049645	1032.845947	0.000000	NaN	NaN
137.999893	0.003798	37.977257	0.050423	1033.612305	0.000000	NaN	NaN
139.499979	0.003732	37.317032	0.051272	1034.447510	0.000000	NaN	NaN
140.999065	0.003707	37.069448	0.052037	1035.200562	0.000000	NaN	NaN
142.499150	0.003748	37.482088	0.052820	1035.970703	0.000000	NaN	NaN
143.999236	0.003756	37.564616	0.053591	1036.729248	0.000000	NaN	NaN
145.499322	0.003781	37.812201	0.054422	1037.547241	0.000000	NaN	NaN
146.999408	0.003781	37.812201	0.055303	1038.413940	0.000000	NaN	NaN
148.499494	0.003690	36.904391	0.055966	1039.066284	0.000000	NaN	NaN
149.999580	0.003814	38.142313	0.056762	1039.849121	0.000000	NaN	NaN
151.499665	0.003781	37.812201	0.057567	1040.641724	0.000000	NaN	NaN
152.999751	0.003723	37.234504	0.058392	1041.453857	0.000000	NaN	NaN
154.499837	0.003682	36.821863	0.059247	1042.294312	0.000000	NaN	NaN
155.999923	0.003847	38.472426	0.060008	1043.043701	0.000000	NaN	NaN
157.500008	0.003723	37.234504	0.060749	1043.772827	0.000000	NaN	NaN
158.999094	0.003822	38.224841	0.061534	1044.545044	0.000000	NaN	NaN
160.499180	0.003649	36.491751	0.062334	1045.332520	0.000000	NaN	NaN
161.999266	0.003864	38.637482	0.063204	1046.188232	0.000000	NaN	NaN
163.499352	0.003781	37.812201	0.063931	1046.904053	0.000000	NaN	NaN
164.999437	0.003707	37.069448	0.064745	1047.704712	0.000000	NaN	NaN
166.499523	0.003913	39.132651	0.065489	1048.436768	0.000000	NaN	NaN
167.999609	0.003781	37.812201	0.066293	1049.228394	0.000000	NaN	NaN
169.499695	0.003798	37.977257	0.067155	1050.076172	0.000000	NaN	NaN
170.999781	0.003756	37.564616	0.067962	1050.870605	0.000000	NaN	NaN
172.499866	0.003814	38.142313	0.068761	1051.656616	0.000000	NaN	NaN
173.999952	0.003814	38.142313	0.069394	1052.279297	0.000000	NaN	NaN
175.500038	0.003831	38.307369	0.070268	1053.139648	0.000000	NaN	NaN
176.999124	0.003847	38.472426	0.071067	1053.925415	0.000000	NaN	NaN
178.499210	0.003814	38.142313	0.071886	1054.731689	0.000000	NaN	NaN
179.999295	0.003905	39.050123	0.072602	1055.435791	0.000000	NaN	NaN
181.499381	0.003847	38.472426	0.073428	1056.248413	0.000000	NaN	NaN
182.999467	0.003913	39.132651	0.074161	1056.969849	0.000000	NaN	NaN
184.499553	0.003781	37.812201	0.074990	1057.786011	0.000000	NaN	NaN
185.999639	0.003946	39.462763	0.075798	1058.580688	0.000000	NaN	NaN
187.499724	0.003814	38.142313	0.076511	1059.282715	0.000000	NaN	NaN
188.999810	0.003814	38.142313	0.077344	1060.102295	0.000000	NaN	NaN
190.499896	0.003913	39.132651	0.078118	1060.863770	0.000000	NaN	NaN
191.999982	0.003880	38.802538	0.078884	1061.616943	0.000000	NaN	NaN
193.499067	0.003930	39.297707	0.079618	1062.339844	0.000000	NaN	NaN
194.999153	0.003905	39.050123	0.080458	1063.166626	0.000000	NaN	NaN
196.499239	0.003922	39.215179	0.081253	1063.948853	0.000000	NaN	NaN
197.999325	0.003922	39.215179	0.082081	1064.763306	0.000000	NaN	NaN
199.499411	0.003938	39.380235	0.082833	1065.503662	0.000000	NaN	NaN
200.999496	0.003971	39.710348	0.083632	1066.288940	0.000000	NaN	NaN
202.499582	0.003839	38.389898	0.084390	1067.035767	0.000000	NaN	NaN
203.999668	0.003971	39.710348	0.085194	1067.826782	0.000000	NaN	NaN
205.499754	0.003913	39.132651	0.086003	1068.622192	0.000000	NaN	NaN
206.999840	0.003872	38.720010	0.086722	1069.329956	0.000000	NaN	NaN
208.499925	0.003971	39.710348	0.087467	1070.063110	0.000000	NaN	NaN
210.000011	0.003946	39.462763	0.088244	1070.827515	0.000000	NaN	NaN
211.499097	0.004045	40.453101	0.089146	1071.715454	0.000000	NaN	NaN
212.999183	0.003905	39.050123	0.090056	1072.610229	0.000000	NaN	NaN
214.499269	0.004144	41.443438	0.090720	1073.263550	0.000000	NaN	NaN
215.999355	0.003963	39.627819	0.091576	1074.106812	0.000000	NaN	NaN
217.499440	0.004021	40.205516	0.092186	1074.706909	0.000000	NaN	NaN
218.999526	0.004045	40.453101	0.092997	1075.504761	0.000000	NaN	NaN
220.499612	0.004103	41.030798	0.093831	1076.325073	0.000000	NaN	NaN
221.999698	0.004153	41.525966	0.094600	1077.081665	0.000000	NaN	NaN
223.499783	0.004095	40.948269	0.095308	1077.778564	0.000000	NaN	NaN
224.999869	0.004260	42.598832	0.096016	1078.475708	0.000000	NaN	NaN
226.499955	0.004128	41.278382	0.096791	1079.237671	0.000000	NaN	NaN
228.000041	0.003996	39.957932	0.097607	1080.040771	0.000000	NaN	NaN
229.499127	0.004177	41.773551	0.098389	1080.810547	0.000000	NaN	NaN
230.999212	0.004111	41.113326	0.099164	1081.573364	0.000000	NaN	NaN
232.499298	0.004177	41.773551	0.099919	1082.316040	0.000000	NaN	NaN
233.999384	0.004177	41.773551	0.100657	1083.042480	0.000000	NaN	NaN
235.499470	0.004153	41.525966	0.101410	1083.782715	0.000000	NaN	NaN
236.999556	0.004144	41.443438	0.102118	1084.479736	0.000000	NaN	NaN
238.499641	0.004111	41.113326	0.102907	1085.255981	0.000000	NaN	NaN
239.999727	0.004120	41.195854	0.103696	1086.032349	0.000000	NaN	NaN
241.499813	0.004136	41.360910	0.104439	1086.763794	0.000000	NaN	NaN
242.999899	0.004219	42.186191	0.105224	1087.536255	0.000000	NaN	NaN
244.499985	0.004103	41.030798	0.105913	1088.214111	0.000000	NaN	NaN
245.999070	0.004120	41.195854	0.106689	1088.977173	0.000000	NaN	NaN
247.499156	0.004260	42.598832	0.107468	1089.743652	0.000000	NaN	NaN
248.999242	0.004260	42.598832	0.108209	1090.473511	0.000000	NaN	NaN
250.499328	0.004120	41.195854	0.108882	1091.135376	0.000000	NaN	NaN
251.999414	0.004235	42.351247	0.109617	1091.858887	0.000000	NaN	NaN
253.499499	0.004235	42.351247	0.110323	1092.553467	0.000000	NaN	NaN
254.999585	0.004235	42.351247	0.111235	1093.451050	0.000000	NaN	NaN
256.499671	0.004177	41.773551	0.111860	1094.065918	0.000000	NaN	NaN
257.999757	0.004227	42.268719	0.112691	1094.883423	0.000000	NaN	NaN
259.499842	0.004161	41.608494	0.113344	1095.525635	0.000000	NaN	NaN
260.999928	0.004194	41.938607	0.114049	1096.219360	0.000000	NaN	NaN
262.500014	0.004301	43.011472	0.114839	1096.996704	0.000000	NaN	NaN
263.999100	0.004219	42.186191	0.115615	1097.760376	0.000000	NaN	NaN
265.499186	0.004318	43.176529	0.116337	1098.470947	0.000000	NaN	NaN
266.999272	0.004210	42.103663	0.117091	1099.212891	0.000000	NaN	NaN
268.499357	0.004235	42.351247	0.117835	1099.945190	0.000000	NaN	NaN
269.999443	0.004235	42.351247	0.118519	1100.618530	0.000000	NaN	NaN
271.499529	0.004375	43.754226	0.119323	1101.409180	0.000000	NaN	NaN
272.999615	0.004136	41.360910	0.120097	1102.170410	0.000000	NaN	NaN
274.499700	0.004318	43.176529	0.120783	1102.846313	0.000000	NaN	NaN
275.999786	0.004243	42.433776	0.121469	1103.521362	0.000000	NaN	NaN
277.499872	0.004309	43.094001	0.122252	1104.291138	0.000000	NaN	NaN
278.999958	0.004276	42.763888	0.122972	1104.999634	0.000000	NaN	NaN
280.500044	0.004301	43.011472	0.123770	1105.785400	0.000000	NaN	NaN
281.999129	0.004359	43.589169	0.124570	1106.572388	0.000000	NaN	NaN
283.499215	0.004276	42.763888	0.125241	1107.232300	0.000000	NaN	NaN
284.999301	0.004408	44.084338	0.125986	1107.965942	0.000000	NaN	NaN
286.499387	0.004309	43.094001	0.126764	1108.731323	0.000000	NaN	NaN
287.999473	0.004367	43.671697	0.127457	1109.412842	0.000000	NaN	NaN
289.499558	0.004334	43.341585	0.128156	1110.100952	0.000000	NaN	NaN
290.999644	0.004318	43.176529	0.128851	1110.784790	0.000000	NaN	NaN
292.499730	0.004326	43.259057	0.129611	1111.532104	0.000000	NaN	NaN
293.999816	0.004318	43.176529	0.130275	1112.185669	0.000000	NaN	NaN
295.499902	0.004441	44.414451	0.130995	1112.894165	0.000000	NaN	NaN
296.999987	0.004367	43.671697	0.131656	1113.545166	0.000000	NaN	NaN
298.499073	0.004392	43.919282	0.132464	1114.339478	0.000000	NaN	NaN
299.999159	0.004392	43.919282	0.133189	1115.053467	0.000000	NaN	NaN
301.499245	0.004491	44.909619	0.133844	1115.698120	0.000000	NaN	NaN
302.999331	0.004384	43.836754	0.134583	1116.424561	0.000000	NaN	NaN
304.499416	0.004400	44.001810	0.135337	1117.166748	0.000000	NaN	NaN
305.999502	0.004441	44.414451	0.136020	1117.839111	0.000000	NaN	NaN
307.499588	0.004392	43.919282	0.136667	1118.475708	0.000000	NaN	NaN
308.999674	0.004392	43.919282	0.137365	1119.162720	0.000000	NaN	NaN
310.499760	0.004342	43.424113	0.138083	1119.869507	0.000000	NaN	NaN
311.999845	0.004326	43.259057	0.138816	1120.590698	0.000000	NaN	NaN
313.499931	0.004425	44.249394	0.139563	1121.325806	0.000000	NaN	NaN
315.000017	0.004474	44.744563	0.140276	1122.027100	0.000000	NaN	NaN
316.499103	0.004532	45.322260	0.141041	1122.779541	0.000000	NaN	NaN
317.999189	0.004458	44.579507	0.141721	1123.448975	0.000000	NaN	NaN
319.499274	0.004491	44.909619	0.142394	1124.110840	0.000000	NaN	NaN
320.999360	0.004499	44.992147	0.143170	1124.874390	0.000000	NaN	NaN
322.499446	0.004474	44.744563	0.143901	1125.593872	0.000000	NaN	NaN
323.999532	0.004375	43.754226	0.144553	1126.235718	0.000000	NaN	NaN
325.499617	0.004483	44.827091	0.145315	1126.984863	0.000000	NaN	NaN
326.999703	0.004441	44.414451	0.145963	1127.622803	0.000000	NaN	NaN
328.499789	0.004507	45.074676	0.146577	1128.227295	0.000000	NaN	NaN
329.999875	0.004441	44.414451	0.147303	1128.941406	0.000000	NaN	NaN
331.499961	0.004507	45.074676	0.147995	1129.622070	0.000000	NaN	NaN
333.000046	0.004491	44.909619	0.148788	1130.402344	0.000000	NaN	NaN
334.499132	0.004540	45.404788	0.149454	1131.058472	0.000000	NaN	NaN
335.999218	0.004656	46.560182	0.150121	1131.714600	0.000000	NaN	NaN
337.499304	0.004458	44.579507	0.150817	1132.399414	0.000000	NaN	NaN
338.999390	0.004648	46.477654	0.151562	1133.132446	0.000000	NaN	NaN
340.499475	0.004582	45.817429	0.152250	1133.809082	0.000000	NaN	NaN
341.999561	0.004532	45.322260	0.152944	1134.492065	0.000000	NaN	NaN
343.499647	0.004623	46.230069	0.153656	1135.193115	0.000000	NaN	NaN
344.999733	0.004557	45.569844	0.154335	1135.861206	0.000000	NaN	NaN
346.499819	0.004549	45.487316	0.154929	1136.445312	0.000000	NaN	NaN
347.999905	0.004590	45.899957	0.155599	1137.104248	0.000000	NaN	NaN
349.499990	0.004557	45.569844	0.156157	1137.654053	0.000000	NaN	NaN
350.999076	0.004582	45.817429	0.156674	1138.162842	0.000000	NaN	NaN
352.499162	0.004565	45.652372	0.157670	1139.143066	0.000000	NaN	NaN
353.999248	0.004607	46.065013	0.158376	1139.837036	0.000000	NaN	NaN
355.499333	0.004573	45.734901	0.159081	1140.530884	0.000000	NaN	NaN
356.999419	0.004640	46.395125	0.159861	1141.298950	0.000000	NaN	NaN
358.499505	0.004656	46.560182	0.160505	1141.931763	0.000000	NaN	NaN
359.999591	0.004615	46.147541	0.161287	1142.701904	0.000000	NaN	NaN
361.499677	0.004697	46.972822	0.161961	1143.364624	0.000000	NaN	NaN
362.999762	0.004689	46.890294	0.162554	1143.948486	0.000000	NaN	NaN
364.499848	0.004590	45.899957	0.163329	1144.711060	0.000000	NaN	NaN
365.999934	0.004862	48.623385	0.164036	1145.407104	0.000000	NaN	NaN
367.500020	0.004491	44.909619	0.164706	1146.066284	0.000000	NaN	NaN
368.999105	0.004623	46.230069	0.165428	1146.776733	0.000000	NaN	NaN
370.499191	0.004640	46.395125	0.166134	1147.471191	0.000000	NaN	NaN
371.999277	0.004557	45.569844	0.166821	1148.146729	0.000000	NaN	NaN
373.499363	0.004623	46.230069	0.167515	1148.829712	0.000000	NaN	NaN
374.999449	0.004565	45.652372	0.168231	1149.534058	0.000000	NaN	NaN
376.499534	0.004640	46.395125	0.168912	1150.204346	0.000000	NaN	NaN
377.999620	0.004697	46.972822	0.169608	1150.889526	0.000000	NaN	NaN
379.499706	0.004747	47.467991	0.170273	1151.543823	0.000000	NaN	NaN
380.999792	0.004598	45.982485	0.170972	1152.231812	0.000000	NaN	NaN
382.499878	0.004664	46.642710	0.171695	1152.942749	0.000000	NaN	NaN
383.999963	0.004780	47.798104	0.172383	1153.619751	0.000000	NaN	NaN
385.500049	0.004714	47.137879	0.173135	1154.359619	0.000000	NaN	NaN
386.999135	0.004540	45.404788	0.173745	1154.960205	0.000000	NaN	NaN
388.499221	0.004805	48.045688	0.174390	1155.594971	0.000000	NaN	NaN
389.999307	0.004623	46.230069	0.175181	1156.373291	0.000000	NaN	NaN
391.499392	0.004813	48.128216	0.175889	1157.070190	0.000000	NaN	NaN
392.999478	0.004796	47.963160	0.176625	1157.793701	0.000000	NaN	NaN
394.499564	0.004821	48.210744	0.177366	1158.523804	0.000000	NaN	NaN
395.999650	0.004796	47.963160	0.178001	1159.147949	0.000000	NaN	NaN
397.499736	0.004862	48.623385	0.178729	1159.864746	0.000000	NaN	NaN
398.999821	0.004772	47.715575	0.179408	1160.532715	0.000000	NaN	NaN
400.499907	0.004714	47.137879	0.180052	1161.165894	0.000000	NaN	NaN
401.999993	0.004780	47.798104	0.180826	1161.927734	0.000000	NaN	NaN
403.499079	0.004706	47.055350	0.181473	1162.564575	0.000000	NaN	NaN
404.999165	0.004879	48.788441	0.182107	1163.188477	0.000000	NaN	NaN
406.499250	0.004829	48.293272	0.182867	1163.935913	0.000000	NaN	NaN
407.999336	0.004854	48.540857	0.183497	1164.555786	0.000000	NaN	NaN
409.499422	0.004813	48.128216	0.184178	1165.226562	0.000000	NaN	NaN
410.999508	0.004986	49.861307	0.184844	1165.882080	0.000000	NaN	NaN
412.499594	0.004813	48.128216	0.185526	1166.552490	0.000000	NaN	NaN
413.999679	0.004871	48.705913	0.186141	1167.157837	0.000000	NaN	NaN
415.499765	0.004689	46.890294	0.186883	1167.887695	0.000000	NaN	NaN
416.999851	0.004821	48.210744	0.187608	1168.601440	0.000000	NaN	NaN
418.499937	0.004871	48.705913	0.188249	1169.231812	0.000000	NaN	NaN
420.000023	0.004706	47.055350	0.188940	1169.911987	0.000000	NaN	NaN
421.499108	0.004739	47.385463	0.189525	1170.487915	0.000000	NaN	NaN
422.999194	0.004722	47.220407	0.190218	1171.169312	0.000000	NaN	NaN
424.499280	0.004829	48.293272	0.190858	1171.799072	0.000000	NaN	NaN
425.999366	0.004986	49.861307	0.191568	1172.497559	0.000000	NaN	NaN
427.499452	0.005044	50.439003	0.192239	1173.158081	0.000000	NaN	NaN
428.999537	0.004879	48.788441	0.192878	1173.787354	0.000000	NaN	NaN
430.499623	0.004895	48.953497	0.193598	1174.495361	0.000000	NaN	NaN
431.999709	0.005044	50.439003	0.194321	1175.206665	0.000000	NaN	NaN
433.499795	0.004945	49.448666	0.194972	1175.847778	0.000000	NaN	NaN
434.999881	0.005151	51.511869	0.195563	1176.429321	0.000000	NaN	NaN
436.499966	0.004961	49.613722	0.196277	1177.131226	0.000000	NaN	NaN
438.000052	0.005003	50.026363	0.196819	1177.664551	0.000000	NaN	NaN
439.499138	0.005036	50.356475	0.197542	1178.376221	0.000000	NaN	NaN
440.999224	0.004772	47.715575	0.198187	1179.010620	0.000000	NaN	NaN
442.499309	0.004953	49.531194	0.198876	1179.688965	0.000000	NaN	NaN
443.999395	0.004904	49.036025	0.199587	1180.388428	0.000000	NaN	NaN
445.499481	0.004986	49.861307	0.200205	1180.996826	0.000000	NaN	NaN
446.999567	0.004986	49.861307	0.200922	1181.702148	0.000000	NaN	NaN
448.499653	0.004706	47.055350	0.201587	1182.357056	0.000000	NaN	NaN
449.999738	0.005011	50.108891	0.202237	1182.995972	0.000000	NaN	NaN
451.499824	0.005060	50.604060	0.202915	1183.663208	0.000000	NaN	NaN
452.999910	0.004821	48.210744	0.203581	1184.318359	0.000000	NaN	NaN
454.499996	0.005143	51.429341	0.204216	1184.943115	0.000000	NaN	NaN
455.999082	0.005085	50.851644	0.204858	1185.575562	0.000000	NaN	NaN
457.499167	0.004912	49.118554	0.205562	1186.267944	0.000000	NaN	NaN
458.999253	0.005036	50.356475	0.206249	1186.944458	0.000000	NaN	NaN
460.499339	0.005052	50.521532	0.206886	1187.571045	0.000000	NaN	NaN
461.999425	0.005209	52.089566	0.207558	1188.232178	0.000000	NaN	NaN
463.499511	0.005069	50.686588	0.208167	1188.831299	0.000000	NaN	NaN
464.999596	0.005102	51.016700	0.208781	1189.435303	0.000000	NaN	NaN
466.499682	0.005044	50.439003	0.209547	1190.189453	0.000000	NaN	NaN
467.999768	0.005019	50.191419	0.210173	1190.805786	0.000000	NaN	NaN
469.499854	0.005085	50.851644	0.210912	1191.532349	0.000000	NaN	NaN
470.999940	0.005077	50.769116	0.211540	1192.150146	0.000000	NaN	NaN
472.500025	0.005052	50.521532	0.212106	1192.707275	0.000000	NaN	NaN
473.999111	0.005093	50.934172	0.212816	1193.406006	0.000000	NaN	NaN
475.499197	0.005085	50.851644	0.213531	1194.109497	0.000000	NaN	NaN
476.999283	0.005052	50.521532	0.214175	1194.743286	0.000000	NaN	NaN
478.499369	0.005069	50.686588	0.214836	1195.394165	0.000000	NaN	NaN
479.999454	0.005159	51.594397	0.215491	1196.038330	0.000000	NaN	NaN
481.499540	0.005176	51.759453	0.216161	1196.697632	0.000000	NaN	NaN
482.999626	0.005110	51.099228	0.216818	1197.343750	0.000000	NaN	NaN
484.499712	0.005077	50.769116	0.217328	1197.845581	0.000000	NaN	NaN
485.999798	0.005201	52.007038	0.218082	1198.587402	0.000000	NaN	NaN
487.499883	0.005135	51.346813	0.218741	1199.235840	0.000000	NaN	NaN
488.999969	0.005102	51.016700	0.219286	1199.772461	0.000000	NaN	NaN
490.500055	0.005093	50.934172	0.220000	1200.474609	0.000000	NaN	NaN
491.999141	0.005184	51.841982	0.220674	1201.138550	0.000000	NaN	NaN
493.499226	0.005135	51.346813	0.221404	1201.856934	0.000000	NaN	NaN
494.999312	0.005201	52.007038	0.221991	1202.434204	0.000000	NaN	NaN
496.499398	0.005234	52.337150	0.222644	1203.076660	0.000000	NaN	NaN
497.999484	0.005093	50.934172	0.223172	1203.596680	0.000000	NaN	NaN
499.499570	0.005341	53.410016	0.223877	1204.289917	0.000000	NaN	NaN
500.999656	0.005201	52.007038	0.224466	1204.869629	0.000000	NaN	NaN
502.499741	0.005250	52.502206	0.225209	1205.600830	0.000000	NaN	NaN
503.999827	0.005184	51.841982	0.225862	1206.243042	0.000000	NaN	NaN
505.499913	0.005184	51.841982	0.226480	1206.850830	0.000000	NaN	NaN
506.999999	0.005267	52.667263	0.227142	1207.502319	0.000000	NaN	NaN
508.499084	0.005110	51.099228	0.227754	1208.105103	0.000000	NaN	NaN
509.999170	0.005085	50.851644	0.228413	1208.753052	0.000000	NaN	NaN
511.499256	0.005135	51.346813	0.229029	1209.359863	0.000000	NaN	NaN
512.999342	0.005250	52.502206	0.229560	1209.882080	0.000000	NaN	NaN
514.499428	0.005217	52.172094	0.230351	1210.660400	0.000000	NaN	NaN
515.999514	0.005275	52.749791	0.230971	1211.270630	0.000000	NaN	NaN
517.499599	0.005432	54.317825	0.232068	1212.349976	0.000000	NaN	NaN
518.999685	0.005448	54.482881	0.232728	1212.999390	0.000000	NaN	NaN
520.499771	0.005358	53.575072	0.233505	1213.764282	0.000000	NaN	NaN
521.999857	0.005473	54.730466	0.234161	1214.409302	0.000000	NaN	NaN
523.499942	0.005399	53.987713	0.234749	1214.987549	0.000000	NaN	NaN
525.000028	0.005267	52.667263	0.235475	1215.702637	0.000000	NaN	NaN
526.499114	0.005358	53.575072	0.236148	1216.364990	0.000000	NaN	NaN
527.999200	0.005374	53.740128	0.236802	1217.007568	0.000000	NaN	NaN
529.499286	0.005258	52.584735	0.237519	1217.713867	0.000000	NaN	NaN
530.999371	0.005300	52.997375	0.238146	1218.330322	0.000000	NaN	NaN
532.499457	0.005168	51.676925	0.238814	1218.987427	0.000000	NaN	NaN
533.999543	0.005366	53.657600	0.239514	1219.677124	0.000000	NaN	NaN
535.499629	0.005333	53.327488	0.240230	1220.381470	0.000000	NaN	NaN
536.999715	0.005341	53.410016	0.240891	1221.031250	0.000000	NaN	NaN
538.499800	0.005275	52.749791	0.241474	1221.605103	0.000000	NaN	NaN
539.999886	0.005192	51.924510	0.242011	1222.134033	0.000000	NaN	NaN
541.499972	0.005151	51.511869	0.242355	1222.472534	0.000000	NaN	NaN
542.999058	0.005159	51.594397	0.242757	1222.867432	0.000000	NaN	NaN
544.499144	0.005275	52.749791	0.243208	1223.312012	0.000000	NaN	NaN
545.999229	0.005300	52.997375	0.243903	1223.995361	0.000000	NaN	NaN
547.499315	0.005366	53.657600	0.244473	1224.556763	0.000000	NaN	NaN
548.999401	0.005291	52.914847	0.245191	1225.262329	0.000000	NaN	NaN
550.499487	0.005374	53.740128	0.245717	1225.780518	0.000000	NaN	NaN
551.999573	0.005448	54.482881	0.246408	1226.460571	0.000000	NaN	NaN
553.499658	0.005506	55.060578	0.246989	1227.032349	0.000000	NaN	NaN
554.999744	0.005225	52.254622	0.247663	1227.695679	0.000000	NaN	NaN
556.499830	0.005250	52.502206	0.248108	1228.133179	0.000000	NaN	NaN
557.999916	0.005382	53.822656	0.248774	1228.788086	0.000000	NaN	NaN
559.500002	0.005333	53.327488	0.249495	1229.498291	0.000000	NaN	NaN
560.999087	0.005349	53.492544	0.250079	1230.072876	0.000000	NaN	NaN
562.499173	0.005349	53.492544	0.250681	1230.665039	0.000000	NaN	NaN
563.999259	0.005234	52.337150	0.251326	1231.299316	0.000000	NaN	NaN
565.499345	0.005374	53.740128	0.251896	1231.860718	0.000000	NaN	NaN
566.999431	0.005432	54.317825	0.252454	1232.409790	0.000000	NaN	NaN
568.499516	0.005440	54.400353	0.253101	1233.046509	0.000000	NaN	NaN
569.999602	0.005424	54.235297	0.253779	1233.713013	0.000000	NaN	NaN
571.499688	0.005424	54.235297	0.254541	1234.463623	0.000000	NaN	NaN
572.999774	0.005589	55.885859	0.255078	1234.991943	0.000000	NaN	NaN
574.499859	0.005465	54.647938	0.255749	1235.651611	0.000000	NaN	NaN
575.999945	0.005506	55.060578	0.256368	1236.261108	0.000000	NaN	NaN
577.500031	0.005440	54.400353	0.256902	1236.786377	0.000000	NaN	NaN
578.999117	0.005448	54.482881	0.257543	1237.416748	0.000000	NaN	NaN
580.499203	0.005473	54.730466	0.258222	1238.084839	0.000000	NaN	NaN
581.999289	0.005580	55.803331	0.258809	1238.662842	0.000000	NaN	NaN
583.499374	0.005572	55.720803	0.259453	1239.296997	0.000000	NaN	NaN
584.999460	0.005366	53.657600	0.260204	1240.035767	0.000000	NaN	NaN
586.499546	0.005539	55.390691	0.260762	1240.584473	0.000000	NaN	NaN
587.999632	0.005514	55.143106	0.261419	1241.231445	0.000000	NaN	NaN
589.499717	0.005613	56.133444	0.262030	1241.832153	0.000000	NaN	NaN
590.999803	0.005514	55.143106	0.262749	1242.539551	0.000000	NaN	NaN
592.499889	0.005539	55.390691	0.263417	1243.197144	0.000000	NaN	NaN
593.999975	0.005457	54.565410	0.264095	1243.864014	0.000000	NaN	NaN
595.499061	0.005490	54.895522	0.264797	1244.555542	0.000000	NaN	NaN
596.999146	0.005580	55.803331	0.265239	1244.989868	0.000000	NaN	NaN
598.499232	0.005481	54.812994	0.265930	1245.670166	0.000000	NaN	NaN
599.999318	0.005391	53.905185	0.266360	1246.092773	0.000000	NaN	NaN
601.499404	0.005556	55.555747	0.267161	1246.880737	0.000000	NaN	NaN
602.999490	0.005498	54.978050	0.267865	1247.573853	0.000000	NaN	NaN
604.499575	0.005572	55.720803	0.268464	1248.163574	0.000000	NaN	NaN
605.999661	0.005638	56.381028	0.269205	1248.892944	0.000000	NaN	NaN
607.499747	0.005613	56.133444	0.269774	1249.452515	0.000000	NaN	NaN
608.999833	0.005589	55.885859	0.270443	1250.110840	0.000000	NaN	NaN
610.499919	0.005481	54.812994	0.271093	1250.750122	0.000000	NaN	NaN
612.000004	0.005490	54.895522	0.271555	1251.204834	0.000000	NaN	NaN
613.499090	0.005671	56.711141	0.272237	1251.875977	0.000000	NaN	NaN
614.999176	0.005638	56.381028	0.272926	1252.554321	0.000000	NaN	NaN
616.499262	0.005605	56.050916	0.273564	1253.181396	0.000000	NaN	NaN
617.999347	0.005498	54.978050	0.274212	1253.819702	0.000000	NaN	NaN
619.499433	0.005531	55.308163	0.274800	1254.398193	0.000000	NaN	NaN
620.999519	0.005580	55.803331	0.275571	1255.156250	0.000000	NaN	NaN
622.499605	0.005622	56.215972	0.276015	1255.593872	0.000000	NaN	NaN
623.999691	0.005655	56.546084	0.276659	1256.226807	0.000000	NaN	NaN
625.499776	0.005597	55.968388	0.277274	1256.832642	0.000000	NaN	NaN
626.999862	0.005803	58.031591	0.277928	1257.476440	0.000000	NaN	NaN
628.499948	0.005556	55.555747	0.279064	1258.593872	0.000000	NaN	NaN
630.000034	0.005589	55.885859	0.279161	1258.689087	0.000000	NaN	NaN
631.499120	0.005605	56.050916	0.279735	1259.254272	0.000000	NaN	NaN
632.999206	0.005630	56.298500	0.280280	1259.789795	0.000000	NaN	NaN
634.499291	0.005490	54.895522	0.281022	1260.520142	0.000000	NaN	NaN
635.999377	0.005564	55.638275	0.281595	1261.084473	0.000000	NaN	NaN
637.499463	0.005622	56.215972	0.282269	1261.747192	0.000000	NaN	NaN
638.999549	0.005556	55.555747	0.282814	1262.284058	0.000000	NaN	NaN
640.499634	0.005605	56.050916	0.283472	1262.931152	0.000000	NaN	NaN
641.999720	0.005811	58.114119	0.284044	1263.493774	0.000000	NaN	NaN
643.499806	0.005712	57.123781	0.284653	1264.093628	0.000000	NaN	NaN
644.999892	0.005712	57.123781	0.285381	1264.809692	0.000000	NaN	NaN
646.499978	0.005646	56.463556	0.285923	1265.343018	0.000000	NaN	NaN
647.999063	0.005613	56.133444	0.286545	1265.955322	0.000000	NaN	NaN
649.499149	0.005663	56.628613	0.287118	1266.519287	0.000000	NaN	NaN
650.999235	0.005646	56.463556	0.287806	1267.196045	0.000000	NaN	NaN
652.499321	0.005663	56.628613	0.288388	1267.768921	0.000000	NaN	NaN
653.999407	0.005737	57.371366	0.288947	1268.318237	0.000000	NaN	NaN
655.499492	0.005622	56.215972	0.289660	1269.020630	0.000000	NaN	NaN
656.999578	0.005704	57.041253	0.290246	1269.596680	0.000000	NaN	NaN
658.499664	0.005671	56.711141	0.290761	1270.103882	0.000000	NaN	NaN
659.999750	0.005688	56.876197	0.291440	1270.771484	0.000000	NaN	NaN
661.499836	0.005737	57.371366	0.292058	1271.380005	0.000000	NaN	NaN
662.999921	0.005613	56.133444	0.292671	1271.983398	0.000000	NaN	NaN
664.500007	0.005704	57.041253	0.293303	1272.604492	0.000000	NaN	NaN
665.999093	0.005622	56.215972	0.293968	1273.259521	0.000000	NaN	NaN
667.499179	0.005622	56.215972	0.294547	1273.828979	0.000000	NaN	NaN
668.999265	0.005737	57.371366	0.295195	1274.466431	0.000000	NaN	NaN
670.499350	0.005655	56.546084	0.295700	1274.963379	0.000000	NaN	NaN
671.999436	0.005762	57.618950	0.296407	1275.659424	0.000000	NaN	NaN
673.499522	0.005655	56.546084	0.297001	1276.243164	0.000000	NaN	NaN
674.999608	0.005745	57.453894	0.297557	1276.791260	0.000000	NaN	NaN
676.499694	0.005869	58.691816	0.298123	1277.348145	0.000000	NaN	NaN
677.999779	0.005704	57.041253	0.298774	1277.988281	0.000000	NaN	NaN
679.499865	0.005646	56.463556	0.299333	1278.537964	0.000000	NaN	NaN
680.999951	0.005646	56.463556	0.299980	1279.175293	0.000000	NaN	NaN
682.500037	0.005696	56.958725	0.300620	1279.804687	0.000000	NaN	NaN
683.999122	0.005622	56.215972	0.301240	1280.414917	0.000000	NaN	NaN
685.499208	0.005778	57.784006	0.301877	1281.041870	0.000000	NaN	NaN
686.999294	0.005688	56.876197	0.302417	1281.573242	0.000000	NaN	NaN
688.499380	0.005721	57.206309	0.303024	1282.170654	0.000000	NaN	NaN
689.999466	0.005861	58.609287	0.303684	1282.819214	0.000000	NaN	NaN
691.499551	0.005638	56.381028	0.304326	1283.451416	0.000000	NaN	NaN
692.999637	0.005902	59.021928	0.304831	1283.947876	0.000000	NaN	NaN
694.499723	0.005770	57.701478	0.305542	1284.648193	0.000000	NaN	NaN
695.999809	0.005787	57.866534	0.306044	1285.142090	0.000000	NaN	NaN
697.499895	0.005712	57.123781	0.306660	1285.747681	0.000000	NaN	NaN
698.999980	0.005770	57.701478	0.307250	1286.328369	0.000000	NaN	NaN
700.499066	0.005671	56.711141	0.307905	1286.973389	0.000000	NaN	NaN
701.999152	0.005622	56.215972	0.308430	1287.490112	0.000000	NaN	NaN
703.499238	0.005795	57.949063	0.309040	1288.090088	0.000000	NaN	NaN
704.999324	0.005737	57.371366	0.309661	1288.701416	0.000000	NaN	NaN
706.499409	0.005704	57.041253	0.310219	1289.249756	0.000000	NaN	NaN
707.999495	0.005729	57.288838	0.310836	1289.857422	0.000000	NaN	NaN
709.499581	0.005712	57.123781	0.311365	1290.378296	0.000000	NaN	NaN
710.999667	0.005745	57.453894	0.311993	1290.995361	0.000000	NaN	NaN
712.499753	0.005704	57.041253	0.312574	1291.567871	0.000000	NaN	NaN
713.999839	0.005721	57.206309	0.313130	1292.114868	0.000000	NaN	NaN
715.499924	0.005704	57.041253	0.313711	1292.686035	0.000000	NaN	NaN
717.000010	0.005795	57.949063	0.314292	1293.257812	0.000000	NaN	NaN
718.499096	0.005679	56.793669	0.314734	1293.692749	0.000000	NaN	NaN
719.999182	0.005655	56.546084	0.315372	1294.320435	0.000000	NaN	NaN
721.499267	0.005589	55.885859	0.315990	1294.928345	0.000000	NaN	NaN
722.999353	0.005721	57.206309	0.316512	1295.442139	0.000000	NaN	NaN
724.499439	0.005712	57.123781	0.317167	1296.087036	0.000000	NaN	NaN
725.999525	0.005630	56.298500	0.317687	1296.598511	0.000000	NaN	NaN
727.499611	0.005844	58.444231	0.318164	1297.067627	0.000000	NaN	NaN
728.999696	0.005663	56.628613	0.318837	1297.729858	0.000000	NaN	NaN
730.499782	0.005638	56.381028	0.319391	1298.275146	0.000000	NaN	NaN
731.999868	0.005844	58.444231	0.319965	1298.839844	0.000000	NaN	NaN
733.499954	0.005828	58.279175	0.320589	1299.454102	0.000000	NaN	NaN
735.000040	0.005721	57.206309	0.321187	1300.042358	0.000000	NaN	NaN
736.499125	0.005787	57.866534	0.321767	1300.613403	0.000000	NaN	NaN
737.999211	0.005737	57.371366	0.322271	1301.109619	0.000000	NaN	NaN
739.499297	0.005679	56.793669	0.322794	1301.623779	0.000000	NaN	NaN
740.999383	0.005861	58.609287	0.323416	1302.236328	0.000000	NaN	NaN
742.499468	0.005902	59.021928	0.324103	1302.911499	0.000000	NaN	NaN
743.999554	0.005679	56.793669	0.324540	1303.341553	0.000000	NaN	NaN
745.499640	0.005745	57.453894	0.325091	1303.884521	0.000000	NaN	NaN
746.999726	0.005638	56.381028	0.325684	1304.467896	0.000000	NaN	NaN
748.499812	0.005754	57.536422	0.326292	1305.065918	0.000000	NaN	NaN
749.999897	0.005663	56.628613	0.326854	1305.618652	0.000000	NaN	NaN
751.499983	0.005745	57.453894	0.327519	1306.273071	0.000000	NaN	NaN
752.999069	0.005523	55.225635	0.328017	1306.763306	0.000000	NaN	NaN
754.499155	0.005597	55.968388	0.328649	1307.385376	0.000000	NaN	NaN
755.999241	0.005630	56.298500	0.329248	1307.974365	0.000000	NaN	NaN
757.499326	0.005663	56.628613	0.329747	1308.465210	0.000000	NaN	NaN
758.999412	0.005696	56.958725	0.330254	1308.964355	0.000000	NaN	NaN
760.499498	0.005688	56.876197	0.330822	1309.522949	0.000000	NaN	NaN
761.999584	0.005712	57.123781	0.331445	1310.136108	0.000000	NaN	NaN
763.499670	0.005349	53.492544	0.332035	1310.716919	0.000000	NaN	NaN
764.999755	0.005754	57.536422	0.332606	1311.278442	0.000000	NaN	NaN
766.499841	0.005564	55.638275	0.333195	1311.858154	0.000000	NaN	NaN
767.999927	0.005572	55.720803	0.333679	1312.334839	0.000000	NaN	NaN
769.500013	0.005613	56.133444	0.334178	1312.825928	0.000000	NaN	NaN
770.999099	0.005564	55.638275	0.334737	1313.375366	0.000000	NaN	NaN
772.499184	0.005737	57.371366	0.335308	1313.937256	0.000000	NaN	NaN
773.999270	0.005556	55.555747	0.335850	1314.470581	0.000000	NaN	NaN
775.499356	0.005531	55.308163	0.336472	1315.083130	0.000000	NaN	NaN
776.999442	0.005506	55.060578	0.337031	1315.633423	0.000000	NaN	NaN
778.499528	0.005605	56.050916	0.337561	1316.154663	0.000000	NaN	NaN
779.999613	0.005490	54.895522	0.338124	1316.708740	0.000000	NaN	NaN
781.499699	0.005481	54.812994	0.338647	1317.222656	0.000000	NaN	NaN
782.999785	0.005572	55.720803	0.339150	1317.718384	0.000000	NaN	NaN
784.499871	0.005407	54.070241	0.339737	1318.296143	0.000000	NaN	NaN
785.999957	0.005473	54.730466	0.340270	1318.820557	0.000000	NaN	NaN
787.500042	0.005424	54.235297	0.340701	1319.243774	0.000000	NaN	NaN
788.999128	0.005407	54.070241	0.341189	1319.724365	0.000000	NaN	NaN
790.499214	0.005324	53.244960	0.341712	1320.239380	0.000000	NaN	NaN
791.999300	0.005324	53.244960	0.342207	1320.725952	0.000000	NaN	NaN
793.499386	0.005316	53.162431	0.342722	1321.232666	0.000000	NaN	NaN
794.999471	0.005209	52.089566	0.343046	1321.551880	0.000000	NaN	NaN
796.499557	0.005110	51.099228	0.343468	1321.966797	0.000000	NaN	NaN
797.999643	0.005159	51.594397	0.343899	1322.390747	0.000000	NaN	NaN
799.499729	0.005077	50.769116	0.344375	1322.859985	0.000000	NaN	NaN
800.999815	0.005052	50.521532	0.344763	1323.241699	0.000000	NaN	NaN
802.499900	0.005044	50.439003	0.345120	1323.592651	0.000000	NaN	NaN
803.999986	0.004970	49.696250	0.345496	1323.963013	0.000000	NaN	NaN
805.499072	0.004879	48.788441	0.345782	1324.243774	0.000000	NaN	NaN
806.999158	0.004805	48.045688	0.346130	1324.586426	0.000000	NaN	NaN
808.499243	0.004871	48.705913	0.346425	1324.876587	0.000000	NaN	NaN
809.999329	0.004689	46.890294	0.346694	1325.141113	0.000000	NaN	NaN
811.499415	0.004697	46.972822	0.346907	1325.351440	0.000000	NaN	NaN
812.999501	0.004631	46.312597	0.347140	1325.580322	0.000000	NaN	NaN
814.499587	0.004565	45.652372	0.347301	1325.738892	0.000000	NaN	NaN
815.999672	0.004425	44.249394	0.347418	1325.854248	0.000000	NaN	NaN
817.499758	0.004301	43.011472	0.347615	1326.047485	0.000000	NaN	NaN
818.999844	0.004351	43.506641	0.347670	1326.101929	0.000000	NaN	NaN
820.499930	0.004227	42.268719	0.347544	1325.977539	0.000000	NaN	NaN
822.000016	0.004120	41.195854	0.347652	1326.084473	0.000000	NaN	NaN
823.499101	0.004103	41.030798	0.347611	1326.043457	0.000000	NaN	NaN
824.999187	0.003955	39.545291	0.347414	1325.849976	0.000000	NaN	NaN
826.499273	0.003880	38.802538	0.347332	1325.768799	0.000000	NaN	NaN
827.999359	0.003740	37.399560	0.347035	1325.477295	0.000000	NaN	NaN
829.499445	0.003451	34.511076	0.346842	1325.286743	0.000000	NaN	NaN
830.999530	0.003501	35.006245	0.346457	1324.908203	0.000000	NaN	NaN
832.499616	0.003369	33.685795	0.345994	1324.452393	0.000000	NaN	NaN
833.999702	0.003171	31.705120	0.345533	1323.999146	0.000000	NaN	NaN
835.499788	0.003096	30.962367	0.344958	1323.433350	0.000000	NaN	NaN
836.999874	0.002997	29.972029	0.344353	1322.837646	0.000000	NaN	NaN
838.499959	0.002725	27.248601	0.344034	1322.523682	0.000000	NaN	NaN
840.000045	0.002585	25.845623	0.342696	1321.207397	0.000000	NaN	NaN
841.499131	0.002461	24.607701	0.342530	1321.044556	0.000000	NaN	NaN
842.999217	0.002312	23.122195	0.341867	1320.392090	0.000000	NaN	NaN
844.499303	0.002106	21.058992	0.340945	1319.484619	0.000000	NaN	NaN
845.999388	0.002131	21.306576	0.340262	1318.812012	0.000000	NaN	NaN
847.499474	0.001966	19.656014	0.339484	1318.046997	0.000000	NaN	NaN
848.999560	0.001957	19.573485	0.338713	1317.288086	0.000000	NaN	NaN
850.499646	0.001850	18.500620	0.337958	1316.544800	0.000000	NaN	NaN
851.999732	0.001627	16.272360	0.337335	1315.932007	0.000000	NaN	NaN
853.499817	0.001759	17.592810	0.336737	1315.343994	0.000000	NaN	NaN
854.999903	0.001710	17.097642	0.336114	1314.730347	0.000000	NaN	NaN
856.499989	0.001536	15.364551	0.335629	1314.253296	0.000000	NaN	NaN
857.999075	0.001470	14.704326	0.335002	1313.636108	0.000000	NaN	NaN
859.499160	0.001429	14.291685	0.334555	1313.196655	0.000000	NaN	NaN
860.999246	0.001289	12.888707	0.334067	1312.716919	0.000000	NaN	NaN
862.499332	0.001281	12.806179	0.333736	1312.390381	0.000000	NaN	NaN
863.999418	0.001231	12.311010	0.333335	1311.996094	0.000000	NaN	NaN
865.499504	0.001297	12.971235	0.333050	1311.716064	0.000000	NaN	NaN
866.999589	0.001173	11.733313	0.332868	1311.536499	0.000000	NaN	NaN
868.499675	0.001017	10.165279	0.332845	1311.513916	0.000000	NaN	NaN
869.999761	0.001058	10.577920	0.332834	1311.502930	0.000000	NaN	NaN
871.499847	0.001033	10.330335	0.332958	1311.625122	0.000000	NaN	NaN
872.999933	0.001066	10.660448	0.333343	1312.003784	0.000000	NaN	NaN
874.500018	0.000959	9.587582	0.334006	1312.656128	0.000000	NaN	NaN
875.999104	0.000827	8.267132	0.335601	1314.225830	0.000000	NaN	NaN
877.499190	0.000686	6.864154	0.337846	1316.434570	0.000000	NaN	NaN
878.999276	0.000472	4.718423	0.340905	1319.444824	0.000000	NaN	NaN
880.499362	0.000109	1.087185	0.344639	1323.118896	0.000000	NaN	NaN
881.999447	0.000241	2.407635	0.348347	1326.767700	0.000000	NaN	NaN
883.499533	0.000109	1.087185	0.351714	1330.080933	0.000000	NaN	NaN
884.999619	0.000100	1.004657	0.354655	1332.974731	0.000000	NaN	NaN
886.499705	9.221289E-5	0.922129	0.357336	1335.613403	0.000000	NaN	NaN
887.999791	-2.332649E-5	-0.233265	0.359715	1337.954346	0.000000	NaN	NaN
889.499876	3.444320E-5	0.344432	0.362270	1340.467651	0.000000	NaN	NaN
890.999962	0.000133	1.334770	0.364542	1342.703369	0.000000	NaN	NaN
892.500048	0.000109	1.087185	0.366701	1344.828613	0.000000	NaN	NaN
893.999134	0.000109	1.087185	0.368684	1346.779663	0.000000	NaN	NaN
895.499220	-3.157930E-5	-0.315793	0.370443	1348.510742	0.000000	NaN	NaN
896.999305	-1.507368E-5	-0.150737	0.372217	1350.255615	0.000000	NaN	NaN
898.499391	3.444320E-5	0.344432	0.374033	1352.042847	0.000000	NaN	NaN
899.999477	1.793757E-5	0.179376	0.375707	1353.689697	0.000000	NaN	NaN
901.499563	5.094882E-5	0.509488	0.377476	1355.431152	0.000000	NaN	NaN
902.999649	5.920164E-5	0.592016	0.261545	1241.355103	0.000000	NaN	NaN
904.499734	3.444320E-5	0.344432	0.381106	1359.002319	0.000000	NaN	NaN
905.999820	1.431948E-6	0.014319	0.384480	1362.322754	0.000000	NaN	NaN
907.499906	-6.459055E-5	-0.645906	0.391660	1369.387573	0.000000	NaN	NaN
908.999992	-0.000139	-1.388659	0.399212	1376.819092	0.000000	NaN	NaN
910.499078	-0.000304	-3.039221	-0.621312	372.627777	0.000000	NaN	NaN
911.999163	-0.000106	-1.058546	-0.835068	162.292145	0.000000	NaN	NaN
913.499249	-0.000213	-2.131412	-0.835086	162.274719	0.000000	NaN	NaN
914.999335	-0.000205	-2.048884	-0.834535	162.816849	0.000000	NaN	NaN
916.499421	-0.000172	-1.718771	-0.834445	162.904968	0.000000	NaN	NaN
917.499478	-0.000164	-1.636243	-0.834749	162.606796	0.000000	NaN	NaN