File: data/115k_1-1_2 (180904).lvm
LabVIEW Measurement
Writer_Version	2
Reader_Version	2
Separator	Tab
Decimal_Separator	.
Multi_Headings	No
X_Columns	One
Time_Pref	Absolute
Operator	user
Description	Load(N)/Stress(MPa)/Distance A(pixel)/Strain A/Distance B(pixel)/Strain B/Poisson's ratio
Date	2018/09/04
Time	19:20:08.3027930259704589844
***End_of_Header***

Notes	X 값은 오직 다음과 같을 때에만 유효함이 보장됩니다. Dev1/ai0
Channels	7
Samples	1	1	1	1	1	1	1
Date	2018/09/04	2018/09/04	2018/09/04	2018/09/04	2018/09/04	2018/09/04	2018/09/04
Time	20:27:55.3034124300349959262	20:27:55.3034124300349959262	20:27:55.3034124374389648437	20:27:55.3034124374389648437	20:27:55.3034124374389648437	20:27:55.3034124374389648437	20:27:55.3034124374389648437
Y_Unit_Label	Volts	Volts
X_Dimension	Time	Time	Time	Time	Time	Time	Time
X0	0.0000000000000000E+0	0.0000000000000000E+0	0.0000000000000000E+0	0.0000000000000000E+0	0.0000000000000000E+0	0.0000000000000000E+0	0.0000000000000000E+0
Delta_X	0.000000	0.000000	1.000000	1.000000	1.000000	1.000000	1.000000
***End_of_Header***
X_Value	Dev1/ai0	Dev1/ai0 1	Untitled	Untitled 1	Untitled 2	Untitled 3	Untitled 4	Comment
0.000000	7.593570E-5	0.759357	-7.224083E-5	965.898926	0.000000	NaN	NaN
1.501086	9.713984E-6	0.097140	-0.000172	965.802063	0.000000	NaN	NaN
3.000172	3.454713E-5	0.345471	-0.000114	965.858948	0.000000	NaN	NaN
4.500257	5.938027E-5	0.593803	0.000231	966.191956	0.000000	NaN	NaN
5.999343	0.000159	1.587128	0.000494	966.446045	0.000000	NaN	NaN
7.500429	0.000184	1.835460	0.000754	966.696594	0.000000	NaN	NaN
9.000515	0.000250	2.497677	0.001062	966.994324	0.000000	NaN	NaN
10.499600	0.000217	2.166568	0.001363	967.285400	0.000000	NaN	NaN
12.000686	0.000390	3.904889	0.001777	967.685425	0.000000	NaN	NaN
13.500772	0.000217	2.166568	0.001068	967.000366	0.000000	NaN	NaN
14.999858	0.000415	4.153220	0.001338	967.260803	0.000000	NaN	NaN
16.500944	0.000374	3.739334	0.001520	967.436768	0.000000	NaN	NaN
18.000030	0.000448	4.484329	0.001612	967.525879	0.000000	NaN	NaN
19.501115	0.000424	4.235997	0.001995	967.895630	0.000000	NaN	NaN
21.001201	0.000589	5.891540	0.002239	968.131165	0.000000	NaN	NaN
22.499287	0.000457	4.567106	0.002309	968.199097	0.000000	NaN	NaN
23.999373	0.000573	5.725986	0.002602	968.481873	0.000000	NaN	NaN
25.500458	0.000606	6.057094	0.002773	968.646851	0.000000	NaN	NaN
27.000544	0.000523	5.229323	0.002801	968.673950	0.000000	NaN	NaN
28.500630	0.000498	4.980991	0.002785	968.659363	0.000000	NaN	NaN
29.999716	0.000597	5.974317	0.002998	968.864624	0.000000	NaN	NaN
31.500802	0.000622	6.222649	0.003224	969.083435	0.000000	NaN	NaN
33.000887	0.000622	6.222649	0.003653	969.497375	0.000000	NaN	NaN
34.500973	0.000581	5.808763	0.003986	969.819519	0.000000	NaN	NaN
36.000059	0.000664	6.636534	0.004452	970.268921	0.000000	NaN	NaN
37.500145	0.000780	7.795414	0.005112	970.906738	0.000000	NaN	NaN
39.000231	0.000763	7.629860	0.005608	971.385681	0.000000	NaN	NaN
40.500316	0.000746	7.464306	0.006176	971.934998	0.000000	NaN	NaN
42.008403	0.000796	7.960969	0.005171	970.964111	0.000000	NaN	NaN
43.500488	0.000821	8.209300	0.005773	971.544800	0.000000	NaN	NaN
44.999574	0.000680	6.802089	0.006252	972.007996	0.000000	NaN	NaN
46.500660	0.000788	7.878191	0.006583	972.327332	0.000000	NaN	NaN
48.000746	0.000796	7.960969	0.007117	972.843018	0.000000	NaN	NaN
49.500831	0.000846	8.457631	0.007667	973.374573	0.000000	NaN	NaN
51.000917	0.000895	8.954294	0.008111	973.803650	0.000000	NaN	NaN
52.501003	0.000970	9.699289	0.007988	973.685120	0.000000	NaN	NaN
54.000089	0.000978	9.782066	0.008472	974.152344	0.000000	NaN	NaN
55.501174	0.000978	9.782066	0.008939	974.603760	0.000000	NaN	NaN
56.999260	0.000962	9.616511	0.009289	974.941956	0.000000	NaN	NaN
58.500346	0.001028	10.278729	0.010001	975.629517	0.000000	NaN	NaN
60.000432	0.001061	10.609837	0.010319	975.936829	0.000000	NaN	NaN
61.500518	0.001127	11.272054	0.010869	976.467468	0.000000	NaN	NaN
63.000603	0.001152	11.520386	0.011385	976.965820	0.000000	NaN	NaN
64.499689	0.001086	10.858169	0.011763	977.331848	0.000000	NaN	NaN
66.000775	0.001210	12.099826	0.012249	977.800781	0.000000	NaN	NaN
67.500861	0.001160	11.603163	0.013631	979.136169	0.000000	NaN	NaN
69.000947	0.001442	14.417586	0.013932	979.426331	0.000000	NaN	NaN
70.501032	0.001284	12.844820	0.014620	980.091187	0.000000	NaN	NaN
72.000118	0.001293	12.927597	0.015100	980.554443	0.000000	NaN	NaN
73.501204	0.001318	13.175929	0.015515	980.955811	0.000000	NaN	NaN
75.000290	0.001342	13.424260	0.016032	981.455078	0.000000	NaN	NaN
76.500375	0.001475	14.748694	0.016441	981.850281	0.000000	NaN	NaN
77.999461	0.001483	14.831472	0.017208	982.591125	0.000000	NaN	NaN
79.499547	0.001525	15.245357	0.017560	982.931335	0.000000	NaN	NaN
80.999633	0.001450	14.500363	-1.000000	0.000000	0.000000	NaN	NaN
82.500719	0.001574	15.742020	0.018428	983.769531	0.000000	NaN	NaN
83.999804	0.001508	15.079803	0.018887	984.212463	0.000000	NaN	NaN
85.500890	0.001483	14.831472	0.019617	984.918518	0.000000	NaN	NaN
87.000976	0.001458	14.583140	0.020114	985.398499	0.000000	NaN	NaN
88.501062	0.001640	16.404237	0.021039	986.291687	0.000000	NaN	NaN
90.001148	0.001740	17.397563	0.021818	987.044250	0.000000	NaN	NaN
91.501233	0.001566	15.659243	0.022570	987.770569	0.000000	NaN	NaN
93.000319	0.001665	16.652569	0.023290	988.466248	0.000000	NaN	NaN
94.500405	0.001657	16.569792	0.023997	989.149170	0.000000	NaN	NaN
96.000491	0.001740	17.397563	0.024712	989.840027	0.000000	NaN	NaN
97.500577	0.001781	17.811449	0.025381	990.486328	0.000000	NaN	NaN
98.999662	0.001715	17.149232	-0.941833	56.187420	0.000000	NaN	NaN
100.500748	0.001823	18.225334	-0.941681	56.334766	0.000000	NaN	NaN
102.000834	0.001847	18.473666	-1.000000	0.000000	0.000000	NaN	NaN
103.499920	0.001707	17.066454	0.032084	996.960327	0.000000	NaN	NaN
105.000006	0.001765	17.645894	0.032788	997.640869	0.000000	NaN	NaN
106.501091	0.001839	18.390889	0.033332	998.166443	0.000000	NaN	NaN
108.000177	0.001856	18.556443	0.034144	998.951111	0.000000	NaN	NaN
109.500263	0.001789	17.894226	0.034853	999.635071	0.000000	NaN	NaN
111.000349	0.001897	18.970329	0.035554	1000.312561	0.000000	NaN	NaN
112.500435	0.001731	17.314786	0.036383	1001.113708	0.000000	NaN	NaN
114.000520	0.001897	18.970329	0.037041	1001.748840	0.000000	NaN	NaN
115.500606	0.001814	18.142557	0.037669	1002.355408	0.000000	NaN	NaN
116.999692	0.001839	18.390889	0.038254	1002.921387	0.000000	NaN	NaN
118.499778	0.001905	19.053106	0.038974	1003.616760	0.000000	NaN	NaN
119.999864	0.001856	18.556443	-1.000000	0.000000	0.000000	NaN	NaN
121.500949	0.001914	19.135883	0.039048	1003.688110	0.000000	NaN	NaN
123.001035	0.001823	18.225334	0.039778	1004.393311	0.000000	NaN	NaN
124.501121	0.001872	18.721997	0.040527	1005.116333	0.000000	NaN	NaN
126.001207	0.001839	18.390889	0.041178	1005.745544	0.000000	NaN	NaN
127.500293	0.001847	18.473666	0.041986	1006.525513	0.000000	NaN	NaN
129.000378	0.001781	17.811449	0.042592	1007.111389	0.000000	NaN	NaN
130.500464	0.001856	18.556443	0.043326	1007.820068	0.000000	NaN	NaN
131.999550	0.001847	18.473666	0.044054	1008.523132	0.000000	NaN	NaN
133.500636	0.001947	19.466992	0.044759	1009.204041	0.000000	NaN	NaN
135.000722	0.001988	19.880877	0.045509	1009.928711	0.000000	NaN	NaN
136.500807	0.001972	19.715323	0.046284	1010.677856	0.000000	NaN	NaN
138.000893	0.001938	19.384214	0.047057	1011.424438	0.000000	NaN	NaN
139.500979	0.002005	20.046432	0.047771	1012.113831	0.000000	NaN	NaN
141.000065	0.001947	19.466992	0.048538	1012.854797	0.000000	NaN	NaN
142.501151	0.001922	19.218660	0.049310	1013.600891	0.000000	NaN	NaN
144.000236	0.001880	18.804774	0.050091	1014.354614	0.000000	NaN	NaN
145.500322	0.002005	20.046432	0.049535	1013.817749	0.000000	NaN	NaN
146.999408	0.002071	20.708649	0.050268	1014.525940	0.000000	NaN	NaN
148.500494	0.001996	19.963654	0.051003	1015.236084	0.000000	NaN	NaN
150.000579	0.001955	19.549769	0.051879	1016.082031	0.000000	NaN	NaN
151.500665	0.001955	19.549769	0.052522	1016.703247	0.000000	NaN	NaN
152.999751	0.001955	19.549769	0.053449	1017.598450	0.000000	NaN	NaN
154.500837	0.001947	19.466992	0.054155	1018.280823	0.000000	NaN	NaN
155.999923	0.001938	19.384214	0.054904	1019.004639	0.000000	NaN	NaN
157.501008	0.002021	20.211986	0.055485	1019.565125	0.000000	NaN	NaN
159.001094	0.002013	20.129209	0.056186	1020.242676	0.000000	NaN	NaN
160.501180	0.001988	19.880877	0.056959	1020.989197	0.000000	NaN	NaN
161.999266	0.001980	19.798100	0.057769	1021.772034	0.000000	NaN	NaN
163.500352	0.001905	19.053106	0.058468	1022.446838	0.000000	NaN	NaN
165.000438	0.002029	20.294763	0.059234	1023.186584	0.000000	NaN	NaN
166.500523	0.001972	19.715323	0.059964	1023.891602	0.000000	NaN	NaN
167.999609	0.002096	20.956980	0.060714	1024.616211	0.000000	NaN	NaN
169.500695	0.002079	20.791426	0.061476	1025.352173	0.000000	NaN	NaN
171.000781	0.002178	21.784752	0.062334	1026.181519	0.000000	NaN	NaN
172.500866	0.001972	19.715323	0.063050	1026.873169	0.000000	NaN	NaN
174.000952	0.002079	20.791426	0.063869	1027.664307	0.000000	NaN	NaN
175.501038	0.002054	20.543094	0.064497	1028.270874	0.000000	NaN	NaN
177.001124	0.002054	20.543094	0.065432	1029.173584	0.000000	NaN	NaN
178.501210	0.002038	20.377540	0.066144	1029.861572	0.000000	NaN	NaN
180.000295	0.002121	21.205312	0.066867	1030.560425	0.000000	NaN	NaN
181.500381	0.002063	20.625872	0.067762	1031.424805	0.000000	NaN	NaN
183.000467	0.002112	21.122534	0.068412	1032.052124	0.000000	NaN	NaN
184.500553	0.002054	20.543094	0.069198	1032.811646	0.000000	NaN	NaN
186.000639	0.002021	20.211986	0.070009	1033.595093	0.000000	NaN	NaN
187.500724	0.002121	21.205312	0.070786	1034.345581	0.000000	NaN	NaN
188.999810	0.002087	20.874203	0.071540	1035.074219	0.000000	NaN	NaN
190.499896	0.002121	21.205312	0.072310	1035.817627	0.000000	NaN	NaN
191.999982	0.002063	20.625872	0.073040	1036.523315	0.000000	NaN	NaN
193.501068	0.002162	21.619197	0.073820	1037.276001	0.000000	NaN	NaN
195.000153	0.002162	21.619197	0.074548	1037.979614	0.000000	NaN	NaN
196.500239	0.002112	21.122534	0.075415	1038.817017	0.000000	NaN	NaN
197.999325	0.002137	21.370866	0.076162	1039.538330	0.000000	NaN	NaN
199.500411	0.002038	20.377540	0.076847	1040.200073	0.000000	NaN	NaN
200.999496	0.002112	21.122534	0.077561	1040.890015	0.000000	NaN	NaN
202.500582	0.002137	21.370866	0.078360	1041.662476	0.000000	NaN	NaN
204.000668	0.002170	21.701974	0.079117	1042.393311	0.000000	NaN	NaN
205.500754	0.002129	21.288089	0.079844	1043.095947	0.000000	NaN	NaN
206.999840	0.002154	21.536420	0.080709	1043.930786	0.000000	NaN	NaN
208.500925	0.002170	21.701974	0.081394	1044.593140	0.000000	NaN	NaN
210.000011	0.002162	21.619197	0.082126	1045.300049	0.000000	NaN	NaN
211.501097	0.002220	22.198637	0.082862	1046.010498	0.000000	NaN	NaN
213.001183	0.002203	22.033083	0.084397	1047.493774	0.000000	NaN	NaN
214.500269	0.002203	22.033083	0.085101	1048.173950	0.000000	NaN	NaN
215.999354	0.002121	21.205312	0.085823	1048.871338	0.000000	NaN	NaN
217.499440	0.002154	21.536420	0.086548	1049.571655	0.000000	NaN	NaN
219.000526	0.002178	21.784752	0.087328	1050.324463	0.000000	NaN	NaN
220.499612	0.002154	21.536420	0.088032	1051.004639	0.000000	NaN	NaN
221.999698	0.002187	21.867529	0.088903	1051.845825	0.000000	NaN	NaN
223.500783	0.002311	23.109186	0.089579	1052.499023	0.000000	NaN	NaN
225.000869	0.002195	21.950306	0.090429	1053.320557	0.000000	NaN	NaN
226.500955	0.002178	21.784752	0.091215	1054.079834	0.000000	NaN	NaN
228.001041	0.002212	22.115860	0.091806	1054.650146	0.000000	NaN	NaN
229.501127	0.002253	22.529746	0.092674	1055.489014	0.000000	NaN	NaN
231.000212	0.002228	22.281414	0.093314	1056.107544	0.000000	NaN	NaN
232.500298	0.002253	22.529746	0.094064	1056.831909	0.000000	NaN	NaN
233.999384	0.002228	22.281414	0.094809	1057.551514	0.000000	NaN	NaN
235.500470	0.002261	22.612523	0.095470	1058.189697	0.000000	NaN	NaN
236.999556	0.002303	23.026409	0.096338	1059.028076	0.000000	NaN	NaN
238.500641	0.002352	23.523072	0.097037	1059.703735	0.000000	NaN	NaN
240.000727	0.002369	23.688626	0.097779	1060.420532	0.000000	NaN	NaN
241.500813	0.002145	21.453643	0.098564	1061.178833	0.000000	NaN	NaN
243.000899	0.002203	22.033083	0.099250	1061.841064	0.000000	NaN	NaN
244.500985	0.002311	23.109186	0.099890	1062.459351	0.000000	NaN	NaN
246.000070	0.002369	23.688626	0.100698	1063.239746	0.000000	NaN	NaN
247.501156	0.002294	22.943632	0.101429	1063.946289	0.000000	NaN	NaN
249.000242	0.002270	22.695300	0.102287	1064.775146	0.000000	NaN	NaN
250.500328	0.002286	22.860854	0.102912	1065.378174	0.000000	NaN	NaN
252.000414	0.002261	22.612523	0.103658	1066.099121	0.000000	NaN	NaN
253.500499	0.002228	22.281414	0.104364	1066.780640	0.000000	NaN	NaN
255.000585	0.002261	22.612523	0.105097	1067.489014	0.000000	NaN	NaN
256.500671	0.002394	23.936957	0.105888	1068.253662	0.000000	NaN	NaN
257.999757	0.002253	22.529746	0.105235	1067.622803	0.000000	NaN	NaN
259.499842	0.002286	22.860854	0.105931	1068.294556	0.000000	NaN	NaN
261.000928	0.002303	23.026409	0.106726	1069.062622	0.000000	NaN	NaN
262.501014	0.002344	23.440294	0.107437	1069.749756	0.000000	NaN	NaN
264.001100	0.002236	22.364192	0.108173	1070.460449	0.000000	NaN	NaN
265.501186	0.002303	23.026409	0.108869	1071.133179	0.000000	NaN	NaN
267.000271	0.002336	23.357517	0.109679	1071.914673	0.000000	NaN	NaN
268.500357	0.002294	22.943632	0.110291	1072.506836	0.000000	NaN	NaN
270.000443	0.002303	23.026409	0.111065	1073.254028	0.000000	NaN	NaN
271.500529	0.002319	23.191963	0.111737	1073.903564	0.000000	NaN	NaN
272.999615	0.002319	23.191963	0.112469	1074.610474	0.000000	NaN	NaN
274.500700	0.002319	23.191963	0.113028	1075.150391	0.000000	NaN	NaN
276.000786	0.002427	24.268066	0.113815	1075.910645	0.000000	NaN	NaN
277.500872	0.002303	23.026409	0.114650	1076.716553	0.000000	NaN	NaN
278.999958	0.002468	24.681952	0.115346	1077.389160	0.000000	NaN	NaN
280.501044	0.002402	24.019734	0.116102	1078.119629	0.000000	NaN	NaN
282.001129	0.002394	23.936957	0.116789	1078.783325	0.000000	NaN	NaN
283.501215	0.002419	24.185289	0.117589	1079.555542	0.000000	NaN	NaN
285.000301	0.002369	23.688626	0.118250	1080.194824	0.000000	NaN	NaN
286.500387	0.002394	23.936957	0.119090	1081.006104	0.000000	NaN	NaN
288.000473	0.002385	23.854180	0.119681	1081.577271	0.000000	NaN	NaN
289.500558	0.002427	24.268066	0.120430	1082.300781	0.000000	NaN	NaN
291.000644	0.002443	24.433620	0.121121	1082.967407	0.000000	NaN	NaN
292.500730	0.002394	23.936957	0.121914	1083.733398	0.000000	NaN	NaN
294.000816	0.002394	23.936957	0.122537	1084.335327	0.000000	NaN	NaN
295.500902	0.002319	23.191963	0.123328	1085.100098	0.000000	NaN	NaN
297.000988	0.002402	24.019734	0.124074	1085.819946	0.000000	NaN	NaN
298.501073	0.002543	25.426946	0.124701	1086.425537	0.000000	NaN	NaN
300.000159	0.002410	24.102512	0.125502	1087.199829	0.000000	NaN	NaN
301.499245	0.002427	24.268066	0.126032	1087.712036	0.000000	NaN	NaN
303.000331	0.002394	23.936957	0.126693	1088.350586	0.000000	NaN	NaN
304.500416	0.002435	24.350843	0.127419	1089.051514	0.000000	NaN	NaN
305.999502	0.002319	23.191963	0.128182	1089.788086	0.000000	NaN	NaN
307.500588	0.002435	24.350843	0.128884	1090.466553	0.000000	NaN	NaN
308.999674	0.002443	24.433620	0.129553	1091.113281	0.000000	NaN	NaN
310.500760	0.002543	25.426946	0.130276	1091.810913	0.000000	NaN	NaN
312.000845	0.002443	24.433620	0.131042	1092.551025	0.000000	NaN	NaN
313.500931	0.002460	24.599174	0.131658	1093.146118	0.000000	NaN	NaN
315.000017	0.002452	24.516397	0.132401	1093.863525	0.000000	NaN	NaN
316.501103	0.002468	24.681952	0.133154	1094.591064	0.000000	NaN	NaN
318.001189	0.002493	24.930283	0.133781	1095.196899	0.000000	NaN	NaN
319.500274	0.002303	23.026409	0.134447	1095.840088	0.000000	NaN	NaN
321.000360	0.002427	24.268066	0.135208	1096.575073	0.000000	NaN	NaN
322.500446	0.002493	24.930283	0.135961	1097.302490	0.000000	NaN	NaN
324.000532	0.002534	25.344169	0.136491	1097.814697	0.000000	NaN	NaN
325.500617	0.002435	24.350843	0.137255	1098.553101	0.000000	NaN	NaN
327.000703	0.002468	24.681952	0.137944	1099.218506	0.000000	NaN	NaN
328.500789	0.002476	24.764729	0.138640	1099.890381	0.000000	NaN	NaN
330.000875	0.002493	24.930283	0.139381	1100.605957	0.000000	NaN	NaN
331.500961	0.002419	24.185289	0.139985	1101.190186	0.000000	NaN	NaN
333.001046	0.002394	23.936957	0.140614	1101.797363	0.000000	NaN	NaN
334.501132	0.002534	25.344169	0.141448	1102.603394	0.000000	NaN	NaN
336.001218	0.002435	24.350843	0.142118	1103.250366	0.000000	NaN	NaN
337.500304	0.002485	24.847506	0.142815	1103.923706	0.000000	NaN	NaN
339.000390	0.002601	26.006386	0.143522	1104.606323	0.000000	NaN	NaN
340.500475	0.002609	26.089163	0.144337	1105.393799	0.000000	NaN	NaN
341.999561	0.002526	25.261392	0.145015	1106.048218	0.000000	NaN	NaN
343.500647	0.002518	25.178614	0.145667	1106.678223	0.000000	NaN	NaN
345.000733	0.002526	25.261392	0.146310	1107.299194	0.000000	NaN	NaN
346.500819	0.002642	26.420272	0.147131	1108.092896	0.000000	NaN	NaN
347.999904	0.002476	24.764729	0.147769	1108.709106	0.000000	NaN	NaN
349.499990	0.002543	25.426946	0.148545	1109.458496	0.000000	NaN	NaN
351.002076	0.002534	25.344169	0.149193	1110.084839	0.000000	NaN	NaN
352.501162	0.002559	25.592500	0.149737	1110.609497	0.000000	NaN	NaN
354.000248	0.002485	24.847506	0.150384	1111.235229	0.000000	NaN	NaN
355.499333	0.002609	26.089163	0.151217	1112.039062	0.000000	NaN	NaN
356.999419	0.002510	25.095837	0.151881	1112.680542	0.000000	NaN	NaN
358.500505	0.002534	25.344169	0.152592	1113.367676	0.000000	NaN	NaN
360.000591	0.002510	25.095837	0.153383	1114.132324	0.000000	NaN	NaN
361.500677	0.002601	26.006386	0.154143	1114.866455	0.000000	NaN	NaN
363.000762	0.002476	24.764729	0.154842	1115.541260	0.000000	NaN	NaN
364.499848	0.002543	25.426946	0.155535	1116.210449	0.000000	NaN	NaN
365.999934	0.002551	25.509723	0.156235	1116.886475	0.000000	NaN	NaN
367.501020	0.002609	26.089163	0.156995	1117.620483	0.000000	NaN	NaN
369.001106	0.002584	25.840832	0.157700	1118.302002	0.000000	NaN	NaN
370.500191	0.002559	25.592500	0.158266	1118.848389	0.000000	NaN	NaN
371.999277	0.002526	25.261392	0.159064	1119.619629	0.000000	NaN	NaN
373.500363	0.002634	26.337494	0.159753	1120.284912	0.000000	NaN	NaN
375.000449	0.002568	25.675277	0.161354	1121.831177	0.000000	NaN	NaN
376.500535	0.002675	26.751380	0.162083	1122.535522	0.000000	NaN	NaN
378.000620	0.002642	26.420272	0.162822	1123.249390	0.000000	NaN	NaN
379.500706	0.002700	26.999712	0.163495	1123.899536	0.000000	NaN	NaN
381.000792	0.002601	26.006386	0.164207	1124.587280	0.000000	NaN	NaN
382.500878	0.002568	25.675277	0.164980	1125.334351	0.000000	NaN	NaN
384.000964	0.002634	26.337494	0.165714	1126.043579	0.000000	NaN	NaN
385.501049	0.002568	25.675277	0.166398	1126.703857	0.000000	NaN	NaN
387.001135	0.002634	26.337494	0.167052	1127.335205	0.000000	NaN	NaN
388.501221	0.002741	27.413597	0.167857	1128.112915	0.000000	NaN	NaN
389.999307	0.002576	25.758054	0.168579	1128.811157	0.000000	NaN	NaN
391.500392	0.002750	27.496374	0.169348	1129.553345	0.000000	NaN	NaN
393.000478	0.002683	26.834157	0.170078	1130.258789	0.000000	NaN	NaN
394.500564	0.002683	26.834157	0.170790	1130.946411	0.000000	NaN	NaN
395.999650	0.002642	26.420272	0.171496	1131.628662	0.000000	NaN	NaN
397.500736	0.002543	25.426946	0.172245	1132.352173	0.000000	NaN	NaN
399.000821	0.002741	27.413597	0.172932	1133.015747	0.000000	NaN	NaN
400.500907	0.002634	26.337494	0.173656	1133.715332	0.000000	NaN	NaN
402.000993	0.002700	26.999712	0.174404	1134.437012	0.000000	NaN	NaN
403.501079	0.002733	27.330820	0.175032	1135.044189	0.000000	NaN	NaN
405.000165	0.002758	27.579152	0.175676	1135.666016	0.000000	NaN	NaN
406.500250	0.002592	25.923609	0.176479	1136.442261	0.000000	NaN	NaN
408.000336	0.002625	26.254717	0.177272	1137.207642	0.000000	NaN	NaN
409.500422	0.002568	25.675277	0.177916	1137.829712	0.000000	NaN	NaN
410.999508	0.002733	27.330820	0.178695	1138.582397	0.000000	NaN	NaN
412.500594	0.002625	26.254717	0.179261	1139.129150	0.000000	NaN	NaN
414.000679	0.002717	27.165266	0.180026	1139.868408	0.000000	NaN	NaN
415.500765	0.002700	26.999712	0.180689	1140.508545	0.000000	NaN	NaN
417.000851	0.002683	26.834157	0.181343	1141.140381	0.000000	NaN	NaN
418.500937	0.002617	26.171940	0.182143	1141.913330	0.000000	NaN	NaN
420.001023	0.002675	26.751380	0.182750	1142.499146	0.000000	NaN	NaN
421.501108	0.002667	26.668603	0.183468	1143.192627	0.000000	NaN	NaN
423.001194	0.002675	26.751380	0.184135	1143.837280	0.000000	NaN	NaN
424.500280	0.002584	25.840832	0.184892	1144.568604	0.000000	NaN	NaN
425.999366	0.002683	26.834157	0.185636	1145.287109	0.000000	NaN	NaN
427.500452	0.002667	26.668603	0.186319	1145.946777	0.000000	NaN	NaN
429.000537	0.002659	26.585826	0.187078	1146.680176	0.000000	NaN	NaN
430.500623	0.002493	24.930283	0.187719	1147.299805	0.000000	NaN	NaN
431.999709	0.002609	26.089163	0.188437	1147.992554	0.000000	NaN	NaN
433.500795	0.002741	27.413597	0.189040	1148.575195	0.000000	NaN	NaN
435.000881	0.002733	27.330820	0.189804	1149.313599	0.000000	NaN	NaN
436.500966	0.002733	27.330820	0.190570	1150.053711	0.000000	NaN	NaN
438.000052	0.002857	28.572477	0.191150	1150.613525	0.000000	NaN	NaN
439.501138	0.002576	25.758054	0.191825	1151.265991	0.000000	NaN	NaN
441.001224	0.002783	27.827483	0.192547	1151.963379	0.000000	NaN	NaN
442.500309	0.002750	27.496374	0.193180	1152.574585	0.000000	NaN	NaN
444.000395	0.002750	27.496374	0.193932	1153.301147	0.000000	NaN	NaN
445.500481	0.002675	26.751380	0.194643	1153.987305	0.000000	NaN	NaN
447.000567	0.002816	28.158592	0.195158	1154.484741	0.000000	NaN	NaN
448.500653	0.002667	26.668603	0.195952	1155.252441	0.000000	NaN	NaN
450.000739	0.002758	27.579152	0.196603	1155.880615	0.000000	NaN	NaN
451.500824	0.002675	26.751380	0.197319	1156.572876	0.000000	NaN	NaN
452.999910	0.002708	27.082489	0.198017	1157.247070	0.000000	NaN	NaN
454.499996	0.002750	27.496374	0.198696	1157.902954	0.000000	NaN	NaN
456.001082	0.002667	26.668603	0.199484	1158.663818	0.000000	NaN	NaN
457.501167	0.002717	27.165266	0.200065	1159.224731	0.000000	NaN	NaN
459.000253	0.002659	26.585826	0.200716	1159.854492	0.000000	NaN	NaN
460.500339	0.002717	27.165266	0.201467	1160.579346	0.000000	NaN	NaN
462.000425	0.002766	27.661929	0.202191	1161.278442	0.000000	NaN	NaN
463.538513	0.002659	26.585826	0.202821	1161.886963	0.000000	NaN	NaN
464.999596	0.002717	27.165266	0.203428	1162.473999	0.000000	NaN	NaN
466.499682	0.002708	27.082489	0.204202	1163.221680	0.000000	NaN	NaN
467.999768	0.002832	28.324146	0.204885	1163.881470	0.000000	NaN	NaN
469.499854	0.002857	28.572477	-1.000000	0.000000	0.000000	NaN	NaN
471.000940	0.002874	28.738031	0.203594	1162.634399	0.000000	NaN	NaN
472.501025	0.002725	27.248043	0.204342	1163.357056	0.000000	NaN	NaN
474.001111	0.002791	27.910260	0.204993	1163.985840	0.000000	NaN	NaN
475.501197	0.002717	27.165266	0.205727	1164.694214	0.000000	NaN	NaN
477.000283	0.002741	27.413597	0.206487	1165.428833	0.000000	NaN	NaN
478.500369	0.002849	28.489700	0.207107	1166.027710	0.000000	NaN	NaN
479.999454	0.002617	26.171940	0.207809	1166.706055	0.000000	NaN	NaN
481.500540	0.002783	27.827483	0.208448	1167.323242	0.000000	NaN	NaN
482.999626	0.002824	28.241369	0.209236	1168.083984	0.000000	NaN	NaN
484.500712	0.002741	27.413597	0.209840	1168.667236	0.000000	NaN	NaN
486.000798	0.002717	27.165266	0.210688	1169.486572	0.000000	NaN	NaN
487.500883	0.002808	28.075814	0.211384	1170.159058	0.000000	NaN	NaN
489.000969	0.002758	27.579152	0.211891	1170.648804	0.000000	NaN	NaN
490.501055	0.002890	28.903586	0.212603	1171.336792	0.000000	NaN	NaN
492.000141	0.002890	28.903586	0.213224	1171.936646	0.000000	NaN	NaN
493.501227	0.002874	28.738031	0.213552	1172.253052	0.000000	NaN	NaN
494.999312	0.002832	28.324146	0.214290	1172.966431	0.000000	NaN	NaN
496.500398	0.002915	29.151917	0.214979	1173.632080	0.000000	NaN	NaN
497.999484	0.002816	28.158592	0.215546	1174.179077	0.000000	NaN	NaN
499.500570	0.002874	28.738031	0.216271	1174.880127	0.000000	NaN	NaN
501.000656	0.002799	27.993037	0.216863	1175.451904	0.000000	NaN	NaN
502.499741	0.002857	28.572477	0.217618	1176.181152	0.000000	NaN	NaN
504.000827	0.002915	29.151917	0.218252	1176.793335	0.000000	NaN	NaN
505.500913	0.002733	27.330820	0.218924	1177.442383	0.000000	NaN	NaN
507.000999	0.002758	27.579152	0.219543	1178.040283	0.000000	NaN	NaN
508.501085	0.002758	27.579152	0.220220	1178.694458	0.000000	NaN	NaN
510.000170	0.002791	27.910260	0.220948	1179.397461	0.000000	NaN	NaN
511.500256	0.002824	28.241369	0.221614	1180.040527	0.000000	NaN	NaN
513.000342	0.002990	29.896911	0.222211	1180.617554	0.000000	NaN	NaN
514.500428	0.002948	29.483026	0.222793	1181.179810	0.000000	NaN	NaN
515.999514	0.002857	28.572477	0.223481	1181.844360	0.000000	NaN	NaN
517.500599	0.002774	27.744706	0.224183	1182.522095	0.000000	NaN	NaN
519.000685	0.002774	27.744706	0.224862	1183.178589	0.000000	NaN	NaN
520.500771	0.002981	29.814134	0.225546	1183.838989	0.000000	NaN	NaN
521.999857	0.002816	28.158592	0.226223	1184.492554	0.000000	NaN	NaN
523.500942	0.002907	29.069140	0.226858	1185.106567	0.000000	NaN	NaN
525.001028	0.002890	28.903586	0.227497	1185.723145	0.000000	NaN	NaN
526.501114	0.002758	27.579152	0.228057	1186.264404	0.000000	NaN	NaN
528.001200	0.002932	29.317471	0.228852	1187.032959	0.000000	NaN	NaN
529.500286	0.002857	28.572477	0.229668	1187.820801	0.000000	NaN	NaN
531.000372	0.002932	29.317471	0.230187	1188.322388	0.000000	NaN	NaN
532.500457	0.002907	29.069140	0.230756	1188.872070	0.000000	NaN	NaN
534.000543	0.002808	28.075814	0.231527	1189.616699	0.000000	NaN	NaN
535.500629	0.002890	28.903586	0.232239	1190.303955	0.000000	NaN	NaN
536.999715	0.002866	28.655254	0.232887	1190.930298	0.000000	NaN	NaN
538.500800	0.002957	29.565803	0.233625	1191.643188	0.000000	NaN	NaN
540.000886	0.002907	29.069140	0.234237	1192.234253	0.000000	NaN	NaN
541.500972	0.002965	29.648580	0.235008	1192.979370	0.000000	NaN	NaN
543.000058	0.002866	28.655254	0.235627	1193.576538	0.000000	NaN	NaN
544.501144	0.002957	29.565803	0.236349	1194.273926	0.000000	NaN	NaN
546.000229	0.002890	28.903586	0.237055	1194.956055	0.000000	NaN	NaN
547.500315	0.002973	29.731357	0.237710	1195.589355	0.000000	NaN	NaN
548.999401	0.002940	29.400249	0.238167	1196.030884	0.000000	NaN	NaN
550.500487	0.002990	29.896911	0.238850	1196.690552	0.000000	NaN	NaN
552.000573	0.002907	29.069140	0.239587	1197.402100	0.000000	NaN	NaN
553.500658	0.002981	29.814134	0.240299	1198.090454	0.000000	NaN	NaN
555.000744	0.002899	28.986363	0.240910	1198.680176	0.000000	NaN	NaN
556.500830	0.002948	29.483026	0.241552	1199.299927	0.000000	NaN	NaN
557.999916	0.002948	29.483026	0.242258	1199.982544	0.000000	NaN	NaN
559.501002	0.002832	28.324146	0.242962	1200.662842	0.000000	NaN	NaN
561.001087	0.002957	29.565803	0.243591	1201.269653	0.000000	NaN	NaN
562.501173	0.003006	30.062466	0.244242	1201.898560	0.000000	NaN	NaN
563.999259	0.002899	28.986363	0.244926	1202.559814	0.000000	NaN	NaN
565.499345	0.002874	28.738031	0.245421	1203.037598	0.000000	NaN	NaN
567.000430	0.002832	28.324146	0.246072	1203.666260	0.000000	NaN	NaN
568.499516	0.002965	29.648580	0.246803	1204.372681	0.000000	NaN	NaN
569.999602	0.003006	30.062466	0.247459	1205.006348	0.000000	NaN	NaN
571.499688	0.002948	29.483026	0.248231	1205.751709	0.000000	NaN	NaN
573.000774	0.002998	29.979689	0.248953	1206.449585	0.000000	NaN	NaN
574.500859	0.002965	29.648580	0.249561	1207.036621	0.000000	NaN	NaN
575.999945	0.002998	29.979689	0.250316	1207.765625	0.000000	NaN	NaN
577.501031	0.002998	29.979689	0.250999	1208.425659	0.000000	NaN	NaN
579.000117	0.002882	28.820809	0.251658	1209.062866	0.000000	NaN	NaN
580.501203	0.003064	30.641906	0.252384	1209.763916	0.000000	NaN	NaN
582.002289	0.002948	29.483026	0.252948	1210.308472	0.000000	NaN	NaN
583.500374	0.003048	30.476351	0.253691	1211.026245	0.000000	NaN	NaN
585.139468	0.002965	29.648580	0.254237	1211.553467	0.000000	NaN	NaN
586.500546	0.002932	29.317471	0.255036	1212.325806	0.000000	NaN	NaN
588.005632	0.002915	29.151917	0.255788	1213.052368	0.000000	NaN	NaN
589.500717	0.003039	30.393574	0.256507	1213.746460	0.000000	NaN	NaN
590.999803	0.002990	29.896911	0.257124	1214.342285	0.000000	NaN	NaN
592.500889	0.003097	30.973014	0.257723	1214.921265	0.000000	NaN	NaN
594.008975	0.002932	29.317471	0.258412	1215.586548	0.000000	NaN	NaN
595.501061	0.002932	29.317471	0.259017	1216.170532	0.000000	NaN	NaN
597.001147	0.003048	30.476351	0.259799	1216.926514	0.000000	NaN	NaN
598.501232	0.003048	30.476351	0.260547	1217.649048	0.000000	NaN	NaN
600.012319	0.002940	29.400249	0.261139	1218.220459	0.000000	NaN	NaN
601.500404	0.002907	29.069140	0.261909	1218.964478	0.000000	NaN	NaN
602.999490	0.003081	30.807460	0.262629	1219.659668	0.000000	NaN	NaN
604.500575	0.002973	29.731357	0.263306	1220.313721	0.000000	NaN	NaN
606.014662	0.002981	29.814134	0.263944	1220.930542	0.000000	NaN	NaN
607.500747	0.003056	30.559129	-1.000000	0.000000	0.000000	NaN	NaN
609.000833	0.003130	31.304123	0.266647	1223.541382	0.000000	NaN	NaN
610.499919	0.003081	30.807460	0.267277	1224.150391	0.000000	NaN	NaN
612.001004	0.002932	29.317471	0.267994	1224.842285	0.000000	NaN	NaN
613.501090	0.002990	29.896911	0.268546	1225.375244	0.000000	NaN	NaN
615.000176	0.003006	30.062466	0.269236	1226.042480	0.000000	NaN	NaN
616.500262	0.003031	30.310797	0.269848	1226.633545	0.000000	NaN	NaN
617.999347	0.002923	29.234694	0.270513	1227.275391	0.000000	NaN	NaN
619.500433	0.003023	30.228020	0.271236	1227.974121	0.000000	NaN	NaN
620.999519	0.003048	30.476351	0.272005	1228.716919	0.000000	NaN	NaN
622.500605	0.002907	29.069140	0.272628	1229.318604	0.000000	NaN	NaN
624.000691	0.002973	29.731357	0.273273	1229.941406	0.000000	NaN	NaN
625.500777	0.003106	31.055791	0.273916	1230.562866	0.000000	NaN	NaN
627.000862	0.003039	30.393574	0.274559	1231.183838	0.000000	NaN	NaN
628.500948	0.003089	30.890237	0.275360	1231.958130	0.000000	NaN	NaN
630.001034	0.003039	30.393574	0.276010	1232.585815	0.000000	NaN	NaN
631.501120	0.002965	29.648580	0.276626	1233.180298	0.000000	NaN	NaN
633.001206	0.002973	29.731357	0.277226	1233.760620	0.000000	NaN	NaN
634.500291	0.003122	31.221346	0.277984	1234.493042	0.000000	NaN	NaN
636.000377	0.003072	30.724683	0.278582	1235.069946	0.000000	NaN	NaN
637.500463	0.003048	30.476351	0.279264	1235.729370	0.000000	NaN	NaN
639.000549	0.003081	30.807460	0.279972	1236.412842	0.000000	NaN	NaN
640.499634	0.003081	30.807460	0.280596	1237.015259	0.000000	NaN	NaN
642.000720	0.003006	30.062466	0.281302	1237.697388	0.000000	NaN	NaN
643.500806	0.003106	31.055791	0.281986	1238.358032	0.000000	NaN	NaN
645.000892	0.003031	30.310797	0.282719	1239.066772	0.000000	NaN	NaN
646.500978	0.003114	31.138569	0.283326	1239.652588	0.000000	NaN	NaN
648.001063	0.003023	30.228020	0.284022	1240.325317	0.000000	NaN	NaN
649.501149	0.003081	30.807460	0.284719	1240.997803	0.000000	NaN	NaN
651.001235	0.003039	30.393574	0.285334	1241.592773	0.000000	NaN	NaN
652.500321	0.002940	29.400249	0.286023	1242.258423	0.000000	NaN	NaN
653.999407	0.003072	30.724683	0.286578	1242.793701	0.000000	NaN	NaN
655.500492	0.003089	30.890237	0.287276	1243.468262	0.000000	NaN	NaN
657.000578	0.003155	31.552454	0.288026	1244.193237	0.000000	NaN	NaN
658.500664	0.003089	30.890237	0.288601	1244.748657	0.000000	NaN	NaN
659.999750	0.002948	29.483026	0.289289	1245.412354	0.000000	NaN	NaN
661.500836	0.003023	30.228020	0.289919	1246.021606	0.000000	NaN	NaN
663.000921	0.003122	31.221346	0.290571	1246.650879	0.000000	NaN	NaN
664.501007	0.003031	30.310797	0.291338	1247.392334	0.000000	NaN	NaN
666.001093	0.003130	31.304123	0.291971	1248.003906	0.000000	NaN	NaN
667.501179	0.003048	30.476351	0.292497	1248.511353	0.000000	NaN	NaN
669.000265	0.003097	30.973014	0.293163	1249.155151	0.000000	NaN	NaN
670.500350	0.003089	30.890237	0.293803	1249.773437	0.000000	NaN	NaN
672.000436	0.003097	30.973014	0.294515	1250.461304	0.000000	NaN	NaN
673.500522	0.003139	31.386900	0.295226	1251.148071	0.000000	NaN	NaN
674.999608	0.003081	30.807460	0.295941	1251.838745	0.000000	NaN	NaN
676.500694	0.003155	31.552454	0.296471	1252.350586	0.000000	NaN	NaN
678.000779	0.003172	31.718009	0.297163	1253.018555	0.000000	NaN	NaN
679.500865	0.003130	31.304123	0.297887	1253.718262	0.000000	NaN	NaN
681.000951	0.003089	30.890237	0.298587	1254.394287	0.000000	NaN	NaN
682.501037	0.003081	30.807460	0.299202	1254.988403	0.000000	NaN	NaN
684.001123	0.003089	30.890237	0.299766	1255.533203	0.000000	NaN	NaN
685.501208	0.003064	30.641906	0.300498	1256.240845	0.000000	NaN	NaN
686.999294	0.003097	30.973014	0.301138	1256.858643	0.000000	NaN	NaN
688.500380	0.003172	31.718009	0.301795	1257.493042	0.000000	NaN	NaN
690.000466	0.003172	31.718009	0.302443	1258.118774	0.000000	NaN	NaN
691.500551	0.003130	31.304123	0.303138	1258.790283	0.000000	NaN	NaN
693.000637	0.003164	31.635231	0.303769	1259.400513	0.000000	NaN	NaN
694.500723	0.003238	32.380226	0.304407	1260.015991	0.000000	NaN	NaN
696.000809	0.003230	32.297449	0.305094	1260.679443	0.000000	NaN	NaN
697.500895	0.003081	30.807460	0.305788	1261.349976	0.000000	NaN	NaN
699.000980	0.003279	32.794111	0.306453	1261.992920	0.000000	NaN	NaN
700.501066	0.003180	31.800786	0.307048	1262.567627	0.000000	NaN	NaN
702.000152	0.003288	32.876889	0.307622	1263.121582	0.000000	NaN	NaN
703.500238	0.003155	31.552454	0.308300	1263.776855	0.000000	NaN	NaN
705.000324	0.003023	30.228020	0.308972	1264.425903	0.000000	NaN	NaN
706.500409	0.003172	31.718009	0.309655	1265.085815	0.000000	NaN	NaN
708.000495	0.003230	32.297449	0.310307	1265.715820	0.000000	NaN	NaN
709.499581	0.003139	31.386900	0.310926	1266.313477	0.000000	NaN	NaN
710.999667	0.003230	32.297449	0.311579	1266.944458	0.000000	NaN	NaN
712.500753	0.003213	32.131894	0.312156	1267.501709	0.000000	NaN	NaN
714.000838	0.003205	32.049117	0.312911	1268.230835	0.000000	NaN	NaN
715.500924	0.003180	31.800786	0.313541	1268.839844	0.000000	NaN	NaN
717.000010	0.003155	31.552454	0.314163	1269.440552	0.000000	NaN	NaN
718.501096	0.003263	32.628557	0.314782	1270.038330	0.000000	NaN	NaN
720.001182	0.003155	31.552454	0.315468	1270.701050	0.000000	NaN	NaN
721.500267	0.003230	32.297449	0.316176	1271.384888	0.000000	NaN	NaN
722.999353	0.003180	31.800786	0.316830	1272.016724	0.000000	NaN	NaN
724.500439	0.003155	31.552454	0.317496	1272.659912	0.000000	NaN	NaN
726.000525	0.003213	32.131894	0.318168	1273.308594	0.000000	NaN	NaN
727.500611	0.003230	32.297449	0.318818	1273.937012	0.000000	NaN	NaN
728.999696	0.003130	31.304123	0.319365	1274.465332	0.000000	NaN	NaN
730.500782	0.003197	31.966340	0.320122	1275.196533	0.000000	NaN	NaN
731.999868	0.003106	31.055791	0.320774	1275.826416	0.000000	NaN	NaN
733.500954	0.003288	32.876889	0.321499	1276.526733	0.000000	NaN	NaN
735.001040	0.003197	31.966340	0.322107	1277.114136	0.000000	NaN	NaN
736.500125	0.003172	31.718009	0.322847	1277.828857	0.000000	NaN	NaN
738.000211	0.003271	32.711334	0.323467	1278.427856	0.000000	NaN	NaN
739.500297	0.003238	32.380226	0.324209	1279.144775	0.000000	NaN	NaN
741.000383	0.003246	32.463003	0.324887	1279.799561	0.000000	NaN	NaN
742.500469	0.003230	32.297449	0.325364	1280.260010	0.000000	NaN	NaN
744.000554	0.003296	32.959666	0.326008	1280.882080	0.000000	NaN	NaN
745.499640	0.003213	32.131894	0.326707	1281.557739	0.000000	NaN	NaN
747.000726	0.003279	32.794111	0.327349	1282.177368	0.000000	NaN	NaN
748.500812	0.003221	32.214671	0.328136	1282.937378	0.000000	NaN	NaN
749.999897	0.003147	31.469677	0.328795	1283.574463	0.000000	NaN	NaN
751.500983	0.003263	32.628557	0.329409	1284.167358	0.000000	NaN	NaN
753.001069	0.003155	31.552454	0.330119	1284.853271	0.000000	NaN	NaN
754.501155	0.003213	32.131894	0.330801	1285.512085	0.000000	NaN	NaN
755.999241	0.003213	32.131894	0.331360	1286.052490	0.000000	NaN	NaN
757.500326	0.003329	33.290774	0.332115	1286.781372	0.000000	NaN	NaN
758.999412	0.003420	34.201323	0.332850	1287.491211	0.000000	NaN	NaN
760.500498	0.003147	31.469677	0.333427	1288.049072	0.000000	NaN	NaN
762.000584	0.003337	33.373551	0.334177	1288.773560	0.000000	NaN	NaN
763.500670	0.003188	31.883563	0.334741	1289.318481	0.000000	NaN	NaN
765.000755	0.003230	32.297449	0.335509	1290.060059	0.000000	NaN	NaN
766.500841	0.003288	32.876889	0.336233	1290.759766	0.000000	NaN	NaN
768.000927	0.003296	32.959666	0.336865	1291.369873	0.000000	NaN	NaN
769.501013	0.003230	32.297449	0.337585	1292.064941	0.000000	NaN	NaN
771.001099	0.003313	33.125220	0.338371	1292.824219	0.000000	NaN	NaN
772.501184	0.003346	33.456329	0.339043	1293.473389	0.000000	NaN	NaN
774.000270	0.003304	33.042443	0.339849	1294.252319	0.000000	NaN	NaN
775.500356	0.003263	32.628557	0.340482	1294.863159	0.000000	NaN	NaN
777.000442	0.003288	32.876889	0.341263	1295.618286	0.000000	NaN	NaN
778.500528	0.003304	33.042443	0.341744	1296.083130	0.000000	NaN	NaN
779.999613	0.003321	33.207997	0.342630	1296.938599	0.000000	NaN	NaN
781.500699	0.003313	33.125220	0.343300	1297.586182	0.000000	NaN	NaN
783.000785	0.003321	33.207997	0.343888	1298.153687	0.000000	NaN	NaN
784.500871	0.003238	32.380226	0.344655	1298.894653	0.000000	NaN	NaN
785.999957	0.003263	32.628557	0.345398	1299.612549	0.000000	NaN	NaN
787.500042	0.003271	32.711334	0.346017	1300.209961	0.000000	NaN	NaN
789.001128	0.003346	33.456329	0.346784	1300.950928	0.000000	NaN	NaN
790.501214	0.003304	33.042443	0.347548	1301.689209	0.000000	NaN	NaN
791.999300	0.003304	33.042443	0.348234	1302.352051	0.000000	NaN	NaN
793.500386	0.003230	32.297449	0.349013	1303.104736	0.000000	NaN	NaN
794.999471	0.003304	33.042443	0.349632	1303.702026	0.000000	NaN	NaN
796.500557	0.003296	32.959666	0.350302	1304.349121	0.000000	NaN	NaN
797.999643	0.003296	32.959666	0.351065	1305.086304	0.000000	NaN	NaN
799.500729	0.003370	33.704660	0.351862	1305.856079	0.000000	NaN	NaN
800.999814	0.003370	33.704660	0.352483	1306.456177	0.000000	NaN	NaN
802.500900	0.003246	32.463003	0.353358	1307.301636	0.000000	NaN	NaN
804.000986	0.003304	33.042443	0.354021	1307.942017	0.000000	NaN	NaN
805.500072	0.003304	33.042443	0.354673	1308.571411	0.000000	NaN	NaN
807.000158	0.003304	33.042443	0.355356	1309.231567	0.000000	NaN	NaN
808.500243	0.003279	32.794111	0.356090	1309.940063	0.000000	NaN	NaN
810.000329	0.003321	33.207997	0.356815	1310.640503	0.000000	NaN	NaN
811.500415	0.003304	33.042443	0.357579	1311.378662	0.000000	NaN	NaN
812.999501	0.003188	31.883563	0.358252	1312.028687	0.000000	NaN	NaN
814.500587	0.003263	32.628557	0.358942	1312.695557	0.000000	NaN	NaN
816.000672	0.003445	34.449654	0.359694	1313.421631	0.000000	NaN	NaN
817.500758	0.003263	32.628557	0.360445	1314.146851	0.000000	NaN	NaN
819.000844	0.003395	33.952991	0.361192	1314.869263	0.000000	NaN	NaN
820.499930	0.003395	33.952991	0.361704	1315.363403	0.000000	NaN	NaN
822.000016	0.003337	33.373551	0.362456	1316.089600	0.000000	NaN	NaN
823.501101	0.003304	33.042443	0.363189	1316.797485	0.000000	NaN	NaN
825.001187	0.003263	32.628557	0.363879	1317.464355	0.000000	NaN	NaN
826.499273	0.003313	33.125220	0.364611	1318.171387	0.000000	NaN	NaN
828.000359	0.003304	33.042443	0.365264	1318.802490	0.000000	NaN	NaN
829.500445	0.003263	32.628557	0.366030	1319.542358	0.000000	NaN	NaN
831.000530	0.003279	32.794111	0.366794	1320.280029	0.000000	NaN	NaN
832.499616	0.003329	33.290774	0.367416	1320.880737	0.000000	NaN	NaN
834.000702	0.003288	32.876889	0.368156	1321.595703	0.000000	NaN	NaN
835.500788	0.003296	32.959666	0.368987	1322.398315	0.000000	NaN	NaN
837.000874	0.003412	34.118546	0.369457	1322.852661	0.000000	NaN	NaN
838.500959	0.003354	33.539106	0.370299	1323.666382	0.000000	NaN	NaN
840.001045	0.003437	34.366877	0.371004	1324.346436	0.000000	NaN	NaN
841.501131	0.003370	33.704660	0.371732	1325.050049	0.000000	NaN	NaN
843.000217	0.003354	33.539106	0.372455	1325.749023	0.000000	NaN	NaN
844.500303	0.003263	32.628557	0.373210	1326.477661	0.000000	NaN	NaN
846.000388	0.003362	33.621883	0.373898	1327.142212	0.000000	NaN	NaN
847.499474	0.003428	34.284100	0.374694	1327.911499	0.000000	NaN	NaN
848.999560	0.003379	33.787437	0.375384	1328.578003	0.000000	NaN	NaN
850.500646	0.003354	33.539106	0.376008	1329.180420	0.000000	NaN	NaN
852.000732	0.003387	33.870214	0.376771	1329.917358	0.000000	NaN	NaN
853.500817	0.003387	33.870214	0.377517	1330.638062	0.000000	NaN	NaN
855.000903	0.003370	33.704660	0.378173	1331.271973	0.000000	NaN	NaN
856.500989	0.003404	34.035769	0.379003	1332.074097	0.000000	NaN	NaN
858.001075	0.003412	34.118546	0.379707	1332.753540	0.000000	NaN	NaN
859.501161	0.003362	33.621883	0.380550	1333.568481	0.000000	NaN	NaN
861.000246	0.003370	33.704660	0.381310	1334.301880	0.000000	NaN	NaN
862.500332	0.003395	33.952991	0.381979	1334.948486	0.000000	NaN	NaN
864.000418	0.003428	34.284100	0.382681	1335.626831	0.000000	NaN	NaN
865.500504	0.003271	32.711334	0.383617	1336.530518	0.000000	NaN	NaN
867.000590	0.003404	34.035769	0.384249	1337.141479	0.000000	NaN	NaN
868.500675	0.003395	33.952991	0.384945	1337.813477	0.000000	NaN	NaN
869.999761	0.003404	34.035769	0.385776	1338.616089	0.000000	NaN	NaN
871.500847	0.003379	33.787437	0.386526	1339.340210	0.000000	NaN	NaN
873.000933	0.003412	34.118546	0.387310	1340.097534	0.000000	NaN	NaN
874.501019	0.003395	33.952991	0.388116	1340.876831	0.000000	NaN	NaN
876.001104	0.003263	32.628557	0.388833	1341.568726	0.000000	NaN	NaN
877.500190	0.003594	35.939643	0.389771	1342.475708	0.000000	NaN	NaN
879.000276	0.003379	33.787437	0.390351	1343.035278	0.000000	NaN	NaN
880.500362	0.003346	33.456329	0.391259	1343.912476	0.000000	NaN	NaN
881.999447	0.003445	34.449654	0.392071	1344.696777	0.000000	NaN	NaN
883.499533	0.003346	33.456329	0.392766	1345.368164	0.000000	NaN	NaN
885.000619	0.003370	33.704660	0.393444	1346.023682	0.000000	NaN	NaN
886.500705	0.003387	33.870214	0.394474	1347.017944	0.000000	NaN	NaN
888.000791	0.003420	34.201323	0.395024	1347.549438	0.000000	NaN	NaN
889.499876	0.003404	34.035769	0.395877	1348.373169	0.000000	NaN	NaN
890.999962	0.003304	33.042443	0.396738	1349.205078	0.000000	NaN	NaN
892.501048	0.003304	33.042443	0.397571	1350.010132	0.000000	NaN	NaN
894.001134	0.003296	32.959666	0.398362	1350.774048	0.000000	NaN	NaN
895.501220	0.003354	33.539106	0.399164	1351.548462	0.000000	NaN	NaN
896.999305	0.003395	33.952991	0.399932	1352.290894	0.000000	NaN	NaN
898.500391	0.003404	34.035769	0.400744	1353.075073	0.000000	NaN	NaN
900.000477	0.003404	34.035769	0.401604	1353.905518	0.000000	NaN	NaN
901.500563	0.003304	33.042443	0.402286	1354.564209	0.000000	NaN	NaN
903.000649	0.003404	34.035769	0.403148	1355.396851	0.000000	NaN	NaN
904.500734	0.003437	34.366877	0.403910	1356.132812	0.000000	NaN	NaN
906.000820	0.003337	33.373551	0.404806	1356.999146	0.000000	NaN	NaN
907.500906	0.003313	33.125220	0.405642	1357.806030	0.000000	NaN	NaN
909.000992	0.003387	33.870214	0.406531	1358.664917	0.000000	NaN	NaN
910.501078	0.003412	34.118546	0.407376	1359.481323	0.000000	NaN	NaN
912.000163	0.003346	33.456329	0.408185	1360.262207	0.000000	NaN	NaN
913.500249	0.003379	33.787437	0.409079	1361.125977	0.000000	NaN	NaN
915.000335	0.003453	34.532431	0.409802	1361.824951	0.000000	NaN	NaN
916.500421	0.003321	33.207997	0.410667	1362.660522	0.000000	NaN	NaN
918.000507	0.003279	32.794111	0.411558	1363.520386	0.000000	NaN	NaN
919.499592	0.003495	34.946317	0.412403	1364.336670	0.000000	NaN	NaN
921.000678	0.003379	33.787437	0.413303	1365.206299	0.000000	NaN	NaN
922.500764	0.003288	32.876889	0.414165	1366.038940	0.000000	NaN	NaN
923.999850	0.003329	33.290774	0.415076	1366.919556	0.000000	NaN	NaN
925.499935	0.003478	34.780763	0.415953	1367.766113	0.000000	NaN	NaN
927.001021	0.003279	32.794111	0.416840	1368.623413	0.000000	NaN	NaN
928.501107	0.003395	33.952991	0.417781	1369.532227	0.000000	NaN	NaN
930.001193	0.003337	33.373551	0.418654	1370.375732	0.000000	NaN	NaN
931.499279	0.003420	34.201323	0.419522	1371.214233	0.000000	NaN	NaN
933.000365	0.003263	32.628557	0.420330	1371.994019	0.000000	NaN	NaN
934.500450	0.003288	32.876889	0.421282	1372.913574	0.000000	NaN	NaN
936.000536	0.003362	33.621883	0.422191	1373.792114	0.000000	NaN	NaN
937.499622	0.003313	33.125220	0.423112	1374.681152	0.000000	NaN	NaN
938.999708	0.003296	32.959666	0.423988	1375.527466	0.000000	NaN	NaN
940.500793	0.003379	33.787437	0.424894	1376.402710	0.000000	NaN	NaN
941.999879	0.003370	33.704660	0.425850	1377.326782	0.000000	NaN	NaN
943.500965	0.003329	33.290774	0.426991	1378.428955	0.000000	NaN	NaN
945.000051	0.003346	33.456329	0.428016	1379.418335	0.000000	NaN	NaN
946.500137	0.003387	33.870214	0.428941	1380.311890	0.000000	NaN	NaN
948.000222	0.003313	33.125220	0.430880	1382.185303	0.000000	NaN	NaN
949.500308	0.003304	33.042443	0.431946	1383.215088	0.000000	NaN	NaN
950.999394	0.003329	33.290774	0.432959	1384.193726	0.000000	NaN	NaN
952.499480	0.003313	33.125220	0.433973	1385.173218	0.000000	NaN	NaN
954.271581	0.003412	34.118546	0.435015	1386.179321	0.000000	NaN	NaN
955.500651	0.003354	33.539106	0.436134	1387.260864	0.000000	NaN	NaN
957.000737	0.003304	33.042443	0.437110	1388.203369	0.000000	NaN	NaN
958.499823	0.003354	33.539106	0.439224	1390.245361	0.000000	NaN	NaN
959.999909	0.003337	33.373551	0.440481	1391.459839	0.000000	NaN	NaN
961.500995	0.003362	33.621883	0.441774	1392.708984	0.000000	NaN	NaN
963.001080	0.003370	33.704660	0.443050	1393.941528	0.000000	NaN	NaN
964.501166	0.003288	32.876889	0.443357	1394.238037	0.000000	NaN	NaN
965.999252	0.003296	32.959666	0.444524	1395.365234	0.000000	NaN	NaN
967.500338	0.003213	32.131894	0.445583	1396.388184	0.000000	NaN	NaN
969.000424	0.003155	31.552454	0.446922	1397.681274	0.000000	NaN	NaN
970.500509	0.003221	32.214671	0.448245	1398.959351	0.000000	NaN	NaN
972.000595	0.003205	32.049117	0.449448	1400.121582	0.000000	NaN	NaN
973.499681	0.003089	30.890237	0.450469	1401.108032	0.000000	NaN	NaN
975.000767	0.003072	30.724683	0.451598	1402.198364	0.000000	NaN	NaN
976.500853	0.003039	30.393574	0.452865	1403.422119	0.000000	NaN	NaN
978.000938	0.003097	30.973014	0.453947	1404.466919	0.000000	NaN	NaN
979.501024	0.003023	30.228020	0.454897	1405.384644	0.000000	NaN	NaN
981.000110	0.003139	31.386900	0.455906	1406.359375	0.000000	NaN	NaN
982.501196	0.002998	29.979689	0.456997	1407.413452	0.000000	NaN	NaN
984.000282	0.002981	29.814134	0.458156	1408.533081	0.000000	NaN	NaN
985.499367	0.003015	30.145243	0.459457	1409.789429	0.000000	NaN	NaN
987.000453	0.003031	30.310797	0.460853	1411.138062	0.000000	NaN	NaN
988.500539	0.003147	31.469677	0.462228	1412.466553	0.000000	NaN	NaN
990.000625	0.002998	29.979689	0.463258	1413.461792	0.000000	NaN	NaN
991.499710	0.002957	29.565803	0.464616	1414.773560	0.000000	NaN	NaN
992.999796	0.002915	29.151917	0.465982	1416.092773	0.000000	NaN	NaN
994.500882	0.002890	28.903586	0.467446	1417.506592	0.000000	NaN	NaN
995.999968	0.002998	29.979689	0.469109	1419.113159	0.000000	NaN	NaN
997.501054	0.002857	28.572477	0.470516	1420.472290	0.000000	NaN	NaN
999.001140	0.002791	27.910260	0.472074	1421.977539	0.000000	NaN	NaN
1000.500225	0.002849	28.489700	0.473758	1423.603882	0.000000	NaN	NaN
1002.000311	0.002667	26.668603	0.475382	1425.173218	0.000000	NaN	NaN
1003.500397	0.002634	26.337494	0.477271	1426.997681	0.000000	NaN	NaN
1005.000483	0.002675	26.751380	0.479027	1428.693726	0.000000	NaN	NaN
1006.500568	0.002518	25.178614	0.480535	1430.150146	0.000000	NaN	NaN
1007.999654	0.002427	24.268066	0.482512	1432.059692	0.000000	NaN	NaN
1009.500740	0.002419	24.185289	0.484417	1433.900513	0.000000	NaN	NaN
1011.000826	0.002261	22.612523	0.486561	1435.971069	0.000000	NaN	NaN
1012.500912	0.002137	21.370866	0.488827	1438.160522	0.000000	NaN	NaN
1014.000998	0.002071	20.708649	0.491507	1440.748657	0.000000	NaN	NaN
1015.500083	0.001748	17.480340	0.494343	1443.488159	0.000000	NaN	NaN
1017.000169	-0.000752	-7.518358	0.498789	1447.783081	0.000000	NaN	NaN
1018.500255	-0.000338	-3.379500	0.538779	1486.412476	0.000000	NaN	NaN
1020.000341	-0.000239	-2.386175	0.545024	1492.444580	0.000000	NaN	NaN
1021.499426	-0.000206	-2.055066	0.549238	1496.515869	0.000000	NaN	NaN
1023.000512	-0.000214	-2.137843	0.552696	1499.855469	0.000000	NaN	NaN
1024.500598	-0.000139	-1.392849	0.555202	1502.276123	0.000000	NaN	NaN
1026.000684	-0.000139	-1.392849	0.557814	1504.800049	0.000000	NaN	NaN
1027.500770	-0.000247	-2.468952	0.560268	1507.170288	0.000000	NaN	NaN
1029.000855	-0.000156	-1.558403	0.562477	1509.303467	0.000000	NaN	NaN
1030.499941	-0.000305	-3.048392	0.564687	1511.438477	0.000000	NaN	NaN
1032.001027	-0.000172	-1.723957	0.566553	1513.240967	0.000000	NaN	NaN
1033.501113	-0.000222	-2.220620	0.568475	1515.097290	0.000000	NaN	NaN
1035.000199	-0.000255	-2.551729	0.570304	1516.864014	0.000000	NaN	NaN
1036.500284	-0.000214	-2.137843	0.572244	1518.738281	0.000000	NaN	NaN
1038.000370	-0.000305	-3.048392	0.573927	1520.363892	0.000000	NaN	NaN
1039.500456	-0.000131	-1.310072	0.575817	1522.189941	0.000000	NaN	NaN
1041.000542	-0.000189	-1.889512	0.577312	1523.633789	0.000000	NaN	NaN
1042.499627	-0.000280	-2.800060	0.578949	1525.215210	0.000000	NaN	NaN
1044.000713	-0.000197	-1.972289	0.580619	1526.828491	0.000000	NaN	NaN
1045.500799	-0.000239	-2.386175	0.582187	1528.343018	0.000000	NaN	NaN
1047.000885	-0.000172	-1.723957	0.583919	1530.015747	0.000000	NaN	NaN
1048.500971	-0.000189	-1.889512	0.585336	1531.385376	0.000000	NaN	NaN
1050.000057	-0.000288	-2.882837	0.586760	1532.760010	0.000000	NaN	NaN
1050.501085	-0.000321	-3.213946	0.587440	1533.417847	0.000000	NaN	NaN