File: data/115k_1-1_3 (181102).lvm
LabVIEW Measurement
Writer_Version	2
Reader_Version	2
Separator	Tab
Decimal_Separator	.
Multi_Headings	No
X_Columns	One
Time_Pref	Absolute
Operator	user
Description	Load(N)/Stress(MPa)/Distance A(pixel)/Strain A/Distance B(pixel)/Strain B/Poisson's ratio
Date	2018/11/02
Time	10:28:23.3113036155700683594
***End_of_Header***

Notes	X 값은 오직 다음과 같을 때에만 유효함이 보장됩니다. Dev1/ai0
Channels	7
Samples	1	1	1	1	1	1	1
Date	2018/11/02	2018/11/02	2018/11/02	2018/11/02	2018/11/02	2018/11/02	2018/11/02
Time	10:53:57.3110434300349919749	10:53:57.3110434300349919749	10:53:57.3110432624816894531	10:53:57.3110432624816894531	10:53:57.3110432624816894531	10:53:57.3110432624816894531	10:53:57.3110432624816894531
Y_Unit_Label	Volts	Volts
X_Dimension	Time	Time	Time	Time	Time	Time	Time
X0	0.0000000000000000E+0	0.0000000000000000E+0	0.0000000000000000E+0	0.0000000000000000E+0	0.0000000000000000E+0	0.0000000000000000E+0	0.0000000000000000E+0
Delta_X	0.000000	0.000000	1.000000	1.000000	1.000000	1.000000	1.000000
***End_of_Header***
X_Value	Dev1/ai0	Dev1/ai0 1	Untitled	Untitled 1	Untitled 2	Untitled 3	Untitled 4	Comment
0.000000	8.421341E-5	0.842134	-4.947186E-5	984.775391	0.000000	NaN	NaN
1.501086	-0.000222	-2.220620	2.694130E-5	984.850586	0.000000	NaN	NaN
3.001172	5.938027E-5	0.593803	0.000116	984.938049	0.000000	NaN	NaN
4.500257	0.000126	1.256020	0.000525	985.341064	0.000000	NaN	NaN
5.999343	0.000150	1.504351	0.000986	985.794739	0.000000	NaN	NaN
7.500429	0.000233	2.332123	0.001372	986.175415	0.000000	NaN	NaN
9.000515	0.000150	1.504351	0.001806	986.602600	0.000000	NaN	NaN
10.500601	0.000250	2.497677	0.002283	987.072510	0.000000	NaN	NaN
12.000686	0.000258	2.580454	0.002622	987.406738	0.000000	NaN	NaN
13.500772	0.000333	3.325449	0.003009	987.787842	0.000000	NaN	NaN
15.000858	0.000473	4.732660	0.003553	988.322693	0.000000	NaN	NaN
16.500944	0.000589	5.891540	0.003973	988.737000	0.000000	NaN	NaN
18.001030	0.000564	5.643209	0.004316	989.074890	0.000000	NaN	NaN
19.501115	0.000688	6.884866	0.004806	989.557251	0.000000	NaN	NaN
21.001201	0.000597	5.974317	0.005061	989.808655	0.000000	NaN	NaN
22.500287	0.000746	7.464306	0.005478	990.219177	0.000000	NaN	NaN
24.000373	0.000647	6.470980	0.005886	990.620544	0.000000	NaN	NaN
25.500458	0.000755	7.547083	0.006468	991.194031	0.000000	NaN	NaN
27.000544	0.000879	8.788740	0.006933	991.651978	0.000000	NaN	NaN
28.499630	0.000821	8.209300	0.007426	992.137268	0.000000	NaN	NaN
30.000716	0.000978	9.782066	0.007826	992.531555	0.000000	NaN	NaN
31.499802	0.000945	9.450957	0.008354	993.050903	0.000000	NaN	NaN
33.000887	0.000945	9.450957	0.009001	993.688782	0.000000	NaN	NaN
34.500973	0.001061	10.609837	0.009471	994.151062	0.000000	NaN	NaN
36.001059	0.001044	10.444283	0.010139	994.809143	0.000000	NaN	NaN
37.501145	0.001160	11.603163	0.010623	995.285522	0.000000	NaN	NaN
39.001231	0.001160	11.603163	0.011049	995.704956	0.000000	NaN	NaN
40.500316	0.001135	11.354832	-1.000000	0.000000	0.000000	NaN	NaN
42.000402	0.001069	10.692614	0.012508	997.142700	0.000000	NaN	NaN
43.522489	0.001243	12.430934	0.013052	997.678467	0.000000	NaN	NaN
45.000574	0.001251	12.513712	0.013776	998.390747	0.000000	NaN	NaN
46.499660	0.001260	12.596489	0.014515	999.118469	0.000000	NaN	NaN
48.000745	0.001376	13.755369	0.015005	999.601135	0.000000	NaN	NaN
49.500831	0.001318	13.175929	0.015576	1000.163757	0.000000	NaN	NaN
51.000917	0.001442	14.417586	0.738003	1711.627319	0.000000	NaN	NaN
52.501003	0.001326	13.258706	0.017012	1001.577759	0.000000	NaN	NaN
54.001089	0.001334	13.341483	-1.000000	0.000000	0.000000	NaN	NaN
55.501174	0.001392	13.920923	0.018813	1003.351746	0.000000	NaN	NaN
57.001260	0.001500	14.997026	0.019498	1004.025940	0.000000	NaN	NaN
58.499346	0.001599	15.990352	0.020133	1004.651367	0.000000	NaN	NaN
60.000432	0.001599	15.990352	0.020914	1005.421082	0.000000	NaN	NaN
61.500518	0.001574	15.742020	0.021525	1006.022461	0.000000	NaN	NaN
63.000603	0.001607	16.073129	0.022190	1006.677734	0.000000	NaN	NaN
64.500689	0.001665	16.652569	0.022805	1007.283020	0.000000	NaN	NaN
66.000775	0.001665	16.652569	0.023603	1008.068604	0.000000	NaN	NaN
67.500861	0.001566	15.659243	0.024448	1008.901184	0.000000	NaN	NaN
69.000947	0.001516	15.162580	0.025230	1009.671448	0.000000	NaN	NaN
70.501032	0.001682	16.818123	0.025887	1010.318054	0.000000	NaN	NaN
72.001118	0.001690	16.900900	0.026583	1011.004150	0.000000	NaN	NaN
73.500204	0.001839	18.390889	0.027379	1011.787415	0.000000	NaN	NaN
75.000290	0.001756	17.563117	0.028215	1012.610657	0.000000	NaN	NaN
76.500375	0.001690	16.900900	0.029015	1013.398560	0.000000	NaN	NaN
78.000461	0.001823	18.225334	0.029766	1014.137939	0.000000	NaN	NaN
79.500547	0.001599	15.990352	0.030447	1014.808594	0.000000	NaN	NaN
81.000633	0.001657	16.569792	0.031063	1015.416077	0.000000	NaN	NaN
82.500719	0.001748	17.480340	0.031924	1016.263245	0.000000	NaN	NaN
84.000805	0.001897	18.970329	0.032737	1017.064697	0.000000	NaN	NaN
85.500890	0.001814	18.142557	0.033708	1018.020447	0.000000	NaN	NaN
87.000976	0.001723	17.232009	0.034586	1018.885132	0.000000	NaN	NaN
88.501062	0.001806	18.059780	0.035423	1019.709167	0.000000	NaN	NaN
90.001148	0.001765	17.645894	0.036104	1020.380493	0.000000	NaN	NaN
91.501233	0.001616	16.155906	0.037089	1021.350159	0.000000	NaN	NaN
93.000319	0.001748	17.480340	0.037866	1022.115234	0.000000	NaN	NaN
94.500405	0.001781	17.811449	0.038725	1022.961060	0.000000	NaN	NaN
96.000491	0.001823	18.225334	0.039675	1023.896790	0.000000	NaN	NaN
97.499577	0.001765	17.645894	0.040425	1024.635864	0.000000	NaN	NaN
99.000663	0.001740	17.397563	0.041392	1025.588135	0.000000	NaN	NaN
100.501748	0.001847	18.473666	0.042035	1026.221558	0.000000	NaN	NaN
102.000834	0.001880	18.804774	0.042809	1026.983154	0.000000	NaN	NaN
103.499920	0.001823	18.225334	0.043742	1027.901855	0.000000	NaN	NaN
105.001006	0.001897	18.970329	0.044555	1028.703125	0.000000	NaN	NaN
106.500091	0.001781	17.811449	0.045459	1029.593628	0.000000	NaN	NaN
108.001177	0.001831	18.308112	0.046205	1030.328247	0.000000	NaN	NaN
109.501263	0.001823	18.225334	0.047251	1031.358276	0.000000	NaN	NaN
111.000349	0.001814	18.142557	0.048058	1032.152710	0.000000	NaN	NaN
112.500435	0.001897	18.970329	0.048828	1032.911499	0.000000	NaN	NaN
114.000520	0.001930	19.301437	0.049633	1033.703613	0.000000	NaN	NaN
115.499606	0.001914	19.135883	0.050490	1034.547974	0.000000	NaN	NaN
117.000692	0.001889	18.887552	0.051425	1035.468262	0.000000	NaN	NaN
118.500778	0.001996	19.963654	0.052024	1036.058716	0.000000	NaN	NaN
120.000864	0.001922	19.218660	0.053267	1037.282471	0.000000	NaN	NaN
121.499949	0.002005	20.046432	0.053918	1037.923706	0.000000	NaN	NaN
123.001035	0.001963	19.632546	0.054732	1038.725342	0.000000	NaN	NaN
124.501121	0.001781	17.811449	0.055396	1039.379761	0.000000	NaN	NaN
126.001207	0.001905	19.053106	0.056239	1040.209961	0.000000	NaN	NaN
127.500293	0.001922	19.218660	0.058479	1042.415649	0.000000	NaN	NaN
129.000378	0.001897	18.970329	0.059143	1043.069580	0.000000	NaN	NaN
130.499464	0.001963	19.632546	0.059837	1043.752808	0.000000	NaN	NaN
132.000550	0.001905	19.053106	0.060645	1044.549072	0.000000	NaN	NaN
133.500636	0.001889	18.887552	0.061519	1045.409058	0.000000	NaN	NaN
134.999721	0.001914	19.135883	0.062229	1046.108643	0.000000	NaN	NaN
136.499807	0.001972	19.715323	0.062989	1046.856812	0.000000	NaN	NaN
138.000893	0.001897	18.970329	0.063786	1047.642212	0.000000	NaN	NaN
139.500979	0.002005	20.046432	0.064599	1048.442505	0.000000	NaN	NaN
141.001065	0.001798	17.977003	0.065303	1049.135986	0.000000	NaN	NaN
142.501151	0.001988	19.880877	0.066130	1049.950562	0.000000	NaN	NaN
144.001236	0.002021	20.211986	0.066839	1050.649170	0.000000	NaN	NaN
145.500322	0.002054	20.543094	0.067698	1051.494629	0.000000	NaN	NaN
147.000408	0.001988	19.880877	0.068428	1052.213867	0.000000	NaN	NaN
148.500494	0.002046	20.460317	0.069105	1052.880615	0.000000	NaN	NaN
149.999579	0.001914	19.135883	0.069985	1053.747070	0.000000	NaN	NaN
151.500665	0.001914	19.135883	0.070741	1054.491333	0.000000	NaN	NaN
153.000751	0.001955	19.549769	0.071530	1055.268555	0.000000	NaN	NaN
154.500837	0.002013	20.129209	0.072433	1056.158081	0.000000	NaN	NaN
156.000923	0.001930	19.301437	0.073148	1056.862549	0.000000	NaN	NaN
157.500008	0.001996	19.963654	0.073920	1057.622192	0.000000	NaN	NaN
159.001094	0.002038	20.377540	0.074730	1058.420288	0.000000	NaN	NaN
160.500180	0.002054	20.543094	0.075522	1059.200073	0.000000	NaN	NaN
162.001266	0.002038	20.377540	0.076378	1060.043335	0.000000	NaN	NaN
163.500352	0.002046	20.460317	0.077145	1060.798828	0.000000	NaN	NaN
165.000437	0.002029	20.294763	0.077944	1061.585205	0.000000	NaN	NaN
166.500523	0.001880	18.804774	0.078645	1062.275757	0.000000	NaN	NaN
168.000609	0.001880	18.804774	0.079383	1063.002930	0.000000	NaN	NaN
169.500695	0.002013	20.129209	0.080305	1063.910278	0.000000	NaN	NaN
170.999781	0.001914	19.135883	0.080898	1064.494629	0.000000	NaN	NaN
172.499866	0.002005	20.046432	0.081756	1065.338989	0.000000	NaN	NaN
174.000952	0.001963	19.632546	0.082450	1066.022705	0.000000	NaN	NaN
175.501038	0.002005	20.046432	0.083260	1066.820435	0.000000	NaN	NaN
177.001124	0.002063	20.625872	0.083982	1067.531982	0.000000	NaN	NaN
178.501210	0.002129	21.288089	0.083032	1066.596191	0.000000	NaN	NaN
179.999295	0.002038	20.377540	0.083732	1067.284912	0.000000	NaN	NaN
181.500381	0.002079	20.791426	0.084475	1068.017212	0.000000	NaN	NaN
183.000467	0.002087	20.874203	0.085301	1068.830322	0.000000	NaN	NaN
184.499553	0.002046	20.460317	0.086007	1069.526123	0.000000	NaN	NaN
185.999639	0.002054	20.543094	0.086846	1070.352295	0.000000	NaN	NaN
187.500724	0.001955	19.549769	0.087626	1071.120361	0.000000	NaN	NaN
189.000810	0.002079	20.791426	0.088101	1071.588013	0.000000	NaN	NaN
190.500896	0.002021	20.211986	0.088862	1072.337158	0.000000	NaN	NaN
192.000982	0.002005	20.046432	0.089638	1073.102173	0.000000	NaN	NaN
193.500067	0.002096	20.956980	0.090427	1073.878662	0.000000	NaN	NaN
195.001153	0.002029	20.294763	0.091226	1074.665161	0.000000	NaN	NaN
196.501239	0.001996	19.963654	0.091955	1075.383789	0.000000	NaN	NaN
198.000325	0.002063	20.625872	0.092811	1076.227051	0.000000	NaN	NaN
199.500411	0.002054	20.543094	0.093517	1076.921875	0.000000	NaN	NaN
201.000496	0.002087	20.874203	0.094251	1077.644287	0.000000	NaN	NaN
202.500582	0.002104	21.039757	0.095052	1078.433228	0.000000	NaN	NaN
204.000668	0.001996	19.963654	0.095840	1079.209351	0.000000	NaN	NaN
205.500754	0.002038	20.377540	0.096579	1079.937012	0.000000	NaN	NaN
206.999840	0.002129	21.288089	0.097360	1080.706177	0.000000	NaN	NaN
208.499925	0.002079	20.791426	0.098171	1081.504761	0.000000	NaN	NaN
210.001011	0.002121	21.205312	0.098867	1082.190430	0.000000	NaN	NaN
211.501097	0.001996	19.963654	0.099598	1082.910522	0.000000	NaN	NaN
213.001183	0.002121	21.205312	0.100359	1083.659912	0.000000	NaN	NaN
214.501269	0.002112	21.122534	0.101080	1084.370239	0.000000	NaN	NaN
216.000354	0.002162	21.619197	0.101844	1085.122314	0.000000	NaN	NaN
217.500440	0.002079	20.791426	0.102660	1085.926147	0.000000	NaN	NaN
219.000526	0.002121	21.205312	0.103310	1086.566772	0.000000	NaN	NaN
220.499612	0.002104	21.039757	0.104099	1087.343262	0.000000	NaN	NaN
222.000698	0.002071	20.708649	0.104839	1088.071899	0.000000	NaN	NaN
223.500783	0.002121	21.205312	0.105611	1088.832397	0.000000	NaN	NaN
225.000869	0.002087	20.874203	0.106322	1089.532349	0.000000	NaN	NaN
226.500955	0.002112	21.122534	0.107080	1090.279541	0.000000	NaN	NaN
228.001041	0.002162	21.619197	0.107764	1090.953003	0.000000	NaN	NaN
229.501127	0.002063	20.625872	0.108577	1091.752930	0.000000	NaN	NaN
231.001213	0.002203	22.033083	0.109318	1092.483154	0.000000	NaN	NaN
232.500298	0.002212	22.115860	0.110020	1093.174805	0.000000	NaN	NaN
234.000384	0.002187	21.867529	0.110815	1093.957153	0.000000	NaN	NaN
235.500470	0.002178	21.784752	0.111546	1094.677734	0.000000	NaN	NaN
237.000556	0.002195	21.950306	0.112330	1095.449829	0.000000	NaN	NaN
238.500641	0.002236	22.364192	0.113006	1096.115234	0.000000	NaN	NaN
240.000727	0.002162	21.619197	0.113748	1096.845459	0.000000	NaN	NaN
241.499813	0.001996	19.963654	0.114430	1097.517212	0.000000	NaN	NaN
243.000899	0.002236	22.364192	0.115300	1098.373901	0.000000	NaN	NaN
244.500985	0.002212	22.115860	0.115918	1098.983276	0.000000	NaN	NaN
246.001070	0.002212	22.115860	0.116754	1099.806641	0.000000	NaN	NaN
247.501156	0.002187	21.867529	0.117464	1100.505493	0.000000	NaN	NaN
249.001242	0.002121	21.205312	0.118161	1101.192017	0.000000	NaN	NaN
250.500328	0.002087	20.874203	0.118878	1101.898437	0.000000	NaN	NaN
252.000414	0.002170	21.701974	0.119610	1102.618896	0.000000	NaN	NaN
253.500499	0.002270	22.695300	0.120318	1103.316406	0.000000	NaN	NaN
255.000585	0.002170	21.701974	0.121221	1104.205078	0.000000	NaN	NaN
256.500671	0.002104	21.039757	0.121948	1104.921265	0.000000	NaN	NaN
258.000757	0.002071	20.708649	0.122536	1105.500488	0.000000	NaN	NaN
259.500843	0.002170	21.701974	0.123219	1106.173584	0.000000	NaN	NaN
261.000928	0.002170	21.701974	0.124000	1106.942017	0.000000	NaN	NaN
262.501014	0.002162	21.619197	0.124835	1107.765137	0.000000	NaN	NaN
264.001100	0.002311	23.109186	0.125566	1108.484863	0.000000	NaN	NaN
265.501186	0.002154	21.536420	0.126293	1109.200928	0.000000	NaN	NaN
267.001272	0.002236	22.364192	0.126968	1109.865234	0.000000	NaN	NaN
268.500357	0.002220	22.198637	0.127709	1110.594604	0.000000	NaN	NaN
270.000443	0.002187	21.867529	0.128352	1111.228638	0.000000	NaN	NaN
271.500529	0.002220	22.198637	0.129012	1111.878540	0.000000	NaN	NaN
273.000615	0.002170	21.701974	0.129809	1112.663452	0.000000	NaN	NaN
274.499700	0.002311	23.109186	0.130568	1113.410767	0.000000	NaN	NaN
276.000786	0.002236	22.364192	0.131184	1114.016846	0.000000	NaN	NaN
277.499872	0.002195	21.950306	0.131926	1114.747681	0.000000	NaN	NaN
279.000958	0.002319	23.191963	0.132602	1115.413818	0.000000	NaN	NaN
280.502044	0.002212	22.115860	0.133393	1116.192627	0.000000	NaN	NaN
282.001129	0.002137	21.370866	0.134036	1116.826294	0.000000	NaN	NaN
283.501215	0.002220	22.198637	0.134747	1117.526489	0.000000	NaN	NaN
285.000301	0.002294	22.943632	0.135425	1118.193970	0.000000	NaN	NaN
286.500387	0.002253	22.529746	0.136026	1118.786133	0.000000	NaN	NaN
288.000473	0.002203	22.033083	0.136835	1119.582886	0.000000	NaN	NaN
289.500558	0.002261	22.612523	0.137489	1120.226440	0.000000	NaN	NaN
291.000644	0.002228	22.281414	0.138248	1120.973755	0.000000	NaN	NaN
292.500730	0.002253	22.529746	0.138903	1121.619385	0.000000	NaN	NaN
294.000816	0.002220	22.198637	0.139585	1122.290649	0.000000	NaN	NaN
295.499902	0.002261	22.612523	0.140271	1122.966064	0.000000	NaN	NaN
297.000987	0.002170	21.701974	0.141029	1123.712402	0.000000	NaN	NaN
298.501073	0.002170	21.701974	0.141607	1124.281738	0.000000	NaN	NaN
300.001159	0.002294	22.943632	0.142368	1125.031128	0.000000	NaN	NaN
301.501245	0.002311	23.109186	0.143136	1125.787964	0.000000	NaN	NaN
303.000331	0.002203	22.033083	0.143814	1126.455933	0.000000	NaN	NaN
304.500416	0.002286	22.860854	0.144615	1127.244263	0.000000	NaN	NaN
305.999502	0.002402	24.019734	0.145296	1127.914673	0.000000	NaN	NaN
307.500588	0.002327	23.274740	0.146001	1128.609741	0.000000	NaN	NaN
309.000674	0.002220	22.198637	0.146727	1129.324463	0.000000	NaN	NaN
310.500760	0.002361	23.605849	0.147383	1129.970337	0.000000	NaN	NaN
312.000845	0.002286	22.860854	-1.000000	0.000000	0.000000	NaN	NaN
313.499931	0.002236	22.364192	0.149422	1131.978027	0.000000	NaN	NaN
315.000017	0.002361	23.605849	0.150145	1132.690063	0.000000	NaN	NaN
316.500103	0.002253	22.529746	0.150941	1133.473999	0.000000	NaN	NaN
318.001189	0.002278	22.778077	0.151589	1134.112427	0.000000	NaN	NaN
319.501274	0.002319	23.191963	0.152420	1134.930786	0.000000	NaN	NaN
321.000360	0.002303	23.026409	0.153050	1135.551880	0.000000	NaN	NaN
322.500446	0.002369	23.688626	0.154192	1136.676147	0.000000	NaN	NaN
324.000532	0.002286	22.860854	0.154919	1137.392090	0.000000	NaN	NaN
325.500617	0.002377	23.771403	0.155550	1138.013672	0.000000	NaN	NaN
327.000703	0.002427	24.268066	0.156270	1138.722778	0.000000	NaN	NaN
328.500789	0.002452	24.516397	0.156910	1139.353027	0.000000	NaN	NaN
330.000875	0.002427	24.268066	0.157704	1140.135010	0.000000	NaN	NaN
331.500961	0.002303	23.026409	0.158383	1140.803101	0.000000	NaN	NaN
333.001046	0.002385	23.854180	0.159176	1141.584473	0.000000	NaN	NaN
334.501132	0.002352	23.523072	0.159681	1142.081909	0.000000	NaN	NaN
336.000218	0.002493	24.930283	0.160477	1142.865479	0.000000	NaN	NaN
337.499304	0.002344	23.440294	0.161229	1143.606323	0.000000	NaN	NaN
339.000390	0.002327	23.274740	0.162000	1144.365723	0.000000	NaN	NaN
340.500475	0.002402	24.019734	0.162626	1144.982178	0.000000	NaN	NaN
342.000561	0.002270	22.695300	0.163388	1145.732544	0.000000	NaN	NaN
343.500647	0.002493	24.930283	0.164195	1146.527466	0.000000	NaN	NaN
345.000733	0.002402	24.019734	0.164772	1147.095947	0.000000	NaN	NaN
346.500819	0.002319	23.191963	0.165522	1147.833618	0.000000	NaN	NaN
348.000904	0.002369	23.688626	0.166282	1148.582520	0.000000	NaN	NaN
349.500990	0.002369	23.688626	0.167045	1149.334473	0.000000	NaN	NaN
351.001076	0.002361	23.605849	0.167789	1150.066284	0.000000	NaN	NaN
352.501162	0.002344	23.440294	0.168516	1150.782227	0.000000	NaN	NaN
354.001248	0.002410	24.102512	0.169140	1151.396973	0.000000	NaN	NaN
355.499333	0.002344	23.440294	0.169971	1152.215576	0.000000	NaN	NaN
356.999419	0.002261	22.612523	0.170680	1152.914307	0.000000	NaN	NaN
358.499505	0.002369	23.688626	0.171427	1153.649780	0.000000	NaN	NaN
360.000591	0.002319	23.191963	0.172143	1154.354248	0.000000	NaN	NaN
361.500677	0.002460	24.599174	0.172819	1155.020142	0.000000	NaN	NaN
362.999762	0.002501	25.013060	0.173459	1155.650757	0.000000	NaN	NaN
364.499848	0.002518	25.178614	0.174212	1156.391968	0.000000	NaN	NaN
366.000934	0.002377	23.771403	0.174910	1157.079468	0.000000	NaN	NaN
367.501020	0.002435	24.350843	0.175725	1157.882812	0.000000	NaN	NaN
369.001106	0.002270	22.695300	0.177141	1159.276367	0.000000	NaN	NaN
370.501191	0.002427	24.268066	0.177833	1159.958618	0.000000	NaN	NaN
372.001277	0.002377	23.771403	0.178527	1160.641724	0.000000	NaN	NaN
373.499363	0.002402	24.019734	0.179274	1161.377808	0.000000	NaN	NaN
375.000449	0.002493	24.930283	0.180067	1162.158569	0.000000	NaN	NaN
376.500535	0.002427	24.268066	0.180657	1162.739014	0.000000	NaN	NaN
378.000620	0.002410	24.102512	0.181342	1163.413940	0.000000	NaN	NaN
379.500706	0.002377	23.771403	0.182137	1164.197510	0.000000	NaN	NaN
381.000792	0.002336	23.357517	0.182808	1164.857788	0.000000	NaN	NaN
382.500878	0.002468	24.681952	0.183557	1165.595093	0.000000	NaN	NaN
384.000964	0.002443	24.433620	0.184275	1166.302979	0.000000	NaN	NaN
385.500049	0.002419	24.185289	0.184823	1166.842651	0.000000	NaN	NaN
387.001135	0.002336	23.357517	0.185540	1167.548096	0.000000	NaN	NaN
388.501221	0.002526	25.261392	0.186328	1168.324707	0.000000	NaN	NaN
390.000307	0.002493	24.930283	0.187083	1169.068359	0.000000	NaN	NaN
391.500392	0.002443	24.433620	0.187745	1169.719604	0.000000	NaN	NaN
393.000478	0.002510	25.095837	0.188539	1170.501587	0.000000	NaN	NaN
394.500564	0.002402	24.019734	0.189230	1171.182617	0.000000	NaN	NaN
396.000650	0.002443	24.433620	0.189970	1171.911133	0.000000	NaN	NaN
397.500736	0.002377	23.771403	0.190709	1172.639404	0.000000	NaN	NaN
399.000821	0.002402	24.019734	0.191364	1173.283569	0.000000	NaN	NaN
400.499907	0.002410	24.102512	0.192044	1173.953613	0.000000	NaN	NaN
402.000993	0.002410	24.102512	0.192716	1174.615723	0.000000	NaN	NaN
403.501079	0.002534	25.344169	0.193427	1175.316162	0.000000	NaN	NaN
405.001165	0.002410	24.102512	0.194100	1175.978394	0.000000	NaN	NaN
406.500250	0.002443	24.433620	0.194774	1176.642334	0.000000	NaN	NaN
408.000336	0.002493	24.930283	0.195513	1177.370117	0.000000	NaN	NaN
409.499422	0.002592	25.923609	0.196248	1178.094238	0.000000	NaN	NaN
411.000508	0.002452	24.516397	0.196787	1178.624756	0.000000	NaN	NaN
412.499594	0.002476	24.764729	0.197444	1179.271973	0.000000	NaN	NaN
414.000679	0.002443	24.433620	0.198170	1179.986572	0.000000	NaN	NaN
415.500765	0.002468	24.681952	0.198976	1180.780029	0.000000	NaN	NaN
417.000851	0.002551	25.509723	0.199651	1181.445435	0.000000	NaN	NaN
418.500937	0.002601	26.006386	0.200502	1182.283081	0.000000	NaN	NaN
420.001023	0.002452	24.516397	0.200982	1182.755737	0.000000	NaN	NaN
421.501108	0.002493	24.930283	0.201704	1183.466797	0.000000	NaN	NaN
423.001194	0.002410	24.102512	0.202413	1184.165161	0.000000	NaN	NaN
424.500280	0.002394	23.936957	0.203110	1184.851807	0.000000	NaN	NaN
426.000366	0.002427	24.268066	0.203873	1185.603271	0.000000	NaN	NaN
427.500452	0.002427	24.268066	0.204596	1186.314941	0.000000	NaN	NaN
429.000537	0.002634	26.337494	0.205173	1186.883423	0.000000	NaN	NaN
430.500623	0.002443	24.433620	0.205929	1187.627808	0.000000	NaN	NaN
432.000709	0.002485	24.847506	0.206594	1188.282837	0.000000	NaN	NaN
433.500795	0.002526	25.261392	0.207330	1189.007690	0.000000	NaN	NaN
435.000881	0.002601	26.006386	0.207975	1189.643066	0.000000	NaN	NaN
436.499966	0.002559	25.592500	0.208733	1190.389648	0.000000	NaN	NaN
438.001052	0.002493	24.930283	0.209364	1191.010620	0.000000	NaN	NaN
439.501138	0.002510	25.095837	0.209979	1191.616577	0.000000	NaN	NaN
441.001224	0.002551	25.509723	0.210649	1192.276245	0.000000	NaN	NaN
442.500309	0.002526	25.261392	0.211532	1193.145386	0.000000	NaN	NaN
444.000395	0.002526	25.261392	0.212228	1193.831665	0.000000	NaN	NaN
445.499481	0.002559	25.592500	0.212735	1194.330811	0.000000	NaN	NaN
447.000567	0.002543	25.426946	0.213503	1195.086670	0.000000	NaN	NaN
448.499653	0.002543	25.426946	-1.000000	0.000000	0.000000	NaN	NaN
454.571000	0.002526	25.261392	0.327617	1307.468750	0.000000	NaN	NaN
456.501110	0.002601	26.006386	0.221612	1203.073120	0.000000	NaN	NaN
458.002196	0.002526	25.261392	0.222251	1203.701782	0.000000	NaN	NaN
459.500282	0.002609	26.089163	0.222885	1204.326416	0.000000	NaN	NaN
461.000368	0.002443	24.433620	0.223565	1204.995850	0.000000	NaN	NaN
462.500453	0.002460	24.599174	0.224293	1205.712891	0.000000	NaN	NaN
464.000539	0.002443	24.433620	0.224938	1206.348145	0.000000	NaN	NaN
465.500625	0.002551	25.509723	0.225612	1207.011963	0.000000	NaN	NaN
467.000711	0.002526	25.261392	0.226344	1207.733276	0.000000	NaN	NaN
468.499797	0.002543	25.426946	0.226987	1208.366699	0.000000	NaN	NaN
470.000882	0.002476	24.764729	0.227663	1209.032104	0.000000	NaN	NaN
471.500968	0.002485	24.847506	0.228355	1209.713135	0.000000	NaN	NaN
473.001054	0.002493	24.930283	0.228994	1210.343140	0.000000	NaN	NaN
474.501140	0.002609	26.089163	0.229690	1211.028076	0.000000	NaN	NaN
476.001226	0.002551	25.509723	0.230335	1211.663940	0.000000	NaN	NaN
477.499311	0.002667	26.668603	0.231062	1212.379883	0.000000	NaN	NaN
479.000397	0.002584	25.840832	0.231764	1213.070435	0.000000	NaN	NaN
480.499483	0.002592	25.923609	0.232387	1213.684326	0.000000	NaN	NaN
482.000569	0.002592	25.923609	0.233067	1214.354004	0.000000	NaN	NaN
483.500655	0.002568	25.675277	0.233743	1215.020264	0.000000	NaN	NaN
485.000740	0.002609	26.089163	0.234409	1215.676147	0.000000	NaN	NaN
486.499826	0.002609	26.089163	0.234987	1216.245239	0.000000	NaN	NaN
488.000912	0.002576	25.758054	0.235685	1216.932373	0.000000	NaN	NaN
489.500998	0.002568	25.675277	0.236342	1217.579102	0.000000	NaN	NaN
491.001084	0.002625	26.254717	0.237058	1218.284668	0.000000	NaN	NaN
492.501169	0.002650	26.503049	0.237695	1218.911621	0.000000	NaN	NaN
494.001255	0.002634	26.337494	0.236338	1217.575317	0.000000	NaN	NaN
495.500341	0.002568	25.675277	0.237090	1218.315918	0.000000	NaN	NaN
497.000427	0.002667	26.668603	0.237800	1219.014893	0.000000	NaN	NaN
498.500513	0.002510	25.095837	0.238342	1219.548584	0.000000	NaN	NaN
500.000598	0.002675	26.751380	0.238933	1220.131348	0.000000	NaN	NaN
501.500684	0.002683	26.834157	0.239702	1220.888916	0.000000	NaN	NaN
503.000770	0.002642	26.420272	0.240393	1221.569092	0.000000	NaN	NaN
504.500856	0.002584	25.840832	0.241036	1222.202515	0.000000	NaN	NaN
506.000942	0.002534	25.344169	0.241705	1222.860596	0.000000	NaN	NaN
507.501027	0.002617	26.171940	0.242473	1223.617187	0.000000	NaN	NaN
509.001113	0.002733	27.330820	0.243152	1224.285645	0.000000	NaN	NaN
510.501199	0.002758	27.579152	0.243649	1224.775024	0.000000	NaN	NaN
512.000285	0.002667	26.668603	0.244382	1225.497192	0.000000	NaN	NaN
513.499370	0.002518	25.178614	0.244948	1226.055054	0.000000	NaN	NaN
515.000456	0.002559	25.592500	0.245733	1226.827637	0.000000	NaN	NaN
516.499542	0.002683	26.834157	0.246405	1227.490112	0.000000	NaN	NaN
518.000628	0.002725	27.248043	0.247087	1228.161133	0.000000	NaN	NaN
519.499714	0.002625	26.254717	0.247734	1228.798096	0.000000	NaN	NaN
521.000799	0.002609	26.089163	0.248426	1229.479858	0.000000	NaN	NaN
522.500885	0.002741	27.413597	0.249094	1230.138306	0.000000	NaN	NaN
524.000971	0.002576	25.758054	0.249758	1230.791382	0.000000	NaN	NaN
525.501057	0.002518	25.178614	0.250408	1231.431519	0.000000	NaN	NaN
527.001143	0.002625	26.254717	0.251115	1232.128662	0.000000	NaN	NaN
528.500228	0.002700	26.999712	0.251761	1232.764038	0.000000	NaN	NaN
530.000314	0.002592	25.923609	0.252358	1233.352539	0.000000	NaN	NaN
531.500400	0.002584	25.840832	0.253089	1234.072510	0.000000	NaN	NaN
533.000486	0.002741	27.413597	0.253758	1234.730835	0.000000	NaN	NaN
534.499572	0.002650	26.503049	0.254470	1235.432251	0.000000	NaN	NaN
536.000657	0.002659	26.585826	0.255157	1236.108398	0.000000	NaN	NaN
537.499743	0.002700	26.999712	0.255738	1236.681519	0.000000	NaN	NaN
539.000829	0.002659	26.585826	0.256505	1237.435913	0.000000	NaN	NaN
540.500915	0.002683	26.834157	0.257126	1238.048096	0.000000	NaN	NaN
542.000001	0.002692	26.916934	0.257761	1238.673584	0.000000	NaN	NaN
543.501086	0.002683	26.834157	0.258470	1239.371216	0.000000	NaN	NaN
545.001172	0.002791	27.910260	0.259092	1239.984375	0.000000	NaN	NaN
546.500258	0.002725	27.248043	0.259758	1240.639893	0.000000	NaN	NaN
548.000344	0.002559	25.592500	0.260526	1241.396118	0.000000	NaN	NaN
549.499429	0.002766	27.661929	0.261224	1242.083740	0.000000	NaN	NaN
550.999515	0.002791	27.910260	0.261055	1241.917358	0.000000	NaN	NaN
552.499601	0.002725	27.248043	0.261621	1242.474609	0.000000	NaN	NaN
553.999687	0.002584	25.840832	0.262340	1243.183228	0.000000	NaN	NaN
555.500773	0.002667	26.668603	0.263050	1243.882324	0.000000	NaN	NaN
557.000859	0.002766	27.661929	0.263756	1244.577515	0.000000	NaN	NaN
558.500944	0.002642	26.420272	0.264279	1245.092407	0.000000	NaN	NaN
560.001030	0.002832	28.324146	0.265115	1245.916016	0.000000	NaN	NaN
561.501116	0.002791	27.910260	0.265759	1246.550415	0.000000	NaN	NaN
563.001202	0.002659	26.585826	0.266368	1247.149780	0.000000	NaN	NaN
564.500287	0.002717	27.165266	0.267230	1247.998413	0.000000	NaN	NaN
566.000373	0.002700	26.999712	0.267833	1248.592041	0.000000	NaN	NaN
567.500459	0.002741	27.413597	0.268448	1249.198120	0.000000	NaN	NaN
569.000545	0.002717	27.165266	0.269232	1249.970337	0.000000	NaN	NaN
570.500631	0.002799	27.993037	0.269803	1250.532593	0.000000	NaN	NaN
572.000716	0.002659	26.585826	0.270469	1251.188843	0.000000	NaN	NaN
573.500802	0.002675	26.751380	0.271188	1251.896851	0.000000	NaN	NaN
575.000888	0.002832	28.324146	0.271857	1252.555664	0.000000	NaN	NaN
576.499974	0.002799	27.993037	0.272495	1253.183594	0.000000	NaN	NaN
578.001060	0.002700	26.999712	0.273147	1253.825806	0.000000	NaN	NaN
579.500145	0.002659	26.585826	0.273744	1254.413452	0.000000	NaN	NaN
581.001231	0.002841	28.406923	0.274584	1255.240601	0.000000	NaN	NaN
582.500317	0.002717	27.165266	0.275224	1255.871338	0.000000	NaN	NaN
584.000403	0.002708	27.082489	0.275989	1256.624390	0.000000	NaN	NaN
585.500489	0.002700	26.999712	0.276494	1257.122314	0.000000	NaN	NaN
586.999574	0.002849	28.489700	0.277257	1257.873901	0.000000	NaN	NaN
588.499660	0.002824	28.241369	0.277814	1258.422363	0.000000	NaN	NaN
590.000746	0.002741	27.413597	0.278379	1258.978027	0.000000	NaN	NaN
591.500832	0.002816	28.158592	0.279138	1259.726318	0.000000	NaN	NaN
593.000918	0.002774	27.744706	0.279766	1260.343994	0.000000	NaN	NaN
594.501003	0.002824	28.241369	0.280527	1261.093872	0.000000	NaN	NaN
596.001089	0.002766	27.661929	0.281048	1261.606567	0.000000	NaN	NaN
597.500175	0.002857	28.572477	0.281719	1262.267334	0.000000	NaN	NaN
599.001261	0.002692	26.916934	0.282382	1262.920654	0.000000	NaN	NaN
600.500347	0.002758	27.579152	0.283154	1263.681274	0.000000	NaN	NaN
602.000432	0.002725	27.248043	0.283793	1264.310547	0.000000	NaN	NaN
603.500518	0.002849	28.489700	0.284418	1264.925293	0.000000	NaN	NaN
605.000604	0.002766	27.661929	0.285090	1265.587280	0.000000	NaN	NaN
606.500690	0.002824	28.241369	0.285603	1266.093262	0.000000	NaN	NaN
608.000776	0.002774	27.744706	0.286340	1266.819092	0.000000	NaN	NaN
609.499861	0.002824	28.241369	0.287055	1267.522827	0.000000	NaN	NaN
610.999947	0.002725	27.248043	0.287681	1268.139282	0.000000	NaN	NaN
612.500033	0.002799	27.993037	0.288294	1268.743408	0.000000	NaN	NaN
614.001119	0.002824	28.241369	0.289088	1269.524902	0.000000	NaN	NaN
615.501205	0.002857	28.572477	0.290399	1270.815918	0.000000	NaN	NaN
617.000290	0.002766	27.661929	0.290951	1271.359985	0.000000	NaN	NaN
618.499376	0.002741	27.413597	0.291697	1272.093994	0.000000	NaN	NaN
620.000462	0.002816	28.158592	0.292370	1272.756958	0.000000	NaN	NaN
621.499548	0.002692	26.916934	0.293122	1273.497803	0.000000	NaN	NaN
622.999633	0.002866	28.655254	0.293768	1274.134155	0.000000	NaN	NaN
624.499719	0.002799	27.993037	0.294383	1274.739746	0.000000	NaN	NaN
625.999805	0.002750	27.496374	0.295140	1275.484619	0.000000	NaN	NaN
627.500891	0.002741	27.413597	0.295556	1275.894653	0.000000	NaN	NaN
629.000977	0.002659	26.585826	0.296289	1276.616211	0.000000	NaN	NaN
630.501063	0.002890	28.903586	0.297015	1277.331421	0.000000	NaN	NaN
632.001148	0.002882	28.820809	0.297658	1277.965210	0.000000	NaN	NaN
633.501234	0.002750	27.496374	0.298334	1278.630859	0.000000	NaN	NaN
635.000320	0.002816	28.158592	0.299044	1279.329590	0.000000	NaN	NaN
636.500406	0.002683	26.834157	0.299594	1279.871826	0.000000	NaN	NaN
638.000491	0.002907	29.069140	0.300355	1280.621094	0.000000	NaN	NaN
639.500577	0.002841	28.406923	0.300841	1281.099609	0.000000	NaN	NaN
641.000663	0.002816	28.158592	0.301365	1281.615112	0.000000	NaN	NaN
642.500749	0.002832	28.324146	0.302090	1282.329346	0.000000	NaN	NaN
644.000835	0.002832	28.324146	0.302755	1282.984863	0.000000	NaN	NaN
645.499920	0.002849	28.489700	0.303415	1283.634155	0.000000	NaN	NaN
647.001006	0.002882	28.820809	0.304141	1284.349731	0.000000	NaN	NaN
648.501092	0.002832	28.324146	0.304791	1284.989746	0.000000	NaN	NaN
650.001178	0.002824	28.241369	0.305408	1285.597778	0.000000	NaN	NaN
651.501264	0.002799	27.993037	0.305964	1286.144775	0.000000	NaN	NaN
653.000349	0.002791	27.910260	0.306700	1286.869995	0.000000	NaN	NaN
654.500435	0.002940	29.400249	0.307238	1287.399048	0.000000	NaN	NaN
656.000521	0.002824	28.241369	0.308063	1288.211914	0.000000	NaN	NaN
657.499607	0.002832	28.324146	0.308616	1288.756592	0.000000	NaN	NaN
658.999693	0.002849	28.489700	0.309317	1289.446411	0.000000	NaN	NaN
660.500778	0.002948	29.483026	0.309893	1290.014038	0.000000	NaN	NaN
662.000864	0.002841	28.406923	0.310548	1290.659180	0.000000	NaN	NaN
663.500950	0.002849	28.489700	0.311188	1291.289551	0.000000	NaN	NaN
665.001036	0.002808	28.075814	0.311735	1291.828247	0.000000	NaN	NaN
666.500122	0.002832	28.324146	0.312583	1292.663574	0.000000	NaN	NaN
668.001207	0.002874	28.738031	0.312996	1293.070068	0.000000	NaN	NaN
669.500293	0.002890	28.903586	0.313805	1293.867310	0.000000	NaN	NaN
671.000379	0.002866	28.655254	0.314280	1294.334473	0.000000	NaN	NaN
672.500465	0.002849	28.489700	0.314953	1294.997070	0.000000	NaN	NaN
674.000551	0.002849	28.489700	0.315544	1295.578979	0.000000	NaN	NaN
675.500636	0.002841	28.406923	0.316197	1296.222290	0.000000	NaN	NaN
677.000722	0.002708	27.082489	0.316755	1296.772095	0.000000	NaN	NaN
678.499808	0.002882	28.820809	0.317420	1297.427490	0.000000	NaN	NaN
680.000894	0.002874	28.738031	0.318074	1298.071045	0.000000	NaN	NaN
681.500980	0.002882	28.820809	0.318591	1298.580200	0.000000	NaN	NaN
683.001065	0.002816	28.158592	0.319310	1299.288330	0.000000	NaN	NaN
684.501151	0.002907	29.069140	0.319906	1299.875488	0.000000	NaN	NaN
686.001237	0.002882	28.820809	0.320605	1300.563843	0.000000	NaN	NaN
687.500323	0.002750	27.496374	0.321286	1301.234741	0.000000	NaN	NaN
689.000409	0.002923	29.234694	0.321756	1301.697021	0.000000	NaN	NaN
690.500494	0.002882	28.820809	0.322532	1302.461426	0.000000	NaN	NaN
692.000580	0.002890	28.903586	0.323050	1302.972046	0.000000	NaN	NaN
693.499666	0.002816	28.158592	0.323787	1303.697388	0.000000	NaN	NaN
695.000752	0.002932	29.317471	0.324286	1304.188965	0.000000	NaN	NaN
696.499837	0.003015	30.145243	0.324980	1304.872192	0.000000	NaN	NaN
698.000923	0.002990	29.896911	0.325589	1305.471802	0.000000	NaN	NaN
699.501009	0.002874	28.738031	0.326208	1306.081787	0.000000	NaN	NaN
701.003095	0.003039	30.393574	0.326797	1306.661255	0.000000	NaN	NaN
702.501181	0.002907	29.069140	0.327453	1307.307739	0.000000	NaN	NaN
704.001267	0.002932	29.317471	0.328171	1308.015259	0.000000	NaN	NaN
705.500352	0.003031	30.310797	0.328791	1308.625366	0.000000	NaN	NaN
707.006438	0.002907	29.069140	0.329436	1309.260620	0.000000	NaN	NaN
708.500524	0.002973	29.731357	0.330058	1309.873535	0.000000	NaN	NaN
710.000610	0.002932	29.317471	0.330590	1310.397461	0.000000	NaN	NaN
711.500695	0.002932	29.317471	0.331397	1311.192261	0.000000	NaN	NaN
713.009782	0.002923	29.234694	0.331943	1311.729614	0.000000	NaN	NaN
714.500867	0.003048	30.476351	0.332590	1312.366821	0.000000	NaN	NaN
716.000953	0.002957	29.565803	0.333020	1312.790161	0.000000	NaN	NaN
717.501039	0.002907	29.069140	0.333856	1313.613037	0.000000	NaN	NaN
719.013125	0.003006	30.062466	0.334509	1314.257080	0.000000	NaN	NaN
720.501210	0.002915	29.151917	0.335028	1314.767700	0.000000	NaN	NaN
722.000296	0.002915	29.151917	0.335647	1315.377686	0.000000	NaN	NaN
723.500382	0.002957	29.565803	0.336232	1315.953125	0.000000	NaN	NaN
725.000468	0.002899	28.986363	0.336939	1316.649658	0.000000	NaN	NaN
726.500553	0.003023	30.228020	0.337533	1317.235107	0.000000	NaN	NaN
728.000639	0.002808	28.075814	0.338112	1317.804810	0.000000	NaN	NaN
729.499725	0.002940	29.400249	0.338807	1318.489136	0.000000	NaN	NaN
731.000811	0.003039	30.393574	0.339442	1319.114624	0.000000	NaN	NaN
732.499897	0.002907	29.069140	0.340084	1319.746704	0.000000	NaN	NaN
734.000982	0.003023	30.228020	0.340713	1320.366333	0.000000	NaN	NaN
735.500068	0.002866	28.655254	0.341123	1320.769775	0.000000	NaN	NaN
737.000154	0.002957	29.565803	0.341909	1321.544556	0.000000	NaN	NaN
738.500240	0.002915	29.151917	0.342630	1322.254395	0.000000	NaN	NaN
740.000326	0.002923	29.234694	0.343169	1322.784912	0.000000	NaN	NaN
741.499411	0.002923	29.234694	-1.000000	0.000000	0.000000	NaN	NaN
743.000497	0.002957	29.565803	0.345062	1324.649658	0.000000	NaN	NaN
744.500583	0.002923	29.234694	0.345661	1325.239014	0.000000	NaN	NaN
746.000669	0.002940	29.400249	0.346401	1325.968262	0.000000	NaN	NaN
747.500755	0.002932	29.317471	0.347038	1326.595825	0.000000	NaN	NaN
749.000840	0.002907	29.069140	0.347615	1327.163818	0.000000	NaN	NaN
750.500926	0.002849	28.489700	0.348100	1327.641724	0.000000	NaN	NaN
752.000012	0.002932	29.317471	0.348712	1328.244019	0.000000	NaN	NaN
753.500098	0.002948	29.483026	0.349253	1328.776611	0.000000	NaN	NaN
755.001184	0.002866	28.655254	0.349952	1329.465332	0.000000	NaN	NaN
756.500269	0.003006	30.062466	0.350473	1329.977905	0.000000	NaN	NaN
758.000355	0.003023	30.228020	0.351184	1330.679077	0.000000	NaN	NaN
759.500441	0.002990	29.896911	0.351846	1331.330566	0.000000	NaN	NaN
761.000527	0.002882	28.820809	0.352355	1331.831665	0.000000	NaN	NaN
762.500612	0.002998	29.979689	0.352981	1332.448242	0.000000	NaN	NaN
764.000698	0.003048	30.476351	0.353777	1333.232422	0.000000	NaN	NaN
765.500784	0.002981	29.814134	0.354326	1333.772583	0.000000	NaN	NaN
767.000870	0.002957	29.565803	0.355031	1334.467529	0.000000	NaN	NaN
768.500956	0.002932	29.317471	0.355477	1334.906860	0.000000	NaN	NaN
770.001042	0.003015	30.145243	0.356080	1335.500610	0.000000	NaN	NaN
771.501127	0.002940	29.400249	0.356835	1336.243774	0.000000	NaN	NaN
773.001213	0.002932	29.317471	0.357333	1336.734619	0.000000	NaN	NaN
774.499299	0.002890	28.903586	0.357889	1337.281982	0.000000	NaN	NaN
776.000385	0.002965	29.648580	0.358639	1338.020752	0.000000	NaN	NaN
777.500470	0.003015	30.145243	0.359194	1338.567261	0.000000	NaN	NaN
779.000556	0.003048	30.476351	0.359951	1339.312744	0.000000	NaN	NaN
780.500642	0.002998	29.979689	0.360550	1339.902588	0.000000	NaN	NaN
782.000728	0.002923	29.234694	0.361297	1340.637817	0.000000	NaN	NaN
783.500814	0.003023	30.228020	0.361847	1341.179321	0.000000	NaN	NaN
785.000899	0.003064	30.641906	0.362337	1341.662354	0.000000	NaN	NaN
786.500985	0.003048	30.476351	0.362930	1342.245972	0.000000	NaN	NaN
788.001071	0.003056	30.559129	0.363524	1342.831177	0.000000	NaN	NaN
789.500157	0.002957	29.565803	0.364286	1343.581299	0.000000	NaN	NaN
791.001243	0.003056	30.559129	0.364694	1343.983276	0.000000	NaN	NaN
792.499328	0.003023	30.228020	0.365319	1344.599121	0.000000	NaN	NaN
794.000414	0.003056	30.559129	0.366009	1345.278564	0.000000	NaN	NaN
795.500500	0.003056	30.559129	0.366713	1345.971436	0.000000	NaN	NaN
797.000586	0.003031	30.310797	0.367351	1346.600464	0.000000	NaN	NaN
798.500672	0.003006	30.062466	0.367918	1347.158813	0.000000	NaN	NaN
800.000757	0.003048	30.476351	0.368468	1347.699951	0.000000	NaN	NaN
801.500843	0.003023	30.228020	0.369177	1348.398315	0.000000	NaN	NaN
803.000929	0.002990	29.896911	0.369722	1348.935547	0.000000	NaN	NaN
804.501015	0.003048	30.476351	0.370258	1349.463013	0.000000	NaN	NaN
806.001101	0.002907	29.069140	0.370929	1350.123779	0.000000	NaN	NaN
807.501186	0.002965	29.648580	0.371482	1350.668945	0.000000	NaN	NaN
809.001272	0.003072	30.724683	0.372183	1351.359253	0.000000	NaN	NaN
810.499358	0.002923	29.234694	0.372769	1351.935913	0.000000	NaN	NaN
812.000444	0.002990	29.896911	0.373418	1352.574707	0.000000	NaN	NaN
813.500529	0.003056	30.559129	0.373851	1353.001831	0.000000	NaN	NaN
815.000615	0.003197	31.966340	0.374512	1353.652710	0.000000	NaN	NaN
816.500701	0.003114	31.138569	-1.000000	0.000000	0.000000	NaN	NaN
817.999787	0.002990	29.896911	0.374969	1354.102295	0.000000	NaN	NaN
819.499873	0.002981	29.814134	0.375389	1354.516113	0.000000	NaN	NaN
821.000959	0.003114	31.138569	0.376147	1355.262695	0.000000	NaN	NaN
822.500044	0.003072	30.724683	0.376691	1355.798950	0.000000	NaN	NaN
824.001130	0.003048	30.476351	0.377264	1356.362671	0.000000	NaN	NaN
825.500216	0.002990	29.896911	0.377755	1356.845947	0.000000	NaN	NaN
827.000302	0.003015	30.145243	0.378497	1357.577148	0.000000	NaN	NaN
828.500387	0.003072	30.724683	0.379112	1358.182495	0.000000	NaN	NaN
830.000473	0.003015	30.145243	0.379669	1358.731323	0.000000	NaN	NaN
831.500559	0.003056	30.559129	0.380272	1359.325317	0.000000	NaN	NaN
833.000645	0.003122	31.221346	0.380949	1359.991577	0.000000	NaN	NaN
834.500731	0.003023	30.228020	0.381268	1360.305908	0.000000	NaN	NaN
836.000817	0.002923	29.234694	0.381893	1360.921143	0.000000	NaN	NaN
837.499902	0.003006	30.062466	0.382341	1361.362427	0.000000	NaN	NaN
839.000988	0.003039	30.393574	0.382914	1361.927368	0.000000	NaN	NaN
840.500074	0.003072	30.724683	0.383566	1362.569458	0.000000	NaN	NaN
842.001160	0.003023	30.228020	0.384088	1363.083008	0.000000	NaN	NaN
843.501245	0.003015	30.145243	0.384776	1363.760376	0.000000	NaN	NaN
845.000331	0.002932	29.317471	0.385331	1364.307495	0.000000	NaN	NaN
846.500417	0.003114	31.138569	0.385992	1364.958618	0.000000	NaN	NaN
848.000503	0.003048	30.476351	0.386552	1365.509644	0.000000	NaN	NaN
849.500589	0.003122	31.221346	0.387138	1366.087280	0.000000	NaN	NaN
851.000674	0.003114	31.138569	0.387652	1366.592896	0.000000	NaN	NaN
852.500760	0.003064	30.641906	0.388451	1367.380249	0.000000	NaN	NaN
854.000846	0.002998	29.979689	0.388981	1367.901489	0.000000	NaN	NaN
855.499932	0.003031	30.310797	0.389585	1368.496948	0.000000	NaN	NaN
857.001018	0.002981	29.814134	0.390167	1369.069824	0.000000	NaN	NaN
858.501103	0.003056	30.559129	0.390654	1369.549561	0.000000	NaN	NaN
860.001189	0.003172	31.718009	0.391381	1370.265503	0.000000	NaN	NaN
861.500275	0.003106	31.055791	0.391892	1370.769043	0.000000	NaN	NaN
863.000361	0.003031	30.310797	0.392462	1371.330566	0.000000	NaN	NaN
864.500447	0.003039	30.393574	0.392970	1371.830078	0.000000	NaN	NaN
866.000532	0.003023	30.228020	0.393699	1372.548340	0.000000	NaN	NaN
867.499618	0.003106	31.055791	0.394123	1372.966064	0.000000	NaN	NaN
869.000704	0.003039	30.393574	0.394728	1373.561401	0.000000	NaN	NaN
870.500790	0.003155	31.552454	0.395384	1374.207764	0.000000	NaN	NaN
872.000876	0.003081	30.807460	0.396000	1374.813965	0.000000	NaN	NaN
873.500961	0.003106	31.055791	0.396551	1375.357178	0.000000	NaN	NaN
875.001047	0.003106	31.055791	0.397283	1376.078247	0.000000	NaN	NaN
876.501133	0.002981	29.814134	0.397625	1376.414917	0.000000	NaN	NaN
878.001219	0.003106	31.055791	0.398316	1377.094971	0.000000	NaN	NaN
879.500304	0.002998	29.979689	0.398915	1377.685059	0.000000	NaN	NaN
881.000390	0.002923	29.234694	0.399379	1378.141968	0.000000	NaN	NaN
882.500476	0.003006	30.062466	0.400130	1378.881470	0.000000	NaN	NaN
884.000562	0.003081	30.807460	0.400714	1379.457031	0.000000	NaN	NaN
885.500648	0.003031	30.310797	0.401321	1380.054932	0.000000	NaN	NaN
887.000734	0.003031	30.310797	0.401877	1380.602417	0.000000	NaN	NaN
888.499819	0.002957	29.565803	0.402565	1381.279297	0.000000	NaN	NaN
890.000905	0.002973	29.731357	0.403026	1381.734009	0.000000	NaN	NaN
891.499991	0.003056	30.559129	0.403548	1382.248169	0.000000	NaN	NaN
893.001077	0.003081	30.807460	0.403992	1382.685425	0.000000	NaN	NaN
894.500162	0.002948	29.483026	0.404624	1383.307129	0.000000	NaN	NaN
896.001248	0.002965	29.648580	0.405191	1383.866333	0.000000	NaN	NaN
897.499334	0.002915	29.151917	0.405862	1384.526978	0.000000	NaN	NaN
899.000420	0.003155	31.552454	0.406255	1384.914185	0.000000	NaN	NaN
900.500506	0.002965	29.648580	0.406937	1385.585449	0.000000	NaN	NaN
901.999591	0.003155	31.552454	0.407535	1386.174194	0.000000	NaN	NaN
903.500677	0.002973	29.731357	0.408183	1386.812988	0.000000	NaN	NaN
905.000763	0.003006	30.062466	0.408737	1387.358521	0.000000	NaN	NaN
906.500849	0.002998	29.979689	0.409095	1387.710571	0.000000	NaN	NaN
908.000935	0.003015	30.145243	0.409689	1388.296143	0.000000	NaN	NaN
909.500020	0.003015	30.145243	0.410028	1388.629272	0.000000	NaN	NaN
911.000106	0.003023	30.228020	0.410992	1389.578735	0.000000	NaN	NaN
912.501192	0.003147	31.469677	0.411226	1389.808960	0.000000	NaN	NaN
914.001278	0.002998	29.979689	0.411999	1390.570679	0.000000	NaN	NaN
915.500364	0.002948	29.483026	0.412233	1390.801514	0.000000	NaN	NaN
916.999449	0.003056	30.559129	0.416572	1395.074219	0.000000	NaN	NaN
918.499535	0.002981	29.814134	0.417161	1395.654541	0.000000	NaN	NaN
920.000621	0.002923	29.234694	-0.728114	267.760193	0.000000	NaN	NaN
921.500707	0.002890	28.903586	0.418212	1396.689087	0.000000	NaN	NaN
922.999793	0.003006	30.062466	-1.000000	0.000000	0.000000	NaN	NaN
924.500878	0.002998	29.979689	0.413344	1391.895630	0.000000	NaN	NaN
926.000964	0.003023	30.228020	0.414057	1392.597656	0.000000	NaN	NaN
927.501050	0.002874	28.738031	0.414529	1393.062622	0.000000	NaN	NaN
929.001136	0.003081	30.807460	0.415120	1393.644287	0.000000	NaN	NaN
930.500221	0.002973	29.731357	0.415760	1394.274292	0.000000	NaN	NaN
931.999307	0.002948	29.483026	0.416380	1394.885376	0.000000	NaN	NaN
933.499393	0.003031	30.310797	0.417039	1395.534058	0.000000	NaN	NaN
935.000479	0.003048	30.476351	0.417511	1395.999146	0.000000	NaN	NaN
936.499565	0.003072	30.724683	0.418089	1396.568359	0.000000	NaN	NaN
938.000651	0.002990	29.896911	0.418686	1397.156006	0.000000	NaN	NaN
939.500736	0.002998	29.979689	0.419271	1397.731812	0.000000	NaN	NaN
941.000822	0.002990	29.896911	0.419802	1398.255493	0.000000	NaN	NaN
942.500908	0.003048	30.476351	0.420467	1398.909668	0.000000	NaN	NaN
944.000994	0.003114	31.138569	0.421003	1399.437866	0.000000	NaN	NaN
945.501079	0.003023	30.228020	0.421516	1399.943604	0.000000	NaN	NaN
947.001165	0.003023	30.228020	0.422109	1400.526978	0.000000	NaN	NaN
948.501251	0.003122	31.221346	0.422733	1401.141724	0.000000	NaN	NaN
950.000337	0.003097	30.973014	0.423294	1401.694458	0.000000	NaN	NaN
951.499423	0.003031	30.310797	0.423869	1402.260620	0.000000	NaN	NaN
953.000509	0.002940	29.400249	0.424413	1402.796021	0.000000	NaN	NaN
954.500594	0.003064	30.641906	0.424975	1403.349731	0.000000	NaN	NaN
956.000680	0.002899	28.986363	0.425533	1403.898804	0.000000	NaN	NaN
957.500766	0.002990	29.896911	0.426005	1404.363892	0.000000	NaN	NaN
959.000852	0.002965	29.648580	0.426648	1404.996826	0.000000	NaN	NaN
960.500937	0.002948	29.483026	0.427221	1405.562012	0.000000	NaN	NaN
962.001023	0.002957	29.565803	0.427552	1405.887207	0.000000	NaN	NaN
963.501109	0.002899	28.986363	0.428107	1406.434570	0.000000	NaN	NaN
965.001195	0.002990	29.896911	0.428577	1406.896606	0.000000	NaN	NaN
966.500281	0.002899	28.986363	0.429171	1407.482178	0.000000	NaN	NaN
967.999366	0.003048	30.476351	0.429646	1407.949585	0.000000	NaN	NaN
969.500452	0.002899	28.986363	0.430004	1408.302368	0.000000	NaN	NaN
970.999538	0.002890	28.903586	0.430469	1408.759888	0.000000	NaN	NaN
972.500624	0.002923	29.234694	0.430770	1409.056641	0.000000	NaN	NaN
974.000710	0.002915	29.151917	0.431320	1409.598022	0.000000	NaN	NaN
975.500795	0.002725	27.248043	0.431699	1409.971191	0.000000	NaN	NaN
977.000881	0.002783	27.827483	0.432146	1410.412109	0.000000	NaN	NaN
978.499967	0.002808	28.075814	0.432301	1410.564697	0.000000	NaN	NaN
980.000053	0.002774	27.744706	0.432685	1410.943115	0.000000	NaN	NaN
981.501139	0.002866	28.655254	0.433008	1411.261230	0.000000	NaN	NaN
983.001224	0.002708	27.082489	0.433241	1411.490723	0.000000	NaN	NaN
984.500310	0.002692	26.916934	0.433581	1411.825439	0.000000	NaN	NaN
985.999396	0.002791	27.910260	0.433457	1411.703003	0.000000	NaN	NaN
987.500482	0.002568	25.675277	0.433836	1412.076050	0.000000	NaN	NaN
989.000568	0.002576	25.758054	0.433947	1412.185303	0.000000	NaN	NaN
990.500653	0.002642	26.420272	0.434059	1412.295654	0.000000	NaN	NaN
992.000739	0.002468	24.681952	0.434041	1412.278198	0.000000	NaN	NaN
993.499825	0.002476	24.764729	0.434248	1412.482422	0.000000	NaN	NaN
994.999911	0.002286	22.860854	0.434058	1412.294678	0.000000	NaN	NaN
996.500997	0.002245	22.446969	0.433682	1411.924194	0.000000	NaN	NaN
998.001082	0.002236	22.364192	0.433623	1411.866455	0.000000	NaN	NaN
999.501168	0.002054	20.543094	0.433215	1411.464722	0.000000	NaN	NaN
1001.001254	0.001963	19.632546	0.432810	1411.065796	0.000000	NaN	NaN
1002.499340	0.001740	17.397563	0.432503	1410.763550	0.000000	NaN	NaN
1004.000426	0.001525	15.245357	0.431692	1409.964478	0.000000	NaN	NaN
1005.500511	-0.000280	-2.800060	1.164470	2131.621826	0.000000	NaN	NaN
1007.000597	-0.000263	-2.634506	1.160614	2127.824707	0.000000	NaN	NaN
1008.500683	-0.000313	-3.131169	1.158834	2126.072021	0.000000	NaN	NaN
1010.000769	-0.000313	-3.131169	1.112503	2080.444092	0.000000	NaN	NaN
1011.500854	-0.000363	-3.627832	1.110980	2078.943604	0.000000	NaN	NaN
1013.000940	-0.000222	-2.220620	1.108555	2076.556152	0.000000	NaN	NaN
1014.501026	-0.000346	-3.462277	1.108254	2076.259277	0.000000	NaN	NaN
1016.001112	-0.000297	-2.965615	0.510271	1487.351196	0.000000	NaN	NaN
1017.501198	-0.000230	-2.303397	-0.652643	342.085358	0.000000	NaN	NaN
1018.000226	-0.000321	-3.213946	0.509931	1487.016357	0.000000	NaN	NaN