File: data/57k_1-3_3 (190415).lvm
LabVIEW Measurement
Writer_Version	2
Reader_Version	2
Separator	Tab
Decimal_Separator	.
Multi_Headings	No
X_Columns	One
Time_Pref	Absolute
Operator	user
Description	Load(N)/Stress(MPa)/Distance A(pixel)/Strain A/Distance B(pixel)/Strain B/Poisson's ratio
Date	2019/04/15
Time	10:27:11.3033933639526367187
***End_of_Header***

Notes	X 값은 오직 다음과 같을 때에만 유효함이 보장됩니다. Dev1/ai0
Channels	7
Samples	1	1	1	1	1	1	1
Date	2019/04/15	2019/04/15	2019/04/15	2019/04/15	2019/04/15	2019/04/15	2019/04/15
Time	11:12:02.8033385300347370674	11:12:02.8033385300347370674	11:12:02.8033385276794433594	11:12:02.8033385276794433594	11:12:02.8033385276794433594	11:12:02.8033385276794433594	11:12:02.8033385276794433594
Y_Unit_Label	Volts	Volts
X_Dimension	Time	Time	Time	Time	Time	Time	Time
X0	0.0000000000000000E+0	0.0000000000000000E+0	0.0000000000000000E+0	0.0000000000000000E+0	0.0000000000000000E+0	0.0000000000000000E+0	0.0000000000000000E+0
Delta_X	0.000000	0.000000	1.000000	1.000000	1.000000	1.000000	1.000000
***End_of_Header***
X_Value	Dev1/ai0	Dev1/ai0 1	Untitled	Untitled 1	Untitled 2	Untitled 3	Untitled 4	Comment
0.000000	3.444320E-5	0.344432	-2.574921E-5	1000.306396	0.000000	NaN	NaN
1.000057	-3.983212E-5	-0.398321	-9.685755E-5	1000.235291	0.000000	NaN	NaN
2.000114	-3.157930E-5	-0.315793	-8.106232E-6	1000.324036	0.000000	NaN	NaN
3.000172	-3.983212E-5	-0.398321	0.000325	1000.657715	0.000000	NaN	NaN
4.000229	-6.820864E-6	-0.068209	0.000616	1000.948608	0.000000	NaN	NaN
5.000286	-2.332649E-5	-0.233265	0.000811	1001.143066	0.000000	NaN	NaN
6.000343	1.431948E-6	0.014319	0.001116	1001.448425	0.000000	NaN	NaN
7.000400	0.000109	1.087185	0.001469	1001.802002	0.000000	NaN	NaN
7.999458	0.000125	1.252241	0.001611	1001.943359	0.000000	NaN	NaN
8.999515	0.000191	1.912466	0.001874	1002.206604	0.000000	NaN	NaN
9.999572	0.000158	1.582354	0.002176	1002.508606	0.000000	NaN	NaN
10.999629	0.000133	1.334770	0.002392	1002.724854	0.000000	NaN	NaN
11.999686	0.000266	2.655220	0.002743	1003.075562	0.000000	NaN	NaN
12.999744	0.000315	3.150388	0.002895	1003.227722	0.000000	NaN	NaN
13.999801	0.000109	1.087185	0.003058	1003.390869	0.000000	NaN	NaN
14.999858	0.000233	2.325107	0.003246	1003.578796	0.000000	NaN	NaN
15.999915	0.000142	1.417298	0.003346	1003.679321	0.000000	NaN	NaN
16.999972	0.000381	3.810613	0.003759	1004.092224	0.000000	NaN	NaN
18.000030	0.000332	3.315445	0.003911	1004.244385	0.000000	NaN	NaN
19.000087	0.000224	2.242579	0.004240	1004.573181	0.000000	NaN	NaN
20.000144	0.000505	5.048535	0.004344	1004.677551	0.000000	NaN	NaN
21.000201	0.000455	4.553366	0.004746	1005.079529	0.000000	NaN	NaN
22.000258	0.000431	4.305782	0.004901	1005.234619	0.000000	NaN	NaN
23.000316	0.000348	3.480501	0.005166	1005.499390	0.000000	NaN	NaN
24.000373	0.000497	4.966007	0.005437	1005.771057	0.000000	NaN	NaN
24.999430	0.000629	6.286457	0.005733	1006.067200	0.000000	NaN	NaN
25.999487	0.000488	4.883479	0.006083	1006.417358	0.000000	NaN	NaN
26.999544	0.000629	6.286457	0.006512	1006.846619	0.000000	NaN	NaN
27.999602	0.000604	6.038873	0.006787	1007.121704	0.000000	NaN	NaN
28.999659	0.000571	5.708760	0.007263	1007.597595	0.000000	NaN	NaN
29.999716	0.000629	6.286457	0.007545	1007.879639	0.000000	NaN	NaN
30.999773	0.000629	6.286457	0.007887	1008.221252	0.000000	NaN	NaN
31.999830	0.000686	6.864154	0.008480	1008.814758	0.000000	NaN	NaN
32.999887	0.000678	6.781626	0.008792	1009.126770	0.000000	NaN	NaN
33.999945	0.000612	6.121401	0.009161	1009.496216	0.000000	NaN	NaN
35.000002	0.000670	6.699098	0.009494	1009.829102	0.000000	NaN	NaN
36.000059	0.000728	7.276795	0.009870	1010.205688	0.000000	NaN	NaN
37.000116	0.000695	6.946682	0.010343	1010.678772	0.000000	NaN	NaN
38.000174	0.000810	8.102076	0.010742	1011.077393	0.000000	NaN	NaN
39.000231	0.000728	7.276795	0.010965	1011.300415	0.000000	NaN	NaN
40.000288	0.000653	6.534042	0.011444	1011.780029	0.000000	NaN	NaN
41.000345	0.000951	9.505054	0.011788	1012.123718	0.000000	NaN	NaN
42.000402	0.000810	8.102076	0.012169	1012.505127	0.000000	NaN	NaN
42.999460	0.000851	8.514717	0.012473	1012.808899	0.000000	NaN	NaN
43.999517	0.000810	8.102076	0.013070	1013.406555	0.000000	NaN	NaN
44.999574	0.000917	9.174942	0.013530	1013.867004	0.000000	NaN	NaN
45.999631	0.000827	8.267132	0.013809	1014.145813	0.000000	NaN	NaN
46.999688	0.000893	8.927357	0.014154	1014.491272	0.000000	NaN	NaN
47.999746	0.000934	9.339998	0.014605	1014.941711	0.000000	NaN	NaN
48.999803	0.000868	8.679773	0.015016	1015.353577	0.000000	NaN	NaN
49.999860	0.000876	8.762301	0.015421	1015.758240	0.000000	NaN	NaN
50.999917	0.000934	9.339998	0.016001	1016.338806	0.000000	NaN	NaN
51.999974	0.001074	10.742976	0.016039	1016.376221	0.000000	NaN	NaN
53.000031	0.001050	10.495392	0.016662	1016.999695	0.000000	NaN	NaN
54.000089	0.000901	9.009885	0.017098	1017.436279	0.000000	NaN	NaN
55.000146	0.000951	9.505054	0.017416	1017.753479	0.000000	NaN	NaN
56.000203	0.000975	9.752638	0.017607	1017.944763	0.000000	NaN	NaN
57.000260	0.001041	10.412863	0.017985	1018.322754	0.000000	NaN	NaN
58.000318	0.001000	10.000223	0.018424	1018.762146	0.000000	NaN	NaN
59.000375	0.001000	10.000223	0.018636	1018.973816	0.000000	NaN	NaN
59.999432	0.001116	11.155617	0.019198	1019.536926	0.000000	NaN	NaN
60.999489	0.001033	10.330335	0.019566	1019.904907	0.000000	NaN	NaN
61.999546	0.001033	10.330335	0.019803	1020.141846	0.000000	NaN	NaN
62.999603	0.001074	10.742976	0.020413	1020.752014	0.000000	NaN	NaN
63.999661	0.001107	11.073088	0.020977	1021.315857	0.000000	NaN	NaN
64.999718	0.001083	10.825504	0.021242	1021.581543	0.000000	NaN	NaN
65.999775	0.001182	11.815842	0.021865	1022.204041	0.000000	NaN	NaN
66.999832	0.001132	11.320673	0.022306	1022.645142	0.000000	NaN	NaN
67.999889	0.001132	11.320673	0.022745	1023.084900	0.000000	NaN	NaN
68.999947	0.001256	12.558595	0.023241	1023.581177	0.000000	NaN	NaN
70.000004	0.001173	11.733313	0.023622	1023.962402	0.000000	NaN	NaN
71.000061	0.001157	11.568257	0.024283	1024.623535	0.000000	NaN	NaN
72.000118	0.001264	12.641123	0.024738	1025.078247	0.000000	NaN	NaN
73.000175	0.001264	12.641123	0.025371	1025.711670	0.000000	NaN	NaN
74.000233	0.001132	11.320673	0.025846	1026.186768	0.000000	NaN	NaN
75.000290	0.001149	11.485729	0.026161	1026.501953	0.000000	NaN	NaN
76.000347	0.001248	12.476067	0.026793	1027.133789	0.000000	NaN	NaN
77.000404	0.001248	12.476067	0.027259	1027.599731	0.000000	NaN	NaN
77.999461	0.001297	12.971235	0.027622	1027.963501	0.000000	NaN	NaN
78.999519	0.001132	11.320673	0.028022	1028.363281	0.000000	NaN	NaN
79.999576	0.001223	12.228482	0.028601	1028.942261	0.000000	NaN	NaN
80.999633	0.001173	11.733313	0.029190	1029.531860	0.000000	NaN	NaN
81.999690	0.001355	13.548932	0.029609	1029.951294	0.000000	NaN	NaN
82.999747	0.001190	11.898370	0.030151	1030.492676	0.000000	NaN	NaN
83.999805	0.001206	12.063426	0.030745	1031.087280	0.000000	NaN	NaN
84.999862	0.001380	13.796517	0.031411	1031.753906	0.000000	NaN	NaN
85.999919	0.001355	13.548932	0.031863	1032.205811	0.000000	NaN	NaN
86.999976	0.001297	12.971235	0.032442	1032.785156	0.000000	NaN	NaN
88.000033	0.001297	12.971235	0.032789	1033.131592	0.000000	NaN	NaN
89.000091	0.001421	14.209157	0.033207	1033.550293	0.000000	NaN	NaN
90.000148	0.001388	13.879045	0.033676	1034.019409	0.000000	NaN	NaN
91.000205	0.001314	13.136292	0.034252	1034.595337	0.000000	NaN	NaN
92.000262	0.001248	12.476067	0.034913	1035.257080	0.000000	NaN	NaN
93.000319	0.001223	12.228482	0.035174	1035.517944	0.000000	NaN	NaN
94.000377	0.001248	12.476067	0.035626	1035.969727	0.000000	NaN	NaN
94.999434	0.001281	12.806179	0.036127	1036.471313	0.000000	NaN	NaN
95.999491	0.001429	14.291685	0.036663	1037.007690	0.000000	NaN	NaN
96.999548	0.001363	13.631460	0.037349	1037.693726	0.000000	NaN	NaN
97.999605	0.001347	13.466404	0.037894	1038.238647	0.000000	NaN	NaN
98.999662	0.001413	14.126629	0.038166	1038.511108	0.000000	NaN	NaN
99.999720	0.001314	13.136292	0.038509	1038.854248	0.000000	NaN	NaN
100.999777	0.001264	12.641123	0.039032	1039.376953	0.000000	NaN	NaN
101.999834	0.001289	12.888707	0.039258	1039.602661	0.000000	NaN	NaN
102.999891	0.001338	13.383876	0.039801	1040.146118	0.000000	NaN	NaN
103.999949	0.001289	12.888707	0.040384	1040.729980	0.000000	NaN	NaN
105.000006	0.001437	14.374213	0.040783	1041.129150	0.000000	NaN	NaN
106.000063	0.001347	13.466404	0.041127	1041.473267	0.000000	NaN	NaN
107.000120	0.001305	13.053763	0.041611	1041.956787	0.000000	NaN	NaN
108.000177	0.001421	14.209157	0.042132	1042.478271	0.000000	NaN	NaN
109.000235	0.001421	14.209157	0.042675	1043.021851	0.000000	NaN	NaN
110.000292	0.001404	14.044101	0.042891	1043.236938	0.000000	NaN	NaN
111.000349	0.001437	14.374213	0.043315	1043.661743	0.000000	NaN	NaN
112.000406	0.001338	13.383876	0.043936	1044.283203	0.000000	NaN	NaN
112.999463	0.001289	12.888707	0.044299	1044.645874	0.000000	NaN	NaN
113.999520	0.001314	13.136292	0.044884	1045.230713	0.000000	NaN	NaN
114.999578	0.001305	13.053763	0.045181	1045.528320	0.000000	NaN	NaN
115.999635	0.001347	13.466404	0.044760	1045.107178	0.000000	NaN	NaN
116.999692	0.001363	13.631460	0.045307	1045.653809	0.000000	NaN	NaN
117.999749	0.001396	13.961573	0.046259	1046.606689	0.000000	NaN	NaN
118.999806	0.001404	14.044101	0.046863	1047.210937	0.000000	NaN	NaN
119.999864	0.001371	13.713988	0.047206	1047.553467	0.000000	NaN	NaN
120.999921	0.001470	14.704326	0.047722	1048.069824	0.000000	NaN	NaN
121.999978	0.001413	14.126629	0.048234	1048.581787	0.000000	NaN	NaN
123.000035	0.001404	14.044101	0.048675	1049.023437	0.000000	NaN	NaN
124.000092	0.001462	14.621798	0.049228	1049.576660	0.000000	NaN	NaN
125.000150	0.001371	13.713988	0.049663	1050.011963	0.000000	NaN	NaN
126.000207	0.001363	13.631460	0.050125	1050.473999	0.000000	NaN	NaN
127.000264	0.001454	14.539270	0.050607	1050.956421	0.000000	NaN	NaN
128.000321	0.001355	13.548932	0.051111	1051.459839	0.000000	NaN	NaN
129.000378	0.001322	13.218820	0.051573	1051.922241	0.000000	NaN	NaN
129.999436	0.001446	14.456742	0.052055	1052.404175	0.000000	NaN	NaN
130.999493	0.001421	14.209157	0.052484	1052.833862	0.000000	NaN	NaN
131.999550	0.001355	13.548932	0.052956	1053.306030	0.000000	NaN	NaN
132.999607	0.001380	13.796517	0.053481	1053.830688	0.000000	NaN	NaN
133.999664	0.001487	14.869382	0.053936	1054.285645	0.000000	NaN	NaN
134.999722	0.001429	14.291685	0.054436	1054.786377	0.000000	NaN	NaN
135.999779	0.001371	13.713988	0.054889	1055.239868	0.000000	NaN	NaN
136.999836	0.001437	14.374213	0.055357	1055.707153	0.000000	NaN	NaN
137.999893	0.001338	13.383876	0.055907	1056.257935	0.000000	NaN	NaN
138.999950	0.001437	14.374213	0.056409	1056.759888	0.000000	NaN	NaN
140.000008	0.001421	14.209157	0.056836	1057.186768	0.000000	NaN	NaN
141.000065	0.001553	15.529607	0.057297	1057.648560	0.000000	NaN	NaN
142.000122	0.001404	14.044101	0.057825	1058.176514	0.000000	NaN	NaN
143.000179	0.001528	15.282023	0.058280	1058.631470	0.000000	NaN	NaN
144.000236	0.001503	15.034438	0.058867	1059.218506	0.000000	NaN	NaN
145.000294	0.001404	14.044101	0.059280	1059.631836	0.000000	NaN	NaN
146.000351	0.001454	14.539270	0.059769	1060.120728	0.000000	NaN	NaN
147.000408	0.001421	14.209157	0.060322	1060.673950	0.000000	NaN	NaN
147.999465	0.001545	15.447079	0.060687	1061.039429	0.000000	NaN	NaN
148.999522	0.001421	14.209157	0.061190	1061.542725	0.000000	NaN	NaN
149.999580	0.001429	14.291685	0.061718	1062.071045	0.000000	NaN	NaN
150.999637	0.001470	14.704326	0.062150	1062.502686	0.000000	NaN	NaN
151.999694	0.001363	13.631460	0.062704	1063.057007	0.000000	NaN	NaN
152.999751	0.001495	14.951910	0.063183	1063.536499	0.000000	NaN	NaN
153.999808	0.001446	14.456742	0.063674	1064.027344	0.000000	NaN	NaN
154.999865	0.001528	15.282023	0.064124	1064.477295	0.000000	NaN	NaN
155.999923	0.001470	14.704326	0.064643	1064.996704	0.000000	NaN	NaN
156.999980	0.001396	13.961573	0.065108	1065.461670	0.000000	NaN	NaN
158.000037	0.001479	14.786854	0.065679	1066.032959	0.000000	NaN	NaN
159.000094	0.001503	15.034438	0.066187	1066.540771	0.000000	NaN	NaN
160.000151	0.001413	14.126629	0.066657	1067.011353	0.000000	NaN	NaN
161.000209	0.001520	15.199495	0.067126	1067.480835	0.000000	NaN	NaN
162.000266	0.001470	14.704326	0.067621	1067.976074	0.000000	NaN	NaN
163.000323	0.001536	15.364551	0.068094	1068.449219	0.000000	NaN	NaN
164.000380	0.001512	15.116967	0.068635	1068.989990	0.000000	NaN	NaN
164.999437	0.001338	13.383876	0.069106	1069.460693	0.000000	NaN	NaN
165.999495	0.001512	15.116967	0.069571	1069.926514	0.000000	NaN	NaN
166.999552	0.001536	15.364551	0.070110	1070.465454	0.000000	NaN	NaN
167.999609	0.001578	15.777192	0.070541	1070.896362	0.000000	NaN	NaN
168.999666	0.001479	14.786854	0.071017	1071.372681	0.000000	NaN	NaN
169.999723	0.001520	15.199495	0.071597	1071.952393	0.000000	NaN	NaN
170.999781	0.001528	15.282023	0.072093	1072.448853	0.000000	NaN	NaN
171.999838	0.001512	15.116967	0.072544	1072.899902	0.000000	NaN	NaN
172.999895	0.001594	15.942248	0.072980	1073.336426	0.000000	NaN	NaN
173.999952	0.001487	14.869382	0.073518	1073.875000	0.000000	NaN	NaN
175.000010	0.001454	14.539270	0.074039	1074.395630	0.000000	NaN	NaN
176.000067	0.001512	15.116967	0.074571	1074.928101	0.000000	NaN	NaN
177.000124	0.001470	14.704326	0.074903	1075.259766	0.000000	NaN	NaN
178.000181	0.001561	15.612135	0.075487	1075.844360	0.000000	NaN	NaN
179.000238	0.001528	15.282023	0.076024	1076.380981	0.000000	NaN	NaN
180.000295	0.001528	15.282023	0.076542	1076.899780	0.000000	NaN	NaN
181.000353	0.001594	15.942248	0.077059	1077.417114	0.000000	NaN	NaN
182.000410	0.001470	14.704326	0.077458	1077.815430	0.000000	NaN	NaN
182.999467	0.001545	15.447079	0.077976	1078.333862	0.000000	NaN	NaN
183.999524	0.001528	15.282023	0.078460	1078.817749	0.000000	NaN	NaN
184.999581	0.001586	15.859720	0.078993	1079.351562	0.000000	NaN	NaN
185.999639	0.001619	16.189832	0.079403	1079.761108	0.000000	NaN	NaN
186.999696	0.001553	15.529607	0.079922	1080.281006	0.000000	NaN	NaN
187.999753	0.001503	15.034438	0.080490	1080.848999	0.000000	NaN	NaN
188.999810	0.001594	15.942248	0.081012	1081.371582	0.000000	NaN	NaN
189.999867	0.001553	15.529607	0.081414	1081.773682	0.000000	NaN	NaN
190.999925	0.001594	15.942248	0.081909	1082.268066	0.000000	NaN	NaN
191.999982	0.001503	15.034438	0.082486	1082.845947	0.000000	NaN	NaN
193.000039	0.001586	15.859720	0.082868	1083.228149	0.000000	NaN	NaN
194.000096	0.001487	14.869382	0.083472	1083.831421	0.000000	NaN	NaN
195.000153	0.001545	15.447079	0.083967	1084.327515	0.000000	NaN	NaN
196.000211	0.001553	15.529607	0.084487	1084.847656	0.000000	NaN	NaN
197.000268	0.001528	15.282023	0.084957	1085.317261	0.000000	NaN	NaN
198.000325	0.001545	15.447079	0.085378	1085.738159	0.000000	NaN	NaN
199.000382	0.001586	15.859720	0.085939	1086.299927	0.000000	NaN	NaN
199.999439	0.001487	14.869382	0.086520	1086.880981	0.000000	NaN	NaN
200.999497	0.001553	15.529607	0.087011	1087.371948	0.000000	NaN	NaN
201.999554	0.001520	15.199495	0.087422	1087.782959	0.000000	NaN	NaN
202.999611	0.001718	17.180170	0.088003	1088.364624	0.000000	NaN	NaN
203.999668	0.001503	15.034438	0.088481	1088.842163	0.000000	NaN	NaN
204.999725	0.001611	16.107304	0.088978	1089.339233	0.000000	NaN	NaN
205.999783	0.001512	15.116967	0.089516	1089.877686	0.000000	NaN	NaN
206.999840	0.001413	14.126629	0.090034	1090.396484	0.000000	NaN	NaN
207.999897	0.001619	16.189832	0.090449	1090.810913	0.000000	NaN	NaN
208.999954	0.001602	16.024776	0.090883	1091.244995	0.000000	NaN	NaN
210.000011	0.001569	15.694663	0.091518	1091.880737	0.000000	NaN	NaN
211.000069	0.001602	16.024776	0.091832	1092.194214	0.000000	NaN	NaN
212.000126	0.001594	15.942248	0.092519	1092.881714	0.000000	NaN	NaN
213.000183	0.001602	16.024776	0.093039	1093.402100	0.000000	NaN	NaN
214.000240	0.001479	14.786854	0.093489	1093.852417	0.000000	NaN	NaN
215.000297	0.001586	15.859720	0.094011	1094.374634	0.000000	NaN	NaN
216.000355	0.001619	16.189832	0.094371	1094.734863	0.000000	NaN	NaN
217.000412	0.001602	16.024776	0.095014	1095.377441	0.000000	NaN	NaN
217.999469	0.001602	16.024776	0.095585	1095.949341	0.000000	NaN	NaN
218.999526	0.001553	15.529607	0.095991	1096.355347	0.000000	NaN	NaN
219.999583	0.001470	14.704326	0.096523	1096.887085	0.000000	NaN	NaN
220.999640	0.001495	14.951910	0.097075	1097.439087	0.000000	NaN	NaN
221.999698	0.001553	15.529607	0.097616	1097.980835	0.000000	NaN	NaN
222.999755	0.001569	15.694663	0.098071	1098.435181	0.000000	NaN	NaN
223.999812	0.001520	15.199495	0.098357	1098.722046	0.000000	NaN	NaN
224.999869	0.001578	15.777192	0.098875	1099.239990	0.000000	NaN	NaN
225.999926	0.001503	15.034438	0.099567	1099.932129	0.000000	NaN	NaN
226.999984	0.001594	15.942248	0.099937	1100.302612	0.000000	NaN	NaN
228.000041	0.001586	15.859720	0.100365	1100.730103	0.000000	NaN	NaN
229.000098	0.001652	16.519945	0.100866	1101.231689	0.000000	NaN	NaN
230.000155	0.001594	15.942248	0.101319	1101.684448	0.000000	NaN	NaN
231.000213	0.001594	15.942248	0.101941	1102.306763	0.000000	NaN	NaN
232.000270	0.001454	14.539270	0.102465	1102.830811	0.000000	NaN	NaN
233.000327	0.001561	15.612135	0.102935	1103.301758	0.000000	NaN	NaN
234.000384	0.001503	15.034438	0.103477	1103.843994	0.000000	NaN	NaN
234.999441	0.001553	15.529607	0.103979	1104.346069	0.000000	NaN	NaN
235.999498	0.001545	15.447079	0.104484	1104.850952	0.000000	NaN	NaN
236.999556	0.001487	14.869382	0.104829	1105.195801	0.000000	NaN	NaN
237.999613	0.001743	17.427754	0.105384	1105.750854	0.000000	NaN	NaN
238.999670	0.001561	15.612135	0.105836	1106.203369	0.000000	NaN	NaN
239.999727	0.001718	17.180170	0.106336	1106.703857	0.000000	NaN	NaN
240.999784	0.001660	16.602473	0.106793	1107.160278	0.000000	NaN	NaN
241.999842	0.001611	16.107304	0.107290	1107.658203	0.000000	NaN	NaN
242.999899	0.001677	16.767529	0.107891	1108.258545	0.000000	NaN	NaN
243.999956	0.001594	15.942248	0.108429	1108.797485	0.000000	NaN	NaN
245.000013	0.001528	15.282023	0.108845	1109.213013	0.000000	NaN	NaN
246.000070	0.001536	15.364551	0.109434	1109.802246	0.000000	NaN	NaN
247.000128	0.001413	14.126629	0.109918	1110.287109	0.000000	NaN	NaN
248.000185	0.001652	16.519945	0.110285	1110.653687	0.000000	NaN	NaN
249.000242	0.001652	16.519945	0.110750	1111.118652	0.000000	NaN	NaN
250.000299	0.001685	16.850057	0.111284	1111.653320	0.000000	NaN	NaN
251.000356	0.001702	17.015114	0.111697	1112.066528	0.000000	NaN	NaN
252.000414	0.001495	14.951910	0.112179	1112.548096	0.000000	NaN	NaN
252.999471	0.001619	16.189832	0.112552	1112.921997	0.000000	NaN	NaN
253.999528	0.001586	15.859720	0.113145	1113.515259	0.000000	NaN	NaN
254.999585	0.001528	15.282023	0.113684	1114.053955	0.000000	NaN	NaN
255.999642	0.001619	16.189832	0.114146	1114.516235	0.000000	NaN	NaN
256.999700	0.001561	15.612135	0.114677	1115.046997	0.000000	NaN	NaN
257.999757	0.001677	16.767529	0.115135	1115.505859	0.000000	NaN	NaN
258.999814	0.001660	16.602473	0.115716	1116.086304	0.000000	NaN	NaN
259.999871	0.001702	17.015114	0.116206	1116.576782	0.000000	NaN	NaN
260.999928	0.001611	16.107304	0.116729	1117.100098	0.000000	NaN	NaN
261.999986	0.001627	16.272360	0.117043	1117.414185	0.000000	NaN	NaN
263.000043	0.001619	16.189832	0.117512	1117.882690	0.000000	NaN	NaN
264.000100	0.001545	15.447079	0.118081	1118.452148	0.000000	NaN	NaN
265.000157	0.001520	15.199495	0.118428	1118.799683	0.000000	NaN	NaN
266.000214	0.001586	15.859720	0.118784	1119.155151	0.000000	NaN	NaN
267.000272	0.001801	18.005451	0.118225	1118.596191	0.000000	NaN	NaN
268.000329	0.001479	14.786854	0.118833	1119.204224	0.000000	NaN	NaN
269.000386	0.001594	15.942248	0.119649	1120.020630	0.000000	NaN	NaN
269.999443	0.001553	15.529607	0.120173	1120.544922	0.000000	NaN	NaN
270.999500	0.001503	15.034438	0.120620	1120.992676	0.000000	NaN	NaN
271.999557	0.001702	17.015114	0.121244	1121.616699	0.000000	NaN	NaN
272.999615	0.001644	16.437417	0.121663	1122.035400	0.000000	NaN	NaN
273.999672	0.001594	15.942248	0.122228	1122.600464	0.000000	NaN	NaN
274.999729	0.001602	16.024776	0.122689	1123.061401	0.000000	NaN	NaN
275.999786	0.001503	15.034438	0.123075	1123.447632	0.000000	NaN	NaN
276.999843	0.001669	16.685001	0.123702	1124.074951	0.000000	NaN	NaN
277.999901	0.001735	17.345226	0.124179	1124.552368	0.000000	NaN	NaN
278.999958	0.001545	15.447079	0.124569	1124.942871	0.000000	NaN	NaN
280.000015	0.001611	16.107304	0.125141	1125.514526	0.000000	NaN	NaN
281.000072	0.001718	17.180170	0.125554	1125.927734	0.000000	NaN	NaN
282.000130	0.001693	16.932585	0.126185	1126.559326	0.000000	NaN	NaN
283.000187	0.001652	16.519945	0.126683	1127.057617	0.000000	NaN	NaN
284.000244	0.001627	16.272360	0.127066	1127.440430	0.000000	NaN	NaN
285.000301	0.001685	16.850057	0.127631	1128.005127	0.000000	NaN	NaN
286.000358	0.001660	16.602473	0.128121	1128.495361	0.000000	NaN	NaN
287.000415	0.001602	16.024776	0.128641	1129.015747	0.000000	NaN	NaN
287.999473	0.001569	15.694663	0.129118	1129.493164	0.000000	NaN	NaN
288.999530	0.001685	16.850057	0.129648	1130.022949	0.000000	NaN	NaN
289.999587	0.001660	16.602473	0.130034	1130.409424	0.000000	NaN	NaN
290.999644	0.001652	16.519945	0.130641	1131.016968	0.000000	NaN	NaN
291.999702	0.001635	16.354889	0.131047	1131.423218	0.000000	NaN	NaN
292.999759	0.001677	16.767529	0.131507	1131.882935	0.000000	NaN	NaN
293.999816	0.001660	16.602473	0.131932	1132.307495	0.000000	NaN	NaN
294.999873	0.001635	16.354889	0.132558	1132.934692	0.000000	NaN	NaN
295.999930	0.001536	15.364551	0.132957	1133.333374	0.000000	NaN	NaN
296.999987	0.001677	16.767529	0.133476	1133.852417	0.000000	NaN	NaN
298.000045	0.001635	16.354889	0.133944	1134.321045	0.000000	NaN	NaN
299.000102	0.001602	16.024776	0.134413	1134.789429	0.000000	NaN	NaN
300.000159	0.001792	17.922923	0.134911	1135.288086	0.000000	NaN	NaN
301.000216	0.001602	16.024776	0.135392	1135.768799	0.000000	NaN	NaN
302.000273	0.001660	16.602473	0.135785	1136.162720	0.000000	NaN	NaN
303.000331	0.001578	15.777192	0.136244	1136.621338	0.000000	NaN	NaN
304.000388	0.001652	16.519945	0.136705	1137.082642	0.000000	NaN	NaN
304.999445	0.001693	16.932585	0.137249	1137.626831	0.000000	NaN	NaN
305.999502	0.001702	17.015114	0.137664	1138.042358	0.000000	NaN	NaN
306.999559	0.001726	17.262698	0.138269	1138.647339	0.000000	NaN	NaN
307.999617	0.001660	16.602473	0.138643	1139.021118	0.000000	NaN	NaN
308.999674	0.001710	17.097642	0.139186	1139.564087	0.000000	NaN	NaN
309.999731	0.001454	14.539270	0.139642	1140.020020	0.000000	NaN	NaN
310.999788	0.001594	15.942248	0.140079	1140.457397	0.000000	NaN	NaN
311.999845	0.001602	16.024776	0.140434	1140.812866	0.000000	NaN	NaN
312.999903	0.001619	16.189832	0.141009	1141.388306	0.000000	NaN	NaN
313.999960	0.001677	16.767529	0.141514	1141.893311	0.000000	NaN	NaN
315.000017	0.001718	17.180170	0.141996	1142.375122	0.000000	NaN	NaN
316.000074	0.001718	17.180170	0.142381	1142.760376	0.000000	NaN	NaN
317.000131	0.001693	16.932585	0.142903	1143.282837	0.000000	NaN	NaN
318.000189	0.001726	17.262698	0.143359	1143.738403	0.000000	NaN	NaN
319.000246	0.001685	16.850057	0.143803	1144.182861	0.000000	NaN	NaN
320.000303	0.001792	17.922923	0.144349	1144.729248	0.000000	NaN	NaN
321.000360	0.001677	16.767529	0.144813	1145.193115	0.000000	NaN	NaN
322.000417	0.001627	16.272360	0.145287	1145.667847	0.000000	NaN	NaN
322.999475	0.001627	16.272360	0.145759	1146.139893	0.000000	NaN	NaN
323.999532	0.001669	16.685001	0.146231	1146.611328	0.000000	NaN	NaN
324.999589	0.001635	16.354889	0.146617	1146.998169	0.000000	NaN	NaN
325.999646	0.001660	16.602473	0.147084	1147.465454	0.000000	NaN	NaN
326.999703	0.001536	15.364551	0.147669	1148.049805	0.000000	NaN	NaN
327.999761	0.001710	17.097642	0.148102	1148.483032	0.000000	NaN	NaN
328.999818	0.001726	17.262698	0.148604	1148.985229	0.000000	NaN	NaN
329.999875	0.001702	17.015114	0.148929	1149.311035	0.000000	NaN	NaN
330.999932	0.001660	16.602473	0.149426	1149.807617	0.000000	NaN	NaN
331.999989	0.001619	16.189832	0.150006	1150.387573	0.000000	NaN	NaN
333.000047	0.001611	16.107304	0.150496	1150.878296	0.000000	NaN	NaN
334.000104	0.001685	16.850057	0.150960	1151.342529	0.000000	NaN	NaN
335.000161	0.001776	17.757867	0.151446	1151.828491	0.000000	NaN	NaN
336.000218	0.001768	17.675339	0.151895	1152.277222	0.000000	NaN	NaN
337.000275	0.001669	16.685001	0.152334	1152.716553	0.000000	NaN	NaN
338.000333	0.001710	17.097642	0.152874	1153.256958	0.000000	NaN	NaN
339.000390	0.001726	17.262698	0.153370	1153.753296	0.000000	NaN	NaN
339.999447	0.001619	16.189832	0.153759	1154.142700	0.000000	NaN	NaN
340.999504	0.001751	17.510282	0.154258	1154.641602	0.000000	NaN	NaN
341.999561	0.001718	17.180170	0.154757	1155.140503	0.000000	NaN	NaN
342.999618	0.001685	16.850057	0.155297	1155.680786	0.000000	NaN	NaN
343.999676	0.001718	17.180170	0.155663	1156.047363	0.000000	NaN	NaN
344.999733	0.001578	15.777192	0.156279	1156.663208	0.000000	NaN	NaN
345.999790	0.001569	15.694663	0.156738	1157.122192	0.000000	NaN	NaN
346.999847	0.001594	15.942248	0.157143	1157.526978	0.000000	NaN	NaN
347.999905	0.001619	16.189832	0.157685	1158.069824	0.000000	NaN	NaN
348.999962	0.001751	17.510282	0.158163	1158.547729	0.000000	NaN	NaN
350.000019	0.001784	17.840395	0.158652	1159.036499	0.000000	NaN	NaN
351.000076	0.001685	16.850057	0.159125	1159.510498	0.000000	NaN	NaN
352.000133	0.001834	18.335564	0.159572	1159.957520	0.000000	NaN	NaN
353.000190	0.001627	16.272360	0.159995	1160.380005	0.000000	NaN	NaN
354.000248	0.001718	17.180170	0.160436	1160.821655	0.000000	NaN	NaN
355.000305	0.001644	16.437417	0.160957	1161.342285	0.000000	NaN	NaN
356.000362	0.001759	17.592810	0.161447	1161.833008	0.000000	NaN	NaN
357.000419	0.001702	17.015114	0.161875	1162.261230	0.000000	NaN	NaN
357.999476	0.001611	16.107304	0.162381	1162.767212	0.000000	NaN	NaN
358.999534	0.001834	18.335564	0.162903	1163.289551	0.000000	NaN	NaN
359.999591	0.001710	17.097642	0.163378	1163.764893	0.000000	NaN	NaN
360.999648	0.001710	17.097642	0.163885	1164.271851	0.000000	NaN	NaN
361.999705	0.001710	17.097642	0.164356	1164.743042	0.000000	NaN	NaN
362.999762	0.001768	17.675339	0.164717	1165.104004	0.000000	NaN	NaN
363.999820	0.001792	17.922923	0.165270	1165.656616	0.000000	NaN	NaN
364.999877	0.001718	17.180170	0.165805	1166.191895	0.000000	NaN	NaN
365.999934	0.001768	17.675339	0.166292	1166.679077	0.000000	NaN	NaN
366.999991	0.001801	18.005451	0.166765	1167.152588	0.000000	NaN	NaN
368.000048	0.001759	17.592810	0.167264	1167.652222	0.000000	NaN	NaN
369.000106	0.001809	18.087979	0.167665	1168.052979	0.000000	NaN	NaN
370.000163	0.001652	16.519945	0.168156	1168.544189	0.000000	NaN	NaN
371.000220	0.001776	17.757867	0.168683	1169.071533	0.000000	NaN	NaN
372.000277	0.001545	15.447079	0.169175	1169.562866	0.000000	NaN	NaN
373.000334	0.001801	18.005451	0.169678	1170.066650	0.000000	NaN	NaN
374.000392	0.001669	16.685001	0.170160	1170.548584	0.000000	NaN	NaN
374.999449	0.001834	18.335564	0.170654	1171.042603	0.000000	NaN	NaN
375.999506	0.001685	16.850057	0.171178	1171.566772	0.000000	NaN	NaN
376.999563	0.001743	17.427754	0.171604	1171.992798	0.000000	NaN	NaN
377.999620	0.001619	16.189832	0.172119	1172.508423	0.000000	NaN	NaN
378.999678	0.001644	16.437417	0.172082	1172.471436	0.000000	NaN	NaN
379.999735	0.001875	18.748204	0.172546	1172.935303	0.000000	NaN	NaN
380.999792	0.001677	16.767529	0.173048	1173.437744	0.000000	NaN	NaN
381.999849	0.001801	18.005451	0.173456	1173.846191	0.000000	NaN	NaN
382.999906	0.001685	16.850057	0.173964	1174.354004	0.000000	NaN	NaN
383.999964	0.001735	17.345226	0.174587	1174.976929	0.000000	NaN	NaN
385.000021	0.001660	16.602473	0.175029	1175.419556	0.000000	NaN	NaN
386.000078	0.001677	16.767529	0.175461	1175.851074	0.000000	NaN	NaN
387.000135	0.001825	18.253035	0.175969	1176.359497	0.000000	NaN	NaN
388.000192	0.001702	17.015114	0.176471	1176.861572	0.000000	NaN	NaN
389.000250	0.001693	16.932585	0.176946	1177.336792	0.000000	NaN	NaN
390.000307	0.001710	17.097642	0.177414	1177.805176	0.000000	NaN	NaN
391.000364	0.001809	18.087979	0.178054	1178.445435	0.000000	NaN	NaN
392.000421	0.001702	17.015114	0.178429	1178.820679	0.000000	NaN	NaN
392.999478	0.001809	18.087979	0.178985	1179.376343	0.000000	NaN	NaN
393.999535	0.001718	17.180170	0.179416	1179.807861	0.000000	NaN	NaN
394.999593	0.001726	17.262698	0.179940	1180.331787	0.000000	NaN	NaN
395.999650	0.001635	16.354889	0.180385	1180.776733	0.000000	NaN	NaN
396.999707	0.001809	18.087979	0.180913	1181.305176	0.000000	NaN	NaN
397.999764	0.001792	17.922923	0.181394	1181.786011	0.000000	NaN	NaN
398.999821	0.001776	17.757867	0.181943	1182.335815	0.000000	NaN	NaN
399.999879	0.001883	18.830732	0.182446	1182.838989	0.000000	NaN	NaN
400.999936	0.001776	17.757867	0.182907	1183.299683	0.000000	NaN	NaN
401.999993	0.001759	17.592810	0.183350	1183.743286	0.000000	NaN	NaN
403.000050	0.001801	18.005451	0.183863	1184.256592	0.000000	NaN	NaN
404.000108	0.001768	17.675339	0.184385	1184.777954	0.000000	NaN	NaN
405.000165	0.001751	17.510282	0.184817	1185.210327	0.000000	NaN	NaN
406.000222	0.001875	18.748204	0.185396	1185.789307	0.000000	NaN	NaN
407.000279	0.001834	18.335564	0.185834	1186.227905	0.000000	NaN	NaN
408.000336	0.001784	17.840395	0.186238	1186.632080	0.000000	NaN	NaN
409.000393	0.001702	17.015114	0.186825	1187.218872	0.000000	NaN	NaN
409.999451	0.001875	18.748204	0.187228	1187.621948	0.000000	NaN	NaN
410.999508	0.001801	18.005451	0.187625	1188.019897	0.000000	NaN	NaN
411.999565	0.001693	16.932585	0.188210	1188.604980	0.000000	NaN	NaN
412.999622	0.001710	17.097642	0.188639	1189.033447	0.000000	NaN	NaN
413.999680	0.001850	18.500620	0.189232	1189.627075	0.000000	NaN	NaN
414.999737	0.001669	16.685001	0.189740	1190.135010	0.000000	NaN	NaN
415.999794	0.001710	17.097642	0.190153	1190.548340	0.000000	NaN	NaN
416.999851	0.001743	17.427754	0.190620	1191.015869	0.000000	NaN	NaN
417.999908	0.001792	17.922923	0.191096	1191.491333	0.000000	NaN	NaN
418.999965	0.001850	18.500620	0.191491	1191.886353	0.000000	NaN	NaN
420.000023	0.001817	18.170507	0.192013	1192.409058	0.000000	NaN	NaN
421.000080	0.001842	18.418092	0.192619	1193.015625	0.000000	NaN	NaN
422.000137	0.001817	18.170507	0.193030	1193.425781	0.000000	NaN	NaN
423.000194	0.001825	18.253035	0.193545	1193.941406	0.000000	NaN	NaN
424.000251	0.001817	18.170507	0.193933	1194.329590	0.000000	NaN	NaN
425.000309	0.001768	17.675339	0.194583	1194.980103	0.000000	NaN	NaN
426.000366	0.001784	17.840395	0.194963	1195.359863	0.000000	NaN	NaN
426.999423	0.001801	18.005451	0.195468	1195.864990	0.000000	NaN	NaN
427.999480	0.001759	17.592810	0.195856	1196.253052	0.000000	NaN	NaN
428.999537	0.001784	17.840395	0.196388	1196.785156	0.000000	NaN	NaN
429.999595	0.001933	19.325901	0.196940	1197.337891	0.000000	NaN	NaN
430.999652	0.001784	17.840395	0.197423	1197.820801	0.000000	NaN	NaN
431.999709	0.001685	16.850057	0.197911	1198.308960	0.000000	NaN	NaN
432.999766	0.001850	18.500620	0.198484	1198.881836	0.000000	NaN	NaN
433.999823	0.001718	17.180170	0.198874	1199.272461	0.000000	NaN	NaN
434.999881	0.001718	17.180170	0.199457	1199.854980	0.000000	NaN	NaN
435.999938	0.001801	18.005451	0.199928	1200.326904	0.000000	NaN	NaN
436.999995	0.001825	18.253035	0.200410	1200.808472	0.000000	NaN	NaN
438.000052	0.001792	17.922923	0.201014	1201.412964	0.000000	NaN	NaN
439.000109	0.001875	18.748204	0.201488	1201.886963	0.000000	NaN	NaN
440.000167	0.001784	17.840395	0.201948	1202.347046	0.000000	NaN	NaN
441.000224	0.001809	18.087979	0.202504	1202.903687	0.000000	NaN	NaN
442.000281	0.001900	18.995789	0.202887	1203.286377	0.000000	NaN	NaN
443.000338	0.001842	18.418092	0.203447	1203.846313	0.000000	NaN	NaN
444.000395	0.001702	17.015114	0.203953	1204.352539	0.000000	NaN	NaN
444.999453	0.001933	19.325901	0.204425	1204.824585	0.000000	NaN	NaN
445.999510	0.001883	18.830732	0.204957	1205.357544	0.000000	NaN	NaN
446.999567	0.001867	18.665676	0.205357	1205.757812	0.000000	NaN	NaN
447.999624	0.001776	17.757867	0.206015	1206.415039	0.000000	NaN	NaN
448.999681	0.001817	18.170507	0.206556	1206.956665	0.000000	NaN	NaN
449.999739	0.001867	18.665676	0.206909	1207.309570	0.000000	NaN	NaN
450.999796	0.001908	19.078317	0.207387	1207.788208	0.000000	NaN	NaN
451.999853	0.001842	18.418092	0.208078	1208.479492	0.000000	NaN	NaN
452.999910	0.001858	18.583148	0.208502	1208.903442	0.000000	NaN	NaN
453.999967	0.001850	18.500620	0.208862	1209.263062	0.000000	NaN	NaN
455.000025	0.001743	17.427754	0.209379	1209.780273	0.000000	NaN	NaN
456.000082	0.001784	17.840395	0.209930	1210.332153	0.000000	NaN	NaN
457.000139	0.001891	18.913260	0.209228	1209.629395	0.000000	NaN	NaN
458.000196	0.001751	17.510282	0.209736	1210.137817	0.000000	NaN	NaN
459.000253	0.001900	18.995789	0.210240	1210.641968	0.000000	NaN	NaN
460.000311	0.001834	18.335564	0.210593	1210.995605	0.000000	NaN	NaN
461.000368	0.001784	17.840395	0.211124	1211.526489	0.000000	NaN	NaN
461.999425	0.001875	18.748204	0.211650	1212.052734	0.000000	NaN	NaN
462.999482	0.001759	17.592810	0.212043	1212.445557	0.000000	NaN	NaN
463.999539	0.001817	18.170507	0.212649	1213.052124	0.000000	NaN	NaN
464.999596	0.001834	18.335564	0.213028	1213.431396	0.000000	NaN	NaN
465.999654	0.001776	17.757867	0.213597	1213.999634	0.000000	NaN	NaN
466.999711	0.001792	17.922923	0.213996	1214.399292	0.000000	NaN	NaN
467.999768	0.001850	18.500620	0.214442	1214.845337	0.000000	NaN	NaN
468.999825	0.001842	18.418092	0.214992	1215.395508	0.000000	NaN	NaN
469.999883	0.001792	17.922923	0.215389	1215.792847	0.000000	NaN	NaN
470.999940	0.001801	18.005451	0.215956	1216.359741	0.000000	NaN	NaN
471.999997	0.001891	18.913260	0.216476	1216.880005	0.000000	NaN	NaN
473.000054	0.001842	18.418092	0.216986	1217.389771	0.000000	NaN	NaN
474.000111	0.001891	18.913260	0.217448	1217.852661	0.000000	NaN	NaN
475.000168	0.001726	17.262698	0.218122	1218.526245	0.000000	NaN	NaN
476.000226	0.001900	18.995789	0.218405	1218.809814	0.000000	NaN	NaN
477.000283	0.001825	18.253035	0.218954	1219.359131	0.000000	NaN	NaN
478.000340	0.001883	18.830732	0.219400	1219.804565	0.000000	NaN	NaN
479.000397	0.001834	18.335564	0.219916	1220.321167	0.000000	NaN	NaN
479.999454	0.001825	18.253035	0.220314	1220.718872	0.000000	NaN	NaN
480.999512	0.001941	19.408429	0.220939	1221.344727	0.000000	NaN	NaN
481.999569	0.001966	19.656014	0.221438	1221.843628	0.000000	NaN	NaN
482.999626	0.001867	18.665676	0.221905	1222.310791	0.000000	NaN	NaN
483.999683	0.001900	18.995789	0.222479	1222.885376	0.000000	NaN	NaN
484.999740	0.001842	18.418092	0.222876	1223.281982	0.000000	NaN	NaN
485.999798	0.001850	18.500620	0.223452	1223.858276	0.000000	NaN	NaN
486.999855	0.001891	18.913260	0.223989	1224.395508	0.000000	NaN	NaN
487.999912	0.001974	19.738542	0.224376	1224.782837	0.000000	NaN	NaN
488.999969	0.001990	19.903598	0.224798	1225.204468	0.000000	NaN	NaN
490.000026	0.001776	17.757867	0.225265	1225.671875	0.000000	NaN	NaN
491.000084	0.001792	17.922923	0.225766	1226.173462	0.000000	NaN	NaN
492.000141	0.001809	18.087979	0.226418	1226.825806	0.000000	NaN	NaN
493.000198	0.001817	18.170507	0.226867	1227.274170	0.000000	NaN	NaN
494.000255	0.001883	18.830732	0.227217	1227.624878	0.000000	NaN	NaN
495.000312	0.001908	19.078317	0.227701	1228.109131	0.000000	NaN	NaN
496.000370	0.001809	18.087979	0.228260	1228.668213	0.000000	NaN	NaN
496.999427	0.001726	17.262698	0.228618	1229.025635	0.000000	NaN	NaN
497.999484	0.001858	18.583148	0.229197	1229.605103	0.000000	NaN	NaN
498.999541	0.001660	16.602473	0.229727	1230.135132	0.000000	NaN	NaN
499.999598	0.001751	17.510282	0.230165	1230.573120	0.000000	NaN	NaN
500.999656	0.001883	18.830732	0.230701	1231.109863	0.000000	NaN	NaN
501.999713	0.001792	17.922923	0.231259	1231.668457	0.000000	NaN	NaN
502.999770	0.001809	18.087979	0.231605	1232.013672	0.000000	NaN	NaN
503.999827	0.001842	18.418092	0.232240	1232.649780	0.000000	NaN	NaN
504.999884	0.001834	18.335564	0.232668	1233.077271	0.000000	NaN	NaN
505.999942	0.001726	17.262698	0.233255	1233.664795	0.000000	NaN	NaN
506.999999	0.002015	20.151182	0.233693	1234.102539	0.000000	NaN	NaN
508.000056	0.001801	18.005451	0.234060	1234.470093	0.000000	NaN	NaN
509.000113	0.001792	17.922923	0.234902	1235.312012	0.000000	NaN	NaN
510.000170	0.001817	18.170507	0.234193	1234.602783	0.000000	NaN	NaN
511.000228	0.001883	18.830732	0.234751	1235.160889	0.000000	NaN	NaN
512.000285	0.001809	18.087979	0.235479	1235.888916	0.000000	NaN	NaN
513.000342	0.001801	18.005451	0.236001	1236.411255	0.000000	NaN	NaN
514.000399	0.001834	18.335564	0.236270	1236.680298	0.000000	NaN	NaN
514.999456	0.001825	18.253035	0.236793	1237.203369	0.000000	NaN	NaN
515.999514	0.001957	19.573485	0.237309	1237.719604	0.000000	NaN	NaN
516.999571	0.001850	18.500620	0.237680	1238.090820	0.000000	NaN	NaN
517.999628	0.002114	21.141520	0.238782	1239.192993	0.000000	NaN	NaN
518.999685	0.001941	19.408429	0.239397	1239.808960	0.000000	NaN	NaN
519.999742	0.001908	19.078317	0.239767	1240.178589	0.000000	NaN	NaN
520.999799	0.001644	16.437417	0.240383	1240.794556	0.000000	NaN	NaN
521.999857	0.001883	18.830732	0.240659	1241.071289	0.000000	NaN	NaN
522.999914	0.001924	19.243373	0.241265	1241.677368	0.000000	NaN	NaN
523.999971	0.001801	18.005451	0.241783	1242.195435	0.000000	NaN	NaN
525.000028	0.001875	18.748204	0.242410	1242.822510	0.000000	NaN	NaN
526.000085	0.001858	18.583148	0.242799	1243.211670	0.000000	NaN	NaN
527.000143	0.001883	18.830732	0.243421	1243.834106	0.000000	NaN	NaN
528.000200	0.001834	18.335564	0.242965	1243.378174	0.000000	NaN	NaN
529.000257	0.001759	17.592810	0.243575	1243.988525	0.000000	NaN	NaN
530.000314	0.001966	19.656014	0.244005	1244.418701	0.000000	NaN	NaN
531.000372	0.001949	19.490957	0.244555	1244.968628	0.000000	NaN	NaN
531.999429	0.001850	18.500620	0.245217	1245.630249	0.000000	NaN	NaN
532.999486	0.001735	17.345226	0.245669	1246.082520	0.000000	NaN	NaN
533.999543	0.001850	18.500620	0.246092	1246.505493	0.000000	NaN	NaN
534.999600	0.001924	19.243373	0.246594	1247.008179	0.000000	NaN	NaN
535.999658	0.001900	18.995789	0.247063	1247.477173	0.000000	NaN	NaN
536.999715	0.001809	18.087979	0.247528	1247.942383	0.000000	NaN	NaN
537.999772	0.001809	18.087979	0.247608	1248.022705	0.000000	NaN	NaN
538.999829	0.001842	18.418092	0.247890	1248.304321	0.000000	NaN	NaN
539.999886	0.001735	17.345226	0.248218	1248.632324	0.000000	NaN	NaN
540.999943	0.001858	18.583148	0.248829	1249.243774	0.000000	NaN	NaN
542.000001	0.001718	17.180170	0.249065	1249.479492	0.000000	NaN	NaN
543.000058	0.001825	18.253035	0.249620	1250.035156	0.000000	NaN	NaN
544.000115	0.001916	19.160845	0.249994	1250.409546	0.000000	NaN	NaN
545.000172	0.001941	19.408429	0.250445	1250.860840	0.000000	NaN	NaN
546.000230	0.001949	19.490957	0.251122	1251.537231	0.000000	NaN	NaN
547.000287	0.001850	18.500620	0.251504	1251.919312	0.000000	NaN	NaN
548.000344	0.001900	18.995789	0.251842	1252.258301	0.000000	NaN	NaN
549.000401	0.001900	18.995789	0.252308	1252.724365	0.000000	NaN	NaN
549.999458	0.001776	17.757867	0.252885	1253.300781	0.000000	NaN	NaN
550.999515	0.001834	18.335564	0.253316	1253.731934	0.000000	NaN	NaN
551.999573	0.001900	18.995789	0.253793	1254.209229	0.000000	NaN	NaN
552.999630	0.001817	18.170507	0.254382	1254.799194	0.000000	NaN	NaN
553.999687	0.001858	18.583148	0.254825	1255.242187	0.000000	NaN	NaN
554.999744	0.001825	18.253035	0.255272	1255.688721	0.000000	NaN	NaN
555.999801	0.001949	19.490957	0.255706	1256.123413	0.000000	NaN	NaN
556.999859	0.001924	19.243373	0.256258	1256.675171	0.000000	NaN	NaN
557.999916	0.001702	17.015114	0.256533	1256.950439	0.000000	NaN	NaN
558.999973	0.001883	18.830732	0.257307	1257.724854	0.000000	NaN	NaN
560.000030	0.001867	18.665676	0.257573	1257.990601	0.000000	NaN	NaN
561.000087	0.001710	17.097642	0.258179	1258.596680	0.000000	NaN	NaN
562.000145	0.001834	18.335564	0.258695	1259.112671	0.000000	NaN	NaN
563.000202	0.001743	17.427754	0.259396	1259.814087	0.000000	NaN	NaN
564.000259	0.001702	17.015114	0.259889	1260.307373	0.000000	NaN	NaN
565.000316	0.001768	17.675339	0.260292	1260.710205	0.000000	NaN	NaN
566.000373	0.001924	19.243373	0.260688	1261.107056	0.000000	NaN	NaN
566.999431	0.002023	20.233710	0.260405	1260.823608	0.000000	NaN	NaN
567.999488	0.001891	18.913260	0.260846	1261.264404	0.000000	NaN	NaN
568.999545	0.001916	19.160845	0.261389	1261.808228	0.000000	NaN	NaN
569.999602	0.001891	18.913260	0.261818	1262.237305	0.000000	NaN	NaN
570.999659	0.001982	19.821070	0.262264	1262.683716	0.000000	NaN	NaN
571.999717	0.001933	19.325901	0.262789	1263.208374	0.000000	NaN	NaN
572.999774	0.001875	18.748204	0.263355	1263.775146	0.000000	NaN	NaN
573.999831	0.001801	18.005451	0.263741	1264.160767	0.000000	NaN	NaN
574.999888	0.001702	17.015114	0.263963	1264.382324	0.000000	NaN	NaN
575.999945	0.001792	17.922923	0.264138	1264.558105	0.000000	NaN	NaN
577.000003	0.001916	19.160845	0.264417	1264.836914	0.000000	NaN	NaN
578.000060	0.001792	17.922923	0.265185	1265.604858	0.000000	NaN	NaN
579.000117	0.001842	18.418092	0.265555	1265.975464	0.000000	NaN	NaN
580.000174	0.001850	18.500620	0.266105	1266.525757	0.000000	NaN	NaN
581.000231	0.001891	18.913260	0.266505	1266.925537	0.000000	NaN	NaN
582.000289	0.001858	18.583148	0.267108	1267.528809	0.000000	NaN	NaN
583.000346	0.001850	18.500620	0.267564	1267.985107	0.000000	NaN	NaN
584.000403	0.001801	18.005451	0.269036	1269.457642	0.000000	NaN	NaN
584.999460	0.001743	17.427754	0.269142	1269.563110	0.000000	NaN	NaN
585.999517	0.001817	18.170507	0.268842	1269.263550	0.000000	NaN	NaN
586.999574	0.001933	19.325901	0.269361	1269.782837	0.000000	NaN	NaN
587.999632	0.001834	18.335564	0.269771	1270.192993	0.000000	NaN	NaN
588.999689	0.001933	19.325901	0.270461	1270.882690	0.000000	NaN	NaN
589.999746	0.001817	18.170507	0.270867	1271.288696	0.000000	NaN	NaN
590.999803	0.001941	19.408429	0.271232	1271.653931	0.000000	NaN	NaN
591.999860	0.001842	18.418092	0.271946	1272.368774	0.000000	NaN	NaN
592.999918	0.001759	17.592810	0.272449	1272.871338	0.000000	NaN	NaN
593.999975	0.001867	18.665676	0.272874	1273.296631	0.000000	NaN	NaN
595.000032	0.001751	17.510282	0.273347	1273.769775	0.000000	NaN	NaN
596.000089	0.001817	18.170507	0.273853	1274.276245	0.000000	NaN	NaN
597.000147	0.001792	17.922923	0.274644	1275.067383	0.000000	NaN	NaN
598.000204	0.001858	18.583148	0.274907	1275.330322	0.000000	NaN	NaN
599.000261	0.001900	18.995789	0.275526	1275.949829	0.000000	NaN	NaN
600.000318	0.001784	17.840395	0.275903	1276.326416	0.000000	NaN	NaN
601.000375	0.001817	18.170507	0.276423	1276.847290	0.000000	NaN	NaN
601.999432	0.001990	19.903598	0.277038	1277.462158	0.000000	NaN	NaN
602.999490	0.001891	18.913260	0.277511	1277.935059	0.000000	NaN	NaN
603.999547	0.001759	17.592810	0.277998	1278.422974	0.000000	NaN	NaN
604.999604	0.001776	17.757867	0.278551	1278.975586	0.000000	NaN	NaN
605.999661	0.001883	18.830732	0.279068	1279.493164	0.000000	NaN	NaN
606.999718	0.001924	19.243373	0.279561	1279.985962	0.000000	NaN	NaN
607.999776	0.001850	18.500620	0.280100	1280.524658	0.000000	NaN	NaN
608.999833	0.001768	17.675339	0.280491	1280.916260	0.000000	NaN	NaN
609.999890	0.001759	17.592810	0.280572	1280.997437	0.000000	NaN	NaN
610.999947	0.001776	17.757867	0.281123	1281.548950	0.000000	NaN	NaN
612.000004	0.001825	18.253035	0.281627	1282.053101	0.000000	NaN	NaN
613.000062	0.001858	18.583148	0.282174	1282.599854	0.000000	NaN	NaN
614.000119	0.001908	19.078317	0.282785	1283.210815	0.000000	NaN	NaN
615.000176	0.001858	18.583148	0.283452	1283.878540	0.000000	NaN	NaN
616.000233	0.001900	18.995789	0.284100	1284.526245	0.000000	NaN	NaN
617.000290	0.001908	19.078317	0.284534	1284.960693	0.000000	NaN	NaN
618.000348	0.001834	18.335564	0.285023	1285.450195	0.000000	NaN	NaN
619.000405	0.001784	17.840395	0.285428	1285.854980	0.000000	NaN	NaN
619.999462	0.001759	17.592810	0.285933	1286.359619	0.000000	NaN	NaN
620.999519	0.001850	18.500620	0.286457	1286.884766	0.000000	NaN	NaN
621.999576	0.001875	18.748204	0.287102	1287.529297	0.000000	NaN	NaN
622.999634	0.001842	18.418092	0.287608	1288.035889	0.000000	NaN	NaN
623.999691	0.001834	18.335564	0.288192	1288.619995	0.000000	NaN	NaN
624.999748	0.001743	17.427754	0.288866	1289.293823	0.000000	NaN	NaN
625.999805	0.001784	17.840395	0.289365	1289.793335	0.000000	NaN	NaN
626.999862	0.001900	18.995789	0.290006	1290.434570	0.000000	NaN	NaN
627.999920	0.001842	18.418092	0.290659	1291.087646	0.000000	NaN	NaN
628.999977	0.001916	19.160845	0.291031	1291.460205	0.000000	NaN	NaN
630.000034	0.001801	18.005451	0.197736	1198.133911	0.000000	NaN	NaN
631.000091	0.001784	17.840395	0.291422	1291.850464	0.000000	NaN	NaN
632.000148	0.001817	18.170507	0.291566	1291.995483	0.000000	NaN	NaN
633.000206	0.001776	17.757867	0.292984	1293.413452	0.000000	NaN	NaN
634.000263	0.001867	18.665676	0.293551	1293.980957	0.000000	NaN	NaN
635.000320	0.001817	18.170507	0.294059	1294.489014	0.000000	NaN	NaN
636.000377	0.001867	18.665676	0.294644	1295.074463	0.000000	NaN	NaN
636.999434	0.001776	17.757867	0.295190	1295.620605	0.000000	NaN	NaN
637.999491	0.001801	18.005451	0.295756	1296.186157	0.000000	NaN	NaN
638.999549	0.001776	17.757867	0.296321	1296.751709	0.000000	NaN	NaN
639.999606	0.001693	16.932585	0.296586	1297.016479	0.000000	NaN	NaN
640.999663	0.001776	17.757867	0.297115	1297.546265	0.000000	NaN	NaN
641.999720	0.001685	16.850057	0.297770	1298.201050	0.000000	NaN	NaN
642.999778	0.001702	17.015114	0.298357	1298.788208	0.000000	NaN	NaN
643.999835	0.001685	16.850057	0.298903	1299.334839	0.000000	NaN	NaN
644.999892	0.001768	17.675339	0.299476	1299.907593	0.000000	NaN	NaN
645.999949	0.001735	17.345226	0.299938	1300.370239	0.000000	NaN	NaN
647.000006	0.001751	17.510282	0.300375	1300.807007	0.000000	NaN	NaN
648.000064	0.001792	17.922923	0.301123	1301.554932	0.000000	NaN	NaN
649.000121	0.001669	16.685001	0.301394	1301.826782	0.000000	NaN	NaN
650.000178	0.001768	17.675339	0.302082	1302.514648	0.000000	NaN	NaN
651.000235	0.001718	17.180170	0.302683	1303.115723	0.000000	NaN	NaN
652.000292	0.001735	17.345226	0.303254	1303.686890	0.000000	NaN	NaN
653.000349	0.001726	17.262698	0.303993	1304.426270	0.000000	NaN	NaN
654.000407	0.001602	16.024776	0.304315	1304.748657	0.000000	NaN	NaN
654.999464	0.001685	16.850057	0.304625	1305.058594	0.000000	NaN	NaN
655.999521	0.001768	17.675339	0.305104	1305.537476	0.000000	NaN	NaN
656.999578	0.001602	16.024776	0.306012	1306.445435	0.000000	NaN	NaN
657.999635	0.001677	16.767529	0.306535	1306.969238	0.000000	NaN	NaN
658.999693	0.001702	17.015114	0.307148	1307.582397	0.000000	NaN	NaN
659.999750	0.001669	16.685001	0.307383	1307.817627	0.000000	NaN	NaN
660.999807	0.001792	17.922923	0.308045	1308.479004	0.000000	NaN	NaN
661.999864	0.001677	16.767529	0.307906	1308.340820	0.000000	NaN	NaN
662.999922	0.001735	17.345226	0.308735	1309.169189	0.000000	NaN	NaN
663.999979	0.001677	16.767529	0.309381	1309.815674	0.000000	NaN	NaN
665.000036	0.001702	17.015114	0.309832	1310.266724	0.000000	NaN	NaN
666.000093	0.001602	16.024776	0.310809	1311.244019	0.000000	NaN	NaN
667.000150	0.001536	15.364551	0.311529	1311.964966	0.000000	NaN	NaN
668.000207	0.001619	16.189832	0.311495	1311.930786	0.000000	NaN	NaN
669.000265	0.001710	17.097642	0.312484	1312.919800	0.000000	NaN	NaN
670.000322	0.001677	16.767529	0.312998	1313.433716	0.000000	NaN	NaN
671.000379	0.001677	16.767529	0.313494	1313.929932	0.000000	NaN	NaN
671.999436	0.001710	17.097642	0.314339	1314.775635	0.000000	NaN	NaN
672.999493	0.001718	17.180170	0.314907	1315.343750	0.000000	NaN	NaN
673.999551	0.001693	16.932585	0.315933	1316.369629	0.000000	NaN	NaN
674.999608	0.001776	17.757867	0.316460	1316.896973	0.000000	NaN	NaN
675.999665	0.001627	16.272360	0.316367	1316.804077	0.000000	NaN	NaN
676.999722	0.001627	16.272360	0.316918	1317.355713	0.000000	NaN	NaN
677.999779	0.001652	16.519945	0.317905	1318.343018	0.000000	NaN	NaN
678.999837	0.001619	16.189832	0.318319	1318.756714	0.000000	NaN	NaN
679.999894	0.001627	16.272360	0.318916	1319.354004	0.000000	NaN	NaN
680.999951	0.001669	16.685001	0.320206	1320.644165	0.000000	NaN	NaN
682.000008	0.001586	15.859720	0.320690	1321.128296	0.000000	NaN	NaN
683.000065	0.001462	14.621798	0.321704	1322.143188	0.000000	NaN	NaN
684.000123	0.001528	15.282023	0.322056	1322.494751	0.000000	NaN	NaN
685.000180	0.001586	15.859720	0.323418	1323.858032	0.000000	NaN	NaN
686.000237	0.001718	17.180170	0.323333	1323.772095	0.000000	NaN	NaN
687.000294	0.001487	14.869382	0.323625	1324.064697	0.000000	NaN	NaN
688.000351	0.001487	14.869382	0.324661	1325.100708	0.000000	NaN	NaN
689.000409	0.001586	15.859720	0.325235	1325.675415	0.000000	NaN	NaN
690.003466	0.001528	15.282023	0.326564	1327.004883	0.000000	NaN	NaN
690.999523	0.001528	15.282023	0.326949	1327.390015	0.000000	NaN	NaN
691.999580	0.001462	14.621798	0.327455	1327.896240	0.000000	NaN	NaN
692.999637	0.001454	14.539270	0.328773	1329.213867	0.000000	NaN	NaN
693.999695	0.001429	14.291685	0.328687	1329.128418	0.000000	NaN	NaN
694.999752	0.001206	12.063426	0.329065	1329.506592	0.000000	NaN	NaN
695.999809	0.001462	14.621798	0.330435	1330.876953	0.000000	NaN	NaN
696.999866	0.001479	14.786854	0.331238	1331.680054	0.000000	NaN	NaN
697.999923	0.001404	14.044101	0.332538	1332.981079	0.000000	NaN	NaN
698.999981	0.001437	14.374213	0.333437	1333.879761	0.000000	NaN	NaN
700.000038	0.001297	12.971235	0.334840	1335.283691	0.000000	NaN	NaN
701.000095	0.001396	13.961573	0.335898	1336.341919	0.000000	NaN	NaN
702.000152	0.001173	11.733313	0.337235	1337.678833	0.000000	NaN	NaN
703.000209	0.001231	12.311010	0.338395	1338.839844	0.000000	NaN	NaN
704.000267	0.001206	12.063426	0.098984	1099.349243	0.000000	NaN	NaN
705.000324	0.001132	11.320673	0.341794	1342.239258	0.000000	NaN	NaN
706.000381	0.001033	10.330335	0.208169	1208.569946	0.000000	NaN	NaN
706.999438	0.001050	10.495392	0.206773	1207.173706	0.000000	NaN	NaN
707.999495	0.001050	10.495392	0.347740	1348.187866	0.000000	NaN	NaN
708.999553	0.000752	7.524379	0.350936	1351.384644	0.000000	NaN	NaN
709.999610	0.000579	5.791288	0.353170	1353.619141	0.000000	NaN	NaN