File: data/57k_1-1_1 (190315).lvm
LabVIEW Measurement
Writer_Version	2
Reader_Version	2
Separator	Tab
Decimal_Separator	.
Multi_Headings	No
X_Columns	One
Time_Pref	Absolute
Operator	user
Description	Load(N)/Stress(MPa)/Distance A(pixel)/Strain A/Distance B(pixel)/Strain B/Poisson's ratio
Date	2019/03/15
Time	14:37:29.3127093315124511719
***End_of_Header***

Notes	X 값은 오직 다음과 같을 때에만 유효함이 보장됩니다. Dev1/ai0
Channels	7
Samples	1	1	1	1	1	1	1
Date	2019/03/15	2019/03/15	2019/03/15	2019/03/15	2019/03/15	2019/03/15	2019/03/15
Time	15:36:04.3127559300349910882	15:36:04.3127559300349910882	15:36:04.3127560615539550781	15:36:04.3127560615539550781	15:36:04.3127560615539550781	15:36:04.3127560615539550781	15:36:04.3127560615539550781
Y_Unit_Label	Volts	Volts
X_Dimension	Time	Time	Time	Time	Time	Time	Time
X0	0.0000000000000000E+0	0.0000000000000000E+0	0.0000000000000000E+0	0.0000000000000000E+0	0.0000000000000000E+0	0.0000000000000000E+0	0.0000000000000000E+0
Delta_X	0.000000	0.000000	1.000000	1.000000	1.000000	1.000000	1.000000
***End_of_Header***
X_Value	Dev1/ai0	Dev1/ai0 1	Untitled	Untitled 1	Untitled 2	Untitled 3	Untitled 4	Comment
0.000000	1.793757E-5	0.179376	3.397465E-5	992.024963	0.000000	NaN	NaN
1.500086	2.619039E-5	0.261904	-1.716614E-5	991.974243	0.000000	NaN	NaN
3.000172	-2.332649E-5	-0.233265	6.318092E-6	991.997498	0.000000	NaN	NaN
4.500257	0.000142	1.417298	0.000274	992.263184	0.000000	NaN	NaN
5.999343	1.793757E-5	0.179376	0.000717	992.702637	0.000000	NaN	NaN
7.499429	2.619039E-5	0.261904	0.001154	993.135742	0.000000	NaN	NaN
8.999515	0.000224	2.242579	0.001673	993.650330	0.000000	NaN	NaN
10.499601	0.000166	1.664882	0.002259	994.232056	0.000000	NaN	NaN
11.999686	0.000199	1.994995	0.002741	994.710144	0.000000	NaN	NaN
13.499772	0.000257	2.572691	0.003208	995.173096	0.000000	NaN	NaN
14.999858	9.221289E-5	0.922129	0.003660	995.621521	0.000000	NaN	NaN
16.499944	0.000266	2.655220	0.003986	995.945007	0.000000	NaN	NaN
18.000030	0.000233	2.325107	0.004483	996.438049	0.000000	NaN	NaN
19.500115	0.000315	3.150388	0.004894	996.846069	0.000000	NaN	NaN
21.000201	0.000373	3.728085	0.005361	997.309631	0.000000	NaN	NaN
22.500287	0.000365	3.645557	0.005626	997.572144	0.000000	NaN	NaN
23.999373	0.000472	4.718423	0.006000	997.943054	0.000000	NaN	NaN
25.499458	0.000488	4.883479	0.006354	998.293945	0.000000	NaN	NaN
26.999544	0.000431	4.305782	0.006586	998.524475	0.000000	NaN	NaN
28.499630	0.000513	5.131063	0.006889	998.825195	0.000000	NaN	NaN
29.999716	0.000447	4.470838	0.007226	999.159302	0.000000	NaN	NaN
31.499802	0.000513	5.131063	0.007611	999.541565	0.000000	NaN	NaN
32.999887	0.000604	6.038873	0.007844	999.772400	0.000000	NaN	NaN
34.499973	0.000587	5.873817	0.008173	1000.098816	0.000000	NaN	NaN
36.000059	0.000571	5.708760	0.008592	1000.514587	0.000000	NaN	NaN
37.500145	0.000604	6.038873	0.008912	1000.832092	0.000000	NaN	NaN
39.000231	0.000719	7.194267	0.009250	1001.166809	0.000000	NaN	NaN
40.499316	0.000719	7.194267	0.009672	1001.586243	0.000000	NaN	NaN
41.999402	0.000901	9.009885	0.010062	1001.972168	0.000000	NaN	NaN
43.499488	0.000695	6.946682	0.010469	1002.376282	0.000000	NaN	NaN
44.999574	0.000794	7.937020	0.010940	1002.843323	0.000000	NaN	NaN
46.499660	0.000686	6.864154	0.011311	1003.211548	0.000000	NaN	NaN
47.999745	0.000893	8.927357	0.011814	1003.710632	0.000000	NaN	NaN
49.499831	0.000893	8.927357	0.012199	1004.092896	0.000000	NaN	NaN
50.999917	0.000827	8.267132	0.012603	1004.493042	0.000000	NaN	NaN
52.500003	0.000901	9.009885	0.013093	1004.979248	0.000000	NaN	NaN
54.000089	0.000893	8.927357	0.013537	1005.420288	0.000000	NaN	NaN
55.500174	0.000893	8.927357	0.013892	1005.771606	0.000000	NaN	NaN
57.000260	0.000967	9.670110	0.014578	1006.452515	0.000000	NaN	NaN
58.499346	0.000843	8.432188	0.015007	1006.877686	0.000000	NaN	NaN
59.999432	0.000909	9.092413	0.015488	1007.355286	0.000000	NaN	NaN
61.499518	0.000984	9.835167	0.015906	1007.769897	0.000000	NaN	NaN
62.999603	0.000893	8.927357	0.016502	1008.361023	0.000000	NaN	NaN
64.499689	0.001033	10.330335	0.017106	1008.960327	0.000000	NaN	NaN
65.999775	0.000975	9.752638	0.017375	1009.227051	0.000000	NaN	NaN
67.499861	0.001066	10.660448	0.017962	1009.809021	0.000000	NaN	NaN
68.999947	0.001124	11.238145	0.018600	1010.442627	0.000000	NaN	NaN
70.500032	0.001083	10.825504	0.019041	1010.879822	0.000000	NaN	NaN
72.000118	0.001083	10.825504	0.019768	1011.601074	0.000000	NaN	NaN
73.500204	0.001099	10.990560	0.020344	1012.172729	0.000000	NaN	NaN
75.000290	0.001025	10.247807	0.020892	1012.716309	0.000000	NaN	NaN
76.499375	0.001149	11.485729	0.021339	1013.159668	0.000000	NaN	NaN
77.999461	0.001157	11.568257	0.021527	1013.346130	0.000000	NaN	NaN
79.499547	0.001256	12.558595	0.021784	1013.600769	0.000000	NaN	NaN
80.999633	0.001140	11.403201	0.022506	1014.317444	0.000000	NaN	NaN
82.499719	0.001083	10.825504	0.023152	1014.958191	0.000000	NaN	NaN
83.999804	0.001099	10.990560	0.023774	1015.574646	0.000000	NaN	NaN
85.499890	0.001322	13.218820	0.024410	1016.206055	0.000000	NaN	NaN
86.999976	0.001157	11.568257	0.025179	1016.968750	0.000000	NaN	NaN
88.500062	0.001206	12.063426	0.025871	1017.655518	0.000000	NaN	NaN
90.000148	0.001165	11.650785	0.026582	1018.360657	0.000000	NaN	NaN
91.500233	0.001091	10.908032	0.027329	1019.101501	0.000000	NaN	NaN
92.999319	0.001173	11.733313	0.028005	1019.771729	0.000000	NaN	NaN
94.499405	0.001338	13.383876	0.028770	1020.530640	0.000000	NaN	NaN
95.999491	0.001314	13.136292	0.029438	1021.193054	0.000000	NaN	NaN
97.499577	0.001305	13.053763	0.030053	1021.803772	0.000000	NaN	NaN
98.999662	0.001264	12.641123	0.030905	1022.648560	0.000000	NaN	NaN
100.499748	0.001239	12.393538	0.031489	1023.228333	0.000000	NaN	NaN
101.999834	0.001338	13.383876	0.032267	1023.999817	0.000000	NaN	NaN
103.499920	0.001223	12.228482	0.033093	1024.818848	0.000000	NaN	NaN
105.000006	0.001157	11.568257	0.033821	1025.540894	0.000000	NaN	NaN
106.500091	0.001248	12.476067	0.034594	1026.308228	0.000000	NaN	NaN
108.000177	0.001173	11.733313	0.035475	1027.181763	0.000000	NaN	NaN
109.500263	0.001223	12.228482	0.036121	1027.822876	0.000000	NaN	NaN
110.999349	0.001380	13.796517	0.036846	1028.541992	0.000000	NaN	NaN
112.499435	0.001305	13.053763	0.037705	1029.394287	0.000000	NaN	NaN
113.999520	0.001421	14.209157	0.038427	1030.110474	0.000000	NaN	NaN
115.499606	0.001297	12.971235	0.039331	1031.007324	0.000000	NaN	NaN
116.999692	0.001281	12.806179	0.039861	1031.533081	0.000000	NaN	NaN
118.499778	0.001363	13.631460	0.040790	1032.454834	0.000000	NaN	NaN
119.999864	0.001231	12.311010	0.041551	1033.209961	0.000000	NaN	NaN
121.499949	0.001289	12.888707	0.042413	1034.064331	0.000000	NaN	NaN
123.000035	0.001239	12.393538	0.043323	1034.967407	0.000000	NaN	NaN
124.500121	0.001429	14.291685	0.044116	1035.753662	0.000000	NaN	NaN
126.000207	0.001347	13.466404	0.044775	1036.407471	0.000000	NaN	NaN
127.499293	0.001396	13.961573	0.045635	1037.261230	0.000000	NaN	NaN
128.999378	0.001314	13.136292	0.046229	1037.849731	0.000000	NaN	NaN
130.499464	0.001429	14.291685	0.047180	1038.793823	0.000000	NaN	NaN
131.999550	0.001413	14.126629	0.048106	1039.711670	0.000000	NaN	NaN
133.499636	0.001454	14.539270	0.048767	1040.367676	0.000000	NaN	NaN
134.999722	0.001256	12.558595	0.049525	1041.119995	0.000000	NaN	NaN
136.499807	0.001380	13.796517	0.050415	1042.002563	0.000000	NaN	NaN
137.999893	0.001355	13.548932	0.051213	1042.793823	0.000000	NaN	NaN
139.499979	0.001363	13.631460	0.051971	1043.545776	0.000000	NaN	NaN
141.000065	0.001446	14.456742	0.052820	1044.387817	0.000000	NaN	NaN
142.500151	0.001363	13.631460	0.053475	1045.038452	0.000000	NaN	NaN
144.000236	0.001371	13.713988	0.054269	1045.826050	0.000000	NaN	NaN
145.499322	0.001264	12.641123	0.055048	1046.598877	0.000000	NaN	NaN
146.999408	0.001569	15.694663	0.055871	1047.415283	0.000000	NaN	NaN
148.499494	0.001371	13.713988	0.056657	1048.194092	0.000000	NaN	NaN
149.999580	0.001314	13.136292	0.057453	1048.983887	0.000000	NaN	NaN
151.499665	0.001396	13.961573	0.058088	1049.614014	0.000000	NaN	NaN
152.999751	0.001347	13.466404	0.058874	1050.393799	0.000000	NaN	NaN
154.499837	0.001404	14.044101	0.059626	1051.139771	0.000000	NaN	NaN
155.999923	0.001338	13.383876	0.060360	1051.867920	0.000000	NaN	NaN
157.500008	0.001512	15.116967	0.061224	1052.725342	0.000000	NaN	NaN
159.000094	0.001396	13.961573	0.061968	1053.462891	0.000000	NaN	NaN
160.500180	0.001396	13.961573	0.062746	1054.234985	0.000000	NaN	NaN
162.000266	0.001429	14.291685	0.063473	1054.955566	0.000000	NaN	NaN
163.499352	0.001421	14.209157	0.064287	1055.763306	0.000000	NaN	NaN
164.999437	0.001413	14.126629	0.065108	1056.577393	0.000000	NaN	NaN
166.499523	0.001338	13.383876	0.065858	1057.321411	0.000000	NaN	NaN
167.999609	0.001437	14.374213	0.066612	1058.069946	0.000000	NaN	NaN
169.499695	0.001503	15.034438	0.067367	1058.819092	0.000000	NaN	NaN
170.999781	0.001388	13.879045	0.068084	1059.529663	0.000000	NaN	NaN
172.499866	0.001413	14.126629	0.068882	1060.321289	0.000000	NaN	NaN
173.999952	0.001396	13.961573	0.069628	1061.061768	0.000000	NaN	NaN
175.500038	0.001338	13.383876	0.070407	1061.834351	0.000000	NaN	NaN
177.000124	0.001338	13.383876	0.071131	1062.552979	0.000000	NaN	NaN
178.500210	0.001487	14.869382	0.072020	1063.434570	0.000000	NaN	NaN
179.999295	0.001421	14.209157	0.072870	1064.277588	0.000000	NaN	NaN
181.499381	0.001454	14.539270	0.073597	1064.999023	0.000000	NaN	NaN
182.999467	0.001380	13.796517	0.074362	1065.758057	0.000000	NaN	NaN
184.499553	0.001388	13.879045	0.075115	1066.504517	0.000000	NaN	NaN
185.999639	0.001429	14.291685	0.075829	1067.212524	0.000000	NaN	NaN
187.499724	0.001487	14.869382	0.076536	1067.914062	0.000000	NaN	NaN
188.999810	0.001388	13.879045	0.077289	1068.661743	0.000000	NaN	NaN
190.499896	0.001413	14.126629	0.078113	1069.478516	0.000000	NaN	NaN
191.999982	0.001371	13.713988	0.078864	1070.223145	0.000000	NaN	NaN
193.500068	0.001396	13.961573	0.079753	1071.105957	0.000000	NaN	NaN
195.000153	0.001520	15.199495	0.080381	1071.728516	0.000000	NaN	NaN
196.500239	0.001421	14.209157	0.081242	1072.582397	0.000000	NaN	NaN
197.999325	0.001264	12.641123	0.082004	1073.338867	0.000000	NaN	NaN
199.499411	0.001421	14.209157	0.082546	1073.875854	0.000000	NaN	NaN
200.999496	0.001503	15.034438	0.083451	1074.774048	0.000000	NaN	NaN
202.499582	0.001462	14.621798	0.084201	1075.517578	0.000000	NaN	NaN
203.999668	0.001462	14.621798	0.085021	1076.331299	0.000000	NaN	NaN
205.499754	0.001545	15.447079	0.085827	1077.130371	0.000000	NaN	NaN
206.999840	0.001479	14.786854	0.086605	1077.902710	0.000000	NaN	NaN
208.499925	0.001536	15.364551	0.087462	1078.752808	0.000000	NaN	NaN
210.000011	0.001495	14.951910	0.088313	1079.596558	0.000000	NaN	NaN
211.500097	0.001677	16.767529	0.088967	1080.245361	0.000000	NaN	NaN
213.000183	0.001586	15.859720	0.089714	1080.986694	0.000000	NaN	NaN
214.500269	0.001421	14.209157	0.090367	1081.634644	0.000000	NaN	NaN
215.999355	0.001479	14.786854	0.091241	1082.501221	0.000000	NaN	NaN
217.499440	0.001396	13.961573	0.092030	1083.284546	0.000000	NaN	NaN
218.999526	0.001421	14.209157	0.092811	1084.059204	0.000000	NaN	NaN
220.499612	0.001437	14.374213	0.093602	1084.843628	0.000000	NaN	NaN
221.999698	0.001479	14.786854	0.094351	1085.586914	0.000000	NaN	NaN
223.499783	0.001578	15.777192	0.095207	1086.436157	0.000000	NaN	NaN
224.999869	0.001437	14.374213	0.095971	1087.193726	0.000000	NaN	NaN
226.499955	0.001569	15.694663	0.096663	1087.880127	0.000000	NaN	NaN
228.000041	0.001495	14.951910	0.097397	1088.608398	0.000000	NaN	NaN
229.500127	0.001503	15.034438	0.098170	1089.375366	0.000000	NaN	NaN
231.000213	0.001528	15.282023	0.098864	1090.063599	0.000000	NaN	NaN
232.499298	0.001569	15.694663	0.099633	1090.826538	0.000000	NaN	NaN
233.999384	0.001487	14.869382	0.100451	1091.637573	0.000000	NaN	NaN
235.499470	0.001627	16.272360	0.101298	1092.478394	0.000000	NaN	NaN
236.999556	0.001520	15.199495	0.101896	1093.071533	0.000000	NaN	NaN
238.499641	0.001437	14.374213	0.102770	1093.938232	0.000000	NaN	NaN
239.999727	0.001512	15.116967	0.103498	1094.660400	0.000000	NaN	NaN
241.499813	0.001479	14.786854	0.104171	1095.327881	0.000000	NaN	NaN
242.999899	0.001528	15.282023	0.105028	1096.178345	0.000000	NaN	NaN
244.499985	0.001437	14.374213	0.105599	1096.744385	0.000000	NaN	NaN
246.000070	0.001371	13.713988	0.106486	1097.624146	0.000000	NaN	NaN
247.500156	0.001503	15.034438	0.107280	1098.412476	0.000000	NaN	NaN
249.000242	0.001553	15.529607	0.108030	1099.156128	0.000000	NaN	NaN
250.499328	0.001536	15.364551	0.108834	1099.953735	0.000000	NaN	NaN
251.999414	0.001561	15.612135	0.109629	1100.742065	0.000000	NaN	NaN
253.499499	0.001528	15.282023	0.110417	1101.524292	0.000000	NaN	NaN
254.999585	0.001479	14.786854	0.111045	1102.146851	0.000000	NaN	NaN
256.499671	0.001677	16.767529	0.111784	1102.879639	0.000000	NaN	NaN
257.999757	0.001611	16.107304	0.112460	1103.550903	0.000000	NaN	NaN
259.499843	0.001520	15.199495	0.113331	1104.414429	0.000000	NaN	NaN
260.999928	0.001454	14.539270	0.114080	1105.157837	0.000000	NaN	NaN
262.500014	0.001578	15.777192	0.114805	1105.876709	0.000000	NaN	NaN
264.000100	0.001545	15.447079	0.115612	1106.677490	0.000000	NaN	NaN
265.500186	0.001520	15.199495	0.116452	1107.510498	0.000000	NaN	NaN
267.000272	0.001371	13.713988	0.117213	1108.265625	0.000000	NaN	NaN
268.499357	0.001586	15.859720	0.117895	1108.942505	0.000000	NaN	NaN
269.999443	0.001627	16.272360	0.118637	1109.677856	0.000000	NaN	NaN
271.499529	0.001619	16.189832	0.119468	1110.502563	0.000000	NaN	NaN
272.999615	0.001578	15.777192	0.120103	1111.132324	0.000000	NaN	NaN
274.499700	0.001669	16.685001	0.120905	1111.927612	0.000000	NaN	NaN
275.999786	0.001553	15.529607	0.121638	1112.654663	0.000000	NaN	NaN
277.499872	0.001652	16.519945	0.122415	1113.426025	0.000000	NaN	NaN
278.999958	0.001479	14.786854	0.123176	1114.180542	0.000000	NaN	NaN
280.500044	0.001611	16.107304	0.123945	1114.943481	0.000000	NaN	NaN
282.000130	0.001735	17.345226	0.124576	1115.569702	0.000000	NaN	NaN
283.500215	0.001545	15.447079	0.125375	1116.361816	0.000000	NaN	NaN
284.999301	0.001611	16.107304	0.125960	1116.942261	0.000000	NaN	NaN
286.499387	0.001652	16.519945	0.126811	1117.786743	0.000000	NaN	NaN
287.999473	0.001635	16.354889	0.127559	1118.528442	0.000000	NaN	NaN
289.499558	0.001553	15.529607	0.128316	1119.279175	0.000000	NaN	NaN
290.999644	0.001611	16.107304	0.129208	1120.164917	0.000000	NaN	NaN
292.499730	0.001536	15.364551	0.129979	1120.929565	0.000000	NaN	NaN
293.999816	0.001569	15.694663	0.130858	1121.801270	0.000000	NaN	NaN
295.499902	0.001619	16.189832	0.131321	1122.260498	0.000000	NaN	NaN
296.999987	0.001660	16.602473	0.132092	1123.024902	0.000000	NaN	NaN
298.500073	0.001561	15.612135	0.132890	1123.816650	0.000000	NaN	NaN
300.000159	0.001602	16.024776	0.133472	1124.394409	0.000000	NaN	NaN
301.500245	0.001652	16.519945	0.134292	1125.208252	0.000000	NaN	NaN
302.999331	0.001495	14.951910	0.135060	1125.969971	0.000000	NaN	NaN
304.499416	0.001553	15.529607	0.135821	1126.724976	0.000000	NaN	NaN
305.999502	0.001751	17.510282	0.136561	1127.458984	0.000000	NaN	NaN
307.499588	0.001611	16.107304	0.137216	1128.107910	0.000000	NaN	NaN
308.999674	0.001677	16.767529	0.138039	1128.924927	0.000000	NaN	NaN
310.499760	0.001602	16.024776	0.138867	1129.745728	0.000000	NaN	NaN
311.999845	0.001545	15.447079	0.139780	1130.652222	0.000000	NaN	NaN
313.499931	0.001635	16.354889	0.140306	1131.173584	0.000000	NaN	NaN
315.000017	0.001644	16.437417	0.141141	1132.001587	0.000000	NaN	NaN
316.500103	0.001669	16.685001	0.141694	1132.550415	0.000000	NaN	NaN
318.000189	0.001685	16.850057	0.143539	1134.380981	0.000000	NaN	NaN
319.500274	0.001660	16.602473	0.144331	1135.166626	0.000000	NaN	NaN
320.999360	0.001520	15.199495	0.145000	1135.829590	0.000000	NaN	NaN
322.499446	0.001759	17.592810	0.145635	1136.459595	0.000000	NaN	NaN
323.999532	0.001759	17.592810	0.145512	1136.338013	0.000000	NaN	NaN
325.499617	0.001693	16.932585	0.146290	1137.109741	0.000000	NaN	NaN
326.999703	0.001743	17.427754	0.147054	1137.867432	0.000000	NaN	NaN
328.499789	0.001693	16.932585	0.147788	1138.595215	0.000000	NaN	NaN
329.999875	0.001702	17.015114	0.148584	1139.385742	0.000000	NaN	NaN
331.499961	0.001602	16.024776	0.149310	1140.105957	0.000000	NaN	NaN
333.000046	0.001759	17.592810	0.150057	1140.846680	0.000000	NaN	NaN
334.500132	0.001685	16.850057	0.150827	1141.610107	0.000000	NaN	NaN
336.000218	0.001743	17.427754	0.151597	1142.374146	0.000000	NaN	NaN
337.499304	0.001627	16.272360	0.152308	1143.079590	0.000000	NaN	NaN
338.999390	0.001594	15.942248	0.153027	1143.792847	0.000000	NaN	NaN
340.499475	0.001652	16.519945	0.153758	1144.518188	0.000000	NaN	NaN
341.999561	0.001586	15.859720	0.154558	1145.311890	0.000000	NaN	NaN
343.499647	0.001685	16.850057	0.155274	1146.021484	0.000000	NaN	NaN
344.999733	0.001602	16.024776	0.156011	1146.753052	0.000000	NaN	NaN
346.499819	0.001652	16.519945	0.156692	1147.428223	0.000000	NaN	NaN
347.999905	0.001693	16.932585	0.157465	1148.195312	0.000000	NaN	NaN
349.499990	0.001660	16.602473	0.158213	1148.936890	0.000000	NaN	NaN
351.000076	0.001602	16.024776	0.158947	1149.665405	0.000000	NaN	NaN
352.500162	0.001586	15.859720	0.159740	1150.451660	0.000000	NaN	NaN
354.000248	0.001627	16.272360	0.160484	1151.190308	0.000000	NaN	NaN
355.499333	0.001611	16.107304	0.161259	1151.958984	0.000000	NaN	NaN
356.999419	0.001685	16.850057	0.161968	1152.661743	0.000000	NaN	NaN
358.499505	0.001726	17.262698	0.162711	1153.399048	0.000000	NaN	NaN
359.999591	0.001594	15.942248	0.163455	1154.137451	0.000000	NaN	NaN
361.499677	0.001726	17.262698	0.164138	1154.814819	0.000000	NaN	NaN
362.999762	0.001693	16.932585	0.164861	1155.531860	0.000000	NaN	NaN
364.499848	0.001685	16.850057	0.165704	1156.368652	0.000000	NaN	NaN
365.999934	0.001627	16.272360	0.166391	1157.049438	0.000000	NaN	NaN
367.500020	0.001669	16.685001	0.167156	1157.808472	0.000000	NaN	NaN
369.000106	0.001685	16.850057	0.167856	1158.503174	0.000000	NaN	NaN
370.500191	0.001735	17.345226	0.168681	1159.321411	0.000000	NaN	NaN
372.000277	0.001726	17.262698	0.169326	1159.961426	0.000000	NaN	NaN
373.499363	0.001718	17.180170	0.170068	1160.697266	0.000000	NaN	NaN
374.999449	0.001669	16.685001	0.170824	1161.447021	0.000000	NaN	NaN
376.499535	0.001809	18.087979	0.171597	1162.214111	0.000000	NaN	NaN
377.999620	0.001594	15.942248	0.172337	1162.947998	0.000000	NaN	NaN
379.499706	0.001652	16.519945	0.173085	1163.690186	0.000000	NaN	NaN
380.999792	0.001792	17.922923	0.173738	1164.338013	0.000000	NaN	NaN
382.499878	0.001776	17.757867	0.174489	1165.082642	0.000000	NaN	NaN
383.999964	0.001718	17.180170	0.175194	1165.781982	0.000000	NaN	NaN
385.500049	0.001710	17.097642	0.175918	1166.499878	0.000000	NaN	NaN
387.000135	0.001735	17.345226	0.176692	1167.268555	0.000000	NaN	NaN
388.500221	0.001718	17.180170	0.177403	1167.973267	0.000000	NaN	NaN
389.999307	0.001718	17.180170	0.178085	1168.649902	0.000000	NaN	NaN
391.499392	0.001792	17.922923	0.178753	1169.312500	0.000000	NaN	NaN
392.999478	0.001627	16.272360	0.179538	1170.091064	0.000000	NaN	NaN
394.499564	0.001974	19.738542	0.180276	1170.823120	0.000000	NaN	NaN
395.999650	0.001569	15.694663	0.181001	1171.542358	0.000000	NaN	NaN
397.499736	0.001669	16.685001	0.181733	1172.268677	0.000000	NaN	NaN
398.999821	0.001726	17.262698	0.182418	1172.947998	0.000000	NaN	NaN
400.499907	0.001776	17.757867	0.183149	1173.673584	0.000000	NaN	NaN
401.999993	0.001677	16.767529	0.183920	1174.438477	0.000000	NaN	NaN
403.500079	0.001660	16.602473	0.184630	1175.142578	0.000000	NaN	NaN
405.000165	0.001718	17.180170	0.185419	1175.925293	0.000000	NaN	NaN
406.500250	0.001776	17.757867	0.186104	1176.605225	0.000000	NaN	NaN
407.999336	0.001784	17.840395	0.186931	1177.424927	0.000000	NaN	NaN
409.499422	0.001751	17.510282	0.187638	1178.126953	0.000000	NaN	NaN
410.999508	0.001842	18.418092	0.188353	1178.836060	0.000000	NaN	NaN
412.499594	0.001784	17.840395	0.189124	1179.601074	0.000000	NaN	NaN
413.999679	0.001759	17.592810	0.189855	1180.326172	0.000000	NaN	NaN
415.499765	0.001801	18.005451	0.190494	1180.959839	0.000000	NaN	NaN
416.999851	0.001743	17.427754	0.191200	1181.659546	0.000000	NaN	NaN
418.499937	0.001784	17.840395	0.192012	1182.465088	0.000000	NaN	NaN
420.000023	0.001693	16.932585	0.192776	1183.223389	0.000000	NaN	NaN
421.500108	0.001784	17.840395	0.193442	1183.883545	0.000000	NaN	NaN
423.000194	0.001726	17.262698	0.194149	1184.585083	0.000000	NaN	NaN
424.500280	0.001627	16.272360	0.194866	1185.296265	0.000000	NaN	NaN
425.999366	0.001768	17.675339	0.195532	1185.957153	0.000000	NaN	NaN
427.499452	0.001685	16.850057	0.196347	1186.765381	0.000000	NaN	NaN
428.999537	0.001825	18.253035	0.197096	1187.508911	0.000000	NaN	NaN
430.499623	0.001635	16.354889	0.197808	1188.215454	0.000000	NaN	NaN
431.999709	0.001776	17.757867	0.198519	1188.919922	0.000000	NaN	NaN
433.499795	0.001710	17.097642	0.199229	1189.625000	0.000000	NaN	NaN
434.999881	0.001660	16.602473	0.199973	1190.362671	0.000000	NaN	NaN
436.499966	0.001784	17.840395	0.200725	1191.108887	0.000000	NaN	NaN
438.000052	0.001759	17.592810	0.201465	1191.843018	0.000000	NaN	NaN
439.500138	0.001784	17.840395	0.202210	1192.581421	0.000000	NaN	NaN
441.000224	0.001792	17.922923	0.202871	1193.237183	0.000000	NaN	NaN
442.499309	0.001768	17.675339	0.203602	1193.962891	0.000000	NaN	NaN
443.999395	0.001743	17.427754	0.204282	1194.636963	0.000000	NaN	NaN
445.499481	0.001677	16.767529	0.205110	1195.458984	0.000000	NaN	NaN
446.999567	0.001685	16.850057	0.205813	1196.156372	0.000000	NaN	NaN
448.499653	0.001635	16.354889	0.206413	1196.750732	0.000000	NaN	NaN
449.999738	0.001751	17.510282	0.207214	1197.545288	0.000000	NaN	NaN
451.499824	0.001776	17.757867	0.207965	1198.291138	0.000000	NaN	NaN
452.999910	0.001743	17.427754	0.208616	1198.936523	0.000000	NaN	NaN
454.499996	0.001685	16.850057	0.209359	1199.673706	0.000000	NaN	NaN
456.000082	0.001677	16.767529	0.210083	1200.391846	0.000000	NaN	NaN
457.500167	0.001784	17.840395	0.210794	1201.097046	0.000000	NaN	NaN
459.000253	0.001693	16.932585	0.211535	1201.832275	0.000000	NaN	NaN
460.499339	0.001759	17.592810	0.212257	1202.547974	0.000000	NaN	NaN
461.999425	0.001792	17.922923	0.212979	1203.264648	0.000000	NaN	NaN
463.499511	0.001710	17.097642	0.213696	1203.975830	0.000000	NaN	NaN
464.999596	0.001702	17.015114	0.214380	1204.653931	0.000000	NaN	NaN
466.499682	0.001759	17.592810	0.215119	1205.386963	0.000000	NaN	NaN
467.999768	0.001726	17.262698	0.215834	1206.096680	0.000000	NaN	NaN
469.499854	0.001635	16.354889	0.216509	1206.766724	0.000000	NaN	NaN
470.999940	0.001825	18.253035	0.217259	1207.509888	0.000000	NaN	NaN
472.500025	0.001784	17.840395	0.217981	1208.226318	0.000000	NaN	NaN
474.000111	0.001768	17.675339	0.218630	1208.869873	0.000000	NaN	NaN
475.500197	0.001751	17.510282	0.219334	1209.569214	0.000000	NaN	NaN
477.000283	0.001751	17.510282	0.220137	1210.365723	0.000000	NaN	NaN
478.499369	0.001883	18.830732	0.220865	1211.087402	0.000000	NaN	NaN
479.999454	0.001875	18.748204	0.221505	1211.722534	0.000000	NaN	NaN
481.499540	0.001635	16.354889	0.222269	1212.480225	0.000000	NaN	NaN
482.999626	0.001784	17.840395	0.222973	1213.178101	0.000000	NaN	NaN
484.499712	0.001933	19.325901	0.223717	1213.916992	0.000000	NaN	NaN
485.999798	0.001801	18.005451	0.224353	1214.547363	0.000000	NaN	NaN
487.499883	0.001751	17.510282	0.225079	1215.267334	0.000000	NaN	NaN
488.999969	0.001891	18.913260	0.225828	1216.010620	0.000000	NaN	NaN
490.500055	0.001850	18.500620	0.226550	1216.726929	0.000000	NaN	NaN
492.000141	0.001768	17.675339	0.227182	1217.353394	0.000000	NaN	NaN
493.500227	0.001817	18.170507	0.227852	1218.018311	0.000000	NaN	NaN
494.999312	0.001768	17.675339	0.228610	1218.770142	0.000000	NaN	NaN
496.499398	0.001850	18.500620	0.229312	1219.466797	0.000000	NaN	NaN
497.999484	0.001801	18.005451	0.229969	1220.118286	0.000000	NaN	NaN
499.499570	0.001768	17.675339	0.230682	1220.825562	0.000000	NaN	NaN
500.999656	0.001619	16.189832	0.231407	1221.545410	0.000000	NaN	NaN
502.499741	0.001776	17.757867	0.232154	1222.286011	0.000000	NaN	NaN
503.999827	0.001735	17.345226	0.232807	1222.933472	0.000000	NaN	NaN
505.499913	0.001718	17.180170	0.233581	1223.701416	0.000000	NaN	NaN
506.999999	0.001743	17.427754	0.234292	1224.406494	0.000000	NaN	NaN
508.500085	0.001809	18.087979	0.234954	1225.063110	0.000000	NaN	NaN
510.000170	0.001867	18.665676	0.235630	1225.734497	0.000000	NaN	NaN
511.500256	0.001834	18.335564	0.236398	1226.496094	0.000000	NaN	NaN
512.999342	0.001809	18.087979	0.237096	1227.188721	0.000000	NaN	NaN
514.499428	0.001726	17.262698	0.237887	1227.973022	0.000000	NaN	NaN
515.999514	0.001726	17.262698	0.238466	1228.547363	0.000000	NaN	NaN
517.499599	0.001768	17.675339	0.239148	1229.224487	0.000000	NaN	NaN
518.999685	0.001858	18.583148	0.239878	1229.948120	0.000000	NaN	NaN
520.499771	0.001710	17.097642	0.240539	1230.603882	0.000000	NaN	NaN
521.999857	0.001858	18.583148	0.241330	1231.388672	0.000000	NaN	NaN
523.499942	0.001842	18.418092	0.242065	1232.117310	0.000000	NaN	NaN
525.000028	0.001858	18.583148	0.242776	1232.823120	0.000000	NaN	NaN
526.500114	0.001801	18.005451	0.243329	1233.371094	0.000000	NaN	NaN
528.000200	0.001759	17.592810	0.244084	1234.120239	0.000000	NaN	NaN
529.500286	0.001858	18.583148	0.244807	1234.838013	0.000000	NaN	NaN
530.999371	0.001817	18.170507	0.245533	1235.558105	0.000000	NaN	NaN
532.499457	0.001759	17.592810	0.246131	1236.151123	0.000000	NaN	NaN
533.999543	0.001792	17.922923	0.246826	1236.840820	0.000000	NaN	NaN
535.499629	0.001677	16.767529	0.247510	1237.519165	0.000000	NaN	NaN
536.999715	0.001834	18.335564	0.248222	1238.225830	0.000000	NaN	NaN
538.499800	0.001817	18.170507	0.248882	1238.880371	0.000000	NaN	NaN
539.999886	0.001850	18.500620	0.249570	1239.562500	0.000000	NaN	NaN
541.499972	0.001825	18.253035	0.250240	1240.227661	0.000000	NaN	NaN
543.000058	0.001867	18.665676	0.250892	1240.874268	0.000000	NaN	NaN
544.500144	0.001759	17.592810	0.251566	1241.542603	0.000000	NaN	NaN
546.000229	0.001784	17.840395	0.252181	1242.152588	0.000000	NaN	NaN
547.499315	0.001933	19.325901	0.252880	1242.846191	0.000000	NaN	NaN
548.999401	0.001891	18.913260	0.253547	1243.507812	0.000000	NaN	NaN
550.499487	0.001759	17.592810	0.254213	1244.168701	0.000000	NaN	NaN
551.999573	0.001776	17.757867	0.254928	1244.877319	0.000000	NaN	NaN
553.499658	0.001743	17.427754	0.255596	1245.540283	0.000000	NaN	NaN
554.999744	0.001924	19.243373	0.256175	1246.114502	0.000000	NaN	NaN
556.499830	0.001726	17.262698	0.256889	1246.822754	0.000000	NaN	NaN
557.999916	0.001784	17.840395	0.257603	1247.530762	0.000000	NaN	NaN
559.500002	0.001834	18.335564	0.258286	1248.208252	0.000000	NaN	NaN
561.000087	0.001776	17.757867	0.258865	1248.782715	0.000000	NaN	NaN
562.500173	0.001768	17.675339	0.259546	1249.458618	0.000000	NaN	NaN
564.000259	0.001842	18.418092	0.260287	1250.194092	0.000000	NaN	NaN
565.499345	0.001718	17.180170	0.260957	1250.858643	0.000000	NaN	NaN
566.999431	0.001768	17.675339	0.261356	1251.253662	0.000000	NaN	NaN
568.499516	0.001809	18.087979	0.261498	1251.394897	0.000000	NaN	NaN
569.999602	0.001776	17.757867	0.262197	1252.088867	0.000000	NaN	NaN
571.499688	0.001735	17.345226	0.262899	1252.785034	0.000000	NaN	NaN
572.999774	0.001834	18.335564	0.263534	1253.414795	0.000000	NaN	NaN
574.499859	0.001792	17.922923	0.264189	1254.064453	0.000000	NaN	NaN
575.999945	0.001900	18.995789	0.264800	1254.670776	0.000000	NaN	NaN
577.500031	0.001751	17.510282	0.265454	1255.319702	0.000000	NaN	NaN
579.000117	0.001842	18.418092	0.266142	1256.001343	0.000000	NaN	NaN
580.500203	0.001817	18.170507	0.267770	1257.617065	0.000000	NaN	NaN
582.000289	0.001784	17.840395	0.268507	1258.347534	0.000000	NaN	NaN
583.499374	0.001941	19.408429	0.269083	1258.918823	0.000000	NaN	NaN
584.999460	0.001809	18.087979	0.269711	1259.541870	0.000000	NaN	NaN
586.499546	0.001825	18.253035	0.270344	1260.170288	0.000000	NaN	NaN
587.999632	0.001875	18.748204	0.270936	1260.757690	0.000000	NaN	NaN
589.499717	0.001834	18.335564	0.271634	1261.450073	0.000000	NaN	NaN
590.999803	0.001900	18.995789	0.272246	1262.056885	0.000000	NaN	NaN
592.499889	0.001867	18.665676	0.272887	1262.692261	0.000000	NaN	NaN
593.999975	0.001842	18.418092	0.273578	1263.378540	0.000000	NaN	NaN
595.500061	0.001801	18.005451	0.274158	1263.953979	0.000000	NaN	NaN
597.000147	0.001842	18.418092	0.274857	1264.647461	0.000000	NaN	NaN
598.500232	0.001776	17.757867	0.275479	1265.264526	0.000000	NaN	NaN
600.000318	0.001718	17.180170	0.276150	1265.929687	0.000000	NaN	NaN
601.499404	0.001801	18.005451	0.276643	1266.418335	0.000000	NaN	NaN
602.999490	0.001817	18.170507	0.277333	1267.103027	0.000000	NaN	NaN
604.499575	0.001858	18.583148	0.277902	1267.668091	0.000000	NaN	NaN
605.999661	0.001867	18.665676	0.278476	1268.236694	0.000000	NaN	NaN
607.499747	0.001801	18.005451	0.279105	1268.861328	0.000000	NaN	NaN
608.999833	0.001743	17.427754	0.279702	1269.452759	0.000000	NaN	NaN
610.499919	0.001900	18.995789	0.280254	1270.001099	0.000000	NaN	NaN
612.000004	0.001751	17.510282	0.280789	1270.531128	0.000000	NaN	NaN
613.500090	0.001867	18.665676	0.281268	1271.007202	0.000000	NaN	NaN
615.000176	0.001875	18.748204	0.281930	1271.663452	0.000000	NaN	NaN
616.500262	0.001834	18.335564	0.282486	1272.214600	0.000000	NaN	NaN
617.999348	0.001850	18.500620	0.283086	1272.810303	0.000000	NaN	NaN
619.499433	0.001817	18.170507	0.283625	1273.344971	0.000000	NaN	NaN
620.999519	0.001842	18.418092	0.284094	1273.809692	0.000000	NaN	NaN
622.499605	0.001875	18.748204	0.284719	1274.430542	0.000000	NaN	NaN
623.999691	0.001792	17.922923	0.285290	1274.996826	0.000000	NaN	NaN
625.499777	0.001792	17.922923	0.285766	1275.468628	0.000000	NaN	NaN
626.999862	0.001677	16.767529	0.286288	1275.986450	0.000000	NaN	NaN
628.499948	0.001900	18.995789	0.286799	1276.493042	0.000000	NaN	NaN
630.000034	0.001842	18.418092	0.287373	1277.063232	0.000000	NaN	NaN
631.500120	0.001710	17.097642	0.287922	1277.607544	0.000000	NaN	NaN
633.000206	0.001867	18.665676	0.288409	1278.089966	0.000000	NaN	NaN
634.499291	0.001850	18.500620	0.288922	1278.599487	0.000000	NaN	NaN
635.999377	0.001941	19.408429	0.289353	1279.027344	0.000000	NaN	NaN
637.499463	0.001784	17.840395	0.289875	1279.545044	0.000000	NaN	NaN
638.999549	0.001801	18.005451	0.290404	1280.069946	0.000000	NaN	NaN
640.499634	0.001817	18.170507	0.290900	1280.561890	0.000000	NaN	NaN
641.999720	0.001759	17.592810	0.291323	1280.980835	0.000000	NaN	NaN
643.499806	0.001834	18.335564	0.291851	1281.505249	0.000000	NaN	NaN
644.999892	0.001768	17.675339	0.292276	1281.926514	0.000000	NaN	NaN
646.499978	0.001941	19.408429	0.292814	1282.460449	0.000000	NaN	NaN
648.000064	0.001842	18.418092	0.293209	1282.851807	0.000000	NaN	NaN
649.500149	0.001743	17.427754	0.293684	1283.323242	0.000000	NaN	NaN
651.000235	0.001743	17.427754	0.294158	1283.793091	0.000000	NaN	NaN
652.499321	0.001718	17.180170	0.294553	1284.185425	0.000000	NaN	NaN
653.999407	0.001776	17.757867	0.294981	1284.610352	0.000000	NaN	NaN
655.499492	0.001784	17.840395	0.295502	1285.126221	0.000000	NaN	NaN
656.999578	0.001792	17.922923	0.295791	1285.413574	0.000000	NaN	NaN
658.499664	0.001809	18.087979	0.296238	1285.857178	0.000000	NaN	NaN
659.999750	0.001718	17.180170	0.296704	1286.319458	0.000000	NaN	NaN
661.499836	0.001669	16.685001	0.296976	1286.588989	0.000000	NaN	NaN
662.999921	0.001726	17.262698	0.297437	1287.046509	0.000000	NaN	NaN
664.500007	0.001776	17.757867	0.297764	1287.370239	0.000000	NaN	NaN
666.000093	0.001743	17.427754	0.298154	1287.757202	0.000000	NaN	NaN
667.500179	0.001685	16.850057	0.298524	1288.124756	0.000000	NaN	NaN
669.000265	0.001710	17.097642	0.298745	1288.343384	0.000000	NaN	NaN
670.499350	0.001611	16.107304	0.299072	1288.667847	0.000000	NaN	NaN
671.999436	0.001726	17.262698	0.299330	1288.924438	0.000000	NaN	NaN
673.499522	0.001710	17.097642	0.299556	1289.148682	0.000000	NaN	NaN
674.999608	0.001569	15.694663	0.299643	1289.234375	0.000000	NaN	NaN
676.499694	0.001503	15.034438	0.299764	1289.354858	0.000000	NaN	NaN
677.999779	0.001512	15.116967	0.299867	1289.456543	0.000000	NaN	NaN
679.499865	0.001404	14.044101	0.299797	1289.387329	0.000000	NaN	NaN
680.999951	0.001289	12.888707	0.299507	1289.099731	0.000000	NaN	NaN
682.500037	0.001272	12.723651	0.299198	1288.793213	0.000000	NaN	NaN
684.000123	0.001173	11.733313	0.298809	1288.407593	0.000000	NaN	NaN
685.500208	0.001165	11.650785	0.298609	1288.209106	0.000000	NaN	NaN
686.999294	0.001107	11.073088	0.298249	1287.851318	0.000000	NaN	NaN
688.499380	0.001058	10.577920	0.297893	1287.498047	0.000000	NaN	NaN
689.999466	0.000934	9.339998	0.297500	1287.108765	0.000000	NaN	NaN
691.499551	0.000967	9.670110	0.297087	1286.698853	0.000000	NaN	NaN
692.999637	0.000843	8.432188	0.296709	1286.323975	0.000000	NaN	NaN
694.499723	0.000975	9.752638	0.296373	1285.991089	0.000000	NaN	NaN
695.999809	0.000802	8.019548	0.295891	1285.512573	0.000000	NaN	NaN
697.499895	0.000884	8.844829	0.295528	1285.152100	0.000000	NaN	NaN
698.999980	0.000827	8.267132	0.294925	1284.554687	0.000000	NaN	NaN
700.500066	0.000802	8.019548	0.294472	1284.104736	0.000000	NaN	NaN
702.000152	0.000711	7.111738	0.294024	1283.660034	0.000000	NaN	NaN
703.500238	0.000703	7.029210	0.293391	1283.033081	0.000000	NaN	NaN
704.999324	0.000777	7.771963	0.292982	1282.626709	0.000000	NaN	NaN
706.499409	0.000728	7.276795	0.292326	1281.975952	0.000000	NaN	NaN
707.999495	0.000629	6.286457	0.292191	1281.842163	0.000000	NaN	NaN
709.499581	0.000414	4.140726	0.291115	1280.775269	0.000000	NaN	NaN
710.999667	0.000373	3.728085	0.490784	1478.844849	0.000000	NaN	NaN
712.499753	0.000422	4.223254	0.498411	1486.411011	0.000000	NaN	NaN
713.999839	0.000389	3.893141	0.506618	1494.552368	0.000000	NaN	NaN
715.499924	-5.633774E-5	-0.563377	0.515438	1503.301636	0.000000	NaN	NaN
717.000010	-0.000122	-1.223602	0.351438	1340.614624	0.000000	NaN	NaN
718.500096	-0.000345	-3.451862	0.364069	1353.145020	0.000000	NaN	NaN
720.000182	-8.934899E-5	-0.893490	0.374104	1363.098999	0.000000	NaN	NaN
721.500267	-0.000131	-1.306131	0.381835	1370.768677	0.000000	NaN	NaN
722.999353	-5.633774E-5	-0.563377	0.389975	1378.843140	0.000000	NaN	NaN
724.499439	-0.000147	-1.471187	0.397878	1386.682739	0.000000	NaN	NaN
725.999525	-0.000155	-1.553715	0.405105	1393.851685	0.000000	NaN	NaN
727.499611	-3.983212E-5	-0.398321	0.412773	1401.458984	0.000000	NaN	NaN
728.999696	-0.000188	-1.883827	0.419109	1407.743774	0.000000	NaN	NaN
730.499782	-0.000131	-1.306131	0.426213	1414.791016	0.000000	NaN	NaN
731.999868	-4.808493E-5	-0.480849	0.433364	1421.884766	0.000000	NaN	NaN
733.499954	-0.000122	-1.223602	0.439956	1428.424194	0.000000	NaN	NaN
735.000040	-0.000246	-2.461524	0.446491	1434.906372	0.000000	NaN	NaN
736.500125	-0.000122	-1.223602	0.453168	1441.529785	0.000000	NaN	NaN
738.000211	-5.633774E-5	-0.563377	0.459642	1447.952026	0.000000	NaN	NaN
739.499297	3.444320E-5	0.344432	0.466311	1454.567383	0.000000	NaN	NaN
740.999383	-7.284337E-5	-0.728434	0.472798	1461.002686	0.000000	NaN	NaN
742.499469	-8.109618E-5	-0.810962	0.479427	1467.578125	0.000000	NaN	NaN
743.999554	-0.000147	-1.471187	0.485735	1473.836304	0.000000	NaN	NaN
745.499640	-8.109618E-5	-0.810962	0.492478	1480.525269	0.000000	NaN	NaN
746.999726	-0.000139	-1.388659	0.498950	1486.944946	0.000000	NaN	NaN
748.499812	5.094882E-5	0.509488	0.505429	1493.372192	0.000000	NaN	NaN
749.999898	-9.760180E-5	-0.976018	0.511758	1499.651001	0.000000	NaN	NaN
751.499983	-0.000122	-1.223602	0.518076	1505.918579	0.000000	NaN	NaN
753.000069	-0.000164	-1.636243	0.524617	1512.406372	0.000000	NaN	NaN
754.500155	-0.000205	-2.048884	0.530660	1518.401733	0.000000	NaN	NaN
756.000241	-0.000139	-1.388659	0.536961	1524.651855	0.000000	NaN	NaN
757.502327	-0.000197	-1.966356	0.543366	1531.005981	0.000000	NaN	NaN
758.999412	-0.000147	-1.471187	0.549956	1537.543091	0.000000	NaN	NaN
760.499498	-0.000304	-3.039221	0.556285	1543.821411	0.000000	NaN	NaN
761.999584	-8.934899E-5	-0.893490	0.562676	1550.160522	0.000000	NaN	NaN
763.499670	-0.000114	-1.141074	0.568611	1556.048828	0.000000	NaN	NaN
763.999698	-0.000131	-1.306131	0.568611	1556.048828	0.000000	NaN	NaN