File: data/57k_1-1_3 (190321).lvm
LabVIEW Measurement
Writer_Version	2
Reader_Version	2
Separator	Tab
Decimal_Separator	.
Multi_Headings	No
X_Columns	One
Time_Pref	Absolute
Operator	user
Description	Load(N)/Stress(MPa)/Distance A(pixel)/Strain A/Distance B(pixel)/Strain B/Poisson's ratio
Date	2019/03/21
Time	10:49:41.3064441680908203125
***End_of_Header***

Notes	X 값은 오직 다음과 같을 때에만 유효함이 보장됩니다. Dev1/ai0
Channels	7
Samples	1	1	1	1	1	1	1
Date	2019/03/21	2019/03/21	2019/03/21	2019/03/21	2019/03/21	2019/03/21	2019/03/21
Time	10:49:41.3064444300349943562	10:49:41.3064444300349943562	10:49:41.3064441680908203125	10:49:41.3064441680908203125	10:49:41.3064441680908203125	10:49:41.3064441680908203125	10:49:41.3064441680908203125
Y_Unit_Label	Volts	Volts
X_Dimension	Time	Time	Time	Time	Time	Time	Time
X0	0.0000000000000000E+0	0.0000000000000000E+0	0.0000000000000000E+0	0.0000000000000000E+0	0.0000000000000000E+0	0.0000000000000000E+0	0.0000000000000000E+0
Delta_X	0.000000	0.000000	1.000000	1.000000	1.000000	1.000000	1.000000
***End_of_Header***
X_Value	Dev1/ai0	Dev1/ai0 1	Untitled	Untitled 1	Untitled 2	Untitled 3	Untitled 4	Comment
0.000000	-6.459055E-5	-0.645906	8.702278E-6	988.200989	0.000000	NaN	NaN
1.000057	-8.934899E-5	-0.893490	5.900860E-5	988.250671	0.000000	NaN	NaN
1.999114	-2.332649E-5	-0.233265	-5.388260E-5	988.139160	0.000000	NaN	NaN
2.999172	0.000216	2.160051	5.447865E-5	988.246277	0.000000	NaN	NaN
3.999229	2.619039E-5	0.261904	0.000271	988.460327	0.000000	NaN	NaN
4.999286	-1.507368E-5	-0.150737	0.000553	988.738708	0.000000	NaN	NaN
5.999343	-0.000296	-2.956693	0.000845	989.027710	0.000000	NaN	NaN
6.999400	0.000208	2.077523	0.001112	989.291077	0.000000	NaN	NaN
7.999458	0.000381	3.810613	0.001357	989.533264	0.000000	NaN	NaN
8.999515	-7.284337E-5	-0.728434	0.001686	989.858643	0.000000	NaN	NaN
9.999572	0.000125	1.252241	0.001837	990.007324	0.000000	NaN	NaN
10.999629	0.000257	2.572691	0.002053	990.221619	0.000000	NaN	NaN
11.999686	0.000356	3.563029	0.002331	990.496094	0.000000	NaN	NaN
12.999744	0.000596	5.956345	0.002571	990.733337	0.000000	NaN	NaN
13.999801	0.000546	5.461176	0.002859	991.018005	0.000000	NaN	NaN
14.999858	0.000266	2.655220	0.002926	991.084167	0.000000	NaN	NaN
15.999915	0.000447	4.470838	0.003178	991.333008	0.000000	NaN	NaN
16.999972	0.000224	2.242579	0.003437	991.589172	0.000000	NaN	NaN
18.000030	0.000472	4.718423	0.003603	991.753113	0.000000	NaN	NaN
18.999087	0.000282	2.820276	0.003833	991.979797	0.000000	NaN	NaN
19.999144	0.000266	2.655220	0.004028	992.172485	0.000000	NaN	NaN
20.999201	0.000282	2.820276	0.004296	992.438049	0.000000	NaN	NaN
21.999258	0.000587	5.873817	0.004541	992.679626	0.000000	NaN	NaN
22.999316	0.000414	4.140726	0.004669	992.806396	0.000000	NaN	NaN
23.999373	0.000678	6.781626	0.004957	993.091248	0.000000	NaN	NaN
24.999430	0.000340	3.397973	0.005103	993.235291	0.000000	NaN	NaN
25.999487	0.000851	8.514717	0.005342	993.471252	0.000000	NaN	NaN
26.999544	0.000612	6.121401	0.005614	993.740540	0.000000	NaN	NaN
27.999602	0.000678	6.781626	0.005848	993.971497	0.000000	NaN	NaN
28.999659	0.000563	5.626232	0.006052	994.173096	0.000000	NaN	NaN
29.999716	0.000538	5.378648	0.006267	994.385376	0.000000	NaN	NaN
30.999773	0.000843	8.432188	0.006550	994.665405	0.000000	NaN	NaN
31.999830	0.000802	8.019548	0.006880	994.991333	0.000000	NaN	NaN
32.999887	0.000802	8.019548	0.007057	995.166138	0.000000	NaN	NaN
33.999945	0.000538	5.378648	0.007388	995.493591	0.000000	NaN	NaN
35.000002	0.000620	6.203929	0.007600	995.702209	0.000000	NaN	NaN
36.000059	0.000744	7.441851	0.007992	996.090271	0.000000	NaN	NaN
36.999116	0.000513	5.131063	0.008175	996.271362	0.000000	NaN	NaN
37.999173	0.000728	7.276795	0.008555	996.646729	0.000000	NaN	NaN
38.999231	0.000612	6.121401	0.008729	996.818298	0.000000	NaN	NaN
39.999288	0.000851	8.514717	0.009153	997.236938	0.000000	NaN	NaN
40.999345	0.000587	5.873817	0.009447	997.528259	0.000000	NaN	NaN
41.999402	0.000810	8.102076	0.009756	997.833374	0.000000	NaN	NaN
42.999459	0.000951	9.505054	0.010128	998.200806	0.000000	NaN	NaN
43.999517	0.001140	11.403201	0.010454	998.523071	0.000000	NaN	NaN
44.999574	0.000851	8.514717	0.010793	998.857544	0.000000	NaN	NaN
45.999631	0.000802	8.019548	0.011244	999.303162	0.000000	NaN	NaN
46.999688	0.000777	7.771963	0.011418	999.475403	0.000000	NaN	NaN
47.999745	0.000736	7.359323	0.011898	999.949585	0.000000	NaN	NaN
48.999803	0.001297	12.971235	0.012293	1000.340393	0.000000	NaN	NaN
49.999860	0.000884	8.844829	0.012581	1000.624573	0.000000	NaN	NaN
50.999917	0.000670	6.699098	0.012822	1000.862793	0.000000	NaN	NaN
51.999974	0.001140	11.403201	0.013218	1001.254395	0.000000	NaN	NaN
53.000031	0.000761	7.606907	0.013492	1001.525208	0.000000	NaN	NaN
53.999089	0.000975	9.752638	0.013898	1001.925964	0.000000	NaN	NaN
54.999146	0.000876	8.762301	0.014418	1002.440430	0.000000	NaN	NaN
55.999203	0.000876	8.762301	0.014709	1002.727905	0.000000	NaN	NaN
56.999260	0.000951	9.505054	0.015093	1003.107483	0.000000	NaN	NaN
57.999317	0.001124	11.238145	0.015584	1003.592224	0.000000	NaN	NaN
58.999375	0.001215	12.145954	0.015940	1003.944214	0.000000	NaN	NaN
59.999432	0.000893	8.927357	0.016385	1004.383606	0.000000	NaN	NaN
60.999489	0.001058	10.577920	0.016702	1004.696960	0.000000	NaN	NaN
61.999546	0.001000	10.000223	0.017163	1005.152893	0.000000	NaN	NaN
62.999603	0.001206	12.063426	0.017665	1005.648743	0.000000	NaN	NaN
63.999661	0.001371	13.713988	0.018010	1005.989868	0.000000	NaN	NaN
64.999718	0.001149	11.485729	0.018529	1006.502930	0.000000	NaN	NaN
65.999775	0.001008	10.082751	0.018823	1006.792664	0.000000	NaN	NaN
66.999832	0.000901	9.009885	0.019197	1007.162903	0.000000	NaN	NaN
67.999889	0.001371	13.713988	0.019786	1007.744507	0.000000	NaN	NaN
68.999947	0.001363	13.631460	0.020168	1008.122192	0.000000	NaN	NaN
70.000004	0.001347	13.466404	0.020691	1008.638916	0.000000	NaN	NaN
71.000061	0.001182	11.815842	0.021127	1009.069397	0.000000	NaN	NaN
71.999118	0.001429	14.291685	0.021606	1009.542969	0.000000	NaN	NaN
72.999175	0.001297	12.971235	0.022073	1010.004883	0.000000	NaN	NaN
73.999233	0.001083	10.825504	0.022606	1010.531128	0.000000	NaN	NaN
74.999290	0.001536	15.364551	0.022931	1010.852173	0.000000	NaN	NaN
75.999347	0.001091	10.908032	0.023552	1011.466675	0.000000	NaN	NaN
76.999404	0.001083	10.825504	0.023795	1011.706360	0.000000	NaN	NaN
77.999461	0.001462	14.621798	0.024285	1012.190796	0.000000	NaN	NaN
78.999518	0.001190	11.898370	0.024790	1012.689514	0.000000	NaN	NaN
79.999576	0.001124	11.238145	0.025178	1013.073486	0.000000	NaN	NaN
80.999633	0.001074	10.742976	0.025705	1013.593689	0.000000	NaN	NaN
81.999690	0.001190	11.898370	0.025933	1013.819275	0.000000	NaN	NaN
82.999747	0.001454	14.539270	0.026594	1014.472778	0.000000	NaN	NaN
83.999804	0.001289	12.888707	0.026952	1014.825989	0.000000	NaN	NaN
84.999862	0.001404	14.044101	0.027284	1015.154602	0.000000	NaN	NaN
85.999919	0.001000	10.000223	0.027867	1015.730225	0.000000	NaN	NaN
86.999976	0.001008	10.082751	0.028181	1016.040405	0.000000	NaN	NaN
88.000033	0.001000	10.000223	0.028659	1016.513123	0.000000	NaN	NaN
88.999090	0.001520	15.199495	0.029045	1016.894226	0.000000	NaN	NaN
89.999148	0.001685	16.850057	0.029568	1017.411316	0.000000	NaN	NaN
90.999205	0.001231	12.311010	0.029992	1017.830505	0.000000	NaN	NaN
91.999262	0.001066	10.660448	0.030519	1018.351196	0.000000	NaN	NaN
92.999319	0.001413	14.126629	0.030623	1018.454102	0.000000	NaN	NaN
93.999376	0.001305	13.053763	0.031137	1018.961792	0.000000	NaN	NaN
94.999434	0.001602	16.024776	0.031457	1019.277588	0.000000	NaN	NaN
95.999491	0.001231	12.311010	0.031716	1019.533752	0.000000	NaN	NaN
96.999548	0.001281	12.806179	0.033160	1020.960571	0.000000	NaN	NaN
97.999605	0.001363	13.631460	0.033552	1021.348633	0.000000	NaN	NaN
98.999662	0.001322	13.218820	0.034135	1021.924438	0.000000	NaN	NaN
99.999720	0.001206	12.063426	0.034615	1022.398743	0.000000	NaN	NaN
100.999777	0.001314	13.136292	0.035093	1022.871033	0.000000	NaN	NaN
101.999834	0.001545	15.447079	0.035556	1023.328979	0.000000	NaN	NaN
102.999891	0.001256	12.558595	0.036020	1023.786987	0.000000	NaN	NaN
103.999948	0.001132	11.320673	0.036493	1024.254517	0.000000	NaN	NaN
105.000006	0.001429	14.291685	0.036933	1024.689087	0.000000	NaN	NaN
106.000063	0.001611	16.107304	0.037422	1025.172974	0.000000	NaN	NaN
106.999120	0.001198	11.980898	0.037883	1025.628052	0.000000	NaN	NaN
107.999177	0.001239	12.393538	0.038340	1026.079712	0.000000	NaN	NaN
108.999234	0.001248	12.476067	0.038913	1026.646362	0.000000	NaN	NaN
109.999292	0.001256	12.558595	0.039373	1027.100586	0.000000	NaN	NaN
110.999349	0.001561	15.612135	0.039803	1027.525391	0.000000	NaN	NaN
111.999406	0.001305	13.053763	0.040319	1028.035522	0.000000	NaN	NaN
112.999463	0.001190	11.898370	0.040756	1028.467041	0.000000	NaN	NaN
113.999520	0.001223	12.228482	0.041357	1029.061401	0.000000	NaN	NaN
114.999578	0.001413	14.126629	0.041777	1029.475586	0.000000	NaN	NaN
115.999635	0.001272	12.723651	0.042270	1029.963745	0.000000	NaN	NaN
116.999692	0.001215	12.145954	0.042657	1030.345947	0.000000	NaN	NaN
117.999749	0.001536	15.364551	0.043186	1030.868042	0.000000	NaN	NaN
118.999806	0.001470	14.704326	0.043707	1031.383301	0.000000	NaN	NaN
119.999864	0.001454	14.539270	0.044136	1031.807129	0.000000	NaN	NaN
120.999921	0.001272	12.723651	0.044683	1032.347656	0.000000	NaN	NaN
121.999978	0.001380	13.796517	0.045152	1032.811035	0.000000	NaN	NaN
123.000035	0.001157	11.568257	0.045577	1033.230835	0.000000	NaN	NaN
123.999092	0.001322	13.218820	0.046052	1033.700317	0.000000	NaN	NaN
124.999150	0.001066	10.660448	0.046602	1034.244507	0.000000	NaN	NaN
125.999207	0.001355	13.548932	0.047073	1034.709229	0.000000	NaN	NaN
126.999264	0.001297	12.971235	0.047537	1035.167847	0.000000	NaN	NaN
127.999321	0.001281	12.806179	0.048158	1035.781982	0.000000	NaN	NaN
128.999378	0.001198	11.980898	0.048551	1036.169922	0.000000	NaN	NaN
129.999436	0.001644	16.437417	0.049124	1036.736328	0.000000	NaN	NaN
130.999493	0.001627	16.272360	0.049553	1037.160522	0.000000	NaN	NaN
131.999550	0.001223	12.228482	0.050048	1037.649170	0.000000	NaN	NaN
132.999607	0.001751	17.510282	0.050468	1038.064819	0.000000	NaN	NaN
133.999664	0.001124	11.238145	0.051065	1038.654419	0.000000	NaN	NaN
134.999721	0.001058	10.577920	0.051453	1039.037598	0.000000	NaN	NaN
135.999779	0.001569	15.694663	0.051953	1039.531982	0.000000	NaN	NaN
136.999836	0.001569	15.694663	0.052643	1040.213501	0.000000	NaN	NaN
137.999893	0.001520	15.199495	0.053026	1040.592651	0.000000	NaN	NaN
138.999950	0.001165	11.650785	0.053495	1041.055908	0.000000	NaN	NaN
140.000008	0.001347	13.466404	0.053950	1041.505615	0.000000	NaN	NaN
141.000065	0.001289	12.888707	0.054432	1041.981201	0.000000	NaN	NaN
141.999122	0.001503	15.034438	0.054995	1042.538452	0.000000	NaN	NaN
142.999179	0.001479	14.786854	0.055464	1043.001709	0.000000	NaN	NaN
143.999236	0.001520	15.199495	0.055936	1043.467896	0.000000	NaN	NaN
144.999293	0.001611	16.107304	0.056403	1043.929321	0.000000	NaN	NaN
145.999351	0.001512	15.116967	0.056953	1044.472900	0.000000	NaN	NaN
146.999408	0.001281	12.806179	0.057464	1044.977539	0.000000	NaN	NaN
147.999465	0.001231	12.311010	0.057846	1045.355591	0.000000	NaN	NaN
148.999522	0.001347	13.466404	0.058382	1045.885132	0.000000	NaN	NaN
149.999580	0.001561	15.612135	0.058899	1046.396240	0.000000	NaN	NaN
150.999637	0.001503	15.034438	0.059406	1046.896729	0.000000	NaN	NaN
151.999694	0.001413	14.126629	0.059875	1047.359985	0.000000	NaN	NaN
152.999751	0.001124	11.238145	0.060466	1047.944458	0.000000	NaN	NaN
153.999808	0.001578	15.777192	0.060925	1048.398193	0.000000	NaN	NaN
154.999865	0.001900	18.995789	0.061454	1048.920410	0.000000	NaN	NaN
155.999923	0.001520	15.199495	0.062024	1049.484131	0.000000	NaN	NaN
156.999980	0.001462	14.621798	0.062566	1050.020020	0.000000	NaN	NaN
158.000037	0.001446	14.456742	0.062920	1050.369873	0.000000	NaN	NaN
158.999094	0.001173	11.733313	0.063481	1050.923706	0.000000	NaN	NaN
159.999151	0.001619	16.189832	0.064050	1051.486206	0.000000	NaN	NaN
160.999209	0.001677	16.767529	0.064437	1051.868286	0.000000	NaN	NaN
161.999266	0.001710	17.097642	0.064965	1052.390503	0.000000	NaN	NaN
162.999323	0.001206	12.063426	0.065497	1052.916016	0.000000	NaN	NaN
163.999380	0.001446	14.456742	0.065940	1053.353882	0.000000	NaN	NaN
164.999437	0.001256	12.558595	0.066473	1053.880615	0.000000	NaN	NaN
165.999495	0.001462	14.621798	0.067107	1054.507202	0.000000	NaN	NaN
166.999552	0.001693	16.932585	0.067444	1054.839966	0.000000	NaN	NaN
167.999609	0.001413	14.126629	0.068018	1055.406982	0.000000	NaN	NaN
168.999666	0.001602	16.024776	0.068534	1055.916870	0.000000	NaN	NaN
169.999723	0.001363	13.631460	0.069033	1056.409912	0.000000	NaN	NaN
170.999781	0.001553	15.529607	0.069337	1056.710571	0.000000	NaN	NaN
171.999838	0.001759	17.592810	0.070032	1057.397339	0.000000	NaN	NaN
172.999895	0.001248	12.476067	0.070422	1057.783081	0.000000	NaN	NaN
173.999952	0.001388	13.879045	0.070954	1058.308716	0.000000	NaN	NaN
175.000009	0.001702	17.015114	0.071413	1058.762329	0.000000	NaN	NaN
176.000067	0.001503	15.034438	0.071907	1059.250610	0.000000	NaN	NaN
176.999124	0.001561	15.612135	0.072411	1059.748291	0.000000	NaN	NaN
177.999181	0.001437	14.374213	0.072904	1060.235596	0.000000	NaN	NaN
178.999238	0.001371	13.713988	0.073539	1060.863281	0.000000	NaN	NaN
179.999295	0.001503	15.034438	0.073900	1061.219849	0.000000	NaN	NaN
180.999353	0.001182	11.815842	0.074445	1061.758545	0.000000	NaN	NaN
181.999410	0.001718	17.180170	0.074981	1062.287720	0.000000	NaN	NaN
182.999467	0.001677	16.767529	0.075480	1062.781006	0.000000	NaN	NaN
183.999524	0.001446	14.456742	0.076353	1063.644043	0.000000	NaN	NaN
184.999581	0.001718	17.180170	0.076756	1064.041626	0.000000	NaN	NaN
185.999639	0.001627	16.272360	0.077262	1064.541626	0.000000	NaN	NaN
186.999696	0.001008	10.082751	0.077820	1065.093750	0.000000	NaN	NaN
187.999753	0.001602	16.024776	0.078377	1065.644287	0.000000	NaN	NaN
188.999810	0.001784	17.840395	0.078754	1066.016357	0.000000	NaN	NaN
189.999867	0.001454	14.539270	0.079240	1066.496582	0.000000	NaN	NaN
190.999925	0.001371	13.713988	0.079853	1067.102417	0.000000	NaN	NaN
191.999982	0.001479	14.786854	0.080232	1067.476807	0.000000	NaN	NaN
193.000039	0.001545	15.447079	0.080721	1067.960083	0.000000	NaN	NaN
193.999096	0.001627	16.272360	0.081244	1068.477173	0.000000	NaN	NaN
194.999153	0.001206	12.063426	0.081714	1068.941650	0.000000	NaN	NaN
195.999211	0.001454	14.539270	0.082202	1069.424194	0.000000	NaN	NaN
196.999268	0.001413	14.126629	0.082748	1069.963745	0.000000	NaN	NaN
197.999325	0.001809	18.087979	0.083358	1070.566284	0.000000	NaN	NaN
198.999382	0.001380	13.796517	0.083768	1070.971802	0.000000	NaN	NaN
199.999439	0.001743	17.427754	0.084316	1071.513062	0.000000	NaN	NaN
200.999496	0.001363	13.631460	0.084834	1072.024292	0.000000	NaN	NaN
201.999554	0.001834	18.335564	0.085286	1072.471436	0.000000	NaN	NaN
202.999611	0.001330	13.301348	0.085814	1072.993408	0.000000	NaN	NaN
203.999668	0.001338	13.383876	0.086351	1073.523315	0.000000	NaN	NaN
204.999725	0.001586	15.859720	0.086766	1073.934204	0.000000	NaN	NaN
205.999783	0.001743	17.427754	0.087292	1074.453369	0.000000	NaN	NaN
206.999840	0.001751	17.510282	0.087920	1075.074463	0.000000	NaN	NaN
207.999897	0.001231	12.311010	0.088344	1075.492798	0.000000	NaN	NaN
208.999954	0.001248	12.476067	0.088889	1076.031372	0.000000	NaN	NaN
210.000011	0.001784	17.840395	0.089368	1076.504883	0.000000	NaN	NaN
211.000068	0.001693	16.932585	0.089877	1077.007935	0.000000	NaN	NaN
211.999126	0.001743	17.427754	0.090224	1077.351440	0.000000	NaN	NaN
212.999183	0.001363	13.631460	0.090931	1078.049927	0.000000	NaN	NaN
213.999240	0.001355	13.548932	0.091321	1078.435547	0.000000	NaN	NaN
214.999297	0.001768	17.675339	0.091756	1078.864746	0.000000	NaN	NaN
215.999354	0.001759	17.592810	0.092292	1079.394531	0.000000	NaN	NaN
216.999412	0.001371	13.713988	0.092870	1079.965942	0.000000	NaN	NaN
217.999469	0.001677	16.767529	0.093300	1080.390747	0.000000	NaN	NaN
218.999526	0.001702	17.015114	0.093835	1080.919800	0.000000	NaN	NaN
219.999583	0.001479	14.786854	0.094410	1081.487427	0.000000	NaN	NaN
220.999640	0.001586	15.859720	0.094857	1081.929565	0.000000	NaN	NaN
221.999698	0.001528	15.282023	0.095396	1082.462280	0.000000	NaN	NaN
222.999755	0.001487	14.869382	0.095908	1082.967651	0.000000	NaN	NaN
223.999812	0.001702	17.015114	0.096330	1083.385376	0.000000	NaN	NaN
224.999869	0.001611	16.107304	0.096810	1083.859619	0.000000	NaN	NaN
225.999926	0.001479	14.786854	0.097411	1084.453491	0.000000	NaN	NaN
226.999984	0.001371	13.713988	0.097808	1084.845703	0.000000	NaN	NaN
228.000041	0.001586	15.859720	0.098347	1085.377686	0.000000	NaN	NaN
228.999098	0.001801	18.005451	0.098762	1085.788086	0.000000	NaN	NaN
229.999155	0.001536	15.364551	0.099398	1086.416992	0.000000	NaN	NaN
230.999212	0.001586	15.859720	0.099849	1086.862915	0.000000	NaN	NaN
231.999270	0.001239	12.393538	0.100362	1087.369385	0.000000	NaN	NaN
232.999327	0.001776	17.757867	0.100811	1087.813477	0.000000	NaN	NaN
233.999384	0.001858	18.583148	0.101230	1088.226685	0.000000	NaN	NaN
234.999441	0.001413	14.126629	0.101891	1088.880249	0.000000	NaN	NaN
235.999498	0.001660	16.602473	0.102340	1089.323608	0.000000	NaN	NaN
236.999556	0.001594	15.942248	0.102701	1089.680664	0.000000	NaN	NaN
237.999613	0.001586	15.859720	0.103302	1090.274658	0.000000	NaN	NaN
238.999670	0.001355	13.548932	0.103913	1090.878540	0.000000	NaN	NaN
239.999727	0.001842	18.418092	0.104226	1091.188232	0.000000	NaN	NaN
240.999784	0.001751	17.510282	0.104792	1091.747559	0.000000	NaN	NaN
241.999842	0.001503	15.034438	0.105378	1092.325928	0.000000	NaN	NaN
242.999899	0.001553	15.529607	0.105752	1092.695801	0.000000	NaN	NaN
243.999956	0.001215	12.145954	0.106386	1093.322632	0.000000	NaN	NaN
245.000013	0.001726	17.262698	0.106970	1093.899170	0.000000	NaN	NaN
246.000070	0.002048	20.481295	0.107286	1094.211914	0.000000	NaN	NaN
246.999128	0.001924	19.243373	0.107906	1094.824341	0.000000	NaN	NaN
247.999185	0.001644	16.437417	0.108525	1095.436035	0.000000	NaN	NaN
248.999242	0.001264	12.641123	0.108915	1095.821167	0.000000	NaN	NaN
249.999299	0.001768	17.675339	0.109417	1096.317749	0.000000	NaN	NaN
250.999356	0.001883	18.830732	0.109981	1096.874756	0.000000	NaN	NaN
251.999414	0.001479	14.786854	0.110331	1097.220337	0.000000	NaN	NaN
252.999471	0.001627	16.272360	0.110916	1097.798462	0.000000	NaN	NaN
253.999528	0.001850	18.500620	0.111412	1098.288574	0.000000	NaN	NaN
254.999585	0.001371	13.713988	0.111814	1098.686646	0.000000	NaN	NaN
255.999642	0.001578	15.777192	0.112235	1099.102417	0.000000	NaN	NaN
256.999700	0.001710	17.097642	0.112751	1099.612183	0.000000	NaN	NaN
257.999757	0.001768	17.675339	0.113278	1100.132568	0.000000	NaN	NaN
258.999814	0.001735	17.345226	0.113654	1100.504150	0.000000	NaN	NaN
259.999871	0.001900	18.995789	0.114248	1101.091064	0.000000	NaN	NaN
260.999928	0.001479	14.786854	0.114751	1101.588501	0.000000	NaN	NaN
261.999985	0.001693	16.932585	0.115101	1101.934814	0.000000	NaN	NaN
263.000043	0.001602	16.024776	0.115638	1102.465332	0.000000	NaN	NaN
263.999100	0.001413	14.126629	0.116317	1103.136353	0.000000	NaN	NaN
264.999157	0.001660	16.602473	0.116559	1103.375366	0.000000	NaN	NaN
265.999214	0.001825	18.253035	0.116907	1103.718628	0.000000	NaN	NaN
266.999272	0.001611	16.107304	0.117685	1104.487793	0.000000	NaN	NaN
267.999329	0.001454	14.539270	0.118119	1104.916504	0.000000	NaN	NaN
268.999386	0.001693	16.932585	0.118558	1105.350830	0.000000	NaN	NaN
269.999443	0.001768	17.675339	0.119056	1105.842285	0.000000	NaN	NaN
270.999500	0.001941	19.408429	0.119652	1106.431641	0.000000	NaN	NaN
271.999557	0.001380	13.796517	0.119956	1106.731812	0.000000	NaN	NaN
272.999615	0.001330	13.301348	0.120552	1107.320679	0.000000	NaN	NaN
273.999672	0.001949	19.490957	0.121077	1107.839844	0.000000	NaN	NaN
274.999729	0.001784	17.840395	0.121588	1108.344360	0.000000	NaN	NaN
275.999786	0.001421	14.209157	0.122036	1108.787842	0.000000	NaN	NaN
276.999843	0.001660	16.602473	0.122548	1109.293213	0.000000	NaN	NaN
277.999901	0.001685	16.850057	0.122984	1109.723877	0.000000	NaN	NaN
278.999958	0.001619	16.189832	0.123548	1110.281738	0.000000	NaN	NaN
280.000015	0.001355	13.548932	0.123863	1110.592651	0.000000	NaN	NaN
281.000072	0.001776	17.757867	0.124406	1111.129883	0.000000	NaN	NaN
281.999129	0.001578	15.777192	0.125054	1111.770142	0.000000	NaN	NaN
282.999187	0.001561	15.612135	0.125539	1112.248779	0.000000	NaN	NaN
283.999244	0.001842	18.418092	0.125984	1112.689087	0.000000	NaN	NaN
284.999301	0.001380	13.796517	0.126402	1113.101562	0.000000	NaN	NaN
285.999358	0.001314	13.136292	0.126885	1113.578979	0.000000	NaN	NaN
286.999415	0.001875	18.748204	0.127485	1114.172241	0.000000	NaN	NaN
287.999473	0.001933	19.325901	0.127873	1114.555786	0.000000	NaN	NaN
288.999530	0.001462	14.621798	0.128359	1115.035889	0.000000	NaN	NaN
289.999587	0.001586	15.859720	0.129040	1115.708374	0.000000	NaN	NaN
290.999644	0.001495	14.951910	0.129384	1116.048584	0.000000	NaN	NaN
291.999701	0.001966	19.656014	0.129886	1116.545166	0.000000	NaN	NaN
292.999759	0.001594	15.942248	0.130456	1117.107666	0.000000	NaN	NaN
293.999816	0.001545	15.447079	0.130896	1117.542725	0.000000	NaN	NaN
294.999873	0.001776	17.757867	0.131510	1118.149536	0.000000	NaN	NaN
295.999930	0.001561	15.612135	0.132024	1118.657227	0.000000	NaN	NaN
296.999987	0.001495	14.951910	0.132403	1119.032104	0.000000	NaN	NaN
298.000045	0.001792	17.922923	0.132934	1119.557007	0.000000	NaN	NaN
298.999102	0.001677	16.767529	0.133564	1120.179687	0.000000	NaN	NaN
299.999159	0.001619	16.189832	0.133887	1120.498413	0.000000	NaN	NaN
300.999216	0.002065	20.646351	0.134467	1121.071289	0.000000	NaN	NaN
301.999273	0.001297	12.971235	0.134946	1121.544800	0.000000	NaN	NaN
302.999331	0.001553	15.529607	0.135281	1121.876465	0.000000	NaN	NaN
303.999388	0.001784	17.840395	0.135719	1122.308960	0.000000	NaN	NaN
304.999445	0.001743	17.427754	0.136138	1122.722778	0.000000	NaN	NaN
305.999502	0.001759	17.592810	0.136684	1123.262329	0.000000	NaN	NaN
306.999559	0.001330	13.301348	0.137138	1123.710937	0.000000	NaN	NaN
307.999617	0.001710	17.097642	0.137722	1124.288208	0.000000	NaN	NaN
308.999674	0.001801	18.005451	0.138285	1124.844116	0.000000	NaN	NaN
309.999731	0.001652	16.519945	0.138756	1125.310059	0.000000	NaN	NaN
310.999788	0.001735	17.345226	0.139219	1125.767578	0.000000	NaN	NaN
311.999845	0.001677	16.767529	0.139768	1126.310425	0.000000	NaN	NaN
312.999903	0.001479	14.786854	0.140194	1126.730957	0.000000	NaN	NaN
313.999960	0.001644	16.437417	0.140651	1127.182617	0.000000	NaN	NaN
315.000017	0.001281	12.806179	0.141238	1127.762573	0.000000	NaN	NaN
315.999074	0.001933	19.325901	0.141638	1128.157715	0.000000	NaN	NaN
316.999131	0.001677	16.767529	0.142074	1128.588379	0.000000	NaN	NaN
317.999189	0.001784	17.840395	0.142580	1129.089233	0.000000	NaN	NaN
318.999246	0.001644	16.437417	0.143098	1129.601196	0.000000	NaN	NaN
319.999303	0.001957	19.573485	0.143468	1129.966309	0.000000	NaN	NaN
320.999360	0.001553	15.529607	0.144199	1130.688232	0.000000	NaN	NaN
321.999417	0.001512	15.116967	0.144531	1131.016846	0.000000	NaN	NaN
322.999475	0.001817	18.170507	0.144898	1131.379517	0.000000	NaN	NaN
323.999532	0.001660	16.602473	0.145516	1131.990112	0.000000	NaN	NaN
324.999589	0.001487	14.869382	0.146059	1132.527100	0.000000	NaN	NaN
325.999646	0.001966	19.656014	0.146430	1132.893799	0.000000	NaN	NaN
326.999703	0.001842	18.418092	0.146918	1133.375488	0.000000	NaN	NaN
327.999760	0.001726	17.262698	0.147616	1134.065552	0.000000	NaN	NaN
328.999818	0.001635	16.354889	0.147920	1134.365845	0.000000	NaN	NaN
329.999875	0.001561	15.612135	0.148469	1134.908691	0.000000	NaN	NaN
330.999932	0.001801	18.005451	0.149068	1135.500244	0.000000	NaN	NaN
331.999989	0.001660	16.602473	0.149485	1135.912476	0.000000	NaN	NaN
333.000046	0.001470	14.704326	0.150008	1136.428711	0.000000	NaN	NaN
333.999104	0.001594	15.942248	0.150608	1137.021973	0.000000	NaN	NaN
334.999161	0.001611	16.107304	0.151012	1137.420898	0.000000	NaN	NaN
335.999218	0.001957	19.573485	0.151516	1137.919189	0.000000	NaN	NaN
336.999275	0.001743	17.427754	0.152090	1138.486816	0.000000	NaN	NaN
337.999332	0.001801	18.005451	0.152520	1138.911255	0.000000	NaN	NaN
338.999390	0.001627	16.272360	0.152880	1139.267212	0.000000	NaN	NaN
339.999447	0.001594	15.942248	0.153360	1139.742065	0.000000	NaN	NaN
340.999504	0.001421	14.209157	0.153961	1140.335815	0.000000	NaN	NaN
341.999561	0.001949	19.490957	0.154356	1140.726196	0.000000	NaN	NaN
342.999618	0.001916	19.160845	0.154865	1141.228882	0.000000	NaN	NaN
343.999676	0.001759	17.592810	0.155354	1141.711792	0.000000	NaN	NaN
344.999733	0.001536	15.364551	0.155748	1142.101196	0.000000	NaN	NaN
345.999790	0.001520	15.199495	0.156327	1142.673584	0.000000	NaN	NaN
346.999847	0.001702	17.015114	0.156823	1143.163940	0.000000	NaN	NaN
347.999904	0.001553	15.529607	0.157229	1143.564453	0.000000	NaN	NaN
348.999962	0.001933	19.325901	0.157804	1144.133057	0.000000	NaN	NaN
350.000019	0.001702	17.015114	0.158370	1144.692261	0.000000	NaN	NaN
350.999076	0.001611	16.107304	0.158765	1145.082642	0.000000	NaN	NaN
351.999133	0.002106	21.058992	0.159261	1145.572510	0.000000	NaN	NaN
352.999190	0.001924	19.243373	0.159834	1146.138916	0.000000	NaN	NaN
353.999248	0.001561	15.612135	0.160206	1146.506836	0.000000	NaN	NaN
354.999305	0.001421	14.209157	0.160600	1146.896240	0.000000	NaN	NaN
355.999362	0.001999	19.986126	0.161149	1147.438354	0.000000	NaN	NaN
356.999419	0.001487	14.869382	0.161744	1148.026733	0.000000	NaN	NaN
357.999476	0.001495	14.951910	0.162104	1148.382690	0.000000	NaN	NaN
358.999534	0.002147	21.471632	0.162688	1148.959961	0.000000	NaN	NaN
359.999591	0.001545	15.447079	0.163303	1149.567261	0.000000	NaN	NaN
360.999648	0.001495	14.951910	0.163610	1149.870117	0.000000	NaN	NaN
361.999705	0.001652	16.519945	0.164163	1150.417480	0.000000	NaN	NaN
362.999762	0.001743	17.427754	0.164733	1150.980347	0.000000	NaN	NaN
363.999820	0.002032	20.316239	0.165186	1151.427979	0.000000	NaN	NaN
364.999877	0.001503	15.034438	0.165594	1151.831055	0.000000	NaN	NaN
365.999934	0.001437	14.374213	0.166221	1152.450439	0.000000	NaN	NaN
366.999991	0.001990	19.903598	0.166549	1152.774902	0.000000	NaN	NaN
368.000048	0.001635	16.354889	0.167049	1153.268555	0.000000	NaN	NaN
368.999105	0.001487	14.869382	0.167663	1153.875732	0.000000	NaN	NaN
369.999163	0.001759	17.592810	0.168143	1154.349609	0.000000	NaN	NaN
370.999220	0.001941	19.408429	0.168411	1154.614502	0.000000	NaN	NaN
371.999277	0.001867	18.665676	0.168953	1155.150513	0.000000	NaN	NaN
372.999334	0.001710	17.097642	0.169502	1155.692505	0.000000	NaN	NaN
373.999392	0.001380	13.796517	0.169944	1156.129272	0.000000	NaN	NaN
374.999449	0.001801	18.005451	0.170391	1156.571777	0.000000	NaN	NaN
375.999506	0.001677	16.767529	0.170946	1157.119751	0.000000	NaN	NaN
376.999563	0.001834	18.335564	0.171395	1157.563721	0.000000	NaN	NaN
377.999620	0.001553	15.529607	0.171915	1158.077393	0.000000	NaN	NaN
378.999678	0.001891	18.913260	0.172484	1158.639404	0.000000	NaN	NaN
379.999735	0.001842	18.418092	0.172882	1159.033325	0.000000	NaN	NaN
380.999792	0.001512	15.116967	0.173458	1159.602539	0.000000	NaN	NaN
381.999849	0.001726	17.262698	0.173887	1160.026001	0.000000	NaN	NaN
382.999906	0.001619	16.189832	0.174302	1160.435791	0.000000	NaN	NaN
383.999963	0.001635	16.354889	0.174852	1160.979492	0.000000	NaN	NaN
385.000021	0.001883	18.830732	0.175249	1161.372559	0.000000	NaN	NaN
385.999078	0.001957	19.573485	0.175730	1161.847412	0.000000	NaN	NaN
386.999135	0.001454	14.539270	0.176013	1162.127319	0.000000	NaN	NaN
387.999192	0.001685	16.850057	0.176658	1162.764282	0.000000	NaN	NaN
388.999250	0.001503	15.034438	0.177186	1163.286377	0.000000	NaN	NaN
389.999307	0.001619	16.189832	0.177558	1163.654175	0.000000	NaN	NaN
390.999364	0.002089	20.893935	0.178146	1164.234497	0.000000	NaN	NaN
391.999421	0.001669	16.685001	0.178696	1164.778809	0.000000	NaN	NaN
392.999478	0.001743	17.427754	0.179069	1165.147095	0.000000	NaN	NaN
393.999535	0.001982	19.821070	0.179628	1165.699219	0.000000	NaN	NaN
394.999593	0.001380	13.796517	0.180196	1166.260864	0.000000	NaN	NaN
395.999650	0.001503	15.034438	0.180604	1166.663940	0.000000	NaN	NaN
396.999707	0.001982	19.821070	0.181107	1167.160645	0.000000	NaN	NaN
397.999764	0.001735	17.345226	0.181633	1167.680664	0.000000	NaN	NaN
398.999821	0.001702	17.015114	0.182070	1168.112671	0.000000	NaN	NaN
399.999879	0.002032	20.316239	0.182512	1168.549072	0.000000	NaN	NaN
400.999936	0.001726	17.262698	0.183054	1169.085083	0.000000	NaN	NaN
401.999993	0.001784	17.840395	0.183462	1169.488037	0.000000	NaN	NaN
403.000050	0.001602	16.024776	0.183833	1169.854492	0.000000	NaN	NaN
403.999107	0.001710	17.097642	0.184468	1170.482422	0.000000	NaN	NaN
404.999165	0.001520	15.199495	0.184928	1170.936401	0.000000	NaN	NaN
405.999222	0.001842	18.418092	0.185295	1171.298950	0.000000	NaN	NaN
406.999279	0.001627	16.272360	0.186054	1172.049805	0.000000	NaN	NaN
407.999336	0.001611	16.107304	0.186412	1172.403198	0.000000	NaN	NaN
408.999393	0.001627	16.272360	0.186751	1172.738281	0.000000	NaN	NaN
409.999451	0.001809	18.087979	0.187343	1173.323364	0.000000	NaN	NaN
410.999508	0.002073	20.728879	0.187920	1173.893188	0.000000	NaN	NaN
411.999565	0.001784	17.840395	0.188189	1174.159546	0.000000	NaN	NaN
412.999622	0.001710	17.097642	0.188806	1174.769165	0.000000	NaN	NaN
413.999679	0.001627	16.272360	0.189277	1175.234131	0.000000	NaN	NaN
414.999737	0.001768	17.675339	0.189720	1175.672363	0.000000	NaN	NaN
415.999794	0.001957	19.573485	0.190220	1176.166382	0.000000	NaN	NaN
416.999851	0.001462	14.621798	0.190780	1176.719971	0.000000	NaN	NaN
417.999908	0.001941	19.408429	0.191206	1177.140625	0.000000	NaN	NaN
418.999965	0.001842	18.418092	0.191562	1177.492676	0.000000	NaN	NaN
420.000023	0.001487	14.869382	0.192206	1178.129028	0.000000	NaN	NaN
420.999080	0.001495	14.951910	0.192575	1178.493408	0.000000	NaN	NaN
421.999137	0.001974	19.738542	0.193004	1178.917236	0.000000	NaN	NaN
422.999194	0.001594	15.942248	0.193309	1179.218994	0.000000	NaN	NaN
423.999251	0.001966	19.656014	0.194508	1180.404053	0.000000	NaN	NaN
424.999309	0.001578	15.777192	0.194912	1180.802490	0.000000	NaN	NaN
425.999366	0.001743	17.427754	0.195421	1181.306030	0.000000	NaN	NaN
426.999423	0.001908	19.078317	0.196020	1181.897949	0.000000	NaN	NaN
427.999480	0.001627	16.272360	0.196344	1182.218506	0.000000	NaN	NaN
428.999537	0.001743	17.427754	0.196780	1182.649170	0.000000	NaN	NaN
429.999595	0.001363	13.631460	0.197239	1183.102905	0.000000	NaN	NaN
430.999652	0.001718	17.180170	0.197746	1183.603271	0.000000	NaN	NaN
431.999709	0.001718	17.180170	0.198184	1184.036133	0.000000	NaN	NaN
432.999766	0.002023	20.233710	0.198625	1184.471924	0.000000	NaN	NaN
433.999823	0.001594	15.942248	0.199256	1185.095703	0.000000	NaN	NaN
434.999881	0.001652	16.519945	0.199591	1185.427002	0.000000	NaN	NaN
435.999938	0.001957	19.573485	0.200096	1185.925415	0.000000	NaN	NaN
436.999995	0.001503	15.034438	0.200625	1186.448120	0.000000	NaN	NaN
438.000052	0.001619	16.189832	0.200965	1186.784424	0.000000	NaN	NaN
438.999109	0.001883	18.830732	0.201542	1187.354736	0.000000	NaN	NaN
439.999167	0.001759	17.592810	0.201873	1187.681763	0.000000	NaN	NaN
440.999224	0.001545	15.447079	0.202386	1188.188721	0.000000	NaN	NaN
441.999281	0.001669	16.685001	0.202796	1188.593750	0.000000	NaN	NaN
442.999338	0.001801	18.005451	0.203304	1189.095581	0.000000	NaN	NaN
443.999395	0.001792	17.922923	0.203790	1189.576538	0.000000	NaN	NaN
444.999453	0.001602	16.024776	0.204229	1190.009644	0.000000	NaN	NaN
445.999510	0.002065	20.646351	0.204699	1190.474121	0.000000	NaN	NaN
446.999567	0.001677	16.767529	0.205143	1190.913330	0.000000	NaN	NaN
447.999624	0.001776	17.757867	0.205725	1191.488159	0.000000	NaN	NaN
448.999681	0.001809	18.087979	0.206159	1191.917114	0.000000	NaN	NaN
449.999738	0.001677	16.767529	0.206735	1192.485962	0.000000	NaN	NaN
450.999796	0.001743	17.427754	0.207008	1192.756348	0.000000	NaN	NaN
451.999853	0.001569	15.694663	0.207548	1193.289917	0.000000	NaN	NaN
452.999910	0.001949	19.490957	0.207978	1193.714722	0.000000	NaN	NaN
453.999967	0.001652	16.519945	0.208607	1194.336426	0.000000	NaN	NaN
455.000024	0.001784	17.840395	0.208862	1194.588379	0.000000	NaN	NaN
455.999082	0.001743	17.427754	0.209292	1195.012817	0.000000	NaN	NaN
456.999139	0.001809	18.087979	0.209823	1195.538330	0.000000	NaN	NaN
457.999196	0.001644	16.437417	0.210247	1195.956543	0.000000	NaN	NaN
458.999253	0.001842	18.418092	0.210590	1196.295410	0.000000	NaN	NaN
459.999310	0.001792	17.922923	0.211169	1196.868408	0.000000	NaN	NaN
460.999368	0.001503	15.034438	0.211545	1197.239746	0.000000	NaN	NaN
461.999425	0.001949	19.490957	0.211992	1197.681274	0.000000	NaN	NaN
462.999482	0.001602	16.024776	0.212459	1198.142578	0.000000	NaN	NaN
463.999539	0.002139	21.389104	0.212831	1198.510620	0.000000	NaN	NaN
464.999596	0.001768	17.675339	0.213239	1198.913574	0.000000	NaN	NaN
465.999654	0.001602	16.024776	0.213700	1199.369385	0.000000	NaN	NaN
466.999711	0.001957	19.573485	0.214154	1199.817505	0.000000	NaN	NaN
467.999768	0.001743	17.427754	0.214695	1200.352295	0.000000	NaN	NaN
468.999825	0.001611	16.107304	0.215080	1200.733276	0.000000	NaN	NaN
469.999882	0.001784	17.840395	0.215545	1201.192261	0.000000	NaN	NaN
470.999940	0.001842	18.418092	0.216165	1201.804932	0.000000	NaN	NaN
471.999997	0.001817	18.170507	0.216518	1202.153809	0.000000	NaN	NaN
473.000054	0.001561	15.612135	0.216833	1202.465210	0.000000	NaN	NaN
473.999111	0.001784	17.840395	0.217336	1202.961792	0.000000	NaN	NaN
474.999168	0.002023	20.233710	0.217920	1203.539185	0.000000	NaN	NaN
475.999226	0.001578	15.777192	0.218364	1203.978027	0.000000	NaN	NaN
476.999283	0.001957	19.573485	0.218784	1204.392700	0.000000	NaN	NaN
477.999340	0.001817	18.170507	0.219352	1204.953979	0.000000	NaN	NaN
478.999397	0.001883	18.830732	0.219730	1205.327637	0.000000	NaN	NaN
479.999454	0.001619	16.189832	0.220223	1205.815430	0.000000	NaN	NaN
480.999512	0.001858	18.583148	0.220677	1206.264160	0.000000	NaN	NaN
481.999569	0.002065	20.646351	0.221065	1206.647095	0.000000	NaN	NaN
482.999626	0.001446	14.456742	0.221442	1207.020020	0.000000	NaN	NaN
483.999683	0.001924	19.243373	0.221879	1207.451904	0.000000	NaN	NaN
484.999740	0.001966	19.656014	0.222384	1207.950562	0.000000	NaN	NaN
485.999798	0.001834	18.335564	0.222798	1208.359131	0.000000	NaN	NaN
486.999855	0.001545	15.447079	0.223090	1208.648071	0.000000	NaN	NaN
487.999912	0.001999	19.986126	0.223698	1209.249268	0.000000	NaN	NaN
488.999969	0.001743	17.427754	0.224086	1209.632568	0.000000	NaN	NaN
490.000026	0.001784	17.840395	0.224514	1210.055420	0.000000	NaN	NaN
490.999083	0.001850	18.500620	0.224970	1210.506104	0.000000	NaN	NaN
491.999141	0.001776	17.757867	0.225349	1210.880737	0.000000	NaN	NaN
492.999198	0.001685	16.850057	0.225855	1211.380615	0.000000	NaN	NaN
493.999255	0.001809	18.087979	0.226274	1211.795166	0.000000	NaN	NaN
494.999312	0.001759	17.592810	0.226738	1212.252930	0.000000	NaN	NaN
495.999369	0.001842	18.418092	0.227142	1212.651978	0.000000	NaN	NaN
496.999427	0.001867	18.665676	0.227465	1212.971802	0.000000	NaN	NaN
497.999484	0.001685	16.850057	0.227833	1213.335083	0.000000	NaN	NaN
498.999541	0.001809	18.087979	0.228291	1213.787476	0.000000	NaN	NaN
499.999598	0.001726	17.262698	0.228770	1214.260742	0.000000	NaN	NaN
500.999656	0.001834	18.335564	0.229072	1214.559570	0.000000	NaN	NaN
501.999713	0.001792	17.922923	0.229423	1214.906616	0.000000	NaN	NaN
502.999770	0.001685	16.850057	0.229945	1215.422241	0.000000	NaN	NaN
503.999827	0.001792	17.922923	0.230412	1215.884033	0.000000	NaN	NaN
504.999884	0.001817	18.170507	0.230673	1216.141968	0.000000	NaN	NaN
505.999941	0.001784	17.840395	0.231192	1216.654541	0.000000	NaN	NaN
506.999999	0.001842	18.418092	0.231505	1216.964111	0.000000	NaN	NaN
508.000056	0.001702	17.015114	0.232034	1217.487061	0.000000	NaN	NaN
508.999113	0.001735	17.345226	0.232378	1217.826050	0.000000	NaN	NaN
509.999170	0.001801	18.005451	0.232801	1218.244141	0.000000	NaN	NaN
510.999228	0.001850	18.500620	0.233232	1218.670898	0.000000	NaN	NaN
511.999285	0.001751	17.510282	0.233552	1218.987061	0.000000	NaN	NaN
512.999342	0.001883	18.830732	0.233966	1219.396118	0.000000	NaN	NaN
513.999399	0.001817	18.170507	0.234393	1219.817383	0.000000	NaN	NaN
514.999456	0.001842	18.418092	0.234853	1220.272339	0.000000	NaN	NaN
515.999514	0.001702	17.015114	0.235195	1220.610107	0.000000	NaN	NaN
516.999571	0.001850	18.500620	0.235651	1221.061035	0.000000	NaN	NaN
517.999628	0.001801	18.005451	0.236168	1221.571533	0.000000	NaN	NaN
518.999685	0.001900	18.995789	0.236582	1221.980713	0.000000	NaN	NaN
519.999742	0.001834	18.335564	0.237015	1222.408325	0.000000	NaN	NaN
520.999799	0.001858	18.583148	0.237383	1222.772217	0.000000	NaN	NaN
521.999857	0.001759	17.592810	0.237858	1223.242065	0.000000	NaN	NaN
522.999914	0.001809	18.087979	0.238265	1223.643555	0.000000	NaN	NaN
523.999971	0.001842	18.418092	0.238652	1224.026489	0.000000	NaN	NaN
525.000028	0.001817	18.170507	0.239001	1224.371094	0.000000	NaN	NaN
525.999085	0.001718	17.180170	0.239402	1224.767456	0.000000	NaN	NaN
526.999143	0.001825	18.253035	0.239910	1225.269287	0.000000	NaN	NaN
527.999200	0.001875	18.748204	0.240248	1225.603394	0.000000	NaN	NaN
528.999257	0.001916	19.160845	0.240694	1226.043945	0.000000	NaN	NaN
529.999314	0.001834	18.335564	0.241111	1226.456665	0.000000	NaN	NaN
530.999371	0.001941	19.408429	0.241571	1226.911011	0.000000	NaN	NaN
531.999429	0.001834	18.335564	0.242059	1227.393555	0.000000	NaN	NaN
532.999486	0.001891	18.913260	0.242418	1227.747681	0.000000	NaN	NaN
533.999543	0.001784	17.840395	0.242871	1228.195557	0.000000	NaN	NaN
534.999600	0.001916	19.160845	0.243313	1228.632324	0.000000	NaN	NaN
535.999657	0.001693	16.932585	0.243729	1229.043823	0.000000	NaN	NaN
536.999715	0.001801	18.005451	0.244072	1229.382080	0.000000	NaN	NaN
537.999772	0.001801	18.005451	0.244646	1229.949585	0.000000	NaN	NaN
538.999829	0.001809	18.087979	0.244991	1230.290405	0.000000	NaN	NaN
539.999886	0.001850	18.500620	0.245464	1230.758301	0.000000	NaN	NaN
540.999943	0.001900	18.995789	0.245798	1231.088013	0.000000	NaN	NaN
542.000001	0.001842	18.418092	0.246332	1231.616211	0.000000	NaN	NaN
543.000058	0.001809	18.087979	0.246752	1232.030518	0.000000	NaN	NaN
543.999115	0.001974	19.738542	0.247160	1232.434326	0.000000	NaN	NaN
544.999172	0.001702	17.015114	0.247688	1232.955444	0.000000	NaN	NaN
545.999229	0.001726	17.262698	0.248043	1233.306152	0.000000	NaN	NaN
546.999287	0.001842	18.418092	0.248518	1233.776367	0.000000	NaN	NaN
547.999344	0.001850	18.500620	0.248931	1234.183838	0.000000	NaN	NaN
548.999401	0.001809	18.087979	0.249368	1234.615967	0.000000	NaN	NaN
549.999458	0.001916	19.160845	0.249767	1235.010254	0.000000	NaN	NaN
550.999515	0.001809	18.087979	0.250169	1235.407471	0.000000	NaN	NaN
551.999573	0.001858	18.583148	0.250657	1235.889404	0.000000	NaN	NaN
552.999630	0.002007	20.068654	0.251315	1236.539551	0.000000	NaN	NaN
553.999687	0.001924	19.243373	0.251662	1236.883179	0.000000	NaN	NaN
554.999744	0.001957	19.573485	0.252095	1237.310303	0.000000	NaN	NaN
555.999801	0.001759	17.592810	0.252609	1237.818481	0.000000	NaN	NaN
556.999859	0.001809	18.087979	0.253013	1238.217529	0.000000	NaN	NaN
557.999916	0.001792	17.922923	0.253411	1238.611206	0.000000	NaN	NaN
558.999973	0.001784	17.840395	0.253843	1239.037842	0.000000	NaN	NaN
560.000030	0.001924	19.243373	0.254314	1239.503906	0.000000	NaN	NaN
560.999087	0.001891	18.913260	0.254655	1239.840698	0.000000	NaN	NaN
561.999145	0.001751	17.510282	0.255290	1240.467529	0.000000	NaN	NaN
562.999202	0.001718	17.180170	0.255710	1240.883179	0.000000	NaN	NaN
563.999259	0.001801	18.005451	0.256073	1241.241699	0.000000	NaN	NaN
564.999316	0.001867	18.665676	0.256707	1241.868652	0.000000	NaN	NaN
565.999373	0.001924	19.243373	0.257012	1242.169312	0.000000	NaN	NaN
566.999431	0.001842	18.418092	0.257457	1242.609253	0.000000	NaN	NaN
567.999488	0.001776	17.757867	0.258005	1243.150879	0.000000	NaN	NaN
568.999545	0.001768	17.675339	0.258468	1243.608276	0.000000	NaN	NaN
569.999602	0.001801	18.005451	0.258932	1244.067139	0.000000	NaN	NaN
570.999659	0.001759	17.592810	0.259290	1244.421143	0.000000	NaN	NaN
571.999716	0.001834	18.335564	0.259824	1244.948608	0.000000	NaN	NaN
572.999774	0.001850	18.500620	0.260322	1245.440796	0.000000	NaN	NaN
573.999831	0.001875	18.748204	0.260711	1245.825195	0.000000	NaN	NaN
574.999888	0.001850	18.500620	0.261117	1246.226685	0.000000	NaN	NaN
575.999945	0.001834	18.335564	0.261488	1246.593018	0.000000	NaN	NaN
577.000003	0.001685	16.850057	0.261986	1247.085205	0.000000	NaN	NaN
578.000060	0.001867	18.665676	0.262515	1247.608154	0.000000	NaN	NaN
578.999117	0.001801	18.005451	0.262809	1247.898437	0.000000	NaN	NaN
579.999174	0.001867	18.665676	0.263482	1248.563232	0.000000	NaN	NaN
580.999231	0.001817	18.170507	0.263934	1249.010376	0.000000	NaN	NaN
581.999288	0.001809	18.087979	0.264413	1249.482910	0.000000	NaN	NaN
582.999346	0.001784	17.840395	0.264839	1249.904541	0.000000	NaN	NaN
583.999403	0.001933	19.325901	0.265316	1250.375977	0.000000	NaN	NaN
584.999460	0.001867	18.665676	0.265822	1250.875610	0.000000	NaN	NaN
585.999517	0.001875	18.748204	0.266389	1251.435669	0.000000	NaN	NaN
586.999574	0.001743	17.427754	0.266806	1251.847656	0.000000	NaN	NaN
587.999632	0.001792	17.922923	0.266952	1251.992310	0.000000	NaN	NaN
588.999689	0.001776	17.757867	0.267843	1252.872437	0.000000	NaN	NaN
589.999746	0.001726	17.262698	0.268175	1253.200806	0.000000	NaN	NaN
590.999803	0.001735	17.345226	0.268493	1253.515259	0.000000	NaN	NaN
591.999860	0.001784	17.840395	0.268890	1253.907104	0.000000	NaN	NaN
592.999918	0.001957	19.573485	0.269375	1254.386353	0.000000	NaN	NaN
593.999975	0.001842	18.418092	0.269858	1254.864136	0.000000	NaN	NaN
595.000032	0.001817	18.170507	0.270183	1255.184937	0.000000	NaN	NaN
595.999089	0.001801	18.005451	0.270682	1255.677734	0.000000	NaN	NaN
596.999146	0.001809	18.087979	0.271119	1256.109741	0.000000	NaN	NaN
597.999204	0.001759	17.592810	0.271583	1256.569092	0.000000	NaN	NaN
598.999261	0.001784	17.840395	0.271912	1256.893311	0.000000	NaN	NaN
599.999318	0.001784	17.840395	0.272331	1257.307861	0.000000	NaN	NaN
600.999375	0.001702	17.015114	0.272660	1257.632568	0.000000	NaN	NaN
601.999432	0.001685	16.850057	0.273165	1258.132080	0.000000	NaN	NaN
602.999490	0.001726	17.262698	0.273581	1258.542969	0.000000	NaN	NaN
603.999547	0.001850	18.500620	0.273801	1258.760498	0.000000	NaN	NaN
604.999604	0.001776	17.757867	0.274174	1259.128662	0.000000	NaN	NaN
605.999661	0.001817	18.170507	0.274589	1259.539062	0.000000	NaN	NaN
606.999718	0.001735	17.345226	0.275005	1259.950073	0.000000	NaN	NaN
607.999776	0.001627	16.272360	0.275272	1260.214355	0.000000	NaN	NaN
608.999833	0.001900	18.995789	0.275917	1260.851562	0.000000	NaN	NaN
609.999890	0.001743	17.427754	0.276257	1261.187500	0.000000	NaN	NaN
610.999947	0.001702	17.015114	0.276664	1261.589966	0.000000	NaN	NaN
612.000004	0.001660	16.602473	0.277040	1261.961060	0.000000	NaN	NaN
613.000062	0.001726	17.262698	0.277331	1262.248657	0.000000	NaN	NaN
613.999119	0.001784	17.840395	0.278019	1262.928589	0.000000	NaN	NaN
614.999176	0.001842	18.418092	0.278229	1263.136230	0.000000	NaN	NaN
615.999233	0.001702	17.015114	0.278784	1263.684692	0.000000	NaN	NaN
616.999290	0.001784	17.840395	0.279001	1263.899536	0.000000	NaN	NaN
617.999347	0.001768	17.675339	0.279521	1264.412964	0.000000	NaN	NaN
618.999405	0.001751	17.510282	0.279854	1264.741699	0.000000	NaN	NaN
619.999462	0.001660	16.602473	0.280136	1265.020508	0.000000	NaN	NaN
620.999519	0.001677	16.767529	0.280522	1265.401611	0.000000	NaN	NaN
621.999576	0.001792	17.922923	0.280785	1265.661987	0.000000	NaN	NaN
622.999633	0.001751	17.510282	0.281141	1266.014038	0.000000	NaN	NaN
623.999691	0.001842	18.418092	0.281603	1266.470093	0.000000	NaN	NaN
624.999748	0.001644	16.437417	0.281934	1266.797607	0.000000	NaN	NaN
625.999805	0.001602	16.024776	0.282164	1267.025146	0.000000	NaN	NaN
626.999862	0.001660	16.602473	0.282479	1267.336426	0.000000	NaN	NaN
627.999920	0.001768	17.675339	0.282687	1267.541870	0.000000	NaN	NaN
628.999977	0.001809	18.087979	0.283169	1268.017334	0.000000	NaN	NaN
630.000034	0.001693	16.932585	0.283347	1268.193726	0.000000	NaN	NaN
630.999091	0.001586	15.859720	0.283949	1268.788574	0.000000	NaN	NaN
631.999148	0.001801	18.005451	0.284259	1269.094971	0.000000	NaN	NaN
632.999206	0.001611	16.107304	0.284490	1269.323608	0.000000	NaN	NaN
633.999263	0.001693	16.932585	0.284689	1269.520142	0.000000	NaN	NaN
634.999320	0.001677	16.767529	0.285051	1269.878052	0.000000	NaN	NaN
635.999377	0.001718	17.180170	0.285397	1270.219604	0.000000	NaN	NaN
636.999434	0.001652	16.519945	0.285573	1270.393799	0.000000	NaN	NaN
637.999491	0.001561	15.612135	0.286066	1270.880249	0.000000	NaN	NaN
638.999549	0.001602	16.024776	0.286345	1271.156738	0.000000	NaN	NaN
639.999606	0.001545	15.447079	0.286480	1271.289429	0.000000	NaN	NaN
640.999663	0.001652	16.519945	0.286629	1271.436646	0.000000	NaN	NaN
641.999720	0.001743	17.427754	0.286886	1271.690552	0.000000	NaN	NaN
642.999778	0.001660	16.602473	0.287041	1271.843994	0.000000	NaN	NaN
643.999835	0.001627	16.272360	0.287174	1271.975464	0.000000	NaN	NaN
644.999892	0.001578	15.777192	0.287289	1272.089478	0.000000	NaN	NaN
645.999949	0.001495	14.951910	0.287459	1272.257568	0.000000	NaN	NaN
647.000006	0.001685	16.850057	0.287791	1272.585693	0.000000	NaN	NaN
648.000064	0.001669	16.685001	0.287834	1272.627808	0.000000	NaN	NaN
648.999121	0.001635	16.354889	0.287920	1272.713013	0.000000	NaN	NaN
649.999178	0.001536	15.364551	0.288060	1272.850952	0.000000	NaN	NaN
650.999235	0.001652	16.519945	0.288262	1273.050781	0.000000	NaN	NaN
651.999292	0.001553	15.529607	0.288412	1273.198730	0.000000	NaN	NaN
652.999349	0.001545	15.447079	0.288389	1273.176514	0.000000	NaN	NaN
653.999407	0.001454	14.539270	0.288380	1273.167236	0.000000	NaN	NaN
654.999464	0.001561	15.612135	0.288297	1273.085449	0.000000	NaN	NaN
655.999521	0.001503	15.034438	0.287655	1272.450928	0.000000	NaN	NaN
656.999578	0.001454	14.539270	0.287498	1272.296143	0.000000	NaN	NaN
657.999635	0.001512	15.116967	0.287264	1272.064575	0.000000	NaN	NaN
658.999693	0.001421	14.209157	0.287239	1272.039795	0.000000	NaN	NaN
659.999750	0.001330	13.301348	0.287115	1271.917114	0.000000	NaN	NaN
660.999807	0.001140	11.403201	0.287044	1271.847168	0.000000	NaN	NaN
661.999864	0.001231	12.311010	0.287001	1271.804443	0.000000	NaN	NaN
662.999921	0.001215	12.145954	0.286882	1271.687256	0.000000	NaN	NaN
663.999979	0.001223	12.228482	0.286611	1271.419678	0.000000	NaN	NaN
665.000036	0.001182	11.815842	0.286406	1271.216431	0.000000	NaN	NaN
665.999093	0.001041	10.412863	0.286112	1270.925903	0.000000	NaN	NaN
666.999150	0.001025	10.247807	0.285992	1270.807373	0.000000	NaN	NaN
667.999207	0.001050	10.495392	0.285492	1270.313232	0.000000	NaN	NaN
668.999265	0.000827	8.267132	0.285199	1270.023682	0.000000	NaN	NaN
669.999322	0.000629	6.286457	0.284779	1269.609253	0.000000	NaN	NaN
670.999379	-7.284337E-5	-0.728434	0.283826	1268.667358	0.000000	NaN	NaN
671.999436	-0.000155	-1.553715	0.277096	1262.016846	0.000000	NaN	NaN
672.999493	-0.000131	-1.306131	0.275022	1259.966919	0.000000	NaN	NaN
673.999551	-4.808493E-5	-0.480849	0.273751	1258.711182	0.000000	NaN	NaN
675.002608	-0.000197	-1.966356	0.272627	1257.600586	0.000000	NaN	NaN
675.999665	-6.459055E-5	-0.645906	0.272138	1257.117187	0.000000	NaN	NaN
676.999722	-0.000246	-2.461524	0.270612	1255.609131	0.000000	NaN	NaN
677.999779	-0.000180	-1.801299	0.270023	1255.026611	0.000000	NaN	NaN