File: data/57k_1-10_2 (190315).lvm
LabVIEW Measurement
Writer_Version	2
Reader_Version	2
Separator	Tab
Decimal_Separator	.
Multi_Headings	No
X_Columns	One
Time_Pref	Absolute
Operator	user
Description	Load(N)/Stress(MPa)/Distance A(pixel)/Strain A/Distance B(pixel)/Strain B/Poisson's ratio
Date	2019/03/15
Time	14:37:29.3127093315124511719
***End_of_Header***

Notes	X 값은 오직 다음과 같을 때에만 유효함이 보장됩니다. Dev1/ai0
Channels	7
Samples	1	1	1	1	1	1	1
Date	2019/03/15	2019/03/15	2019/03/15	2019/03/15	2019/03/15	2019/03/15	2019/03/15
Time	15:04:58.8120554300347325538	15:04:58.8120554300347325538	15:04:58.8120555877685546875	15:04:58.8120555877685546875	15:04:58.8120555877685546875	15:04:58.8120555877685546875	15:04:58.8120555877685546875
Y_Unit_Label	Volts	Volts
X_Dimension	Time	Time	Time	Time	Time	Time	Time
X0	0.0000000000000000E+0	0.0000000000000000E+0	0.0000000000000000E+0	0.0000000000000000E+0	0.0000000000000000E+0	0.0000000000000000E+0	0.0000000000000000E+0
Delta_X	0.000000	0.000000	1.000000	1.000000	1.000000	1.000000	1.000000
***End_of_Header***
X_Value	Dev1/ai0	Dev1/ai0 1	Untitled	Untitled 1	Untitled 2	Untitled 3	Untitled 4	Comment
0.000000	-3.157930E-5	-0.315793	0.000134	1004.332642	0.000000	NaN	NaN
0.500029	-6.820864E-6	-0.068209	0.000106	1004.304138	0.000000	NaN	NaN
1.000057	-4.808493E-5	-0.480849	1.692772E-5	1004.215149	0.000000	NaN	NaN
1.500086	1.793757E-5	0.179376	0.000173	1004.371643	0.000000	NaN	NaN
2.000114	-2.332649E-5	-0.233265	2.026558E-6	1004.200195	0.000000	NaN	NaN
2.500143	5.920164E-5	0.592016	0.000262	1004.461548	0.000000	NaN	NaN
3.000172	-5.633774E-5	-0.563377	0.000177	1004.375854	0.000000	NaN	NaN
3.500200	2.619039E-5	0.261904	0.000398	1004.597717	0.000000	NaN	NaN
4.000229	9.684761E-6	0.096848	0.000669	1004.869568	0.000000	NaN	NaN
4.500257	-6.820864E-6	-0.068209	0.000574	1004.774048	0.000000	NaN	NaN
5.000286	1.793757E-5	0.179376	0.000959	1005.161133	0.000000	NaN	NaN
5.500315	2.619039E-5	0.261904	0.001120	1005.323364	0.000000	NaN	NaN
6.000343	-2.332649E-5	-0.233265	0.001125	1005.327942	0.000000	NaN	NaN
6.500372	5.920164E-5	0.592016	0.001337	1005.540710	0.000000	NaN	NaN
7.000400	-4.808493E-5	-0.480849	0.001199	1005.401855	0.000000	NaN	NaN
7.500429	5.920164E-5	0.592016	0.001755	1005.960144	0.000000	NaN	NaN
8.000458	1.431948E-6	0.014319	0.001880	1006.085754	0.000000	NaN	NaN
8.500486	-5.633774E-5	-0.563377	0.001923	1006.129456	0.000000	NaN	NaN
9.000515	7.570726E-5	0.757073	0.002139	1006.346130	0.000000	NaN	NaN
9.500543	5.920164E-5	0.592016	0.002263	1006.470215	0.000000	NaN	NaN
10.000572	0.000133	1.334770	0.002437	1006.645081	0.000000	NaN	NaN
10.500601	6.745445E-5	0.674545	0.002485	1006.693542	0.000000	NaN	NaN
11.000629	0.000563	5.626232	0.002753	1006.962769	0.000000	NaN	NaN
11.500658	0.000224	2.242579	0.002939	1007.150024	0.000000	NaN	NaN
12.000686	0.000241	2.407635	0.003036	1007.246521	0.000000	NaN	NaN
12.500715	0.000166	1.664882	0.003192	1007.403809	0.000000	NaN	NaN
13.000744	5.920164E-5	0.592016	0.003422	1007.634094	0.000000	NaN	NaN
13.500772	7.570726E-5	0.757073	0.003382	1007.594299	0.000000	NaN	NaN
14.000801	0.000307	3.067860	0.003554	1007.767273	0.000000	NaN	NaN
14.500829	0.000166	1.664882	0.003949	1008.163452	0.000000	NaN	NaN
15.000858	0.000199	1.994995	0.004138	1008.354004	0.000000	NaN	NaN
15.500887	0.000191	1.912466	0.004024	1008.239502	0.000000	NaN	NaN
16.000915	0.000266	2.655220	0.004108	1008.323425	0.000000	NaN	NaN
16.500944	0.000216	2.160051	0.004310	1008.525940	0.000000	NaN	NaN
17.000972	0.000166	1.664882	0.004479	1008.696106	0.000000	NaN	NaN
17.500001	0.000241	2.407635	0.004560	1008.776978	0.000000	NaN	NaN
18.000030	7.570726E-5	0.757073	0.004564	1008.781006	0.000000	NaN	NaN
18.500058	0.000257	2.572691	0.005138	1009.357666	0.000000	NaN	NaN
19.000087	0.000150	1.499826	0.005105	1009.324829	0.000000	NaN	NaN
19.500115	0.000199	1.994995	0.005138	1009.358154	0.000000	NaN	NaN
20.000144	0.000257	2.572691	0.005470	1009.691162	0.000000	NaN	NaN
20.500173	0.000191	1.912466	0.005499	1009.720337	0.000000	NaN	NaN
21.000201	0.000199	1.994995	0.005726	1009.948242	0.000000	NaN	NaN
21.500230	0.000365	3.645557	0.005597	1009.819092	0.000000	NaN	NaN
22.000258	0.000191	1.912466	0.006141	1010.364502	0.000000	NaN	NaN
22.500287	0.000389	3.893141	0.006141	1010.364502	0.000000	NaN	NaN
23.000315	0.000208	2.077523	0.853615	1861.397217	0.000000	NaN	NaN
23.500344	0.000414	4.140726	0.853850	1861.633179	0.000000	NaN	NaN
24.000373	0.000249	2.490163	0.853986	1861.769653	0.000000	NaN	NaN
24.500401	0.000299	2.985332	0.854098	1861.881958	0.000000	NaN	NaN
25.000430	0.000257	2.572691	0.854467	1862.252441	0.000000	NaN	NaN
25.500459	0.000241	2.407635	0.854646	1862.432129	0.000000	NaN	NaN
26.000487	0.000356	3.563029	0.855145	1862.933716	0.000000	NaN	NaN
26.500516	0.000257	2.572691	0.855252	1863.040771	0.000000	NaN	NaN
27.000544	0.000274	2.737748	0.855370	1863.158813	0.000000	NaN	NaN
27.500573	0.000332	3.315445	0.855599	1863.388672	0.000000	NaN	NaN
28.000601	0.000249	2.490163	0.855827	1863.617798	0.000000	NaN	NaN
28.500630	0.000422	4.223254	0.855871	1863.662476	0.000000	NaN	NaN
29.000659	0.000365	3.645557	0.855848	1863.638916	0.000000	NaN	NaN
29.500687	0.000315	3.150388	0.855962	1863.753662	0.000000	NaN	NaN
30.000716	0.000282	2.820276	0.855717	1863.507690	0.000000	NaN	NaN
30.500745	0.000381	3.810613	0.855827	1863.618164	0.000000	NaN	NaN
31.000773	0.000315	3.150388	0.855618	1863.407959	0.000000	NaN	NaN
31.500802	0.000356	3.563029	0.855854	1863.644775	0.000000	NaN	NaN
32.000830	0.000356	3.563029	0.855784	1863.575073	0.000000	NaN	NaN
32.500859	0.000348	3.480501	0.855944	1863.735962	0.000000	NaN	NaN
33.000887	0.000299	2.985332	0.855807	1863.597778	0.000000	NaN	NaN
33.500916	0.000348	3.480501	0.855843	1863.634277	0.000000	NaN	NaN
34.000945	0.000323	3.232916	0.855843	1863.634277	0.000000	NaN	NaN
34.500973	0.000422	4.223254	0.011571	1015.818054	0.000000	NaN	NaN
35.000002	0.000307	3.067860	0.011703	1015.950623	0.000000	NaN	NaN
35.500031	0.000208	2.077523	0.011710	1015.957275	0.000000	NaN	NaN
36.000059	0.000290	2.902804	0.011702	1015.949341	0.000000	NaN	NaN
36.500088	0.000266	2.655220	0.011588	1015.835083	0.000000	NaN	NaN
37.000116	0.000340	3.397973	0.011751	1015.998230	0.000000	NaN	NaN
37.500145	0.000389	3.893141	0.011683	1015.930603	0.000000	NaN	NaN
38.000174	0.000439	4.388310	0.011707	1015.954285	0.000000	NaN	NaN
38.500202	0.000274	2.737748	0.011649	1015.895996	0.000000	NaN	NaN
39.000231	0.000266	2.655220	0.011708	1015.955872	0.000000	NaN	NaN
39.500259	0.000290	2.902804	0.011491	1015.737671	0.000000	NaN	NaN
40.000288	0.000191	1.912466	0.011491	1015.737671	0.000000	NaN	NaN
40.500317	0.000307	3.067860	0.011511	1015.757263	0.000000	NaN	NaN
41.000345	0.000290	2.902804	0.011398	1015.644287	0.000000	NaN	NaN
41.500374	0.000290	2.902804	0.011825	1016.073242	0.000000	NaN	NaN
42.000402	0.000216	2.160051	0.011784	1016.031311	0.000000	NaN	NaN
42.500431	0.000381	3.810613	0.011794	1016.042114	0.000000	NaN	NaN
43.000459	0.000332	3.315445	0.011674	1015.920776	0.000000	NaN	NaN
43.500488	0.000299	2.985332	0.011937	1016.185303	0.000000	NaN	NaN
44.000517	0.000389	3.893141	0.011695	1015.941772	0.000000	NaN	NaN
44.500545	0.000233	2.325107	0.011672	1015.919250	0.000000	NaN	NaN
45.000574	0.000290	2.902804	0.011858	1016.106018	0.000000	NaN	NaN
45.500603	0.000299	2.985332	0.011732	1015.979553	0.000000	NaN	NaN
46.000631	0.000373	3.728085	0.011587	1015.833618	0.000000	NaN	NaN
46.500660	0.000299	2.985332	0.011701	1015.948792	0.000000	NaN	NaN
47.000688	0.000398	3.975670	0.011567	1015.813538	0.000000	NaN	NaN
47.500717	0.000365	3.645557	0.011679	1015.926575	0.000000	NaN	NaN
48.000746	0.000216	2.160051	0.011813	1016.060974	0.000000	NaN	NaN
48.500774	0.000241	2.407635	0.011802	1016.049866	0.000000	NaN	NaN
49.000803	0.000414	4.140726	0.011802	1016.049866	0.000000	NaN	NaN
49.500831	0.000290	2.902804	0.011717	1015.964722	0.000000	NaN	NaN
50.000860	0.000216	2.160051	0.011849	1016.096436	0.000000	NaN	NaN
50.500889	0.000257	2.572691	0.011769	1016.016846	0.000000	NaN	NaN
51.000917	0.000266	2.655220	0.011654	1015.901611	0.000000	NaN	NaN
51.500946	0.000274	2.737748	0.011780	1016.027832	0.000000	NaN	NaN
52.000974	0.000266	2.655220	0.011564	1015.810608	0.000000	NaN	NaN
52.500003	0.000315	3.150388	0.011985	1016.233582	0.000000	NaN	NaN
53.000031	0.000266	2.655220	0.011946	1016.194702	0.000000	NaN	NaN
53.500060	0.000241	2.407635	0.011821	1016.068848	0.000000	NaN	NaN
54.000089	0.000422	4.223254	0.011574	1015.820557	0.000000	NaN	NaN
54.500117	0.000249	2.490163	0.011781	1016.028748	0.000000	NaN	NaN
55.000146	0.000332	3.315445	0.011781	1016.028748	0.000000	NaN	NaN
55.500174	0.000241	2.407635	0.012051	1016.300049	0.000000	NaN	NaN
56.000203	0.000299	2.985332	0.012139	1016.387817	0.000000	NaN	NaN
56.500232	0.000299	2.985332	0.011929	1016.177490	0.000000	NaN	NaN
57.000260	0.000513	5.131063	0.011958	1016.206177	0.000000	NaN	NaN
57.500289	0.000233	2.325107	0.011940	1016.188599	0.000000	NaN	NaN
58.000317	0.000332	3.315445	0.012036	1016.284302	0.000000	NaN	NaN
58.500346	0.000389	3.893141	0.012068	1016.316895	0.000000	NaN	NaN
59.000375	0.000224	2.242579	0.011907	1016.155640	0.000000	NaN	NaN
59.500403	0.000340	3.397973	0.012010	1016.258118	0.000000	NaN	NaN
60.000432	0.000249	2.490163	0.011792	1016.040161	0.000000	NaN	NaN
60.500460	0.000373	3.728085	0.011974	1016.222412	0.000000	NaN	NaN
61.000489	0.000290	2.902804	0.012008	1016.256958	0.000000	NaN	NaN
61.500518	0.000365	3.645557	0.011902	1016.150635	0.000000	NaN	NaN
62.000546	0.000315	3.150388	0.012040	1016.289001	0.000000	NaN	NaN
62.500575	0.000216	2.160051	0.011772	1016.019653	0.000000	NaN	NaN
63.000603	0.000233	2.325107	0.011719	1015.966064	0.000000	NaN	NaN
63.500632	0.000282	2.820276	0.011642	1015.889404	0.000000	NaN	NaN
64.000661	0.000290	2.902804	0.011725	1015.972717	0.000000	NaN	NaN
64.500689	0.000257	2.572691	0.012049	1016.297607	0.000000	NaN	NaN
65.000718	0.000389	3.893141	0.011993	1016.241455	0.000000	NaN	NaN
65.500746	0.000290	2.902804	0.012170	1016.419617	0.000000	NaN	NaN
66.000775	0.000241	2.407635	0.011957	1016.205811	0.000000	NaN	NaN
66.500804	0.000224	2.242579	0.011922	1016.169800	0.000000	NaN	NaN
67.000832	0.000199	1.994995	0.011984	1016.232849	0.000000	NaN	NaN
67.500861	0.000290	2.902804	0.012103	1016.352356	0.000000	NaN	NaN
68.000889	0.000299	2.985332	0.011730	1015.977783	0.000000	NaN	NaN
68.500918	0.000381	3.810613	0.011954	1016.202515	0.000000	NaN	NaN
69.000947	0.000307	3.067860	0.011973	1016.221680	0.000000	NaN	NaN
69.500975	0.000257	2.572691	0.012224	1016.473267	0.000000	NaN	NaN
70.000004	0.000332	3.315445	0.012493	1016.743713	0.000000	NaN	NaN
70.500032	0.000439	4.388310	0.012579	1016.830444	0.000000	NaN	NaN
71.000061	0.000224	2.242579	0.012682	1016.933472	0.000000	NaN	NaN
71.500090	0.000315	3.150388	0.012797	1017.048462	0.000000	NaN	NaN
72.000118	0.000431	4.305782	0.013176	1017.429626	0.000000	NaN	NaN
72.500147	0.000323	3.232916	0.013256	1017.509399	0.000000	NaN	NaN
73.000175	0.000406	4.058198	0.013300	1017.553772	0.000000	NaN	NaN
73.500204	0.000282	2.820276	0.013481	1017.736328	0.000000	NaN	NaN
74.000232	0.000497	4.966007	0.013427	1017.681335	0.000000	NaN	NaN
74.500261	0.000398	3.975670	0.013802	1018.058228	0.000000	NaN	NaN
75.000290	0.000447	4.470838	0.013724	1017.980286	0.000000	NaN	NaN
75.500318	0.000422	4.223254	0.014004	1018.261475	0.000000	NaN	NaN
76.000347	0.000447	4.470838	0.014284	1018.542358	0.000000	NaN	NaN
76.500376	0.000348	3.480501	0.014578	1018.837646	0.000000	NaN	NaN
77.000404	0.000389	3.893141	0.014463	1018.721741	0.000000	NaN	NaN
77.500433	0.000546	5.461176	0.014552	1018.811157	0.000000	NaN	NaN
78.000461	0.000348	3.480501	0.014909	1019.169556	0.000000	NaN	NaN
78.500490	0.000414	4.140726	0.014909	1019.169556	0.000000	NaN	NaN
79.000518	0.000455	4.553366	0.014929	1019.189819	0.000000	NaN	NaN
79.500547	0.000554	5.543704	0.015150	1019.411377	0.000000	NaN	NaN
80.000576	0.000431	4.305782	0.015726	1019.990540	0.000000	NaN	NaN
80.500604	0.000488	4.883479	0.015840	1020.104492	0.000000	NaN	NaN
81.000633	0.000587	5.873817	0.016038	1020.303040	0.000000	NaN	NaN
81.500662	0.000538	5.378648	0.016097	1020.362305	0.000000	NaN	NaN
82.000690	0.000497	4.966007	0.016097	1020.362305	0.000000	NaN	NaN
82.500719	0.000538	5.378648	0.016122	1020.387390	0.000000	NaN	NaN
83.000747	0.000455	4.553366	0.016774	1021.042236	0.000000	NaN	NaN
83.500776	0.000472	4.718423	0.016531	1020.799011	0.000000	NaN	NaN
84.000805	0.000579	5.791288	0.016947	1021.216187	0.000000	NaN	NaN
84.500833	0.000554	5.543704	0.017065	1021.334473	0.000000	NaN	NaN
85.000862	0.000513	5.131063	0.017268	1021.539124	0.000000	NaN	NaN
85.500890	0.000546	5.461176	0.017272	1021.542603	0.000000	NaN	NaN
86.000919	0.000653	6.534042	0.017423	1021.694275	0.000000	NaN	NaN
86.500948	0.000546	5.461176	0.017423	1021.694275	0.000000	NaN	NaN
87.000976	0.000538	5.378648	0.018067	1022.341248	0.000000	NaN	NaN
87.500005	0.000521	5.213591	0.018102	1022.376160	0.000000	NaN	NaN
88.000033	0.000563	5.626232	0.018478	1022.753845	0.000000	NaN	NaN
88.500062	0.000513	5.131063	0.018497	1022.772339	0.000000	NaN	NaN
89.000090	0.000538	5.378648	0.018865	1023.142273	0.000000	NaN	NaN
89.500119	0.000530	5.296120	0.019041	1023.318665	0.000000	NaN	NaN
90.000148	0.000604	6.038873	0.018890	1023.167480	0.000000	NaN	NaN
90.500176	0.000488	4.883479	0.019298	1023.577087	0.000000	NaN	NaN
91.000205	0.000596	5.956345	0.019399	1023.678894	0.000000	NaN	NaN
91.500234	0.000596	5.956345	0.019582	1023.862244	0.000000	NaN	NaN
92.000262	0.000604	6.038873	0.019952	1024.233521	0.000000	NaN	NaN
92.500291	0.000653	6.534042	0.019932	1024.213379	0.000000	NaN	NaN
93.000319	0.000538	5.378648	0.020495	1024.779175	0.000000	NaN	NaN
93.500348	0.000571	5.708760	0.020296	1024.578857	0.000000	NaN	NaN
94.000377	0.000579	5.791288	0.020279	1024.562500	0.000000	NaN	NaN
94.500405	0.000653	6.534042	0.020939	1025.225098	0.000000	NaN	NaN
95.000434	0.000414	4.140726	0.020948	1025.234497	0.000000	NaN	NaN
95.500462	0.000736	7.359323	0.020957	1025.242920	0.000000	NaN	NaN
96.000491	0.000637	6.368985	0.021051	1025.337646	0.000000	NaN	NaN
96.500520	0.000587	5.873817	0.021051	1025.337646	0.000000	NaN	NaN
97.000548	0.000629	6.286457	0.021051	1025.337646	0.000000	NaN	NaN
97.500577	0.000530	5.296120	0.021117	1025.404053	0.000000	NaN	NaN
98.000605	0.000629	6.286457	0.021473	1025.760864	0.000000	NaN	NaN
98.506634	0.000579	5.791288	0.021301	1025.588745	0.000000	NaN	NaN
99.000663	0.000579	5.791288	0.021840	1026.130371	0.000000	NaN	NaN
99.500691	0.000670	6.699098	0.021855	1026.144897	0.000000	NaN	NaN
100.000720	0.000629	6.286457	0.022215	1026.506348	0.000000	NaN	NaN
100.500748	0.000744	7.441851	0.022364	1026.656006	0.000000	NaN	NaN
101.000777	0.000612	6.121401	0.022363	1026.655029	0.000000	NaN	NaN
101.500806	0.000521	5.213591	0.022433	1026.725586	0.000000	NaN	NaN
102.000834	0.000604	6.038873	0.022774	1027.068115	0.000000	NaN	NaN
102.500863	0.000653	6.534042	0.023038	1027.333008	0.000000	NaN	NaN
103.000891	0.000596	5.956345	0.023061	1027.356201	0.000000	NaN	NaN
103.500920	0.000728	7.276795	0.023356	1027.652710	0.000000	NaN	NaN
104.000948	0.000711	7.111738	0.023594	1027.891602	0.000000	NaN	NaN
104.500977	0.000645	6.451513	0.023801	1028.099243	0.000000	NaN	NaN
105.000006	0.000579	5.791288	0.023948	1028.246582	0.000000	NaN	NaN
105.500034	0.000637	6.368985	0.024145	1028.444458	0.000000	NaN	NaN
106.000063	0.000662	6.616570	0.024251	1028.550903	0.000000	NaN	NaN
106.500091	0.000521	5.213591	0.024558	1028.859253	0.000000	NaN	NaN
107.000120	0.000761	7.606907	0.024762	1029.063721	0.000000	NaN	NaN
107.500149	0.000629	6.286457	0.024903	1029.205322	0.000000	NaN	NaN
108.000177	0.000736	7.359323	0.025184	1029.488281	0.000000	NaN	NaN
108.500206	0.000637	6.368985	0.025441	1029.746216	0.000000	NaN	NaN
109.000234	0.000670	6.699098	0.025630	1029.935547	0.000000	NaN	NaN
109.500263	0.000645	6.451513	0.025844	1030.150146	0.000000	NaN	NaN
110.000292	0.000587	5.873817	0.026076	1030.383789	0.000000	NaN	NaN
110.500320	0.000719	7.194267	0.026371	1030.679443	0.000000	NaN	NaN
111.000349	0.000711	7.111738	0.026263	1030.571533	0.000000	NaN	NaN
111.500377	0.000596	5.956345	0.026690	1031.000610	0.000000	NaN	NaN
112.000406	0.000596	5.956345	0.026805	1031.115234	0.000000	NaN	NaN
112.500435	0.000637	6.368985	0.026910	1031.221436	0.000000	NaN	NaN
113.000463	0.000554	5.543704	0.027231	1031.543213	0.000000	NaN	NaN
113.500492	0.000761	7.606907	0.027528	1031.841553	0.000000	NaN	NaN
114.000520	0.000546	5.461176	0.027528	1031.841553	0.000000	NaN	NaN
114.500549	0.000662	6.616570	0.028493	1032.811157	0.000000	NaN	NaN
115.000578	0.000719	7.194267	0.028738	1033.057373	0.000000	NaN	NaN
115.500606	0.000777	7.771963	0.029224	1033.545044	0.000000	NaN	NaN
116.000635	0.000571	5.708760	0.029136	1033.456909	0.000000	NaN	NaN
116.500663	0.000802	8.019548	0.029380	1033.701782	0.000000	NaN	NaN
117.000692	0.000876	8.762301	0.029578	1033.900635	0.000000	NaN	NaN
117.500721	0.000604	6.038873	0.029936	1034.259399	0.000000	NaN	NaN
118.000749	0.000563	5.626232	0.029897	1034.220337	0.000000	NaN	NaN
118.500778	0.000744	7.441851	0.030237	1034.562378	0.000000	NaN	NaN
119.000806	0.000728	7.276795	0.030597	1034.923950	0.000000	NaN	NaN
119.500835	0.000711	7.111738	0.030589	1034.915527	0.000000	NaN	NaN
120.000864	0.000695	6.946682	0.030790	1035.117920	0.000000	NaN	NaN
120.500892	0.000728	7.276795	0.031103	1035.431641	0.000000	NaN	NaN
121.000921	0.000678	6.781626	0.031362	1035.692261	0.000000	NaN	NaN
121.500949	0.000785	7.854492	0.031484	1035.813965	0.000000	NaN	NaN
122.000978	0.000703	7.029210	0.031698	1036.029297	0.000000	NaN	NaN
122.500007	0.000579	5.791288	0.031752	1036.083374	0.000000	NaN	NaN
123.000035	0.000645	6.451513	0.032247	1036.580200	0.000000	NaN	NaN
123.500064	0.000604	6.038873	0.032582	1036.917358	0.000000	NaN	NaN
124.000092	0.000653	6.534042	0.032562	1036.897339	0.000000	NaN	NaN
124.500121	0.000620	6.203929	0.032714	1037.049561	0.000000	NaN	NaN
125.000150	0.000653	6.534042	0.033085	1037.422363	0.000000	NaN	NaN
125.500178	0.000653	6.534042	0.033184	1037.521362	0.000000	NaN	NaN
126.000207	0.000686	6.864154	0.033377	1037.715698	0.000000	NaN	NaN
126.500235	0.000629	6.286457	0.033593	1037.931763	0.000000	NaN	NaN
127.000264	0.000711	7.111738	0.033873	1038.213745	0.000000	NaN	NaN
127.500293	0.000587	5.873817	0.034061	1038.402588	0.000000	NaN	NaN
128.000321	0.000538	5.378648	0.034300	1038.641846	0.000000	NaN	NaN
128.500350	0.000728	7.276795	0.034406	1038.748779	0.000000	NaN	NaN
129.000378	0.000645	6.451513	0.034711	1039.054932	0.000000	NaN	NaN
129.500407	0.000629	6.286457	0.034963	1039.308472	0.000000	NaN	NaN
130.000436	0.000686	6.864154	0.035226	1039.572144	0.000000	NaN	NaN
130.500464	0.000620	6.203929	0.035419	1039.765991	0.000000	NaN	NaN
131.000493	0.000761	7.606907	0.035605	1039.952393	0.000000	NaN	NaN
131.500521	0.000785	7.854492	0.035650	1039.998291	0.000000	NaN	NaN
132.000550	0.000653	6.534042	0.035988	1040.337280	0.000000	NaN	NaN
132.500579	0.000653	6.534042	0.036078	1040.427490	0.000000	NaN	NaN
133.000607	0.000695	6.946682	0.036297	1040.647583	0.000000	NaN	NaN
133.500636	0.000686	6.864154	0.036801	1041.153564	0.000000	NaN	NaN
134.000664	0.000901	9.009885	0.036715	1041.067261	0.000000	NaN	NaN
134.500693	0.000711	7.111738	0.037140	1041.493652	0.000000	NaN	NaN
135.000722	0.000719	7.194267	0.037268	1041.622192	0.000000	NaN	NaN
135.500750	0.000620	6.203929	0.037473	1041.828857	0.000000	NaN	NaN
136.000779	0.000670	6.699098	0.037848	1042.205078	0.000000	NaN	NaN
136.500807	0.000670	6.699098	0.037932	1042.289795	0.000000	NaN	NaN
137.000836	0.000868	8.679773	0.038123	1042.481689	0.000000	NaN	NaN
137.500865	0.000662	6.616570	0.038332	1042.690918	0.000000	NaN	NaN
138.001893	0.000563	5.626232	0.038725	1043.085571	0.000000	NaN	NaN
138.500922	0.000563	5.626232	0.038844	1043.205444	0.000000	NaN	NaN
139.000950	0.000769	7.689435	0.038844	1043.205444	0.000000	NaN	NaN
139.500979	0.000926	9.257470	0.039290	1043.653320	0.000000	NaN	NaN
140.000008	0.000744	7.441851	0.039545	1043.908936	0.000000	NaN	NaN
140.500036	0.000777	7.771963	0.039614	1043.978394	0.000000	NaN	NaN
141.000065	0.000827	8.267132	0.039872	1044.237915	0.000000	NaN	NaN
141.500093	0.000835	8.349660	0.040202	1044.569092	0.000000	NaN	NaN
142.000122	0.000554	5.543704	0.040399	1044.766602	0.000000	NaN	NaN
142.500151	0.000686	6.864154	0.040669	1045.037720	0.000000	NaN	NaN
143.000179	0.000612	6.121401	0.040874	1045.243408	0.000000	NaN	NaN
143.500208	0.000637	6.368985	0.041028	1045.398437	0.000000	NaN	NaN
144.000236	0.000678	6.781626	0.041252	1045.623779	0.000000	NaN	NaN
144.500265	0.000818	8.184604	0.041614	1045.986816	0.000000	NaN	NaN
145.000293	0.000728	7.276795	0.041699	1046.072021	0.000000	NaN	NaN
145.500322	0.000711	7.111738	0.041991	1046.365967	0.000000	NaN	NaN
146.000351	0.000686	6.864154	0.042229	1046.604248	0.000000	NaN	NaN
146.500379	0.000670	6.699098	0.042574	1046.950928	0.000000	NaN	NaN
147.000408	0.000678	6.781626	0.042651	1047.028320	0.000000	NaN	NaN
147.500437	0.000703	7.029210	0.042922	1047.300049	0.000000	NaN	NaN
148.000465	0.000686	6.864154	0.043196	1047.575317	0.000000	NaN	NaN
148.500494	0.000719	7.194267	0.043628	1048.008911	0.000000	NaN	NaN
149.000522	0.000678	6.781626	0.043684	1048.065918	0.000000	NaN	NaN
149.500551	0.000711	7.111738	0.043865	1048.247437	0.000000	NaN	NaN
150.000579	0.000662	6.616570	0.044153	1048.536133	0.000000	NaN	NaN
150.500608	0.000785	7.854492	0.044325	1048.709595	0.000000	NaN	NaN
151.000637	0.000901	9.009885	0.044556	1048.941528	0.000000	NaN	NaN
151.500665	0.000678	6.781626	0.044902	1049.288940	0.000000	NaN	NaN
152.000694	0.000752	7.524379	0.045089	1049.476929	0.000000	NaN	NaN
152.500723	0.000719	7.194267	0.045397	1049.785400	0.000000	NaN	NaN
153.000751	0.000686	6.864154	0.045515	1049.904175	0.000000	NaN	NaN
153.500780	0.000761	7.606907	0.045824	1050.214233	0.000000	NaN	NaN
154.000808	0.000843	8.432188	0.046208	1050.600586	0.000000	NaN	NaN
154.500837	0.000695	6.946682	0.046381	1050.774170	0.000000	NaN	NaN
155.000866	0.000744	7.441851	0.046747	1051.141602	0.000000	NaN	NaN
155.500894	0.000777	7.771963	0.046982	1051.377686	0.000000	NaN	NaN
156.000923	0.000769	7.689435	0.047028	1051.423462	0.000000	NaN	NaN
156.500951	0.000563	5.626232	0.047398	1051.795166	0.000000	NaN	NaN
157.000980	0.000728	7.276795	0.047542	1051.940186	0.000000	NaN	NaN
157.500009	0.000785	7.854492	0.047905	1052.304077	0.000000	NaN	NaN
158.000037	0.000719	7.194267	0.047960	1052.359741	0.000000	NaN	NaN
158.500066	0.000719	7.194267	0.048262	1052.663208	0.000000	NaN	NaN
159.000094	0.000604	6.038873	0.048488	1052.889404	0.000000	NaN	NaN
159.500123	0.000794	7.937020	0.048565	1052.966675	0.000000	NaN	NaN
160.000151	0.000728	7.276795	0.048994	1053.398193	0.000000	NaN	NaN
160.500180	0.000818	8.184604	0.049123	1053.527832	0.000000	NaN	NaN
161.000209	0.000711	7.111738	0.049465	1053.871094	0.000000	NaN	NaN
161.500237	0.000645	6.451513	0.049548	1053.954468	0.000000	NaN	NaN
162.000266	0.000810	8.102076	0.049697	1054.103882	0.000000	NaN	NaN
162.500295	0.000695	6.946682	0.050290	1054.699219	0.000000	NaN	NaN
163.000323	0.000752	7.524379	0.050684	1055.094849	0.000000	NaN	NaN
163.500352	0.000662	6.616570	0.050632	1055.043213	0.000000	NaN	NaN
164.000380	0.000959	9.587582	0.050800	1055.211792	0.000000	NaN	NaN
164.500409	0.000662	6.616570	0.051204	1055.617432	0.000000	NaN	NaN
165.000438	0.000744	7.441851	0.051403	1055.816772	0.000000	NaN	NaN
165.500466	0.000752	7.524379	0.051573	1055.987305	0.000000	NaN	NaN
166.000495	0.000653	6.534042	0.051984	1056.400269	0.000000	NaN	NaN
166.500523	0.000827	8.267132	0.052159	1056.576416	0.000000	NaN	NaN
167.000552	0.000752	7.524379	0.052525	1056.943848	0.000000	NaN	NaN
167.500581	0.000645	6.451513	0.052684	1057.103516	0.000000	NaN	NaN
168.000609	0.000794	7.937020	0.052966	1057.386597	0.000000	NaN	NaN
168.500638	0.000868	8.679773	0.052966	1057.386597	0.000000	NaN	NaN
169.000666	0.000662	6.616570	0.053610	1058.033081	0.000000	NaN	NaN
169.500695	0.000785	7.854492	0.053776	1058.199707	0.000000	NaN	NaN
170.000723	0.000744	7.441851	0.054030	1058.454956	0.000000	NaN	NaN
170.500752	0.000752	7.524379	0.054268	1058.694092	0.000000	NaN	NaN
171.000781	0.000761	7.606907	0.054612	1059.039185	0.000000	NaN	NaN
171.500809	0.000728	7.276795	0.055147	1059.576538	0.000000	NaN	NaN
172.000838	0.000711	7.111738	0.055163	1059.592896	0.000000	NaN	NaN
172.500867	0.000769	7.689435	0.055657	1060.088867	0.000000	NaN	NaN
173.000895	0.000827	8.267132	0.055757	1060.189209	0.000000	NaN	NaN
173.500924	0.000744	7.441851	0.056040	1060.473511	0.000000	NaN	NaN
174.000952	0.000761	7.606907	0.056257	1060.691528	0.000000	NaN	NaN
174.500981	0.000744	7.441851	0.056565	1061.000732	0.000000	NaN	NaN
175.000009	0.000703	7.029210	0.056725	1061.161133	0.000000	NaN	NaN
175.500038	0.000744	7.441851	0.056887	1061.323608	0.000000	NaN	NaN
176.000067	0.000769	7.689435	0.057378	1061.817139	0.000000	NaN	NaN
176.500095	0.000563	5.626232	0.057458	1061.897583	0.000000	NaN	NaN
177.000124	0.000629	6.286457	0.057756	1062.196411	0.000000	NaN	NaN
177.500152	0.000703	7.029210	0.058007	1062.448486	0.000000	NaN	NaN
178.000181	0.000810	8.102076	0.058289	1062.731689	0.000000	NaN	NaN
178.500210	0.000736	7.359323	0.058509	1062.953003	0.000000	NaN	NaN
179.000238	0.000752	7.524379	0.058777	1063.222290	0.000000	NaN	NaN
179.500267	0.000761	7.606907	0.059035	1063.481445	0.000000	NaN	NaN
180.000295	0.000777	7.771963	0.059300	1063.747559	0.000000	NaN	NaN
180.500324	0.000860	8.597245	0.059636	1064.084229	0.000000	NaN	NaN
181.000353	0.000761	7.606907	0.059828	1064.277710	0.000000	NaN	NaN
181.500381	0.000686	6.864154	0.060027	1064.477295	0.000000	NaN	NaN
182.000410	0.000703	7.029210	0.060228	1064.678955	0.000000	NaN	NaN
182.500438	0.000835	8.349660	0.060622	1065.074585	0.000000	NaN	NaN
183.000467	0.000818	8.184604	0.060782	1065.235474	0.000000	NaN	NaN
183.500496	0.000719	7.194267	0.061118	1065.572632	0.000000	NaN	NaN
184.000524	0.000695	6.946682	0.061229	1065.684082	0.000000	NaN	NaN
184.500553	0.000736	7.359323	0.061549	1066.005737	0.000000	NaN	NaN
185.000581	0.000827	8.267132	0.061614	1066.071167	0.000000	NaN	NaN
185.500610	0.000752	7.524379	0.062049	1066.507935	0.000000	NaN	NaN
186.000639	0.000744	7.441851	0.062160	1066.618774	0.000000	NaN	NaN
186.500667	0.000728	7.276795	0.062504	1066.964844	0.000000	NaN	NaN
187.000696	0.000736	7.359323	0.062668	1067.129028	0.000000	NaN	NaN
187.500724	0.000785	7.854492	0.062953	1067.415405	0.000000	NaN	NaN
188.000753	0.000711	7.111738	0.063284	1067.747437	0.000000	NaN	NaN
188.500782	0.000802	8.019548	0.063397	1067.861328	0.000000	NaN	NaN
189.000810	0.000769	7.689435	0.063888	1068.354614	0.000000	NaN	NaN
189.500839	0.000728	7.276795	0.064078	1068.545044	0.000000	NaN	NaN
190.000867	0.000728	7.276795	0.064179	1068.646240	0.000000	NaN	NaN
190.500896	0.000835	8.349660	0.064378	1068.846069	0.000000	NaN	NaN
191.000925	0.000752	7.524379	0.064773	1069.243530	0.000000	NaN	NaN
191.500953	0.000662	6.616570	0.064951	1069.421631	0.000000	NaN	NaN
192.000982	0.000736	7.359323	0.065128	1069.599365	0.000000	NaN	NaN
192.500010	0.000695	6.946682	0.065472	1069.944946	0.000000	NaN	NaN
193.000039	0.000662	6.616570	0.065683	1070.157349	0.000000	NaN	NaN
193.500068	0.000686	6.864154	0.065999	1070.473755	0.000000	NaN	NaN
194.000096	0.000761	7.606907	0.066311	1070.788086	0.000000	NaN	NaN
194.500125	0.000860	8.597245	0.066474	1070.951050	0.000000	NaN	NaN
195.000153	0.000711	7.111738	0.066795	1071.273560	0.000000	NaN	NaN
195.500182	0.000893	8.927357	0.066925	1071.403687	0.000000	NaN	NaN
196.000211	0.000769	7.689435	0.067223	1071.703369	0.000000	NaN	NaN
196.500239	0.000769	7.689435	0.067380	1071.860718	0.000000	NaN	NaN
197.000268	0.000868	8.679773	0.067673	1072.155762	0.000000	NaN	NaN
197.500296	0.000736	7.359323	0.068004	1072.488159	0.000000	NaN	NaN
198.000325	0.000761	7.606907	0.068288	1072.772827	0.000000	NaN	NaN
198.500354	0.000711	7.111738	0.068480	1072.965454	0.000000	NaN	NaN
199.000382	0.000719	7.194267	0.068713	1073.200073	0.000000	NaN	NaN
199.500411	0.000662	6.616570	0.068899	1073.386475	0.000000	NaN	NaN
200.000439	0.000777	7.771963	0.068899	1073.386475	0.000000	NaN	NaN
200.500468	0.000843	8.432188	0.070291	1074.784424	0.000000	NaN	NaN
201.000496	0.000785	7.854492	0.070505	1074.999390	0.000000	NaN	NaN
201.500525	0.000711	7.111738	0.070818	1075.313232	0.000000	NaN	NaN
202.000554	0.000744	7.441851	0.071098	1075.594727	0.000000	NaN	NaN
202.500582	0.000777	7.771963	0.071207	1075.704102	0.000000	NaN	NaN
203.000611	0.000761	7.606907	0.071591	1076.090088	0.000000	NaN	NaN
203.500640	0.000810	8.102076	0.071739	1076.238525	0.000000	NaN	NaN
204.000668	0.000785	7.854492	0.072109	1076.609863	0.000000	NaN	NaN
204.500697	0.000744	7.441851	0.072386	1076.887817	0.000000	NaN	NaN
205.000725	0.000761	7.606907	0.072621	1077.124023	0.000000	NaN	NaN
205.500754	0.000744	7.441851	0.072760	1077.263428	0.000000	NaN	NaN
206.000782	0.000835	8.349660	0.073134	1077.639038	0.000000	NaN	NaN
206.500811	0.000719	7.194267	0.073276	1077.781860	0.000000	NaN	NaN
207.000840	0.000728	7.276795	0.073516	1078.022461	0.000000	NaN	NaN
207.500868	0.000835	8.349660	0.074054	1078.562866	0.000000	NaN	NaN
208.000897	0.000827	8.267132	0.074150	1078.659180	0.000000	NaN	NaN
208.500926	0.000794	7.937020	0.074417	1078.927734	0.000000	NaN	NaN
209.000954	0.000736	7.359323	0.074661	1079.172363	0.000000	NaN	NaN
209.500983	0.000620	6.203929	0.074939	1079.451294	0.000000	NaN	NaN
210.000011	0.000777	7.771963	0.075219	1079.732788	0.000000	NaN	NaN
210.500040	0.000653	6.534042	0.075217	1079.731445	0.000000	NaN	NaN
211.000068	0.000653	6.534042	0.075598	1080.113037	0.000000	NaN	NaN
211.500097	0.000728	7.276795	0.075880	1080.396362	0.000000	NaN	NaN
212.000126	0.000769	7.689435	0.076071	1080.588867	0.000000	NaN	NaN
212.500154	0.000736	7.359323	0.076624	1081.143799	0.000000	NaN	NaN
213.000183	0.000653	6.534042	0.077258	1081.780518	0.000000	NaN	NaN
213.500212	0.000744	7.441851	0.078026	1082.551636	0.000000	NaN	NaN
214.000240	0.000431	4.305782	0.079714	1084.247070	0.000000	NaN	NaN
214.500269	5.920164E-5	0.592016	0.086597	1091.159180	0.000000	NaN	NaN
215.000297	-0.000122	-1.223602	0.101827	1106.452881	0.000000	NaN	NaN
215.500326	-0.000320	-3.204278	0.122249	1126.959961	0.000000	NaN	NaN
216.000354	-9.760180E-5	-0.976018	-0.229911	773.322327	0.000000	NaN	NaN
216.500383	-0.000197	-1.966356	-0.227464	775.779175	0.000000	NaN	NaN
217.000412	-7.284337E-5	-0.728434	-0.226555	776.691895	0.000000	NaN	NaN
217.500440	-0.000139	-1.388659	-0.224951	778.302551	0.000000	NaN	NaN
218.000469	-0.000139	-1.388659	-0.223384	779.876587	0.000000	NaN	NaN
218.500498	-4.808493E-5	-0.480849	-0.222758	780.504700	0.000000	NaN	NaN
219.000526	-0.000131	-1.306131	-0.221752	781.515076	0.000000	NaN	NaN
219.500555	-6.459055E-5	-0.645906	-0.221123	782.146667	0.000000	NaN	NaN
220.000583	-4.808493E-5	-0.480849	-0.219864	783.411621	0.000000	NaN	NaN
220.500612	-0.000147	-1.471187	-0.219091	784.187866	0.000000	NaN	NaN
221.000641	-0.000213	-2.131412	-0.218137	785.145447	0.000000	NaN	NaN
221.500669	-5.633774E-5	-0.563377	-0.217405	785.880249	0.000000	NaN	NaN
222.000698	-0.000263	-2.626581	-0.216794	786.493530	0.000000	NaN	NaN
222.500726	-0.000287	-2.874165	-0.216435	786.854126	0.000000	NaN	NaN
223.000755	-9.760180E-5	-0.976018	-0.215717	787.576050	0.000000	NaN	NaN
223.500784	-0.000221	-2.213940	-0.214999	788.296448	0.000000	NaN	NaN
224.000812	-7.284337E-5	-0.728434	-0.214440	788.857483	0.000000	NaN	NaN
224.500841	-0.000139	-1.388659	-0.214142	789.157227	0.000000	NaN	NaN
225.000869	-0.000164	-1.636243	-0.213391	789.911194	0.000000	NaN	NaN
225.500898	-8.934899E-5	-0.893490	-0.212475	790.830933	0.000000	NaN	NaN
226.000926	-0.000147	-1.471187	-0.212003	791.305542	0.000000	NaN	NaN
226.500955	-8.109618E-5	-0.810962	-0.211534	791.775757	0.000000	NaN	NaN
227.000984	-0.000155	-1.553715	-0.210893	792.420227	0.000000	NaN	NaN
227.500012	-8.934899E-5	-0.893490	-0.210332	792.983215	0.000000	NaN	NaN
228.000041	-0.000180	-1.801299	-0.209333	793.986755	0.000000	NaN	NaN
228.500069	-9.760180E-5	-0.976018	-0.208882	794.439575	0.000000	NaN	NaN
229.000098	-0.000221	-2.213940	-0.208616	794.706360	0.000000	NaN	NaN
229.500127	-0.000180	-1.801299	-0.208021	795.304321	0.000000	NaN	NaN
230.000155	-0.000213	-2.131412	-0.207342	795.985474	0.000000	NaN	NaN
230.500184	-0.000205	-2.048884	-0.207095	796.233398	0.000000	NaN	NaN
231.000212	-0.000188	-1.883827	-0.206681	796.649597	0.000000	NaN	NaN
231.500241	-4.808493E-5	-0.480849	-0.206253	797.079651	0.000000	NaN	NaN
232.000270	-0.000320	-3.204278	-0.205757	797.577576	0.000000	NaN	NaN
232.500298	-0.000147	-1.471187	0.100845	1105.466919	0.000000	NaN	NaN
233.000327	-0.000155	-1.553715	0.101063	1105.685181	0.000000	NaN	NaN
233.500355	-0.000221	-2.213940	0.101514	1106.138428	0.000000	NaN	NaN
234.000384	-7.284337E-5	-0.728434	0.102036	1106.662842	0.000000	NaN	NaN
234.500413	-0.000139	-1.388659	0.102815	1107.444458	0.000000	NaN	NaN
235.000441	-8.934899E-5	-0.893490	0.103063	1107.694214	0.000000	NaN	NaN
235.500470	-0.000172	-1.718771	-0.201956	801.394531	0.000000	NaN	NaN
236.000498	-0.000106	-1.058546	0.103672	1108.305542	0.000000	NaN	NaN
236.500527	-0.000213	-2.131412	-0.201166	802.187805	0.000000	NaN	NaN
237.000556	-0.000205	-2.048884	-0.200570	802.785706	0.000000	NaN	NaN
237.500584	-9.760180E-5	-0.976018	-0.200309	803.048645	0.000000	NaN	NaN
238.000613	-0.000106	-1.058546	-0.199975	803.383545	0.000000	NaN	NaN
238.500641	-0.000246	-2.461524	0.106174	1110.817627	0.000000	NaN	NaN
239.000670	-0.000131	-1.306131	0.107055	1111.702393	0.000000	NaN	NaN
239.500699	-0.000197	-1.966356	0.107110	1111.758179	0.000000	NaN	NaN
240.000727	-0.000155	-1.553715	0.107449	1112.098145	0.000000	NaN	NaN
240.500756	-0.000122	-1.223602	0.108434	1113.087891	0.000000	NaN	NaN
241.000784	-0.000131	-1.306131	-0.197199	806.171265	0.000000	NaN	NaN
241.500813	-0.000147	-1.471187	0.200683	1205.723877	0.000000	NaN	NaN
242.000842	-0.000188	-1.883827	0.109393	1114.050171	0.000000	NaN	NaN
242.500870	-0.000246	-2.461524	0.110395	1115.056519	0.000000	NaN	NaN
243.000899	-0.000139	-1.388659	0.110755	1115.418213	0.000000	NaN	NaN