File: data/57k_15-1_1 (190315).lvm
LabVIEW Measurement
Writer_Version	2
Reader_Version	2
Separator	Tab
Decimal_Separator	.
Multi_Headings	No
X_Columns	One
Time_Pref	Absolute
Operator	user
Description	Load(N)/Stress(MPa)/Distance A(pixel)/Strain A/Distance B(pixel)/Strain B/Poisson's ratio
Date	2019/03/15
Time	14:37:29.3127093315124511719
***End_of_Header***

Notes	X 값은 오직 다음과 같을 때에만 유효함이 보장됩니다. Dev1/ai0
Channels	7
Samples	1	1	1	1	1	1	1
Date	2019/03/15	2019/03/15	2019/03/15	2019/03/15	2019/03/15	2019/03/15	2019/03/15
Time	16:54:31.8130095300347320598	16:54:31.8130095300347320598	16:54:31.8130092620849609375	16:54:31.8130092620849609375	16:54:31.8130092620849609375	16:54:31.8130092620849609375	16:54:31.8130092620849609375
Y_Unit_Label	Volts	Volts
X_Dimension	Time	Time	Time	Time	Time	Time	Time
X0	0.0000000000000000E+0	0.0000000000000000E+0	0.0000000000000000E+0	0.0000000000000000E+0	0.0000000000000000E+0	0.0000000000000000E+0	0.0000000000000000E+0
Delta_X	0.000000	0.000000	1.000000	1.000000	1.000000	1.000000	1.000000
***End_of_Header***
X_Value	Dev1/ai0	Dev1/ai0 1	Untitled	Untitled 1	Untitled 2	Untitled 3	Untitled 4	Comment
0.000000	1.431948E-6	0.014319	-1.418591E-5	988.039062	0.000000	NaN	NaN
0.999057	9.684761E-6	0.096848	4.947186E-5	988.101929	0.000000	NaN	NaN
1.999114	-0.000114	-1.141074	3.027916E-5	988.083069	0.000000	NaN	NaN
2.999172	-1.507368E-5	-0.150737	6.580353E-5	988.118164	0.000000	NaN	NaN
3.999229	-3.983212E-5	-0.398321	0.000173	988.224487	0.000000	NaN	NaN
4.999286	0.000125	1.252241	0.000427	988.474976	0.000000	NaN	NaN
5.999343	4.269601E-5	0.426960	0.000704	988.748352	0.000000	NaN	NaN
6.999400	0.000199	1.994995	0.001043	989.083923	0.000000	NaN	NaN
7.999458	0.000191	1.912466	0.001326	989.363342	0.000000	NaN	NaN
8.999515	0.000266	2.655220	0.001713	989.745483	0.000000	NaN	NaN
9.999572	0.000282	2.820276	0.001964	989.993774	0.000000	NaN	NaN
10.999629	0.000241	2.407635	0.002150	990.177002	0.000000	NaN	NaN
11.999686	0.000266	2.655220	0.002323	990.347961	0.000000	NaN	NaN
12.999744	0.000340	3.397973	0.002563	990.585937	0.000000	NaN	NaN
13.999801	0.000249	2.490163	0.002741	990.760986	0.000000	NaN	NaN
14.999858	0.000282	2.820276	0.002926	990.944580	0.000000	NaN	NaN
15.999915	0.000332	3.315445	0.003150	991.164978	0.000000	NaN	NaN
16.999972	0.000290	2.902804	0.003264	991.278198	0.000000	NaN	NaN
18.000030	0.000472	4.718423	0.003524	991.535278	0.000000	NaN	NaN
18.999087	0.000431	4.305782	0.003769	991.777344	0.000000	NaN	NaN
19.999144	0.000472	4.718423	0.003861	991.867981	0.000000	NaN	NaN
20.999201	0.000398	3.975670	0.004035	992.040161	0.000000	NaN	NaN
21.999258	0.000472	4.718423	0.004348	992.349365	0.000000	NaN	NaN
22.999316	0.000472	4.718423	0.004472	992.471863	0.000000	NaN	NaN
23.999373	0.000439	4.388310	0.004694	992.691406	0.000000	NaN	NaN
24.999430	0.000497	4.966007	0.004889	992.883484	0.000000	NaN	NaN
25.999487	0.000571	5.708760	0.005098	993.090576	0.000000	NaN	NaN
26.999544	0.000571	5.708760	0.005264	993.253967	0.000000	NaN	NaN
27.999602	0.000587	5.873817	0.005489	993.476807	0.000000	NaN	NaN
28.999659	0.000703	7.029210	0.005686	993.670715	0.000000	NaN	NaN
29.999716	0.000629	6.286457	0.005895	993.878113	0.000000	NaN	NaN
30.999773	0.000538	5.378648	0.005987	993.968262	0.000000	NaN	NaN
31.999830	0.000711	7.111738	0.006175	994.154480	0.000000	NaN	NaN
32.999887	0.000521	5.213591	0.006429	994.404907	0.000000	NaN	NaN
33.999945	0.000736	7.359323	0.006539	994.514282	0.000000	NaN	NaN
35.000002	0.000645	6.451513	0.006731	994.703369	0.000000	NaN	NaN
35.999059	0.000670	6.699098	0.006893	994.864136	0.000000	NaN	NaN
36.999116	0.000596	5.956345	0.007114	995.081970	0.000000	NaN	NaN
37.999173	0.000637	6.368985	0.007320	995.286072	0.000000	NaN	NaN
38.999231	0.000670	6.699098	0.007473	995.437195	0.000000	NaN	NaN
39.999288	0.000818	8.184604	0.007765	995.725647	0.000000	NaN	NaN
40.999345	0.000893	8.927357	0.008000	995.957642	0.000000	NaN	NaN
41.999402	0.000835	8.349660	0.008253	996.207092	0.000000	NaN	NaN
42.999460	0.000884	8.844829	0.008492	996.443115	0.000000	NaN	NaN
43.999517	0.000851	8.514717	0.008755	996.703369	0.000000	NaN	NaN
44.999574	0.000909	9.092413	0.009101	997.045410	0.000000	NaN	NaN
45.999631	0.000934	9.339998	0.009452	997.392334	0.000000	NaN	NaN
46.999688	0.000959	9.587582	0.009636	997.574158	0.000000	NaN	NaN
47.999746	0.000909	9.092413	0.009931	997.865845	0.000000	NaN	NaN
48.999803	0.000992	9.917695	0.010305	998.235168	0.000000	NaN	NaN
49.999860	0.001000	10.000223	0.010608	998.534119	0.000000	NaN	NaN
50.999917	0.001025	10.247807	0.010893	998.816101	0.000000	NaN	NaN
51.999974	0.001091	10.908032	0.011155	999.075073	0.000000	NaN	NaN
53.000031	0.001074	10.742976	0.011467	999.383423	0.000000	NaN	NaN
53.999089	0.001165	11.650785	0.011725	999.637939	0.000000	NaN	NaN
54.999146	0.001182	11.815842	0.012131	1000.039673	0.000000	NaN	NaN
55.999203	0.001107	11.073088	0.012519	1000.422363	0.000000	NaN	NaN
56.999260	0.001223	12.228482	0.012765	1000.665955	0.000000	NaN	NaN
57.999317	0.001132	11.320673	0.013204	1001.098938	0.000000	NaN	NaN
58.999375	0.001157	11.568257	0.013526	1001.417114	0.000000	NaN	NaN
59.999432	0.001058	10.577920	0.013856	1001.743347	0.000000	NaN	NaN
60.999489	0.001099	10.990560	0.014277	1002.159485	0.000000	NaN	NaN
61.999546	0.001371	13.713988	0.014676	1002.553467	0.000000	NaN	NaN
62.999603	0.001404	14.044101	0.014846	1002.721802	0.000000	NaN	NaN
63.999661	0.001256	12.558595	0.014403	1002.283630	0.000000	NaN	NaN
64.999718	0.001338	13.383876	0.014816	1002.691956	0.000000	NaN	NaN
65.999775	0.001231	12.311010	0.015197	1003.068848	0.000000	NaN	NaN
66.999832	0.001371	13.713988	0.016456	1004.312500	0.000000	NaN	NaN
67.999889	0.001272	12.723651	0.016855	1004.706360	0.000000	NaN	NaN
68.999947	0.001413	14.126629	0.017323	1005.169312	0.000000	NaN	NaN
70.000004	0.001462	14.621798	0.017763	1005.604431	0.000000	NaN	NaN
70.999061	0.001487	14.869382	0.018118	1005.955017	0.000000	NaN	NaN
71.999118	0.001404	14.044101	0.018502	1006.333862	0.000000	NaN	NaN
72.999175	0.001371	13.713988	0.019011	1006.837280	0.000000	NaN	NaN
73.999233	0.001371	13.713988	0.019371	1007.192383	0.000000	NaN	NaN
74.999290	0.001371	13.713988	0.019761	1007.578308	0.000000	NaN	NaN
75.999347	0.001437	14.374213	0.020238	1008.049438	0.000000	NaN	NaN
76.999404	0.001462	14.621798	0.020604	1008.411438	0.000000	NaN	NaN
77.999461	0.001429	14.291685	0.020982	1008.784485	0.000000	NaN	NaN
78.999518	0.001396	13.961573	0.021499	1009.294983	0.000000	NaN	NaN
79.999576	0.001495	14.951910	0.021878	1009.670044	0.000000	NaN	NaN
80.999633	0.001404	14.044101	0.022260	1010.047546	0.000000	NaN	NaN
81.999690	0.001479	14.786854	0.022666	1010.448486	0.000000	NaN	NaN
82.999747	0.001495	14.951910	0.023128	1010.904968	0.000000	NaN	NaN
83.999804	0.001545	15.447079	0.023519	1011.291443	0.000000	NaN	NaN
84.999862	0.001528	15.282023	0.023965	1011.732056	0.000000	NaN	NaN
85.999919	0.001495	14.951910	0.024426	1012.187439	0.000000	NaN	NaN
86.999976	0.001578	15.777192	0.024813	1012.569946	0.000000	NaN	NaN
88.000033	0.001594	15.942248	0.025201	1012.952637	0.000000	NaN	NaN
88.999090	0.001718	17.180170	0.025726	1013.471863	0.000000	NaN	NaN
89.999148	0.001569	15.694663	0.026112	1013.852905	0.000000	NaN	NaN
90.999205	0.001586	15.859720	0.026452	1014.189270	0.000000	NaN	NaN
91.999262	0.001611	16.107304	0.027056	1014.785339	0.000000	NaN	NaN
92.999319	0.001586	15.859720	0.027451	1015.176331	0.000000	NaN	NaN
93.999376	0.001578	15.777192	0.027783	1015.504517	0.000000	NaN	NaN
94.999434	0.001586	15.859720	0.028331	1016.045654	0.000000	NaN	NaN
95.999491	0.001586	15.859720	0.028876	1016.584351	0.000000	NaN	NaN
96.999548	0.001594	15.942248	0.029157	1016.861938	0.000000	NaN	NaN
97.999605	0.001669	16.685001	0.029705	1017.403381	0.000000	NaN	NaN
98.999662	0.001586	15.859720	0.030189	1017.881531	0.000000	NaN	NaN
99.999720	0.001553	15.529607	0.030555	1018.243347	0.000000	NaN	NaN
100.999777	0.001644	16.437417	0.030995	1018.678223	0.000000	NaN	NaN
101.999834	0.001685	16.850057	0.031607	1019.282471	0.000000	NaN	NaN
102.999891	0.001512	15.116967	0.031957	1019.628601	0.000000	NaN	NaN
103.999949	0.001627	16.272360	0.032356	1020.022156	0.000000	NaN	NaN
105.000006	0.001677	16.767529	0.032862	1020.522705	0.000000	NaN	NaN
105.999063	0.001710	17.097642	0.033390	1021.043762	0.000000	NaN	NaN
106.999120	0.001726	17.262698	0.033782	1021.431580	0.000000	NaN	NaN
107.999177	0.001693	16.932585	0.034326	1021.969177	0.000000	NaN	NaN
108.999234	0.001619	16.189832	0.034796	1022.433655	0.000000	NaN	NaN
109.999292	0.001652	16.519945	0.035006	1022.640564	0.000000	NaN	NaN
110.999349	0.001735	17.345226	0.036350	1023.969299	0.000000	NaN	NaN
111.999406	0.001743	17.427754	0.036898	1024.510010	0.000000	NaN	NaN
112.999463	0.001652	16.519945	0.036220	1023.840393	0.000000	NaN	NaN
113.999520	0.001702	17.015114	0.036705	1024.319946	0.000000	NaN	NaN
114.999578	0.001644	16.437417	0.037184	1024.793091	0.000000	NaN	NaN
115.999635	0.001726	17.262698	0.037719	1025.321899	0.000000	NaN	NaN
116.999692	0.001644	16.437417	0.038210	1025.806885	0.000000	NaN	NaN
117.999749	0.001652	16.519945	0.038637	1026.228027	0.000000	NaN	NaN
118.999806	0.001726	17.262698	0.039141	1026.726196	0.000000	NaN	NaN
119.999864	0.001669	16.685001	0.039749	1027.327026	0.000000	NaN	NaN
120.999921	0.001726	17.262698	0.040200	1027.772705	0.000000	NaN	NaN
121.999978	0.001809	18.087979	0.040728	1028.294800	0.000000	NaN	NaN
123.000035	0.001801	18.005451	0.041206	1028.766724	0.000000	NaN	NaN
123.999092	0.001710	17.097642	0.041734	1029.288086	0.000000	NaN	NaN
124.999150	0.001751	17.510282	0.042153	1029.702759	0.000000	NaN	NaN
125.999207	0.001792	17.922923	0.042673	1030.216675	0.000000	NaN	NaN
126.999264	0.001825	18.253035	0.043119	1030.657227	0.000000	NaN	NaN
127.999321	0.001801	18.005451	0.043597	1031.129395	0.000000	NaN	NaN
128.999378	0.001784	17.840395	0.044180	1031.705200	0.000000	NaN	NaN
129.999436	0.001801	18.005451	0.044648	1032.167847	0.000000	NaN	NaN
130.999493	0.001817	18.170507	0.045132	1032.645630	0.000000	NaN	NaN
131.999550	0.001751	17.510282	0.045637	1033.144531	0.000000	NaN	NaN
132.999607	0.001842	18.418092	0.046142	1033.643799	0.000000	NaN	NaN
133.999664	0.001867	18.665676	0.046629	1034.125488	0.000000	NaN	NaN
134.999722	0.001759	17.592810	0.047199	1034.687744	0.000000	NaN	NaN
135.999779	0.001751	17.510282	0.047689	1035.172241	0.000000	NaN	NaN
136.999836	0.001908	19.078317	0.048136	1035.613770	0.000000	NaN	NaN
137.999893	0.001776	17.757867	0.048715	1036.186523	0.000000	NaN	NaN
138.999950	0.001825	18.253035	0.049228	1036.692627	0.000000	NaN	NaN
140.000008	0.001908	19.078317	0.049643	1037.103149	0.000000	NaN	NaN
140.999065	0.001817	18.170507	0.050141	1037.595215	0.000000	NaN	NaN
141.999122	0.001751	17.510282	0.050637	1038.085083	0.000000	NaN	NaN
142.999179	0.001792	17.922923	0.051157	1038.598877	0.000000	NaN	NaN
143.999236	0.001710	17.097642	0.051666	1039.101685	0.000000	NaN	NaN
144.999293	0.001957	19.573485	0.052178	1039.607300	0.000000	NaN	NaN
145.999351	0.002098	20.976463	0.052601	1040.026123	0.000000	NaN	NaN
146.999408	0.001627	16.272360	0.053081	1040.500000	0.000000	NaN	NaN
147.999465	0.001768	17.675339	0.053648	1041.059937	0.000000	NaN	NaN
148.999522	0.001776	17.757867	0.054127	1041.533447	0.000000	NaN	NaN
149.999580	0.001685	16.850057	0.054525	1041.926758	0.000000	NaN	NaN
150.999637	0.001759	17.592810	0.055048	1042.443604	0.000000	NaN	NaN
151.999694	0.001883	18.830732	0.055587	1042.976196	0.000000	NaN	NaN
152.999751	0.001825	18.253035	0.056075	1043.457642	0.000000	NaN	NaN
153.999808	0.001834	18.335564	0.056565	1043.942383	0.000000	NaN	NaN
154.999865	0.001957	19.573485	0.057108	1044.478516	0.000000	NaN	NaN
155.999923	0.001817	18.170507	0.057511	1044.876709	0.000000	NaN	NaN
156.999980	0.001825	18.253035	0.058082	1045.441650	0.000000	NaN	NaN
158.000037	0.001916	19.160845	0.058604	1045.956543	0.000000	NaN	NaN
158.999094	0.001735	17.345226	0.059043	1046.390381	0.000000	NaN	NaN
159.999152	0.001875	18.748204	0.059626	1046.966675	0.000000	NaN	NaN
160.999209	0.001850	18.500620	0.060205	1047.538574	0.000000	NaN	NaN
161.999266	0.001842	18.418092	0.060693	1048.020752	0.000000	NaN	NaN
162.999323	0.001817	18.170507	0.061244	1048.565796	0.000000	NaN	NaN
163.999380	0.001809	18.087979	0.061781	1049.095947	0.000000	NaN	NaN
164.999437	0.001768	17.675339	0.062186	1049.495850	0.000000	NaN	NaN
165.999495	0.001817	18.170507	0.062790	1050.092651	0.000000	NaN	NaN
166.999552	0.001842	18.418092	0.063305	1050.602051	0.000000	NaN	NaN
167.999609	0.001990	19.903598	0.063759	1051.050659	0.000000	NaN	NaN
168.999666	0.002048	20.481295	0.064153	1051.440063	0.000000	NaN	NaN
169.999723	0.001900	18.995789	0.064802	1052.080688	0.000000	NaN	NaN
170.999781	0.001842	18.418092	0.065304	1052.576538	0.000000	NaN	NaN
171.999838	0.001834	18.335564	0.065771	1053.038574	0.000000	NaN	NaN
172.999895	0.001834	18.335564	0.066321	1053.581299	0.000000	NaN	NaN
173.999952	0.001883	18.830732	0.066780	1054.035400	0.000000	NaN	NaN
175.000010	0.001842	18.418092	0.067226	1054.475708	0.000000	NaN	NaN
175.999067	0.001891	18.913260	0.067886	1055.128052	0.000000	NaN	NaN
176.999124	0.001867	18.665676	0.068314	1055.551025	0.000000	NaN	NaN
177.999181	0.001900	18.995789	0.068714	1055.946533	0.000000	NaN	NaN
178.999238	0.001949	19.490957	0.069178	1056.404419	0.000000	NaN	NaN
179.999295	0.001949	19.490957	0.069795	1057.014160	0.000000	NaN	NaN
180.999353	0.001875	18.748204	0.070194	1057.408081	0.000000	NaN	NaN
181.999410	0.001900	18.995789	0.070753	1057.961060	0.000000	NaN	NaN
182.999467	0.001850	18.500620	0.071232	1058.433716	0.000000	NaN	NaN
183.999524	0.001883	18.830732	0.071649	1058.846313	0.000000	NaN	NaN
184.999581	0.001924	19.243373	0.072249	1059.438843	0.000000	NaN	NaN
185.999639	0.001867	18.665676	0.072734	1059.918579	0.000000	NaN	NaN
186.999696	0.001933	19.325901	0.073155	1060.334351	0.000000	NaN	NaN
187.999753	0.001916	19.160845	0.073644	1060.817139	0.000000	NaN	NaN
188.999810	0.001858	18.583148	0.074221	1061.387695	0.000000	NaN	NaN
189.999867	0.001957	19.573485	0.074639	1061.800049	0.000000	NaN	NaN
190.999925	0.001842	18.418092	0.075048	1062.204956	0.000000	NaN	NaN
191.999982	0.001891	18.913260	0.075659	1062.808350	0.000000	NaN	NaN
192.999039	0.001908	19.078317	0.076093	1063.236572	0.000000	NaN	NaN
193.999096	0.001957	19.573485	0.076516	1063.654785	0.000000	NaN	NaN
194.999153	0.001957	19.573485	0.077079	1064.210815	0.000000	NaN	NaN
195.999211	0.001957	19.573485	0.077582	1064.708618	0.000000	NaN	NaN
196.999268	0.002023	20.233710	0.078019	1065.139526	0.000000	NaN	NaN
197.999325	0.001842	18.418092	0.078593	1065.706787	0.000000	NaN	NaN
198.999382	0.001875	18.748204	0.079054	1066.163086	0.000000	NaN	NaN
199.999439	0.001916	19.160845	0.079496	1066.599121	0.000000	NaN	NaN
200.999496	0.001933	19.325901	0.080006	1067.102783	0.000000	NaN	NaN
201.999554	0.001883	18.830732	0.080519	1067.610229	0.000000	NaN	NaN
202.999611	0.001850	18.500620	0.080968	1068.053345	0.000000	NaN	NaN
203.999668	0.001966	19.656014	0.081545	1068.623657	0.000000	NaN	NaN
204.999725	0.001990	19.903598	0.082058	1069.131104	0.000000	NaN	NaN
205.999783	0.001801	18.005451	0.082476	1069.543945	0.000000	NaN	NaN
206.999840	0.001908	19.078317	0.082875	1069.938354	0.000000	NaN	NaN
207.999897	0.001825	18.253035	0.083633	1070.686768	0.000000	NaN	NaN
208.999954	0.002015	20.151182	0.084055	1071.104126	0.000000	NaN	NaN
210.000011	0.001999	19.986126	0.084585	1071.627319	0.000000	NaN	NaN
210.999068	0.001924	19.243373	0.085162	1072.197876	0.000000	NaN	NaN
211.999126	0.002040	20.398767	0.085583	1072.613892	0.000000	NaN	NaN
212.999183	0.001900	18.995789	0.086020	1073.045166	0.000000	NaN	NaN
213.999240	0.001966	19.656014	0.086730	1073.747437	0.000000	NaN	NaN
214.999297	0.001966	19.656014	0.087059	1074.071899	0.000000	NaN	NaN
215.999355	0.001891	18.913260	0.087457	1074.465088	0.000000	NaN	NaN
216.999412	0.002007	20.068654	0.088086	1075.087036	0.000000	NaN	NaN
217.999469	0.001966	19.656014	0.088631	1075.624756	0.000000	NaN	NaN
218.999526	0.002015	20.151182	0.089059	1076.047852	0.000000	NaN	NaN
219.999583	0.001850	18.500620	0.089531	1076.514648	0.000000	NaN	NaN
220.999640	0.002056	20.563823	0.090060	1077.036865	0.000000	NaN	NaN
221.999698	0.001933	19.325901	0.090529	1077.500854	0.000000	NaN	NaN
222.999755	0.001941	19.408429	0.091062	1078.027588	0.000000	NaN	NaN
223.999812	0.002015	20.151182	0.091587	1078.546143	0.000000	NaN	NaN
224.999869	0.002089	20.893935	0.091960	1078.914795	0.000000	NaN	NaN
225.999926	0.001891	18.913260	0.092505	1079.453125	0.000000	NaN	NaN
226.999984	0.001982	19.821070	0.092999	1079.940552	0.000000	NaN	NaN
227.999041	0.001916	19.160845	0.093519	1080.455078	0.000000	NaN	NaN
228.999098	0.001966	19.656014	0.093762	1080.694702	0.000000	NaN	NaN
229.999155	0.002065	20.646351	0.094330	1081.255737	0.000000	NaN	NaN
230.999212	0.001982	19.821070	0.094980	1081.898193	0.000000	NaN	NaN
231.999270	0.001891	18.913260	0.095348	1082.262085	0.000000	NaN	NaN
232.999327	0.002040	20.398767	0.095915	1082.822632	0.000000	NaN	NaN
233.999384	0.001900	18.995789	0.096470	1083.370728	0.000000	NaN	NaN
234.999441	0.001990	19.903598	0.096870	1083.765991	0.000000	NaN	NaN
235.999498	0.002015	20.151182	0.097495	1084.383789	0.000000	NaN	NaN
236.999556	0.002056	20.563823	0.097963	1084.845947	0.000000	NaN	NaN
237.999613	0.002040	20.398767	0.098418	1085.295532	0.000000	NaN	NaN
238.999670	0.001999	19.986126	0.098903	1085.774780	0.000000	NaN	NaN
239.999727	0.002056	20.563823	0.099457	1086.322144	0.000000	NaN	NaN
240.999784	0.001999	19.986126	0.099647	1086.509644	0.000000	NaN	NaN
241.999842	0.002007	20.068654	0.100848	1087.696045	0.000000	NaN	NaN
242.999899	0.002048	20.481295	0.101423	1088.264282	0.000000	NaN	NaN
243.999956	0.001908	19.078317	0.101771	1088.608398	0.000000	NaN	NaN
245.000013	0.002098	20.976463	0.102306	1089.137207	0.000000	NaN	NaN
245.999070	0.001850	18.500620	0.102877	1089.701416	0.000000	NaN	NaN
246.999128	0.002131	21.306576	0.103294	1090.112915	0.000000	NaN	NaN
247.999185	0.002048	20.481295	0.103828	1090.640869	0.000000	NaN	NaN
248.999242	0.001957	19.573485	0.104232	1091.039673	0.000000	NaN	NaN
249.999299	0.001867	18.665676	0.104763	1091.564697	0.000000	NaN	NaN
250.999356	0.001916	19.160845	0.105184	1091.980347	0.000000	NaN	NaN
251.999414	0.002048	20.481295	0.105702	1092.492187	0.000000	NaN	NaN
252.999471	0.002056	20.563823	0.106208	1092.991821	0.000000	NaN	NaN
253.999528	0.002007	20.068654	0.106709	1093.486938	0.000000	NaN	NaN
254.999585	0.001875	18.748204	0.107223	1093.995117	0.000000	NaN	NaN
255.999642	0.001974	19.738542	0.107770	1094.535522	0.000000	NaN	NaN
256.999700	0.001949	19.490957	0.108107	1094.868530	0.000000	NaN	NaN
257.999757	0.001982	19.821070	0.108776	1095.529297	0.000000	NaN	NaN
258.999814	0.002007	20.068654	0.109368	1096.114868	0.000000	NaN	NaN
259.999871	0.002007	20.068654	0.109743	1096.484741	0.000000	NaN	NaN
260.999928	0.001982	19.821070	0.110300	1097.035767	0.000000	NaN	NaN
261.999986	0.001974	19.738542	0.110888	1097.616455	0.000000	NaN	NaN
262.999043	0.002106	21.058992	0.111264	1097.987915	0.000000	NaN	NaN
263.999100	0.002015	20.151182	0.111788	1098.505981	0.000000	NaN	NaN
264.999157	0.002032	20.316239	0.112365	1099.075439	0.000000	NaN	NaN
265.999214	0.002139	21.389104	0.112721	1099.427856	0.000000	NaN	NaN
266.999272	0.001933	19.325901	0.113297	1099.996216	0.000000	NaN	NaN
267.999329	0.001916	19.160845	0.113918	1100.610596	0.000000	NaN	NaN
268.999386	0.002098	20.976463	0.114234	1100.922852	0.000000	NaN	NaN
269.999443	0.002147	21.471632	0.114631	1101.314209	0.000000	NaN	NaN
270.999500	0.002007	20.068654	0.115342	1102.017090	0.000000	NaN	NaN
271.999557	0.001974	19.738542	0.115742	1102.412476	0.000000	NaN	NaN
272.999615	0.001982	19.821070	0.116355	1103.017822	0.000000	NaN	NaN
273.999672	0.002023	20.233710	0.116922	1103.577759	0.000000	NaN	NaN
274.999729	0.002040	20.398767	0.117324	1103.975830	0.000000	NaN	NaN
275.999786	0.002048	20.481295	0.117698	1104.344604	0.000000	NaN	NaN
276.999843	0.001999	19.986126	0.118423	1105.060913	0.000000	NaN	NaN
277.999901	0.002073	20.728879	0.118858	1105.491089	0.000000	NaN	NaN
278.999958	0.002065	20.646351	0.119190	1105.819214	0.000000	NaN	NaN
280.000015	0.002106	21.058992	0.119726	1106.348511	0.000000	NaN	NaN
280.999072	0.001982	19.821070	0.120329	1106.944458	0.000000	NaN	NaN
281.999129	0.002023	20.233710	0.120704	1107.314941	0.000000	NaN	NaN
282.999187	0.002114	21.141520	0.121304	1107.907593	0.000000	NaN	NaN
283.999244	0.002131	21.306576	0.121969	1108.565430	0.000000	NaN	NaN
284.999301	0.001924	19.243373	0.122383	1108.974243	0.000000	NaN	NaN
285.999358	0.001941	19.408429	0.123160	1109.742065	0.000000	NaN	NaN
286.999415	0.002098	20.976463	0.123437	1110.015381	0.000000	NaN	NaN
287.999473	0.001982	19.821070	0.123820	1110.393677	0.000000	NaN	NaN
288.999530	0.002155	21.554160	0.124451	1111.017090	0.000000	NaN	NaN
289.999587	0.001883	18.830732	0.125010	1111.569214	0.000000	NaN	NaN
290.999644	0.002065	20.646351	0.125406	1111.961304	0.000000	NaN	NaN
291.999702	0.002131	21.306576	0.125925	1112.473511	0.000000	NaN	NaN
292.999759	0.001999	19.986126	0.126458	1113.000366	0.000000	NaN	NaN
293.999816	0.002015	20.151182	0.126856	1113.393188	0.000000	NaN	NaN
294.999873	0.002122	21.224048	0.127396	1113.927612	0.000000	NaN	NaN
295.999930	0.002081	20.811407	0.128008	1114.531372	0.000000	NaN	NaN
296.999987	0.002048	20.481295	0.128382	1114.901123	0.000000	NaN	NaN
297.999045	0.002056	20.563823	0.128916	1115.428833	0.000000	NaN	NaN
298.999102	0.002065	20.646351	0.129529	1116.034302	0.000000	NaN	NaN
299.999159	0.002246	22.461970	0.129933	1116.433350	0.000000	NaN	NaN
300.999216	0.002073	20.728879	0.130481	1116.975464	0.000000	NaN	NaN
301.999273	0.002139	21.389104	0.131018	1117.506226	0.000000	NaN	NaN
302.999331	0.002081	20.811407	0.131396	1117.878906	0.000000	NaN	NaN
303.999388	0.002246	22.461970	0.131749	1118.228394	0.000000	NaN	NaN
304.999445	0.002188	21.884273	0.132548	1119.017822	0.000000	NaN	NaN
305.999502	0.001999	19.986126	0.132907	1119.371948	0.000000	NaN	NaN
306.999559	0.002040	20.398767	0.133292	1119.752686	0.000000	NaN	NaN
307.999617	0.002147	21.471632	0.133790	1120.244995	0.000000	NaN	NaN
308.999674	0.002139	21.389104	0.134308	1120.756470	0.000000	NaN	NaN
309.999731	0.002106	21.058992	0.134789	1121.232178	0.000000	NaN	NaN
310.999788	0.002065	20.646351	0.135609	1122.042236	0.000000	NaN	NaN
311.999845	0.002213	22.131857	0.135950	1122.379028	0.000000	NaN	NaN
312.999903	0.001974	19.738542	0.136338	1122.762085	0.000000	NaN	NaN
313.999960	0.002098	20.976463	0.137144	1123.558960	0.000000	NaN	NaN
315.000017	0.002081	20.811407	0.137540	1123.949463	0.000000	NaN	NaN
315.999074	0.002147	21.471632	0.137909	1124.314575	0.000000	NaN	NaN
316.999131	0.002065	20.646351	0.138461	1124.859619	0.000000	NaN	NaN
317.999189	0.002197	21.966801	0.138975	1125.367920	0.000000	NaN	NaN
318.999246	0.002197	21.966801	0.139359	1125.747559	0.000000	NaN	NaN
319.999303	0.002147	21.471632	0.139888	1126.269653	0.000000	NaN	NaN
320.999360	0.002056	20.563823	0.140471	1126.846313	0.000000	NaN	NaN
321.999417	0.002122	21.224048	0.140816	1127.186890	0.000000	NaN	NaN
322.999475	0.002164	21.636688	0.141397	1127.760742	0.000000	NaN	NaN
323.999532	0.002089	20.893935	0.141976	1128.333008	0.000000	NaN	NaN
324.999589	0.002089	20.893935	0.142306	1128.659180	0.000000	NaN	NaN
325.999646	0.001990	19.903598	0.142642	1128.990479	0.000000	NaN	NaN
326.999703	0.002098	20.976463	0.143422	1129.761597	0.000000	NaN	NaN
327.999760	0.002073	20.728879	0.143819	1130.154053	0.000000	NaN	NaN
328.999818	0.002205	22.049329	0.144183	1130.513306	0.000000	NaN	NaN
329.999875	0.002172	21.719217	0.144736	1131.059570	0.000000	NaN	NaN
330.999932	0.002089	20.893935	0.145267	1131.584717	0.000000	NaN	NaN
331.999989	0.002106	21.058992	0.145656	1131.968628	0.000000	NaN	NaN
332.999047	0.002180	21.801745	0.146208	1132.514648	0.000000	NaN	NaN
333.999104	0.002147	21.471632	0.146942	1133.239746	0.000000	NaN	NaN
334.999161	0.002089	20.893935	0.147269	1133.562378	0.000000	NaN	NaN
335.999218	0.002122	21.224048	0.147759	1134.046631	0.000000	NaN	NaN
336.999275	0.001974	19.738542	0.148299	1134.580566	0.000000	NaN	NaN
337.999332	0.002180	21.801745	0.148644	1134.921509	0.000000	NaN	NaN
338.999390	0.002139	21.389104	0.149223	1135.493408	0.000000	NaN	NaN
339.999447	0.002205	22.049329	0.149811	1136.074219	0.000000	NaN	NaN
340.999504	0.002098	20.976463	0.150179	1136.437500	0.000000	NaN	NaN
341.999561	0.002131	21.306576	0.150703	1136.955566	0.000000	NaN	NaN
342.999618	0.002279	22.792082	0.151290	1137.535767	0.000000	NaN	NaN
343.999676	0.002188	21.884273	0.151631	1137.872803	0.000000	NaN	NaN
344.999733	0.002230	22.296913	0.152210	1138.444702	0.000000	NaN	NaN
345.999790	0.002122	21.224048	0.152746	1138.974365	0.000000	NaN	NaN
346.999847	0.002188	21.884273	0.153076	1139.300415	0.000000	NaN	NaN
347.999905	0.002131	21.306576	0.153449	1139.669312	0.000000	NaN	NaN
348.999962	0.002254	22.544498	0.154285	1140.495239	0.000000	NaN	NaN
350.000019	0.002081	20.811407	0.154572	1140.777954	0.000000	NaN	NaN
350.999076	0.001908	19.078317	0.155190	1141.388794	0.000000	NaN	NaN
351.999133	0.002230	22.296913	0.155736	1141.928101	0.000000	NaN	NaN
352.999190	0.002081	20.811407	0.156053	1142.242187	0.000000	NaN	NaN
353.999248	0.002238	22.379442	0.156402	1142.586548	0.000000	NaN	NaN
354.999305	0.002164	21.636688	0.156950	1143.127563	0.000000	NaN	NaN
355.999362	0.002155	21.554160	0.157597	1143.767212	0.000000	NaN	NaN
356.999419	0.002213	22.131857	0.157919	1144.085571	0.000000	NaN	NaN
357.999476	0.002213	22.131857	0.158403	1144.563354	0.000000	NaN	NaN
358.999534	0.002164	21.636688	0.158947	1145.101318	0.000000	NaN	NaN
359.999591	0.002287	22.874610	0.159334	1145.484009	0.000000	NaN	NaN
360.999648	0.002221	22.214385	0.159937	1146.078979	0.000000	NaN	NaN
361.999705	0.002205	22.049329	0.160581	1146.715332	0.000000	NaN	NaN
362.999762	0.002246	22.461970	0.160979	1147.108521	0.000000	NaN	NaN
363.999820	0.002122	21.224048	0.161617	1147.738892	0.000000	NaN	NaN
364.999877	0.002073	20.728879	0.162156	1148.271606	0.000000	NaN	NaN
365.999934	0.002230	22.296913	0.162447	1148.559692	0.000000	NaN	NaN
366.999991	0.002172	21.719217	0.163073	1149.177734	0.000000	NaN	NaN
367.999048	0.002155	21.554160	0.163698	1149.795044	0.000000	NaN	NaN
368.999106	0.002155	21.554160	0.163917	1150.012207	0.000000	NaN	NaN
369.999163	0.002180	21.801745	0.164589	1150.675293	0.000000	NaN	NaN
370.999220	0.002180	21.801745	0.164746	1150.831299	0.000000	NaN	NaN
371.999277	0.002263	22.627026	0.164958	1151.040894	0.000000	NaN	NaN
372.999334	0.002287	22.874610	0.165581	1151.655884	0.000000	NaN	NaN
373.999392	0.002197	21.966801	0.166106	1152.174927	0.000000	NaN	NaN
374.999449	0.002287	22.874610	0.166639	1152.701050	0.000000	NaN	NaN
375.999506	0.002180	21.801745	0.167092	1153.148437	0.000000	NaN	NaN
376.999563	0.002098	20.976463	0.167600	1153.650513	0.000000	NaN	NaN
377.999620	0.002147	21.471632	0.168002	1154.047852	0.000000	NaN	NaN
378.999678	0.002238	22.379442	0.168581	1154.619751	0.000000	NaN	NaN
379.999735	0.002378	23.782420	0.169048	1155.081543	0.000000	NaN	NaN
380.999792	0.002345	23.452307	0.169500	1155.528564	0.000000	NaN	NaN
381.999849	0.002164	21.636688	0.169965	1155.987061	0.000000	NaN	NaN
382.999906	0.002188	21.884273	0.170481	1156.497192	0.000000	NaN	NaN
383.999964	0.002205	22.049329	0.170982	1156.992676	0.000000	NaN	NaN
385.000021	0.002296	22.957138	0.171447	1157.451416	0.000000	NaN	NaN
385.999078	0.002122	21.224048	0.171919	1157.918579	0.000000	NaN	NaN
386.999135	0.002271	22.709554	0.172374	1158.367310	0.000000	NaN	NaN
387.999192	0.002205	22.049329	0.172833	1158.821289	0.000000	NaN	NaN
388.999250	0.002172	21.719217	0.173391	1159.372803	0.000000	NaN	NaN
389.999307	0.002213	22.131857	0.173861	1159.836548	0.000000	NaN	NaN
390.999364	0.002164	21.636688	0.174342	1160.311768	0.000000	NaN	NaN
391.999421	0.002337	23.369779	0.174800	1160.765137	0.000000	NaN	NaN
392.999478	0.002271	22.709554	0.175332	1161.290894	0.000000	NaN	NaN
393.999535	0.002221	22.214385	0.175816	1161.768433	0.000000	NaN	NaN
394.999593	0.002263	22.627026	0.176286	1162.233521	0.000000	NaN	NaN
395.999650	0.002197	21.966801	0.176722	1162.664062	0.000000	NaN	NaN
396.999707	0.002246	22.461970	0.177182	1163.118286	0.000000	NaN	NaN
397.999764	0.002205	22.049329	0.177735	1163.664551	0.000000	NaN	NaN
398.999821	0.002304	23.039667	0.178221	1164.144409	0.000000	NaN	NaN
399.999879	0.002287	22.874610	0.178662	1164.581055	0.000000	NaN	NaN
400.999936	0.002221	22.214385	0.179125	1165.038452	0.000000	NaN	NaN
401.999993	0.002230	22.296913	0.179590	1165.497437	0.000000	NaN	NaN
402.999050	0.002188	21.884273	0.180097	1165.998169	0.000000	NaN	NaN
403.999107	0.002312	23.122195	0.180569	1166.464722	0.000000	NaN	NaN
404.999165	0.002205	22.049329	0.181023	1166.913452	0.000000	NaN	NaN
405.999222	0.002188	21.884273	0.181461	1167.346069	0.000000	NaN	NaN
406.999279	0.002098	20.976463	0.182061	1167.938843	0.000000	NaN	NaN
407.999336	0.002213	22.131857	0.182466	1168.339600	0.000000	NaN	NaN
408.999393	0.002287	22.874610	0.182939	1168.806885	0.000000	NaN	NaN
409.999451	0.002213	22.131857	0.183359	1169.221802	0.000000	NaN	NaN
410.999508	0.002296	22.957138	0.183835	1169.692261	0.000000	NaN	NaN
411.999565	0.002221	22.214385	0.184356	1170.206665	0.000000	NaN	NaN
412.999622	0.002172	21.719217	0.184816	1170.660767	0.000000	NaN	NaN
413.999680	0.002254	22.544498	0.185300	1171.139526	0.000000	NaN	NaN
414.999737	0.002320	23.204723	0.185719	1171.553101	0.000000	NaN	NaN
415.999794	0.002254	22.544498	0.186231	1172.059326	0.000000	NaN	NaN
416.999851	0.002287	22.874610	0.186725	1172.547607	0.000000	NaN	NaN
417.999908	0.002188	21.884273	0.187155	1172.971680	0.000000	NaN	NaN
418.999965	0.002205	22.049329	0.187682	1173.493042	0.000000	NaN	NaN
420.000023	0.002287	22.874610	0.188200	1174.005005	0.000000	NaN	NaN
420.999080	0.002246	22.461970	0.188679	1174.477905	0.000000	NaN	NaN
421.999137	0.002263	22.627026	0.189114	1174.907349	0.000000	NaN	NaN
422.999194	0.002205	22.049329	0.189635	1175.422241	0.000000	NaN	NaN
423.999251	0.002205	22.049329	0.190065	1175.847778	0.000000	NaN	NaN
424.999309	0.002353	23.534835	0.190539	1176.316162	0.000000	NaN	NaN
425.999366	0.002271	22.709554	0.190980	1176.751099	0.000000	NaN	NaN
426.999423	0.002312	23.122195	0.191517	1177.281982	0.000000	NaN	NaN
427.999480	0.002353	23.534835	0.191965	1177.725098	0.000000	NaN	NaN
428.999537	0.002304	23.039667	0.192465	1178.218506	0.000000	NaN	NaN
429.999595	0.002320	23.204723	0.192947	1178.694580	0.000000	NaN	NaN
430.999652	0.002271	22.709554	0.193471	1179.212891	0.000000	NaN	NaN
431.999709	0.002279	22.792082	0.193916	1179.652710	0.000000	NaN	NaN
432.999766	0.002263	22.627026	0.194405	1180.135742	0.000000	NaN	NaN
433.999823	0.002139	21.389104	0.194789	1180.515259	0.000000	NaN	NaN
434.999881	0.002370	23.699892	0.195354	1181.073364	0.000000	NaN	NaN
435.999938	0.002395	23.947476	0.195841	1181.554810	0.000000	NaN	NaN
436.999995	0.002197	21.966801	0.196237	1181.945679	0.000000	NaN	NaN
437.999052	0.002287	22.874610	0.196814	1182.515991	0.000000	NaN	NaN
438.999109	0.002271	22.709554	0.197275	1182.971436	0.000000	NaN	NaN
439.999167	0.002254	22.544498	0.197775	1183.465088	0.000000	NaN	NaN
440.999224	0.002329	23.287251	0.198253	1183.937378	0.000000	NaN	NaN
441.999281	0.002221	22.214385	0.198674	1184.353638	0.000000	NaN	NaN
442.999338	0.002213	22.131857	0.199219	1184.892212	0.000000	NaN	NaN
443.999395	0.002345	23.452307	0.199760	1185.426514	0.000000	NaN	NaN
444.999453	0.002353	23.534835	0.200165	1185.826294	0.000000	NaN	NaN
445.999510	0.002213	22.131857	0.200707	1186.362549	0.000000	NaN	NaN
446.999567	0.002172	21.719217	0.201176	1186.825317	0.000000	NaN	NaN
447.999624	0.002246	22.461970	0.201608	1187.252563	0.000000	NaN	NaN
448.999681	0.002188	21.884273	0.202074	1187.713257	0.000000	NaN	NaN
449.999738	0.002279	22.792082	0.202664	1188.296143	0.000000	NaN	NaN
450.999796	0.002188	21.884273	0.203044	1188.671753	0.000000	NaN	NaN
451.999853	0.002386	23.864948	0.203548	1189.169067	0.000000	NaN	NaN
452.999910	0.002362	23.617363	0.203975	1189.591064	0.000000	NaN	NaN
453.999967	0.002312	23.122195	0.204509	1190.119263	0.000000	NaN	NaN
455.000024	0.002378	23.782420	0.205041	1190.644775	0.000000	NaN	NaN
455.999082	0.002329	23.287251	0.205489	1191.086914	0.000000	NaN	NaN
456.999139	0.002312	23.122195	0.206000	1191.592407	0.000000	NaN	NaN
457.999196	0.002370	23.699892	0.206495	1192.081299	0.000000	NaN	NaN
458.999253	0.002213	22.131857	0.206945	1192.525879	0.000000	NaN	NaN
459.999310	0.002353	23.534835	0.207456	1193.030884	0.000000	NaN	NaN
460.999368	0.002362	23.617363	0.207856	1193.426270	0.000000	NaN	NaN
461.999425	0.002345	23.452307	0.208400	1193.963623	0.000000	NaN	NaN
462.999482	0.002353	23.534835	0.208943	1194.500122	0.000000	NaN	NaN
463.999539	0.002221	22.214385	0.209360	1194.912231	0.000000	NaN	NaN
464.999596	0.002246	22.461970	0.209852	1195.397949	0.000000	NaN	NaN
465.999654	0.002370	23.699892	0.210333	1195.872925	0.000000	NaN	NaN
466.999711	0.002345	23.452307	0.210828	1196.361938	0.000000	NaN	NaN
467.999768	0.002461	24.607701	0.211346	1196.874512	0.000000	NaN	NaN
468.999825	0.002304	23.039667	0.211849	1197.370850	0.000000	NaN	NaN
469.999883	0.002263	22.627026	0.212294	1197.810913	0.000000	NaN	NaN
470.999940	0.002362	23.617363	0.212768	1198.279663	0.000000	NaN	NaN
471.999997	0.002312	23.122195	0.213359	1198.863525	0.000000	NaN	NaN
472.999054	0.002271	22.709554	0.213760	1199.259155	0.000000	NaN	NaN
473.999111	0.002403	24.030004	0.214322	1199.814331	0.000000	NaN	NaN
474.999168	0.002329	23.287251	0.214821	1200.307251	0.000000	NaN	NaN
475.999226	0.002279	22.792082	0.215304	1200.785156	0.000000	NaN	NaN
476.999283	0.002370	23.699892	0.215798	1201.272827	0.000000	NaN	NaN
477.999340	0.002263	22.627026	0.216310	1201.778564	0.000000	NaN	NaN
478.999397	0.002345	23.452307	0.216769	1202.232666	0.000000	NaN	NaN
479.999454	0.002345	23.452307	0.217260	1202.717407	0.000000	NaN	NaN
480.999512	0.002461	24.607701	0.217722	1203.173950	0.000000	NaN	NaN
481.999569	0.002287	22.874610	0.218239	1203.684692	0.000000	NaN	NaN
482.999626	0.002188	21.884273	0.218700	1204.140747	0.000000	NaN	NaN
483.999683	0.002345	23.452307	0.219186	1204.620605	0.000000	NaN	NaN
484.999740	0.002230	22.296913	0.219720	1205.147705	0.000000	NaN	NaN
485.999798	0.002370	23.699892	0.220235	1205.656616	0.000000	NaN	NaN
486.999855	0.002312	23.122195	0.220608	1206.025269	0.000000	NaN	NaN
487.999912	0.002386	23.864948	0.221134	1206.544922	0.000000	NaN	NaN
488.999969	0.002362	23.617363	0.221545	1206.951172	0.000000	NaN	NaN
490.000026	0.002386	23.864948	0.222086	1207.485840	0.000000	NaN	NaN
490.999084	0.002337	23.369779	0.222633	1208.026123	0.000000	NaN	NaN
491.999141	0.002420	24.195060	0.223054	1208.442017	0.000000	NaN	NaN
492.999198	0.002312	23.122195	0.223579	1208.961304	0.000000	NaN	NaN
493.999255	0.002337	23.369779	0.223993	1209.369873	0.000000	NaN	NaN
494.999312	0.002386	23.864948	0.224575	1209.945068	0.000000	NaN	NaN
495.999370	0.002263	22.627026	0.225071	1210.435303	0.000000	NaN	NaN
496.999427	0.002395	23.947476	0.225498	1210.857178	0.000000	NaN	NaN
497.999484	0.002238	22.379442	0.226028	1211.380493	0.000000	NaN	NaN
498.999541	0.002362	23.617363	0.226539	1211.886108	0.000000	NaN	NaN
499.999598	0.002304	23.039667	0.227017	1212.358032	0.000000	NaN	NaN
500.999656	0.002312	23.122195	0.227524	1212.858643	0.000000	NaN	NaN
501.999713	0.002403	24.030004	0.228010	1213.339233	0.000000	NaN	NaN
502.999770	0.002420	24.195060	0.228383	1213.707275	0.000000	NaN	NaN
503.999827	0.002378	23.782420	0.228873	1214.191772	0.000000	NaN	NaN
504.999884	0.002411	24.112532	0.229477	1214.788574	0.000000	NaN	NaN
505.999942	0.002279	22.792082	0.229895	1215.201416	0.000000	NaN	NaN
506.999999	0.002395	23.947476	0.230416	1215.716553	0.000000	NaN	NaN
507.999056	0.002370	23.699892	0.230823	1216.118286	0.000000	NaN	NaN
508.999113	0.002386	23.864948	0.231384	1216.673096	0.000000	NaN	NaN
509.999170	0.002271	22.709554	0.231904	1217.186523	0.000000	NaN	NaN
510.999228	0.002279	22.792082	0.232332	1217.609131	0.000000	NaN	NaN
511.999285	0.002395	23.947476	0.232872	1218.142578	0.000000	NaN	NaN
512.999342	0.002353	23.534835	0.233330	1218.595459	0.000000	NaN	NaN
513.999399	0.002420	24.195060	0.233846	1219.105225	0.000000	NaN	NaN
514.999456	0.002320	23.204723	0.234348	1219.601318	0.000000	NaN	NaN
515.999514	0.002420	24.195060	0.234819	1220.067139	0.000000	NaN	NaN
516.999571	0.002345	23.452307	0.235253	1220.495972	0.000000	NaN	NaN
517.999628	0.002345	23.452307	0.235830	1221.065552	0.000000	NaN	NaN
518.999685	0.002362	23.617363	0.236211	1221.442261	0.000000	NaN	NaN
519.999742	0.002271	22.709554	0.236771	1221.995483	0.000000	NaN	NaN
520.999799	0.002428	24.277588	0.237242	1222.460815	0.000000	NaN	NaN
521.999857	0.002378	23.782420	0.237700	1222.913696	0.000000	NaN	NaN
522.999914	0.002403	24.030004	0.238268	1223.474487	0.000000	NaN	NaN
523.999971	0.002304	23.039667	0.238722	1223.922974	0.000000	NaN	NaN
525.000028	0.002411	24.112532	0.239157	1224.353149	0.000000	NaN	NaN
525.999085	0.002444	24.442645	0.239686	1224.875244	0.000000	NaN	NaN
526.999143	0.002329	23.287251	0.240100	1225.284424	0.000000	NaN	NaN
527.999200	0.002304	23.039667	0.240683	1225.861084	0.000000	NaN	NaN
528.999257	0.002362	23.617363	0.241178	1226.349609	0.000000	NaN	NaN
529.999314	0.002386	23.864948	0.241569	1226.736450	0.000000	NaN	NaN
530.999371	0.002345	23.452307	0.242067	1227.227905	0.000000	NaN	NaN
531.999429	0.002337	23.369779	0.242658	1227.811646	0.000000	NaN	NaN
532.999486	0.002370	23.699892	0.243072	1228.221436	0.000000	NaN	NaN
533.999543	0.002353	23.534835	0.243591	1228.733887	0.000000	NaN	NaN
534.999600	0.002411	24.112532	0.244117	1229.253174	0.000000	NaN	NaN
535.999657	0.002353	23.534835	0.244551	1229.682739	0.000000	NaN	NaN
536.999715	0.002370	23.699892	0.245081	1230.206299	0.000000	NaN	NaN
537.999772	0.002337	23.369779	0.245490	1230.609863	0.000000	NaN	NaN
538.999829	0.002411	24.112532	0.246017	1231.131348	0.000000	NaN	NaN
539.999886	0.002420	24.195060	0.246555	1231.662231	0.000000	NaN	NaN
540.999943	0.002436	24.360117	0.247019	1232.121094	0.000000	NaN	NaN
542.000001	0.002386	23.864948	0.247500	1232.596680	0.000000	NaN	NaN
542.999058	0.002601	26.010679	0.248106	1233.195312	0.000000	NaN	NaN
543.999115	0.002461	24.607701	0.248503	1233.587402	0.000000	NaN	NaN
544.999172	0.002411	24.112532	0.249058	1234.135620	0.000000	NaN	NaN
545.999229	0.002428	24.277588	0.249588	1234.659180	0.000000	NaN	NaN
546.999287	0.002403	24.030004	0.250059	1235.124634	0.000000	NaN	NaN
547.999344	0.002378	23.782420	0.250567	1235.626587	0.000000	NaN	NaN
548.999401	0.002411	24.112532	0.250997	1236.051636	0.000000	NaN	NaN
549.999458	0.002362	23.617363	0.251535	1236.583008	0.000000	NaN	NaN
550.999515	0.002320	23.204723	0.252124	1237.165405	0.000000	NaN	NaN
551.999573	0.002469	24.690229	0.252679	1237.713623	0.000000	NaN	NaN
552.999630	0.002188	21.884273	0.253052	1238.082275	0.000000	NaN	NaN
553.999687	0.002453	24.525173	0.253628	1238.651001	0.000000	NaN	NaN
554.999744	0.002353	23.534835	0.254058	1239.075928	0.000000	NaN	NaN
555.999801	0.002370	23.699892	0.254610	1239.621460	0.000000	NaN	NaN
556.999859	0.002329	23.287251	0.255142	1240.147095	0.000000	NaN	NaN
557.999916	0.002263	22.627026	0.255625	1240.624023	0.000000	NaN	NaN
558.999973	0.002494	24.937813	0.256124	1241.117310	0.000000	NaN	NaN
560.000030	0.002453	24.525173	0.256698	1241.683960	0.000000	NaN	NaN
560.999087	0.002378	23.782420	0.257166	1242.146606	0.000000	NaN	NaN
561.999145	0.002386	23.864948	0.257722	1242.696533	0.000000	NaN	NaN
562.999202	0.002353	23.534835	0.258264	1243.232056	0.000000	NaN	NaN
563.999259	0.002312	23.122195	0.258698	1243.660889	0.000000	NaN	NaN
564.999316	0.002420	24.195060	0.259247	1244.202759	0.000000	NaN	NaN
565.999373	0.002362	23.617363	0.259797	1244.746460	0.000000	NaN	NaN
566.999431	0.002428	24.277588	0.260282	1245.225098	0.000000	NaN	NaN
567.999488	0.002378	23.782420	0.260824	1245.761475	0.000000	NaN	NaN
568.999545	0.002535	25.350454	0.261405	1246.334595	0.000000	NaN	NaN
569.999602	0.002428	24.277588	0.261875	1246.799561	0.000000	NaN	NaN
570.999659	0.002428	24.277588	0.262407	1247.325195	0.000000	NaN	NaN
571.999716	0.002420	24.195060	0.262944	1247.856079	0.000000	NaN	NaN
572.999774	0.002386	23.864948	0.263380	1248.286743	0.000000	NaN	NaN
573.999831	0.002469	24.690229	0.263986	1248.885254	0.000000	NaN	NaN
574.999888	0.002403	24.030004	0.264536	1249.428711	0.000000	NaN	NaN
575.999945	0.002353	23.534835	0.265039	1249.925537	0.000000	NaN	NaN
577.000003	0.002345	23.452307	0.265570	1250.450439	0.000000	NaN	NaN
577.999060	0.002411	24.112532	0.266097	1250.970947	0.000000	NaN	NaN
578.999117	0.002469	24.690229	0.266694	1251.560791	0.000000	NaN	NaN
579.999174	0.002411	24.112532	0.267268	1252.127930	0.000000	NaN	NaN
580.999231	0.002279	22.792082	0.267868	1252.720581	0.000000	NaN	NaN
581.999289	0.002362	23.617363	0.268377	1253.223511	0.000000	NaN	NaN
582.999346	0.002345	23.452307	0.268998	1253.836914	0.000000	NaN	NaN
583.999403	0.002337	23.369779	0.269570	1254.402466	0.000000	NaN	NaN
584.999460	0.002362	23.617363	0.270129	1254.954590	0.000000	NaN	NaN
585.999517	0.002486	24.855285	0.270704	1255.522705	0.000000	NaN	NaN
586.999574	0.002436	24.360117	0.271287	1256.098755	0.000000	NaN	NaN
587.999632	0.002320	23.204723	0.271910	1256.714355	0.000000	NaN	NaN
588.999689	0.002345	23.452307	0.272464	1257.261841	0.000000	NaN	NaN
589.999746	0.002428	24.277588	0.273082	1257.872559	0.000000	NaN	NaN
590.999803	0.002329	23.287251	0.273756	1258.538330	0.000000	NaN	NaN
591.999860	0.002370	23.699892	0.274220	1258.997070	0.000000	NaN	NaN
592.999918	0.002370	23.699892	0.274963	1259.730957	0.000000	NaN	NaN
593.999975	0.002320	23.204723	0.275657	1260.416748	0.000000	NaN	NaN
595.000032	0.002320	23.204723	0.276221	1260.974487	0.000000	NaN	NaN
595.999089	0.002370	23.699892	0.276957	1261.701050	0.000000	NaN	NaN
596.999146	0.002345	23.452307	0.277677	1262.412842	0.000000	NaN	NaN
597.999204	0.002246	22.461970	0.278441	1263.167725	0.000000	NaN	NaN
598.999261	0.002320	23.204723	0.279240	1263.956787	0.000000	NaN	NaN
599.999318	0.002238	22.379442	0.279944	1264.652954	0.000000	NaN	NaN
600.999375	0.002172	21.719217	0.281053	1265.748779	0.000000	NaN	NaN
601.999432	0.002246	22.461970	0.283201	1267.870972	0.000000	NaN	NaN
602.999490	0.002205	22.049329	0.284377	1269.032227	0.000000	NaN	NaN
603.999547	0.002337	23.369779	0.285439	1270.082153	0.000000	NaN	NaN
604.999604	0.002155	21.554160	0.286475	1271.105225	0.000000	NaN	NaN
605.999661	0.002065	20.646351	0.287464	1272.082520	0.000000	NaN	NaN
606.999718	0.002197	21.966801	0.288535	1273.140747	0.000000	NaN	NaN
607.999776	0.002172	21.719217	0.289477	1274.071411	0.000000	NaN	NaN
608.999833	0.002139	21.389104	0.290305	1274.889893	0.000000	NaN	NaN
609.999890	0.002139	21.389104	0.291193	1275.767212	0.000000	NaN	NaN
610.999947	0.002106	21.058992	0.292129	1276.692505	0.000000	NaN	NaN
612.000004	0.002122	21.224048	0.292998	1277.550659	0.000000	NaN	NaN
612.999062	0.002056	20.563823	0.293841	1278.383667	0.000000	NaN	NaN
613.999119	0.002106	21.058992	0.294738	1279.269531	0.000000	NaN	NaN
614.999176	0.002056	20.563823	0.295461	1279.984375	0.000000	NaN	NaN
615.999233	0.002073	20.728879	0.296416	1280.927368	0.000000	NaN	NaN
616.999290	0.001974	19.738542	0.297212	1281.713867	0.000000	NaN	NaN
617.999348	0.002081	20.811407	0.298067	1282.559570	0.000000	NaN	NaN
618.999405	0.001966	19.656014	0.298866	1283.348389	0.000000	NaN	NaN
619.999462	0.002032	20.316239	0.299770	1284.241455	0.000000	NaN	NaN
620.999519	0.002073	20.728879	0.300549	1285.011719	0.000000	NaN	NaN
621.999576	0.002065	20.646351	0.301364	1285.816650	0.000000	NaN	NaN
622.999634	0.002131	21.306576	0.302230	1286.672363	0.000000	NaN	NaN
623.999691	0.002155	21.554160	0.303112	1287.544189	0.000000	NaN	NaN
624.999748	0.002065	20.646351	0.304042	1288.463135	0.000000	NaN	NaN
625.999805	0.001867	18.665676	0.304919	1289.329468	0.000000	NaN	NaN
626.999862	0.001974	19.738542	0.305708	1290.109009	0.000000	NaN	NaN
627.999920	0.001999	19.986126	0.306587	1290.976929	0.000000	NaN	NaN
628.999977	0.002056	20.563823	0.307467	1291.847290	0.000000	NaN	NaN
630.000034	0.002131	21.306576	0.308414	1292.782959	0.000000	NaN	NaN
630.999091	0.001966	19.656014	0.309269	1293.627075	0.000000	NaN	NaN
631.999148	0.001949	19.490957	0.310182	1294.529175	0.000000	NaN	NaN
632.999206	0.002023	20.233710	0.311017	1295.354736	0.000000	NaN	NaN
633.999263	0.001999	19.986126	0.311888	1296.215088	0.000000	NaN	NaN
634.999320	0.001941	19.408429	0.312752	1297.068604	0.000000	NaN	NaN
635.999377	0.001974	19.738542	0.313616	1297.922119	0.000000	NaN	NaN
636.999434	0.001999	19.986126	0.314551	1298.846436	0.000000	NaN	NaN
637.999491	0.002056	20.563823	0.315461	1299.745728	0.000000	NaN	NaN
638.999549	0.001924	19.243373	0.316427	1300.700195	0.000000	NaN	NaN
639.999606	0.001908	19.078317	0.317301	1301.563477	0.000000	NaN	NaN
640.999663	0.001900	18.995789	0.318125	1302.377808	0.000000	NaN	NaN
641.999720	0.001982	19.821070	0.319029	1303.270264	0.000000	NaN	NaN
642.999778	0.001924	19.243373	0.319923	1304.153564	0.000000	NaN	NaN
643.999835	0.001850	18.500620	0.320913	1305.132080	0.000000	NaN	NaN
644.999892	0.001850	18.500620	0.321820	1306.028198	0.000000	NaN	NaN
645.999949	0.001743	17.427754	0.322848	1307.044312	0.000000	NaN	NaN
647.000006	0.001867	18.665676	0.324345	1308.523682	0.000000	NaN	NaN
647.999063	0.001875	18.748204	0.325604	1309.766724	0.000000	NaN	NaN
648.999121	0.001817	18.170507	0.326659	1310.809814	0.000000	NaN	NaN
649.999178	0.001842	18.418092	0.327734	1311.871460	0.000000	NaN	NaN
650.999235	0.001792	17.922923	0.328703	1312.828857	0.000000	NaN	NaN
651.999292	0.001743	17.427754	0.329656	1313.770996	0.000000	NaN	NaN
652.999349	0.001669	16.685001	0.330800	1314.900757	0.000000	NaN	NaN
653.999407	0.001867	18.665676	0.331762	1315.851929	0.000000	NaN	NaN
654.999464	0.001858	18.583148	0.332635	1316.714478	0.000000	NaN	NaN
655.999521	0.001776	17.757867	0.333627	1317.694580	0.000000	NaN	NaN
656.999578	0.001718	17.180170	0.334572	1318.628174	0.000000	NaN	NaN
657.999635	0.001669	16.685001	0.335680	1319.722900	0.000000	NaN	NaN
658.999693	0.001693	16.932585	0.336642	1320.673706	0.000000	NaN	NaN
659.999750	0.001635	16.354889	0.337563	1321.583496	0.000000	NaN	NaN
660.999807	0.001586	15.859720	0.338531	1322.539307	0.000000	NaN	NaN
661.999864	0.001726	17.262698	0.339597	1323.592896	0.000000	NaN	NaN
662.999921	0.001784	17.840395	0.340599	1324.582642	0.000000	NaN	NaN
663.999979	0.001726	17.262698	0.341547	1325.519775	0.000000	NaN	NaN
665.000036	0.001528	15.282023	0.342394	1326.356689	0.000000	NaN	NaN
665.999093	0.001627	16.272360	0.343424	1327.373901	0.000000	NaN	NaN
666.999150	0.001503	15.034438	0.344474	1328.411255	0.000000	NaN	NaN
667.999207	0.001735	17.345226	0.345501	1329.426147	0.000000	NaN	NaN
668.999265	0.001751	17.510282	0.346503	1330.416016	0.000000	NaN	NaN
669.999322	0.001586	15.859720	0.347517	1331.418213	0.000000	NaN	NaN
670.999379	0.001545	15.447079	0.348572	1332.460449	0.000000	NaN	NaN
671.999436	0.001627	16.272360	0.349588	1333.464844	0.000000	NaN	NaN
672.999493	0.001520	15.199495	0.350655	1334.518677	0.000000	NaN	NaN
673.999551	0.001561	15.612135	0.351657	1335.508545	0.000000	NaN	NaN
674.999608	0.001487	14.869382	0.352663	1336.502686	0.000000	NaN	NaN
675.999665	0.001487	14.869382	0.353874	1337.699341	0.000000	NaN	NaN
676.999722	0.001462	14.621798	0.354874	1338.687134	0.000000	NaN	NaN
677.999779	0.001784	17.840395	0.355845	1339.646973	0.000000	NaN	NaN
678.999837	0.001462	14.621798	0.356928	1340.717407	0.000000	NaN	NaN
679.999894	0.001413	14.126629	0.357826	1341.603882	0.000000	NaN	NaN
680.999951	0.001446	14.456742	0.359056	1342.819336	0.000000	NaN	NaN
682.000008	0.001528	15.282023	0.360057	1343.808350	0.000000	NaN	NaN
682.999065	0.001495	14.951910	0.361183	1344.920898	0.000000	NaN	NaN
683.999122	0.001446	14.456742	0.362244	1345.969238	0.000000	NaN	NaN
684.999180	0.001437	14.374213	0.363439	1347.150146	0.000000	NaN	NaN
685.999237	0.001396	13.961573	0.364540	1348.237793	0.000000	NaN	NaN
686.999294	0.001355	13.548932	0.365638	1349.322998	0.000000	NaN	NaN
687.999351	0.001347	13.466404	0.366677	1350.349854	0.000000	NaN	NaN
688.999408	0.001380	13.796517	0.367761	1351.420044	0.000000	NaN	NaN
689.999466	0.001421	14.209157	0.368911	1352.556641	0.000000	NaN	NaN
690.999523	0.001487	14.869382	0.370036	1353.668213	0.000000	NaN	NaN
691.999580	0.001314	13.136292	0.371132	1354.751465	0.000000	NaN	NaN
692.999637	0.001355	13.548932	0.372199	1355.805298	0.000000	NaN	NaN
693.999695	0.001289	12.888707	0.373330	1356.923462	0.000000	NaN	NaN
694.999752	0.001297	12.971235	0.374556	1358.134033	0.000000	NaN	NaN
695.999809	0.001248	12.476067	0.375661	1359.225830	0.000000	NaN	NaN
696.999866	0.001256	12.558595	0.376798	1360.349365	0.000000	NaN	NaN
697.999923	0.001157	11.568257	0.377941	1361.478882	0.000000	NaN	NaN
698.999980	0.001272	12.723651	0.379126	1362.649658	0.000000	NaN	NaN
699.999038	0.001099	10.990560	0.380311	1363.820557	0.000000	NaN	NaN
700.999095	0.001223	12.228482	0.381539	1365.033447	0.000000	NaN	NaN
701.999152	0.001124	11.238145	0.382675	1366.156616	0.000000	NaN	NaN
702.999209	0.001124	11.238145	0.383805	1367.272583	0.000000	NaN	NaN
703.999266	0.001099	10.990560	0.385096	1368.548706	0.000000	NaN	NaN
704.999324	0.001025	10.247807	0.386217	1369.656250	0.000000	NaN	NaN
705.999381	0.001033	10.330335	0.387333	1370.758301	0.000000	NaN	NaN
706.999438	0.001066	10.660448	0.388497	1371.908447	0.000000	NaN	NaN
707.999495	0.001091	10.908032	0.389615	1373.013184	0.000000	NaN	NaN
708.999553	0.001124	11.238145	0.390897	1374.279663	0.000000	NaN	NaN
709.999610	0.000926	9.257470	0.392091	1375.459351	0.000000	NaN	NaN
710.999667	0.000876	8.762301	0.393266	1376.620850	0.000000	NaN	NaN
711.999724	0.000901	9.009885	0.394463	1377.803589	0.000000	NaN	NaN
712.999781	0.000917	9.174942	0.395804	1379.128296	0.000000	NaN	NaN
713.999839	0.001050	10.495392	0.396983	1380.293701	0.000000	NaN	NaN
714.999896	0.000752	7.524379	0.398172	1381.467896	0.000000	NaN	NaN
715.999953	0.000777	7.771963	0.399438	1382.719238	0.000000	NaN	NaN
717.000010	0.000728	7.276795	0.400712	1383.978027	0.000000	NaN	NaN
717.999067	0.000736	7.359323	0.402250	1385.497803	0.000000	NaN	NaN
718.999124	0.000744	7.441851	0.403553	1386.785400	0.000000	NaN	NaN
719.999182	0.000670	6.699098	0.404892	1388.107788	0.000000	NaN	NaN
720.999239	0.000670	6.699098	0.406303	1389.502319	0.000000	NaN	NaN
721.999296	0.000662	6.616570	0.407824	1391.004883	0.000000	NaN	NaN
722.999353	0.000571	5.708760	0.409531	1392.691162	0.000000	NaN	NaN
723.999410	0.000488	4.883479	0.411493	1394.630249	0.000000	NaN	NaN
724.999468	0.000389	3.893141	0.413439	1396.553223	0.000000	NaN	NaN
725.999525	0.000249	2.490163	0.415939	1399.022705	0.000000	NaN	NaN
726.999582	-0.000345	-3.451862	0.419611	1402.650879	0.000000	NaN	NaN
727.999639	-0.000213	-2.131412	0.435554	1418.403442	0.000000	NaN	NaN
728.999696	-0.000122	-1.223602	0.441720	1424.496338	0.000000	NaN	NaN
729.999754	-0.000131	-1.306131	0.445159	1427.893799	0.000000	NaN	NaN
730.999811	-0.000246	-2.461524	0.447596	1430.302124	0.000000	NaN	NaN
731.499839	-0.000205	-2.048884	0.448851	1431.541870	0.000000	NaN	NaN