File: data/57k_5-1_3 (190415).lvm
LabVIEW Measurement
Writer_Version	2
Reader_Version	2
Separator	Tab
Decimal_Separator	.
Multi_Headings	No
X_Columns	One
Time_Pref	Absolute
Operator	user
Description	Load(N)/Stress(MPa)/Distance A(pixel)/Strain A/Distance B(pixel)/Strain B/Poisson's ratio
Date	2019/04/15
Time	13:10:04.8134063300347318543
***End_of_Header***

Notes	X 값은 오직 다음과 같을 때에만 유효함이 보장됩니다. Dev1/ai0
Channels	7
Samples	1	1	1	1	1	1	1
Date	2019/04/15	2019/04/15	2019/04/15	2019/04/15	2019/04/15	2019/04/15	2019/04/15
Time	14:36:02.8134271300347318436	14:36:02.8134271300347318436	14:36:02.813426971435546875	14:36:02.813426971435546875	14:36:02.813426971435546875	14:36:02.813426971435546875	14:36:02.813426971435546875
Y_Unit_Label	Volts	Volts
X_Dimension	Time	Time	Time	Time	Time	Time	Time
X0	0.0000000000000000E+0	0.0000000000000000E+0	0.0000000000000000E+0	0.0000000000000000E+0	0.0000000000000000E+0	0.0000000000000000E+0	0.0000000000000000E+0
Delta_X	0.000000	0.000000	1.000000	1.000000	1.000000	1.000000	1.000000
***End_of_Header***
X_Value	Dev1/ai0	Dev1/ai0 1	Untitled	Untitled 1	Untitled 2	Untitled 3	Untitled 4	Comment
0.000000	9.221289E-5	0.922129	-7.313490E-5	992.042725	0.000000	NaN	NaN
1.500086	9.221289E-5	0.922129	1.323223E-5	992.055908	0.000000	NaN	NaN
3.000172	2.619039E-5	0.261904	0.000435	992.473816	0.000000	NaN	NaN
4.500257	0.000266	2.655220	0.000862	992.898315	0.000000	NaN	NaN
5.999343	0.000249	2.490163	0.001180	993.213074	0.000000	NaN	NaN
7.499429	0.000233	2.325107	0.001595	993.625549	0.000000	NaN	NaN
8.999515	0.000233	2.325107	0.001828	993.856201	0.000000	NaN	NaN
10.499601	0.000290	2.902804	0.002261	994.285706	0.000000	NaN	NaN
11.999686	0.000695	6.946682	0.002733	994.754089	0.000000	NaN	NaN
13.499772	0.000497	4.966007	0.003055	995.073303	0.000000	NaN	NaN
14.999858	0.000530	5.296120	0.003516	995.531067	0.000000	NaN	NaN
16.499944	0.000571	5.708760	0.003921	995.932068	0.000000	NaN	NaN
18.000030	0.000513	5.131063	0.004332	996.340332	0.000000	NaN	NaN
19.500115	0.000794	7.937020	0.004728	996.732910	0.000000	NaN	NaN
21.000201	0.000686	6.864154	0.005131	997.132507	0.000000	NaN	NaN
22.500287	0.000917	9.174942	0.005587	997.585144	0.000000	NaN	NaN
23.999373	0.000711	7.111738	0.006021	998.015625	0.000000	NaN	NaN
25.499459	0.000835	8.349660	0.006575	998.565552	0.000000	NaN	NaN
26.999544	0.001058	10.577920	0.007030	999.017151	0.000000	NaN	NaN
28.499630	0.000959	9.587582	0.007538	999.521179	0.000000	NaN	NaN
29.999716	0.001025	10.247807	0.008030	1000.009033	0.000000	NaN	NaN
31.499802	0.001107	11.073088	0.008589	1000.562927	0.000000	NaN	NaN
32.999887	0.001124	11.238145	0.009142	1001.111877	0.000000	NaN	NaN
34.499973	0.001116	11.155617	0.009714	1001.679443	0.000000	NaN	NaN
36.000059	0.001239	12.393538	0.010329	1002.289551	0.000000	NaN	NaN
37.500145	0.001223	12.228482	0.010974	1002.929810	0.000000	NaN	NaN
39.000231	0.001264	12.641123	0.011596	1003.546814	0.000000	NaN	NaN
40.499316	0.001429	14.291685	0.012183	1004.128357	0.000000	NaN	NaN
41.999402	0.001355	13.548932	0.012905	1004.845459	0.000000	NaN	NaN
43.499488	0.001495	14.951910	0.013463	1005.398987	0.000000	NaN	NaN
44.999574	0.001396	13.961573	0.014143	1006.073425	0.000000	NaN	NaN
46.499660	0.001619	16.189832	0.014835	1006.759277	0.000000	NaN	NaN
47.999745	0.001495	14.951910	0.015304	1007.225281	0.000000	NaN	NaN
49.499831	0.001635	16.354889	0.015858	1007.774719	0.000000	NaN	NaN
50.999917	0.001677	16.767529	0.016607	1008.517944	0.000000	NaN	NaN
52.500003	0.001693	16.932585	0.017115	1009.021729	0.000000	NaN	NaN
54.000089	0.001702	17.015114	0.017688	1009.590393	0.000000	NaN	NaN
55.500174	0.001817	18.170507	0.018215	1010.112610	0.000000	NaN	NaN
57.000260	0.001726	17.262698	0.018912	1010.804443	0.000000	NaN	NaN
58.499346	0.001776	17.757867	0.019354	1011.242859	0.000000	NaN	NaN
59.999432	0.001858	18.583148	0.020026	1011.909363	0.000000	NaN	NaN
61.499518	0.001842	18.418092	0.020422	1012.302246	0.000000	NaN	NaN
62.999603	0.001941	19.408429	0.021075	1012.950012	0.000000	NaN	NaN
64.499689	0.001916	19.160845	0.020491	1012.370728	0.000000	NaN	NaN
65.999775	0.001949	19.490957	0.021137	1013.011536	0.000000	NaN	NaN
67.499861	0.001957	19.573485	0.021850	1013.719238	0.000000	NaN	NaN
68.999946	0.001949	19.490957	0.022381	1014.245605	0.000000	NaN	NaN
70.500032	0.001982	19.821070	0.023076	1014.934937	0.000000	NaN	NaN
72.000118	0.001949	19.490957	0.023682	1015.536194	0.000000	NaN	NaN
73.500204	0.002089	20.893935	0.024354	1016.203369	0.000000	NaN	NaN
75.000290	0.002007	20.068654	0.025559	1017.398743	0.000000	NaN	NaN
76.499376	0.002023	20.233710	0.026234	1018.067566	0.000000	NaN	NaN
77.999461	0.002147	21.471632	0.026982	1018.809692	0.000000	NaN	NaN
79.499547	0.001999	19.986126	0.027622	1019.445068	0.000000	NaN	NaN
80.999633	0.001916	19.160845	0.028301	1020.118896	0.000000	NaN	NaN
82.499719	0.001990	19.903598	0.029073	1020.884277	0.000000	NaN	NaN
83.999804	0.002122	21.224048	0.029803	1021.608765	0.000000	NaN	NaN
85.499890	0.002221	22.214385	0.030576	1022.375122	0.000000	NaN	NaN
86.999976	0.002015	20.151182	0.031210	1023.004211	0.000000	NaN	NaN
88.500062	0.002114	21.141520	0.031855	1023.644470	0.000000	NaN	NaN
90.000148	0.002213	22.131857	0.032551	1024.334229	0.000000	NaN	NaN
91.500234	0.002073	20.728879	0.033373	1025.149780	0.000000	NaN	NaN
92.999319	0.002155	21.554160	0.034092	1025.863892	0.000000	NaN	NaN
94.499405	0.002230	22.296913	0.034847	1026.612427	0.000000	NaN	NaN
95.999491	0.002098	20.976463	0.035546	1027.306030	0.000000	NaN	NaN
97.499577	0.002205	22.049329	0.036296	1028.050049	0.000000	NaN	NaN
98.999662	0.002246	22.461970	0.037068	1028.816162	0.000000	NaN	NaN
100.499748	0.002073	20.728879	0.037873	1029.613892	0.000000	NaN	NaN
101.999834	0.002238	22.379442	0.038586	1030.321289	0.000000	NaN	NaN
103.499920	0.002197	21.966801	0.039438	1031.167114	0.000000	NaN	NaN
105.000006	0.002362	23.617363	0.040169	1031.892212	0.000000	NaN	NaN
106.500091	0.002155	21.554160	0.040960	1032.677124	0.000000	NaN	NaN
108.000177	0.002147	21.471632	0.041629	1033.340088	0.000000	NaN	NaN
109.500263	0.002081	20.811407	0.042538	1034.241943	0.000000	NaN	NaN
110.999349	0.002147	21.471632	0.043213	1034.911499	0.000000	NaN	NaN
112.499435	0.002246	22.461970	0.044038	1035.730469	0.000000	NaN	NaN
113.999520	0.002271	22.709554	0.044724	1036.411011	0.000000	NaN	NaN
115.499606	0.002089	20.893935	0.045451	1037.132080	0.000000	NaN	NaN
116.999692	0.002238	22.379442	0.046313	1037.987061	0.000000	NaN	NaN
118.499778	0.002106	21.058992	0.047069	1038.737427	0.000000	NaN	NaN
119.999864	0.002197	21.966801	0.047857	1039.519043	0.000000	NaN	NaN
121.499949	0.002254	22.544498	0.048667	1040.322632	0.000000	NaN	NaN
123.000035	0.002197	21.966801	0.049387	1041.037109	0.000000	NaN	NaN
124.500121	0.002164	21.636688	0.050000	1041.645142	0.000000	NaN	NaN
126.000207	0.002353	23.534835	0.050894	1042.531616	0.000000	NaN	NaN
127.500293	0.002287	22.874610	0.051573	1043.205566	0.000000	NaN	NaN
128.999378	0.002296	22.957138	0.052374	1044.000122	0.000000	NaN	NaN
130.499464	0.002230	22.296913	0.053021	1044.642212	0.000000	NaN	NaN
131.999550	0.002246	22.461970	0.053847	1045.460937	0.000000	NaN	NaN
133.499636	0.002164	21.636688	0.054546	1046.154785	0.000000	NaN	NaN
134.999721	0.002279	22.792082	0.055325	1046.927002	0.000000	NaN	NaN
136.499807	0.002271	22.709554	0.056059	1047.655273	0.000000	NaN	NaN
137.999893	0.002197	21.966801	0.056912	1048.502075	0.000000	NaN	NaN
139.499979	0.002246	22.461970	0.057577	1049.161377	0.000000	NaN	NaN
141.000065	0.002263	22.627026	0.058232	1049.811035	0.000000	NaN	NaN
142.500151	0.002304	23.039667	0.059143	1050.715210	0.000000	NaN	NaN
144.000236	0.002329	23.287251	0.059742	1051.308960	0.000000	NaN	NaN
145.499322	0.002436	24.360117	0.060581	1052.141479	0.000000	NaN	NaN
146.999408	0.002337	23.369779	0.061311	1052.865723	0.000000	NaN	NaN
148.499494	0.002246	22.461970	0.062084	1053.633057	0.000000	NaN	NaN
149.999580	0.002461	24.607701	0.062789	1054.332397	0.000000	NaN	NaN
151.499665	0.002312	23.122195	0.063719	1055.255127	0.000000	NaN	NaN
152.999751	0.002271	22.709554	0.064294	1055.824707	0.000000	NaN	NaN
154.499837	0.002296	22.957138	0.065214	1056.737671	0.000000	NaN	NaN
155.999923	0.002279	22.792082	0.065909	1057.427002	0.000000	NaN	NaN
157.500009	0.002246	22.461970	0.066613	1058.125732	0.000000	NaN	NaN
159.000094	0.002320	23.204723	0.067386	1058.892090	0.000000	NaN	NaN
160.500180	0.002320	23.204723	0.068131	1059.631470	0.000000	NaN	NaN
162.000266	0.002461	24.607701	0.068866	1060.361084	0.000000	NaN	NaN
163.499352	0.002329	23.287251	0.069635	1061.123291	0.000000	NaN	NaN
164.999437	0.002329	23.287251	0.070365	1061.848022	0.000000	NaN	NaN
166.499523	0.002188	21.884273	0.071087	1062.563965	0.000000	NaN	NaN
167.999609	0.002320	23.204723	0.071969	1063.438843	0.000000	NaN	NaN
169.499695	0.002230	22.296913	0.072720	1064.184448	0.000000	NaN	NaN
170.999781	0.002510	25.102870	0.073514	1064.971924	0.000000	NaN	NaN
172.499866	0.002370	23.699892	0.074107	1065.560059	0.000000	NaN	NaN
173.999952	0.002494	24.937813	0.074967	1066.413086	0.000000	NaN	NaN
175.500038	0.002345	23.452307	0.075632	1067.073364	0.000000	NaN	NaN
177.000124	0.002386	23.864948	0.076437	1067.871338	0.000000	NaN	NaN
178.500210	0.002320	23.204723	0.077151	1068.579468	0.000000	NaN	NaN
180.000295	0.002378	23.782420	0.077914	1069.336548	0.000000	NaN	NaN
181.499381	0.002238	22.379442	0.078674	1070.090698	0.000000	NaN	NaN
182.999467	0.002453	24.525173	0.079458	1070.868042	0.000000	NaN	NaN
184.499553	0.002362	23.617363	0.080243	1071.646973	0.000000	NaN	NaN
185.999639	0.002345	23.452307	0.080889	1072.288452	0.000000	NaN	NaN
187.499724	0.002411	24.112532	0.081664	1073.057007	0.000000	NaN	NaN
188.999810	0.002543	25.432982	0.082483	1073.869141	0.000000	NaN	NaN
190.499896	0.002370	23.699892	0.083230	1074.610840	0.000000	NaN	NaN
191.999982	0.002477	24.772757	0.083867	1075.242310	0.000000	NaN	NaN
193.500068	0.002395	23.947476	0.084740	1076.108276	0.000000	NaN	NaN
195.000153	0.002370	23.699892	0.085415	1076.777710	0.000000	NaN	NaN
196.500239	0.002436	24.360117	0.086413	1077.767944	0.000000	NaN	NaN
197.999325	0.002477	24.772757	0.087031	1078.381226	0.000000	NaN	NaN
199.499411	0.002527	25.267926	0.087842	1079.185303	0.000000	NaN	NaN
200.999496	0.002395	23.947476	0.088432	1079.771118	0.000000	NaN	NaN
202.499582	0.002469	24.690229	0.089275	1080.607422	0.000000	NaN	NaN
203.999668	0.002527	25.267926	0.089885	1081.212158	0.000000	NaN	NaN
205.499754	0.002510	25.102870	0.090722	1082.042480	0.000000	NaN	NaN
206.999840	0.002345	23.452307	0.091368	1082.683594	0.000000	NaN	NaN
208.499926	0.002370	23.699892	0.092026	1083.336792	0.000000	NaN	NaN
210.000011	0.002329	23.287251	0.092894	1084.197510	0.000000	NaN	NaN
211.500097	0.002486	24.855285	0.093652	1084.949463	0.000000	NaN	NaN
213.000183	0.002477	24.772757	0.094489	1085.779297	0.000000	NaN	NaN
214.500269	0.002477	24.772757	0.095159	1086.444580	0.000000	NaN	NaN
215.999354	0.002370	23.699892	0.095913	1087.192505	0.000000	NaN	NaN
217.499440	0.002444	24.442645	0.096673	1087.946289	0.000000	NaN	NaN
218.999526	0.002519	25.185398	0.097375	1088.643311	0.000000	NaN	NaN
220.499612	0.002560	25.598038	0.098157	1089.418213	0.000000	NaN	NaN
221.999698	0.002395	23.947476	0.098992	1090.246704	0.000000	NaN	NaN
223.499783	0.002395	23.947476	0.099745	1090.994141	0.000000	NaN	NaN
224.999869	0.002378	23.782420	0.100521	1091.763794	0.000000	NaN	NaN
226.499955	0.002494	24.937813	0.101284	1092.520508	0.000000	NaN	NaN
228.000041	0.002576	25.763095	0.101933	1093.164551	0.000000	NaN	NaN
229.500127	0.002568	25.680567	0.102736	1093.961182	0.000000	NaN	NaN
231.000212	0.002601	26.010679	0.103546	1094.764404	0.000000	NaN	NaN
232.500298	0.002403	24.030004	0.104149	1095.362671	0.000000	NaN	NaN
233.999384	0.002543	25.432982	0.104986	1096.193481	0.000000	NaN	NaN
235.499470	0.002411	24.112532	0.105600	1096.802002	0.000000	NaN	NaN
236.999556	0.002386	23.864948	0.106420	1097.616211	0.000000	NaN	NaN
238.499641	0.002585	25.845623	0.107179	1098.368408	0.000000	NaN	NaN
239.999727	0.002684	26.835960	0.108045	1099.227539	0.000000	NaN	NaN
241.499813	0.002494	24.937813	0.108675	1099.853271	0.000000	NaN	NaN
242.999899	0.002477	24.772757	0.109368	1100.540527	0.000000	NaN	NaN
244.499985	0.002386	23.864948	0.110067	1101.233521	0.000000	NaN	NaN
246.000070	0.002535	25.350454	0.110777	1101.937744	0.000000	NaN	NaN
247.500156	0.002684	26.835960	0.111496	1102.651733	0.000000	NaN	NaN
249.000242	0.002461	24.607701	0.112313	1103.462280	0.000000	NaN	NaN
250.499328	0.002453	24.525173	0.113029	1104.172363	0.000000	NaN	NaN
251.999414	0.002411	24.112532	0.113804	1104.940674	0.000000	NaN	NaN
253.499499	0.002543	25.432982	0.114616	1105.746460	0.000000	NaN	NaN
254.999585	0.002469	24.690229	0.115184	1106.310181	0.000000	NaN	NaN
256.499671	0.002535	25.350454	0.115973	1107.093384	0.000000	NaN	NaN
257.999757	0.002593	25.928151	0.116585	1107.700073	0.000000	NaN	NaN
259.499843	0.002560	25.598038	0.117427	1108.535156	0.000000	NaN	NaN
260.999928	0.002560	25.598038	0.117976	1109.079712	0.000000	NaN	NaN
262.500014	0.002527	25.267926	0.118729	1109.827393	0.000000	NaN	NaN
264.000100	0.002585	25.845623	0.119470	1110.562256	0.000000	NaN	NaN
265.500186	0.002502	25.020342	0.120270	1111.355957	0.000000	NaN	NaN
267.000271	0.002469	24.690229	0.121435	1112.511475	0.000000	NaN	NaN
268.499357	0.002717	27.166073	0.122138	1113.209229	0.000000	NaN	NaN
269.999443	0.002552	25.515510	0.122643	1113.709961	0.000000	NaN	NaN
271.499529	0.002733	27.331129	0.123770	1114.828369	0.000000	NaN	NaN
272.999615	0.002527	25.267926	0.124552	1115.604004	0.000000	NaN	NaN
274.499701	0.002667	26.670904	0.125268	1116.313843	0.000000	NaN	NaN
275.999786	0.002692	26.918488	0.125988	1117.028687	0.000000	NaN	NaN
277.499872	0.002642	26.423320	0.126549	1117.585205	0.000000	NaN	NaN
278.999958	0.002543	25.432982	0.127442	1118.470703	0.000000	NaN	NaN
280.500044	0.002609	26.093207	0.127985	1119.008789	0.000000	NaN	NaN
282.000130	0.002642	26.423320	0.128878	1119.895142	0.000000	NaN	NaN
283.500215	0.002642	26.423320	0.129421	1120.434326	0.000000	NaN	NaN
285.000301	0.002585	25.845623	0.130093	1121.100464	0.000000	NaN	NaN
286.499387	0.002684	26.835960	0.130884	1121.885498	0.000000	NaN	NaN
287.999473	0.002783	27.826298	0.131636	1122.631348	0.000000	NaN	NaN
289.499558	0.002576	25.763095	0.132277	1123.267334	0.000000	NaN	NaN
290.999644	0.002700	27.001017	0.132850	1123.835693	0.000000	NaN	NaN
292.499730	0.002609	26.093207	0.133687	1124.665649	0.000000	NaN	NaN
293.999816	0.002758	27.578713	0.134366	1125.339233	0.000000	NaN	NaN
295.499902	0.002807	28.073882	0.135131	1126.098633	0.000000	NaN	NaN
296.999987	0.002733	27.331129	0.135797	1126.758789	0.000000	NaN	NaN
298.500073	0.002799	27.991354	0.136546	1127.502441	0.000000	NaN	NaN
300.000159	0.002717	27.166073	0.137320	1128.269775	0.000000	NaN	NaN
301.500245	0.002593	25.928151	0.138130	1129.073975	0.000000	NaN	NaN
302.999330	0.002684	26.835960	0.138729	1129.668213	0.000000	NaN	NaN
304.499416	0.002700	27.001017	0.139491	1130.423462	0.000000	NaN	NaN
305.999502	0.002552	25.515510	0.140208	1131.134766	0.000000	NaN	NaN
307.499588	0.002634	26.340792	0.140911	1131.832397	0.000000	NaN	NaN
308.999674	0.002576	25.763095	0.141593	1132.509155	0.000000	NaN	NaN
310.499760	0.002684	26.835960	0.142290	1133.200684	0.000000	NaN	NaN
311.999845	0.002799	27.991354	0.142980	1133.884644	0.000000	NaN	NaN
313.499931	0.002725	27.248601	0.143810	1134.708740	0.000000	NaN	NaN
315.000017	0.002684	26.835960	0.144416	1135.310059	0.000000	NaN	NaN
316.500103	0.002840	28.403995	0.145091	1135.979492	0.000000	NaN	NaN
318.000188	0.002791	27.908826	0.145809	1136.691406	0.000000	NaN	NaN
319.500274	0.002774	27.743770	0.146444	1137.321289	0.000000	NaN	NaN
320.999360	0.002783	27.826298	0.147166	1138.037354	0.000000	NaN	NaN
322.499446	0.002659	26.588376	0.147899	1138.765259	0.000000	NaN	NaN
323.999532	0.002659	26.588376	0.148467	1139.328369	0.000000	NaN	NaN
325.499618	0.002626	26.258263	0.149383	1140.237427	0.000000	NaN	NaN
326.999703	0.002766	27.661242	0.150042	1140.891113	0.000000	NaN	NaN
328.499789	0.002642	26.423320	0.150738	1141.581421	0.000000	NaN	NaN
329.999875	0.002626	26.258263	0.151524	1142.361328	0.000000	NaN	NaN
331.499961	0.002708	27.083545	0.152156	1142.987549	0.000000	NaN	NaN
333.000046	0.002840	28.403995	0.152732	1143.559082	0.000000	NaN	NaN
334.500132	0.002725	27.248601	0.153597	1144.417114	0.000000	NaN	NaN
336.000218	0.002750	27.496185	0.154064	1144.881226	0.000000	NaN	NaN
337.500304	0.002725	27.248601	0.154855	1145.665527	0.000000	NaN	NaN
338.999390	0.002906	29.064220	0.155497	1146.302612	0.000000	NaN	NaN
340.499475	0.002642	26.423320	0.156244	1147.042969	0.000000	NaN	NaN
341.999561	0.002708	27.083545	0.156966	1147.759399	0.000000	NaN	NaN
343.499647	0.002642	26.423320	0.157648	1148.436768	0.000000	NaN	NaN
344.999733	0.002840	28.403995	0.158304	1149.086914	0.000000	NaN	NaN
346.499819	0.002824	28.238938	0.159131	1149.907471	0.000000	NaN	NaN
347.999904	0.002700	27.001017	0.159753	1150.524292	0.000000	NaN	NaN
349.499990	0.002651	26.505848	0.160355	1151.122070	0.000000	NaN	NaN
351.000076	0.002766	27.661242	0.161181	1151.941284	0.000000	NaN	NaN
352.500162	0.002873	28.734107	0.161761	1152.516479	0.000000	NaN	NaN
354.000248	0.002733	27.331129	0.162589	1153.337891	0.000000	NaN	NaN
355.499333	0.002791	27.908826	0.163253	1153.997070	0.000000	NaN	NaN
356.999419	0.002774	27.743770	0.163971	1154.709106	0.000000	NaN	NaN
358.499505	0.002824	28.238938	0.164651	1155.383911	0.000000	NaN	NaN
359.999591	0.002857	28.569051	0.165261	1155.988770	0.000000	NaN	NaN
361.499677	0.002807	28.073882	0.166020	1156.741821	0.000000	NaN	NaN
362.999762	0.002807	28.073882	0.166692	1157.408203	0.000000	NaN	NaN
364.499848	0.002865	28.651579	0.167368	1158.079102	0.000000	NaN	NaN
365.999934	0.002816	28.156410	0.168129	1158.834351	0.000000	NaN	NaN
367.500020	0.002741	27.413657	0.168749	1159.449097	0.000000	NaN	NaN
369.000106	0.002906	29.064220	0.169411	1160.105347	0.000000	NaN	NaN
370.500191	0.002840	28.403995	0.170165	1160.853760	0.000000	NaN	NaN
372.000277	0.002766	27.661242	0.170795	1161.479126	0.000000	NaN	NaN
373.499363	0.002840	28.403995	0.171523	1162.201172	0.000000	NaN	NaN
374.999449	0.002758	27.578713	0.172000	1162.673950	0.000000	NaN	NaN
376.499535	0.002882	28.816635	0.172000	1162.674316	0.000000	NaN	NaN
377.999620	0.002807	28.073882	0.172636	1163.305420	0.000000	NaN	NaN
379.499706	0.002840	28.403995	0.173363	1164.026367	0.000000	NaN	NaN
380.999792	0.002849	28.486523	0.174157	1164.813477	0.000000	NaN	NaN
382.499878	0.002840	28.403995	0.174809	1165.460937	0.000000	NaN	NaN
383.999963	0.002799	27.991354	0.175433	1166.079468	0.000000	NaN	NaN
385.500049	0.002774	27.743770	0.176217	1166.857666	0.000000	NaN	NaN
387.000135	0.002832	28.321467	0.176894	1167.528931	0.000000	NaN	NaN
388.500221	0.002915	29.146748	0.177583	1168.212769	0.000000	NaN	NaN
390.000307	0.002824	28.238938	0.178282	1168.906494	0.000000	NaN	NaN
391.499393	0.002791	27.908826	0.179027	1169.645264	0.000000	NaN	NaN
392.999478	0.002807	28.073882	0.179751	1170.363281	0.000000	NaN	NaN
394.499564	0.002807	28.073882	0.180334	1170.941895	0.000000	NaN	NaN
395.999650	0.002865	28.651579	0.181049	1171.651367	0.000000	NaN	NaN
397.499736	0.002832	28.321467	0.181804	1172.399780	0.000000	NaN	NaN
398.999821	0.002824	28.238938	0.182429	1173.019897	0.000000	NaN	NaN
400.499907	0.002840	28.403995	0.183240	1173.824463	0.000000	NaN	NaN
401.999993	0.002824	28.238938	0.183867	1174.446289	0.000000	NaN	NaN
403.500079	0.002807	28.073882	0.184647	1175.220825	0.000000	NaN	NaN
405.000165	0.003030	30.302142	0.185271	1175.839600	0.000000	NaN	NaN
406.500251	0.002972	29.724445	0.186001	1176.563965	0.000000	NaN	NaN
407.999336	0.002939	29.394332	0.186735	1177.291748	0.000000	NaN	NaN
409.499422	0.002824	28.238938	0.187501	1178.052124	0.000000	NaN	NaN
410.999508	0.002915	29.146748	0.188167	1178.712280	0.000000	NaN	NaN
412.499594	0.002939	29.394332	0.188815	1179.355225	0.000000	NaN	NaN
413.999679	0.002972	29.724445	0.189592	1180.126465	0.000000	NaN	NaN
415.499765	0.002807	28.073882	0.190278	1180.807007	0.000000	NaN	NaN
416.999851	0.002923	29.229276	0.191004	1181.526978	0.000000	NaN	NaN
418.499937	0.002906	29.064220	0.191747	1182.263916	0.000000	NaN	NaN
420.000023	0.002915	29.146748	0.192410	1182.921875	0.000000	NaN	NaN
421.500108	0.002956	29.559388	0.193141	1183.646851	0.000000	NaN	NaN
423.000194	0.003088	30.879838	0.193887	1184.386963	0.000000	NaN	NaN
424.500280	0.002948	29.476860	0.194569	1185.063354	0.000000	NaN	NaN
425.999366	0.002931	29.311804	0.195296	1185.785156	0.000000	NaN	NaN
427.499452	0.002807	28.073882	0.195995	1186.477783	0.000000	NaN	NaN
428.999537	0.002873	28.734107	0.196710	1187.187500	0.000000	NaN	NaN
430.499623	0.002923	29.229276	0.197356	1187.827881	0.000000	NaN	NaN
431.999709	0.003129	31.292479	0.198154	1188.619995	0.000000	NaN	NaN
433.499795	0.003038	30.384670	0.198808	1189.268921	0.000000	NaN	NaN
434.999881	0.003005	30.054557	0.199565	1190.019897	0.000000	NaN	NaN
436.499966	0.002849	28.486523	0.200192	1190.641724	0.000000	NaN	NaN
438.000052	0.002873	28.734107	0.200856	1191.300903	0.000000	NaN	NaN
439.500138	0.003154	31.540063	0.201601	1192.039429	0.000000	NaN	NaN
441.000224	0.002939	29.394332	0.202230	1192.663696	0.000000	NaN	NaN
442.499310	0.002865	28.651579	0.202893	1193.321655	0.000000	NaN	NaN
443.999395	0.003005	30.054557	0.203607	1194.029419	0.000000	NaN	NaN
445.499481	0.003022	30.219613	0.204300	1194.717041	0.000000	NaN	NaN
446.999567	0.002783	27.826298	0.204988	1195.399780	0.000000	NaN	NaN
448.499653	0.002873	28.734107	0.205709	1196.115234	0.000000	NaN	NaN
449.999738	0.002807	28.073882	0.206329	1196.729858	0.000000	NaN	NaN
451.499824	0.003063	30.632254	0.207149	1197.543823	0.000000	NaN	NaN
452.999910	0.002873	28.734107	0.207803	1198.192627	0.000000	NaN	NaN
454.499996	0.003005	30.054557	0.208465	1198.848999	0.000000	NaN	NaN
456.000082	0.003063	30.632254	0.209204	1199.582153	0.000000	NaN	NaN
457.500168	0.002890	28.899163	0.209796	1200.169800	0.000000	NaN	NaN
459.000253	0.002972	29.724445	0.210544	1200.911255	0.000000	NaN	NaN
460.499339	0.002873	28.734107	0.211275	1201.636597	0.000000	NaN	NaN
461.999425	0.002906	29.064220	0.211912	1202.268799	0.000000	NaN	NaN
463.499511	0.002840	28.403995	0.212590	1202.940552	0.000000	NaN	NaN
464.999596	0.002972	29.724445	0.213330	1203.675049	0.000000	NaN	NaN
466.499682	0.002989	29.889501	0.213976	1204.316406	0.000000	NaN	NaN
467.999768	0.002997	29.972029	0.214704	1205.038574	0.000000	NaN	NaN
469.499854	0.002972	29.724445	0.215398	1205.726929	0.000000	NaN	NaN
470.999940	0.002964	29.641917	0.216082	1206.405396	0.000000	NaN	NaN
472.500025	0.002816	28.156410	0.216798	1207.115723	0.000000	NaN	NaN
474.000111	0.002972	29.724445	0.217430	1207.742920	0.000000	NaN	NaN
475.500197	0.002807	28.073882	0.218193	1208.499756	0.000000	NaN	NaN
477.000283	0.002774	27.743770	0.218806	1209.107544	0.000000	NaN	NaN
478.499369	0.003030	30.302142	0.219489	1209.785278	0.000000	NaN	NaN
479.999454	0.002964	29.641917	0.220065	1210.356567	0.000000	NaN	NaN
481.499540	0.002989	29.889501	0.220848	1211.133545	0.000000	NaN	NaN
482.999626	0.002956	29.559388	0.221485	1211.764893	0.000000	NaN	NaN
484.499712	0.003030	30.302142	0.222238	1212.512085	0.000000	NaN	NaN
485.999798	0.002898	28.981692	0.222868	1213.137451	0.000000	NaN	NaN
487.499883	0.003104	31.044895	0.223586	1213.849609	0.000000	NaN	NaN
488.999969	0.002981	29.806973	0.224224	1214.482544	0.000000	NaN	NaN
490.500055	0.003055	30.549726	0.225002	1215.254761	0.000000	NaN	NaN
492.000141	0.002956	29.559388	0.225695	1215.941895	0.000000	NaN	NaN
493.500227	0.002956	29.559388	0.226408	1216.649170	0.000000	NaN	NaN
494.999312	0.002898	28.981692	0.227034	1217.270142	0.000000	NaN	NaN
496.499398	0.002857	28.569051	0.227623	1217.854370	0.000000	NaN	NaN
497.999484	0.003096	30.962367	0.228397	1218.622314	0.000000	NaN	NaN
499.499570	0.003055	30.549726	0.229104	1219.323608	0.000000	NaN	NaN
500.999656	0.003104	31.044895	0.229927	1220.140137	0.000000	NaN	NaN
502.499741	0.002997	29.972029	0.230558	1220.766113	0.000000	NaN	NaN
503.999827	0.002989	29.889501	0.231333	1221.534790	0.000000	NaN	NaN
505.499913	0.003005	30.054557	0.231962	1222.158813	0.000000	NaN	NaN
506.999999	0.003071	30.714782	0.232650	1222.841064	0.000000	NaN	NaN
508.500085	0.003138	31.375007	0.233227	1223.414062	0.000000	NaN	NaN
510.000170	0.002981	29.806973	0.233992	1224.172974	0.000000	NaN	NaN
511.500256	0.002956	29.559388	0.234687	1224.862427	0.000000	NaN	NaN
512.999342	0.003071	30.714782	0.235433	1225.602295	0.000000	NaN	NaN
514.499428	0.003088	30.879838	0.236107	1226.270874	0.000000	NaN	NaN
515.999514	0.002989	29.889501	0.236656	1226.815308	0.000000	NaN	NaN
517.499599	0.002791	27.908826	0.237446	1227.598999	0.000000	NaN	NaN
518.999685	0.002915	29.146748	0.238071	1228.219604	0.000000	NaN	NaN
520.499771	0.003047	30.467198	0.238801	1228.942993	0.000000	NaN	NaN
521.999857	0.003014	30.137085	0.239371	1229.508545	0.000000	NaN	NaN
523.499943	0.002981	29.806973	0.240070	1230.202271	0.000000	NaN	NaN
525.000028	0.002906	29.064220	0.240744	1230.871094	0.000000	NaN	NaN
526.500114	0.002948	29.476860	0.241512	1231.632690	0.000000	NaN	NaN
528.000200	0.002857	28.569051	0.242129	1232.245239	0.000000	NaN	NaN
529.500286	0.003121	31.209951	0.242867	1232.976685	0.000000	NaN	NaN
530.999371	0.003047	30.467198	0.243518	1233.623291	0.000000	NaN	NaN
532.499457	0.003055	30.549726	0.244183	1234.282227	0.000000	NaN	NaN
533.999543	0.003055	30.549726	0.244900	1234.994507	0.000000	NaN	NaN
535.499629	0.003088	30.879838	0.245472	1235.561768	0.000000	NaN	NaN
536.999715	0.003005	30.054557	0.246226	1236.309326	0.000000	NaN	NaN
538.499800	0.003022	30.219613	0.246881	1236.959473	0.000000	NaN	NaN
539.999886	0.002972	29.724445	0.247542	1237.614868	0.000000	NaN	NaN
541.499972	0.003121	31.209951	0.248194	1238.261597	0.000000	NaN	NaN
543.000058	0.003088	30.879838	0.248893	1238.955566	0.000000	NaN	NaN
544.500144	0.002964	29.641917	0.249675	1239.730957	0.000000	NaN	NaN
546.000229	0.003005	30.054557	0.250286	1240.337036	0.000000	NaN	NaN
547.499315	0.003088	30.879838	0.250943	1240.988892	0.000000	NaN	NaN
548.999401	0.003022	30.219613	0.251613	1241.653076	0.000000	NaN	NaN
550.499487	0.003113	31.127423	0.252332	1242.367065	0.000000	NaN	NaN
551.999572	0.003080	30.797310	0.252889	1242.919556	0.000000	NaN	NaN
553.499658	0.003113	31.127423	0.253723	1243.746460	0.000000	NaN	NaN
554.999744	0.003038	30.384670	0.254346	1244.364990	0.000000	NaN	NaN
556.499830	0.003005	30.054557	0.254849	1244.863525	0.000000	NaN	NaN
557.999916	0.003063	30.632254	0.255618	1245.626709	0.000000	NaN	NaN
559.500002	0.002972	29.724445	0.256369	1246.371338	0.000000	NaN	NaN
561.000087	0.003104	31.044895	0.257029	1247.026733	0.000000	NaN	NaN
562.500173	0.003063	30.632254	0.257608	1247.600708	0.000000	NaN	NaN
564.000259	0.002989	29.889501	0.258405	1248.391357	0.000000	NaN	NaN
565.499345	0.002997	29.972029	0.258995	1248.976929	0.000000	NaN	NaN
566.999431	0.003055	30.549726	0.259815	1249.789917	0.000000	NaN	NaN
568.499516	0.003071	30.714782	0.260440	1250.410156	0.000000	NaN	NaN
569.999602	0.002981	29.806973	0.261140	1251.105225	0.000000	NaN	NaN
571.499688	0.003071	30.714782	0.261866	1251.824829	0.000000	NaN	NaN
572.999774	0.003022	30.219613	0.262532	1252.485718	0.000000	NaN	NaN
574.499860	0.003030	30.302142	0.263251	1253.198608	0.000000	NaN	NaN
575.999945	0.003005	30.054557	0.263852	1253.795166	0.000000	NaN	NaN
577.500031	0.003038	30.384670	0.264608	1254.545532	0.000000	NaN	NaN
579.000117	0.003162	31.622592	0.265256	1255.187988	0.000000	NaN	NaN
580.500203	0.003047	30.467198	0.265949	1255.875610	0.000000	NaN	NaN
582.000289	0.003071	30.714782	0.266616	1256.537109	0.000000	NaN	NaN
583.499374	0.003146	31.457535	0.267198	1257.114258	0.000000	NaN	NaN
584.999460	0.002956	29.559388	0.267990	1257.900024	0.000000	NaN	NaN
586.499546	0.003212	32.117760	0.268676	1258.581177	0.000000	NaN	NaN
587.999632	0.003212	32.117760	0.269316	1259.215820	0.000000	NaN	NaN
589.499717	0.003104	31.044895	0.270089	1259.982788	0.000000	NaN	NaN
590.999803	0.003171	31.705120	0.270764	1260.652466	0.000000	NaN	NaN
592.499889	0.003212	32.117760	0.271399	1261.281982	0.000000	NaN	NaN
593.999975	0.003071	30.714782	0.272685	1262.558350	0.000000	NaN	NaN
595.500061	0.003096	30.962367	0.273350	1263.217773	0.000000	NaN	NaN
597.000146	0.003088	30.879838	0.274110	1263.971924	0.000000	NaN	NaN
598.500232	0.003171	31.705120	0.274770	1264.626587	0.000000	NaN	NaN
599.999318	0.003195	31.952704	0.275447	1265.298096	0.000000	NaN	NaN
601.499404	0.003171	31.705120	0.276292	1266.136353	0.000000	NaN	NaN
602.999490	0.003162	31.622592	0.277031	1266.869507	0.000000	NaN	NaN
604.499575	0.003162	31.622592	0.277599	1267.432495	0.000000	NaN	NaN
605.999661	0.003220	32.200288	0.278411	1268.238159	0.000000	NaN	NaN
607.499747	0.003204	32.035232	0.279111	1268.932373	0.000000	NaN	NaN
608.999833	0.003030	30.302142	0.279701	1269.518433	0.000000	NaN	NaN
610.499919	0.003154	31.540063	0.280191	1270.004028	0.000000	NaN	NaN
612.000004	0.003187	31.870176	0.281012	1270.818481	0.000000	NaN	NaN
613.500090	0.003104	31.044895	0.281729	1271.530396	0.000000	NaN	NaN
615.000176	0.003237	32.365345	0.282240	1272.037231	0.000000	NaN	NaN
616.500262	0.003204	32.035232	0.282790	1272.582520	0.000000	NaN	NaN
617.999347	0.003220	32.200288	0.283525	1273.312012	0.000000	NaN	NaN
619.499433	0.003063	30.632254	0.284138	1273.920166	0.000000	NaN	NaN
620.999519	0.003104	31.044895	0.284747	1274.523926	0.000000	NaN	NaN
622.499605	0.003088	30.879838	0.285531	1275.302002	0.000000	NaN	NaN
623.999691	0.003088	30.879838	0.286062	1275.828491	0.000000	NaN	NaN
625.499777	0.003154	31.540063	0.286769	1276.529419	0.000000	NaN	NaN
626.999862	0.003253	32.530401	0.287519	1277.273437	0.000000	NaN	NaN
628.499948	0.003311	33.108098	0.288173	1277.923096	0.000000	NaN	NaN
630.000034	0.003146	31.457535	0.288977	1278.720459	0.000000	NaN	NaN
631.500120	0.003146	31.457535	0.289570	1279.308350	0.000000	NaN	NaN
633.000205	0.003030	30.302142	0.290238	1279.971680	0.000000	NaN	NaN
634.500291	0.003113	31.127423	0.291000	1280.727539	0.000000	NaN	NaN
635.999377	0.003179	31.787648	0.291583	1281.305542	0.000000	NaN	NaN
637.499463	0.003146	31.457535	0.292435	1282.151123	0.000000	NaN	NaN
638.999549	0.003311	33.108098	0.293048	1282.758789	0.000000	NaN	NaN
640.499635	0.003154	31.540063	0.293766	1283.470703	0.000000	NaN	NaN
641.999720	0.003294	32.943041	0.294522	1284.221558	0.000000	NaN	NaN
643.499806	0.003204	32.035232	0.295094	1284.788208	0.000000	NaN	NaN
644.999892	0.003220	32.200288	0.295883	1285.571289	0.000000	NaN	NaN
646.499978	0.003080	30.797310	0.296655	1286.337036	0.000000	NaN	NaN
648.000064	0.003080	30.797310	0.297274	1286.951538	0.000000	NaN	NaN
649.500149	0.003294	32.943041	0.297985	1287.656738	0.000000	NaN	NaN
651.000235	0.003278	32.777985	0.298620	1288.286621	0.000000	NaN	NaN
652.499321	0.003146	31.457535	0.299261	1288.922729	0.000000	NaN	NaN
653.999407	0.003047	30.467198	0.300100	1289.754761	0.000000	NaN	NaN
655.499492	0.003261	32.612929	0.300774	1290.423096	0.000000	NaN	NaN
656.999578	0.003261	32.612929	0.301510	1291.153687	0.000000	NaN	NaN
658.499664	0.003104	31.044895	0.302180	1291.817749	0.000000	NaN	NaN
659.999750	0.003336	33.355682	0.302793	1292.426147	0.000000	NaN	NaN
661.499836	0.003443	34.428548	0.303634	1293.260620	0.000000	NaN	NaN
662.999921	0.003179	31.787648	0.304328	1293.948853	0.000000	NaN	NaN
664.500007	0.003212	32.117760	0.305023	1294.638428	0.000000	NaN	NaN
666.000093	0.003237	32.365345	0.305781	1295.390625	0.000000	NaN	NaN
667.500179	0.003237	32.365345	0.306275	1295.880615	0.000000	NaN	NaN
669.000265	0.003319	33.190626	0.307067	1296.665894	0.000000	NaN	NaN
670.499350	0.003237	32.365345	0.307829	1297.421875	0.000000	NaN	NaN
671.999436	0.003245	32.447873	0.308536	1298.123779	0.000000	NaN	NaN
673.499522	0.003212	32.117760	0.309233	1298.815063	0.000000	NaN	NaN
674.999608	0.003278	32.777985	0.309795	1299.372925	0.000000	NaN	NaN
676.499694	0.003204	32.035232	0.310667	1300.237915	0.000000	NaN	NaN
677.999779	0.003303	33.025570	0.311286	1300.851807	0.000000	NaN	NaN
679.499865	0.003270	32.695457	0.311991	1301.550781	0.000000	NaN	NaN
680.999951	0.003286	32.860513	0.312881	1302.433594	0.000000	NaN	NaN
682.500037	0.003162	31.622592	0.313414	1302.963013	0.000000	NaN	NaN
684.000122	0.003476	34.758660	0.314077	1303.620239	0.000000	NaN	NaN
685.500208	0.003286	32.860513	0.314918	1304.454956	0.000000	NaN	NaN
687.000294	0.003294	32.943041	0.315481	1305.013306	0.000000	NaN	NaN
688.499380	0.003138	31.375007	0.316298	1305.824097	0.000000	NaN	NaN
689.999466	0.003352	33.520738	0.316985	1306.505249	0.000000	NaN	NaN
691.499552	0.003204	32.035232	0.317736	1307.250488	0.000000	NaN	NaN
692.999637	0.003270	32.695457	0.318468	1307.976685	0.000000	NaN	NaN
694.499723	0.003303	33.025570	0.319079	1308.582275	0.000000	NaN	NaN
695.999809	0.003286	32.860513	0.319879	1309.376221	0.000000	NaN	NaN
697.499895	0.003088	30.879838	0.320614	1310.105225	0.000000	NaN	NaN
698.999980	0.003336	33.355682	0.321213	1310.700073	0.000000	NaN	NaN
700.500066	0.003245	32.447873	0.321978	1311.458984	0.000000	NaN	NaN
702.000152	0.003228	32.282816	0.322644	1312.119751	0.000000	NaN	NaN
703.500238	0.003393	33.933379	0.323380	1312.849243	0.000000	NaN	NaN
704.999324	0.003278	32.777985	0.324129	1313.592773	0.000000	NaN	NaN
706.499409	0.003237	32.365345	0.324906	1314.363281	0.000000	NaN	NaN
707.999495	0.003220	32.200288	0.325698	1315.149170	0.000000	NaN	NaN
709.499581	0.003270	32.695457	0.326367	1315.812622	0.000000	NaN	NaN
710.999667	0.003261	32.612929	0.326951	1316.391968	0.000000	NaN	NaN
712.499753	0.003319	33.190626	0.327780	1317.214844	0.000000	NaN	NaN
713.999838	0.003204	32.035232	0.328478	1317.907104	0.000000	NaN	NaN
715.499924	0.003311	33.108098	0.329278	1318.700928	0.000000	NaN	NaN
717.000010	0.003261	32.612929	0.329963	1319.380249	0.000000	NaN	NaN
718.500096	0.003179	31.787648	0.330627	1320.038940	0.000000	NaN	NaN
720.000182	0.003303	33.025570	0.331471	1320.876343	0.000000	NaN	NaN
721.500267	0.003344	33.438210	0.332262	1321.660400	0.000000	NaN	NaN
722.999353	0.003237	32.365345	0.332886	1322.280151	0.000000	NaN	NaN
724.499439	0.003336	33.355682	0.333706	1323.093628	0.000000	NaN	NaN
725.999525	0.003311	33.108098	0.334363	1323.745239	0.000000	NaN	NaN
727.499611	0.003319	33.190626	0.335026	1324.402588	0.000000	NaN	NaN
728.999696	0.003245	32.447873	0.335892	1325.262329	0.000000	NaN	NaN
730.499782	0.003319	33.190626	0.336653	1326.017212	0.000000	NaN	NaN
731.999868	0.003377	33.768323	0.337342	1326.700195	0.000000	NaN	NaN
733.499954	0.003261	32.612929	0.337922	1327.275513	0.000000	NaN	NaN
735.000040	0.003228	32.282816	0.338604	1327.952515	0.000000	NaN	NaN
736.500125	0.003171	31.705120	0.339423	1328.765259	0.000000	NaN	NaN
738.000211	0.003435	34.346020	0.340176	1329.511475	0.000000	NaN	NaN
739.500297	0.003204	32.035232	0.341057	1330.386108	0.000000	NaN	NaN
740.999383	0.003237	32.365345	0.341561	1330.886230	0.000000	NaN	NaN
742.499469	0.003303	33.025570	0.342334	1331.652344	0.000000	NaN	NaN
743.999554	0.003253	32.530401	0.343046	1332.359009	0.000000	NaN	NaN
745.499640	0.003121	31.209951	0.343888	1333.193970	0.000000	NaN	NaN
746.999726	0.003261	32.612929	0.344542	1333.843506	0.000000	NaN	NaN
748.499812	0.003212	32.117760	0.345260	1334.555664	0.000000	NaN	NaN
749.999897	0.003344	33.438210	0.345901	1335.190796	0.000000	NaN	NaN
751.499983	0.003237	32.365345	0.346560	1335.845093	0.000000	NaN	NaN
753.000069	0.003171	31.705120	0.347509	1336.786377	0.000000	NaN	NaN
754.500155	0.003195	31.952704	0.348062	1337.335327	0.000000	NaN	NaN
756.000241	0.003319	33.190626	0.347552	1336.829102	0.000000	NaN	NaN
757.499327	0.003360	33.603266	0.348792	1338.059082	0.000000	NaN	NaN
758.999412	0.003261	32.612929	0.349653	1338.913940	0.000000	NaN	NaN
760.499498	0.003311	33.108098	0.350297	1339.552490	0.000000	NaN	NaN
761.999584	0.003336	33.355682	0.351033	1340.282104	0.000000	NaN	NaN
763.499670	0.003360	33.603266	0.351735	1340.979126	0.000000	NaN	NaN
764.999755	0.003204	32.035232	0.352608	1341.844604	0.000000	NaN	NaN
766.499841	0.003360	33.603266	0.353342	1342.573242	0.000000	NaN	NaN
767.999927	0.003319	33.190626	0.353943	1343.169067	0.000000	NaN	NaN
769.500013	0.003270	32.695457	0.354669	1343.889771	0.000000	NaN	NaN
771.000099	0.003402	34.015907	0.355543	1344.757080	0.000000	NaN	NaN
772.500185	0.003245	32.447873	0.356316	1345.523071	0.000000	NaN	NaN
774.000270	0.003286	32.860513	0.357075	1346.276367	0.000000	NaN	NaN
775.499356	0.003377	33.768323	0.357903	1347.097534	0.000000	NaN	NaN
776.999442	0.003286	32.860513	0.358598	1347.786865	0.000000	NaN	NaN
778.499528	0.003352	33.520738	0.359414	1348.596436	0.000000	NaN	NaN
779.999613	0.003426	34.263491	0.360259	1349.435181	0.000000	NaN	NaN
781.499699	0.003253	32.530401	0.360856	1350.027710	0.000000	NaN	NaN
782.999785	0.003171	31.705120	0.361554	1350.719360	0.000000	NaN	NaN
784.499871	0.003294	32.943041	0.362348	1351.507690	0.000000	NaN	NaN
785.999957	0.003212	32.117760	0.363163	1352.316162	0.000000	NaN	NaN
787.500042	0.003352	33.520738	0.363901	1353.047607	0.000000	NaN	NaN
789.000128	0.003393	33.933379	0.364632	1353.773315	0.000000	NaN	NaN
790.500214	0.003402	34.015907	0.365565	1354.698486	0.000000	NaN	NaN
792.000300	0.003121	31.209951	0.366211	1355.339600	0.000000	NaN	NaN
793.499386	0.003253	32.530401	0.366999	1356.121216	0.000000	NaN	NaN
794.999471	0.003336	33.355682	0.367907	1357.022217	0.000000	NaN	NaN
796.499557	0.003369	33.685795	0.368608	1357.717773	0.000000	NaN	NaN
797.999643	0.003261	32.612929	0.369253	1358.357300	0.000000	NaN	NaN
799.499729	0.003204	32.035232	0.370260	1359.356079	0.000000	NaN	NaN
800.999814	0.003237	32.365345	0.370933	1360.023682	0.000000	NaN	NaN
802.499900	0.003286	32.860513	0.371839	1360.922729	0.000000	NaN	NaN
803.999986	0.003261	32.612929	0.372662	1361.739502	0.000000	NaN	NaN
805.500072	0.003270	32.695457	0.373465	1362.535645	0.000000	NaN	NaN
807.000158	0.003237	32.365345	0.374330	1363.394043	0.000000	NaN	NaN
808.500244	0.003228	32.282816	0.375101	1364.159302	0.000000	NaN	NaN
809.999329	0.003237	32.365345	0.375793	1364.845093	0.000000	NaN	NaN
811.499415	0.003220	32.200288	0.376619	1365.664551	0.000000	NaN	NaN
812.999501	0.003179	31.787648	0.377419	1366.458008	0.000000	NaN	NaN
814.499587	0.003228	32.282816	0.378430	1367.461914	0.000000	NaN	NaN
815.999672	0.003261	32.612929	0.379162	1368.187988	0.000000	NaN	NaN
817.499758	0.003220	32.200288	0.380037	1369.055420	0.000000	NaN	NaN
818.999844	0.003261	32.612929	0.380933	1369.944824	0.000000	NaN	NaN
820.499930	0.003179	31.787648	0.381684	1370.689209	0.000000	NaN	NaN
822.000016	0.002906	29.064220	0.382439	1371.438599	0.000000	NaN	NaN
823.500102	0.003129	31.292479	0.382905	1371.901245	0.000000	NaN	NaN
825.000187	0.003261	32.612929	0.384560	1373.542358	0.000000	NaN	NaN
826.500273	0.003212	32.117760	0.384770	1373.751099	0.000000	NaN	NaN
827.999359	0.003096	30.962367	0.385969	1374.940552	0.000000	NaN	NaN
829.499445	0.003261	32.612929	0.386624	1375.589722	0.000000	NaN	NaN
830.999530	0.003138	31.375007	0.387671	1376.628906	0.000000	NaN	NaN
832.499616	0.003220	32.200288	0.388149	1377.103638	0.000000	NaN	NaN
833.999702	0.003179	31.787648	0.389366	1378.310425	0.000000	NaN	NaN
835.499788	0.003047	30.467198	0.390126	1379.064331	0.000000	NaN	NaN
836.999874	0.003121	31.209951	0.390920	1379.852173	0.000000	NaN	NaN
838.499959	0.003055	30.549726	0.392005	1380.928467	0.000000	NaN	NaN
840.000045	0.003624	36.244166	0.392818	1381.735352	0.000000	NaN	NaN
841.500131	0.003889	38.885066	0.398642	1387.512817	0.000000	NaN	NaN
843.000217	0.003195	31.952704	-0.162399	830.935608	0.000000	NaN	NaN
844.500303	3.444320E-5	0.344432	0.422331	1411.013428	0.000000	NaN	NaN
845.999388	-6.820864E-6	-0.068209	-0.726536	271.288086	0.000000	NaN	NaN
847.499474	-0.000131	-1.306131	-0.721736	276.049805	0.000000	NaN	NaN
848.999560	-1.507368E-5	-0.150737	-0.719446	278.321899	0.000000	NaN	NaN