File: data/57k_15-1_2 (190315).lvm
LabVIEW Measurement
Writer_Version	2
Reader_Version	2
Separator	Tab
Decimal_Separator	.
Multi_Headings	No
X_Columns	One
Time_Pref	Absolute
Operator	user
Description	Load(N)/Stress(MPa)/Distance A(pixel)/Strain A/Distance B(pixel)/Strain B/Poisson's ratio
Date	2019/03/15
Time	14:37:29.3127093315124511719
***End_of_Header***

Notes	X 값은 오직 다음과 같을 때에만 유효함이 보장됩니다. Dev1/ai0
Channels	7
Samples	1	1	1	1	1	1	1
Date	2019/03/15	2019/03/15	2019/03/15	2019/03/15	2019/03/15	2019/03/15	2019/03/15
Time	17:17:45.8127417300347321985	17:17:45.8127417300347321985	17:17:45.8127417564392089844	17:17:45.8127417564392089844	17:17:45.8127417564392089844	17:17:45.8127417564392089844	17:17:45.8127417564392089844
Y_Unit_Label	Volts	Volts
X_Dimension	Time	Time	Time	Time	Time	Time	Time
X0	0.0000000000000000E+0	0.0000000000000000E+0	0.0000000000000000E+0	0.0000000000000000E+0	0.0000000000000000E+0	0.0000000000000000E+0	0.0000000000000000E+0
Delta_X	0.000000	0.000000	1.000000	1.000000	1.000000	1.000000	1.000000
***End_of_Header***
X_Value	Dev1/ai0	Dev1/ai0 1	Untitled	Untitled 1	Untitled 2	Untitled 3	Untitled 4	Comment
0.000000	1.431948E-6	0.014319	1.692772E-5	996.108398	0.000000	NaN	NaN
1.500086	-0.000139	-1.388659	6.556511E-6	996.098022	0.000000	NaN	NaN
3.000172	6.745445E-5	0.674545	0.000135	996.226196	0.000000	NaN	NaN
4.500257	-3.157930E-5	-0.315793	0.000570	996.659668	0.000000	NaN	NaN
5.999343	0.000142	1.417298	0.000926	997.014038	0.000000	NaN	NaN
7.499429	-1.507368E-5	-0.150737	0.001241	997.327515	0.000000	NaN	NaN
8.999515	0.000266	2.655220	0.001400	997.486023	0.000000	NaN	NaN
10.499601	0.000257	2.572691	0.001519	997.604736	0.000000	NaN	NaN
11.999686	0.000299	2.985332	0.001771	997.855713	0.000000	NaN	NaN
13.499772	0.000241	2.407635	0.002143	998.225891	0.000000	NaN	NaN
14.999858	0.000158	1.582354	0.002367	998.449463	0.000000	NaN	NaN
16.499944	0.000340	3.397973	0.002712	998.793274	0.000000	NaN	NaN
18.000030	0.000389	3.893141	0.003067	999.146057	0.000000	NaN	NaN
19.500115	0.000422	4.223254	0.003297	999.375671	0.000000	NaN	NaN
21.000201	0.000447	4.470838	0.003614	999.690918	0.000000	NaN	NaN
22.500287	0.000455	4.553366	0.003985	1000.060608	0.000000	NaN	NaN
23.999373	0.000488	4.883479	0.004256	1000.330444	0.000000	NaN	NaN
25.499459	0.000488	4.883479	0.004483	1000.557007	0.000000	NaN	NaN
26.999544	0.000571	5.708760	0.004580	1000.653625	0.000000	NaN	NaN
28.499630	0.000513	5.131063	0.004776	1000.848450	0.000000	NaN	NaN
29.999716	0.000455	4.553366	0.005109	1001.180237	0.000000	NaN	NaN
31.499802	0.000513	5.131063	0.005589	1001.659180	0.000000	NaN	NaN
33.001888	0.000612	6.121401	0.005942	1002.010559	0.000000	NaN	NaN
34.499973	0.000818	8.184604	0.006343	1002.410034	0.000000	NaN	NaN
36.000059	0.000678	6.781626	0.006814	1002.879150	0.000000	NaN	NaN
37.500145	0.000695	6.946682	0.007028	1003.092163	0.000000	NaN	NaN
39.000231	0.000818	8.184604	0.007462	1003.524231	0.000000	NaN	NaN
40.499317	0.000777	7.771963	0.007985	1004.045410	0.000000	NaN	NaN
41.999402	0.000827	8.267132	0.008210	1004.269653	0.000000	NaN	NaN
43.499488	0.000909	9.092413	0.008671	1004.728699	0.000000	NaN	NaN
44.999574	0.000884	8.844829	0.009179	1005.234131	0.000000	NaN	NaN
46.499660	0.000926	9.257470	0.009796	1005.848694	0.000000	NaN	NaN
47.999746	0.001033	10.330335	0.009950	1006.002563	0.000000	NaN	NaN
49.499831	0.000984	9.835167	0.010544	1006.594299	0.000000	NaN	NaN
50.999917	0.000967	9.670110	0.010706	1006.755554	0.000000	NaN	NaN
52.502003	0.001066	10.660448	-0.448146	549.696655	0.000000	NaN	NaN
54.000089	0.001099	10.990560	-0.447416	550.424683	0.000000	NaN	NaN
55.500175	0.001281	12.806179	-0.446718	551.119446	0.000000	NaN	NaN
57.000260	0.001206	12.063426	-0.445524	552.308716	0.000000	NaN	NaN
58.499346	0.001256	12.558595	-0.444793	553.037415	0.000000	NaN	NaN
59.999432	0.001272	12.723651	-0.444181	553.646790	0.000000	NaN	NaN
61.499518	0.001272	12.723651	-0.443391	554.433105	0.000000	NaN	NaN
62.999603	0.001305	13.053763	-0.443239	554.584778	0.000000	NaN	NaN
64.499689	0.001256	12.558595	-0.441868	555.950684	0.000000	NaN	NaN
65.999775	0.001380	13.796517	0.019315	1015.330872	0.000000	NaN	NaN
67.499861	0.001380	13.796517	0.019819	1015.832886	0.000000	NaN	NaN
69.000947	0.001404	14.044101	0.020363	1016.374817	0.000000	NaN	NaN
70.500032	0.001256	12.558595	0.020985	1016.994141	0.000000	NaN	NaN
72.001118	0.001371	13.713988	0.021547	1017.553833	0.000000	NaN	NaN
73.500204	0.001462	14.621798	0.022168	1018.172791	0.000000	NaN	NaN
75.000290	0.001421	14.209157	0.022736	1018.738586	0.000000	NaN	NaN
76.499376	0.001421	14.209157	0.023354	1019.354553	0.000000	NaN	NaN
77.999461	0.001470	14.704326	0.023969	1019.966492	0.000000	NaN	NaN
79.499547	0.001446	14.456742	0.024581	1020.576294	0.000000	NaN	NaN
80.999633	0.001470	14.704326	0.025154	1021.147461	0.000000	NaN	NaN
82.499719	0.001487	14.869382	0.025866	1021.856445	0.000000	NaN	NaN
83.999805	0.001569	15.694663	0.026504	1022.491455	0.000000	NaN	NaN
85.499890	0.001553	15.529607	0.027145	1023.130066	0.000000	NaN	NaN
86.999976	0.001437	14.374213	0.027740	1023.723389	0.000000	NaN	NaN
88.500062	0.001586	15.859720	0.028482	1024.462036	0.000000	NaN	NaN
90.000148	0.001569	15.694663	0.029175	1025.152832	0.000000	NaN	NaN
91.500234	0.001578	15.777192	0.029896	1025.870972	0.000000	NaN	NaN
92.999319	0.001602	16.024776	0.030479	1026.451416	0.000000	NaN	NaN
94.499405	0.001652	16.519945	0.034929	1030.884399	0.000000	NaN	NaN
96.002491	0.001652	16.519945	0.035652	1031.604004	0.000000	NaN	NaN
97.500577	0.001685	16.850057	0.035982	1031.933228	0.000000	NaN	NaN
98.999662	0.001669	16.685001	0.036729	1032.676880	0.000000	NaN	NaN
100.499748	0.001602	16.024776	0.037465	1033.410278	0.000000	NaN	NaN
102.001834	0.001635	16.354889	0.038124	1034.066284	0.000000	NaN	NaN
103.499920	0.001627	16.272360	0.038833	1034.772461	0.000000	NaN	NaN
105.002006	0.001602	16.024776	0.039659	1035.595459	0.000000	NaN	NaN
106.500092	0.001735	17.345226	0.040355	1036.288818	0.000000	NaN	NaN
108.000177	0.001726	17.262698	0.041176	1037.106812	0.000000	NaN	NaN
109.500263	0.001635	16.354889	0.041873	1037.800293	0.000000	NaN	NaN
110.999349	0.001726	17.262698	0.042677	1038.601685	0.000000	NaN	NaN
112.499435	0.001693	16.932585	0.043414	1039.335693	0.000000	NaN	NaN
113.999520	0.001685	16.850057	0.044240	1040.158203	0.000000	NaN	NaN
115.499606	0.001669	16.685001	0.044953	1040.869019	0.000000	NaN	NaN
116.999692	0.001743	17.427754	0.045805	1041.717285	0.000000	NaN	NaN
118.499778	0.001726	17.262698	0.046455	1042.365356	0.000000	NaN	NaN
119.999864	0.001586	15.859720	0.047301	1043.207153	0.000000	NaN	NaN
121.500950	0.001776	17.757867	0.048025	1043.928711	0.000000	NaN	NaN
123.000035	0.001801	18.005451	0.048833	1044.733521	0.000000	NaN	NaN
124.500121	0.001776	17.757867	0.049581	1045.479004	0.000000	NaN	NaN
126.000207	0.001726	17.262698	0.050362	1046.256470	0.000000	NaN	NaN
127.500293	0.001677	16.767529	0.051083	1046.974487	0.000000	NaN	NaN
128.999378	0.001677	16.767529	0.051841	1047.729492	0.000000	NaN	NaN
130.499464	0.001726	17.262698	0.052640	1048.525757	0.000000	NaN	NaN
131.999550	0.001726	17.262698	0.053401	1049.283325	0.000000	NaN	NaN
133.499636	0.001867	18.665676	0.054229	1050.108154	0.000000	NaN	NaN
134.999722	0.001726	17.262698	0.054971	1050.847168	0.000000	NaN	NaN
136.499807	0.001809	18.087979	0.055670	1051.543945	0.000000	NaN	NaN
138.000893	0.001735	17.345226	0.056448	1052.318481	0.000000	NaN	NaN
139.499979	0.001586	15.859720	0.057184	1053.051514	0.000000	NaN	NaN
141.015066	0.001735	17.345226	0.057963	1053.828125	0.000000	NaN	NaN
142.500151	0.001751	17.510282	0.058688	1054.550171	0.000000	NaN	NaN
144.000236	0.001759	17.592810	0.059380	1055.239624	0.000000	NaN	NaN
145.499322	0.001726	17.262698	0.060140	1055.996094	0.000000	NaN	NaN
146.999408	0.001751	17.510282	0.060960	1056.812988	0.000000	NaN	NaN
148.499494	0.001669	16.685001	0.061643	1057.493896	0.000000	NaN	NaN
149.999580	0.001999	19.986126	0.062512	1058.359375	0.000000	NaN	NaN
151.499665	0.001751	17.510282	0.063206	1059.050659	0.000000	NaN	NaN
153.000751	0.001867	18.665676	0.064019	1059.860718	0.000000	NaN	NaN
154.499837	0.001842	18.418092	0.064811	1060.649536	0.000000	NaN	NaN
155.999923	0.001883	18.830732	0.065483	1061.318970	0.000000	NaN	NaN
157.500009	0.001702	17.015114	0.066316	1062.148804	0.000000	NaN	NaN
159.000094	0.001784	17.840395	0.066982	1062.811523	0.000000	NaN	NaN
160.500180	0.001768	17.675339	0.067794	1063.620850	0.000000	NaN	NaN
162.001266	0.001776	17.757867	0.068415	1064.238892	0.000000	NaN	NaN
163.499352	0.001801	18.005451	0.069247	1065.067505	0.000000	NaN	NaN
164.999437	0.001850	18.500620	0.069945	1065.763550	0.000000	NaN	NaN
166.499523	0.001801	18.005451	0.070723	1066.538452	0.000000	NaN	NaN
167.999609	0.001916	19.160845	0.071541	1067.352783	0.000000	NaN	NaN
169.499695	0.001784	17.840395	0.072228	1068.036987	0.000000	NaN	NaN
170.999781	0.001825	18.253035	0.073021	1068.827271	0.000000	NaN	NaN
172.499867	0.001867	18.665676	0.073736	1069.539551	0.000000	NaN	NaN
173.999952	0.001801	18.005451	0.074552	1070.352295	0.000000	NaN	NaN
175.500038	0.001809	18.087979	0.075234	1071.031738	0.000000	NaN	NaN
177.000124	0.001834	18.335564	0.076070	1071.863770	0.000000	NaN	NaN
178.500210	0.001768	17.675339	0.076714	1072.505981	0.000000	NaN	NaN
180.000295	0.001875	18.748204	0.077546	1073.334839	0.000000	NaN	NaN
181.499381	0.001817	18.170507	0.078328	1074.113647	0.000000	NaN	NaN
182.999467	0.001858	18.583148	0.079055	1074.837891	0.000000	NaN	NaN
184.499553	0.001809	18.087979	0.079892	1075.670776	0.000000	NaN	NaN
185.999639	0.001949	19.490957	0.080326	1076.103149	0.000000	NaN	NaN
187.499724	0.001858	18.583148	0.080109	1075.887207	0.000000	NaN	NaN
188.999810	0.001842	18.418092	0.080800	1076.575439	0.000000	NaN	NaN
190.499896	0.001916	19.160845	0.081642	1077.414307	0.000000	NaN	NaN
191.999982	0.001941	19.408429	0.082365	1078.134888	0.000000	NaN	NaN
193.500068	0.001751	17.510282	0.083119	1078.885986	0.000000	NaN	NaN
195.000153	0.001941	19.408429	0.083857	1079.621094	0.000000	NaN	NaN
196.500239	0.001834	18.335564	0.084614	1080.374756	0.000000	NaN	NaN
197.999325	0.001990	19.903598	0.085406	1081.163818	0.000000	NaN	NaN
199.499411	0.001842	18.418092	0.086134	1081.888428	0.000000	NaN	NaN
200.999497	0.001941	19.408429	0.086980	1082.731079	0.000000	NaN	NaN
202.499582	0.001875	18.748204	0.087736	1083.484375	0.000000	NaN	NaN
203.999668	0.002007	20.068654	0.088428	1084.174072	0.000000	NaN	NaN
205.499754	0.001858	18.583148	0.089167	1084.910034	0.000000	NaN	NaN
206.999840	0.001974	19.738542	0.089974	1085.714233	0.000000	NaN	NaN
208.499926	0.002048	20.481295	0.090773	1086.509521	0.000000	NaN	NaN
210.000011	0.001883	18.830732	0.091597	1087.330688	0.000000	NaN	NaN
211.500097	0.001941	19.408429	0.092339	1088.069336	0.000000	NaN	NaN
213.000183	0.001982	19.821070	0.093078	1088.805786	0.000000	NaN	NaN
214.500269	0.001941	19.408429	0.093887	1089.611694	0.000000	NaN	NaN
215.999355	0.001941	19.408429	0.094620	1090.341797	0.000000	NaN	NaN
217.499440	0.001801	18.005451	0.095372	1091.090942	0.000000	NaN	NaN
218.999526	0.002048	20.481295	0.096282	1091.997681	0.000000	NaN	NaN
220.499612	0.002040	20.398767	0.096937	1092.649780	0.000000	NaN	NaN
221.999698	0.002073	20.728879	0.097799	1093.508423	0.000000	NaN	NaN
223.499784	0.001891	18.913260	0.098582	1094.288208	0.000000	NaN	NaN
224.999869	0.002040	20.398767	0.099390	1095.093018	0.000000	NaN	NaN
226.499955	0.001999	19.986126	0.100136	1095.836060	0.000000	NaN	NaN
228.000041	0.001990	19.903598	0.100853	1096.550781	0.000000	NaN	NaN
229.500127	0.002114	21.141520	0.101558	1097.252686	0.000000	NaN	NaN
231.000213	0.001990	19.903598	0.102315	1098.006226	0.000000	NaN	NaN
232.500298	0.002065	20.646351	0.103154	1098.841919	0.000000	NaN	NaN
233.999384	0.001982	19.821070	0.103961	1099.646606	0.000000	NaN	NaN
235.499470	0.002073	20.728879	0.104682	1100.364380	0.000000	NaN	NaN
236.999556	0.001974	19.738542	0.105378	1101.057861	0.000000	NaN	NaN
238.499641	0.002114	21.141520	0.106141	1101.818115	0.000000	NaN	NaN
239.999727	0.002040	20.398767	0.106905	1102.578125	0.000000	NaN	NaN
241.499813	0.002106	21.058992	0.107676	1103.346436	0.000000	NaN	NaN
242.999899	0.001966	19.656014	0.108467	1104.134521	0.000000	NaN	NaN
244.499985	0.001949	19.490957	0.109277	1104.941406	0.000000	NaN	NaN
246.000070	0.001900	18.995789	0.109999	1105.660645	0.000000	NaN	NaN
247.500156	0.002015	20.151182	0.110719	1106.378052	0.000000	NaN	NaN
249.000242	0.002131	21.306576	0.111438	1107.093994	0.000000	NaN	NaN
250.499328	0.001999	19.986126	0.112257	1107.909302	0.000000	NaN	NaN
251.999414	0.002007	20.068654	0.113082	1108.731445	0.000000	NaN	NaN
253.499499	0.001990	19.903598	0.113859	1109.505371	0.000000	NaN	NaN
254.999585	0.001957	19.573485	0.114575	1110.218384	0.000000	NaN	NaN
256.499671	0.002040	20.398767	0.115333	1110.973755	0.000000	NaN	NaN
257.999757	0.002007	20.068654	0.116063	1111.700562	0.000000	NaN	NaN
259.499843	0.001982	19.821070	0.116802	1112.436523	0.000000	NaN	NaN
260.999928	0.002065	20.646351	0.117693	1113.324585	0.000000	NaN	NaN
262.500014	0.002040	20.398767	0.118279	1113.907715	0.000000	NaN	NaN
264.000100	0.002056	20.563823	0.119128	1114.753662	0.000000	NaN	NaN
265.500186	0.002098	20.976463	0.119827	1115.449951	0.000000	NaN	NaN
267.000272	0.002032	20.316239	0.120675	1116.295288	0.000000	NaN	NaN
268.499357	0.001900	18.995789	0.121318	1116.935791	0.000000	NaN	NaN
269.999443	0.002023	20.233710	0.122117	1117.731079	0.000000	NaN	NaN
271.499529	0.002098	20.976463	0.122848	1118.459473	0.000000	NaN	NaN
272.999615	0.001999	19.986126	0.123606	1119.214844	0.000000	NaN	NaN
274.499701	0.002098	20.976463	0.124340	1119.945801	0.000000	NaN	NaN
275.999786	0.002007	20.068654	0.125071	1120.674072	0.000000	NaN	NaN
277.499872	0.002098	20.976463	0.125905	1121.504272	0.000000	NaN	NaN
278.999958	0.001957	19.573485	0.126629	1122.225342	0.000000	NaN	NaN
280.500044	0.002081	20.811407	0.127387	1122.980713	0.000000	NaN	NaN
282.000130	0.002015	20.151182	0.128125	1123.715942	0.000000	NaN	NaN
283.500215	0.002114	21.141520	0.128927	1124.514893	0.000000	NaN	NaN
285.000301	0.002155	21.554160	0.129652	1125.236816	0.000000	NaN	NaN
286.499387	0.002106	21.058992	0.130466	1126.047363	0.000000	NaN	NaN
287.999473	0.002114	21.141520	0.131036	1126.615723	0.000000	NaN	NaN
289.499559	0.002048	20.481295	0.131760	1127.336548	0.000000	NaN	NaN
290.999644	0.002131	21.306576	0.132612	1128.185547	0.000000	NaN	NaN
292.499730	0.002098	20.976463	0.133399	1128.968750	0.000000	NaN	NaN
293.999816	0.002172	21.719217	0.134089	1129.656616	0.000000	NaN	NaN
295.499902	0.002205	22.049329	0.134949	1130.513428	0.000000	NaN	NaN
296.999987	0.002106	21.058992	0.135505	1131.067139	0.000000	NaN	NaN
298.500073	0.002131	21.306576	0.136365	1131.923340	0.000000	NaN	NaN
300.000159	0.002139	21.389104	0.137094	1132.649658	0.000000	NaN	NaN
301.500245	0.002106	21.058992	0.137761	1133.313965	0.000000	NaN	NaN
302.999331	0.002238	22.379442	0.138506	1134.055664	0.000000	NaN	NaN
304.499416	0.002098	20.976463	0.139308	1134.855103	0.000000	NaN	NaN
305.999502	0.002007	20.068654	0.140058	1135.602051	0.000000	NaN	NaN
307.499588	0.002122	21.224048	0.140766	1136.307373	0.000000	NaN	NaN
308.999674	0.002122	21.224048	0.141529	1137.067627	0.000000	NaN	NaN
310.499760	0.002114	21.141520	0.142224	1137.759644	0.000000	NaN	NaN
311.999845	0.002040	20.398767	0.143031	1138.563843	0.000000	NaN	NaN
313.499931	0.002015	20.151182	0.143696	1139.225464	0.000000	NaN	NaN
315.000017	0.002213	22.131857	0.144401	1139.927734	0.000000	NaN	NaN
316.500103	0.002023	20.233710	0.145214	1140.737549	0.000000	NaN	NaN
318.000189	0.002106	21.058992	0.145939	1141.459595	0.000000	NaN	NaN
319.500274	0.002073	20.728879	0.146750	1142.267944	0.000000	NaN	NaN
320.999360	0.001982	19.821070	0.147493	1143.008301	0.000000	NaN	NaN
322.499446	0.002139	21.389104	0.148133	1143.645508	0.000000	NaN	NaN
323.999532	0.002122	21.224048	0.148897	1144.406738	0.000000	NaN	NaN
325.499618	0.002098	20.976463	0.149591	1145.097412	0.000000	NaN	NaN
326.999703	0.002131	21.306576	0.150385	1145.888428	0.000000	NaN	NaN
328.499789	0.002081	20.811407	0.151136	1146.636353	0.000000	NaN	NaN
329.999875	0.002180	21.801745	0.151950	1147.447266	0.000000	NaN	NaN
331.499961	0.002205	22.049329	0.152535	1148.030640	0.000000	NaN	NaN
333.000047	0.002155	21.554160	0.153343	1148.834839	0.000000	NaN	NaN
334.500132	0.002172	21.719217	0.154180	1149.669067	0.000000	NaN	NaN
336.000218	0.002197	21.966801	0.154882	1150.368530	0.000000	NaN	NaN
337.500304	0.002180	21.801745	0.155697	1151.180054	0.000000	NaN	NaN
338.999390	0.002131	21.306576	0.156293	1151.773804	0.000000	NaN	NaN
340.499476	0.002180	21.801745	0.157075	1152.552612	0.000000	NaN	NaN
341.999561	0.002205	22.049329	0.157800	1153.274658	0.000000	NaN	NaN
343.499647	0.002213	22.131857	0.158590	1154.062012	0.000000	NaN	NaN
344.999733	0.002164	21.636688	0.159174	1154.643677	0.000000	NaN	NaN
346.499819	0.002081	20.811407	0.160030	1155.495972	0.000000	NaN	NaN
347.999905	0.002032	20.316239	0.160645	1156.108521	0.000000	NaN	NaN
349.499990	0.002155	21.554160	0.161371	1156.832153	0.000000	NaN	NaN
351.000076	0.002147	21.471632	0.162103	1157.561035	0.000000	NaN	NaN
352.500162	0.002221	22.214385	0.162809	1158.264282	0.000000	NaN	NaN
354.000248	0.002139	21.389104	0.163575	1159.027466	0.000000	NaN	NaN
355.499333	0.002279	22.792082	0.164261	1159.710449	0.000000	NaN	NaN
356.999419	0.002254	22.544498	0.164991	1160.437134	0.000000	NaN	NaN
358.499505	0.002180	21.801745	0.165672	1161.115723	0.000000	NaN	NaN
359.999591	0.002213	22.131857	0.166478	1161.918945	0.000000	NaN	NaN
361.499677	0.002065	20.646351	0.167169	1162.607300	0.000000	NaN	NaN
362.999762	0.002263	22.627026	0.167912	1163.347168	0.000000	NaN	NaN
364.499848	0.002197	21.966801	0.168463	1163.896362	0.000000	NaN	NaN
365.999934	0.002230	22.296913	0.169258	1164.687866	0.000000	NaN	NaN
367.500020	0.002180	21.801745	0.170000	1165.427246	0.000000	NaN	NaN
369.000106	0.002254	22.544498	0.170826	1166.249390	0.000000	NaN	NaN
370.500191	0.002221	22.214385	0.171545	1166.965942	0.000000	NaN	NaN
372.000277	0.002230	22.296913	0.172204	1167.622437	0.000000	NaN	NaN
373.499363	0.002238	22.379442	0.172896	1168.311646	0.000000	NaN	NaN
374.999449	0.002221	22.214385	0.173604	1169.016724	0.000000	NaN	NaN
376.499535	0.002345	23.452307	0.174388	1169.797974	0.000000	NaN	NaN
377.999620	0.002155	21.554160	0.175067	1170.474121	0.000000	NaN	NaN
379.499706	0.002263	22.627026	0.175778	1171.182007	0.000000	NaN	NaN
380.999792	0.002254	22.544498	0.176514	1171.915283	0.000000	NaN	NaN
382.499878	0.002106	21.058992	0.177229	1172.627686	0.000000	NaN	NaN
383.999964	0.002230	22.296913	0.177911	1173.306763	0.000000	NaN	NaN
385.500049	0.002254	22.544498	0.178679	1174.071899	0.000000	NaN	NaN
387.000135	0.002395	23.947476	0.179370	1174.760498	0.000000	NaN	NaN
388.500221	0.002337	23.369779	0.180174	1175.561157	0.000000	NaN	NaN
389.999307	0.002180	21.801745	0.180801	1176.186035	0.000000	NaN	NaN
391.499393	0.002263	22.627026	0.181514	1176.896118	0.000000	NaN	NaN
392.999478	0.002312	23.122195	0.182313	1177.692139	0.000000	NaN	NaN
394.499564	0.002254	22.544498	0.183039	1178.414795	0.000000	NaN	NaN
395.999650	0.002353	23.534835	0.183741	1179.114502	0.000000	NaN	NaN
397.499736	0.002221	22.214385	0.184435	1179.805420	0.000000	NaN	NaN
398.999821	0.002378	23.782420	0.185136	1180.503784	0.000000	NaN	NaN
400.499907	0.002296	22.957138	0.185846	1181.210937	0.000000	NaN	NaN
401.999993	0.002296	22.957138	0.186608	1181.970337	0.000000	NaN	NaN
403.500079	0.002246	22.461970	0.187369	1182.727661	0.000000	NaN	NaN
405.000165	0.002353	23.534835	0.188125	1183.480835	0.000000	NaN	NaN
406.500251	0.002370	23.699892	0.188814	1184.167236	0.000000	NaN	NaN
407.999336	0.002238	22.379442	0.189562	1184.912964	0.000000	NaN	NaN
409.499422	0.002353	23.534835	0.190257	1185.604980	0.000000	NaN	NaN
410.999508	0.002155	21.554160	0.191089	1186.433228	0.000000	NaN	NaN
412.499594	0.002263	22.627026	0.191741	1187.082764	0.000000	NaN	NaN
413.999680	0.002230	22.296913	0.192549	1187.887817	0.000000	NaN	NaN
415.499765	0.002337	23.369779	0.193157	1188.494019	0.000000	NaN	NaN
416.999851	0.002271	22.709554	0.193894	1189.227905	0.000000	NaN	NaN
418.499937	0.002246	22.461970	0.194707	1190.037109	0.000000	NaN	NaN
420.000023	0.002320	23.204723	0.195434	1190.761719	0.000000	NaN	NaN
421.500109	0.002296	22.957138	0.196117	1191.442383	0.000000	NaN	NaN
423.003194	0.002254	22.544498	0.196943	1192.265137	0.000000	NaN	NaN
424.500280	0.002320	23.204723	0.197572	1192.891357	0.000000	NaN	NaN
425.999366	0.002197	21.966801	0.198355	1193.671265	0.000000	NaN	NaN
427.499452	0.002296	22.957138	0.199053	1194.366455	0.000000	NaN	NaN
428.999537	0.002420	24.195060	0.199766	1195.076660	0.000000	NaN	NaN
430.499623	0.002197	21.966801	0.200487	1195.794434	0.000000	NaN	NaN
431.999709	0.002254	22.544498	0.201260	1196.564941	0.000000	NaN	NaN
433.499795	0.002312	23.122195	0.201860	1197.162109	0.000000	NaN	NaN
434.999881	0.002370	23.699892	0.202628	1197.927612	0.000000	NaN	NaN
436.499966	0.002337	23.369779	0.203387	1198.684082	0.000000	NaN	NaN
438.000052	0.002386	23.864948	0.204164	1199.457886	0.000000	NaN	NaN
439.500138	0.002370	23.699892	0.204839	1200.129761	0.000000	NaN	NaN
441.000224	0.002304	23.039667	0.205484	1200.771973	0.000000	NaN	NaN
442.499310	0.002353	23.534835	0.206297	1201.582397	0.000000	NaN	NaN
443.999395	0.002353	23.534835	0.206956	1202.238892	0.000000	NaN	NaN
445.499481	0.002337	23.369779	0.207692	1202.971924	0.000000	NaN	NaN
446.999567	0.002263	22.627026	0.208525	1203.801025	0.000000	NaN	NaN
448.499653	0.002477	24.772757	0.209198	1204.472290	0.000000	NaN	NaN
449.999739	0.002411	24.112532	0.209837	1205.108765	0.000000	NaN	NaN
451.499824	0.002420	24.195060	0.210630	1205.898071	0.000000	NaN	NaN
452.999910	0.002370	23.699892	0.211350	1206.615723	0.000000	NaN	NaN
454.499996	0.002420	24.195060	0.212100	1207.362305	0.000000	NaN	NaN
456.000082	0.002378	23.782420	0.212764	1208.023804	0.000000	NaN	NaN
457.500168	0.002411	24.112532	0.213552	1208.808838	0.000000	NaN	NaN
459.000253	0.002353	23.534835	0.214150	1209.404541	0.000000	NaN	NaN
460.499339	0.002312	23.122195	0.214889	1210.140747	0.000000	NaN	NaN
461.999425	0.002395	23.947476	0.215575	1210.824097	0.000000	NaN	NaN
463.499511	0.002312	23.122195	0.216258	1211.504272	0.000000	NaN	NaN
464.999596	0.002312	23.122195	0.217019	1212.262695	0.000000	NaN	NaN
466.499682	0.002411	24.112532	0.217631	1212.871826	0.000000	NaN	NaN
467.999768	0.002345	23.452307	0.218400	1213.638062	0.000000	NaN	NaN
469.499854	0.002461	24.607701	0.219068	1214.303589	0.000000	NaN	NaN
470.999940	0.002271	22.709554	0.219842	1215.073975	0.000000	NaN	NaN
472.500026	0.002320	23.204723	0.220612	1215.841675	0.000000	NaN	NaN
474.000111	0.002279	22.792082	0.221193	1216.420288	0.000000	NaN	NaN
475.500197	0.002304	23.039667	0.221908	1217.132202	0.000000	NaN	NaN
477.000283	0.002337	23.369779	0.222570	1217.791992	0.000000	NaN	NaN
478.499369	0.002312	23.122195	0.223273	1218.492065	0.000000	NaN	NaN
479.999454	0.002444	24.442645	0.224044	1219.259644	0.000000	NaN	NaN
481.499540	0.002320	23.204723	0.224712	1219.925293	0.000000	NaN	NaN
482.999626	0.002420	24.195060	0.225465	1220.675415	0.000000	NaN	NaN
484.499712	0.002428	24.277588	0.226079	1221.287354	0.000000	NaN	NaN
485.999798	0.002395	23.947476	0.226844	1222.049194	0.000000	NaN	NaN
487.499883	0.002254	22.544498	0.227496	1222.698730	0.000000	NaN	NaN
488.999969	0.002337	23.369779	0.228271	1223.470703	0.000000	NaN	NaN
490.500055	0.002395	23.947476	0.228949	1224.145264	0.000000	NaN	NaN
492.000141	0.002296	22.957138	0.229586	1224.780029	0.000000	NaN	NaN
493.500227	0.002370	23.699892	0.230318	1225.508911	0.000000	NaN	NaN
494.999312	0.002345	23.452307	0.231104	1226.292114	0.000000	NaN	NaN
496.499398	0.002453	24.525173	0.231744	1226.929932	0.000000	NaN	NaN
497.999484	0.002444	24.442645	0.232467	1227.649536	0.000000	NaN	NaN
499.499570	0.002304	23.039667	0.233253	1228.432617	0.000000	NaN	NaN
500.999656	0.002329	23.287251	0.233926	1229.103638	0.000000	NaN	NaN
502.499741	0.002263	22.627026	0.234591	1229.766113	0.000000	NaN	NaN
503.999827	0.002378	23.782420	0.235302	1230.473999	0.000000	NaN	NaN
505.499913	0.002287	22.874610	0.236058	1231.226685	0.000000	NaN	NaN
506.999999	0.002304	23.039667	0.236777	1231.943237	0.000000	NaN	NaN
508.500085	0.002312	23.122195	0.237480	1232.643311	0.000000	NaN	NaN
510.000170	0.002411	24.112532	0.238091	1233.251831	0.000000	NaN	NaN
511.500256	0.002370	23.699892	0.238849	1234.006836	0.000000	NaN	NaN
512.999342	0.002477	24.772757	0.239531	1234.685913	0.000000	NaN	NaN
514.499428	0.002469	24.690229	0.240314	1235.466187	0.000000	NaN	NaN
515.999514	0.002329	23.287251	0.240970	1236.119263	0.000000	NaN	NaN
517.499599	0.002444	24.442645	0.241714	1236.860229	0.000000	NaN	NaN
518.999685	0.002353	23.534835	0.242421	1237.564941	0.000000	NaN	NaN
520.499771	0.002287	22.874610	0.243072	1238.213623	0.000000	NaN	NaN
521.999857	0.002411	24.112532	0.243851	1238.989502	0.000000	NaN	NaN
523.499943	0.002436	24.360117	0.244632	1239.767090	0.000000	NaN	NaN
525.000028	0.002477	24.772757	0.245267	1240.400269	0.000000	NaN	NaN
526.500114	0.002444	24.442645	0.246009	1241.139160	0.000000	NaN	NaN
528.000200	0.002469	24.690229	0.246642	1241.769897	0.000000	NaN	NaN
529.500286	0.002469	24.690229	0.247373	1242.497559	0.000000	NaN	NaN
530.999372	0.002519	25.185398	0.248122	1243.243530	0.000000	NaN	NaN
532.499457	0.002378	23.782420	0.248850	1243.968384	0.000000	NaN	NaN
533.999543	0.002386	23.864948	0.249482	1244.597900	0.000000	NaN	NaN
535.499629	0.002469	24.690229	0.250142	1245.255981	0.000000	NaN	NaN
536.999715	0.002585	25.845623	0.250851	1245.961670	0.000000	NaN	NaN
538.499801	0.002395	23.947476	0.251549	1246.657104	0.000000	NaN	NaN
539.999886	0.002469	24.690229	0.252218	1247.324097	0.000000	NaN	NaN
541.499972	0.002494	24.937813	0.252936	1248.038452	0.000000	NaN	NaN
543.000058	0.002436	24.360117	0.253577	1248.677612	0.000000	NaN	NaN
544.500144	0.002386	23.864948	0.254291	1249.388428	0.000000	NaN	NaN
546.000230	0.002378	23.782420	0.254961	1250.055542	0.000000	NaN	NaN
547.499315	0.002469	24.690229	0.255600	1250.692627	0.000000	NaN	NaN
548.999401	0.002403	24.030004	0.256355	1251.444946	0.000000	NaN	NaN
550.499487	0.002535	25.350454	0.257040	1252.127197	0.000000	NaN	NaN
551.999573	0.002403	24.030004	0.257661	1252.745850	0.000000	NaN	NaN
553.499658	0.002477	24.772757	0.258363	1253.444458	0.000000	NaN	NaN
554.999744	0.002428	24.277588	0.259051	1254.129883	0.000000	NaN	NaN
556.499830	0.002527	25.267926	0.259790	1254.865723	0.000000	NaN	NaN
557.999916	0.002560	25.598038	0.260424	1255.497314	0.000000	NaN	NaN
559.500002	0.002519	25.185398	0.261157	1256.227783	0.000000	NaN	NaN
561.000087	0.002444	24.442645	0.261841	1256.909302	0.000000	NaN	NaN
562.500173	0.002519	25.185398	0.262539	1257.604248	0.000000	NaN	NaN
564.000259	0.002386	23.864948	0.263233	1258.296021	0.000000	NaN	NaN
565.499345	0.002345	23.452307	0.263943	1259.002930	0.000000	NaN	NaN
566.999431	0.002362	23.617363	0.264611	1259.667969	0.000000	NaN	NaN
568.499516	0.002461	24.607701	0.265363	1260.416992	0.000000	NaN	NaN
569.999602	0.002519	25.185398	0.265941	1260.992920	0.000000	NaN	NaN
571.499688	0.002494	24.937813	0.266725	1261.774292	0.000000	NaN	NaN
572.999774	0.002510	25.102870	0.267385	1262.431763	0.000000	NaN	NaN
574.499860	0.002395	23.947476	0.268096	1263.140015	0.000000	NaN	NaN
575.999945	0.002444	24.442645	0.268761	1263.801758	0.000000	NaN	NaN
577.500031	0.002378	23.782420	0.269432	1264.470459	0.000000	NaN	NaN
579.000117	0.002453	24.525173	0.270222	1265.256958	0.000000	NaN	NaN
580.500203	0.002576	25.763095	0.270860	1265.892944	0.000000	NaN	NaN
582.000289	0.002601	26.010679	0.271507	1266.537354	0.000000	NaN	NaN
583.499374	0.002453	24.525173	0.272212	1267.239990	0.000000	NaN	NaN
584.999460	0.002477	24.772757	0.272992	1268.015991	0.000000	NaN	NaN
586.499546	0.002395	23.947476	0.273570	1268.591919	0.000000	NaN	NaN
587.999632	0.002609	26.093207	0.274275	1269.294922	0.000000	NaN	NaN
589.499718	0.002576	25.763095	0.275076	1270.092651	0.000000	NaN	NaN
590.999803	0.002353	23.534835	0.275716	1270.729858	0.000000	NaN	NaN
592.499889	0.002494	24.937813	0.276319	1271.330444	0.000000	NaN	NaN
593.999975	0.002461	24.607701	0.277048	1272.056641	0.000000	NaN	NaN
595.500061	0.002502	25.020342	0.277694	1272.699707	0.000000	NaN	NaN
597.000147	0.002345	23.452307	0.278519	1273.521484	0.000000	NaN	NaN
598.500232	0.002494	24.937813	0.279149	1274.149170	0.000000	NaN	NaN
599.999318	0.002494	24.937813	0.279870	1274.867554	0.000000	NaN	NaN
601.499404	0.002494	24.937813	0.280484	1275.479492	0.000000	NaN	NaN
602.999490	0.002403	24.030004	0.281230	1276.221924	0.000000	NaN	NaN
604.499575	0.002444	24.442645	0.281902	1276.891479	0.000000	NaN	NaN
605.999661	0.002609	26.093207	0.282517	1277.504639	0.000000	NaN	NaN
607.499747	0.002626	26.258263	0.283213	1278.197388	0.000000	NaN	NaN
608.999833	0.002535	25.350454	0.284005	1278.986084	0.000000	NaN	NaN
610.499919	0.002428	24.277588	0.284569	1279.548096	0.000000	NaN	NaN
612.000004	0.002535	25.350454	0.285215	1280.191772	0.000000	NaN	NaN
613.500090	0.002543	25.432982	0.286044	1281.017212	0.000000	NaN	NaN
615.000176	0.002411	24.112532	0.286732	1281.702515	0.000000	NaN	NaN
616.500262	0.002543	25.432982	0.287361	1282.328857	0.000000	NaN	NaN
617.999348	0.002461	24.607701	0.288103	1283.068237	0.000000	NaN	NaN
619.499433	0.002535	25.350454	0.288740	1283.702515	0.000000	NaN	NaN
620.999519	0.002527	25.267926	0.289484	1284.443726	0.000000	NaN	NaN
622.499605	0.002585	25.845623	0.290143	1285.100098	0.000000	NaN	NaN
623.999691	0.002585	25.845623	0.290875	1285.829712	0.000000	NaN	NaN
625.499777	0.002552	25.515510	0.291744	1286.695557	0.000000	NaN	NaN
626.999862	0.002510	25.102870	0.292380	1287.328613	0.000000	NaN	NaN
628.499948	0.002576	25.763095	0.293105	1288.051147	0.000000	NaN	NaN
630.000034	0.002543	25.432982	0.293704	1288.647583	0.000000	NaN	NaN
631.500120	0.002494	24.937813	0.294429	1289.369385	0.000000	NaN	NaN
633.000206	0.002552	25.515510	0.295183	1290.120361	0.000000	NaN	NaN
634.500291	0.002626	26.258263	0.295886	1290.820923	0.000000	NaN	NaN
635.999377	0.002527	25.267926	0.296653	1291.585083	0.000000	NaN	NaN
637.499463	0.002601	26.010679	0.297386	1292.315186	0.000000	NaN	NaN
638.999549	0.002576	25.763095	0.298114	1293.040161	0.000000	NaN	NaN
640.499635	0.002568	25.680567	0.298822	1293.745728	0.000000	NaN	NaN
641.999720	0.002609	26.093207	0.299551	1294.471802	0.000000	NaN	NaN
643.499806	0.002477	24.772757	0.300271	1295.189087	0.000000	NaN	NaN
644.999892	0.002469	24.690229	0.300939	1295.854492	0.000000	NaN	NaN
646.499978	0.002601	26.010679	0.301698	1296.609985	0.000000	NaN	NaN
648.000064	0.002502	25.020342	0.302383	1297.292358	0.000000	NaN	NaN
649.500149	0.002527	25.267926	0.303083	1297.989746	0.000000	NaN	NaN
651.000235	0.002634	26.340792	0.303830	1298.734009	0.000000	NaN	NaN
652.499321	0.002593	25.928151	0.304472	1299.373657	0.000000	NaN	NaN
653.999407	0.002568	25.680567	0.305277	1300.175659	0.000000	NaN	NaN
655.499493	0.002618	26.175735	0.305029	1299.928589	0.000000	NaN	NaN
656.999578	0.002527	25.267926	0.306768	1301.660400	0.000000	NaN	NaN
658.499664	0.002543	25.432982	0.307447	1302.337158	0.000000	NaN	NaN
659.999750	0.002618	26.175735	0.308284	1303.170410	0.000000	NaN	NaN
661.499836	0.002486	24.855285	0.308844	1303.728638	0.000000	NaN	NaN
662.999922	0.002626	26.258263	0.309576	1304.457397	0.000000	NaN	NaN
664.500007	0.002601	26.010679	0.310322	1305.200928	0.000000	NaN	NaN
666.000093	0.002510	25.102870	0.310972	1305.848267	0.000000	NaN	NaN
667.500179	0.002585	25.845623	0.311676	1306.548828	0.000000	NaN	NaN
669.000265	0.002618	26.175735	0.312415	1307.284912	0.000000	NaN	NaN
670.499350	0.002576	25.763095	0.313146	1308.013306	0.000000	NaN	NaN
671.999436	0.002626	26.258263	0.313792	1308.656738	0.000000	NaN	NaN
673.499522	0.002626	26.258263	0.314492	1309.354370	0.000000	NaN	NaN
674.999608	0.002552	25.515510	0.315207	1310.066284	0.000000	NaN	NaN
676.499694	0.002717	27.166073	0.315893	1310.750244	0.000000	NaN	NaN
677.999779	0.002651	26.505848	0.316700	1311.553711	0.000000	NaN	NaN
679.499865	0.002527	25.267926	0.317291	1312.141846	0.000000	NaN	NaN
680.999951	0.002700	27.001017	0.317986	1312.834961	0.000000	NaN	NaN
682.500037	0.002585	25.845623	0.318686	1313.531860	0.000000	NaN	NaN
684.000123	0.002601	26.010679	0.319373	1314.216064	0.000000	NaN	NaN
685.500208	0.002601	26.010679	0.320234	1315.073853	0.000000	NaN	NaN
687.000294	0.002634	26.340792	0.320864	1315.701172	0.000000	NaN	NaN
688.499380	0.002552	25.515510	0.321660	1316.494507	0.000000	NaN	NaN
689.999466	0.002568	25.680567	0.322256	1317.087769	0.000000	NaN	NaN
691.499552	0.002510	25.102870	0.323054	1317.882690	0.000000	NaN	NaN
692.999637	0.002576	25.763095	0.323680	1318.506836	0.000000	NaN	NaN
694.499723	0.002799	27.991354	0.324473	1319.296021	0.000000	NaN	NaN
695.999809	0.002667	26.670904	0.325047	1319.868530	0.000000	NaN	NaN
697.499895	0.002601	26.010679	0.325786	1320.604126	0.000000	NaN	NaN
698.999981	0.002700	27.001017	0.326478	1321.293091	0.000000	NaN	NaN
700.500066	0.002684	26.835960	0.327250	1322.062622	0.000000	NaN	NaN
702.000152	0.002626	26.258263	0.328005	1322.814941	0.000000	NaN	NaN
703.500238	0.002535	25.350454	0.328712	1323.518555	0.000000	NaN	NaN
704.999324	0.002593	25.928151	0.329420	1324.223877	0.000000	NaN	NaN
706.499410	0.002700	27.001017	0.330114	1324.915527	0.000000	NaN	NaN
707.999495	0.002535	25.350454	0.330895	1325.693481	0.000000	NaN	NaN
709.499581	0.002618	26.175735	0.331493	1326.289185	0.000000	NaN	NaN
710.999667	0.002626	26.258263	0.332357	1327.149658	0.000000	NaN	NaN
712.499753	0.002684	26.835960	0.333027	1327.816895	0.000000	NaN	NaN
713.999839	0.002626	26.258263	0.333789	1328.576172	0.000000	NaN	NaN
715.499924	0.002708	27.083545	0.334575	1329.358521	0.000000	NaN	NaN
717.000010	0.002601	26.010679	0.335317	1330.098145	0.000000	NaN	NaN
718.500096	0.002659	26.588376	0.335960	1330.738037	0.000000	NaN	NaN
720.000182	0.002659	26.588376	0.336848	1331.622681	0.000000	NaN	NaN
721.500268	0.002609	26.093207	0.337509	1332.281128	0.000000	NaN	NaN
722.999353	0.002618	26.175735	0.338294	1333.063477	0.000000	NaN	NaN
724.499439	0.002642	26.423320	0.339099	1333.865112	0.000000	NaN	NaN
725.999525	0.002733	27.331129	0.339831	1334.594727	0.000000	NaN	NaN
727.499611	0.002659	26.588376	0.340622	1335.382202	0.000000	NaN	NaN
728.999696	0.002642	26.423320	0.341394	1336.151123	0.000000	NaN	NaN
730.499782	0.002601	26.010679	0.342190	1336.944092	0.000000	NaN	NaN
731.999868	0.002725	27.248601	0.342957	1337.707886	0.000000	NaN	NaN
733.499954	0.002708	27.083545	0.343701	1338.449219	0.000000	NaN	NaN
735.000040	0.002552	25.515510	0.344399	1339.144287	0.000000	NaN	NaN
736.500125	0.002708	27.083545	0.345316	1340.058105	0.000000	NaN	NaN
738.000211	0.002519	25.185398	0.345977	1340.716431	0.000000	NaN	NaN
739.500297	0.002593	25.928151	0.346772	1341.507935	0.000000	NaN	NaN
740.999383	0.002659	26.588376	0.347484	1342.217041	0.000000	NaN	NaN
742.499469	0.002585	25.845623	0.348289	1343.018921	0.000000	NaN	NaN
743.999554	0.002626	26.258263	0.349114	1343.840820	0.000000	NaN	NaN
745.499640	0.002692	26.918488	0.349979	1344.702759	0.000000	NaN	NaN
746.999726	0.002626	26.258263	0.350548	1345.269165	0.000000	NaN	NaN
748.499812	0.002766	27.661242	0.351502	1346.219727	0.000000	NaN	NaN
749.999898	0.002651	26.505848	0.352130	1346.845337	0.000000	NaN	NaN
751.499983	0.002675	26.753432	0.352777	1347.489746	0.000000	NaN	NaN
753.000069	0.002601	26.010679	0.353588	1348.297241	0.000000	NaN	NaN
754.500155	0.002684	26.835960	0.354292	1348.998657	0.000000	NaN	NaN
756.000241	0.002634	26.340792	0.355027	1349.731201	0.000000	NaN	NaN
757.499327	0.002733	27.331129	0.355809	1350.510254	0.000000	NaN	NaN
758.999412	0.002717	27.166073	0.356720	1351.416992	0.000000	NaN	NaN
760.499498	0.002576	25.763095	0.357403	1352.097534	0.000000	NaN	NaN
761.999584	0.002618	26.175735	0.358053	1352.745239	0.000000	NaN	NaN
763.499670	0.002667	26.670904	0.358899	1353.587280	0.000000	NaN	NaN
764.999755	0.002626	26.258263	0.359712	1354.398071	0.000000	NaN	NaN
766.499841	0.002684	26.835960	0.360441	1355.123413	0.000000	NaN	NaN
767.999927	0.002725	27.248601	0.361201	1355.880493	0.000000	NaN	NaN
769.500013	0.002692	26.918488	0.361988	1356.664795	0.000000	NaN	NaN
771.000099	0.002733	27.331129	0.362825	1357.498047	0.000000	NaN	NaN
772.500185	0.002634	26.340792	0.363529	1358.200073	0.000000	NaN	NaN
774.000270	0.002758	27.578713	0.364462	1359.129150	0.000000	NaN	NaN
775.499356	0.002700	27.001017	0.365361	1360.024780	0.000000	NaN	NaN
776.999442	0.002692	26.918488	0.365975	1360.636108	0.000000	NaN	NaN
778.499528	0.002568	25.680567	0.366916	1361.573853	0.000000	NaN	NaN
779.999614	0.002766	27.661242	0.367708	1362.361938	0.000000	NaN	NaN
781.499699	0.002667	26.670904	0.368653	1363.304077	0.000000	NaN	NaN
782.999785	0.002700	27.001017	0.369463	1364.110474	0.000000	NaN	NaN
784.499871	0.002725	27.248601	0.370386	1365.029419	0.000000	NaN	NaN
785.999957	0.002659	26.588376	0.371347	1365.987305	0.000000	NaN	NaN
787.500043	0.002684	26.835960	0.372097	1366.734375	0.000000	NaN	NaN
789.000128	0.002733	27.331129	0.373046	1367.679443	0.000000	NaN	NaN
790.500214	0.002675	26.753432	0.373760	1368.390747	0.000000	NaN	NaN
792.000300	0.002642	26.423320	0.374599	1369.226440	0.000000	NaN	NaN
793.499386	0.002585	25.845623	0.375469	1370.093140	0.000000	NaN	NaN
794.999471	0.002560	25.598038	0.376449	1371.069458	0.000000	NaN	NaN
796.499557	0.002609	26.093207	0.377254	1371.870483	0.000000	NaN	NaN
797.999643	0.002609	26.093207	0.378169	1372.781982	0.000000	NaN	NaN
799.499729	0.002626	26.258263	0.378995	1373.605347	0.000000	NaN	NaN
800.999815	0.002576	25.763095	0.380041	1374.646851	0.000000	NaN	NaN
802.499900	0.002601	26.010679	0.380925	1375.527954	0.000000	NaN	NaN
803.999986	0.002502	25.020342	0.381941	1376.539795	0.000000	NaN	NaN
805.500072	0.002626	26.258263	0.382819	1377.413818	0.000000	NaN	NaN
807.000158	0.002576	25.763095	0.383775	1378.365967	0.000000	NaN	NaN
808.500244	0.002659	26.588376	0.384757	1379.344971	0.000000	NaN	NaN
809.999329	0.002585	25.845623	0.385658	1380.241699	0.000000	NaN	NaN
811.499415	0.002535	25.350454	0.386735	1381.314819	0.000000	NaN	NaN
812.999501	0.002494	24.937813	0.387691	1382.267334	0.000000	NaN	NaN
814.499587	0.002535	25.350454	0.388730	1383.302368	0.000000	NaN	NaN
815.999673	0.002543	25.432982	0.389688	1384.256226	0.000000	NaN	NaN
817.499758	0.002609	26.093207	0.390594	1385.158691	0.000000	NaN	NaN
818.999844	0.002560	25.598038	0.391729	1386.289185	0.000000	NaN	NaN
820.499930	0.002411	24.112532	0.392882	1387.437744	0.000000	NaN	NaN
822.000016	0.002675	26.753432	0.393900	1388.451538	0.000000	NaN	NaN
823.500102	0.002593	25.928151	0.394955	1389.502686	0.000000	NaN	NaN
825.000187	0.002659	26.588376	0.395772	1390.316650	0.000000	NaN	NaN
826.500273	0.002444	24.442645	0.397109	1391.648804	0.000000	NaN	NaN
827.999359	0.002519	25.185398	0.398183	1392.718506	0.000000	NaN	NaN
829.499445	0.002560	25.598038	0.399239	1393.770142	0.000000	NaN	NaN
830.999530	0.002519	25.185398	0.400432	1394.958496	0.000000	NaN	NaN
832.499616	0.002552	25.515510	0.401512	1396.034302	0.000000	NaN	NaN
833.999702	0.002626	26.258263	0.402775	1397.292603	0.000000	NaN	NaN
835.499788	0.002403	24.030004	0.403815	1398.328003	0.000000	NaN	NaN
836.999874	0.002552	25.515510	0.404158	1398.669312	0.000000	NaN	NaN
838.499960	0.002420	24.195060	0.404884	1399.392944	0.000000	NaN	NaN
840.000045	0.002320	23.204723	0.406236	1400.739746	0.000000	NaN	NaN
841.500131	0.002469	24.690229	0.407224	1401.723999	0.000000	NaN	NaN
843.000217	0.002345	23.452307	0.408376	1402.871338	0.000000	NaN	NaN
844.500303	0.002411	24.112532	0.409783	1404.272339	0.000000	NaN	NaN
845.999388	0.002519	25.185398	0.410983	1405.468628	0.000000	NaN	NaN
847.499474	0.002486	24.855285	0.412350	1406.830078	0.000000	NaN	NaN
848.999560	0.002320	23.204723	0.413397	1407.872437	0.000000	NaN	NaN
850.499646	0.002461	24.607701	0.414779	1409.248901	0.000000	NaN	NaN
851.999732	0.002411	24.112532	0.416153	1410.618408	0.000000	NaN	NaN
853.499817	0.002263	22.627026	0.417436	1411.895508	0.000000	NaN	NaN
854.999903	0.002378	23.782420	0.418878	1413.332031	0.000000	NaN	NaN
856.499989	0.002378	23.782420	0.420296	1414.744629	0.000000	NaN	NaN
858.000075	0.002287	22.874610	0.421535	1415.978760	0.000000	NaN	NaN
859.500161	0.002205	22.049329	0.423065	1417.502563	0.000000	NaN	NaN
861.000246	0.002213	22.131857	0.424476	1418.908325	0.000000	NaN	NaN
862.499332	0.002147	21.471632	0.426051	1420.477295	0.000000	NaN	NaN
863.999418	0.002304	23.039667	0.427603	1422.023560	0.000000	NaN	NaN
865.499504	0.002188	21.884273	0.429108	1423.522095	0.000000	NaN	NaN
866.999590	0.002131	21.306576	0.430717	1425.125000	0.000000	NaN	NaN
868.499675	0.002131	21.306576	0.432215	1426.617432	0.000000	NaN	NaN
869.999761	0.002089	20.893935	0.433961	1428.356201	0.000000	NaN	NaN
871.499847	0.002172	21.719217	0.435532	1429.921631	0.000000	NaN	NaN
872.999933	0.002032	20.316239	0.437486	1431.867554	0.000000	NaN	NaN
874.500019	0.001966	19.656014	0.438999	1433.375000	0.000000	NaN	NaN
876.000104	0.002007	20.068654	0.441047	1435.414307	0.000000	NaN	NaN
877.500190	0.001817	18.170507	0.442987	1437.347534	0.000000	NaN	NaN
879.000276	0.001834	18.335564	0.443826	1438.183228	0.000000	NaN	NaN
880.499362	0.001883	18.830732	0.446602	1440.947754	0.000000	NaN	NaN
881.999447	0.001702	17.015114	0.448691	1443.028931	0.000000	NaN	NaN
883.499533	0.001834	18.335564	0.450755	1445.084961	0.000000	NaN	NaN
884.999619	0.001627	16.272360	0.452841	1447.162231	0.000000	NaN	NaN
886.499705	0.001644	16.437417	0.455238	1449.550659	0.000000	NaN	NaN
887.999791	0.001536	15.364551	0.457634	1451.937134	0.000000	NaN	NaN
889.499877	0.001421	14.209157	0.460171	1454.464355	0.000000	NaN	NaN
890.999962	0.001421	14.209157	0.462623	1456.906006	0.000000	NaN	NaN
892.500048	0.001330	13.301348	0.464995	1459.269409	0.000000	NaN	NaN
894.000134	0.001330	13.301348	0.467597	1461.860474	0.000000	NaN	NaN
895.500220	0.001272	12.723651	0.470762	1465.013794	0.000000	NaN	NaN
896.999305	0.001182	11.815842	0.474068	1468.306763	0.000000	NaN	NaN
898.499391	0.000843	8.432188	0.479312	1473.530151	0.000000	NaN	NaN
899.999477	0.000785	7.854492	0.484715	1478.911987	0.000000	NaN	NaN
901.499563	0.000744	7.441851	0.488373	1482.555908	0.000000	NaN	NaN
902.999649	0.000662	6.616570	0.492243	1486.410889	0.000000	NaN	NaN
904.499735	0.000604	6.038873	0.495485	1489.640259	0.000000	NaN	NaN
905.999820	0.000620	6.203929	0.498512	1492.654663	0.000000	NaN	NaN
907.499906	0.000389	3.893141	0.501372	1495.503418	0.000000	NaN	NaN
908.999992	0.000348	3.480501	0.504124	1498.245361	0.000000	NaN	NaN
910.500078	0.000398	3.975670	0.506901	1501.011108	0.000000	NaN	NaN
912.000163	0.000290	2.902804	0.509513	1503.613525	0.000000	NaN	NaN
913.500249	0.000422	4.223254	0.512245	1506.334351	0.000000	NaN	NaN
914.999335	0.000233	2.325107	0.514809	1508.887939	0.000000	NaN	NaN
916.499421	0.000348	3.480501	0.516912	1510.983032	0.000000	NaN	NaN
917.999507	0.000191	1.912466	0.519382	1513.443359	0.000000	NaN	NaN
919.499592	0.000109	1.087185	0.522031	1516.082520	0.000000	NaN	NaN
920.999678	0.000150	1.499826	0.524600	1518.641357	0.000000	NaN	NaN
921.999735	0.000241	2.407635	0.526435	1520.468994	0.000000	NaN	NaN