File: data/57k_1-10_1 (190315).lvm
LabVIEW Measurement
Writer_Version	2
Reader_Version	2
Separator	Tab
Decimal_Separator	.
Multi_Headings	No
X_Columns	One
Time_Pref	Absolute
Operator	user
Description	Load(N)/Stress(MPa)/Distance A(pixel)/Strain A/Distance B(pixel)/Strain B/Poisson's ratio
Date	2019/03/15
Time	14:37:29.3127093315124511719
***End_of_Header***

Notes	X 값은 오직 다음과 같을 때에만 유효함이 보장됩니다. Dev1/ai0
Channels	7
Samples	1	1	1	1	1	1	1
Date	2019/03/15	2019/03/15	2019/03/15	2019/03/15	2019/03/15	2019/03/15	2019/03/15
Time	14:37:29.3127094300349911122	14:37:29.3127094300349911122	14:37:29.3127093315124511719	14:37:29.3127093315124511719	14:37:29.3127093315124511719	14:37:29.3127093315124511719	14:37:29.3127093315124511719
Y_Unit_Label	Volts	Volts
X_Dimension	Time	Time	Time	Time	Time	Time	Time
X0	0.0000000000000000E+0	0.0000000000000000E+0	0.0000000000000000E+0	0.0000000000000000E+0	0.0000000000000000E+0	0.0000000000000000E+0	0.0000000000000000E+0
Delta_X	0.000000	0.000000	1.000000	1.000000	1.000000	1.000000	1.000000
***End_of_Header***
X_Value	Dev1/ai0	Dev1/ai0 1	Untitled	Untitled 1	Untitled 2	Untitled 3	Untitled 4	Comment
0.000000	-7.284337E-5	-0.728434	-8.171797E-5	1002.157288	0.000000	NaN	NaN
1.000057	5.094882E-5	0.509488	-7.981062E-5	1002.159180	0.000000	NaN	NaN
2.000114	-5.633774E-5	-0.563377	8.225441E-5	1002.321594	0.000000	NaN	NaN
3.000172	-2.332649E-5	-0.233265	2.753735E-5	1002.266785	0.000000	NaN	NaN
4.000229	5.920164E-5	0.592016	0.000373	1002.612915	0.000000	NaN	NaN
5.000286	9.684761E-6	0.096848	0.000726	1002.967102	0.000000	NaN	NaN
5.999343	6.745445E-5	0.674545	0.001002	1003.243652	0.000000	NaN	NaN
6.999400	0.000166	1.664882	0.001442	1003.684875	0.000000	NaN	NaN
7.999458	0.000183	1.829938	0.001808	1004.050781	0.000000	NaN	NaN
8.999515	0.000109	1.087185	0.002044	1004.288269	0.000000	NaN	NaN
9.999572	0.000166	1.664882	0.002308	1004.551880	0.000000	NaN	NaN
10.999629	6.745445E-5	0.674545	0.002582	1004.827209	0.000000	NaN	NaN
11.999686	0.000175	1.747410	0.003000	1005.245544	0.000000	NaN	NaN
12.999744	0.000191	1.912466	0.003233	1005.479065	0.000000	NaN	NaN
13.999801	0.000100	1.004657	0.003752	1005.999573	0.000000	NaN	NaN
14.999858	0.000257	2.572691	0.003865	1006.112671	0.000000	NaN	NaN
15.999915	0.000150	1.499826	0.004298	1006.546997	0.000000	NaN	NaN
16.999972	0.000290	2.902804	0.004532	1006.781555	0.000000	NaN	NaN
18.000030	0.000290	2.902804	0.004992	1007.241882	0.000000	NaN	NaN
19.000087	0.000365	3.645557	0.005331	1007.581970	0.000000	NaN	NaN
20.000144	0.000224	2.242579	0.005594	1007.845520	0.000000	NaN	NaN
21.000201	0.000299	2.985332	0.005901	1008.153198	0.000000	NaN	NaN
22.000258	0.000315	3.150388	0.006116	1008.369263	0.000000	NaN	NaN
23.000315	0.000348	3.480501	0.006284	1008.537659	0.000000	NaN	NaN
23.999373	0.000315	3.150388	0.006680	1008.934021	0.000000	NaN	NaN
24.999430	0.000266	2.655220	0.006955	1009.209839	0.000000	NaN	NaN
25.999487	0.000307	3.067860	0.007543	1009.799255	0.000000	NaN	NaN
26.999544	0.000381	3.810613	0.007847	1010.103577	0.000000	NaN	NaN
27.999602	0.000299	2.985332	0.008135	1010.392273	0.000000	NaN	NaN
28.999659	0.000356	3.563029	0.008765	1011.023621	0.000000	NaN	NaN
29.999716	0.000365	3.645557	0.008862	1011.121399	0.000000	NaN	NaN
30.999773	0.000257	2.572691	0.009637	1011.897705	0.000000	NaN	NaN
31.999830	0.000299	2.985332	0.009949	1012.210815	0.000000	NaN	NaN
32.999887	0.000422	4.223254	0.010178	1012.439758	0.000000	NaN	NaN
33.999945	0.000398	3.975670	0.010625	1012.888245	0.000000	NaN	NaN
35.000002	0.000389	3.893141	0.011030	1013.293823	0.000000	NaN	NaN
36.000059	0.000604	6.038873	0.011538	1013.802795	0.000000	NaN	NaN
37.000116	0.000439	4.388310	0.012274	1014.540710	0.000000	NaN	NaN
38.000174	0.000488	4.883479	0.012608	1014.875061	0.000000	NaN	NaN
39.000231	0.000472	4.718423	0.013059	1015.327759	0.000000	NaN	NaN
40.000288	0.000373	3.728085	0.013046	1015.314636	0.000000	NaN	NaN
40.999345	0.000488	4.883479	0.013616	1015.885498	0.000000	NaN	NaN
41.999402	0.000447	4.470838	0.014197	1016.467529	0.000000	NaN	NaN
42.999459	0.000530	5.296120	0.014596	1016.867981	0.000000	NaN	NaN
43.999517	0.000414	4.140726	0.014827	1017.099548	0.000000	NaN	NaN
44.999574	0.000554	5.543704	0.015078	1017.350891	0.000000	NaN	NaN
45.999631	0.000579	5.791288	0.015598	1017.872009	0.000000	NaN	NaN
46.999688	0.000546	5.461176	0.016227	1018.502686	0.000000	NaN	NaN
47.999745	0.000538	5.378648	0.016338	1018.613464	0.000000	NaN	NaN
48.999803	0.000497	4.966007	0.016826	1019.102600	0.000000	NaN	NaN
49.999860	0.000563	5.626232	0.016907	1019.183899	0.000000	NaN	NaN
50.999917	0.000521	5.213591	0.017840	1020.119019	0.000000	NaN	NaN
51.999974	0.000653	6.534042	0.018087	1020.366516	0.000000	NaN	NaN
53.000031	0.000587	5.873817	0.018339	1020.619019	0.000000	NaN	NaN
54.000089	0.000563	5.626232	0.018535	1020.815369	0.000000	NaN	NaN
55.000146	0.000620	6.203929	0.018735	1021.015686	0.000000	NaN	NaN
56.000203	0.000579	5.791288	0.019153	1021.434875	0.000000	NaN	NaN
57.000260	0.000744	7.441851	0.019358	1021.640320	0.000000	NaN	NaN
58.000317	0.000719	7.194267	0.019901	1022.184814	0.000000	NaN	NaN
58.999375	0.000744	7.441851	0.020035	1022.318726	0.000000	NaN	NaN
59.999432	0.000662	6.616570	0.020411	1022.695618	0.000000	NaN	NaN
60.999489	0.000719	7.194267	0.020607	1022.892700	0.000000	NaN	NaN
61.999546	0.000744	7.441851	0.020736	1023.021240	0.000000	NaN	NaN
62.999603	0.000653	6.534042	0.020167	1022.451416	0.000000	NaN	NaN
63.999661	0.000695	6.946682	0.020557	1022.841858	0.000000	NaN	NaN
64.999718	0.000728	7.276795	0.020937	1023.222656	0.000000	NaN	NaN
65.999775	0.000670	6.699098	0.021186	1023.472778	0.000000	NaN	NaN
66.999832	0.000686	6.864154	0.021474	1023.761414	0.000000	NaN	NaN
67.999889	0.000769	7.689435	0.021971	1024.259277	0.000000	NaN	NaN
68.999947	0.000802	8.019548	0.022339	1024.627686	0.000000	NaN	NaN
70.000004	0.000703	7.029210	0.022663	1024.953247	0.000000	NaN	NaN
71.000061	0.000703	7.029210	0.023146	1025.436890	0.000000	NaN	NaN
72.000118	0.000769	7.689435	0.023312	1025.603394	0.000000	NaN	NaN
73.000175	0.000851	8.514717	0.023780	1026.072876	0.000000	NaN	NaN
74.000233	0.000703	7.029210	0.024106	1026.398926	0.000000	NaN	NaN
75.000290	0.000777	7.771963	0.024338	1026.631836	0.000000	NaN	NaN
75.999347	0.000851	8.514717	0.024829	1027.123413	0.000000	NaN	NaN
76.999404	0.000686	6.864154	0.025226	1027.521973	0.000000	NaN	NaN
77.999461	0.000620	6.203929	0.025624	1027.920410	0.000000	NaN	NaN
78.999518	0.000777	7.771963	0.025952	1028.248779	0.000000	NaN	NaN
79.999576	0.000711	7.111738	0.026216	1028.514282	0.000000	NaN	NaN
80.999633	0.000678	6.781626	0.026569	1028.867187	0.000000	NaN	NaN
81.999690	0.000827	8.267132	0.026799	1029.098633	0.000000	NaN	NaN
82.999747	0.000851	8.514717	0.027357	1029.657837	0.000000	NaN	NaN
83.999804	0.000752	7.524379	0.027760	1030.061401	0.000000	NaN	NaN
84.999862	0.000761	7.606907	0.027957	1030.259033	0.000000	NaN	NaN
85.999919	0.000802	8.019548	0.028485	1030.787842	0.000000	NaN	NaN
86.999976	0.000818	8.184604	0.028900	1031.204102	0.000000	NaN	NaN
88.000033	0.000835	8.349660	0.029258	1031.563110	0.000000	NaN	NaN
89.000090	0.000802	8.019548	0.029619	1031.924194	0.000000	NaN	NaN
90.000148	0.000827	8.267132	0.030128	1032.435059	0.000000	NaN	NaN
91.000205	0.000794	7.937020	0.030504	1032.812012	0.000000	NaN	NaN
92.000262	0.000802	8.019548	0.030743	1033.050537	0.000000	NaN	NaN
93.000319	0.000835	8.349660	0.031055	1033.363647	0.000000	NaN	NaN
93.999376	0.000851	8.514717	0.031572	1033.881836	0.000000	NaN	NaN
94.999434	0.000876	8.762301	0.031870	1034.180542	0.000000	NaN	NaN
95.999491	0.000876	8.762301	0.032365	1034.676758	0.000000	NaN	NaN
96.999548	0.000851	8.514717	0.032727	1035.039185	0.000000	NaN	NaN
97.999605	0.000851	8.514717	0.033143	1035.456299	0.000000	NaN	NaN
98.999662	0.000818	8.184604	0.033556	1035.869873	0.000000	NaN	NaN
99.999720	0.000785	7.854492	0.033932	1036.247681	0.000000	NaN	NaN
100.999777	0.001058	10.577920	0.034142	1036.458008	0.000000	NaN	NaN
101.999834	0.000909	9.092413	0.033704	1036.018799	0.000000	NaN	NaN
102.999891	0.000876	8.762301	0.034168	1036.484131	0.000000	NaN	NaN
103.999949	0.000785	7.854492	0.034487	1036.803955	0.000000	NaN	NaN
105.000006	0.000777	7.771963	0.034976	1037.293823	0.000000	NaN	NaN
106.000063	0.000959	9.587582	0.035347	1037.665527	0.000000	NaN	NaN
107.000120	0.000835	8.349660	0.035763	1038.082153	0.000000	NaN	NaN
108.000177	0.000901	9.009885	0.036291	1038.611450	0.000000	NaN	NaN
109.000235	0.000777	7.771963	0.036548	1038.869019	0.000000	NaN	NaN
110.000292	0.000884	8.844829	0.037028	1039.349976	0.000000	NaN	NaN
110.999349	0.000843	8.432188	0.037351	1039.673828	0.000000	NaN	NaN
111.999406	0.000802	8.019548	0.037748	1040.071411	0.000000	NaN	NaN
112.999463	0.000703	7.029210	0.038371	1040.696411	0.000000	NaN	NaN
113.999520	0.000876	8.762301	0.038549	1040.874512	0.000000	NaN	NaN
114.999578	0.000802	8.019548	0.039096	1041.423096	0.000000	NaN	NaN
115.999635	0.000851	8.514717	0.039565	1041.893188	0.000000	NaN	NaN
116.999692	0.000876	8.762301	0.039888	1042.216064	0.000000	NaN	NaN
117.999749	0.000926	9.257470	0.040366	1042.695801	0.000000	NaN	NaN
118.999806	0.000967	9.670110	0.040661	1042.990845	0.000000	NaN	NaN
119.999864	0.000860	8.597245	0.041047	1043.377686	0.000000	NaN	NaN
120.999921	0.000777	7.771963	0.041487	1043.818970	0.000000	NaN	NaN
121.999978	0.000917	9.174942	0.041983	1044.316650	0.000000	NaN	NaN
123.000035	0.000876	8.762301	0.042427	1044.760864	0.000000	NaN	NaN
124.000092	0.000934	9.339998	0.042748	1045.083252	0.000000	NaN	NaN
125.000150	0.000860	8.597245	0.043254	1045.589966	0.000000	NaN	NaN
126.000207	0.000884	8.844829	0.043752	1046.089233	0.000000	NaN	NaN
127.000264	0.000884	8.844829	0.044051	1046.388550	0.000000	NaN	NaN
128.000321	0.000860	8.597245	0.044442	1046.780762	0.000000	NaN	NaN
128.999378	0.000926	9.257470	0.045016	1047.355713	0.000000	NaN	NaN
129.999436	0.001033	10.330335	0.045422	1047.763306	0.000000	NaN	NaN
130.999493	0.000901	9.009885	0.045782	1048.123535	0.000000	NaN	NaN
131.999550	0.000884	8.844829	0.046118	1048.460449	0.000000	NaN	NaN
132.999607	0.000984	9.835167	0.046351	1048.693848	0.000000	NaN	NaN
133.999664	0.000860	8.597245	0.046194	1048.536621	0.000000	NaN	NaN
134.999721	0.000893	8.927357	0.046715	1049.059082	0.000000	NaN	NaN
135.999779	0.000901	9.009885	0.047222	1049.567261	0.000000	NaN	NaN
136.999836	0.001017	10.165279	0.047554	1049.899414	0.000000	NaN	NaN
137.999893	0.001074	10.742976	0.048013	1050.359863	0.000000	NaN	NaN
138.999950	0.000926	9.257470	0.048544	1050.891846	0.000000	NaN	NaN
140.000008	0.000926	9.257470	0.049039	1051.387939	0.000000	NaN	NaN
141.000065	0.000827	8.267132	0.049389	1051.738647	0.000000	NaN	NaN
142.000122	0.000959	9.587582	0.049891	1052.241699	0.000000	NaN	NaN
143.000179	0.000975	9.752638	0.050296	1052.648071	0.000000	NaN	NaN
144.000236	0.000901	9.009885	0.050798	1053.151245	0.000000	NaN	NaN
145.000293	0.000975	9.752638	0.051332	1053.685791	0.000000	NaN	NaN
145.999351	0.000951	9.505054	0.051633	1053.988159	0.000000	NaN	NaN
146.999408	0.000992	9.917695	0.052108	1054.463501	0.000000	NaN	NaN
147.999465	0.001017	10.165279	0.052531	1054.887329	0.000000	NaN	NaN
148.999522	0.000975	9.752638	0.052966	1055.324097	0.000000	NaN	NaN
149.999580	0.000926	9.257470	0.053385	1055.743530	0.000000	NaN	NaN
150.999637	0.000959	9.587582	0.053812	1056.171753	0.000000	NaN	NaN
151.999694	0.000901	9.009885	0.054331	1056.691528	0.000000	NaN	NaN
152.999751	0.001083	10.825504	0.054744	1057.106201	0.000000	NaN	NaN
153.999808	0.000967	9.670110	0.055233	1057.595825	0.000000	NaN	NaN
154.999865	0.000942	9.422526	0.055734	1058.097534	0.000000	NaN	NaN
155.999923	0.000959	9.587582	0.055980	1058.344116	0.000000	NaN	NaN
156.999980	0.001041	10.412863	0.056549	1058.914429	0.000000	NaN	NaN
158.000037	0.001008	10.082751	0.056844	1059.210693	0.000000	NaN	NaN
159.000094	0.001041	10.412863	0.057349	1059.716797	0.000000	NaN	NaN
160.000151	0.000975	9.752638	0.057874	1060.243286	0.000000	NaN	NaN
161.000209	0.000984	9.835167	0.058254	1060.624023	0.000000	NaN	NaN
162.000266	0.000917	9.174942	0.058796	1061.166870	0.000000	NaN	NaN
163.000323	0.000851	8.514717	0.059266	1061.638306	0.000000	NaN	NaN
163.999380	0.000975	9.752638	0.059819	1062.192261	0.000000	NaN	NaN
164.999437	0.000934	9.339998	0.060131	1062.505005	0.000000	NaN	NaN
165.999495	0.000951	9.505054	0.060689	1063.064575	0.000000	NaN	NaN
166.999552	0.001050	10.495392	0.061052	1063.427979	0.000000	NaN	NaN
167.999609	0.000810	8.102076	0.061633	1064.010010	0.000000	NaN	NaN
168.999666	0.000901	9.009885	0.062003	1064.380981	0.000000	NaN	NaN
169.999723	0.000951	9.505054	0.062511	1064.890015	0.000000	NaN	NaN
170.999781	0.001033	10.330335	0.062850	1065.229614	0.000000	NaN	NaN
171.999838	0.000992	9.917695	0.063291	1065.671875	0.000000	NaN	NaN
172.999895	0.000951	9.505054	0.063781	1066.162842	0.000000	NaN	NaN
173.999952	0.001000	10.000223	0.064234	1066.616943	0.000000	NaN	NaN
175.000009	0.000984	9.835167	0.064758	1067.142578	0.000000	NaN	NaN
176.000067	0.001058	10.577920	0.065141	1067.525635	0.000000	NaN	NaN
177.000124	0.000975	9.752638	0.065740	1068.126709	0.000000	NaN	NaN
178.000181	0.000901	9.009885	0.066155	1068.541870	0.000000	NaN	NaN
179.000238	0.000909	9.092413	0.066600	1068.988770	0.000000	NaN	NaN
180.000295	0.000984	9.835167	0.067058	1069.447021	0.000000	NaN	NaN
180.999353	0.001058	10.577920	0.067448	1069.838013	0.000000	NaN	NaN
181.999410	0.000959	9.587582	0.067884	1070.274780	0.000000	NaN	NaN
182.999467	0.000901	9.009885	0.068523	1070.916016	0.000000	NaN	NaN
183.999524	0.000992	9.917695	0.068932	1071.325317	0.000000	NaN	NaN
184.999581	0.000992	9.917695	0.069286	1071.680542	0.000000	NaN	NaN
185.999639	0.000975	9.752638	0.069912	1072.307617	0.000000	NaN	NaN
186.999696	0.001058	10.577920	0.070187	1072.583862	0.000000	NaN	NaN
187.999753	0.000843	8.432188	0.070779	1073.176270	0.000000	NaN	NaN
188.999810	0.001000	10.000223	0.071292	1073.691040	0.000000	NaN	NaN
189.999867	0.000917	9.174942	0.071720	1074.119629	0.000000	NaN	NaN
190.999925	0.000868	8.679773	0.072179	1074.579590	0.000000	NaN	NaN
191.999982	0.001033	10.330335	0.072610	1075.012085	0.000000	NaN	NaN
193.000039	0.000975	9.752638	0.073045	1075.447510	0.000000	NaN	NaN
194.000096	0.000992	9.917695	0.073467	1075.870850	0.000000	NaN	NaN
195.000153	0.001017	10.165279	0.073920	1076.324585	0.000000	NaN	NaN
196.000211	0.001091	10.908032	0.074427	1076.833252	0.000000	NaN	NaN
197.000268	0.001000	10.000223	0.074865	1077.271851	0.000000	NaN	NaN
198.000325	0.001017	10.165279	0.075395	1077.802734	0.000000	NaN	NaN
198.999382	0.001091	10.908032	0.075757	1078.165894	0.000000	NaN	NaN
199.999439	0.001033	10.330335	0.076303	1078.713013	0.000000	NaN	NaN
200.999496	0.001000	10.000223	0.076729	1079.139893	0.000000	NaN	NaN
201.999554	0.000984	9.835167	0.077163	1079.575073	0.000000	NaN	NaN
202.999611	0.001074	10.742976	0.077673	1080.086548	0.000000	NaN	NaN
203.999668	0.000967	9.670110	0.078106	1080.520264	0.000000	NaN	NaN
204.999725	0.001149	11.485729	0.078654	1081.069458	0.000000	NaN	NaN
205.999783	0.001066	10.660448	0.079049	1081.464722	0.000000	NaN	NaN
206.999840	0.001058	10.577920	0.079568	1081.985107	0.000000	NaN	NaN
207.999897	0.000992	9.917695	0.079982	1082.400391	0.000000	NaN	NaN
208.999954	0.001058	10.577920	0.080506	1082.925781	0.000000	NaN	NaN
210.000011	0.001050	10.495392	0.080969	1083.390015	0.000000	NaN	NaN
211.000068	0.001033	10.330335	0.081446	1083.867187	0.000000	NaN	NaN
212.000126	0.000959	9.587582	0.081855	1084.277466	0.000000	NaN	NaN
213.000183	0.000967	9.670110	0.082426	1084.849609	0.000000	NaN	NaN
214.000240	0.001000	10.000223	0.082981	1085.406128	0.000000	NaN	NaN
215.000297	0.000967	9.670110	0.083379	1085.804810	0.000000	NaN	NaN
215.999355	0.000975	9.752638	0.083870	1086.297119	0.000000	NaN	NaN
216.999412	0.001116	11.155617	0.084360	1086.788330	0.000000	NaN	NaN
217.999469	0.001173	11.733313	0.084656	1087.084717	0.000000	NaN	NaN
218.999526	0.001124	11.238145	0.085230	1087.659546	0.000000	NaN	NaN
219.999583	0.001025	10.247807	0.085782	1088.213013	0.000000	NaN	NaN
220.999640	0.000984	9.835167	0.086278	1088.710693	0.000000	NaN	NaN
221.999698	0.000917	9.174942	0.086682	1089.115723	0.000000	NaN	NaN
222.999755	0.001083	10.825504	0.087246	1089.680176	0.000000	NaN	NaN
223.999812	0.001173	11.733313	0.087661	1090.096069	0.000000	NaN	NaN
224.999869	0.001050	10.495392	0.088159	1090.595337	0.000000	NaN	NaN
225.999926	0.001066	10.660448	0.088598	1091.035889	0.000000	NaN	NaN
226.999984	0.000934	9.339998	0.089252	1091.691162	0.000000	NaN	NaN
228.000041	0.000992	9.917695	0.089609	1092.048706	0.000000	NaN	NaN
229.000098	0.000992	9.917695	0.089969	1092.410034	0.000000	NaN	NaN
230.000155	0.001017	10.165279	0.090131	1092.571777	0.000000	NaN	NaN
231.000213	0.001058	10.577920	0.090724	1093.166870	0.000000	NaN	NaN
232.000270	0.000967	9.670110	0.091023	1093.465820	0.000000	NaN	NaN
233.000327	0.000992	9.917695	0.091588	1094.032349	0.000000	NaN	NaN
233.999384	0.001074	10.742976	0.092122	1094.567261	0.000000	NaN	NaN
234.999441	0.001074	10.742976	0.092531	1094.977539	0.000000	NaN	NaN
235.999498	0.001000	10.000223	0.092930	1095.377441	0.000000	NaN	NaN
236.999556	0.001058	10.577920	0.093452	1095.900269	0.000000	NaN	NaN
237.999613	0.001099	10.990560	0.093868	1096.317749	0.000000	NaN	NaN
238.999670	0.001107	11.073088	0.094301	1096.751099	0.000000	NaN	NaN
239.999727	0.000893	8.927357	0.094722	1097.173340	0.000000	NaN	NaN
240.999784	0.001041	10.412863	0.095129	1097.581665	0.000000	NaN	NaN
241.999842	0.001132	11.320673	0.095380	1097.833008	0.000000	NaN	NaN
242.999899	0.001058	10.577920	-0.005525	996.701660	0.000000	NaN	NaN
243.999956	0.000967	9.670110	-0.003588	998.642639	0.000000	NaN	NaN
245.000013	0.001008	10.082751	0.228682	1231.432983	0.000000	NaN	NaN
246.000070	0.001132	11.320673	-0.004413	997.816101	0.000000	NaN	NaN
247.000128	0.000992	9.917695	0.246674	1249.465210	0.000000	NaN	NaN
248.000185	0.001132	11.320673	-0.036555	965.601929	0.000000	NaN	NaN
249.000242	0.001091	10.908032	-0.034522	967.640259	0.000000	NaN	NaN
250.000299	0.001033	10.330335	0.097530	1099.987183	0.000000	NaN	NaN
250.999356	0.001132	11.320673	0.097918	1100.376221	0.000000	NaN	NaN
251.999414	0.001033	10.330335	0.098424	1100.883667	0.000000	NaN	NaN
252.999471	0.000951	9.505054	0.098959	1101.420288	0.000000	NaN	NaN
253.999528	0.001099	10.990560	0.099350	1101.811523	0.000000	NaN	NaN
254.999585	0.001132	11.320673	0.099854	1102.316895	0.000000	NaN	NaN
255.999642	0.001091	10.908032	0.100421	1102.884644	0.000000	NaN	NaN
256.999700	0.001091	10.908032	0.100776	1103.240845	0.000000	NaN	NaN
257.999757	0.001239	12.393538	0.101253	1103.718506	0.000000	NaN	NaN
258.999814	0.001041	10.412863	0.101687	1104.153564	0.000000	NaN	NaN
259.999871	0.001025	10.247807	0.102078	1104.545532	0.000000	NaN	NaN
260.999928	0.001091	10.908032	0.102638	1105.106689	0.000000	NaN	NaN
261.999985	0.001091	10.908032	0.103095	1105.565308	0.000000	NaN	NaN
263.000043	0.001033	10.330335	0.103485	1105.955688	0.000000	NaN	NaN
264.000100	0.001017	10.165279	0.103952	1106.423950	0.000000	NaN	NaN
265.000157	0.001116	11.155617	0.104412	1106.885010	0.000000	NaN	NaN
266.000214	0.001074	10.742976	0.104904	1107.378296	0.000000	NaN	NaN
267.000271	0.001066	10.660448	0.105428	1107.902954	0.000000	NaN	NaN
268.000329	0.001050	10.495392	0.105787	1108.263062	0.000000	NaN	NaN
268.999386	0.001058	10.577920	0.106408	1108.885620	0.000000	NaN	NaN
269.999443	0.001017	10.165279	0.106853	1109.330933	0.000000	NaN	NaN
270.999500	0.001173	11.733313	0.107304	1109.783081	0.000000	NaN	NaN
271.999557	0.001099	10.990560	0.107772	1110.252930	0.000000	NaN	NaN
272.999615	0.001165	11.650785	0.108294	1110.775513	0.000000	NaN	NaN
273.999672	0.001066	10.660448	0.108625	1111.107422	0.000000	NaN	NaN
274.999729	0.001058	10.577920	0.109188	1111.671509	0.000000	NaN	NaN
275.999786	0.001066	10.660448	0.109668	1112.153076	0.000000	NaN	NaN
276.999843	0.001025	10.247807	0.110065	1112.551147	0.000000	NaN	NaN
277.999901	0.000959	9.587582	0.110515	1113.002197	0.000000	NaN	NaN
278.999958	0.001099	10.990560	0.111153	1113.640991	0.000000	NaN	NaN
280.000015	0.001083	10.825504	0.111596	1114.085083	0.000000	NaN	NaN
281.000072	0.001132	11.320673	0.111997	1114.487427	0.000000	NaN	NaN
282.000130	0.001041	10.412863	0.112470	1114.961060	0.000000	NaN	NaN
283.000187	0.001165	11.650785	0.112929	1115.420654	0.000000	NaN	NaN
284.000244	0.001149	11.485729	0.113424	1115.917114	0.000000	NaN	NaN
285.000301	0.001074	10.742976	0.113868	1116.362061	0.000000	NaN	NaN
285.999358	0.001000	10.000223	0.114329	1116.824585	0.000000	NaN	NaN
286.999415	0.001000	10.000223	0.114863	1117.359497	0.000000	NaN	NaN
287.999473	0.001074	10.742976	0.115365	1117.862183	0.000000	NaN	NaN
288.999530	0.001025	10.247807	0.115724	1118.222534	0.000000	NaN	NaN
289.999587	0.001058	10.577920	0.116163	1118.662109	0.000000	NaN	NaN
290.999644	0.001091	10.908032	0.116670	1119.170776	0.000000	NaN	NaN
291.999701	0.001149	11.485729	0.117088	1119.589844	0.000000	NaN	NaN
292.999759	0.001008	10.082751	0.117576	1120.078979	0.000000	NaN	NaN
293.999816	0.001149	11.485729	0.118012	1120.515137	0.000000	NaN	NaN
294.999873	0.001000	10.000223	0.118521	1121.025391	0.000000	NaN	NaN
295.999930	0.000975	9.752638	0.118909	1121.414795	0.000000	NaN	NaN
296.999987	0.001050	10.495392	0.119424	1121.930786	0.000000	NaN	NaN
298.000045	0.001157	11.568257	0.119877	1122.385010	0.000000	NaN	NaN
299.000102	0.001074	10.742976	0.120330	1122.838501	0.000000	NaN	NaN
300.000159	0.001066	10.660448	0.120790	1123.299194	0.000000	NaN	NaN
301.000216	0.001099	10.990560	0.121196	1123.706177	0.000000	NaN	NaN
302.000273	0.000984	9.835167	0.121674	1124.185425	0.000000	NaN	NaN
303.000331	0.001074	10.742976	0.122130	1124.643066	0.000000	NaN	NaN
303.999388	0.001116	11.155617	0.122631	1125.145264	0.000000	NaN	NaN
304.999445	0.001165	11.650785	0.123055	1125.569824	0.000000	NaN	NaN
305.999502	0.001066	10.660448	0.123513	1126.029053	0.000000	NaN	NaN
306.999559	0.001091	10.908032	0.123962	1126.478882	0.000000	NaN	NaN
307.999617	0.001157	11.568257	0.124584	1127.102051	0.000000	NaN	NaN
308.999674	0.001091	10.908032	0.124996	1127.515503	0.000000	NaN	NaN
309.999731	0.001182	11.815842	0.125390	1127.910278	0.000000	NaN	NaN
310.999788	0.001074	10.742976	0.125816	1128.337280	0.000000	NaN	NaN
311.999845	0.001025	10.247807	0.126262	1128.783813	0.000000	NaN	NaN
312.999903	0.001083	10.825504	0.126701	1129.223999	0.000000	NaN	NaN
313.999960	0.001058	10.577920	0.127178	1129.701904	0.000000	NaN	NaN
315.000017	0.001050	10.495392	0.127586	1130.110718	0.000000	NaN	NaN
316.000074	0.001149	11.485729	0.128061	1130.587036	0.000000	NaN	NaN
317.000131	0.001025	10.247807	0.128507	1131.033936	0.000000	NaN	NaN
318.000189	0.001058	10.577920	0.128996	1131.523560	0.000000	NaN	NaN
319.000246	0.001033	10.330335	0.129457	1131.985962	0.000000	NaN	NaN
320.000303	0.001149	11.485729	0.129840	1132.370361	0.000000	NaN	NaN
320.999360	0.001066	10.660448	0.130281	1132.812378	0.000000	NaN	NaN
321.999417	0.001083	10.825504	0.130838	1133.370239	0.000000	NaN	NaN
322.999475	0.001099	10.990560	0.131267	1133.799805	0.000000	NaN	NaN
323.999532	0.001099	10.990560	0.131694	1134.228394	0.000000	NaN	NaN
324.999589	0.000984	9.835167	0.132123	1134.658325	0.000000	NaN	NaN
325.999646	0.001149	11.485729	0.132716	1135.252319	0.000000	NaN	NaN
326.999703	0.001132	11.320673	0.133180	1135.717285	0.000000	NaN	NaN
327.999760	0.001033	10.330335	0.133475	1136.013428	0.000000	NaN	NaN
328.999818	0.001066	10.660448	0.134007	1136.546509	0.000000	NaN	NaN
329.999875	0.001132	11.320673	0.134502	1137.042480	0.000000	NaN	NaN
330.999932	0.001091	10.908032	0.134968	1137.509399	0.000000	NaN	NaN
331.999989	0.001091	10.908032	0.135413	1137.954956	0.000000	NaN	NaN
333.000046	0.001132	11.320673	0.135878	1138.421631	0.000000	NaN	NaN
334.000104	0.001050	10.495392	0.136310	1138.854736	0.000000	NaN	NaN
335.000161	0.001083	10.825504	0.136798	1139.343384	0.000000	NaN	NaN
336.000218	0.001124	11.238145	0.137238	1139.784058	0.000000	NaN	NaN
337.000275	0.001008	10.082751	0.137742	1140.289185	0.000000	NaN	NaN
338.000333	0.001033	10.330335	0.138145	1140.693726	0.000000	NaN	NaN
338.999390	0.001182	11.815842	0.138608	1141.157593	0.000000	NaN	NaN
339.999447	0.001099	10.990560	0.139120	1141.670288	0.000000	NaN	NaN
340.999504	0.001231	12.311010	0.139509	1142.060669	0.000000	NaN	NaN
341.999561	0.001033	10.330335	0.140076	1142.629150	0.000000	NaN	NaN
342.999618	0.001116	11.155617	0.140407	1142.960693	0.000000	NaN	NaN
343.999676	0.001165	11.650785	0.140886	1143.440918	0.000000	NaN	NaN
344.999733	0.001033	10.330335	0.141444	1143.999634	0.000000	NaN	NaN
345.999790	0.001116	11.155617	0.141777	1144.333740	0.000000	NaN	NaN
346.999847	0.001182	11.815842	0.142380	1144.938354	0.000000	NaN	NaN
347.999905	0.001050	10.495392	0.142691	1145.249634	0.000000	NaN	NaN
348.999962	0.001058	10.577920	0.143172	1145.731445	0.000000	NaN	NaN
350.000019	0.000975	9.752638	0.143674	1146.234985	0.000000	NaN	NaN
351.000076	0.001050	10.495392	0.144116	1146.678223	0.000000	NaN	NaN
352.000133	0.001083	10.825504	0.144566	1147.129272	0.000000	NaN	NaN
353.000190	0.001008	10.082751	0.145081	1147.644775	0.000000	NaN	NaN
354.000248	0.001140	11.403201	0.145575	1148.139771	0.000000	NaN	NaN
355.000305	0.000917	9.174942	0.145939	1148.505127	0.000000	NaN	NaN
355.999362	0.001157	11.568257	0.146454	1149.021240	0.000000	NaN	NaN
356.999419	0.001182	11.815842	0.146962	1149.530029	0.000000	NaN	NaN
357.999476	0.000967	9.670110	0.147354	1149.923340	0.000000	NaN	NaN
358.999534	0.001074	10.742976	0.147742	1150.312256	0.000000	NaN	NaN
359.999591	0.001008	10.082751	0.148271	1150.842651	0.000000	NaN	NaN
360.999648	0.000752	7.524379	0.148667	1151.238770	0.000000	NaN	NaN
361.999705	0.001050	10.495392	0.149112	1151.685303	0.000000	NaN	NaN
362.999762	0.000901	9.009885	0.149557	1152.131470	0.000000	NaN	NaN
363.999820	0.001033	10.330335	0.150050	1152.625244	0.000000	NaN	NaN
364.999877	0.000967	9.670110	0.150439	1153.015015	0.000000	NaN	NaN
365.999934	0.000984	9.835167	0.150897	1153.474365	0.000000	NaN	NaN
366.999991	0.000992	9.917695	0.151303	1153.880737	0.000000	NaN	NaN
368.000048	0.000909	9.092413	0.151842	1154.421143	0.000000	NaN	NaN
369.000106	0.001050	10.495392	0.152195	1154.775391	0.000000	NaN	NaN
370.000163	0.000835	8.349660	0.152674	1155.255493	0.000000	NaN	NaN
371.000220	0.001008	10.082751	0.153114	1155.695801	0.000000	NaN	NaN
372.000277	0.000851	8.514717	0.153466	1156.049072	0.000000	NaN	NaN
373.000334	0.000992	9.917695	0.153979	1156.563354	0.000000	NaN	NaN
373.999392	0.000876	8.762301	0.154428	1157.013428	0.000000	NaN	NaN
374.999449	0.000794	7.937020	0.154822	1157.407837	0.000000	NaN	NaN
375.999506	0.000860	8.597245	0.155175	1157.762085	0.000000	NaN	NaN
376.999563	0.000843	8.432188	0.155665	1158.252686	0.000000	NaN	NaN
377.999620	0.000810	8.102076	0.156011	1158.599731	0.000000	NaN	NaN
378.999678	0.000670	6.699098	0.156577	1159.166382	0.000000	NaN	NaN
379.999735	0.000596	5.956345	0.156988	1159.578369	0.000000	NaN	NaN
380.999792	0.000695	6.946682	0.157577	1160.168579	0.000000	NaN	NaN
381.999849	0.000579	5.791288	0.157926	1160.518433	0.000000	NaN	NaN
382.999906	0.000571	5.708760	0.158112	1160.705078	0.000000	NaN	NaN
383.999963	0.000546	5.461176	0.158449	1161.043091	0.000000	NaN	NaN
385.000021	0.000538	5.378648	0.158224	1160.817749	0.000000	NaN	NaN
386.000078	0.000406	4.058198	0.157980	1160.573120	0.000000	NaN	NaN
387.000135	0.000356	3.563029	0.157947	1160.540161	0.000000	NaN	NaN
388.000192	0.000257	2.572691	0.158259	1160.852905	0.000000	NaN	NaN
389.000249	-8.934899E-5	-0.893490	0.268929	1271.770020	0.000000	NaN	NaN
390.000307	1.793757E-5	0.179376	0.200975	1203.664673	0.000000	NaN	NaN
390.999364	-0.000188	-1.883827	0.208581	1211.287231	0.000000	NaN	NaN
391.999421	9.684761E-6	0.096848	0.212741	1215.456055	0.000000	NaN	NaN
392.999478	-0.000131	-1.306131	0.216171	1218.894653	0.000000	NaN	NaN
393.999535	-4.808493E-5	-0.480849	0.218782	1221.510742	0.000000	NaN	NaN