File: data/57k_5-1_1 (190415).lvm
LabVIEW Measurement
Writer_Version	2
Reader_Version	2
Separator	Tab
Decimal_Separator	.
Multi_Headings	No
X_Columns	One
Time_Pref	Absolute
Operator	user
Description	Load(N)/Stress(MPa)/Distance A(pixel)/Strain A/Distance B(pixel)/Strain B/Poisson's ratio
Date	2019/04/15
Time	13:10:04.8134063300347318543
***End_of_Header***

Notes	X 값은 오직 다음과 같을 때에만 유효함이 보장됩니다. Dev1/ai0
Channels	7
Samples	1	1	1	1	1	1	1
Date	2019/04/15	2019/04/15	2019/04/15	2019/04/15	2019/04/15	2019/04/15	2019/04/15
Time	13:32:53.3136801300349906096	13:32:53.3136801300349906096	13:32:53.3136801719665527344	13:32:53.3136801719665527344	13:32:53.3136801719665527344	13:32:53.3136801719665527344	13:32:53.3136801719665527344
Y_Unit_Label	Volts	Volts
X_Dimension	Time	Time	Time	Time	Time	Time	Time
X0	0.0000000000000000E+0	0.0000000000000000E+0	0.0000000000000000E+0	0.0000000000000000E+0	0.0000000000000000E+0	0.0000000000000000E+0	0.0000000000000000E+0
Delta_X	0.000000	0.000000	1.000000	1.000000	1.000000	1.000000	1.000000
***End_of_Header***
X_Value	Dev1/ai0	Dev1/ai0 1	Untitled	Untitled 1	Untitled 2	Untitled 3	Untitled 4	Comment
0.000000	5.920164E-5	0.592016	2.551079E-5	1006.312317	0.000000	NaN	NaN
1.500086	3.444320E-5	0.344432	5.018711E-5	1006.362793	0.000000	NaN	NaN
2.999172	-8.109618E-5	-0.810962	1.871586E-5	1006.331177	0.000000	NaN	NaN
5.103292	0.000175	1.747410	0.000514	1006.829163	0.000000	NaN	NaN
6.499372	0.000183	1.829938	0.001286	1007.606873	0.000000	NaN	NaN
7.999458	0.000241	2.407635	0.001740	1008.063599	0.000000	NaN	NaN
9.499543	0.000290	2.902804	0.001993	1008.317993	0.000000	NaN	NaN
10.999629	0.000233	2.325107	0.002652	1008.981018	0.000000	NaN	NaN
12.499715	0.000365	3.645557	0.002958	1009.288818	0.000000	NaN	NaN
13.999801	0.000513	5.131063	0.003182	1009.514465	0.000000	NaN	NaN
15.499886	0.000447	4.470838	0.003586	1009.921326	0.000000	NaN	NaN
16.999972	0.000530	5.296120	0.003049	1009.380066	0.000000	NaN	NaN
18.499058	0.000546	5.461176	0.003423	1009.757202	0.000000	NaN	NaN
19.999144	0.000554	5.543704	0.003433	1009.767273	0.000000	NaN	NaN
21.499230	0.000563	5.626232	0.003549	1009.884155	0.000000	NaN	NaN
22.999316	0.000554	5.543704	0.003934	1010.270996	0.000000	NaN	NaN
24.499401	0.000645	6.451513	0.003918	1010.255249	0.000000	NaN	NaN
25.999487	0.000521	5.213591	0.003869	1010.205750	0.000000	NaN	NaN
27.499573	0.000653	6.534042	0.003979	1010.316101	0.000000	NaN	NaN
28.999659	0.000744	7.441851	0.004212	1010.550842	0.000000	NaN	NaN
30.499744	0.000736	7.359323	0.004476	1010.816956	0.000000	NaN	NaN
31.999830	0.000827	8.267132	0.004826	1011.168823	0.000000	NaN	NaN
33.499916	0.000835	8.349660	0.004971	1011.314758	0.000000	NaN	NaN
35.000002	0.000769	7.689435	0.005287	1011.632812	0.000000	NaN	NaN
36.499088	0.000909	9.092413	0.005531	1011.877991	0.000000	NaN	NaN
37.999173	0.000868	8.679773	0.005684	1012.032410	0.000000	NaN	NaN
39.499259	0.000901	9.009885	0.005944	1012.293701	0.000000	NaN	NaN
40.999345	0.000992	9.917695	0.006253	1012.605225	0.000000	NaN	NaN
42.499431	0.001058	10.577920	0.006464	1012.816772	0.000000	NaN	NaN
43.999517	0.001074	10.742976	0.006823	1013.178589	0.000000	NaN	NaN
45.499602	0.001066	10.660448	0.006982	1013.338806	0.000000	NaN	NaN
46.999688	0.001066	10.660448	0.007336	1013.694580	0.000000	NaN	NaN
48.499774	0.001107	11.073088	0.007721	1014.082397	0.000000	NaN	NaN
49.999860	0.001124	11.238145	0.008006	1014.368774	0.000000	NaN	NaN
51.499946	0.001206	12.063426	0.008264	1014.628601	0.000000	NaN	NaN
53.000031	0.001223	12.228482	0.008703	1015.069946	0.000000	NaN	NaN
54.499117	0.001281	12.806179	0.009073	1015.442932	0.000000	NaN	NaN
55.999203	0.001206	12.063426	0.009569	1015.941650	0.000000	NaN	NaN
57.499289	0.001404	14.044101	0.009880	1016.254700	0.000000	NaN	NaN
58.999375	0.001305	13.053763	0.010361	1016.738708	0.000000	NaN	NaN
60.499460	0.001437	14.374213	0.010568	1016.946777	0.000000	NaN	NaN
61.999546	0.001454	14.539270	0.011132	1017.514221	0.000000	NaN	NaN
63.499632	0.001470	14.704326	0.011552	1017.937500	0.000000	NaN	NaN
64.999718	0.001528	15.282023	0.012092	1018.480408	0.000000	NaN	NaN
66.499804	0.001586	15.859720	0.012651	1019.043518	0.000000	NaN	NaN
67.999889	0.001380	13.796517	0.013140	1019.535156	0.000000	NaN	NaN
69.499975	0.001619	16.189832	0.013713	1020.111389	0.000000	NaN	NaN
70.999061	0.001644	16.437417	0.014385	1020.787781	0.000000	NaN	NaN
72.499147	0.001710	17.097642	0.014905	1021.311890	0.000000	NaN	NaN
73.999233	0.001602	16.024776	0.015512	1021.922302	0.000000	NaN	NaN
75.499318	0.001685	16.850057	0.016221	1022.635315	0.000000	NaN	NaN
76.999404	0.001743	17.427754	0.016714	1023.131653	0.000000	NaN	NaN
78.499490	0.001768	17.675339	0.018176	1024.603394	0.000000	NaN	NaN
79.999576	0.001850	18.500620	0.018815	1025.245850	0.000000	NaN	NaN
81.499661	0.001792	17.922923	0.019402	1025.836792	0.000000	NaN	NaN
82.999747	0.001801	18.005451	0.020006	1026.444336	0.000000	NaN	NaN
84.499833	0.001635	16.354889	0.020718	1027.161011	0.000000	NaN	NaN
85.999919	0.001801	18.005451	0.021390	1027.837158	0.000000	NaN	NaN
87.500005	0.001784	17.840395	0.022129	1028.581055	0.000000	NaN	NaN
88.999090	0.001817	18.170507	0.021373	1027.820068	0.000000	NaN	NaN
90.499176	0.001784	17.840395	0.022039	1028.490723	0.000000	NaN	NaN
91.999262	0.001924	19.243373	0.022841	1029.297974	0.000000	NaN	NaN
93.499348	0.001933	19.325901	0.023546	1030.007324	0.000000	NaN	NaN
94.999434	0.001858	18.583148	0.024170	1030.635254	0.000000	NaN	NaN
96.499519	0.001858	18.583148	0.024875	1031.343994	0.000000	NaN	NaN
97.999605	0.001867	18.665676	0.025566	1032.040039	0.000000	NaN	NaN
99.499691	0.001933	19.325901	0.026232	1032.710327	0.000000	NaN	NaN
100.999777	0.001883	18.830732	0.026891	1033.373291	0.000000	NaN	NaN
102.499863	0.001900	18.995789	0.027660	1034.146606	0.000000	NaN	NaN
103.999948	0.001957	19.573485	0.028447	1034.939331	0.000000	NaN	NaN
105.500034	0.001949	19.490957	0.029271	1035.767944	0.000000	NaN	NaN
106.999120	0.001933	19.325901	0.029932	1036.433594	0.000000	NaN	NaN
108.499206	0.001891	18.913260	0.030688	1037.193970	0.000000	NaN	NaN
109.999292	0.001982	19.821070	0.031503	1038.014038	0.000000	NaN	NaN
111.499377	0.002056	20.563823	0.032115	1038.629883	0.000000	NaN	NaN
112.999463	0.001883	18.830732	0.032805	1039.324219	0.000000	NaN	NaN
114.499549	0.002073	20.728879	0.033519	1040.042847	0.000000	NaN	NaN
115.999635	0.001924	19.243373	0.034177	1040.705444	0.000000	NaN	NaN
117.499721	0.001924	19.243373	0.034885	1041.417358	0.000000	NaN	NaN
118.999806	0.001941	19.408429	0.035756	1042.294189	0.000000	NaN	NaN
120.499892	0.001999	19.986126	0.036284	1042.825195	0.000000	NaN	NaN
121.999978	0.001949	19.490957	0.038396	1044.950195	0.000000	NaN	NaN
123.499064	0.002048	20.481295	0.038811	1045.368530	0.000000	NaN	NaN
124.999150	0.001990	19.903598	0.038739	1045.295654	0.000000	NaN	NaN
126.499235	0.001974	19.738542	0.039530	1046.091919	0.000000	NaN	NaN
127.999321	0.002023	20.233710	0.040350	1046.917480	0.000000	NaN	NaN
129.499407	0.001933	19.325901	0.041085	1047.656982	0.000000	NaN	NaN
130.999493	0.001982	19.821070	0.041864	1048.440186	0.000000	NaN	NaN
132.499578	0.002048	20.481295	0.042564	1049.145020	0.000000	NaN	NaN
133.999664	0.001974	19.738542	0.043368	1049.954102	0.000000	NaN	NaN
135.499750	0.001982	19.821070	0.044177	1050.768311	0.000000	NaN	NaN
136.999836	0.002089	20.893935	0.044954	1051.550171	0.000000	NaN	NaN
138.499922	0.002155	21.554160	0.045687	1052.287354	0.000000	NaN	NaN
140.000008	0.002122	21.224048	0.046410	1053.015747	0.000000	NaN	NaN
141.499093	0.002048	20.481295	0.047072	1053.681763	0.000000	NaN	NaN
142.999179	0.002023	20.233710	0.047947	1054.561523	0.000000	NaN	NaN
144.499265	0.002015	20.151182	0.048671	1055.290161	0.000000	NaN	NaN
145.999351	0.002089	20.893935	0.049358	1055.981445	0.000000	NaN	NaN
147.499436	0.002065	20.646351	0.050112	1056.740479	0.000000	NaN	NaN
148.999522	0.002081	20.811407	0.050897	1057.530884	0.000000	NaN	NaN
150.499608	0.001990	19.903598	0.051621	1058.258789	0.000000	NaN	NaN
151.999694	0.002155	21.554160	0.052402	1059.045532	0.000000	NaN	NaN
153.499780	0.001974	19.738542	0.053049	1059.696045	0.000000	NaN	NaN
154.999865	0.002230	22.296913	0.053809	1060.461182	0.000000	NaN	NaN
156.499951	0.002081	20.811407	0.054563	1061.220093	0.000000	NaN	NaN
158.000037	0.002073	20.728879	0.055254	1061.915527	0.000000	NaN	NaN
159.499123	0.002089	20.893935	0.056051	1062.716675	0.000000	NaN	NaN
160.999209	0.002106	21.058992	0.056697	1063.367676	0.000000	NaN	NaN
162.499294	0.002139	21.389104	0.057473	1064.148193	0.000000	NaN	NaN
163.999380	0.002114	21.141520	0.058272	1064.952515	0.000000	NaN	NaN
165.499466	0.002081	20.811407	0.059079	1065.763794	0.000000	NaN	NaN
166.999552	0.002205	22.049329	0.059732	1066.421143	0.000000	NaN	NaN
168.499638	0.002131	21.306576	0.060436	1067.129761	0.000000	NaN	NaN
169.999723	0.002106	21.058992	0.061246	1067.944580	0.000000	NaN	NaN
171.499809	0.002106	21.058992	0.061979	1068.682129	0.000000	NaN	NaN
172.999895	0.002180	21.801745	0.062710	1069.417969	0.000000	NaN	NaN
174.499981	0.002213	22.131857	0.063176	1069.887207	0.000000	NaN	NaN
175.999067	0.002238	22.379442	0.063804	1070.519287	0.000000	NaN	NaN
177.499152	0.002197	21.966801	0.064565	1071.284912	0.000000	NaN	NaN
178.999238	0.002098	20.976463	0.065292	1072.016602	0.000000	NaN	NaN
180.499324	0.002131	21.306576	0.066161	1072.890869	0.000000	NaN	NaN
181.999410	0.002147	21.471632	0.066827	1073.560791	0.000000	NaN	NaN
183.499496	0.002131	21.306576	0.067564	1074.302490	0.000000	NaN	NaN
184.999581	0.002089	20.893935	0.068359	1075.103271	0.000000	NaN	NaN
186.499667	0.002155	21.554160	0.069077	1075.825684	0.000000	NaN	NaN
187.999753	0.002164	21.636688	0.069807	1076.559937	0.000000	NaN	NaN
189.499839	0.002114	21.141520	0.070516	1077.272949	0.000000	NaN	NaN
190.999925	0.002246	22.461970	0.071343	1078.105835	0.000000	NaN	NaN
192.500010	0.002106	21.058992	0.072028	1078.795044	0.000000	NaN	NaN
193.999096	0.002089	20.893935	0.072801	1079.572388	0.000000	NaN	NaN
195.499182	0.002221	22.214385	0.073606	1080.382568	0.000000	NaN	NaN
196.999268	0.002230	22.296913	0.074340	1081.121582	0.000000	NaN	NaN
198.499353	0.002131	21.306576	0.075038	1081.824463	0.000000	NaN	NaN
199.999439	0.002246	22.461970	0.075808	1082.598755	0.000000	NaN	NaN
201.499525	0.002320	23.204723	0.076534	1083.329468	0.000000	NaN	NaN
202.999611	0.002164	21.636688	0.077289	1084.089233	0.000000	NaN	NaN
204.499697	0.002213	22.131857	0.078003	1084.807251	0.000000	NaN	NaN
205.999783	0.002213	22.131857	0.078774	1085.583130	0.000000	NaN	NaN
207.499868	0.002254	22.544498	0.079543	1086.357300	0.000000	NaN	NaN
208.999954	0.002238	22.379442	0.080289	1087.108032	0.000000	NaN	NaN
210.500040	0.002147	21.471632	0.081077	1087.901245	0.000000	NaN	NaN
211.999126	0.002271	22.709554	0.081810	1088.639038	0.000000	NaN	NaN
213.499211	0.002205	22.049329	0.082581	1089.415039	0.000000	NaN	NaN
214.999297	0.002122	21.224048	0.083298	1090.135986	0.000000	NaN	NaN
216.499383	0.002238	22.379442	0.084083	1090.925903	0.000000	NaN	NaN
217.999469	0.002230	22.296913	0.084781	1091.628052	0.000000	NaN	NaN
219.499555	0.002114	21.141520	0.085544	1092.396484	0.000000	NaN	NaN
220.999640	0.002271	22.709554	0.086293	1093.150024	0.000000	NaN	NaN
222.499726	0.002263	22.627026	0.087081	1093.942749	0.000000	NaN	NaN
223.999812	0.002197	21.966801	0.087808	1094.674072	0.000000	NaN	NaN
225.499898	0.002197	21.966801	0.088524	1095.395508	0.000000	NaN	NaN
226.999984	0.002180	21.801745	0.089290	1096.165894	0.000000	NaN	NaN
228.499069	0.002254	22.544498	0.090096	1096.976685	0.000000	NaN	NaN
229.999155	0.002296	22.957138	0.090770	1097.655640	0.000000	NaN	NaN
231.499241	0.002279	22.792082	0.091572	1098.462769	0.000000	NaN	NaN
232.999327	0.002320	23.204723	0.092356	1099.250977	0.000000	NaN	NaN
234.499413	0.002271	22.709554	0.093013	1099.911987	0.000000	NaN	NaN
235.999498	0.002353	23.534835	0.093760	1100.664673	0.000000	NaN	NaN
237.499584	0.002213	22.131857	0.094512	1101.420532	0.000000	NaN	NaN
238.999670	0.002337	23.369779	0.095306	1102.219971	0.000000	NaN	NaN
240.499756	0.002312	23.122195	0.096059	1102.977295	0.000000	NaN	NaN
241.999842	0.002246	22.461970	0.096763	1103.686035	0.000000	NaN	NaN
243.499927	0.002411	24.112532	0.096431	1103.351807	0.000000	NaN	NaN
245.000013	0.002386	23.864948	0.097139	1104.064453	0.000000	NaN	NaN
246.499099	0.002353	23.534835	0.097858	1104.788208	0.000000	NaN	NaN
247.999185	0.002312	23.122195	0.098679	1105.614502	0.000000	NaN	NaN
249.499270	0.002271	22.709554	0.099374	1106.313599	0.000000	NaN	NaN
250.999356	0.002378	23.782420	0.100164	1107.108154	0.000000	NaN	NaN
252.499442	0.002271	22.709554	0.100963	1107.912964	0.000000	NaN	NaN
253.999528	0.002370	23.699892	0.101676	1108.629883	0.000000	NaN	NaN
255.499614	0.002205	22.049329	0.102457	1109.416260	0.000000	NaN	NaN
256.999700	0.002494	24.937813	0.103198	1110.161987	0.000000	NaN	NaN
258.499785	0.002362	23.617363	0.103950	1110.917969	0.000000	NaN	NaN
259.999871	0.002502	25.020342	0.104683	1111.655762	0.000000	NaN	NaN
261.499957	0.002362	23.617363	0.105511	1112.489014	0.000000	NaN	NaN
263.000043	0.002420	24.195060	0.106227	1113.210083	0.000000	NaN	NaN
264.499128	0.002362	23.617363	0.107015	1114.002808	0.000000	NaN	NaN
265.999214	0.002296	22.957138	0.107753	1114.745361	0.000000	NaN	NaN
267.499300	0.002337	23.369779	0.108568	1115.565796	0.000000	NaN	NaN
268.999386	0.002395	23.947476	0.109235	1116.236572	0.000000	NaN	NaN
270.499472	0.002345	23.452307	0.109996	1117.003052	0.000000	NaN	NaN
271.999557	0.002362	23.617363	0.110754	1117.765625	0.000000	NaN	NaN
273.499643	0.002337	23.369779	0.111488	1118.504150	0.000000	NaN	NaN
274.999729	0.002395	23.947476	0.112193	1119.213501	0.000000	NaN	NaN
276.499815	0.002411	24.112532	0.112944	1119.969116	0.000000	NaN	NaN
277.999901	0.002353	23.534835	0.113674	1120.704102	0.000000	NaN	NaN
279.499986	0.002304	23.039667	0.114430	1121.464478	0.000000	NaN	NaN
280.999072	0.002477	24.772757	0.115234	1122.273926	0.000000	NaN	NaN
282.499158	0.002362	23.617363	0.115916	1122.960083	0.000000	NaN	NaN
283.999244	0.002370	23.699892	0.116770	1123.818970	0.000000	NaN	NaN
285.499330	0.002386	23.864948	0.117435	1124.488770	0.000000	NaN	NaN
286.999415	0.002386	23.864948	0.118161	1125.218750	0.000000	NaN	NaN
288.499501	0.002428	24.277588	0.118877	1125.939575	0.000000	NaN	NaN
289.999587	0.002386	23.864948	0.119566	1126.633423	0.000000	NaN	NaN
291.499673	0.002494	24.937813	0.120344	1127.415649	0.000000	NaN	NaN
292.999759	0.002345	23.452307	0.120773	1127.847412	0.000000	NaN	NaN
294.499844	0.002411	24.112532	0.122244	1129.328003	0.000000	NaN	NaN
295.999930	0.002345	23.452307	0.123139	1130.228394	0.000000	NaN	NaN
297.500016	0.002411	24.112532	0.123708	1130.800781	0.000000	NaN	NaN
298.999102	0.002453	24.525173	0.124464	1131.562134	0.000000	NaN	NaN
300.499188	0.002436	24.360117	0.125200	1132.302979	0.000000	NaN	NaN
301.999273	0.002420	24.195060	0.125898	1133.005493	0.000000	NaN	NaN
303.499359	0.002510	25.102870	0.126596	1133.707520	0.000000	NaN	NaN
304.999445	0.002527	25.267926	0.127381	1134.497070	0.000000	NaN	NaN
306.499531	0.002370	23.699892	0.128061	1135.181885	0.000000	NaN	NaN
307.999617	0.002477	24.772757	0.128819	1135.944946	0.000000	NaN	NaN
309.499702	0.002494	24.937813	0.129519	1136.649048	0.000000	NaN	NaN
310.999788	0.002477	24.772757	0.130190	1137.323608	0.000000	NaN	NaN
312.499874	0.002436	24.360117	0.130901	1138.039307	0.000000	NaN	NaN
313.999960	0.002519	25.185398	0.131563	1138.705933	0.000000	NaN	NaN
315.500046	0.002486	24.855285	0.132490	1139.638672	0.000000	NaN	NaN
316.999131	0.002552	25.515510	0.133070	1140.221802	0.000000	NaN	NaN
318.499217	0.002494	24.937813	0.133788	1140.944458	0.000000	NaN	NaN
319.999303	0.002486	24.855285	0.134496	1141.657104	0.000000	NaN	NaN
321.499389	0.002543	25.432982	0.135185	1142.350952	0.000000	NaN	NaN
322.999475	0.002552	25.515510	0.135957	1143.127563	0.000000	NaN	NaN
324.499560	0.002420	24.195060	0.136711	1143.886597	0.000000	NaN	NaN
325.999646	0.002461	24.607701	0.137445	1144.624878	0.000000	NaN	NaN
327.499732	0.002453	24.525173	0.138120	1145.304199	0.000000	NaN	NaN
328.999818	0.002552	25.515510	0.138832	1146.020752	0.000000	NaN	NaN
330.499903	0.002527	25.267926	0.139614	1146.807129	0.000000	NaN	NaN
331.999989	0.002411	24.112532	0.140331	1147.529541	0.000000	NaN	NaN
333.499075	0.002626	26.258263	0.141085	1148.287598	0.000000	NaN	NaN
334.999161	0.002601	26.010679	0.141769	1148.976196	0.000000	NaN	NaN
336.499247	0.002560	25.598038	0.142561	1149.773193	0.000000	NaN	NaN
337.999332	0.002535	25.350454	0.143213	1150.429565	0.000000	NaN	NaN
339.499418	0.002502	25.020342	0.143454	1150.671875	0.000000	NaN	NaN
340.999504	0.002403	24.030004	0.144156	1151.377808	0.000000	NaN	NaN
342.499590	0.002519	25.185398	0.144918	1152.145386	0.000000	NaN	NaN
343.999676	0.002626	26.258263	0.145556	1152.786865	0.000000	NaN	NaN
345.499761	0.002576	25.763095	0.146305	1153.540527	0.000000	NaN	NaN
346.999847	0.002494	24.937813	0.146966	1154.206421	0.000000	NaN	NaN
348.499933	0.002585	25.845623	0.147646	1154.890625	0.000000	NaN	NaN
350.000019	0.002667	26.670904	0.148511	1155.760376	0.000000	NaN	NaN
351.499105	0.002527	25.267926	0.149129	1156.382446	0.000000	NaN	NaN
352.999190	0.002543	25.432982	0.149825	1157.083496	0.000000	NaN	NaN
354.499276	0.002477	24.772757	0.150565	1157.827271	0.000000	NaN	NaN
355.999362	0.002502	25.020342	0.151309	1158.575928	0.000000	NaN	NaN
357.499448	0.002659	26.588376	0.151964	1159.235596	0.000000	NaN	NaN
358.999534	0.002568	25.680567	0.152759	1160.035767	0.000000	NaN	NaN
360.499619	0.002568	25.680567	0.153365	1160.644897	0.000000	NaN	NaN
361.999705	0.002609	26.093207	0.153951	1161.235352	0.000000	NaN	NaN
363.499791	0.002651	26.505848	0.154740	1162.029419	0.000000	NaN	NaN
364.999877	0.002593	25.928151	0.155487	1162.781128	0.000000	NaN	NaN
366.499963	0.002527	25.267926	0.156232	1163.530518	0.000000	NaN	NaN
368.000048	0.002535	25.350454	0.157005	1164.308105	0.000000	NaN	NaN
369.499134	0.002576	25.763095	0.157539	1164.845581	0.000000	NaN	NaN
370.999220	0.002502	25.020342	0.158250	1165.560913	0.000000	NaN	NaN
372.499306	0.002527	25.267926	0.158947	1166.263062	0.000000	NaN	NaN
373.999392	0.002634	26.340792	0.159700	1167.020020	0.000000	NaN	NaN
375.499477	0.002609	26.093207	0.160366	1167.690552	0.000000	NaN	NaN
376.999563	0.002502	25.020342	0.161033	1168.361572	0.000000	NaN	NaN
378.499649	0.002486	24.855285	0.161764	1169.096924	0.000000	NaN	NaN
379.999735	0.002576	25.763095	0.162462	1169.800171	0.000000	NaN	NaN
381.499820	0.002543	25.432982	0.163451	1170.795166	0.000000	NaN	NaN
382.999906	0.002519	25.185398	0.164180	1171.528564	0.000000	NaN	NaN
384.499992	0.002675	26.753432	0.164919	1172.272339	0.000000	NaN	NaN
385.999078	0.002634	26.340792	0.165580	1172.937744	0.000000	NaN	NaN
387.499164	0.002601	26.010679	0.166333	1173.694946	0.000000	NaN	NaN
388.999250	0.002651	26.505848	0.166900	1174.265503	0.000000	NaN	NaN
390.499335	0.002626	26.258263	0.167649	1175.019165	0.000000	NaN	NaN
391.999421	0.002560	25.598038	0.168322	1175.696899	0.000000	NaN	NaN
393.499507	0.002642	26.423320	0.168975	1176.354004	0.000000	NaN	NaN
394.999593	0.002651	26.505848	0.169753	1177.136841	0.000000	NaN	NaN
396.499678	0.002651	26.505848	0.170402	1177.790405	0.000000	NaN	NaN
397.999764	0.002717	27.166073	0.171164	1178.556274	0.000000	NaN	NaN
399.499850	0.002626	26.258263	0.171898	1179.295654	0.000000	NaN	NaN
400.999936	0.002741	27.413657	0.172462	1179.862915	0.000000	NaN	NaN
402.500022	0.002684	26.835960	0.173210	1180.615845	0.000000	NaN	NaN
403.999107	0.002667	26.670904	0.173921	1181.331177	0.000000	NaN	NaN
405.499193	0.002700	27.001017	0.174500	1181.913940	0.000000	NaN	NaN
406.999279	0.002750	27.496185	0.175283	1182.702148	0.000000	NaN	NaN
408.499365	0.002675	26.753432	0.175997	1183.420288	0.000000	NaN	NaN
409.999451	0.002642	26.423320	0.176725	1184.152954	0.000000	NaN	NaN
411.499536	0.002651	26.505848	0.177451	1184.883423	0.000000	NaN	NaN
412.999622	0.002692	26.918488	0.178138	1185.574951	0.000000	NaN	NaN
414.499708	0.002717	27.166073	0.178817	1186.257568	0.000000	NaN	NaN
415.999794	0.002601	26.010679	0.179475	1186.920044	0.000000	NaN	NaN
417.499880	0.002585	25.845623	0.180260	1187.709717	0.000000	NaN	NaN
418.999965	0.002750	27.496185	0.180930	1188.384521	0.000000	NaN	NaN
420.500051	0.002651	26.505848	0.181624	1189.082397	0.000000	NaN	NaN
421.999137	0.002642	26.423320	0.182258	1189.720581	0.000000	NaN	NaN
423.499223	0.002774	27.743770	0.182994	1190.461304	0.000000	NaN	NaN
424.999309	0.002675	26.753432	0.183686	1191.157349	0.000000	NaN	NaN
426.499394	0.002659	26.588376	0.184368	1191.844604	0.000000	NaN	NaN
427.999480	0.002651	26.505848	0.185116	1192.596924	0.000000	NaN	NaN
429.499566	0.002609	26.093207	0.185803	1193.287964	0.000000	NaN	NaN
430.999652	0.002725	27.248601	0.186489	1193.978027	0.000000	NaN	NaN
432.499738	0.002717	27.166073	0.187120	1194.613525	0.000000	NaN	NaN
433.999823	0.002700	27.001017	0.187665	1195.161743	0.000000	NaN	NaN
435.499909	0.002758	27.578713	0.189153	1196.659180	0.000000	NaN	NaN
436.999995	0.002626	26.258263	0.190045	1197.557007	0.000000	NaN	NaN
438.499081	0.002783	27.826298	0.190612	1198.127197	0.000000	NaN	NaN
439.999167	0.002717	27.166073	0.191403	1198.923828	0.000000	NaN	NaN
441.499252	0.002618	26.175735	0.192097	1199.621948	0.000000	NaN	NaN
442.999338	0.002692	26.918488	0.192837	1200.366577	0.000000	NaN	NaN
444.499424	0.002750	27.496185	0.193514	1201.047974	0.000000	NaN	NaN
445.999510	0.002774	27.743770	0.194273	1201.811279	0.000000	NaN	NaN
447.499595	0.002799	27.991354	0.194852	1202.394409	0.000000	NaN	NaN
448.999681	0.002651	26.505848	0.195630	1203.177124	0.000000	NaN	NaN
450.499767	0.002692	26.918488	0.196347	1203.898926	0.000000	NaN	NaN
451.999853	0.002774	27.743770	0.197047	1204.602905	0.000000	NaN	NaN
453.499939	0.002708	27.083545	0.197761	1205.321167	0.000000	NaN	NaN
455.000024	0.002799	27.991354	0.198358	1205.922729	0.000000	NaN	NaN
456.499110	0.002849	28.486523	0.199147	1206.716553	0.000000	NaN	NaN
457.999196	0.002659	26.588376	0.199833	1207.406494	0.000000	NaN	NaN
459.499282	0.002766	27.661242	0.200505	1208.082520	0.000000	NaN	NaN
460.999368	0.002717	27.166073	0.201175	1208.757324	0.000000	NaN	NaN
462.499453	0.002700	27.001017	0.201941	1209.528442	0.000000	NaN	NaN
463.999539	0.002667	26.670904	0.201861	1209.447510	0.000000	NaN	NaN
465.499625	0.002667	26.670904	0.202622	1210.213623	0.000000	NaN	NaN
466.999711	0.002700	27.001017	0.203324	1210.919556	0.000000	NaN	NaN
468.499797	0.002783	27.826298	0.204100	1211.700928	0.000000	NaN	NaN
469.999882	0.002692	26.918488	0.204665	1212.269531	0.000000	NaN	NaN
471.499968	0.002717	27.166073	0.205351	1212.959595	0.000000	NaN	NaN
473.000054	0.002733	27.331129	0.206075	1213.687988	0.000000	NaN	NaN
474.499140	0.002849	28.486523	0.206738	1214.355103	0.000000	NaN	NaN
475.999226	0.002766	27.661242	0.207383	1215.004272	0.000000	NaN	NaN
477.499311	0.002816	28.156410	0.208038	1215.663452	0.000000	NaN	NaN
478.999397	0.002725	27.248601	0.208846	1216.477051	0.000000	NaN	NaN
480.499483	0.002725	27.248601	0.209450	1217.083984	0.000000	NaN	NaN
481.999569	0.002824	28.238938	0.210126	1217.764404	0.000000	NaN	NaN
483.499655	0.002799	27.991354	0.210916	1218.559448	0.000000	NaN	NaN
484.999740	0.002832	28.321467	0.211524	1219.171265	0.000000	NaN	NaN
486.499826	0.002849	28.486523	0.212221	1219.872559	0.000000	NaN	NaN
487.999912	0.002857	28.569051	0.212979	1220.635254	0.000000	NaN	NaN
489.499998	0.002799	27.991354	0.213568	1221.228516	0.000000	NaN	NaN
490.999083	0.002758	27.578713	0.214274	1221.938599	0.000000	NaN	NaN
492.499169	0.002774	27.743770	0.214970	1222.639282	0.000000	NaN	NaN
493.999255	0.002799	27.991354	0.215584	1223.256714	0.000000	NaN	NaN
495.499341	0.002758	27.578713	0.216361	1224.038574	0.000000	NaN	NaN
496.999427	0.002857	28.569051	0.216983	1224.664795	0.000000	NaN	NaN
498.499512	0.002824	28.238938	0.217610	1225.296265	0.000000	NaN	NaN
499.999598	0.002840	28.403995	0.211470	1219.116943	0.000000	NaN	NaN
501.499684	0.002865	28.651579	0.212182	1219.833252	0.000000	NaN	NaN
502.999770	0.002684	26.835960	0.212822	1220.477661	0.000000	NaN	NaN
504.499856	0.002840	28.403995	0.213540	1221.200195	0.000000	NaN	NaN
505.999941	0.002642	26.423320	0.214159	1221.822998	0.000000	NaN	NaN
507.500027	0.002816	28.156410	0.214774	1222.441528	0.000000	NaN	NaN
508.999113	0.002865	28.651579	0.215578	1223.250732	0.000000	NaN	NaN
510.499199	0.002766	27.661242	0.216160	1223.837036	0.000000	NaN	NaN
511.999285	0.002865	28.651579	0.216800	1224.481323	0.000000	NaN	NaN
513.499370	0.002791	27.908826	0.217663	1225.349609	0.000000	NaN	NaN
514.999456	0.002890	28.899163	0.218208	1225.897827	0.000000	NaN	NaN
516.499542	0.002799	27.991354	0.219020	1226.714600	0.000000	NaN	NaN
517.999628	0.002923	29.229276	0.219570	1227.268188	0.000000	NaN	NaN
519.499714	0.002882	28.816635	0.220331	1228.034058	0.000000	NaN	NaN
520.999799	0.002840	28.403995	0.221066	1228.774170	0.000000	NaN	NaN
522.499885	0.002898	28.981692	0.221605	1229.316162	0.000000	NaN	NaN
523.999971	0.003005	30.054557	0.222382	1230.097778	0.000000	NaN	NaN
525.499057	0.002898	28.981692	0.223172	1230.893311	0.000000	NaN	NaN
526.999143	0.002882	28.816635	0.223747	1231.472046	0.000000	NaN	NaN
528.499228	0.002923	29.229276	0.224545	1232.275146	0.000000	NaN	NaN
529.999314	0.002857	28.569051	0.225138	1232.871704	0.000000	NaN	NaN
531.499400	0.002865	28.651579	0.225629	1233.365479	0.000000	NaN	NaN
532.999486	0.003005	30.054557	0.226531	1234.273315	0.000000	NaN	NaN
534.499572	0.002898	28.981692	0.227013	1234.758179	0.000000	NaN	NaN
535.999657	0.002832	28.321467	0.227936	1235.687256	0.000000	NaN	NaN
537.499743	0.002882	28.816635	0.228493	1236.247681	0.000000	NaN	NaN
538.999829	0.002931	29.311804	0.229228	1236.987427	0.000000	NaN	NaN
540.499915	0.002783	27.826298	0.229896	1237.659058	0.000000	NaN	NaN
542.000001	0.002890	28.899163	0.230600	1238.367432	0.000000	NaN	NaN
543.499086	0.002857	28.569051	0.231162	1238.933472	0.000000	NaN	NaN
544.999172	0.002972	29.724445	0.231923	1239.699341	0.000000	NaN	NaN
546.499258	0.002865	28.651579	0.232619	1240.399780	0.000000	NaN	NaN
547.999344	0.002890	28.899163	0.233222	1241.006714	0.000000	NaN	NaN
549.499430	0.002906	29.064220	0.233924	1241.712769	0.000000	NaN	NaN
550.999515	0.002948	29.476860	0.234687	1242.480835	0.000000	NaN	NaN
552.499601	0.002939	29.394332	0.235232	1243.028931	0.000000	NaN	NaN
553.999687	0.002840	28.403995	0.236126	1243.929077	0.000000	NaN	NaN
555.499773	0.002882	28.816635	0.236631	1244.436890	0.000000	NaN	NaN
556.999859	0.002873	28.734107	0.237231	1245.041260	0.000000	NaN	NaN
558.499944	0.002849	28.486523	0.237986	1245.800659	0.000000	NaN	NaN
560.000030	0.002807	28.073882	0.238640	1246.459106	0.000000	NaN	NaN
561.499116	0.002939	29.394332	0.239254	1247.076782	0.000000	NaN	NaN
562.999202	0.002890	28.899163	0.239833	1247.659424	0.000000	NaN	NaN
564.499287	0.002840	28.403995	0.240598	1248.429321	0.000000	NaN	NaN
565.999373	0.002906	29.064220	0.241233	1249.068481	0.000000	NaN	NaN
567.499459	0.002865	28.651579	0.242019	1249.858887	0.000000	NaN	NaN
568.999545	0.002857	28.569051	0.242509	1250.351929	0.000000	NaN	NaN
570.499631	0.002882	28.816635	0.243363	1251.211670	0.000000	NaN	NaN
571.999716	0.003162	31.622592	0.244037	1251.889648	0.000000	NaN	NaN
573.499802	0.003055	30.549726	0.245254	1253.114624	0.000000	NaN	NaN
574.999888	0.003088	30.879838	0.245997	1253.861694	0.000000	NaN	NaN
576.499974	0.003080	30.797310	0.246690	1254.559448	0.000000	NaN	NaN
577.999060	0.003030	30.302142	0.247426	1255.300049	0.000000	NaN	NaN
579.499145	0.002972	29.724445	0.248180	1256.059204	0.000000	NaN	NaN
580.999231	0.002964	29.641917	0.249029	1256.913208	0.000000	NaN	NaN
582.499317	0.002840	28.403995	0.249461	1257.348145	0.000000	NaN	NaN
583.999403	0.002923	29.229276	0.251290	1259.188232	0.000000	NaN	NaN
585.499489	0.003014	30.137085	0.251989	1259.891968	0.000000	NaN	NaN
586.999574	0.002931	29.311804	0.252592	1260.499023	0.000000	NaN	NaN
588.499660	0.002898	28.981692	0.253074	1260.983887	0.000000	NaN	NaN
589.999746	0.002725	27.248601	0.253302	1261.212769	0.000000	NaN	NaN
591.499832	0.002849	28.486523	0.253915	1261.830078	0.000000	NaN	NaN
592.999918	0.002832	28.321467	0.254610	1262.529053	0.000000	NaN	NaN
594.500003	0.002807	28.073882	0.255270	1263.193970	0.000000	NaN	NaN
595.999089	0.003047	30.467198	0.255947	1263.874390	0.000000	NaN	NaN
597.499175	0.002931	29.311804	0.256495	1264.426636	0.000000	NaN	NaN
598.999261	0.002981	29.806973	0.257090	1265.024902	0.000000	NaN	NaN
600.499347	0.002923	29.229276	0.257736	1265.675659	0.000000	NaN	NaN
601.999432	0.002948	29.476860	0.258353	1266.295898	0.000000	NaN	NaN
603.499518	0.002857	28.569051	0.259050	1266.997192	0.000000	NaN	NaN
604.999604	0.002948	29.476860	0.259679	1267.630249	0.000000	NaN	NaN
606.499690	0.002931	29.311804	0.260471	1268.427368	0.000000	NaN	NaN
607.999776	0.002849	28.486523	0.261109	1269.069580	0.000000	NaN	NaN
609.499861	0.003055	30.549726	0.261641	1269.604370	0.000000	NaN	NaN
610.999947	0.002989	29.889501	0.262317	1270.285522	0.000000	NaN	NaN
612.500033	0.002997	29.972029	0.262913	1270.885010	0.000000	NaN	NaN
613.999119	0.002832	28.321467	0.263625	1271.601685	0.000000	NaN	NaN
615.499204	0.003030	30.302142	0.264246	1272.226318	0.000000	NaN	NaN
616.999290	0.003030	30.302142	0.264910	1272.894165	0.000000	NaN	NaN
618.499376	0.003014	30.137085	0.265537	1273.525024	0.000000	NaN	NaN
619.999462	0.003038	30.384670	0.266264	1274.257202	0.000000	NaN	NaN
621.499548	0.003030	30.302142	0.266986	1274.983521	0.000000	NaN	NaN
622.999633	0.003022	30.219613	0.267572	1275.573608	0.000000	NaN	NaN
624.499719	0.002956	29.559388	0.268243	1276.248291	0.000000	NaN	NaN
625.999805	0.002972	29.724445	0.268923	1276.932861	0.000000	NaN	NaN
627.499891	0.003071	30.714782	0.269666	1277.680786	0.000000	NaN	NaN
628.999977	0.002972	29.724445	0.270278	1278.295898	0.000000	NaN	NaN
630.499062	0.003080	30.797310	0.270992	1279.015015	0.000000	NaN	NaN
631.999148	0.003022	30.219613	0.271742	1279.769775	0.000000	NaN	NaN
633.499234	0.003055	30.549726	0.272324	1280.355225	0.000000	NaN	NaN
634.999320	0.003022	30.219613	0.272956	1280.991455	0.000000	NaN	NaN
636.499406	0.003022	30.219613	0.273713	1281.752930	0.000000	NaN	NaN
637.999491	0.003038	30.384670	0.274296	1282.340088	0.000000	NaN	NaN
639.499577	0.003005	30.054557	0.275080	1283.128784	0.000000	NaN	NaN
640.999663	0.003047	30.467198	0.275900	1283.954102	0.000000	NaN	NaN
642.499749	0.003071	30.714782	0.276332	1284.389038	0.000000	NaN	NaN
643.999835	0.003146	31.457535	0.277245	1285.307373	0.000000	NaN	NaN
645.499920	0.003104	31.044895	0.277813	1285.878784	0.000000	NaN	NaN
647.000006	0.003055	30.549726	0.278580	1286.650513	0.000000	NaN	NaN
648.499092	0.003047	30.467198	0.278212	1286.280640	0.000000	NaN	NaN
649.999178	0.003088	30.879838	0.278655	1286.726562	0.000000	NaN	NaN
651.499264	0.002939	29.394332	0.279338	1287.413452	0.000000	NaN	NaN
652.999349	0.003047	30.467198	0.280108	1288.188721	0.000000	NaN	NaN
654.499435	0.003038	30.384670	0.280831	1288.916504	0.000000	NaN	NaN
655.999521	0.003038	30.384670	0.281581	1289.670410	0.000000	NaN	NaN
657.499607	0.003047	30.467198	0.282252	1290.345825	0.000000	NaN	NaN
658.999693	0.003138	31.375007	0.282778	1290.875366	0.000000	NaN	NaN
660.499778	0.003104	31.044895	0.283600	1291.702637	0.000000	NaN	NaN
661.999864	0.003022	30.219613	0.284147	1292.252563	0.000000	NaN	NaN
663.499950	0.003195	31.952704	0.285094	1293.205688	0.000000	NaN	NaN
665.000036	0.003146	31.457535	0.285659	1293.774902	0.000000	NaN	NaN
666.499122	0.003038	30.384670	0.286304	1294.423706	0.000000	NaN	NaN
667.999207	0.003080	30.797310	0.287008	1295.132080	0.000000	NaN	NaN
669.499293	0.003154	31.540063	0.287634	1295.761597	0.000000	NaN	NaN
670.999379	0.003162	31.622592	0.288385	1296.518066	0.000000	NaN	NaN
672.499465	0.003096	30.962367	0.288983	1297.119995	0.000000	NaN	NaN
673.999551	0.003113	31.127423	0.289793	1297.934082	0.000000	NaN	NaN
675.499636	0.003071	30.714782	0.290346	1298.490723	0.000000	NaN	NaN
676.999722	0.003104	31.044895	0.291025	1299.174561	0.000000	NaN	NaN
678.499808	0.003071	30.714782	0.291991	1300.146240	0.000000	NaN	NaN
679.999894	0.003088	30.879838	0.292368	1300.526123	0.000000	NaN	NaN
681.499980	0.003055	30.549726	0.293235	1301.398437	0.000000	NaN	NaN
682.999065	0.003071	30.714782	0.293803	1301.969727	0.000000	NaN	NaN
684.499151	0.003096	30.962367	0.294423	1302.593506	0.000000	NaN	NaN
685.999237	0.003113	31.127423	0.293195	1301.358521	0.000000	NaN	NaN
687.499323	0.003327	33.273154	0.293681	1301.847534	0.000000	NaN	NaN
688.999408	0.003195	31.952704	0.294513	1302.683960	0.000000	NaN	NaN
690.499494	0.003129	31.292479	0.295210	1303.385376	0.000000	NaN	NaN
691.999580	0.003146	31.457535	0.295886	1304.066284	0.000000	NaN	NaN
693.499666	0.002989	29.889501	0.296454	1304.638062	0.000000	NaN	NaN
694.999752	0.003113	31.127423	0.297068	1305.255493	0.000000	NaN	NaN
696.499837	0.003138	31.375007	0.297768	1305.960327	0.000000	NaN	NaN
697.999923	0.003096	30.962367	0.298482	1306.678833	0.000000	NaN	NaN
699.500009	0.003055	30.549726	0.299074	1307.274048	0.000000	NaN	NaN
700.999095	0.002997	29.972029	0.299887	1308.092163	0.000000	NaN	NaN
702.499181	0.003096	30.962367	0.300525	1308.734619	0.000000	NaN	NaN
703.999266	0.003080	30.797310	0.301274	1309.487793	0.000000	NaN	NaN
705.499352	0.003096	30.962367	0.301994	1310.212646	0.000000	NaN	NaN
706.999438	0.003204	32.035232	0.302415	1310.636108	0.000000	NaN	NaN
708.499524	0.003129	31.292479	0.303238	1311.464722	0.000000	NaN	NaN
709.999610	0.003104	31.044895	0.303922	1312.152466	0.000000	NaN	NaN
711.499695	0.003171	31.705120	0.304565	1312.799927	0.000000	NaN	NaN
712.999781	0.003121	31.209951	0.305235	1313.473755	0.000000	NaN	NaN
714.499867	0.003187	31.870176	0.305970	1314.213623	0.000000	NaN	NaN
715.999953	0.003138	31.375007	0.306453	1314.699829	0.000000	NaN	NaN
717.500039	0.003162	31.622592	0.307286	1315.537720	0.000000	NaN	NaN
718.999124	0.003071	30.714782	0.307920	1316.176270	0.000000	NaN	NaN
720.499210	0.003245	32.447873	0.308746	1317.007202	0.000000	NaN	NaN
721.999296	0.003096	30.962367	0.309301	1317.565918	0.000000	NaN	NaN
723.499382	0.003121	31.209951	0.309891	1318.159058	0.000000	NaN	NaN
724.999468	0.003146	31.457535	0.310675	1318.948242	0.000000	NaN	NaN
726.499553	0.003071	30.714782	0.311361	1319.639038	0.000000	NaN	NaN
727.999639	0.003204	32.035232	0.312091	1320.373535	0.000000	NaN	NaN
729.499725	0.003154	31.540063	0.312749	1321.035034	0.000000	NaN	NaN
730.999811	0.003162	31.622592	0.313517	1321.808350	0.000000	NaN	NaN
732.499897	0.003171	31.705120	0.314137	1322.432007	0.000000	NaN	NaN
733.999982	0.003154	31.540063	0.314865	1323.165161	0.000000	NaN	NaN
735.499068	0.003195	31.952704	0.315369	1323.672119	0.000000	NaN	NaN
736.999154	0.003195	31.952704	0.316043	1324.349976	0.000000	NaN	NaN
738.499240	0.003212	32.117760	0.316857	1325.169678	0.000000	NaN	NaN
739.999326	0.003171	31.705120	0.317603	1325.920288	0.000000	NaN	NaN
741.499411	0.003171	31.705120	0.318374	1326.696411	0.000000	NaN	NaN
742.999497	0.003154	31.540063	0.318891	1327.216553	0.000000	NaN	NaN
744.499583	0.003195	31.952704	0.319679	1328.009033	0.000000	NaN	NaN
745.999669	0.003162	31.622592	0.320253	1328.587402	0.000000	NaN	NaN
747.499754	0.003171	31.705120	0.321062	1329.400635	0.000000	NaN	NaN
748.999840	0.003204	32.035232	0.321709	1330.051636	0.000000	NaN	NaN
750.499926	0.003228	32.282816	0.322333	1330.680298	0.000000	NaN	NaN
752.000012	0.003121	31.209951	0.322932	1331.282837	0.000000	NaN	NaN
753.499098	0.003146	31.457535	0.323694	1332.049927	0.000000	NaN	NaN
754.999183	0.003195	31.952704	0.324339	1332.698364	0.000000	NaN	NaN
756.499269	0.003344	33.438210	0.325029	1333.392578	0.000000	NaN	NaN
757.999355	0.003195	31.952704	0.325767	1334.136108	0.000000	NaN	NaN
759.499441	0.003171	31.705120	0.326661	1335.035645	0.000000	NaN	NaN
760.999527	0.003154	31.540063	0.327192	1335.569580	0.000000	NaN	NaN
762.499612	0.003162	31.622592	0.327725	1336.106079	0.000000	NaN	NaN
763.999698	0.003129	31.292479	0.328406	1336.791626	0.000000	NaN	NaN
765.499784	0.003113	31.127423	0.329002	1337.390991	0.000000	NaN	NaN
766.999870	0.003138	31.375007	0.329662	1338.055298	0.000000	NaN	NaN
768.499956	0.003113	31.127423	0.330478	1338.875977	0.000000	NaN	NaN
770.000041	0.003212	32.117760	0.331026	1339.427612	0.000000	NaN	NaN
771.499127	0.003146	31.457535	0.331517	1339.922119	0.000000	NaN	NaN
772.999213	0.003162	31.622592	0.332510	1340.921753	0.000000	NaN	NaN
774.499299	0.003171	31.705120	0.333199	1341.614502	0.000000	NaN	NaN
775.999385	0.003138	31.375007	0.333773	1342.192749	0.000000	NaN	NaN
777.499470	0.003237	32.365345	0.334379	1342.802124	0.000000	NaN	NaN
778.999556	0.003195	31.952704	0.335057	1343.484741	0.000000	NaN	NaN
780.499642	0.003179	31.787648	0.335666	1344.096802	0.000000	NaN	NaN
781.999728	0.003121	31.209951	0.336371	1344.806396	0.000000	NaN	NaN
783.499814	0.003129	31.292479	0.337105	1345.545044	0.000000	NaN	NaN
784.999899	0.003179	31.787648	0.337911	1346.356689	0.000000	NaN	NaN
786.499985	0.003146	31.457535	0.338593	1347.042603	0.000000	NaN	NaN
787.999071	0.003245	32.447873	0.339211	1347.664795	0.000000	NaN	NaN
789.499157	0.003261	32.612929	0.339973	1348.431641	0.000000	NaN	NaN
790.999243	0.003187	31.870176	0.340508	1348.970093	0.000000	NaN	NaN
792.499328	0.003113	31.127423	0.341324	1349.791016	0.000000	NaN	NaN
793.999414	0.003212	32.117760	0.342013	1350.484009	0.000000	NaN	NaN
795.499500	0.003121	31.209951	0.342616	1351.091309	0.000000	NaN	NaN
796.999586	0.003104	31.044895	0.343191	1351.669800	0.000000	NaN	NaN
798.499672	0.003212	32.117760	0.344221	1352.705933	0.000000	NaN	NaN
799.999757	0.003294	32.943041	0.344760	1353.248169	0.000000	NaN	NaN
801.499843	0.003270	32.695457	0.345611	1354.104858	0.000000	NaN	NaN
802.999929	0.003187	31.870176	0.346101	1354.598389	0.000000	NaN	NaN
804.500015	0.003237	32.365345	0.347077	1355.580688	0.000000	NaN	NaN
805.999101	0.003245	32.447873	0.347613	1356.119019	0.000000	NaN	NaN
807.499186	0.003162	31.622592	0.348257	1356.767578	0.000000	NaN	NaN
808.999272	0.003146	31.457535	0.349016	1357.531494	0.000000	NaN	NaN
810.499358	0.003319	33.190626	0.349751	1358.270752	0.000000	NaN	NaN
811.999444	0.003204	32.035232	0.350314	1358.837524	0.000000	NaN	NaN
813.499529	0.003212	32.117760	0.350949	1359.476196	0.000000	NaN	NaN
814.999615	0.003146	31.457535	0.351749	1360.282104	0.000000	NaN	NaN
816.499701	0.003212	32.117760	0.352376	1360.912231	0.000000	NaN	NaN
817.999787	0.003195	31.952704	0.353199	1361.741211	0.000000	NaN	NaN
819.499873	0.003080	30.797310	0.353837	1362.382812	0.000000	NaN	NaN
820.999959	0.003278	32.777985	0.354452	1363.001221	0.000000	NaN	NaN
822.500044	0.003204	32.035232	0.355015	1363.568359	0.000000	NaN	NaN
823.999130	0.003228	32.282816	0.355709	1364.267090	0.000000	NaN	NaN
825.499216	0.003261	32.612929	0.356538	1365.101196	0.000000	NaN	NaN
826.999302	0.003146	31.457535	0.357296	1365.863281	0.000000	NaN	NaN
828.499387	0.003204	32.035232	0.357932	1366.503296	0.000000	NaN	NaN
829.999473	0.003195	31.952704	0.358723	1367.299438	0.000000	NaN	NaN
831.499559	0.003253	32.530401	0.359568	1368.150513	0.000000	NaN	NaN
832.999645	0.003336	33.355682	0.360171	1368.756958	0.000000	NaN	NaN
834.499731	0.003253	32.530401	0.360985	1369.575806	0.000000	NaN	NaN
835.999816	0.003253	32.530401	0.361879	1370.475952	0.000000	NaN	NaN
837.499902	0.003162	31.622592	0.362406	1371.005859	0.000000	NaN	NaN
838.999988	0.003104	31.044895	0.363195	1371.800171	0.000000	NaN	NaN
840.499074	0.003179	31.787648	0.363859	1372.467773	0.000000	NaN	NaN
841.999160	0.003121	31.209951	0.364531	1373.144165	0.000000	NaN	NaN
843.499245	0.003113	31.127423	0.365462	1374.080811	0.000000	NaN	NaN
844.999331	0.003261	32.612929	0.366190	1374.813721	0.000000	NaN	NaN
846.499417	0.003204	32.035232	0.366700	1375.327026	0.000000	NaN	NaN
847.999503	0.003113	31.127423	0.367503	1376.134644	0.000000	NaN	NaN
849.499589	0.003162	31.622592	0.368109	1376.744507	0.000000	NaN	NaN
850.999674	0.003187	31.870176	0.369026	1377.667847	0.000000	NaN	NaN
852.499760	0.003261	32.612929	0.369675	1378.321167	0.000000	NaN	NaN
853.999846	0.003138	31.375007	0.370305	1378.955078	0.000000	NaN	NaN
855.499932	0.003080	30.797310	0.371171	1379.826416	0.000000	NaN	NaN
857.000018	0.003104	31.044895	0.371715	1380.373779	0.000000	NaN	NaN
858.499103	0.003113	31.127423	0.372601	1381.265015	0.000000	NaN	NaN
859.999189	0.003146	31.457535	0.373377	1382.046143	0.000000	NaN	NaN
861.499275	0.003146	31.457535	0.374193	1382.866943	0.000000	NaN	NaN
862.999361	0.003204	32.035232	0.374939	1383.618408	0.000000	NaN	NaN
864.499446	0.003104	31.044895	0.375480	1384.161987	0.000000	NaN	NaN
865.999532	0.003104	31.044895	0.376273	1384.960449	0.000000	NaN	NaN
867.499618	0.003071	30.714782	0.377044	1385.735962	0.000000	NaN	NaN
868.999704	0.003138	31.375007	0.378018	1386.716919	0.000000	NaN	NaN
870.499790	0.003179	31.787648	0.378745	1387.448486	0.000000	NaN	NaN
871.999876	0.003138	31.375007	0.379367	1388.073486	0.000000	NaN	NaN
873.499961	0.003171	31.705120	0.380172	1388.883911	0.000000	NaN	NaN
875.000047	0.003171	31.705120	0.381050	1389.767822	0.000000	NaN	NaN
876.499133	0.003055	30.549726	0.381976	1390.699341	0.000000	NaN	NaN
877.999219	0.003088	30.879838	0.382798	1391.526367	0.000000	NaN	NaN
879.499304	0.002989	29.889501	0.383488	1392.220947	0.000000	NaN	NaN
880.999390	0.002989	29.889501	0.384378	1393.116333	0.000000	NaN	NaN
882.499476	0.003063	30.632254	0.385315	1394.059204	0.000000	NaN	NaN
883.999562	0.003096	30.962367	0.385964	1394.712891	0.000000	NaN	NaN
885.499648	0.003063	30.632254	0.386670	1395.423584	0.000000	NaN	NaN
886.999734	0.002865	28.651579	0.387677	1396.436523	0.000000	NaN	NaN
888.499819	0.003113	31.127423	0.388313	1397.076538	0.000000	NaN	NaN
889.999905	0.002939	29.394332	0.389364	1398.133789	0.000000	NaN	NaN
891.499991	0.003071	30.714782	0.390146	1398.921265	0.000000	NaN	NaN
892.999077	0.002981	29.806973	0.391039	1399.819580	0.000000	NaN	NaN
894.499162	0.002906	29.064220	0.392029	1400.816162	0.000000	NaN	NaN
895.999248	0.002948	29.476860	0.392863	1401.655640	0.000000	NaN	NaN
897.499334	0.002948	29.476860	0.393891	1402.689209	0.000000	NaN	NaN
898.999420	0.003038	30.384670	0.394739	1403.542969	0.000000	NaN	NaN
900.499506	0.003030	30.302142	0.395691	1404.501343	0.000000	NaN	NaN
901.999591	0.003055	30.549726	0.396649	1405.465332	0.000000	NaN	NaN
903.499677	0.002824	28.238938	0.397706	1406.528564	0.000000	NaN	NaN
904.999763	0.002824	28.238938	0.398661	1407.489624	0.000000	NaN	NaN
906.499849	0.002816	28.156410	0.399790	1408.626343	0.000000	NaN	NaN
907.999935	0.002733	27.331129	0.400684	1409.525024	0.000000	NaN	NaN
909.500020	0.002807	28.073882	0.401884	1410.732788	0.000000	NaN	NaN
910.999106	0.002865	28.651579	0.402986	1411.841675	0.000000	NaN	NaN
912.499192	0.002824	28.238938	0.404517	1413.382568	0.000000	NaN	NaN
913.999278	0.002799	27.991354	0.405698	1414.571533	0.000000	NaN	NaN
915.499364	0.002642	26.423320	0.407100	1415.981689	0.000000	NaN	NaN
916.999449	0.002717	27.166073	0.408660	1417.551880	0.000000	NaN	NaN
918.499535	0.002560	25.598038	0.410136	1419.037231	0.000000	NaN	NaN
919.999621	0.002453	24.525173	0.411992	1420.904785	0.000000	NaN	NaN
921.499707	0.002304	23.039667	0.413932	1422.856934	0.000000	NaN	NaN
922.999793	0.002254	22.544498	0.415970	1424.907715	0.000000	NaN	NaN
924.499878	0.002065	20.646351	0.418723	1427.678589	0.000000	NaN	NaN
925.999964	0.001809	18.087979	0.422058	1431.034790	0.000000	NaN	NaN
927.500050	0.001635	16.354889	0.425715	1434.714600	0.000000	NaN	NaN
928.999136	0.001338	13.383876	0.429551	1438.574341	0.000000	NaN	NaN
930.499221	0.001173	11.733313	0.433357	1442.404663	0.000000	NaN	NaN
931.999307	0.000901	9.009885	0.335768	1344.199829	0.000000	NaN	NaN
933.499393	0.000752	7.524379	0.339990	1348.448486	0.000000	NaN	NaN
934.999479	0.000761	7.606907	0.312725	1321.010986	0.000000	NaN	NaN
936.514566	0.000686	6.864154	0.318615	1326.938232	0.000000	NaN	NaN
937.999651	0.000488	4.883479	0.315564	1323.868042	0.000000	NaN	NaN
939.499736	0.000216	2.160051	0.315474	1323.777954	0.000000	NaN	NaN
940.999822	-2.332649E-5	-0.233265	0.387838	1396.598877	0.000000	NaN	NaN
942.499908	-3.157930E-5	-0.315793	0.739918	1750.901001	0.000000	NaN	NaN
943.999994	-0.000147	-1.471187	-0.345078	659.056274	0.000000	NaN	NaN
945.499079	-8.109618E-5	-0.810962	-0.335990	668.201294	0.000000	NaN	NaN
946.999165	-8.109618E-5	-0.810962	-0.334450	669.751404	0.000000	NaN	NaN
947.999222	-7.284337E-5	-0.728434	-0.332822	671.389893	0.000000	NaN	NaN