File: data/57k_1-3_2 (190415).lvm
LabVIEW Measurement
Writer_Version	2
Reader_Version	2
Separator	Tab
Decimal_Separator	.
Multi_Headings	No
X_Columns	One
Time_Pref	Absolute
Operator	user
Description	Load(N)/Stress(MPa)/Distance A(pixel)/Strain A/Distance B(pixel)/Strain B/Poisson's ratio
Date	2019/04/15
Time	13:10:04.8134063300347318543
***End_of_Header***

Notes	X 값은 오직 다음과 같을 때에만 유효함이 보장됩니다. Dev1/ai0
Channels	7
Samples	1	1	1	1	1	1	1
Date	2019/04/15	2019/04/15	2019/04/15	2019/04/15	2019/04/15	2019/04/15	2019/04/15
Time	13:10:04.8134063300347318543	13:10:04.8134063300347318543	13:10:04.8134064674377441406	13:10:04.8134064674377441406	13:10:04.8134064674377441406	13:10:04.8134064674377441406	13:10:04.8134064674377441406
Y_Unit_Label	Volts	Volts
X_Dimension	Time	Time	Time	Time	Time	Time	Time
X0	0.0000000000000000E+0	0.0000000000000000E+0	0.0000000000000000E+0	0.0000000000000000E+0	0.0000000000000000E+0	0.0000000000000000E+0	0.0000000000000000E+0
Delta_X	0.000000	0.000000	1.000000	1.000000	1.000000	1.000000	1.000000
***End_of_Header***
X_Value	Dev1/ai0	Dev1/ai0 1	Untitled	Untitled 1	Untitled 2	Untitled 3	Untitled 4	Comment
0.000000	5.094882E-5	0.509488	-0.000122	920.235413	0.000000	NaN	NaN
1.000057	-3.983212E-5	-0.398321	-9.232759E-5	920.262878	0.000000	NaN	NaN
2.000114	3.444320E-5	0.344432	-3.588200E-5	920.314819	0.000000	NaN	NaN
3.000172	-0.000122	-1.223602	-0.000137	920.222107	0.000000	NaN	NaN
4.000229	-4.808493E-5	-0.480849	5.352497E-5	920.397156	0.000000	NaN	NaN
5.188297	1.793757E-5	0.179376	0.000354	920.673523	0.000000	NaN	NaN
5.999343	3.444320E-5	0.344432	0.000636	920.932861	0.000000	NaN	NaN
6.999400	-1.507368E-5	-0.150737	0.000879	921.156616	0.000000	NaN	NaN
7.999458	1.793757E-5	0.179376	0.001035	921.300659	0.000000	NaN	NaN
8.999515	0.000290	2.902804	0.001376	921.614380	0.000000	NaN	NaN
9.999572	6.745445E-5	0.674545	0.001528	921.754089	0.000000	NaN	NaN
10.999629	0.000389	3.893141	0.001975	922.165833	0.000000	NaN	NaN
11.999686	0.000257	2.572691	0.002290	922.455383	0.000000	NaN	NaN
12.999744	0.000249	2.490163	0.002602	922.742859	0.000000	NaN	NaN
13.999801	0.000307	3.067860	0.002902	923.018555	0.000000	NaN	NaN
14.999858	0.000389	3.893141	0.002951	923.064087	0.000000	NaN	NaN
15.999915	0.000249	2.490163	0.003407	923.483765	0.000000	NaN	NaN
16.999972	0.000505	5.048535	0.003695	923.748169	0.000000	NaN	NaN
18.000030	0.000431	4.305782	0.003952	923.984802	0.000000	NaN	NaN
19.000087	0.000348	3.480501	0.004284	924.290161	0.000000	NaN	NaN
20.000144	0.000299	2.985332	0.004571	924.554871	0.000000	NaN	NaN
21.000201	0.000381	3.810613	0.004802	924.767517	0.000000	NaN	NaN
22.000258	0.000505	5.048535	0.005152	925.089539	0.000000	NaN	NaN
23.000316	0.000464	4.635895	0.005394	925.311768	0.000000	NaN	NaN
23.999373	0.000596	5.956345	0.005754	925.643127	0.000000	NaN	NaN
24.999430	0.000587	5.873817	0.005968	925.840332	0.000000	NaN	NaN
25.999487	0.000398	3.975670	0.006275	926.123230	0.000000	NaN	NaN
26.999544	0.000579	5.791288	0.006624	926.444031	0.000000	NaN	NaN
27.999602	0.000546	5.461176	0.006876	926.675842	0.000000	NaN	NaN
28.999659	0.000736	7.359323	0.007259	927.028259	0.000000	NaN	NaN
29.999716	0.000554	5.543704	0.007413	927.169922	0.000000	NaN	NaN
30.999773	0.000645	6.451513	0.007720	927.452759	0.000000	NaN	NaN
31.999830	0.000604	6.038873	0.008056	927.762024	0.000000	NaN	NaN
32.999887	0.000744	7.441851	0.008432	928.108215	0.000000	NaN	NaN
33.999945	0.000670	6.699098	0.008689	928.345154	0.000000	NaN	NaN
35.000002	0.000653	6.534042	0.009003	928.634033	0.000000	NaN	NaN
36.000059	0.000851	8.514717	0.009366	928.968018	0.000000	NaN	NaN
37.000116	0.000752	7.524379	0.009721	929.294556	0.000000	NaN	NaN
38.000174	0.000810	8.102076	0.010023	929.572815	0.000000	NaN	NaN
39.000231	0.000802	8.019548	0.010410	929.928406	0.000000	NaN	NaN
40.000288	0.000951	9.505054	0.010821	930.307373	0.000000	NaN	NaN
40.999345	0.000909	9.092413	0.011307	930.754089	0.000000	NaN	NaN
41.999402	0.000860	8.597245	0.011572	930.997986	0.000000	NaN	NaN
42.999460	0.000835	8.349660	0.012167	931.545532	0.000000	NaN	NaN
43.999517	0.001140	11.403201	0.012757	932.088562	0.000000	NaN	NaN
44.999574	0.001008	10.082751	0.013027	932.337524	0.000000	NaN	NaN
45.999631	0.000951	9.505054	0.013260	932.551331	0.000000	NaN	NaN
46.999688	0.000975	9.752638	0.014003	933.235840	0.000000	NaN	NaN
47.999746	0.001050	10.495392	0.014379	933.581787	0.000000	NaN	NaN
48.999803	0.000984	9.835167	0.014812	933.979919	0.000000	NaN	NaN
49.999860	0.001066	10.660448	0.015101	934.246460	0.000000	NaN	NaN
50.999917	0.001157	11.568257	0.015643	934.744629	0.000000	NaN	NaN
51.999974	0.001157	11.568257	0.016101	935.166199	0.000000	NaN	NaN
53.000031	0.001074	10.742976	0.016500	935.533691	0.000000	NaN	NaN
54.000089	0.001132	11.320673	0.016882	935.885132	0.000000	NaN	NaN
55.000146	0.001281	12.806179	0.017514	936.466858	0.000000	NaN	NaN
56.000203	0.001355	13.548932	0.017891	936.813660	0.000000	NaN	NaN
57.000260	0.001173	11.733313	0.018322	937.210327	0.000000	NaN	NaN
58.000318	0.001107	11.073088	0.018741	937.595886	0.000000	NaN	NaN
58.999375	0.001091	10.908032	0.019104	937.929749	0.000000	NaN	NaN
59.999432	0.001182	11.815842	0.019795	938.566101	0.000000	NaN	NaN
60.999489	0.001157	11.568257	0.020209	938.947388	0.000000	NaN	NaN
61.999546	0.001231	12.311010	0.020601	939.308105	0.000000	NaN	NaN
62.999603	0.001223	12.228482	0.021012	939.686401	0.000000	NaN	NaN
63.999661	0.001239	12.393538	0.021605	940.232422	0.000000	NaN	NaN
64.999718	0.001264	12.641123	0.022039	940.631348	0.000000	NaN	NaN
65.999775	0.001182	11.815842	0.022442	941.002625	0.000000	NaN	NaN
66.999832	0.001264	12.641123	0.022990	941.506470	0.000000	NaN	NaN
67.999889	0.001289	12.888707	0.023449	941.929260	0.000000	NaN	NaN
68.999947	0.001355	13.548932	0.024216	942.634766	0.000000	NaN	NaN
70.000004	0.001330	13.301348	0.024707	943.087280	0.000000	NaN	NaN
71.000061	0.001165	11.650785	0.024956	943.315857	0.000000	NaN	NaN
72.000118	0.001380	13.796517	0.025377	943.703918	0.000000	NaN	NaN
73.000175	0.001305	13.053763	0.026065	944.336792	0.000000	NaN	NaN
74.000233	0.001239	12.393538	0.026682	944.904846	0.000000	NaN	NaN
75.000290	0.001330	13.301348	0.027156	945.340515	0.000000	NaN	NaN
75.999347	0.001404	14.044101	0.027630	945.777344	0.000000	NaN	NaN
76.999404	0.001190	11.898370	0.028128	946.235291	0.000000	NaN	NaN
77.999461	0.001371	13.713988	0.028779	946.834839	0.000000	NaN	NaN
78.999519	0.001330	13.301348	0.029233	947.252014	0.000000	NaN	NaN
79.999576	0.001314	13.136292	0.030089	948.040100	0.000000	NaN	NaN
80.999633	0.001429	14.291685	0.030262	948.199890	0.000000	NaN	NaN
81.999690	0.001355	13.548932	0.030911	948.797119	0.000000	NaN	NaN
82.999747	0.001363	13.631460	0.031333	949.185242	0.000000	NaN	NaN
83.999805	0.001363	13.631460	0.031808	949.622742	0.000000	NaN	NaN
84.999862	0.001380	13.796517	0.032406	950.172546	0.000000	NaN	NaN
85.999919	0.001338	13.383876	0.032950	950.672913	0.000000	NaN	NaN
86.999976	0.001347	13.466404	0.033769	951.427185	0.000000	NaN	NaN
88.000033	0.001355	13.548932	0.033932	951.577332	0.000000	NaN	NaN
89.000091	0.001363	13.631460	0.034465	952.067505	0.000000	NaN	NaN
90.000148	0.001470	14.704326	-0.842776	144.701111	0.000000	NaN	NaN
91.000205	0.001330	13.301348	0.035580	953.094055	0.000000	NaN	NaN
92.000262	0.001437	14.374213	-0.843721	143.831436	0.000000	NaN	NaN
93.000319	0.001388	13.879045	-0.841139	146.207336	0.000000	NaN	NaN
93.999376	0.001429	14.291685	0.036994	954.394958	0.000000	NaN	NaN
94.999434	0.001289	12.888707	-0.841913	145.495499	0.000000	NaN	NaN
95.999491	0.001528	15.282023	-0.840115	147.149811	0.000000	NaN	NaN
96.999548	0.001380	13.796517	0.038858	956.110962	0.000000	NaN	NaN
97.999605	0.001347	13.466404	0.039517	956.716797	0.000000	NaN	NaN
98.999662	0.001380	13.796517	0.039982	957.145569	0.000000	NaN	NaN
99.999720	0.001396	13.961573	0.040531	957.650391	0.000000	NaN	NaN
101.001777	0.001454	14.539270	0.040992	958.074768	0.000000	NaN	NaN
101.999834	0.001380	13.796517	0.041481	958.525146	0.000000	NaN	NaN
102.999891	0.001446	14.456742	0.041963	958.968079	0.000000	NaN	NaN
103.999949	0.001470	14.704326	0.042468	959.433105	0.000000	NaN	NaN
105.000006	0.001413	14.126629	0.042971	959.896606	0.000000	NaN	NaN
106.000063	0.001470	14.704326	0.043606	960.480408	0.000000	NaN	NaN
107.000120	0.001413	14.126629	0.044137	960.969421	0.000000	NaN	NaN
108.000177	0.001338	13.383876	0.044540	961.340393	0.000000	NaN	NaN
109.000235	0.001314	13.136292	0.044982	961.746521	0.000000	NaN	NaN
110.000292	0.001289	12.888707	0.045605	962.319885	0.000000	NaN	NaN
110.999349	0.001429	14.291685	0.046209	962.875916	0.000000	NaN	NaN
111.999406	0.001520	15.199495	0.046545	963.185791	0.000000	NaN	NaN
112.999463	0.001470	14.704326	0.047096	963.692383	0.000000	NaN	NaN
113.999520	0.001536	15.364551	0.047441	964.009827	0.000000	NaN	NaN
114.999578	0.001503	15.034438	0.047853	964.389465	0.000000	NaN	NaN
115.999635	0.001437	14.374213	0.048427	964.917542	0.000000	NaN	NaN
116.999692	0.001470	14.704326	0.048967	965.414978	0.000000	NaN	NaN
117.999749	0.001462	14.621798	0.049417	965.828247	0.000000	NaN	NaN
118.999806	0.001487	14.869382	0.050002	966.367493	0.000000	NaN	NaN
119.999864	0.001404	14.044101	0.050589	966.907227	0.000000	NaN	NaN
120.999921	0.001635	16.354889	0.051066	967.345886	0.000000	NaN	NaN
121.999978	0.001569	15.694663	0.051557	967.798096	0.000000	NaN	NaN
123.000035	0.001553	15.529607	0.052107	968.304260	0.000000	NaN	NaN
124.000092	0.001487	14.869382	0.052720	968.868408	0.000000	NaN	NaN
125.000150	0.001421	14.209157	0.053130	969.246216	0.000000	NaN	NaN
126.000207	0.001429	14.291685	0.053578	969.658508	0.000000	NaN	NaN
127.000264	0.001503	15.034438	0.054188	970.220093	0.000000	NaN	NaN
128.000321	0.001454	14.539270	0.054686	970.678345	0.000000	NaN	NaN
128.999378	0.001437	14.374213	0.055291	971.234680	0.000000	NaN	NaN
129.999436	0.001446	14.456742	0.055721	971.630676	0.000000	NaN	NaN
130.999493	0.001536	15.364551	0.056334	972.194641	0.000000	NaN	NaN
131.999550	0.001396	13.961573	0.056772	972.597473	0.000000	NaN	NaN
132.999607	0.001437	14.374213	0.057289	973.073425	0.000000	NaN	NaN
133.999664	0.001404	14.044101	0.057929	973.662354	0.000000	NaN	NaN
134.999722	0.001693	16.932585	0.058332	974.033508	0.000000	NaN	NaN
135.999779	0.001479	14.786854	0.058868	974.526733	0.000000	NaN	NaN
136.999836	0.001520	15.199495	0.059411	975.026550	0.000000	NaN	NaN
137.999893	0.001561	15.612135	0.059897	975.474243	0.000000	NaN	NaN
138.999950	0.001479	14.786854	0.060408	975.944275	0.000000	NaN	NaN
140.000008	0.001635	16.354889	0.061085	976.567017	0.000000	NaN	NaN
141.000065	0.001594	15.942248	0.061523	976.970520	0.000000	NaN	NaN
142.000122	0.001561	15.612135	0.061970	977.382202	0.000000	NaN	NaN
143.000179	0.001553	15.529607	0.062596	977.957825	0.000000	NaN	NaN
144.000236	0.001578	15.777192	0.063086	978.409302	0.000000	NaN	NaN
145.000294	0.001569	15.694663	0.063638	978.917053	0.000000	NaN	NaN
145.999351	0.001437	14.374213	0.064035	979.282654	0.000000	NaN	NaN
146.999408	0.001487	14.869382	0.064500	979.710144	0.000000	NaN	NaN
147.999465	0.001182	11.815842	0.065102	980.264221	0.000000	NaN	NaN
148.999522	0.001462	14.621798	0.065608	980.729980	0.000000	NaN	NaN
149.999580	0.001545	15.447079	0.066045	981.132080	0.000000	NaN	NaN
150.999637	0.001495	14.951910	0.066574	981.618835	0.000000	NaN	NaN
151.999694	0.001503	15.034438	0.067172	982.169556	0.000000	NaN	NaN
152.999751	0.001528	15.282023	0.067654	982.613098	0.000000	NaN	NaN
153.999808	0.001652	16.519945	0.068135	983.055359	0.000000	NaN	NaN
154.999865	0.001809	18.087979	0.068648	983.528320	0.000000	NaN	NaN
155.999923	0.001602	16.024776	0.069117	983.959717	0.000000	NaN	NaN
156.999980	0.001569	15.694663	0.069625	984.427002	0.000000	NaN	NaN
158.000037	0.001569	15.694663	0.070275	985.025391	0.000000	NaN	NaN
159.000094	0.001561	15.612135	0.070763	985.474609	0.000000	NaN	NaN
160.000151	0.001553	15.529607	0.071332	985.997803	0.000000	NaN	NaN
161.000209	0.001858	18.583148	0.071697	986.334290	0.000000	NaN	NaN
162.000266	0.001644	16.437417	0.072278	986.869202	0.000000	NaN	NaN
163.000323	0.001619	16.189832	0.072760	987.312805	0.000000	NaN	NaN
163.999380	0.001528	15.282023	0.073305	987.813660	0.000000	NaN	NaN
164.999437	0.001569	15.694663	0.073815	988.283081	0.000000	NaN	NaN
165.999495	0.001644	16.437417	0.074360	988.784790	0.000000	NaN	NaN
166.999552	0.001512	15.116967	0.074807	989.196289	0.000000	NaN	NaN
167.999609	0.001743	17.427754	0.075454	989.791321	0.000000	NaN	NaN
168.999666	0.001619	16.189832	0.075958	990.255981	0.000000	NaN	NaN
169.999723	0.001487	14.869382	0.076409	990.670593	0.000000	NaN	NaN
170.999781	0.001652	16.519945	0.077008	991.222351	0.000000	NaN	NaN
171.999838	0.001735	17.345226	0.077613	991.778748	0.000000	NaN	NaN
172.999895	0.001487	14.869382	0.078143	992.266907	0.000000	NaN	NaN
173.999952	0.001611	16.107304	0.078458	992.556519	0.000000	NaN	NaN
175.000010	0.001635	16.354889	0.079111	993.157776	0.000000	NaN	NaN
176.000067	0.001660	16.602473	0.079621	993.626953	0.000000	NaN	NaN
177.000124	0.001710	17.097642	0.080120	994.086060	0.000000	NaN	NaN
178.000181	0.001726	17.262698	0.080500	994.436279	0.000000	NaN	NaN
179.000238	0.001619	16.189832	0.081017	994.911804	0.000000	NaN	NaN
180.000295	0.001619	16.189832	0.081655	995.499084	0.000000	NaN	NaN
180.999353	0.001578	15.777192	0.082150	995.954834	0.000000	NaN	NaN
181.999410	0.001586	15.859720	0.082657	996.420837	0.000000	NaN	NaN
182.999467	0.001602	16.024776	0.083261	996.976501	0.000000	NaN	NaN
183.999524	0.002106	21.058992	0.083600	997.288574	0.000000	NaN	NaN
184.999581	0.001693	16.932585	0.084366	997.993652	0.000000	NaN	NaN
185.999639	0.001718	17.180170	0.084604	998.212830	0.000000	NaN	NaN
186.999696	0.001768	17.675339	0.085047	998.621094	0.000000	NaN	NaN
187.999753	0.001718	17.180170	0.085729	999.248108	0.000000	NaN	NaN
188.999810	0.001578	15.777192	0.086227	999.706726	0.000000	NaN	NaN
189.999867	0.001586	15.859720	-0.794203	189.405029	0.000000	NaN	NaN
190.999925	0.001652	16.519945	0.087130	1000.537659	0.000000	NaN	NaN
191.999982	0.001858	18.583148	0.087681	1001.045288	0.000000	NaN	NaN
193.000039	0.001635	16.354889	-0.791979	191.451294	0.000000	NaN	NaN
194.000096	0.001652	16.519945	-0.790267	193.027557	0.000000	NaN	NaN
195.000153	0.001677	16.767529	-0.790667	192.658920	0.000000	NaN	NaN
196.000211	0.001619	16.189832	-0.790103	193.177963	0.000000	NaN	NaN
197.000268	0.001652	16.519945	-0.790421	192.886032	0.000000	NaN	NaN
198.000325	0.001545	15.447079	-0.789442	193.786743	0.000000	NaN	NaN
198.999382	0.001743	17.427754	0.091515	1004.573120	0.000000	NaN	NaN
199.999439	0.001652	16.519945	0.091750	1004.789490	0.000000	NaN	NaN
200.999497	0.001685	16.850057	0.091983	1005.004150	0.000000	NaN	NaN
201.999554	0.001759	17.592810	0.093082	1006.015381	0.000000	NaN	NaN
202.999611	0.001776	17.757867	0.093350	1006.262329	0.000000	NaN	NaN
203.999668	0.001635	16.354889	0.093371	1006.281738	0.000000	NaN	NaN
204.999725	0.001602	16.024776	0.093929	1006.794800	0.000000	NaN	NaN
205.999783	0.001710	17.097642	0.094354	1007.186157	0.000000	NaN	NaN
206.999840	0.001528	15.282023	0.094854	1007.646606	0.000000	NaN	NaN
207.999897	0.001710	17.097642	0.095383	1008.133545	0.000000	NaN	NaN
208.999954	0.001710	17.097642	0.095843	1008.556824	0.000000	NaN	NaN
210.000011	0.001644	16.437417	0.096430	1009.097168	0.000000	NaN	NaN
211.000069	0.001776	17.757867	0.096864	1009.495911	0.000000	NaN	NaN
212.000126	0.001710	17.097642	0.097345	1009.939392	0.000000	NaN	NaN
213.000183	0.001776	17.757867	0.097840	1010.394470	0.000000	NaN	NaN
214.000240	0.001594	15.942248	0.098425	1010.932922	0.000000	NaN	NaN
215.000297	0.001611	16.107304	0.098945	1011.411682	0.000000	NaN	NaN
215.999355	0.001644	16.437417	0.099384	1011.816040	0.000000	NaN	NaN
216.999412	0.001702	17.015114	0.099922	1012.310852	0.000000	NaN	NaN
217.999469	0.001735	17.345226	0.100346	1012.701111	0.000000	NaN	NaN
218.999526	0.001635	16.354889	0.100842	1013.157104	0.000000	NaN	NaN
219.999583	0.001982	19.821070	0.101348	1013.622925	0.000000	NaN	NaN
220.999640	0.001677	16.767529	0.101848	1014.083008	0.000000	NaN	NaN
221.999698	0.001693	16.932585	0.102387	1014.579102	0.000000	NaN	NaN
222.999755	0.001660	16.602473	0.102833	1014.989624	0.000000	NaN	NaN
223.999812	0.001801	18.005451	0.103313	1015.431763	0.000000	NaN	NaN
224.999869	0.001751	17.510282	0.103832	1015.909424	0.000000	NaN	NaN
225.999926	0.001710	17.097642	0.104337	1016.373779	0.000000	NaN	NaN
226.999984	0.001652	16.519945	0.104920	1016.910706	0.000000	NaN	NaN
228.000041	0.001776	17.757867	0.105298	1017.258362	0.000000	NaN	NaN
229.000098	0.001759	17.592810	0.105832	1017.750061	0.000000	NaN	NaN
230.000155	0.001726	17.262698	0.106365	1018.240967	0.000000	NaN	NaN
231.000213	0.001735	17.345226	0.106816	1018.655579	0.000000	NaN	NaN
232.000270	0.001710	17.097642	0.107365	1019.160706	0.000000	NaN	NaN
233.000327	0.001743	17.427754	0.107813	1019.573303	0.000000	NaN	NaN
233.999384	0.001784	17.840395	0.108370	1020.086243	0.000000	NaN	NaN
234.999441	0.001735	17.345226	0.108820	1020.499878	0.000000	NaN	NaN
235.999498	0.001867	18.665676	0.109329	1020.968506	0.000000	NaN	NaN
236.999556	0.001850	18.500620	0.109896	1021.490540	0.000000	NaN	NaN
237.999613	0.001784	17.840395	0.110454	1022.003662	0.000000	NaN	NaN
238.999670	0.001718	17.180170	0.110880	1022.396362	0.000000	NaN	NaN
239.999727	0.001743	17.427754	0.111363	1022.840881	0.000000	NaN	NaN
240.999784	0.001693	16.932585	0.111939	1023.370361	0.000000	NaN	NaN
241.999842	0.001867	18.665676	0.112412	1023.805725	0.000000	NaN	NaN
242.999899	0.001735	17.345226	0.112908	1024.262817	0.000000	NaN	NaN
243.999956	0.001834	18.335564	0.113376	1024.693481	0.000000	NaN	NaN
245.000013	0.001660	16.602473	0.113974	1025.243896	0.000000	NaN	NaN
246.000070	0.001751	17.510282	0.114509	1025.735962	0.000000	NaN	NaN
247.000128	0.001784	17.840395	0.114876	1026.073364	0.000000	NaN	NaN
248.000185	0.001718	17.180170	0.115427	1026.581055	0.000000	NaN	NaN
249.000242	0.001924	19.243373	0.115917	1027.031982	0.000000	NaN	NaN
250.000299	0.001776	17.757867	0.116446	1027.518921	0.000000	NaN	NaN
250.999356	0.001825	18.253035	0.116907	1027.942993	0.000000	NaN	NaN
251.999414	0.001817	18.170507	0.117430	1028.424683	0.000000	NaN	NaN
252.999471	0.001726	17.262698	0.117863	1028.822998	0.000000	NaN	NaN
253.999528	0.001809	18.087979	0.118465	1029.377075	0.000000	NaN	NaN
254.999585	0.001743	17.427754	0.119015	1029.882812	0.000000	NaN	NaN
255.999642	0.001735	17.345226	0.119386	1030.224121	0.000000	NaN	NaN
256.999700	0.001784	17.840395	0.119879	1030.678711	0.000000	NaN	NaN
257.999757	0.001710	17.097642	0.120423	1031.179199	0.000000	NaN	NaN
258.999814	0.001776	17.757867	0.120905	1031.622192	0.000000	NaN	NaN
259.999871	0.001702	17.015114	0.121408	1032.085693	0.000000	NaN	NaN
260.999928	0.001850	18.500620	0.121955	1032.588745	0.000000	NaN	NaN
261.999986	0.001784	17.840395	0.122479	1033.071167	0.000000	NaN	NaN
263.000043	0.001867	18.665676	0.122878	1033.438477	0.000000	NaN	NaN
264.000100	0.001825	18.253035	0.123391	1033.910645	0.000000	NaN	NaN
265.000157	0.001726	17.262698	0.123893	1034.372681	0.000000	NaN	NaN
266.000214	0.001718	17.180170	0.124342	1034.786011	0.000000	NaN	NaN
267.000272	0.001949	19.490957	0.124895	1035.294312	0.000000	NaN	NaN
267.999329	0.001792	17.922923	0.125315	1035.680908	0.000000	NaN	NaN
268.999386	0.001743	17.427754	0.125837	1036.161865	0.000000	NaN	NaN
269.999443	0.001776	17.757867	0.126306	1036.593506	0.000000	NaN	NaN
270.999500	0.001784	17.840395	0.126863	1037.105469	0.000000	NaN	NaN
271.999557	0.001825	18.253035	0.127360	1037.562866	0.000000	NaN	NaN
272.999615	0.001875	18.748204	0.127868	1038.031006	0.000000	NaN	NaN
273.999672	0.001743	17.427754	0.128416	1038.534912	0.000000	NaN	NaN
274.999729	0.001941	19.408429	0.128837	1038.922485	0.000000	NaN	NaN
275.999786	0.001949	19.490957	0.129395	1039.436035	0.000000	NaN	NaN
276.999843	0.001751	17.510282	0.129795	1039.804321	0.000000	NaN	NaN
277.999901	0.001891	18.913260	0.130391	1040.352539	0.000000	NaN	NaN
278.999958	0.001735	17.345226	0.130916	1040.836304	0.000000	NaN	NaN
280.000015	0.001933	19.325901	0.131253	1041.146240	0.000000	NaN	NaN
281.000072	0.001809	18.087979	0.131855	1041.700439	0.000000	NaN	NaN
282.000130	0.001726	17.262698	0.132340	1042.146606	0.000000	NaN	NaN
283.000187	0.001792	17.922923	0.132886	1042.648804	0.000000	NaN	NaN
284.000244	0.001850	18.500620	0.133508	1043.221436	0.000000	NaN	NaN
285.000301	0.001801	18.005451	0.133904	1043.586304	0.000000	NaN	NaN
285.999358	0.001908	19.078317	0.134398	1044.040527	0.000000	NaN	NaN
286.999415	0.001809	18.087979	0.135015	1044.608887	0.000000	NaN	NaN
287.999473	0.001875	18.748204	0.135434	1044.994629	0.000000	NaN	NaN
288.999530	0.001776	17.757867	0.135976	1045.493408	0.000000	NaN	NaN
289.999587	0.001982	19.821070	0.136477	1045.954346	0.000000	NaN	NaN
290.999644	0.001817	18.170507	0.136948	1046.387817	0.000000	NaN	NaN
291.999702	0.001990	19.903598	0.137444	1046.843750	0.000000	NaN	NaN
292.999759	0.001817	18.170507	0.137876	1047.241699	0.000000	NaN	NaN
293.999816	0.001941	19.408429	0.138339	1047.668091	0.000000	NaN	NaN
294.999873	0.002048	20.481295	0.138859	1048.145996	0.000000	NaN	NaN
295.999930	0.001809	18.087979	0.139537	1048.770020	0.000000	NaN	NaN
296.999987	0.001768	17.675339	0.140063	1049.254883	0.000000	NaN	NaN
298.000045	0.001743	17.427754	0.140535	1049.688965	0.000000	NaN	NaN
299.000102	0.001891	18.913260	0.141048	1050.161011	0.000000	NaN	NaN
300.000159	0.001858	18.583148	0.141564	1050.635986	0.000000	NaN	NaN
301.000216	0.001776	17.757867	0.142136	1051.162476	0.000000	NaN	NaN
302.000273	0.001875	18.748204	0.142510	1051.506226	0.000000	NaN	NaN
302.999331	0.001891	18.913260	0.143053	1052.006714	0.000000	NaN	NaN
303.999388	0.001891	18.913260	0.143536	1052.451172	0.000000	NaN	NaN
304.999445	0.001792	17.922923	0.144056	1052.929687	0.000000	NaN	NaN
305.999502	0.001957	19.573485	0.144510	1053.347412	0.000000	NaN	NaN
306.999559	0.001924	19.243373	0.145087	1053.878418	0.000000	NaN	NaN
307.999617	0.001875	18.748204	0.145594	1054.344604	0.000000	NaN	NaN
308.999674	0.001957	19.573485	0.146160	1054.865479	0.000000	NaN	NaN
309.999731	0.001974	19.738542	0.146674	1055.338501	0.000000	NaN	NaN
310.999788	0.001817	18.170507	0.147200	1055.823120	0.000000	NaN	NaN
311.999845	0.001809	18.087979	0.147745	1056.324951	0.000000	NaN	NaN
312.999903	0.001949	19.490957	0.148141	1056.689453	0.000000	NaN	NaN
313.999960	0.001900	18.995789	0.148635	1057.143677	0.000000	NaN	NaN
315.000017	0.001776	17.757867	0.149225	1057.686646	0.000000	NaN	NaN
316.000074	0.001842	18.418092	0.149127	1057.596924	0.000000	NaN	NaN
317.000131	0.001858	18.583148	0.149408	1057.855469	0.000000	NaN	NaN
318.000189	0.001834	18.335564	0.150218	1058.601074	0.000000	NaN	NaN
319.000246	0.001990	19.903598	0.150779	1059.117310	0.000000	NaN	NaN
320.000303	0.001982	19.821070	0.151275	1059.573120	0.000000	NaN	NaN
320.999360	0.001900	18.995789	0.151739	1060.000977	0.000000	NaN	NaN
321.999417	0.001908	19.078317	0.152235	1060.456665	0.000000	NaN	NaN
322.999475	0.001801	18.005451	0.152817	1060.993042	0.000000	NaN	NaN
323.999532	0.002023	20.233710	0.153387	1061.516968	0.000000	NaN	NaN
324.999589	0.001908	19.078317	0.153735	1061.837524	0.000000	NaN	NaN
325.999646	0.001916	19.160845	0.154256	1062.316772	0.000000	NaN	NaN
326.999703	0.002056	20.563823	0.154748	1062.769531	0.000000	NaN	NaN
327.999761	0.002023	20.233710	0.155347	1063.321167	0.000000	NaN	NaN
328.999818	0.002032	20.316239	0.155853	1063.787109	0.000000	NaN	NaN
329.999875	0.002015	20.151182	0.156223	1064.127563	0.000000	NaN	NaN
330.999932	0.002040	20.398767	0.156841	1064.696167	0.000000	NaN	NaN
331.999989	0.001941	19.408429	0.157285	1065.104736	0.000000	NaN	NaN
333.000047	0.001858	18.583148	0.157740	1065.523437	0.000000	NaN	NaN
334.000104	0.001924	19.243373	0.158281	1066.021240	0.000000	NaN	NaN
335.000161	0.001949	19.490957	0.158778	1066.478882	0.000000	NaN	NaN
336.000218	0.001900	18.995789	0.159346	1067.001709	0.000000	NaN	NaN
337.000275	0.001858	18.583148	0.159719	1067.345337	0.000000	NaN	NaN
337.999332	0.001825	18.253035	0.160240	1067.824341	0.000000	NaN	NaN
338.999390	0.001900	18.995789	0.160832	1068.368774	0.000000	NaN	NaN
339.999447	0.001999	19.986126	0.161248	1068.752441	0.000000	NaN	NaN
340.999504	0.001842	18.418092	0.161823	1069.281128	0.000000	NaN	NaN
341.999561	0.001933	19.325901	0.162217	1069.643799	0.000000	NaN	NaN
342.999618	0.001966	19.656014	0.162766	1070.149170	0.000000	NaN	NaN
343.999676	0.002106	21.058992	0.163363	1070.698730	0.000000	NaN	NaN
344.999733	0.001875	18.748204	0.163736	1071.042236	0.000000	NaN	NaN
345.999790	0.001957	19.573485	0.164154	1071.426880	0.000000	NaN	NaN
346.999847	0.001966	19.656014	0.164733	1071.959717	0.000000	NaN	NaN
347.999905	0.001974	19.738542	0.165205	1072.394287	0.000000	NaN	NaN
348.999962	0.002023	20.233710	0.165660	1072.812256	0.000000	NaN	NaN
350.000019	0.001891	18.913260	0.166183	1073.294434	0.000000	NaN	NaN
351.000076	0.001974	19.738542	0.166832	1073.891235	0.000000	NaN	NaN
352.000133	0.001867	18.665676	0.167307	1074.328613	0.000000	NaN	NaN
353.000190	0.001949	19.490957	0.167692	1074.682983	0.000000	NaN	NaN
354.000248	0.002048	20.481295	0.168245	1075.191895	0.000000	NaN	NaN
355.000305	0.001974	19.738542	0.168732	1075.639526	0.000000	NaN	NaN
355.999362	0.001974	19.738542	0.169324	1076.184814	0.000000	NaN	NaN
356.999419	0.001858	18.583148	0.169771	1076.595825	0.000000	NaN	NaN
357.999476	0.001924	19.243373	0.170310	1077.092407	0.000000	NaN	NaN
358.999534	0.002015	20.151182	0.170740	1077.487793	0.000000	NaN	NaN
359.999591	0.001941	19.408429	0.171284	1077.988647	0.000000	NaN	NaN
360.999648	0.001990	19.903598	0.171746	1078.413696	0.000000	NaN	NaN
361.999705	0.002023	20.233710	0.172262	1078.888794	0.000000	NaN	NaN
362.999762	0.001817	18.170507	0.172721	1079.310791	0.000000	NaN	NaN
363.999820	0.002032	20.316239	0.173347	1079.887085	0.000000	NaN	NaN
364.999877	0.001957	19.573485	0.173694	1080.206909	0.000000	NaN	NaN
365.999934	0.001974	19.738542	0.174305	1080.769043	0.000000	NaN	NaN
366.999991	0.001825	18.253035	0.174771	1081.197754	0.000000	NaN	NaN
368.000048	0.001974	19.738542	0.175256	1081.643921	0.000000	NaN	NaN
369.000106	0.001867	18.665676	0.175773	1082.120239	0.000000	NaN	NaN
370.000163	0.002040	20.398767	0.176299	1082.604126	0.000000	NaN	NaN
371.000220	0.001982	19.821070	0.176937	1083.191895	0.000000	NaN	NaN
372.000277	0.002056	20.563823	0.177315	1083.539673	0.000000	NaN	NaN
372.999334	0.001999	19.986126	0.177735	1083.926025	0.000000	NaN	NaN
373.999392	0.001875	18.748204	0.178240	1084.390991	0.000000	NaN	NaN
374.999449	0.002032	20.316239	0.178733	1084.844116	0.000000	NaN	NaN
375.999506	0.002032	20.316239	0.179233	1085.304687	0.000000	NaN	NaN
376.999563	0.002098	20.976463	0.179699	1085.733643	0.000000	NaN	NaN
377.999620	0.001924	19.243373	0.180186	1086.182007	0.000000	NaN	NaN
378.999678	0.001990	19.903598	0.180609	1086.571045	0.000000	NaN	NaN
379.999735	0.001957	19.573485	0.181198	1087.112549	0.000000	NaN	NaN
380.999792	0.001916	19.160845	0.181746	1087.617310	0.000000	NaN	NaN
381.999849	0.001924	19.243373	0.182183	1088.019165	0.000000	NaN	NaN
382.999906	0.002007	20.068654	0.182658	1088.457153	0.000000	NaN	NaN
383.999964	0.002023	20.233710	0.183254	1089.005005	0.000000	NaN	NaN
385.000021	0.001999	19.986126	0.183737	1089.450195	0.000000	NaN	NaN
386.000078	0.002056	20.563823	0.184271	1089.941650	0.000000	NaN	NaN
387.000135	0.002122	21.224048	0.184763	1090.393921	0.000000	NaN	NaN
388.000192	0.001924	19.243373	0.185155	1090.754883	0.000000	NaN	NaN
389.000250	0.001990	19.903598	0.185720	1091.274658	0.000000	NaN	NaN
390.000307	0.001966	19.656014	0.186167	1091.686401	0.000000	NaN	NaN
390.999364	0.001974	19.738542	0.186721	1092.196167	0.000000	NaN	NaN
391.999421	0.002065	20.646351	0.187249	1092.681763	0.000000	NaN	NaN
392.999478	0.001924	19.243373	0.187711	1093.106934	0.000000	NaN	NaN
393.999535	0.002056	20.563823	0.188228	1093.582642	0.000000	NaN	NaN
394.999593	0.002106	21.058992	0.188773	1094.084351	0.000000	NaN	NaN
395.999650	0.002023	20.233710	0.189165	1094.445435	0.000000	NaN	NaN
396.999707	0.002048	20.481295	0.189634	1094.877197	0.000000	NaN	NaN
397.999764	0.002015	20.151182	0.190081	1095.288696	0.000000	NaN	NaN
398.999821	0.001966	19.656014	0.190623	1095.787720	0.000000	NaN	NaN
399.999879	0.002032	20.316239	0.191128	1096.252075	0.000000	NaN	NaN
400.999936	0.001974	19.738542	0.191531	1096.623047	0.000000	NaN	NaN
401.999993	0.001941	19.408429	0.192114	1097.159790	0.000000	NaN	NaN
403.000050	0.002015	20.151182	0.192572	1097.581055	0.000000	NaN	NaN
404.000108	0.001966	19.656014	0.193031	1098.003418	0.000000	NaN	NaN
405.000165	0.002098	20.976463	0.193441	1098.381104	0.000000	NaN	NaN
406.000222	0.001941	19.408429	0.193997	1098.892334	0.000000	NaN	NaN
407.000279	0.002081	20.811407	0.194552	1099.403442	0.000000	NaN	NaN
407.999336	0.001916	19.160845	0.194956	1099.775024	0.000000	NaN	NaN
408.999393	0.001933	19.325901	0.195463	1100.241699	0.000000	NaN	NaN
409.999451	0.002048	20.481295	0.195916	1100.658813	0.000000	NaN	NaN
410.999508	0.001933	19.325901	0.196458	1101.157349	0.000000	NaN	NaN
411.999565	0.002015	20.151182	0.196909	1101.572876	0.000000	NaN	NaN
412.999622	0.001974	19.738542	0.197284	1101.917969	0.000000	NaN	NaN
413.999680	0.002065	20.646351	0.197757	1102.353516	0.000000	NaN	NaN
414.999737	0.001883	18.830732	0.198312	1102.863647	0.000000	NaN	NaN
415.999794	0.001949	19.490957	0.198712	1103.231567	0.000000	NaN	NaN
416.999851	0.001982	19.821070	0.199259	1103.734985	0.000000	NaN	NaN
417.999908	0.002098	20.976463	0.199737	1104.175171	0.000000	NaN	NaN
418.999965	0.002015	20.151182	0.200154	1104.559082	0.000000	NaN	NaN
420.000023	0.002065	20.646351	0.200647	1105.012573	0.000000	NaN	NaN
421.000080	0.002007	20.068654	0.201187	1105.510132	0.000000	NaN	NaN
422.000137	0.002106	21.058992	0.201784	1106.059204	0.000000	NaN	NaN
423.000194	0.002081	20.811407	0.202135	1106.381958	0.000000	NaN	NaN
424.000251	0.001933	19.325901	0.202564	1106.776978	0.000000	NaN	NaN
425.000309	0.002015	20.151182	0.203137	1107.304932	0.000000	NaN	NaN
425.999366	0.002048	20.481295	0.203571	1107.704102	0.000000	NaN	NaN
426.999423	0.002139	21.389104	0.204060	1108.154053	0.000000	NaN	NaN
427.999480	0.001966	19.656014	0.204474	1108.535034	0.000000	NaN	NaN
428.999537	0.001924	19.243373	0.204962	1108.984009	0.000000	NaN	NaN
429.999595	0.002015	20.151182	0.205496	1109.475830	0.000000	NaN	NaN
430.999652	0.002098	20.976463	0.205953	1109.896240	0.000000	NaN	NaN
431.999709	0.002015	20.151182	0.206517	1110.415527	0.000000	NaN	NaN
432.999766	0.001891	18.913260	0.207103	1110.954590	0.000000	NaN	NaN
433.999823	0.001933	19.325901	0.207367	1111.197510	0.000000	NaN	NaN
434.999881	0.002081	20.811407	0.207968	1111.750610	0.000000	NaN	NaN
435.999938	0.002032	20.316239	0.208521	1112.260132	0.000000	NaN	NaN
436.999995	0.002081	20.811407	0.208939	1112.644409	0.000000	NaN	NaN
438.000052	0.001999	19.986126	0.209331	1113.005249	0.000000	NaN	NaN
439.000109	0.002040	20.398767	0.209876	1113.506836	0.000000	NaN	NaN
440.000167	0.002164	21.636688	0.210414	1114.001587	0.000000	NaN	NaN
441.000224	0.002023	20.233710	0.210966	1114.510010	0.000000	NaN	NaN
442.000281	0.001825	18.253035	0.211336	1114.850830	0.000000	NaN	NaN
442.999338	0.002098	20.976463	0.211882	1115.352783	0.000000	NaN	NaN
443.999395	0.002139	21.389104	0.212268	1115.708252	0.000000	NaN	NaN
444.999453	0.002065	20.646351	0.212894	1116.284790	0.000000	NaN	NaN
445.999510	0.002040	20.398767	0.213365	1116.718262	0.000000	NaN	NaN
446.999567	0.002040	20.398767	0.213932	1117.239380	0.000000	NaN	NaN
447.999624	0.001949	19.490957	0.214301	1117.578979	0.000000	NaN	NaN
448.999681	0.002106	21.058992	0.214830	1118.066528	0.000000	NaN	NaN
449.999739	0.002056	20.563823	0.215292	1118.491699	0.000000	NaN	NaN
450.999796	0.002056	20.563823	0.215665	1118.834717	0.000000	NaN	NaN
451.999853	0.001966	19.656014	0.216256	1119.378296	0.000000	NaN	NaN
452.999910	0.002073	20.728879	0.216719	1119.804810	0.000000	NaN	NaN
453.999967	0.001990	19.903598	0.217207	1120.254028	0.000000	NaN	NaN
455.000025	0.002007	20.068654	0.217757	1120.760010	0.000000	NaN	NaN
456.000082	0.002032	20.316239	0.218186	1121.154663	0.000000	NaN	NaN
457.000139	0.002073	20.728879	0.218639	1121.571533	0.000000	NaN	NaN
458.000196	0.002089	20.893935	0.219200	1122.087769	0.000000	NaN	NaN
459.000253	0.002073	20.728879	0.219604	1122.459961	0.000000	NaN	NaN
460.000311	0.002056	20.563823	0.220134	1122.947632	0.000000	NaN	NaN
460.999368	0.002023	20.233710	0.220596	1123.373047	0.000000	NaN	NaN
461.999425	0.002073	20.728879	0.221108	1123.843872	0.000000	NaN	NaN
462.999482	0.002155	21.554160	0.221588	1124.285889	0.000000	NaN	NaN
463.999539	0.002089	20.893935	0.222123	1124.778198	0.000000	NaN	NaN
464.999596	0.002007	20.068654	0.222692	1125.302368	0.000000	NaN	NaN
465.999654	0.001941	19.408429	0.223103	1125.680542	0.000000	NaN	NaN
466.999711	0.002081	20.811407	0.223572	1126.112061	0.000000	NaN	NaN
467.999768	0.002106	21.058992	0.224110	1126.606812	0.000000	NaN	NaN
468.999825	0.001999	19.986126	0.224493	1126.959473	0.000000	NaN	NaN
469.999883	0.002114	21.141520	0.225084	1127.503418	0.000000	NaN	NaN
470.999940	0.002122	21.224048	0.225555	1127.937134	0.000000	NaN	NaN
471.999997	0.002065	20.646351	0.226171	1128.503418	0.000000	NaN	NaN
473.000054	0.002073	20.728879	0.226684	1128.975708	0.000000	NaN	NaN
474.000111	0.002089	20.893935	0.227276	1129.520508	0.000000	NaN	NaN
475.000168	0.002015	20.151182	0.227676	1129.888794	0.000000	NaN	NaN
476.000226	0.002048	20.481295	0.228188	1130.359741	0.000000	NaN	NaN
477.000283	0.002081	20.811407	0.228691	1130.823486	0.000000	NaN	NaN
477.999340	0.002098	20.976463	0.229252	1131.339478	0.000000	NaN	NaN
478.999397	0.002122	21.224048	0.229684	1131.737305	0.000000	NaN	NaN
479.999454	0.002065	20.646351	0.230156	1132.171387	0.000000	NaN	NaN
480.999512	0.002015	20.151182	0.230515	1132.501831	0.000000	NaN	NaN
481.999569	0.002081	20.811407	0.231232	1133.161987	0.000000	NaN	NaN
482.999626	0.002122	21.224048	0.231740	1133.628906	0.000000	NaN	NaN
483.999683	0.002015	20.151182	0.232317	1134.160522	0.000000	NaN	NaN
484.999740	0.002023	20.233710	0.232738	1134.547363	0.000000	NaN	NaN
485.999798	0.002122	21.224048	0.233441	1135.194824	0.000000	NaN	NaN
486.999855	0.002023	20.233710	0.233893	1135.610352	0.000000	NaN	NaN
487.999912	0.002106	21.058992	0.234232	1135.922607	0.000000	NaN	NaN
488.999969	0.002172	21.719217	0.234930	1136.565430	0.000000	NaN	NaN
490.000026	0.002048	20.481295	0.235354	1136.955811	0.000000	NaN	NaN
491.000084	0.002213	22.131857	0.235953	1137.506348	0.000000	NaN	NaN
492.000141	0.002007	20.068654	0.236447	1137.961792	0.000000	NaN	NaN
493.000198	0.002040	20.398767	0.236887	1138.365967	0.000000	NaN	NaN
494.000255	0.002048	20.481295	0.237475	1138.907227	0.000000	NaN	NaN
495.000312	0.001941	19.408429	0.237931	1139.327026	0.000000	NaN	NaN
495.999370	0.002032	20.316239	0.238432	1139.788330	0.000000	NaN	NaN
496.999427	0.002147	21.471632	0.239002	1140.312500	0.000000	NaN	NaN
497.999484	0.002081	20.811407	0.239547	1140.814453	0.000000	NaN	NaN
498.999541	0.002147	21.471632	0.240041	1141.268921	0.000000	NaN	NaN
499.999598	0.002048	20.481295	0.240696	1141.871948	0.000000	NaN	NaN
500.999656	0.002180	21.801745	0.241271	1142.400757	0.000000	NaN	NaN
501.999713	0.001966	19.656014	0.241763	1142.854370	0.000000	NaN	NaN
502.999770	0.002089	20.893935	0.242256	1143.307617	0.000000	NaN	NaN
503.999827	0.002147	21.471632	0.242990	1143.982788	0.000000	NaN	NaN
504.999884	0.002122	21.224048	0.243623	1144.565796	0.000000	NaN	NaN
505.999942	0.002073	20.728879	0.244116	1145.019409	0.000000	NaN	NaN
506.999999	0.002023	20.233710	0.244735	1145.589478	0.000000	NaN	NaN
508.000056	0.002139	21.389104	0.245296	1146.105713	0.000000	NaN	NaN
509.000113	0.001974	19.738542	0.246046	1146.795410	0.000000	NaN	NaN
510.000170	0.002098	20.976463	0.246899	1147.580811	0.000000	NaN	NaN
511.000228	0.001883	18.830732	0.248457	1149.014526	0.000000	NaN	NaN
512.000285	0.001990	19.903598	0.249319	1149.808472	0.000000	NaN	NaN
512.999342	0.002139	21.389104	0.250151	1150.573486	0.000000	NaN	NaN
513.999399	0.002089	20.893935	0.251133	1151.477661	0.000000	NaN	NaN
514.999456	0.002007	20.068654	0.251890	1152.174072	0.000000	NaN	NaN
515.999514	0.002048	20.481295	0.252725	1152.942383	0.000000	NaN	NaN
516.999571	0.002089	20.893935	0.253537	1153.689697	0.000000	NaN	NaN
517.999628	0.001941	19.408429	0.254420	1154.502441	0.000000	NaN	NaN
518.999685	0.002015	20.151182	0.255251	1155.267822	0.000000	NaN	NaN
519.999742	0.001990	19.903598	0.256013	1155.968506	0.000000	NaN	NaN
520.999799	0.001809	18.087979	0.256781	1156.675659	0.000000	NaN	NaN
521.999857	0.002122	21.224048	0.257637	1157.463501	0.000000	NaN	NaN
522.999914	0.002122	21.224048	0.258487	1158.245728	0.000000	NaN	NaN
523.999971	0.002073	20.728879	0.259222	1158.922363	0.000000	NaN	NaN
525.000028	0.002040	20.398767	0.260144	1159.770630	0.000000	NaN	NaN
526.000085	0.001990	19.903598	0.260907	1160.472656	0.000000	NaN	NaN
527.000143	0.001999	19.986126	0.261700	1161.203247	0.000000	NaN	NaN
528.000200	0.002032	20.316239	0.262474	1161.915039	0.000000	NaN	NaN
529.000257	0.002081	20.811407	0.263347	1162.718628	0.000000	NaN	NaN
530.000314	0.002032	20.316239	0.264138	1163.446289	0.000000	NaN	NaN
530.999372	0.002007	20.068654	0.264959	1164.202148	0.000000	NaN	NaN
531.999429	0.002040	20.398767	0.265619	1164.809448	0.000000	NaN	NaN
532.999486	0.002032	20.316239	0.266709	1165.813354	0.000000	NaN	NaN
533.999543	0.001966	19.656014	0.267523	1166.562012	0.000000	NaN	NaN
534.999600	0.002065	20.646351	0.268318	1167.294067	0.000000	NaN	NaN
535.999658	0.001850	18.500620	0.269280	1168.178955	0.000000	NaN	NaN
536.999715	0.001990	19.903598	0.270405	1169.214844	0.000000	NaN	NaN
537.999772	0.002023	20.233710	0.271212	1169.956787	0.000000	NaN	NaN
538.999829	0.001966	19.656014	0.272103	1170.777222	0.000000	NaN	NaN
539.999886	0.001933	19.325901	0.272933	1171.541626	0.000000	NaN	NaN
540.999943	0.001982	19.821070	0.273769	1172.310547	0.000000	NaN	NaN
542.000001	0.001933	19.325901	0.274876	1173.329224	0.000000	NaN	NaN
543.000058	0.001982	19.821070	0.275860	1174.234741	0.000000	NaN	NaN
544.000115	0.001933	19.325901	0.276770	1175.072021	0.000000	NaN	NaN
545.000172	0.002081	20.811407	0.277576	1175.814087	0.000000	NaN	NaN
546.000230	0.001974	19.738542	0.278590	1176.747681	0.000000	NaN	NaN
547.000287	0.001949	19.490957	0.279719	1177.786621	0.000000	NaN	NaN
547.999344	0.001891	18.913260	0.280924	1178.895386	0.000000	NaN	NaN
548.999401	0.001966	19.656014	0.282023	1179.906860	0.000000	NaN	NaN
549.999458	0.001850	18.500620	0.283369	1181.145508	0.000000	NaN	NaN
550.999515	0.001990	19.903598	0.284417	1182.110474	0.000000	NaN	NaN
551.999573	0.001867	18.665676	0.285549	1183.152100	0.000000	NaN	NaN
552.999630	0.001792	17.922923	0.286643	1184.158813	0.000000	NaN	NaN
553.999687	0.001817	18.170507	0.287741	1185.169800	0.000000	NaN	NaN
554.999744	0.001900	18.995789	0.288880	1186.217529	0.000000	NaN	NaN
555.999801	0.001759	17.592810	0.290054	1187.298096	0.000000	NaN	NaN
556.999859	0.001784	17.840395	0.291306	1188.451172	0.000000	NaN	NaN
557.999916	0.001718	17.180170	0.292488	1189.538330	0.000000	NaN	NaN
558.999973	0.001660	16.602473	0.293594	1190.556152	0.000000	NaN	NaN
560.000030	0.001702	17.015114	0.294893	1191.751709	0.000000	NaN	NaN
561.000087	0.001768	17.675339	0.296203	1192.957886	0.000000	NaN	NaN
562.000145	0.001759	17.592810	0.297300	1193.967285	0.000000	NaN	NaN
563.000202	0.001685	16.850057	0.298541	1195.109253	0.000000	NaN	NaN
564.000259	0.001834	18.335564	0.299782	1196.251709	0.000000	NaN	NaN
565.000316	0.001825	18.253035	0.301493	1197.826050	0.000000	NaN	NaN
565.999373	0.001635	16.354889	0.303041	1199.250977	0.000000	NaN	NaN
566.999431	0.001602	16.024776	0.304181	1200.299927	0.000000	NaN	NaN
567.999488	0.001660	16.602473	0.305712	1201.708740	0.000000	NaN	NaN
568.999545	0.001635	16.354889	0.307087	1202.974487	0.000000	NaN	NaN
569.999602	0.001569	15.694663	0.308879	1204.624023	0.000000	NaN	NaN
570.999659	0.001454	14.539270	0.310252	1205.887939	0.000000	NaN	NaN
571.999717	0.001520	15.199495	0.311909	1207.412842	0.000000	NaN	NaN
572.999774	0.001470	14.704326	0.313481	1208.859497	0.000000	NaN	NaN
573.999831	0.001503	15.034438	0.315609	1210.817627	0.000000	NaN	NaN
574.999888	0.001404	14.044101	0.317201	1212.283447	0.000000	NaN	NaN
575.999945	0.001371	13.713988	0.318911	1213.856812	0.000000	NaN	NaN
577.000003	0.001281	12.806179	0.320993	1215.773071	0.000000	NaN	NaN
578.000060	0.001289	12.888707	0.322734	1217.375854	0.000000	NaN	NaN
579.000117	0.001140	11.403201	0.325167	1219.614624	0.000000	NaN	NaN
580.000174	0.001074	10.742976	0.327212	1221.496948	0.000000	NaN	NaN
581.000231	0.001149	11.485729	0.331531	1225.472046	0.000000	NaN	NaN
582.000289	0.000827	8.267132	0.334994	1228.658691	0.000000	NaN	NaN
582.999346	0.000843	8.432188	-0.538959	424.318176	0.000000	NaN	NaN
583.999403	0.000876	8.762301	-0.537417	425.737549	0.000000	NaN	NaN
584.999460	0.000777	7.771963	0.343092	1236.112061	0.000000	NaN	NaN
585.999517	0.000620	6.203929	0.345125	1237.982788	0.000000	NaN	NaN
586.999574	0.000711	7.111738	0.346982	1239.692017	0.000000	NaN	NaN
587.999632	0.000563	5.626232	0.349529	1242.036011	0.000000	NaN	NaN
588.999689	0.000431	4.305782	-0.531605	431.086639	0.000000	NaN	NaN
589.999746	0.000571	5.708760	-0.527964	434.437561	0.000000	NaN	NaN
590.999803	0.000596	5.956345	-0.526547	435.741821	0.000000	NaN	NaN
591.999860	0.000488	4.883479	-0.527421	434.936646	0.000000	NaN	NaN
592.999918	0.000348	3.480501	-0.524637	437.499786	0.000000	NaN	NaN
593.999975	0.000662	6.616570	0.267162	1166.230103	0.000000	NaN	NaN