File: data/57k_1-10_3 (190320).lvm
LabVIEW Measurement
Writer_Version	2
Reader_Version	2
Separator	Tab
Decimal_Separator	.
Multi_Headings	No
X_Columns	One
Time_Pref	Absolute
Operator	user
Description	Load(N)/Stress(MPa)/Distance A(pixel)/Strain A/Distance B(pixel)/Strain B/Poisson's ratio
Date	2019/03/20
Time	14:28:44.3019042015075683594
***End_of_Header***

Notes	X 값은 오직 다음과 같을 때에만 유효함이 보장됩니다. Dev1/ai0
Channels	7
Samples	1	1	1	1	1	1	1
Date	2019/03/20	2019/03/20	2019/03/20	2019/03/20	2019/03/20	2019/03/20	2019/03/20
Time	14:28:44.3019043300349967071	14:28:44.3019043300349967071	14:28:44.3019042015075683594	14:28:44.3019042015075683594	14:28:44.3019042015075683594	14:28:44.3019042015075683594	14:28:44.3019042015075683594
Y_Unit_Label	Volts	Volts
X_Dimension	Time	Time	Time	Time	Time	Time	Time
X0	0.0000000000000000E+0	0.0000000000000000E+0	0.0000000000000000E+0	0.0000000000000000E+0	0.0000000000000000E+0	0.0000000000000000E+0	0.0000000000000000E+0
Delta_X	0.000000	0.000000	1.000000	1.000000	1.000000	1.000000	1.000000
***End_of_Header***
X_Value	Dev1/ai0	Dev1/ai0 1	Untitled	Untitled 1	Untitled 2	Untitled 3	Untitled 4	Comment
0.000000	-0.000213	-2.131412	-9.948015E-5	984.527222	0.000000	NaN	NaN
0.500029	-0.000131	-1.306131	0.000347	984.966919	0.000000	NaN	NaN
1.000057	-3.157930E-5	-0.315793	0.000588	985.203918	0.000000	NaN	NaN
1.500086	-0.000271	-2.709109	0.000548	985.164978	0.000000	NaN	NaN
2.000114	-7.284337E-5	-0.728434	0.000970	985.580017	0.000000	NaN	NaN
2.500143	-0.000106	-1.058546	0.001171	985.778137	0.000000	NaN	NaN
3.000172	-8.109618E-5	-0.810962	0.001248	985.854309	0.000000	NaN	NaN
3.500200	-3.983212E-5	-0.398321	0.001546	986.147156	0.000000	NaN	NaN
4.000229	9.684761E-6	0.096848	0.001752	986.350464	0.000000	NaN	NaN
4.500257	-8.934899E-5	-0.893490	0.001614	986.214111	0.000000	NaN	NaN
5.000286	4.269601E-5	0.426960	0.001927	986.522766	0.000000	NaN	NaN
5.500315	5.920164E-5	0.592016	0.002478	987.064697	0.000000	NaN	NaN
6.000343	-5.633774E-5	-0.563377	0.002288	986.877747	0.000000	NaN	NaN
6.500372	-5.633774E-5	-0.563377	0.002454	987.041321	0.000000	NaN	NaN
7.000400	1.793757E-5	0.179376	0.002666	987.250000	0.000000	NaN	NaN
7.500429	0.000183	1.829938	0.002770	987.352722	0.000000	NaN	NaN
8.000458	4.269601E-5	0.426960	0.003149	987.725281	0.000000	NaN	NaN
8.500486	1.793757E-5	0.179376	0.002905	987.485779	0.000000	NaN	NaN
9.000515	0.000100	1.004657	0.003220	987.795959	0.000000	NaN	NaN
9.500543	1.431948E-6	0.014319	0.003440	988.012268	0.000000	NaN	NaN
10.000572	-1.507368E-5	-0.150737	0.003568	988.137878	0.000000	NaN	NaN
10.500601	1.431948E-6	0.014319	0.003035	987.613586	0.000000	NaN	NaN
11.000629	-3.983212E-5	-0.398321	0.003849	988.414551	0.000000	NaN	NaN
11.500658	6.745445E-5	0.674545	0.004050	988.613159	0.000000	NaN	NaN
12.000686	5.094882E-5	0.509488	0.004034	988.596985	0.000000	NaN	NaN
12.500715	-1.507368E-5	-0.150737	0.004456	989.013062	0.000000	NaN	NaN
13.000744	4.269601E-5	0.426960	0.004537	989.092468	0.000000	NaN	NaN
13.500772	-4.808493E-5	-0.480849	0.004608	989.162170	0.000000	NaN	NaN
14.000801	0.000100	1.004657	0.004944	989.493286	0.000000	NaN	NaN
14.500829	0.000117	1.169713	0.004812	989.362732	0.000000	NaN	NaN
15.000858	8.396008E-5	0.839601	0.004719	989.271790	0.000000	NaN	NaN
15.499886	-6.820864E-6	-0.068209	0.005042	989.590088	0.000000	NaN	NaN
15.999915	0.000100	1.004657	0.004888	989.438293	0.000000	NaN	NaN
16.499944	1.793757E-5	0.179376	0.004954	989.502563	0.000000	NaN	NaN
16.999972	0.000117	1.169713	0.005344	989.886658	0.000000	NaN	NaN
17.500001	4.269601E-5	0.426960	0.005351	989.894165	0.000000	NaN	NaN
18.000030	8.396008E-5	0.839601	0.005548	990.087891	0.000000	NaN	NaN
18.500058	2.619039E-5	0.261904	0.005574	990.113037	0.000000	NaN	NaN
19.000087	0.000100	1.004657	0.005708	990.245422	0.000000	NaN	NaN
19.500115	0.000166	1.664882	0.005834	990.369263	0.000000	NaN	NaN
20.000144	6.745445E-5	0.674545	0.005918	990.451721	0.000000	NaN	NaN
20.500172	1.431948E-6	0.014319	0.006440	990.965942	0.000000	NaN	NaN
21.000201	5.920164E-5	0.592016	0.006301	990.829224	0.000000	NaN	NaN
21.500230	0.000224	2.242579	0.006414	990.940369	0.000000	NaN	NaN
22.000258	3.444320E-5	0.344432	0.006407	990.934021	0.000000	NaN	NaN
22.500287	0.000216	2.160051	0.006831	991.350708	0.000000	NaN	NaN
23.000315	0.000133	1.334770	0.006901	991.419739	0.000000	NaN	NaN
23.500344	8.396008E-5	0.839601	0.006682	991.204712	0.000000	NaN	NaN
24.000373	0.000224	2.242579	0.007150	991.665161	0.000000	NaN	NaN
24.500401	0.000142	1.417298	0.007604	992.111755	0.000000	NaN	NaN
25.000430	0.000166	1.664882	0.007390	991.902100	0.000000	NaN	NaN
25.500458	0.000208	2.077523	0.007580	992.088562	0.000000	NaN	NaN
26.000487	8.396008E-5	0.839601	0.007747	992.252869	0.000000	NaN	NaN
26.500516	0.000266	2.655220	0.007608	992.115967	0.000000	NaN	NaN
27.000544	0.000100	1.004657	0.008089	992.589478	0.000000	NaN	NaN
27.500573	0.000216	2.160051	0.007685	992.191711	0.000000	NaN	NaN
28.000601	0.000183	1.829938	0.007297	991.810303	0.000000	NaN	NaN
28.500630	0.000233	2.325107	0.008283	992.780762	0.000000	NaN	NaN
29.000659	0.000274	2.737748	0.008363	992.859680	0.000000	NaN	NaN
29.500687	0.000224	2.242579	0.008056	992.557129	0.000000	NaN	NaN
30.000716	0.000224	2.242579	0.008135	992.634705	0.000000	NaN	NaN
30.500744	0.000241	2.407635	0.008835	993.324158	0.000000	NaN	NaN
31.000773	0.000208	2.077523	0.008347	992.843384	0.000000	NaN	NaN
31.500802	0.000183	1.829938	0.008625	993.117493	0.000000	NaN	NaN
32.000830	0.000257	2.572691	0.008811	993.301208	0.000000	NaN	NaN
32.500859	0.000233	2.325107	0.009013	993.499207	0.000000	NaN	NaN
32.999887	0.000307	3.067860	0.009542	994.020691	0.000000	NaN	NaN
33.499916	0.000431	4.305782	0.009522	994.000732	0.000000	NaN	NaN
33.999945	0.000348	3.480501	0.009561	994.039307	0.000000	NaN	NaN
34.499973	0.000233	2.325107	0.009664	994.140137	0.000000	NaN	NaN
35.000002	0.000224	2.242579	0.010161	994.629883	0.000000	NaN	NaN
35.500030	0.000274	2.737748	0.010418	994.883362	0.000000	NaN	NaN
36.000059	0.000191	1.912466	0.010218	994.686035	0.000000	NaN	NaN
36.500088	0.000224	2.242579	0.010343	994.809509	0.000000	NaN	NaN
37.000116	0.000282	2.820276	0.010506	994.969849	0.000000	NaN	NaN
37.500145	0.000224	2.242579	0.010732	995.192383	0.000000	NaN	NaN
38.000173	0.000290	2.902804	0.010811	995.270020	0.000000	NaN	NaN
38.500202	0.000241	2.407635	0.010849	995.307007	0.000000	NaN	NaN
39.000231	0.000398	3.975670	0.010893	995.350708	0.000000	NaN	NaN
39.500259	0.000406	4.058198	0.010973	995.429626	0.000000	NaN	NaN
40.000288	0.000315	3.150388	0.011366	995.816345	0.000000	NaN	NaN
40.500316	0.000389	3.893141	0.011557	996.004028	0.000000	NaN	NaN
41.000345	0.000274	2.737748	0.011753	996.197693	0.000000	NaN	NaN
41.500374	0.000381	3.810613	0.011763	996.207153	0.000000	NaN	NaN
42.000402	0.000389	3.893141	0.011201	995.654053	0.000000	NaN	NaN
42.500431	0.000348	3.480501	0.011862	996.305115	0.000000	NaN	NaN
43.000459	0.000282	2.820276	0.011675	996.120361	0.000000	NaN	NaN
43.500488	0.000447	4.470838	0.012719	997.148682	0.000000	NaN	NaN
44.000517	0.000348	3.480501	0.012499	996.932373	0.000000	NaN	NaN
44.500545	0.000340	3.397973	0.012766	997.194641	0.000000	NaN	NaN
45.000574	0.000356	3.563029	0.013089	997.512695	0.000000	NaN	NaN
45.500602	0.000389	3.893141	0.013259	997.680359	0.000000	NaN	NaN
46.000631	0.000365	3.645557	0.013029	997.454102	0.000000	NaN	NaN
46.500660	0.000323	3.232916	0.013373	997.792786	0.000000	NaN	NaN
47.000688	0.000191	1.912466	0.013686	998.100403	0.000000	NaN	NaN
47.500717	0.000455	4.553366	0.013399	997.818237	0.000000	NaN	NaN
48.000745	0.000348	3.480501	0.013856	998.268066	0.000000	NaN	NaN
48.500774	0.000389	3.893141	0.013910	998.321777	0.000000	NaN	NaN
49.000803	0.000373	3.728085	0.014056	998.465332	0.000000	NaN	NaN
49.500831	0.000307	3.067860	0.014122	998.530090	0.000000	NaN	NaN
50.000860	0.000257	2.572691	0.014327	998.731812	0.000000	NaN	NaN
50.499888	0.000447	4.470838	0.015029	999.423340	0.000000	NaN	NaN
50.999917	0.000439	4.388310	0.014894	999.290710	0.000000	NaN	NaN
51.499946	0.000348	3.480501	0.015280	999.670410	0.000000	NaN	NaN
51.999974	0.000431	4.305782	0.015383	999.771179	0.000000	NaN	NaN
52.500003	0.000546	5.461176	0.015654	1000.039001	0.000000	NaN	NaN
53.000031	0.000497	4.966007	0.015797	1000.179077	0.000000	NaN	NaN
53.500060	0.000439	4.388310	0.015908	1000.288269	0.000000	NaN	NaN
54.000089	0.000307	3.067860	0.016018	1000.397278	0.000000	NaN	NaN
54.500117	0.000538	5.378648	0.016346	1000.720032	0.000000	NaN	NaN
55.000146	0.000398	3.975670	0.016061	1000.439087	0.000000	NaN	NaN
55.500174	0.000431	4.305782	0.016861	1001.226929	0.000000	NaN	NaN
56.000203	0.000249	2.490163	0.016487	1000.858215	0.000000	NaN	NaN
56.500232	0.000464	4.635895	0.016529	1000.900452	0.000000	NaN	NaN
57.000260	0.000224	2.242579	0.017203	1001.563538	0.000000	NaN	NaN
57.500289	0.000373	3.728085	0.017330	1001.688599	0.000000	NaN	NaN
58.000317	0.000439	4.388310	0.017611	1001.965088	0.000000	NaN	NaN
58.500346	0.000488	4.883479	0.017567	1001.922424	0.000000	NaN	NaN
59.000375	0.000505	5.048535	0.017590	1001.944519	0.000000	NaN	NaN
59.500403	0.000398	3.975670	0.017934	1002.283691	0.000000	NaN	NaN
60.000432	0.000521	5.213591	0.018202	1002.547668	0.000000	NaN	NaN
60.500460	0.000414	4.140726	0.018808	1003.144470	0.000000	NaN	NaN
61.000489	0.000398	3.975670	0.018898	1003.233154	0.000000	NaN	NaN
61.500518	0.000472	4.718423	0.018835	1003.170959	0.000000	NaN	NaN
62.000546	0.000398	3.975670	0.019089	1003.420715	0.000000	NaN	NaN
62.500575	0.000530	5.296120	0.019326	1003.654419	0.000000	NaN	NaN
63.000603	0.000513	5.131063	0.019925	1004.244324	0.000000	NaN	NaN
63.500632	0.000505	5.048535	0.019821	1004.141357	0.000000	NaN	NaN
64.000661	0.000554	5.543704	0.020144	1004.459900	0.000000	NaN	NaN
64.500689	0.000365	3.645557	0.020059	1004.375854	0.000000	NaN	NaN
65.000718	0.000587	5.873817	0.020005	1004.322388	0.000000	NaN	NaN
65.500746	0.000571	5.708760	0.020328	1004.640320	0.000000	NaN	NaN
66.000775	0.000447	4.470838	0.020576	1004.884521	0.000000	NaN	NaN
66.500804	0.000373	3.728085	0.021326	1005.623230	0.000000	NaN	NaN
67.000832	0.000431	4.305782	0.021241	1005.539490	0.000000	NaN	NaN
67.500861	0.000480	4.800951	0.021597	1005.890137	0.000000	NaN	NaN
67.999889	0.000505	5.048535	0.021039	1005.340210	0.000000	NaN	NaN
68.499918	0.000299	2.985332	0.021438	1005.733459	0.000000	NaN	NaN
68.999946	0.000447	4.470838	0.021845	1006.134705	0.000000	NaN	NaN
69.499975	0.000439	4.388310	0.021684	1005.975464	0.000000	NaN	NaN
70.000004	0.000554	5.543704	0.022592	1006.869690	0.000000	NaN	NaN
70.500032	0.000431	4.305782	0.022804	1007.078796	0.000000	NaN	NaN
71.000061	0.000422	4.223254	0.023148	1007.417542	0.000000	NaN	NaN
71.500089	0.000447	4.470838	0.023069	1007.339172	0.000000	NaN	NaN
72.000118	0.000554	5.543704	0.023672	1007.933411	0.000000	NaN	NaN
72.500147	0.000488	4.883479	0.023980	1008.236877	0.000000	NaN	NaN
73.000175	0.000398	3.975670	0.023933	1008.189758	0.000000	NaN	NaN
73.500204	0.000422	4.223254	0.024574	1008.821472	0.000000	NaN	NaN
74.000232	0.000521	5.213591	0.024423	1008.672302	0.000000	NaN	NaN
74.500261	0.000447	4.470838	0.025383	1009.617859	0.000000	NaN	NaN
75.000290	0.000447	4.470838	0.025260	1009.496887	0.000000	NaN	NaN
75.500318	0.000554	5.543704	0.025225	1009.462585	0.000000	NaN	NaN
76.000347	0.000497	4.966007	0.025485	1009.718567	0.000000	NaN	NaN
76.500375	0.000488	4.883479	0.026668	1010.883423	0.000000	NaN	NaN
77.000404	0.000530	5.296120	0.026360	1010.579956	0.000000	NaN	NaN
77.500433	0.000497	4.966007	0.026899	1011.110962	0.000000	NaN	NaN
78.000461	0.000546	5.461176	0.027570	1011.771179	0.000000	NaN	NaN
78.500490	0.000563	5.626232	0.028211	1012.402832	0.000000	NaN	NaN
79.000518	0.000497	4.966007	0.027874	1012.071106	0.000000	NaN	NaN
79.500547	0.000596	5.956345	0.027638	1011.838562	0.000000	NaN	NaN
80.000576	0.000579	5.791288	0.028074	1012.267822	0.000000	NaN	NaN
80.500604	0.000513	5.131063	0.027502	1011.704285	0.000000	NaN	NaN
81.000633	0.000604	6.038873	0.027616	1011.816162	0.000000	NaN	NaN
81.500661	0.000365	3.645557	0.027858	1012.054932	0.000000	NaN	NaN
82.000690	0.000439	4.388310	0.028377	1012.565552	0.000000	NaN	NaN
82.500719	0.000571	5.708760	0.028261	1012.451843	0.000000	NaN	NaN
83.000747	0.000554	5.543704	0.028767	1012.950256	0.000000	NaN	NaN
83.500776	0.000629	6.286457	0.028852	1013.033081	0.000000	NaN	NaN
84.000805	0.000505	5.048535	0.028965	1013.144592	0.000000	NaN	NaN
84.500833	0.000447	4.470838	0.029735	1013.902771	0.000000	NaN	NaN
85.000862	0.000554	5.543704	0.029876	1014.041809	0.000000	NaN	NaN
85.499890	0.000653	6.534042	0.030347	1014.506042	0.000000	NaN	NaN
85.999919	0.000513	5.131063	0.030405	1014.562439	0.000000	NaN	NaN
86.499947	0.000596	5.956345	0.030025	1014.189087	0.000000	NaN	NaN
86.999976	0.000505	5.048535	0.030790	1014.942261	0.000000	NaN	NaN
87.500005	0.000521	5.213591	0.030854	1015.005188	0.000000	NaN	NaN
88.000033	0.000538	5.378648	0.031488	1015.629150	0.000000	NaN	NaN
88.500062	0.000563	5.626232	0.032177	1016.307739	0.000000	NaN	NaN
89.000090	0.000538	5.378648	0.031750	1015.887024	0.000000	NaN	NaN
89.500119	0.000521	5.213591	0.032299	1016.427490	0.000000	NaN	NaN
90.000148	0.000505	5.048535	0.032123	1016.254456	0.000000	NaN	NaN
90.500176	0.000488	4.883479	0.032707	1016.829285	0.000000	NaN	NaN
91.000205	0.000422	4.223254	0.032761	1016.882812	0.000000	NaN	NaN
91.500233	0.000538	5.378648	0.032449	1016.575195	0.000000	NaN	NaN
92.000262	0.000447	4.470838	0.033339	1017.451477	0.000000	NaN	NaN
92.500291	0.000530	5.296120	0.033309	1017.422119	0.000000	NaN	NaN
93.000319	0.000497	4.966007	0.033610	1017.718262	0.000000	NaN	NaN
93.500348	0.000538	5.378648	0.034450	1018.545837	0.000000	NaN	NaN
94.000377	0.000414	4.140726	0.034708	1018.799072	0.000000	NaN	NaN
94.500405	0.000571	5.708760	0.034768	1018.858826	0.000000	NaN	NaN
95.000434	0.000554	5.543704	0.035008	1019.095093	0.000000	NaN	NaN
95.500462	0.000678	6.781626	0.035747	1019.822876	0.000000	NaN	NaN
96.000491	0.000596	5.956345	0.035895	1019.968018	0.000000	NaN	NaN
96.500519	0.000488	4.883479	0.035445	1019.525574	0.000000	NaN	NaN
97.000548	0.000546	5.461176	0.036584	1020.646667	0.000000	NaN	NaN
97.500577	0.000538	5.378648	0.035895	1019.967896	0.000000	NaN	NaN
98.000605	0.000645	6.451513	0.036538	1020.601501	0.000000	NaN	NaN
98.500634	0.000513	5.131063	0.036619	1020.681091	0.000000	NaN	NaN
99.000663	0.000530	5.296120	0.037000	1021.056763	0.000000	NaN	NaN
99.500691	0.000554	5.543704	0.037539	1021.586548	0.000000	NaN	NaN
100.000720	0.000505	5.048535	0.036898	1020.955872	0.000000	NaN	NaN
100.500748	0.000604	6.038873	0.037967	1022.008301	0.000000	NaN	NaN
101.000777	0.000497	4.966007	0.038139	1022.177368	0.000000	NaN	NaN
101.500805	0.000530	5.296120	0.037900	1021.942261	0.000000	NaN	NaN
102.000834	0.000505	5.048535	0.038825	1022.853271	0.000000	NaN	NaN
102.500863	0.000637	6.368985	0.038410	1022.444763	0.000000	NaN	NaN
102.999891	0.000538	5.378648	0.038870	1022.897339	0.000000	NaN	NaN
103.499920	0.000513	5.131063	0.039114	1023.137451	0.000000	NaN	NaN
103.999948	0.000530	5.296120	0.039457	1023.475220	0.000000	NaN	NaN
104.499977	0.000554	5.543704	0.039534	1023.551270	0.000000	NaN	NaN
105.000006	0.000488	4.883479	0.039691	1023.705627	0.000000	NaN	NaN
105.500034	0.000554	5.543704	0.040250	1024.256470	0.000000	NaN	NaN
106.000063	0.000538	5.378648	0.040418	1024.421753	0.000000	NaN	NaN
106.500091	0.000645	6.451513	0.040570	1024.571045	0.000000	NaN	NaN
107.000120	0.000538	5.378648	0.041140	1025.132568	0.000000	NaN	NaN
107.500149	0.000488	4.883479	0.041720	1025.703491	0.000000	NaN	NaN
108.000177	0.000587	5.873817	0.041534	1025.520508	0.000000	NaN	NaN
108.500206	0.000505	5.048535	0.042094	1026.072510	0.000000	NaN	NaN
109.000234	0.000579	5.791288	0.041856	1025.837646	0.000000	NaN	NaN
109.500263	0.000513	5.131063	0.041956	1025.936401	0.000000	NaN	NaN
110.000292	0.000464	4.635895	0.042507	1026.479004	0.000000	NaN	NaN
110.500320	0.000538	5.378648	0.042890	1026.855347	0.000000	NaN	NaN
111.000349	0.000414	4.140726	0.043004	1026.968384	0.000000	NaN	NaN
111.500377	0.000554	5.543704	0.043455	1027.411987	0.000000	NaN	NaN
112.000406	0.000579	5.791288	0.043642	1027.596436	0.000000	NaN	NaN
112.500435	-0.000329	-3.286806	0.044687	1028.625000	0.000000	NaN	NaN
113.000463	-0.000213	-2.131412	0.045013	1028.945679	0.000000	NaN	NaN
113.500492	-0.000320	-3.204278	0.019023	1003.356079	0.000000	NaN	NaN
114.000520	-0.000238	-2.378996	0.014971	999.365540	0.000000	NaN	NaN
114.500549	-0.000205	-2.048884	0.013810	998.222412	0.000000	NaN	NaN
115.000578	-0.000329	-3.286806	0.013097	997.520874	0.000000	NaN	NaN
115.500606	-0.000345	-3.451862	0.012554	996.985718	0.000000	NaN	NaN
116.000635	-9.760180E-5	-0.976018	0.012609	997.039856	0.000000	NaN	NaN
116.500663	-0.000419	-4.194615	0.011671	996.116760	0.000000	NaN	NaN
117.000692	-0.000122	-1.223602	0.011624	996.070801	0.000000	NaN	NaN
117.500721	-0.000329	-3.286806	0.011212	995.664795	0.000000	NaN	NaN
118.000749	-0.000197	-1.966356	0.011202	995.654846	0.000000	NaN	NaN
118.500778	-0.000106	-1.058546	0.011329	995.779785	0.000000	NaN	NaN
119.000806	-0.000287	-2.874165	0.011101	995.555725	0.000000	NaN	NaN
119.500835	-0.000197	-1.966356	0.011056	995.511108	0.000000	NaN	NaN
120.000864	-0.000147	-1.471187	0.010576	995.038574	0.000000	NaN	NaN
120.499892	-0.000651	-6.505403	0.010707	995.167419	0.000000	NaN	NaN
120.999921	-0.000337	-3.369334	0.010574	995.036682	0.000000	NaN	NaN
121.499949	-0.000230	-2.296468	0.010337	994.803711	0.000000	NaN	NaN
121.999978	-0.000238	-2.378996	0.010369	994.835083	0.000000	NaN	NaN
122.500007	-0.000197	-1.966356	0.010336	994.802124	0.000000	NaN	NaN
123.000035	-0.000353	-3.534390	0.010198	994.666443	0.000000	NaN	NaN
123.500064	-0.000131	-1.306131	0.010139	994.608154	0.000000	NaN	NaN
124.000092	-0.000155	-1.553715	0.010080	994.549988	0.000000	NaN	NaN
124.500121	-0.000279	-2.791637	0.010302	994.768921	0.000000	NaN	NaN
125.000150	-0.000287	-2.874165	0.009999	994.470398	0.000000	NaN	NaN
125.500178	-0.000230	-2.296468	0.009936	994.408081	0.000000	NaN	NaN
126.000207	-0.000230	-2.296468	0.009980	994.451538	0.000000	NaN	NaN
126.500235	-0.000246	-2.461524	0.009742	994.217041	0.000000	NaN	NaN
127.000264	-0.000271	-2.709109	0.009691	994.167236	0.000000	NaN	NaN
127.500293	-0.000131	-1.306131	0.009783	994.257812	0.000000	NaN	NaN
128.000321	-0.000287	-2.874165	0.009833	994.306763	0.000000	NaN	NaN
128.500350	-0.000395	-3.947031	0.009651	994.128235	0.000000	NaN	NaN
129.000378	-0.000254	-2.544052	0.009854	994.327454	0.000000	NaN	NaN
129.500407	-0.000271	-2.709109	0.009704	994.179626	0.000000	NaN	NaN
130.000436	-0.000197	-1.966356	0.009624	994.101746	0.000000	NaN	NaN
130.500464	-0.000155	-1.553715	0.009722	994.197388	0.000000	NaN	NaN
131.000493	-0.000213	-2.131412	0.009681	994.157349	0.000000	NaN	NaN
131.500521	-0.000172	-1.718771	0.009650	994.126953	0.000000	NaN	NaN
132.000550	-0.000238	-2.378996	0.009353	993.834595	0.000000	NaN	NaN
132.500579	-0.000312	-3.121749	0.009470	993.949463	0.000000	NaN	NaN
133.000607	-0.000172	-1.718771	0.009503	993.981873	0.000000	NaN	NaN
133.500636	-0.000279	-2.791637	0.009644	994.120911	0.000000	NaN	NaN
134.000664	-0.000345	-3.451862	0.009539	994.017273	0.000000	NaN	NaN
134.500693	-9.760180E-5	-0.976018	0.009271	993.753418	0.000000	NaN	NaN
135.000722	-0.000180	-1.801299	0.009325	993.807007	0.000000	NaN	NaN
135.500750	-0.000296	-2.956693	0.009017	993.503662	0.000000	NaN	NaN
136.000779	-0.000205	-2.048884	0.009125	993.609924	0.000000	NaN	NaN
136.500807	-0.000246	-2.461524	0.009369	993.850220	0.000000	NaN	NaN
137.000836	-0.000254	-2.544052	0.009158	993.642761	0.000000	NaN	NaN
137.500865	-0.000287	-2.874165	0.009238	993.721252	0.000000	NaN	NaN
137.999893	-0.000205	-2.048884	0.009304	993.786255	0.000000	NaN	NaN
138.499922	-0.000263	-2.626581	0.009075	993.560181	0.000000	NaN	NaN
138.999950	-0.000230	-2.296468	0.009096	993.581726	0.000000	NaN	NaN
139.499979	-0.000329	-3.286806	0.008939	993.426392	0.000000	NaN	NaN
140.000008	-0.000213	-2.131412	0.009142	993.626404	0.000000	NaN	NaN
140.500036	-0.000230	-2.296468	0.009219	993.702820	0.000000	NaN	NaN
141.000065	-0.000205	-2.048884	0.009196	993.679565	0.000000	NaN	NaN
141.500093	-0.000312	-3.121749	0.009133	993.618164	0.000000	NaN	NaN
142.000122	-0.000304	-3.039221	0.008869	993.358154	0.000000	NaN	NaN
142.500150	-0.000296	-2.956693	0.008753	993.243469	0.000000	NaN	NaN
143.000179	-0.000345	-3.451862	0.009017	993.503845	0.000000	NaN	NaN
143.500208	-0.000304	-3.039221	0.009170	993.654358	0.000000	NaN	NaN
144.000236	-0.000337	-3.369334	0.008909	993.397217	0.000000	NaN	NaN
144.500265	-0.000172	-1.718771	0.009042	993.528259	0.000000	NaN	NaN
145.000293	-0.000312	-3.121749	0.008927	993.414612	0.000000	NaN	NaN
145.500322	-0.000221	-2.213940	0.008729	993.219604	0.000000	NaN	NaN
146.000351	-0.000271	-2.709109	0.008798	993.288025	0.000000	NaN	NaN
146.500379	-0.000378	-3.781974	0.008717	993.208069	0.000000	NaN	NaN
147.000408	-0.000246	-2.461524	0.008827	993.316772	0.000000	NaN	NaN