File: data/57k_5-1_2 (190415).lvm
LabVIEW Measurement
Writer_Version	2
Reader_Version	2
Separator	Tab
Decimal_Separator	.
Multi_Headings	No
X_Columns	One
Time_Pref	Absolute
Operator	user
Description	Load(N)/Stress(MPa)/Distance A(pixel)/Strain A/Distance B(pixel)/Strain B/Poisson's ratio
Date	2019/04/15
Time	13:10:04.8134063300347318543
***End_of_Header***

Notes	X 값은 오직 다음과 같을 때에만 유효함이 보장됩니다. Dev1/ai0
Channels	7
Samples	1	1	1	1	1	1	1
Date	2019/04/15	2019/04/15	2019/04/15	2019/04/15	2019/04/15	2019/04/15	2019/04/15
Time	14:01:22.8134579300347318276	14:01:22.8134579300347318276	14:01:22.8134579658508300781	14:01:22.8134579658508300781	14:01:22.8134579658508300781	14:01:22.8134579658508300781	14:01:22.8134579658508300781
Y_Unit_Label	Volts	Volts
X_Dimension	Time	Time	Time	Time	Time	Time	Time
X0	0.0000000000000000E+0	0.0000000000000000E+0	0.0000000000000000E+0	0.0000000000000000E+0	0.0000000000000000E+0	0.0000000000000000E+0	0.0000000000000000E+0
Delta_X	0.000000	0.000000	1.000000	1.000000	1.000000	1.000000	1.000000
***End_of_Header***
X_Value	Dev1/ai0	Dev1/ai0 1	Untitled	Untitled 1	Untitled 2	Untitled 3	Untitled 4	Comment
0.000000	-0.000131	-1.306131	4.231930E-5	1024.057983	0.000000	NaN	NaN
1.500086	-7.284337E-5	-0.728434	1.597404E-5	1024.031006	0.000000	NaN	NaN
3.000172	-6.820864E-6	-0.068209	-3.480911E-5	1023.979004	0.000000	NaN	NaN
4.500257	-6.459055E-5	-0.645906	0.000360	1024.383179	0.000000	NaN	NaN
5.999343	3.444320E-5	0.344432	0.000836	1024.870239	0.000000	NaN	NaN
7.499429	0.000158	1.582354	0.001237	1025.281128	0.000000	NaN	NaN
8.999515	0.000249	2.490163	0.001655	1025.709839	0.000000	NaN	NaN
10.499601	0.000216	2.160051	0.002113	1026.178833	0.000000	NaN	NaN
11.999686	0.000299	2.985332	0.002569	1026.645752	0.000000	NaN	NaN
13.499772	0.000233	2.325107	0.002887	1026.970947	0.000000	NaN	NaN
14.999858	0.000381	3.810613	0.003218	1027.309937	0.000000	NaN	NaN
16.499944	0.000348	3.480501	0.003486	1027.584473	0.000000	NaN	NaN
18.000030	0.000464	4.635895	0.003782	1027.887817	0.000000	NaN	NaN
19.500115	0.000464	4.635895	0.004127	1028.241089	0.000000	NaN	NaN
21.000201	0.000497	4.966007	0.004416	1028.536865	0.000000	NaN	NaN
22.499287	0.000554	5.543704	0.004584	1028.708862	0.000000	NaN	NaN
23.999373	0.000546	5.461176	0.005119	1029.256836	0.000000	NaN	NaN
25.499459	0.000645	6.451513	0.005523	1029.670166	0.000000	NaN	NaN
26.999544	0.000596	5.956345	0.005900	1030.056519	0.000000	NaN	NaN
28.499630	0.000818	8.184604	0.006481	1030.651123	0.000000	NaN	NaN
29.999716	0.000719	7.194267	0.006928	1031.108765	0.000000	NaN	NaN
31.499802	0.000794	7.937020	0.007321	1031.511597	0.000000	NaN	NaN
32.999887	0.000818	8.184604	0.007939	1032.143921	0.000000	NaN	NaN
34.499973	0.000909	9.092413	0.008432	1032.648926	0.000000	NaN	NaN
36.000059	0.001025	10.247807	0.008962	1033.191528	0.000000	NaN	NaN
37.500145	0.001132	11.320673	0.009467	1033.708496	0.000000	NaN	NaN
39.000231	0.001190	11.898370	0.009901	1034.153687	0.000000	NaN	NaN
40.499316	0.001050	10.495392	0.010398	1034.662354	0.000000	NaN	NaN
41.999402	0.001165	11.650785	0.010896	1035.172485	0.000000	NaN	NaN
43.499488	0.001239	12.393538	0.011400	1035.688110	0.000000	NaN	NaN
44.999574	0.001404	14.044101	0.012014	1036.316650	0.000000	NaN	NaN
46.499660	0.001363	13.631460	0.012564	1036.880737	0.000000	NaN	NaN
47.999745	0.001289	12.888707	0.013094	1037.423096	0.000000	NaN	NaN
49.499831	0.001380	13.796517	0.013495	1037.834229	0.000000	NaN	NaN
50.999917	0.001454	14.539270	0.013891	1038.239502	0.000000	NaN	NaN
52.500003	0.001561	15.612135	0.014334	1038.692505	0.000000	NaN	NaN
54.000089	0.001470	14.704326	0.015001	1039.376099	0.000000	NaN	NaN
55.500174	0.001553	15.529607	0.015345	1039.727783	0.000000	NaN	NaN
57.000260	0.001578	15.777192	0.015926	1040.323364	0.000000	NaN	NaN
58.499346	0.001512	15.116967	0.016437	1040.845947	0.000000	NaN	NaN
59.999432	0.001710	17.097642	0.016758	1041.175049	0.000000	NaN	NaN
61.499518	0.001652	16.519945	0.017331	1041.761719	0.000000	NaN	NaN
62.999603	0.001652	16.519945	0.017853	1042.295898	0.000000	NaN	NaN
64.499689	0.001702	17.015114	0.018404	1042.861084	0.000000	NaN	NaN
65.999775	0.001685	16.850057	0.019543	1044.026489	0.000000	NaN	NaN
67.499861	0.001809	18.087979	0.020116	1044.613403	0.000000	NaN	NaN
68.999947	0.001759	17.592810	0.019528	1044.011963	0.000000	NaN	NaN
70.500032	0.001735	17.345226	0.020200	1044.699219	0.000000	NaN	NaN
72.000118	0.001759	17.592810	0.020760	1045.273071	0.000000	NaN	NaN
73.500204	0.001702	17.015114	0.021434	1045.963745	0.000000	NaN	NaN
74.999290	0.001718	17.180170	0.022129	1046.675049	0.000000	NaN	NaN
76.499376	0.001883	18.830732	0.022702	1047.261719	0.000000	NaN	NaN
77.999461	0.001990	19.903598	0.023464	1048.042603	0.000000	NaN	NaN
79.499547	0.001875	18.748204	0.024153	1048.748169	0.000000	NaN	NaN
80.999633	0.001867	18.665676	0.024850	1049.461060	0.000000	NaN	NaN
82.499719	0.001974	19.738542	0.025602	1050.231934	0.000000	NaN	NaN
83.999804	0.002040	20.398767	0.026234	1050.878296	0.000000	NaN	NaN
85.499890	0.001900	18.995789	0.026864	1051.524048	0.000000	NaN	NaN
86.999976	0.002015	20.151182	0.027615	1052.292603	0.000000	NaN	NaN
88.500062	0.001883	18.830732	0.028289	1052.982544	0.000000	NaN	NaN
90.000148	0.001966	19.656014	0.029049	1053.760742	0.000000	NaN	NaN
91.500234	0.001999	19.986126	0.029841	1054.572632	0.000000	NaN	NaN
92.999319	0.002015	20.151182	0.030481	1055.227417	0.000000	NaN	NaN
94.499405	0.002048	20.481295	0.031251	1056.016235	0.000000	NaN	NaN
95.999491	0.001875	18.748204	0.031961	1056.743652	0.000000	NaN	NaN
97.499577	0.002056	20.563823	0.032649	1057.448120	0.000000	NaN	NaN
98.999662	0.001924	19.243373	0.033415	1058.231689	0.000000	NaN	NaN
100.499748	0.001949	19.490957	0.034145	1058.979248	0.000000	NaN	NaN
101.999834	0.001990	19.903598	0.034788	1059.637817	0.000000	NaN	NaN
103.499920	0.002056	20.563823	0.035604	1060.474121	0.000000	NaN	NaN
105.000006	0.001900	18.995789	0.036297	1061.183228	0.000000	NaN	NaN
106.500091	0.001957	19.573485	0.037094	1061.999512	0.000000	NaN	NaN
108.000177	0.002073	20.728879	0.037815	1062.737915	0.000000	NaN	NaN
109.500263	0.002040	20.398767	0.038630	1063.572388	0.000000	NaN	NaN
110.999349	0.002056	20.563823	0.039354	1064.313354	0.000000	NaN	NaN
112.499435	0.001941	19.408429	0.039996	1064.971069	0.000000	NaN	NaN
113.999520	0.002040	20.398767	0.040675	1065.666016	0.000000	NaN	NaN
115.499606	0.002065	20.646351	0.041486	1066.497070	0.000000	NaN	NaN
116.999692	0.002180	21.801745	0.042271	1067.300415	0.000000	NaN	NaN
118.499778	0.002023	20.233710	0.042983	1068.029419	0.000000	NaN	NaN
119.999864	0.002056	20.563823	0.043808	1068.874756	0.000000	NaN	NaN
121.499949	0.002131	21.306576	0.044419	1069.500244	0.000000	NaN	NaN
123.000035	0.001974	19.738542	0.045228	1070.328613	0.000000	NaN	NaN
124.500121	0.002238	22.379442	0.045838	1070.953003	0.000000	NaN	NaN
126.000207	0.002081	20.811407	0.046646	1071.781250	0.000000	NaN	NaN
127.499293	0.002172	21.719217	0.047319	1072.469971	0.000000	NaN	NaN
128.999378	0.001941	19.408429	0.048089	1073.258789	0.000000	NaN	NaN
130.499464	0.002048	20.481295	0.048899	1074.088013	0.000000	NaN	NaN
131.999550	0.002089	20.893935	0.049585	1074.790894	0.000000	NaN	NaN
133.499636	0.002139	21.389104	0.050280	1075.502075	0.000000	NaN	NaN
134.999721	0.002180	21.801745	0.050918	1076.155640	0.000000	NaN	NaN
136.499807	0.002048	20.481295	0.051748	1077.005127	0.000000	NaN	NaN
137.999893	0.002122	21.224048	0.052456	1077.730225	0.000000	NaN	NaN
139.499979	0.002106	21.058992	0.053272	1078.566406	0.000000	NaN	NaN
141.000065	0.002155	21.554160	0.053813	1079.119873	0.000000	NaN	NaN
142.500151	0.002114	21.141520	0.054692	1080.020264	0.000000	NaN	NaN
144.000236	0.002073	20.728879	0.055333	1080.676758	0.000000	NaN	NaN
145.499322	0.002015	20.151182	0.056229	1081.593628	0.000000	NaN	NaN
146.999408	0.002205	22.049329	0.057106	1082.491821	0.000000	NaN	NaN
148.499494	0.002131	21.306576	0.057708	1083.108887	0.000000	NaN	NaN
149.999580	0.002139	21.389104	0.058339	1083.754639	0.000000	NaN	NaN
151.499665	0.002122	21.224048	0.059206	1084.641968	0.000000	NaN	NaN
152.999751	0.002279	22.792082	0.059816	1085.267090	0.000000	NaN	NaN
154.499837	0.002205	22.049329	0.060798	1086.272461	0.000000	NaN	NaN
155.999923	0.002287	22.874610	0.061283	1086.769287	0.000000	NaN	NaN
157.500009	0.002114	21.141520	0.062214	1087.722534	0.000000	NaN	NaN
159.000094	0.002147	21.471632	0.062804	1088.327393	0.000000	NaN	NaN
160.500180	0.002098	20.976463	0.063714	1089.258667	0.000000	NaN	NaN
162.000266	0.002172	21.719217	0.064353	1089.913452	0.000000	NaN	NaN
163.499352	0.002065	20.646351	0.065239	1090.820679	0.000000	NaN	NaN
164.999437	0.002073	20.728879	0.065820	1091.415039	0.000000	NaN	NaN
166.499523	0.002246	22.461970	0.066681	1092.297241	0.000000	NaN	NaN
167.999609	0.002230	22.296913	0.067106	1092.731689	0.000000	NaN	NaN
169.499695	0.002246	22.461970	0.068090	1093.739868	0.000000	NaN	NaN
170.999781	0.002353	23.534835	0.068776	1094.442505	0.000000	NaN	NaN
172.499866	0.002213	22.131857	0.069696	1095.384033	0.000000	NaN	NaN
173.999952	0.002114	21.141520	0.070145	1095.843628	0.000000	NaN	NaN
175.500038	0.002197	21.966801	0.070824	1096.539673	0.000000	NaN	NaN
177.000124	0.002147	21.471632	0.071527	1097.259888	0.000000	NaN	NaN
178.500210	0.002246	22.461970	0.072290	1098.041016	0.000000	NaN	NaN
179.999295	0.002106	21.058992	0.073054	1098.823120	0.000000	NaN	NaN
181.499381	0.002213	22.131857	0.073805	1099.592041	0.000000	NaN	NaN
182.999467	0.002263	22.627026	0.074572	1100.377563	0.000000	NaN	NaN
184.499553	0.002353	23.534835	0.075289	1101.112061	0.000000	NaN	NaN
185.999639	0.002312	23.122195	0.076070	1101.911133	0.000000	NaN	NaN
187.499724	0.002279	22.792082	0.076815	1102.673950	0.000000	NaN	NaN
188.999810	0.002287	22.874610	0.077635	1103.514038	0.000000	NaN	NaN
190.499896	0.002320	23.204723	0.078416	1104.313721	0.000000	NaN	NaN
191.999982	0.002312	23.122195	0.079111	1105.025879	0.000000	NaN	NaN
193.500068	0.002279	22.792082	0.079816	1105.747559	0.000000	NaN	NaN
195.000153	0.002271	22.709554	0.080590	1106.539917	0.000000	NaN	NaN
196.500239	0.002230	22.296913	0.081389	1107.358154	0.000000	NaN	NaN
197.999325	0.002254	22.544498	0.082080	1108.065674	0.000000	NaN	NaN
199.499411	0.002155	21.554160	0.082871	1108.875732	0.000000	NaN	NaN
200.999496	0.002271	22.709554	0.083530	1109.550659	0.000000	NaN	NaN
202.499582	0.002287	22.874610	0.084305	1110.344604	0.000000	NaN	NaN
203.999668	0.002370	23.699892	0.085070	1111.128052	0.000000	NaN	NaN
205.499754	0.002486	24.855285	0.085700	1111.772949	0.000000	NaN	NaN
206.999840	0.002428	24.277588	0.086580	1112.674194	0.000000	NaN	NaN
208.499926	0.002403	24.030004	0.087244	1113.353394	0.000000	NaN	NaN
210.000011	0.002453	24.525173	0.087964	1114.090820	0.000000	NaN	NaN
211.500097	0.002329	23.287251	0.088740	1114.886108	0.000000	NaN	NaN
213.000183	0.002362	23.617363	0.089536	1115.700806	0.000000	NaN	NaN
214.500269	0.002329	23.287251	0.090293	1116.476318	0.000000	NaN	NaN
215.999354	0.002329	23.287251	0.090992	1117.191650	0.000000	NaN	NaN
217.499440	0.002279	22.792082	0.091671	1117.887573	0.000000	NaN	NaN
218.999526	0.002320	23.204723	0.092432	1118.666382	0.000000	NaN	NaN
220.499612	0.002411	24.112532	0.093193	1119.446045	0.000000	NaN	NaN
221.999698	0.002337	23.369779	0.094001	1120.272583	0.000000	NaN	NaN
223.499783	0.002403	24.030004	0.094786	1121.076904	0.000000	NaN	NaN
224.999869	0.002304	23.039667	0.095542	1121.850952	0.000000	NaN	NaN
226.499955	0.002362	23.617363	0.096249	1122.575317	0.000000	NaN	NaN
228.000041	0.002420	24.195060	0.097038	1123.382935	0.000000	NaN	NaN
229.500127	0.002279	22.792082	0.097739	1124.100342	0.000000	NaN	NaN
231.000212	0.002345	23.452307	0.098532	1124.912720	0.000000	NaN	NaN
232.499298	0.002386	23.864948	0.099305	1125.704590	0.000000	NaN	NaN
233.999384	0.002337	23.369779	0.100008	1126.423950	0.000000	NaN	NaN
235.499470	0.002320	23.204723	0.100806	1127.240967	0.000000	NaN	NaN
236.999556	0.002337	23.369779	0.101515	1127.967163	0.000000	NaN	NaN
238.499641	0.002304	23.039667	0.102279	1128.749512	0.000000	NaN	NaN
239.999727	0.002386	23.864948	0.103000	1129.487793	0.000000	NaN	NaN
241.499813	0.002535	25.350454	0.103848	1130.356812	0.000000	NaN	NaN
242.999899	0.002428	24.277588	0.104547	1131.072510	0.000000	NaN	NaN
244.499985	0.002420	24.195060	0.105216	1131.757812	0.000000	NaN	NaN
246.000070	0.002469	24.690229	0.105873	1132.430298	0.000000	NaN	NaN
247.500156	0.002337	23.369779	0.106640	1133.215698	0.000000	NaN	NaN
249.000242	0.002353	23.534835	0.107493	1134.089355	0.000000	NaN	NaN
250.499328	0.002428	24.277588	0.108163	1134.775024	0.000000	NaN	NaN
251.999414	0.002420	24.195060	0.108847	1135.475098	0.000000	NaN	NaN
253.499499	0.002378	23.782420	0.109656	1136.303955	0.000000	NaN	NaN
254.999585	0.002395	23.947476	0.110345	1137.009888	0.000000	NaN	NaN
256.499671	0.002403	24.030004	0.110993	1137.673340	0.000000	NaN	NaN
257.999757	0.002378	23.782420	0.111762	1138.460327	0.000000	NaN	NaN
259.499843	0.002436	24.360117	0.112474	1139.189575	0.000000	NaN	NaN
260.999928	0.002411	24.112532	0.113226	1139.959473	0.000000	NaN	NaN
262.500014	0.002510	25.102870	0.113998	1140.750488	0.000000	NaN	NaN
264.000100	0.002395	23.947476	0.114713	1141.482788	0.000000	NaN	NaN
265.500186	0.002337	23.369779	0.115456	1142.243774	0.000000	NaN	NaN
267.000271	0.002453	24.525173	0.116163	1142.967163	0.000000	NaN	NaN
268.499357	0.002477	24.772757	0.116849	1143.669678	0.000000	NaN	NaN
269.999443	0.002411	24.112532	0.117604	1144.443237	0.000000	NaN	NaN
271.499529	0.002494	24.937813	0.118351	1145.207642	0.000000	NaN	NaN
272.999615	0.002510	25.102870	0.119072	1145.946533	0.000000	NaN	NaN
274.499701	0.002312	23.122195	0.119814	1146.705933	0.000000	NaN	NaN
275.999786	0.002519	25.185398	0.120526	1147.435425	0.000000	NaN	NaN
277.499872	0.002370	23.699892	0.121197	1148.122070	0.000000	NaN	NaN
278.999958	0.002576	25.763095	0.122035	1148.980347	0.000000	NaN	NaN
280.500044	0.002519	25.185398	0.122778	1149.740967	0.000000	NaN	NaN
282.000130	0.002494	24.937813	0.123455	1150.434082	0.000000	NaN	NaN
283.500215	0.002469	24.690229	0.124177	1151.174194	0.000000	NaN	NaN
284.999301	0.002386	23.864948	0.124925	1151.939941	0.000000	NaN	NaN
286.499387	0.002444	24.442645	0.125676	1152.708618	0.000000	NaN	NaN
287.999473	0.002494	24.937813	0.126478	1153.529541	0.000000	NaN	NaN
289.499558	0.002370	23.699892	0.127218	1154.288086	0.000000	NaN	NaN
290.999644	0.002519	25.185398	0.127897	1154.983398	0.000000	NaN	NaN
292.499730	0.002444	24.442645	0.128698	1155.803589	0.000000	NaN	NaN
293.999816	0.002535	25.350454	0.129317	1156.437256	0.000000	NaN	NaN
295.499902	0.002444	24.442645	0.130135	1157.274780	0.000000	NaN	NaN
296.999987	0.002634	26.340792	0.130945	1158.103882	0.000000	NaN	NaN
298.500073	0.002469	24.690229	0.131718	1158.895508	0.000000	NaN	NaN
300.000159	0.002494	24.937813	0.132392	1159.586060	0.000000	NaN	NaN
301.500245	0.002486	24.855285	0.133146	1160.358276	0.000000	NaN	NaN
302.999331	0.002560	25.598038	0.133880	1161.109375	0.000000	NaN	NaN
304.499416	0.002560	25.598038	0.134604	1161.850952	0.000000	NaN	NaN
305.999502	0.002436	24.360117	0.135337	1162.601685	0.000000	NaN	NaN
307.499588	0.002469	24.690229	0.136165	1163.449341	0.000000	NaN	NaN
308.999674	0.002543	25.432982	0.136868	1164.169312	0.000000	NaN	NaN
310.499760	0.002494	24.937813	0.137605	1164.923950	0.000000	NaN	NaN
311.999845	0.002609	26.093207	0.138207	1165.540894	0.000000	NaN	NaN
313.499931	0.002576	25.763095	0.139050	1166.404175	0.000000	NaN	NaN
315.000017	0.002552	25.515510	0.139750	1167.120605	0.000000	NaN	NaN
316.500103	0.002527	25.267926	0.140524	1167.913452	0.000000	NaN	NaN
318.000189	0.002560	25.598038	0.141307	1168.715454	0.000000	NaN	NaN
319.500274	0.002535	25.350454	0.142013	1169.438110	0.000000	NaN	NaN
320.999360	0.002469	24.690229	0.142690	1170.130859	0.000000	NaN	NaN
322.499446	0.002477	24.772757	0.143353	1170.810425	0.000000	NaN	NaN
323.999532	0.002527	25.267926	0.144207	1171.685059	0.000000	NaN	NaN
325.499618	0.002651	26.505848	0.144988	1172.484497	0.000000	NaN	NaN
326.999703	0.002576	25.763095	0.145605	1173.116211	0.000000	NaN	NaN
328.499789	0.002568	25.680567	0.146288	1173.816162	0.000000	NaN	NaN
329.999875	0.002593	25.928151	0.147001	1174.546143	0.000000	NaN	NaN
331.499961	0.002593	25.928151	0.147711	1175.273193	0.000000	NaN	NaN
333.000046	0.002560	25.598038	0.148543	1176.124878	0.000000	NaN	NaN
334.500132	0.002642	26.423320	0.149247	1176.845703	0.000000	NaN	NaN
336.000218	0.002700	27.001017	0.149974	1177.590698	0.000000	NaN	NaN
337.499304	0.002609	26.093207	0.150618	1178.249268	0.000000	NaN	NaN
338.999390	0.002568	25.680567	0.151434	1179.085205	0.000000	NaN	NaN
340.499475	0.002585	25.845623	0.152039	1179.705078	0.000000	NaN	NaN
341.999561	0.002494	24.937813	0.152915	1180.602051	0.000000	NaN	NaN
343.499647	0.002543	25.432982	0.153448	1181.147339	0.000000	NaN	NaN
344.999733	0.002642	26.423320	0.154218	1181.936157	0.000000	NaN	NaN
346.499819	0.002717	27.166073	0.154948	1182.683350	0.000000	NaN	NaN
347.999904	0.002510	25.102870	0.155693	1183.446289	0.000000	NaN	NaN
349.499990	0.002618	26.175735	0.156404	1184.174194	0.000000	NaN	NaN
351.000076	0.002593	25.928151	0.157118	1184.905396	0.000000	NaN	NaN
352.500162	0.002651	26.505848	0.157781	1185.584229	0.000000	NaN	NaN
354.000248	0.002692	26.918488	0.158580	1186.403198	0.000000	NaN	NaN
355.499333	0.002684	26.835960	0.159110	1186.945435	0.000000	NaN	NaN
356.999419	0.002560	25.598038	0.159951	1187.806396	0.000000	NaN	NaN
358.499505	0.002684	26.835960	0.160628	1188.499878	0.000000	NaN	NaN
359.999591	0.002642	26.423320	0.161347	1189.235840	0.000000	NaN	NaN
361.499677	0.002700	27.001017	0.162068	1189.974243	0.000000	NaN	NaN
362.999762	0.002618	26.175735	0.162677	1190.598511	0.000000	NaN	NaN
364.499848	0.002692	26.918488	0.163480	1191.420776	0.000000	NaN	NaN
365.999934	0.002758	27.578713	0.164152	1192.108521	0.000000	NaN	NaN
367.500020	0.002700	27.001017	0.164870	1192.843994	0.000000	NaN	NaN
369.000106	0.002667	26.670904	0.165565	1193.555420	0.000000	NaN	NaN
370.500191	0.002675	26.753432	0.166319	1194.328125	0.000000	NaN	NaN
371.999277	0.002519	25.185398	0.167009	1195.034302	0.000000	NaN	NaN
373.499363	0.002634	26.340792	0.167680	1195.721436	0.000000	NaN	NaN
374.999449	0.002733	27.331129	0.168271	1196.326538	0.000000	NaN	NaN
376.499535	0.002684	26.835960	0.169012	1197.085083	0.000000	NaN	NaN
377.999620	0.002667	26.670904	0.169867	1197.960449	0.000000	NaN	NaN
379.499706	0.002651	26.505848	0.170548	1198.657837	0.000000	NaN	NaN
380.999792	0.002659	26.588376	0.171330	1199.458984	0.000000	NaN	NaN
382.499878	0.002667	26.670904	0.172078	1200.225464	0.000000	NaN	NaN
383.999963	0.002717	27.166073	0.172656	1200.816528	0.000000	NaN	NaN
385.500049	0.002783	27.826298	0.173427	1201.606812	0.000000	NaN	NaN
387.000135	0.002634	26.340792	0.174138	1202.334961	0.000000	NaN	NaN
388.500221	0.002634	26.340792	0.174831	1203.043945	0.000000	NaN	NaN
389.999307	0.002626	26.258263	0.175647	1203.879639	0.000000	NaN	NaN
391.499393	0.002609	26.093207	0.176310	1204.558838	0.000000	NaN	NaN
392.999478	0.002717	27.166073	0.176980	1205.245239	0.000000	NaN	NaN
394.499564	0.002849	28.486523	0.177762	1206.045654	0.000000	NaN	NaN
395.999650	0.002543	25.432982	0.178400	1206.698853	0.000000	NaN	NaN
397.499736	0.002642	26.423320	0.179104	1207.419678	0.000000	NaN	NaN
398.999821	0.002799	27.991354	0.179849	1208.182251	0.000000	NaN	NaN
400.499907	0.002816	28.156410	0.180459	1208.807617	0.000000	NaN	NaN
401.999993	0.002568	25.680567	0.181235	1209.602173	0.000000	NaN	NaN
403.500079	0.002684	26.835960	0.182743	1211.146606	0.000000	NaN	NaN
405.000165	0.002642	26.423320	0.183320	1211.736694	0.000000	NaN	NaN
406.500251	0.002692	26.918488	0.183159	1211.572266	0.000000	NaN	NaN
407.999336	0.002791	27.908826	0.183771	1212.198364	0.000000	NaN	NaN
409.499422	0.002700	27.001017	0.184495	1212.940308	0.000000	NaN	NaN
410.999508	0.002758	27.578713	0.185258	1213.721191	0.000000	NaN	NaN
412.499594	0.002791	27.908826	0.185962	1214.442139	0.000000	NaN	NaN
413.999679	0.002675	26.753432	0.186729	1215.228271	0.000000	NaN	NaN
415.499765	0.002692	26.918488	0.187351	1215.864624	0.000000	NaN	NaN
416.999851	0.002634	26.340792	0.188057	1216.587402	0.000000	NaN	NaN
418.499937	0.002849	28.486523	0.188765	1217.312500	0.000000	NaN	NaN
420.000023	0.002601	26.010679	0.189516	1218.081909	0.000000	NaN	NaN
421.500108	0.002708	27.083545	0.190220	1218.802856	0.000000	NaN	NaN
423.000194	0.002725	27.248601	0.190933	1219.533203	0.000000	NaN	NaN
424.499280	0.002717	27.166073	0.191597	1220.212646	0.000000	NaN	NaN
425.999366	0.002824	28.238938	0.192334	1220.967896	0.000000	NaN	NaN
427.499452	0.002832	28.321467	0.193082	1221.733032	0.000000	NaN	NaN
428.999537	0.002700	27.001017	0.193666	1222.331055	0.000000	NaN	NaN
430.499623	0.002667	26.670904	0.194380	1223.062500	0.000000	NaN	NaN
431.999709	0.002774	27.743770	0.195066	1223.765137	0.000000	NaN	NaN
433.499795	0.002840	28.403995	0.195808	1224.525024	0.000000	NaN	NaN
434.999881	0.002832	28.321467	0.196504	1225.237915	0.000000	NaN	NaN
436.499966	0.002923	29.229276	0.197110	1225.858154	0.000000	NaN	NaN
438.000052	0.002807	28.073882	0.197876	1226.643066	0.000000	NaN	NaN
439.500138	0.002816	28.156410	0.198539	1227.321533	0.000000	NaN	NaN
441.000224	0.002708	27.083545	0.199241	1228.040649	0.000000	NaN	NaN
442.499310	0.002807	28.073882	0.199900	1228.714722	0.000000	NaN	NaN
443.999395	0.002799	27.991354	0.200562	1229.393311	0.000000	NaN	NaN
445.499481	0.002816	28.156410	0.201309	1230.158447	0.000000	NaN	NaN
446.999567	0.002741	27.413657	0.201919	1230.783081	0.000000	NaN	NaN
448.499653	0.002915	29.146748	0.202686	1231.568237	0.000000	NaN	NaN
449.999738	0.002799	27.991354	0.203333	1232.230835	0.000000	NaN	NaN
451.499824	0.002725	27.248601	0.204102	1233.017700	0.000000	NaN	NaN
452.999910	0.002865	28.651579	0.204771	1233.703247	0.000000	NaN	NaN
454.499996	0.002783	27.826298	0.205503	1234.452637	0.000000	NaN	NaN
456.000082	0.002799	27.991354	0.206104	1235.068115	0.000000	NaN	NaN
457.500168	0.002783	27.826298	0.206990	1235.975708	0.000000	NaN	NaN
459.000253	0.002849	28.486523	0.207621	1236.621948	0.000000	NaN	NaN
460.499339	0.002824	28.238938	0.208235	1237.249878	0.000000	NaN	NaN
461.999425	0.002956	29.559388	0.208962	1237.995239	0.000000	NaN	NaN
463.499511	0.002791	27.908826	0.209665	1238.714966	0.000000	NaN	NaN
464.999596	0.002849	28.486523	0.210426	1239.493652	0.000000	NaN	NaN
466.499682	0.002758	27.578713	0.211173	1240.258545	0.000000	NaN	NaN
467.999768	0.002783	27.826298	0.211765	1240.865112	0.000000	NaN	NaN
469.499854	0.002832	28.321467	0.212463	1241.579834	0.000000	NaN	NaN
470.999940	0.002816	28.156410	0.213161	1242.294434	0.000000	NaN	NaN
472.500025	0.002849	28.486523	0.213844	1242.993652	0.000000	NaN	NaN
474.000111	0.002832	28.321467	0.214634	1243.803345	0.000000	NaN	NaN
475.500197	0.002824	28.238938	0.215263	1244.447266	0.000000	NaN	NaN
476.999283	0.002807	28.073882	0.215921	1245.121338	0.000000	NaN	NaN
478.499369	0.002857	28.569051	0.216718	1245.936768	0.000000	NaN	NaN
479.999454	0.002882	28.816635	0.217383	1246.617554	0.000000	NaN	NaN
481.499540	0.002824	28.238938	0.218050	1247.301392	0.000000	NaN	NaN
482.999626	0.002840	28.403995	0.218861	1248.131104	0.000000	NaN	NaN
484.499712	0.002972	29.724445	0.219481	1248.766724	0.000000	NaN	NaN
485.999798	0.002849	28.486523	0.220278	1249.582153	0.000000	NaN	NaN
487.499883	0.002882	28.816635	0.220988	1250.309326	0.000000	NaN	NaN
488.999969	0.002832	28.321467	0.221601	1250.937500	0.000000	NaN	NaN
490.500055	0.002799	27.991354	0.222436	1251.792480	0.000000	NaN	NaN
492.000141	0.002733	27.331129	0.223063	1252.434937	0.000000	NaN	NaN
493.500227	0.002733	27.331129	0.223795	1253.183716	0.000000	NaN	NaN
494.999312	0.002898	28.981692	0.224541	1253.947876	0.000000	NaN	NaN
496.499398	0.002890	28.899163	0.225292	1254.717285	0.000000	NaN	NaN
497.999484	0.002873	28.734107	0.225962	1255.402832	0.000000	NaN	NaN
499.499570	0.002923	29.229276	0.226721	1256.180054	0.000000	NaN	NaN
500.999656	0.002964	29.641917	0.227365	1256.840088	0.000000	NaN	NaN
502.499741	0.002948	29.476860	0.227907	1257.394531	0.000000	NaN	NaN
503.999827	0.002832	28.321467	0.228788	1258.296753	0.000000	NaN	NaN
505.499913	0.002873	28.734107	0.229396	1258.919678	0.000000	NaN	NaN
506.999999	0.002725	27.248601	0.230173	1259.715576	0.000000	NaN	NaN
508.500085	0.002816	28.156410	0.230825	1260.382935	0.000000	NaN	NaN
510.000170	0.002906	29.064220	0.231496	1261.070190	0.000000	NaN	NaN
511.500256	0.002807	28.073882	0.232219	1261.809937	0.000000	NaN	NaN
512.999342	0.002956	29.559388	0.232832	1262.437622	0.000000	NaN	NaN
514.499428	0.002931	29.311804	0.233580	1263.204102	0.000000	NaN	NaN
515.999514	0.002923	29.229276	0.233685	1263.311157	0.000000	NaN	NaN
517.499599	0.002923	29.229276	0.234385	1264.028320	0.000000	NaN	NaN
518.999685	0.002882	28.816635	0.235072	1264.732178	0.000000	NaN	NaN
520.499771	0.002849	28.486523	0.235831	1265.509399	0.000000	NaN	NaN
521.999857	0.002939	29.394332	0.236486	1266.179687	0.000000	NaN	NaN
523.499943	0.002898	28.981692	0.237186	1266.896851	0.000000	NaN	NaN
525.000028	0.002890	28.899163	0.237910	1267.638184	0.000000	NaN	NaN
526.500114	0.002997	29.972029	0.238440	1268.180542	0.000000	NaN	NaN
528.000200	0.002882	28.816635	0.239404	1269.167969	0.000000	NaN	NaN
529.499286	0.002857	28.569051	0.239968	1269.745483	0.000000	NaN	NaN
530.999371	0.002997	29.972029	0.240580	1270.372192	0.000000	NaN	NaN
532.499457	0.002906	29.064220	0.241398	1271.209717	0.000000	NaN	NaN
533.999543	0.002873	28.734107	0.242028	1271.855103	0.000000	NaN	NaN
535.499629	0.002849	28.486523	0.242668	1272.510132	0.000000	NaN	NaN
536.999715	0.002931	29.311804	0.243374	1273.233521	0.000000	NaN	NaN
538.499800	0.002906	29.064220	0.244126	1274.003418	0.000000	NaN	NaN
539.999886	0.003014	30.137085	0.244887	1274.782837	0.000000	NaN	NaN
541.499972	0.002964	29.641917	0.245612	1275.524414	0.000000	NaN	NaN
543.000058	0.002939	29.394332	0.246291	1276.219849	0.000000	NaN	NaN
544.500144	0.002948	29.476860	0.247083	1277.031006	0.000000	NaN	NaN
546.000229	0.002964	29.641917	0.247617	1277.578369	0.000000	NaN	NaN
547.499315	0.002956	29.559388	0.248471	1278.453003	0.000000	NaN	NaN
548.999401	0.002915	29.146748	0.249096	1279.092773	0.000000	NaN	NaN
550.499487	0.002931	29.311804	0.249781	1279.793579	0.000000	NaN	NaN
551.999572	0.003047	30.467198	0.250524	1280.555298	0.000000	NaN	NaN
553.499658	0.002964	29.641917	0.251236	1281.283569	0.000000	NaN	NaN
554.999744	0.002989	29.889501	0.251965	1282.030884	0.000000	NaN	NaN
556.499830	0.002906	29.064220	0.252660	1282.741699	0.000000	NaN	NaN
557.999916	0.002824	28.238938	0.253346	1283.444702	0.000000	NaN	NaN
559.500002	0.003063	30.632254	0.253999	1284.112915	0.000000	NaN	NaN
561.000087	0.002956	29.559388	0.254717	1284.848877	0.000000	NaN	NaN
562.500173	0.003080	30.797310	0.255304	1285.449707	0.000000	NaN	NaN
564.000259	0.002923	29.229276	0.256143	1286.309326	0.000000	NaN	NaN
565.499345	0.003055	30.549726	0.256847	1287.029419	0.000000	NaN	NaN
566.999431	0.002981	29.806973	0.257573	1287.772705	0.000000	NaN	NaN
568.499516	0.002906	29.064220	0.258283	1288.500000	0.000000	NaN	NaN
569.999602	0.002906	29.064220	0.258903	1289.135376	0.000000	NaN	NaN
571.499688	0.003038	30.384670	0.259570	1289.817627	0.000000	NaN	NaN
572.999774	0.002948	29.476860	0.260347	1290.614258	0.000000	NaN	NaN
574.499860	0.002890	28.899163	0.261005	1291.287354	0.000000	NaN	NaN
575.999945	0.002964	29.641917	0.261692	1291.991455	0.000000	NaN	NaN
577.500031	0.003005	30.054557	0.262370	1292.685425	0.000000	NaN	NaN
579.000117	0.003022	30.219613	0.263144	1293.478027	0.000000	NaN	NaN
580.500203	0.003022	30.219613	0.263799	1294.149170	0.000000	NaN	NaN
581.999288	0.003063	30.632254	0.264511	1294.878174	0.000000	NaN	NaN
583.499374	0.002865	28.651579	0.265151	1295.532715	0.000000	NaN	NaN
584.999460	0.002873	28.734107	0.265987	1296.389526	0.000000	NaN	NaN
586.499546	0.003022	30.219613	0.266576	1296.991943	0.000000	NaN	NaN
587.999632	0.002931	29.311804	0.267214	1297.645874	0.000000	NaN	NaN
589.499717	0.002898	28.981692	0.267961	1298.410767	0.000000	NaN	NaN
590.999803	0.002939	29.394332	0.268538	1299.001465	0.000000	NaN	NaN
592.499889	0.002964	29.641917	0.269319	1299.801514	0.000000	NaN	NaN
593.999975	0.003038	30.384670	0.270098	1300.599365	0.000000	NaN	NaN
595.500061	0.002972	29.724445	0.270719	1301.234375	0.000000	NaN	NaN
597.000146	0.002964	29.641917	0.271359	1301.890137	0.000000	NaN	NaN
598.500232	0.003038	30.384670	0.272068	1302.616211	0.000000	NaN	NaN
599.999318	0.003005	30.054557	0.272764	1303.328979	0.000000	NaN	NaN
601.499404	0.002997	29.972029	0.273496	1304.078491	0.000000	NaN	NaN
602.999490	0.002956	29.559388	0.274140	1304.737915	0.000000	NaN	NaN
604.499575	0.002997	29.972029	0.274816	1305.430542	0.000000	NaN	NaN
605.999661	0.002981	29.806973	0.275470	1306.099731	0.000000	NaN	NaN
607.499747	0.003055	30.549726	0.276236	1306.884521	0.000000	NaN	NaN
608.999833	0.003047	30.467198	0.277081	1307.750122	0.000000	NaN	NaN
610.499919	0.003047	30.467198	0.277658	1308.340332	0.000000	NaN	NaN
612.000004	0.003014	30.137085	0.278384	1309.084351	0.000000	NaN	NaN
613.500090	0.002948	29.476860	0.279108	1309.825562	0.000000	NaN	NaN
615.000176	0.003096	30.962367	0.279758	1310.491211	0.000000	NaN	NaN
616.500262	0.003080	30.797310	0.280497	1311.247925	0.000000	NaN	NaN
617.999347	0.003071	30.714782	0.281383	1312.155273	0.000000	NaN	NaN
619.499433	0.003129	31.292479	0.281995	1312.781738	0.000000	NaN	NaN
620.999519	0.003030	30.302142	0.198697	1227.483643	0.000000	NaN	NaN
622.499605	0.002964	29.641917	0.424987	1459.207764	0.000000	NaN	NaN
623.999691	0.003071	30.714782	0.284182	1315.021240	0.000000	NaN	NaN
625.499777	0.003022	30.219613	0.428414	1462.717285	0.000000	NaN	NaN
626.999862	0.002972	29.724445	0.428080	1462.375122	0.000000	NaN	NaN
628.499948	0.002972	29.724445	0.200322	1229.147217	0.000000	NaN	NaN
630.000034	0.003088	30.879838	0.201169	1230.014282	0.000000	NaN	NaN
631.500120	0.003104	31.044895	0.202698	1231.580566	0.000000	NaN	NaN
633.000205	0.002981	29.806973	0.203190	1232.084229	0.000000	NaN	NaN
634.499291	0.003038	30.384670	0.203992	1232.905029	0.000000	NaN	NaN
635.999377	0.002898	28.981692	0.201948	1230.811890	0.000000	NaN	NaN
637.499463	0.003063	30.632254	0.205503	1234.453003	0.000000	NaN	NaN
638.999549	0.003121	31.209951	0.205147	1234.088379	0.000000	NaN	NaN
640.499635	0.003129	31.292479	0.204973	1233.909546	0.000000	NaN	NaN
641.999720	0.002972	29.724445	0.206571	1235.546631	0.000000	NaN	NaN
643.499806	0.003129	31.292479	0.208228	1237.243286	0.000000	NaN	NaN
644.999892	0.003080	30.797310	0.207964	1236.972900	0.000000	NaN	NaN
646.499978	0.003080	30.797310	0.292324	1323.359009	0.000000	NaN	NaN
648.000064	0.003096	30.962367	0.293047	1324.099121	0.000000	NaN	NaN
649.500149	0.003038	30.384670	0.293787	1324.856689	0.000000	NaN	NaN
651.000235	0.003088	30.879838	0.294476	1325.561890	0.000000	NaN	NaN
652.499321	0.002939	29.394332	0.295182	1326.285278	0.000000	NaN	NaN
653.999407	0.003080	30.797310	0.295688	1326.802979	0.000000	NaN	NaN
655.499492	0.003014	30.137085	0.296708	1327.848267	0.000000	NaN	NaN
656.999578	0.003022	30.219613	0.297415	1328.572510	0.000000	NaN	NaN
658.499664	0.003071	30.714782	0.298175	1329.349731	0.000000	NaN	NaN
659.999750	0.003038	30.384670	0.298533	1329.716919	0.000000	NaN	NaN
661.499836	0.002972	29.724445	0.299090	1330.287354	0.000000	NaN	NaN
662.999921	0.003088	30.879838	0.299641	1330.851196	0.000000	NaN	NaN
664.500007	0.003138	31.375007	0.300465	1331.695068	0.000000	NaN	NaN
666.000093	0.003113	31.127423	0.301096	1332.341553	0.000000	NaN	NaN
667.500179	0.003047	30.467198	0.301727	1332.987671	0.000000	NaN	NaN
669.000265	0.003121	31.209951	0.302473	1333.751465	0.000000	NaN	NaN
670.499350	0.002989	29.889501	0.302877	1334.165405	0.000000	NaN	NaN
671.999436	0.003129	31.292479	0.304427	1335.752319	0.000000	NaN	NaN
673.499522	0.003055	30.549726	0.304977	1336.316040	0.000000	NaN	NaN
674.999608	0.002997	29.972029	0.305639	1336.993164	0.000000	NaN	NaN
676.499694	0.003129	31.292479	0.306223	1337.591064	0.000000	NaN	NaN
677.999779	0.003071	30.714782	0.307138	1338.528931	0.000000	NaN	NaN
679.499865	0.003063	30.632254	0.307650	1339.053223	0.000000	NaN	NaN
680.999951	0.003146	31.457535	0.308387	1339.807495	0.000000	NaN	NaN
682.500037	0.003047	30.467198	0.309204	1340.643921	0.000000	NaN	NaN
684.000122	0.003212	32.117760	0.309797	1341.251343	0.000000	NaN	NaN
685.500208	0.003162	31.622592	0.310427	1341.895996	0.000000	NaN	NaN
686.999294	0.003195	31.952704	0.311317	1342.808105	0.000000	NaN	NaN
688.499380	0.003030	30.302142	0.312033	1343.540649	0.000000	NaN	NaN
689.999466	0.003038	30.384670	0.312577	1344.097778	0.000000	NaN	NaN
691.499552	0.003237	32.365345	0.313327	1344.865845	0.000000	NaN	NaN
692.999637	0.003228	32.282816	0.313995	1345.550415	0.000000	NaN	NaN
694.499723	0.003179	31.787648	0.314840	1346.415649	0.000000	NaN	NaN
695.999809	0.003245	32.447873	0.315413	1347.002319	0.000000	NaN	NaN
697.499895	0.003162	31.622592	0.315981	1347.583618	0.000000	NaN	NaN
698.999980	0.003154	31.540063	0.316852	1348.475830	0.000000	NaN	NaN
700.500066	0.003171	31.705120	0.317520	1349.160156	0.000000	NaN	NaN
702.000152	0.003237	32.365345	0.318359	1350.018433	0.000000	NaN	NaN
703.500238	0.003088	30.879838	0.318982	1350.656860	0.000000	NaN	NaN
704.999324	0.003146	31.457535	0.319712	1351.403931	0.000000	NaN	NaN
706.499409	0.003187	31.870176	0.320165	1351.867920	0.000000	NaN	NaN
707.999495	0.003063	30.632254	0.320961	1352.683838	0.000000	NaN	NaN
709.499581	0.003154	31.540063	0.321695	1353.434692	0.000000	NaN	NaN
710.999667	0.003063	30.632254	0.322355	1354.110474	0.000000	NaN	NaN
712.499753	0.003162	31.622592	0.323085	1354.858032	0.000000	NaN	NaN
713.999838	0.003121	31.209951	0.323615	1355.400879	0.000000	NaN	NaN
715.499924	0.003154	31.540063	0.324433	1356.238525	0.000000	NaN	NaN
717.000010	0.003278	32.777985	0.325142	1356.964600	0.000000	NaN	NaN
718.500096	0.003080	30.797310	0.325725	1357.561401	0.000000	NaN	NaN
720.000182	0.003162	31.622592	0.326475	1358.329834	0.000000	NaN	NaN
721.500267	0.003162	31.622592	0.327180	1359.051514	0.000000	NaN	NaN
722.999353	0.003154	31.540063	0.327811	1359.698242	0.000000	NaN	NaN
724.499439	0.003228	32.282816	0.328564	1360.469116	0.000000	NaN	NaN
725.999525	0.003303	33.025570	0.329087	1361.004517	0.000000	NaN	NaN
727.499611	0.003245	32.447873	0.329918	1361.855713	0.000000	NaN	NaN
728.999696	0.003237	32.365345	0.330607	1362.560791	0.000000	NaN	NaN
730.499782	0.003080	30.797310	0.331173	1363.140869	0.000000	NaN	NaN
731.999868	0.003055	30.549726	0.331771	1363.753052	0.000000	NaN	NaN
733.499954	0.003171	31.705120	0.332501	1364.500732	0.000000	NaN	NaN
735.000040	0.003204	32.035232	0.333208	1365.224854	0.000000	NaN	NaN
736.500125	0.003162	31.622592	0.333798	1365.828491	0.000000	NaN	NaN
738.000211	0.003352	33.520738	0.334547	1366.596069	0.000000	NaN	NaN
739.499297	0.003179	31.787648	0.335145	1367.207886	0.000000	NaN	NaN
740.999383	0.003146	31.457535	0.335885	1367.965820	0.000000	NaN	NaN
742.499469	0.003171	31.705120	0.336472	1368.566895	0.000000	NaN	NaN
743.999554	0.003071	30.714782	0.337059	1369.167480	0.000000	NaN	NaN
745.499640	0.003294	32.943041	0.337803	1369.929443	0.000000	NaN	NaN
746.999726	0.003195	31.952704	0.338386	1370.526733	0.000000	NaN	NaN
748.499812	0.003071	30.714782	0.339069	1371.226074	0.000000	NaN	NaN
749.999897	0.003129	31.292479	0.339636	1371.807129	0.000000	NaN	NaN
751.499983	0.003138	31.375007	0.340337	1372.524780	0.000000	NaN	NaN
753.000069	0.003104	31.044895	0.341077	1373.282593	0.000000	NaN	NaN
754.500155	0.003154	31.540063	0.341680	1373.899780	0.000000	NaN	NaN
756.000241	0.003138	31.375007	0.342243	1374.476074	0.000000	NaN	NaN
757.499327	0.003179	31.787648	0.343000	1375.251953	0.000000	NaN	NaN
758.999412	0.003187	31.870176	0.343688	1375.956299	0.000000	NaN	NaN
760.499498	0.003212	32.117760	0.344280	1376.562622	0.000000	NaN	NaN
761.999584	0.003162	31.622592	0.344900	1377.197266	0.000000	NaN	NaN
763.499670	0.003121	31.209951	0.345497	1377.808716	0.000000	NaN	NaN
764.999755	0.003237	32.365345	0.346180	1378.508301	0.000000	NaN	NaN
766.499841	0.003237	32.365345	0.346855	1379.198853	0.000000	NaN	NaN
767.999927	0.003294	32.943041	0.347619	1379.981812	0.000000	NaN	NaN
769.500013	0.003204	32.035232	0.348226	1380.603149	0.000000	NaN	NaN
771.000099	0.003179	31.787648	0.348860	1381.252808	0.000000	NaN	NaN
772.500185	0.003228	32.282816	0.349521	1381.929565	0.000000	NaN	NaN
774.000270	0.003204	32.035232	0.350192	1382.616089	0.000000	NaN	NaN
775.499356	0.003270	32.695457	0.350921	1383.362793	0.000000	NaN	NaN
776.999442	0.003146	31.457535	0.351355	1383.807251	0.000000	NaN	NaN
778.499528	0.003228	32.282816	0.352051	1384.519897	0.000000	NaN	NaN
779.999613	0.003138	31.375007	0.352759	1385.244507	0.000000	NaN	NaN
781.499699	0.003204	32.035232	0.353261	1385.758667	0.000000	NaN	NaN
782.999785	0.003220	32.200288	0.353797	1386.308105	0.000000	NaN	NaN
784.499871	0.003146	31.457535	0.353717	1386.226440	0.000000	NaN	NaN
785.999957	0.003129	31.292479	0.354423	1386.948975	0.000000	NaN	NaN
787.500042	0.003286	32.860513	0.355097	1387.639404	0.000000	NaN	NaN
789.000128	0.003228	32.282816	0.355611	1388.165649	0.000000	NaN	NaN
790.500214	0.003154	31.540063	0.356229	1388.798828	0.000000	NaN	NaN
791.999300	0.003154	31.540063	0.356944	1389.530151	0.000000	NaN	NaN
793.499386	0.003261	32.612929	0.357534	1390.134644	0.000000	NaN	NaN
794.999471	0.003179	31.787648	0.358204	1390.820557	0.000000	NaN	NaN
796.499557	0.003162	31.622592	0.358894	1391.527344	0.000000	NaN	NaN
797.999643	0.003204	32.035232	0.359353	1391.997070	0.000000	NaN	NaN
799.499729	0.003237	32.365345	0.360107	1392.769775	0.000000	NaN	NaN
800.999814	0.003278	32.777985	0.360739	1393.416992	0.000000	NaN	NaN
802.499900	0.003129	31.292479	0.361521	1394.216919	0.000000	NaN	NaN
803.999986	0.003113	31.127423	0.362138	1394.848999	0.000000	NaN	NaN
805.500072	0.003195	31.952704	0.362713	1395.437622	0.000000	NaN	NaN
807.000158	0.003204	32.035232	0.363245	1395.982422	0.000000	NaN	NaN
808.500244	0.003171	31.705120	0.363885	1396.638672	0.000000	NaN	NaN
809.999329	0.003212	32.117760	0.364514	1397.281982	0.000000	NaN	NaN
811.499415	0.003162	31.622592	0.365170	1397.954346	0.000000	NaN	NaN
812.999501	0.003228	32.282816	0.365768	1398.566162	0.000000	NaN	NaN
814.499587	0.003220	32.200288	0.366422	1399.235718	0.000000	NaN	NaN
815.999672	0.003245	32.447873	0.366938	1399.764160	0.000000	NaN	NaN
817.499758	0.003162	31.622592	0.367789	1400.635498	0.000000	NaN	NaN
818.999844	0.003228	32.282816	0.368152	1401.007935	0.000000	NaN	NaN
820.499930	0.003162	31.622592	0.368884	1401.756958	0.000000	NaN	NaN
822.000016	0.003237	32.365345	0.369506	1402.394287	0.000000	NaN	NaN
823.500102	0.003187	31.870176	0.370080	1402.982178	0.000000	NaN	NaN
825.000187	0.003138	31.375007	0.370869	1403.790039	0.000000	NaN	NaN
826.500273	0.003393	33.933379	0.371453	1404.387817	0.000000	NaN	NaN
827.999359	0.003278	32.777985	0.371906	1404.851562	0.000000	NaN	NaN
829.499445	0.003228	32.282816	0.372685	1405.649170	0.000000	NaN	NaN
830.999530	0.003261	32.612929	0.373198	1406.174683	0.000000	NaN	NaN
832.499616	0.003204	32.035232	0.373823	1406.814697	0.000000	NaN	NaN
833.999702	0.003228	32.282816	0.374537	1407.545532	0.000000	NaN	NaN
835.499788	0.003129	31.292479	0.375110	1408.133057	0.000000	NaN	NaN
836.999874	0.003179	31.787648	0.375701	1408.738403	0.000000	NaN	NaN
838.499959	0.003179	31.787648	0.376474	1409.529785	0.000000	NaN	NaN
840.000045	0.003104	31.044895	0.377096	1410.166260	0.000000	NaN	NaN
841.500131	0.003080	30.797310	0.377640	1410.723145	0.000000	NaN	NaN
843.000217	0.003245	32.447873	0.378218	1411.315430	0.000000	NaN	NaN
844.499303	0.003360	33.603266	0.378912	1412.026001	0.000000	NaN	NaN
845.999388	0.003204	32.035232	0.379853	1412.990234	0.000000	NaN	NaN
847.499474	0.003261	32.612929	0.380378	1413.527710	0.000000	NaN	NaN
848.999560	0.003220	32.200288	0.380987	1414.151123	0.000000	NaN	NaN
850.499646	0.003344	33.438210	0.381902	1415.088257	0.000000	NaN	NaN
851.999732	0.003270	32.695457	0.382505	1415.705566	0.000000	NaN	NaN
853.499817	0.003113	31.127423	0.383147	1416.363281	0.000000	NaN	NaN
854.999903	0.003286	32.860513	0.383585	1416.811035	0.000000	NaN	NaN
856.499989	0.003245	32.447873	0.383584	1416.810425	0.000000	NaN	NaN
858.000075	0.003195	31.952704	0.385275	1418.542114	0.000000	NaN	NaN
859.500161	0.003146	31.457535	0.386034	1419.319092	0.000000	NaN	NaN
861.000246	0.003220	32.200288	0.386742	1420.043823	0.000000	NaN	NaN
862.499332	0.003237	32.365345	0.387407	1420.724854	0.000000	NaN	NaN
863.999418	0.003104	31.044895	0.388060	1421.394165	0.000000	NaN	NaN
865.499504	0.003179	31.787648	0.388659	1422.007080	0.000000	NaN	NaN
866.999589	0.002981	29.806973	0.389222	1422.583252	0.000000	NaN	NaN
868.499675	0.003129	31.292479	0.389696	1423.069336	0.000000	NaN	NaN
869.999761	0.003113	31.127423	0.390358	1423.746704	0.000000	NaN	NaN
871.499847	0.003138	31.375007	0.391155	1424.562622	0.000000	NaN	NaN
872.999933	0.003104	31.044895	0.391782	1425.205200	0.000000	NaN	NaN
874.500019	0.003138	31.375007	0.392310	1425.745972	0.000000	NaN	NaN
876.000104	0.003237	32.365345	0.393114	1426.568726	0.000000	NaN	NaN
877.500190	0.003121	31.209951	0.393630	1427.097046	0.000000	NaN	NaN
879.000276	0.003113	31.127423	0.394354	1427.838867	0.000000	NaN	NaN
880.499362	0.003055	30.549726	0.395219	1428.724854	0.000000	NaN	NaN
881.999447	0.002948	29.476860	0.395780	1429.299194	0.000000	NaN	NaN
883.499533	0.003138	31.375007	0.396495	1430.031372	0.000000	NaN	NaN
884.999619	0.003212	32.117760	0.397160	1430.712158	0.000000	NaN	NaN
886.499705	0.003220	32.200288	0.397951	1431.522339	0.000000	NaN	NaN
887.999791	0.003055	30.549726	0.398616	1432.203125	0.000000	NaN	NaN
889.499877	0.003204	32.035232	0.399345	1432.949829	0.000000	NaN	NaN
890.999962	0.003187	31.870176	0.400085	1433.707275	0.000000	NaN	NaN
892.500048	0.003195	31.952704	0.400906	1434.547974	0.000000	NaN	NaN
894.000134	0.003088	30.879838	0.401603	1435.261719	0.000000	NaN	NaN
895.500220	0.003129	31.292479	0.402187	1435.859619	0.000000	NaN	NaN
896.999305	0.003104	31.044895	0.402869	1436.557983	0.000000	NaN	NaN
898.499391	0.003195	31.952704	0.403797	1437.508179	0.000000	NaN	NaN
899.999477	0.003195	31.952704	0.404334	1438.058960	0.000000	NaN	NaN
901.499563	0.003022	30.219613	0.405231	1438.976807	0.000000	NaN	NaN
902.999649	0.003038	30.384670	0.405941	1439.704468	0.000000	NaN	NaN
904.499734	0.003063	30.632254	0.406701	1440.482178	0.000000	NaN	NaN
905.999820	0.002972	29.724445	0.407452	1441.251709	0.000000	NaN	NaN
907.499906	0.003038	30.384670	0.408245	1442.063599	0.000000	NaN	NaN
908.999992	0.003047	30.467198	0.408970	1442.806274	0.000000	NaN	NaN
910.500078	0.003047	30.467198	0.409793	1443.649048	0.000000	NaN	NaN
912.000163	0.002956	29.559388	0.410654	1444.530396	0.000000	NaN	NaN
913.500249	0.003014	30.137085	0.411340	1445.232666	0.000000	NaN	NaN
914.999335	0.003005	30.054557	0.412372	1446.289551	0.000000	NaN	NaN
916.499421	0.003022	30.219613	0.413365	1447.306396	0.000000	NaN	NaN
917.999507	0.003030	30.302142	0.414125	1448.084839	0.000000	NaN	NaN
919.499592	0.002898	28.981692	0.415007	1448.987549	0.000000	NaN	NaN
920.999678	0.002832	28.321467	0.416074	1450.080688	0.000000	NaN	NaN
922.499764	0.002857	28.569051	0.416823	1450.847534	0.000000	NaN	NaN
923.999850	0.002807	28.073882	0.417994	1452.046997	0.000000	NaN	NaN
925.499936	0.002791	27.908826	0.418889	1452.962891	0.000000	NaN	NaN
927.000021	0.002865	28.651579	0.420001	1454.101807	0.000000	NaN	NaN
928.500107	0.002832	28.321467	0.421107	1455.234863	0.000000	NaN	NaN
930.000193	0.002733	27.331129	0.422463	1456.622559	0.000000	NaN	NaN
931.499279	0.002708	27.083545	0.423511	1457.695801	0.000000	NaN	NaN
932.999364	0.002832	28.321467	0.424736	1458.950806	0.000000	NaN	NaN
934.499450	0.002717	27.166073	0.425855	1460.096680	0.000000	NaN	NaN
935.999536	0.002494	24.937813	0.427168	1461.440552	0.000000	NaN	NaN
937.499622	0.002576	25.763095	0.428435	1462.738770	0.000000	NaN	NaN
938.999708	0.002453	24.525173	0.429868	1464.205566	0.000000	NaN	NaN
940.499794	0.002510	25.102870	0.431235	1465.606079	0.000000	NaN	NaN
941.999879	0.002494	24.937813	0.432979	1467.391235	0.000000	NaN	NaN
943.499965	0.002444	24.442645	0.434160	1468.600586	0.000000	NaN	NaN
945.000051	0.002320	23.204723	0.436103	1470.590576	0.000000	NaN	NaN
946.500137	0.002155	21.554160	0.437721	1472.247314	0.000000	NaN	NaN
948.000222	-0.000329	-3.286806	0.439910	1474.489258	0.000000	NaN	NaN
949.499308	-0.000254	-2.544052	-0.041361	981.660034	0.000000	NaN	NaN
950.999394	0.000133	1.334770	-0.091747	930.063965	0.000000	NaN	NaN
952.499480	-0.000279	-2.791637	-0.091002	930.827332	0.000000	NaN	NaN
953.999566	-0.000312	-3.121749	-0.092049	929.754700	0.000000	NaN	NaN
955.499651	-0.000395	-3.947031	-0.091791	930.019348	0.000000	NaN	NaN
956.999737	-0.000238	-2.378996	0.201450	1230.302124	0.000000	NaN	NaN
958.499823	-0.000114	-1.141074	0.211432	1240.524414	0.000000	NaN	NaN
959.999909	-0.000287	-2.874165	0.216605	1245.821533	0.000000	NaN	NaN
961.499995	-0.000386	-3.864503	0.138388	1165.726318	0.000000	NaN	NaN
963.000080	-0.000477	-4.772312	0.679889	1720.231323	0.000000	NaN	NaN
964.500166	-5.633774E-5	-0.563377	0.680123	1720.470581	0.000000	NaN	NaN
966.000252	-9.760180E-5	-0.976018	0.295940	1327.061646	0.000000	NaN	NaN
967.499338	-0.000304	-3.039221	0.683902	1724.340210	0.000000	NaN	NaN
968.499395	-0.000312	-3.121749	0.684039	1724.481079	0.000000	NaN	NaN