File: data/57k_15-1_3 (190321).lvm
LabVIEW Measurement
Writer_Version	2
Reader_Version	2
Separator	Tab
Decimal_Separator	.
Multi_Headings	No
X_Columns	One
Time_Pref	Absolute
Operator	user
Description	Load(N)/Stress(MPa)/Distance A(pixel)/Strain A/Distance B(pixel)/Strain B/Poisson's ratio
Date	2019/03/21
Time	10:49:41.3064441680908203125
***End_of_Header***

Notes	X 값은 오직 다음과 같을 때에만 유효함이 보장됩니다. Dev1/ai0
Channels	7
Samples	1	1	1	1	1	1	1
Date	2019/03/21	2019/03/21	2019/03/21	2019/03/21	2019/03/21	2019/03/21	2019/03/21
Time	11:15:16.3062414300349944613	11:15:16.3062414300349944613	11:15:16.3062415122985839844	11:15:16.3062415122985839844	11:15:16.3062415122985839844	11:15:16.3062415122985839844	11:15:16.3062415122985839844
Y_Unit_Label	Volts	Volts
X_Dimension	Time	Time	Time	Time	Time	Time	Time
X0	0.0000000000000000E+0	0.0000000000000000E+0	0.0000000000000000E+0	0.0000000000000000E+0	0.0000000000000000E+0	0.0000000000000000E+0	0.0000000000000000E+0
Delta_X	0.000000	0.000000	1.000000	1.000000	1.000000	1.000000	1.000000
***End_of_Header***
X_Value	Dev1/ai0	Dev1/ai0 1	Untitled	Untitled 1	Untitled 2	Untitled 3	Untitled 4	Comment
0.000000	-4.808493E-5	-0.480849	-3.629923E-5	956.324219	0.000000	NaN	NaN
1.500086	-0.000180	-1.801299	-2.938509E-5	956.330872	0.000000	NaN	NaN
3.000172	0.000109	1.087185	-4.553795E-5	956.315369	0.000000	NaN	NaN
4.500257	1.431948E-6	0.014319	0.000322	956.666565	0.000000	NaN	NaN
5.999343	0.000142	1.417298	0.000760	957.086243	0.000000	NaN	NaN
7.499429	0.000125	1.252241	0.001213	957.518799	0.000000	NaN	NaN
8.999515	0.000299	2.985332	0.001727	958.010803	0.000000	NaN	NaN
10.499600	0.000249	2.490163	0.002177	958.441406	0.000000	NaN	NaN
11.999686	0.000282	2.820276	0.002641	958.884399	0.000000	NaN	NaN
13.499772	0.000356	3.563029	0.002943	959.173401	0.000000	NaN	NaN
14.999858	0.000373	3.728085	0.003253	959.470154	0.000000	NaN	NaN
16.499944	0.000472	4.718423	0.003566	959.769104	0.000000	NaN	NaN
18.000030	0.000480	4.800951	0.003888	960.077454	0.000000	NaN	NaN
19.500115	0.000431	4.305782	0.004182	960.358154	0.000000	NaN	NaN
21.000201	0.000414	4.140726	0.004469	960.632507	0.000000	NaN	NaN
22.499287	0.000340	3.397973	0.004730	960.882385	0.000000	NaN	NaN
23.999373	0.000530	5.296120	0.005026	961.165161	0.000000	NaN	NaN
25.499458	0.000629	6.286457	0.005366	961.490845	0.000000	NaN	NaN
26.999544	0.000521	5.213591	0.005655	961.767212	0.000000	NaN	NaN
28.499630	0.000761	7.606907	0.005994	962.091003	0.000000	NaN	NaN
29.999716	0.000695	6.946682	0.006342	962.423828	0.000000	NaN	NaN
31.499802	0.000827	8.267132	0.006734	962.799377	0.000000	NaN	NaN
32.999887	0.000777	7.771963	0.007076	963.126038	0.000000	NaN	NaN
34.499973	0.000769	7.689435	0.007469	963.501648	0.000000	NaN	NaN
36.000059	0.000810	8.102076	0.007896	963.909973	0.000000	NaN	NaN
37.500145	0.000917	9.174942	0.008345	964.339539	0.000000	NaN	NaN
39.000231	0.000843	8.432188	0.008846	964.818481	0.000000	NaN	NaN
40.499316	0.000876	8.762301	0.009268	965.222107	0.000000	NaN	NaN
41.999402	0.000901	9.009885	0.009768	965.700317	0.000000	NaN	NaN
43.499488	0.000917	9.174942	0.010378	966.283691	0.000000	NaN	NaN
44.999574	0.000967	9.670110	0.010823	966.709351	0.000000	NaN	NaN
46.499660	0.001008	10.082751	0.011306	967.171753	0.000000	NaN	NaN
47.999745	0.001132	11.320673	0.011819	967.662476	0.000000	NaN	NaN
49.499831	0.001231	12.311010	0.012413	968.229797	0.000000	NaN	NaN
50.999917	0.001116	11.155617	0.012996	968.788147	0.000000	NaN	NaN
52.500003	0.001099	10.990560	0.013474	969.244629	0.000000	NaN	NaN
54.000089	0.001231	12.311010	0.014133	969.875122	0.000000	NaN	NaN
55.500174	0.001132	11.320673	0.014653	970.372437	0.000000	NaN	NaN
57.000260	0.001140	11.403201	0.015266	970.958740	0.000000	NaN	NaN
58.499346	0.001248	12.476067	0.015879	971.545044	0.000000	NaN	NaN
59.999432	0.001041	10.412863	0.016585	972.220215	0.000000	NaN	NaN
61.499517	0.001223	12.228482	0.017225	972.832458	0.000000	NaN	NaN
62.999603	0.001239	12.393538	0.017568	973.160522	0.000000	NaN	NaN
64.499689	0.001281	12.806179	0.018315	973.874451	0.000000	NaN	NaN
65.999775	0.001338	13.383876	0.018986	974.515869	0.000000	NaN	NaN
67.499861	0.001446	14.456742	0.019632	975.134033	0.000000	NaN	NaN
68.999946	0.001371	13.713988	0.020336	975.807800	0.000000	NaN	NaN
70.500032	0.001396	13.961573	0.020934	976.379639	0.000000	NaN	NaN
72.000118	0.001545	15.447079	0.021320	976.748291	0.000000	NaN	NaN
73.500204	0.001454	14.539270	0.021957	977.357544	0.000000	NaN	NaN
74.999290	0.001413	14.126629	0.022591	977.964478	0.000000	NaN	NaN
76.499375	0.001487	14.869382	0.023301	978.642700	0.000000	NaN	NaN
77.999461	0.001470	14.704326	0.024009	979.320312	0.000000	NaN	NaN
79.499547	0.001437	14.374213	0.024781	980.058960	0.000000	NaN	NaN
80.999633	0.001528	15.282023	0.025460	980.707825	0.000000	NaN	NaN
82.499719	0.001479	14.786854	0.026165	981.382507	0.000000	NaN	NaN
83.999804	0.001619	16.189832	0.025998	981.222595	0.000000	NaN	NaN
85.499890	0.001569	15.694663	0.026736	981.928223	0.000000	NaN	NaN
86.999976	0.001685	16.850057	0.027380	982.543579	0.000000	NaN	NaN
88.500062	0.001545	15.447079	0.028156	983.286377	0.000000	NaN	NaN
90.000148	0.001611	16.107304	0.028786	983.888245	0.000000	NaN	NaN
91.500233	0.001635	16.354889	0.029541	984.610596	0.000000	NaN	NaN
92.999319	0.001693	16.932585	0.030210	985.250671	0.000000	NaN	NaN
94.499405	0.001528	15.282023	0.030924	985.933655	0.000000	NaN	NaN
95.999491	0.001627	16.272360	0.031748	986.721375	0.000000	NaN	NaN
97.499577	0.001669	16.685001	0.032478	987.419312	0.000000	NaN	NaN
98.999662	0.001536	15.364551	0.033140	988.052551	0.000000	NaN	NaN
100.499748	0.001619	16.189832	0.033848	988.729370	0.000000	NaN	NaN
101.999834	0.001635	16.354889	0.034601	989.449951	0.000000	NaN	NaN
103.499920	0.001702	17.015114	0.035178	990.001770	0.000000	NaN	NaN
105.000006	0.001768	17.675339	0.036003	990.790833	0.000000	NaN	NaN
106.500091	0.001693	16.932585	0.036716	991.472107	0.000000	NaN	NaN
108.000177	0.001743	17.427754	0.037419	992.145142	0.000000	NaN	NaN
109.500263	0.001685	16.850057	0.038226	992.916382	0.000000	NaN	NaN
110.999349	0.001718	17.180170	0.038993	993.650330	0.000000	NaN	NaN
112.499435	0.001817	18.170507	0.039706	994.332336	0.000000	NaN	NaN
113.999520	0.001817	18.170507	0.040447	995.040710	0.000000	NaN	NaN
115.499606	0.001726	17.262698	0.042194	996.712036	0.000000	NaN	NaN
116.999692	0.001825	18.253035	0.042952	997.436646	0.000000	NaN	NaN
118.499778	0.001677	16.767529	0.043691	998.143188	0.000000	NaN	NaN
119.999864	0.001660	16.602473	0.044388	998.809509	0.000000	NaN	NaN
121.499949	0.001834	18.335564	0.045297	999.679321	0.000000	NaN	NaN
123.000035	0.001817	18.170507	0.045926	1000.280640	0.000000	NaN	NaN
124.500121	0.001677	16.767529	0.046757	1001.075684	0.000000	NaN	NaN
126.000207	0.001809	18.087979	0.047335	1001.627869	0.000000	NaN	NaN
127.499292	0.001743	17.427754	0.048224	1002.478516	0.000000	NaN	NaN
128.999378	0.001850	18.500620	0.048803	1003.032043	0.000000	NaN	NaN
130.499464	0.001735	17.345226	0.049707	1003.896240	0.000000	NaN	NaN
131.999550	0.001726	17.262698	0.050268	1004.433167	0.000000	NaN	NaN
133.499636	0.001718	17.180170	0.050980	1005.113831	0.000000	NaN	NaN
134.999721	0.001710	17.097642	0.051779	1005.878052	0.000000	NaN	NaN
136.499807	0.001726	17.262698	0.052520	1006.587341	0.000000	NaN	NaN
137.999893	0.001908	19.078317	0.053257	1007.291687	0.000000	NaN	NaN
139.499979	0.001726	17.262698	0.053909	1007.915344	0.000000	NaN	NaN
141.000065	0.001933	19.325901	0.054704	1008.675964	0.000000	NaN	NaN
142.500150	0.001710	17.097642	0.055343	1009.286377	0.000000	NaN	NaN
144.000236	0.001825	18.253035	0.056326	1010.226685	0.000000	NaN	NaN
145.499322	0.001941	19.408429	0.056871	1010.747742	0.000000	NaN	NaN
146.999408	0.001726	17.262698	0.057807	1011.643066	0.000000	NaN	NaN
148.499494	0.001875	18.748204	0.058409	1012.219055	0.000000	NaN	NaN
149.999579	0.001809	18.087979	0.059252	1013.025208	0.000000	NaN	NaN
151.499665	0.001858	18.583148	0.059901	1013.646240	0.000000	NaN	NaN
152.999751	0.001908	19.078317	0.060553	1014.269470	0.000000	NaN	NaN
154.499837	0.001825	18.253035	0.061323	1015.005676	0.000000	NaN	NaN
155.999923	0.001916	19.160845	0.062056	1015.706543	0.000000	NaN	NaN
157.500008	0.001966	19.656014	0.062742	1016.362671	0.000000	NaN	NaN
159.000094	0.001768	17.675339	0.063393	1016.985474	0.000000	NaN	NaN
160.500180	0.001900	18.995789	0.064359	1017.909363	0.000000	NaN	NaN
162.000266	0.001751	17.510282	0.065141	1018.657410	0.000000	NaN	NaN
163.499352	0.001792	17.922923	0.065835	1019.321045	0.000000	NaN	NaN
164.999437	0.001850	18.500620	0.066472	1019.930298	0.000000	NaN	NaN
166.499523	0.001817	18.170507	0.067397	1020.814819	0.000000	NaN	NaN
167.999609	0.001867	18.665676	0.067972	1021.364197	0.000000	NaN	NaN
169.499695	0.001768	17.675339	0.068956	1022.305237	0.000000	NaN	NaN
170.999781	0.001801	18.005451	0.069472	1022.798889	0.000000	NaN	NaN
172.499866	0.001792	17.922923	0.070378	1023.665283	0.000000	NaN	NaN
173.999952	0.001941	19.408429	0.070972	1024.234009	0.000000	NaN	NaN
175.500038	0.001702	17.015114	0.071652	1024.883545	0.000000	NaN	NaN
177.000124	0.001751	17.510282	0.072438	1025.635498	0.000000	NaN	NaN
178.500210	0.001792	17.922923	-0.057585	901.286621	0.000000	NaN	NaN
179.999295	0.001875	18.748204	-0.056055	902.750305	0.000000	NaN	NaN
181.499381	0.001999	19.986126	-0.057949	900.938843	0.000000	NaN	NaN
182.999467	0.001858	18.583148	-0.056237	902.576050	0.000000	NaN	NaN
184.499553	0.001916	19.160845	-0.056723	902.111633	0.000000	NaN	NaN
185.999639	0.001702	17.015114	-0.058221	900.678406	0.000000	NaN	NaN
187.499724	0.001924	19.243373	-0.059292	899.654663	0.000000	NaN	NaN
188.999810	0.001908	19.078317	0.560867	1492.749512	0.000000	NaN	NaN
190.499896	0.001627	16.272360	0.560732	1492.620483	0.000000	NaN	NaN
191.999982	0.001957	19.573485	0.560698	1492.587280	0.000000	NaN	NaN
193.500067	0.001891	18.913260	0.560696	1492.585571	0.000000	NaN	NaN
195.000153	0.001858	18.583148	0.560624	1492.516846	0.000000	NaN	NaN
196.500239	0.001891	18.913260	0.560636	1492.528442	0.000000	NaN	NaN
197.999325	0.001949	19.490957	0.560544	1492.440063	0.000000	NaN	NaN
199.499411	0.001801	18.005451	0.082921	1035.660767	0.000000	NaN	NaN
200.999496	0.002081	20.811407	-0.061136	897.890686	0.000000	NaN	NaN
202.499582	0.001825	18.253035	-0.060033	898.945557	0.000000	NaN	NaN
203.999668	0.001809	18.087979	-0.060729	898.280457	0.000000	NaN	NaN
205.499754	0.001949	19.490957	0.085911	1038.520996	0.000000	NaN	NaN
206.999840	0.001990	19.903598	-0.060816	898.196838	0.000000	NaN	NaN
208.499925	0.001949	19.490957	-0.062240	896.835205	0.000000	NaN	NaN
210.000011	0.001834	18.335564	-0.062774	896.324524	0.000000	NaN	NaN
211.500097	0.001974	19.738542	-0.062835	896.266052	0.000000	NaN	NaN
213.000183	0.001875	18.748204	-0.061970	897.093323	0.000000	NaN	NaN
214.500269	0.001957	19.573485	-0.061634	897.414917	0.000000	NaN	NaN
215.999354	0.001999	19.986126	-0.063437	895.690369	0.000000	NaN	NaN
217.499440	0.001933	19.325901	-0.062407	896.675354	0.000000	NaN	NaN
218.999526	0.001784	17.840395	-0.064043	895.110718	0.000000	NaN	NaN
220.499612	0.001924	19.243373	0.093348	1045.633057	0.000000	NaN	NaN
221.999698	0.001990	19.903598	0.094108	1046.360352	0.000000	NaN	NaN
223.499783	0.001941	19.408429	0.094808	1047.029419	0.000000	NaN	NaN
224.999869	0.001974	19.738542	0.095539	1047.729004	0.000000	NaN	NaN
226.499955	0.001867	18.665676	0.096300	1048.455933	0.000000	NaN	NaN
228.000041	0.001924	19.243373	0.097074	1049.196411	0.000000	NaN	NaN
229.500127	0.001974	19.738542	0.097825	1049.915161	0.000000	NaN	NaN
231.000212	0.002098	20.976463	0.098605	1050.661011	0.000000	NaN	NaN
232.499298	0.002032	20.316239	0.099391	1051.412231	0.000000	NaN	NaN
233.999384	0.002023	20.233710	0.100075	1052.067017	0.000000	NaN	NaN
235.499470	0.001966	19.656014	0.100796	1052.755859	0.000000	NaN	NaN
236.999556	0.001883	18.830732	0.101590	1053.515137	0.000000	NaN	NaN
238.499641	0.001974	19.738542	0.102369	1054.260254	0.000000	NaN	NaN
239.999727	0.002007	20.068654	0.103198	1055.053223	0.000000	NaN	NaN
241.499813	0.001999	19.986126	0.103606	1055.443115	0.000000	NaN	NaN
243.136907	0.001990	19.903598	0.104609	1056.403076	0.000000	NaN	NaN
244.499985	0.001891	18.913260	0.105417	1057.175171	0.000000	NaN	NaN
246.000070	0.001957	19.573485	0.106153	1057.879395	0.000000	NaN	NaN
247.500156	0.002065	20.646351	0.106862	1058.557495	0.000000	NaN	NaN
249.000242	0.001999	19.986126	0.107660	1059.320190	0.000000	NaN	NaN
250.499328	0.002065	20.646351	0.108333	1059.964600	0.000000	NaN	NaN
251.999414	0.001834	18.335564	0.109123	1060.719971	0.000000	NaN	NaN
253.499499	0.001982	19.821070	0.109904	1061.466553	0.000000	NaN	NaN
254.999585	0.001982	19.821070	0.110647	1062.176880	0.000000	NaN	NaN
256.499671	0.001941	19.408429	0.111386	1062.883545	0.000000	NaN	NaN
257.999757	0.001982	19.821070	0.112162	1063.625854	0.000000	NaN	NaN
259.499842	0.001941	19.408429	0.112822	1064.257202	0.000000	NaN	NaN
260.999928	0.001957	19.573485	0.113558	1064.961304	0.000000	NaN	NaN
262.500014	0.002007	20.068654	0.114329	1065.697998	0.000000	NaN	NaN
264.000100	0.002023	20.233710	0.115035	1066.373779	0.000000	NaN	NaN
265.500186	0.002023	20.233710	0.115752	1067.059692	0.000000	NaN	NaN
267.000271	0.001966	19.656014	0.116526	1067.799438	0.000000	NaN	NaN
268.499357	0.001867	18.665676	0.117201	1068.445312	0.000000	NaN	NaN
269.999443	0.001867	18.665676	0.117995	1069.204712	0.000000	NaN	NaN
271.499529	0.001941	19.408429	0.118731	1069.908691	0.000000	NaN	NaN
272.999615	0.002032	20.316239	0.119535	1070.677124	0.000000	NaN	NaN
274.499700	0.001941	19.408429	0.115415	1066.737183	0.000000	NaN	NaN
275.999786	0.002122	21.224048	0.116188	1067.476074	0.000000	NaN	NaN
277.499872	0.002089	20.893935	0.116729	1067.993896	0.000000	NaN	NaN
278.999958	0.002089	20.893935	0.117498	1068.729248	0.000000	NaN	NaN
280.500044	0.001891	18.913260	0.118231	1069.430542	0.000000	NaN	NaN
282.000129	0.002040	20.398767	0.118974	1070.141113	0.000000	NaN	NaN
283.500215	0.002007	20.068654	0.119725	1070.858643	0.000000	NaN	NaN
284.999301	0.002073	20.728879	0.120444	1071.546997	0.000000	NaN	NaN
286.499387	0.001974	19.738542	0.121230	1072.298462	0.000000	NaN	NaN
287.999473	0.001941	19.408429	0.121906	1072.945068	0.000000	NaN	NaN
289.499558	0.002106	21.058992	0.122715	1073.718262	0.000000	NaN	NaN
290.999644	0.002081	20.811407	0.123426	1074.398560	0.000000	NaN	NaN
292.499730	0.001891	18.913260	0.124101	1075.044312	0.000000	NaN	NaN
293.999816	0.002122	21.224048	0.124780	1075.693848	0.000000	NaN	NaN
295.499902	0.002015	20.151182	0.125543	1076.423340	0.000000	NaN	NaN
297.084992	0.002081	20.811407	0.126264	1077.113037	0.000000	NaN	NaN
298.500073	0.002155	21.554160	0.127039	1077.853882	0.000000	NaN	NaN
300.000159	0.002081	20.811407	0.127757	1078.540894	0.000000	NaN	NaN
301.500245	0.002155	21.554160	0.128428	1079.182373	0.000000	NaN	NaN
302.999330	0.002147	21.471632	0.129234	1079.952881	0.000000	NaN	NaN
304.499416	0.002089	20.893935	0.129823	1080.516602	0.000000	NaN	NaN
305.999502	0.002056	20.563823	0.130628	1081.286377	0.000000	NaN	NaN
307.499588	0.002073	20.728879	0.131398	1082.022339	0.000000	NaN	NaN
308.999674	0.002081	20.811407	0.132220	1082.808594	0.000000	NaN	NaN
310.499759	0.002139	21.389104	0.132867	1083.427002	0.000000	NaN	NaN
311.999845	0.002073	20.728879	0.133686	1084.210693	0.000000	NaN	NaN
313.499931	0.002180	21.801745	0.134403	1084.896118	0.000000	NaN	NaN
315.000017	0.002164	21.636688	0.135081	1085.545044	0.000000	NaN	NaN
316.500103	0.002155	21.554160	0.135847	1086.277710	0.000000	NaN	NaN
318.000188	0.002089	20.893935	0.136549	1086.948364	0.000000	NaN	NaN
319.500274	0.002098	20.976463	0.137348	1087.712524	0.000000	NaN	NaN
320.999360	0.002238	22.379442	0.138072	1088.405273	0.000000	NaN	NaN
322.499446	0.002155	21.554160	0.138932	1089.227539	0.000000	NaN	NaN
323.999532	0.002139	21.389104	0.139624	1089.890015	0.000000	NaN	NaN
325.499617	0.002180	21.801745	0.140392	1090.623779	0.000000	NaN	NaN
326.999703	0.002155	21.554160	0.141141	1091.340332	0.000000	NaN	NaN
328.499789	0.002188	21.884273	0.141744	1091.917358	0.000000	NaN	NaN
329.999875	0.002164	21.636688	0.142569	1092.705811	0.000000	NaN	NaN
331.499961	0.002114	21.141520	0.143235	1093.343018	0.000000	NaN	NaN
333.000046	0.002106	21.058992	0.144053	1094.124878	0.000000	NaN	NaN
334.500132	0.002023	20.233710	0.144793	1094.833008	0.000000	NaN	NaN
336.000218	0.002015	20.151182	0.145550	1095.556885	0.000000	NaN	NaN
337.499304	0.002155	21.554160	0.146245	1096.222168	0.000000	NaN	NaN
338.999390	0.002131	21.306576	0.147045	1096.986938	0.000000	NaN	NaN
340.499475	0.002023	20.233710	0.147712	1097.624512	0.000000	NaN	NaN
341.999561	0.001990	19.903598	0.148388	1098.271484	0.000000	NaN	NaN
343.499647	0.002263	22.627026	0.149188	1099.036011	0.000000	NaN	NaN
344.999733	0.002320	23.204723	0.149832	1099.652466	0.000000	NaN	NaN
346.499819	0.002230	22.296913	0.150622	1100.407959	0.000000	NaN	NaN
347.999904	0.002081	20.811407	0.151375	1101.127563	0.000000	NaN	NaN
349.499990	0.002180	21.801745	0.152165	1101.883667	0.000000	NaN	NaN
351.000076	0.002131	21.306576	0.152902	1102.588501	0.000000	NaN	NaN
352.500162	0.002114	21.141520	0.153739	1103.388916	0.000000	NaN	NaN
354.000248	0.002040	20.398767	0.154421	1104.040894	0.000000	NaN	NaN
355.499333	0.002180	21.801745	0.155106	1104.695923	0.000000	NaN	NaN
356.999419	0.002081	20.811407	0.155879	1105.434814	0.000000	NaN	NaN
358.499505	0.002065	20.646351	0.156510	1106.038208	0.000000	NaN	NaN
359.999591	0.002048	20.481295	0.157260	1106.756104	0.000000	NaN	NaN
361.499677	0.002172	21.719217	0.157917	1107.384766	0.000000	NaN	NaN
362.999762	0.002164	21.636688	0.159180	1108.592529	0.000000	NaN	NaN
364.499848	0.002098	20.976463	0.159819	1109.203613	0.000000	NaN	NaN
365.999934	0.002073	20.728879	0.160620	1109.968994	0.000000	NaN	NaN
367.500020	0.002139	21.389104	0.161317	1110.635986	0.000000	NaN	NaN
369.000106	0.002230	22.296913	0.162082	1111.367310	0.000000	NaN	NaN
370.500191	0.002147	21.471632	0.162775	1112.029907	0.000000	NaN	NaN
371.999277	0.002213	22.131857	0.163454	1112.680054	0.000000	NaN	NaN
373.499363	0.002073	20.728879	0.164168	1113.362793	0.000000	NaN	NaN
374.999449	0.002213	22.131857	0.164908	1114.070435	0.000000	NaN	NaN
376.499534	0.002205	22.049329	0.165590	1114.722290	0.000000	NaN	NaN
377.999620	0.002164	21.636688	0.166319	1115.420044	0.000000	NaN	NaN
379.499706	0.002188	21.884273	0.167041	1116.109863	0.000000	NaN	NaN
380.999792	0.002164	21.636688	0.167750	1116.788452	0.000000	NaN	NaN
382.499878	0.002188	21.884273	0.168519	1117.523682	0.000000	NaN	NaN
383.999963	0.002271	22.709554	0.169219	1118.193115	0.000000	NaN	NaN
385.500049	0.002271	22.709554	0.170018	1118.957520	0.000000	NaN	NaN
387.000135	0.002287	22.874610	0.170686	1119.596191	0.000000	NaN	NaN
388.500221	0.002188	21.884273	0.171400	1120.279053	0.000000	NaN	NaN
389.999307	0.002254	22.544498	0.172203	1121.046997	0.000000	NaN	NaN
391.499392	0.002362	23.617363	0.172934	1121.746216	0.000000	NaN	NaN
392.999478	0.002188	21.884273	0.173717	1122.494751	0.000000	NaN	NaN
394.499564	0.002032	20.316239	0.174490	1123.234375	0.000000	NaN	NaN
395.999650	0.002337	23.369779	0.175197	1123.909912	0.000000	NaN	NaN
397.499736	0.002296	22.957138	0.175848	1124.533081	0.000000	NaN	NaN
398.999821	0.002139	21.389104	0.176620	1125.270752	0.000000	NaN	NaN
400.499907	0.002345	23.452307	0.177362	1125.980347	0.000000	NaN	NaN
401.999993	0.002197	21.966801	0.178087	1126.673950	0.000000	NaN	NaN
403.500079	0.002238	22.379442	0.178781	1127.337769	0.000000	NaN	NaN
405.000165	0.002296	22.957138	0.179515	1128.039795	0.000000	NaN	NaN
406.500250	0.002188	21.884273	0.180225	1128.718262	0.000000	NaN	NaN
407.999336	0.002197	21.966801	0.181010	1129.469116	0.000000	NaN	NaN
409.499422	0.002287	22.874610	0.181704	1130.133545	0.000000	NaN	NaN
410.999508	0.002254	22.544498	0.182386	1130.785400	0.000000	NaN	NaN
412.499594	0.002411	24.112532	0.183149	1131.515259	0.000000	NaN	NaN
413.999679	0.002329	23.287251	0.183787	1132.125122	0.000000	NaN	NaN
415.499765	0.002287	22.874610	0.184498	1132.805542	0.000000	NaN	NaN
416.999851	0.002312	23.122195	0.185243	1133.517578	0.000000	NaN	NaN
418.499937	0.002089	20.893935	0.185985	1134.227661	0.000000	NaN	NaN
420.000023	0.002139	21.389104	0.186739	1134.948730	0.000000	NaN	NaN
421.500108	0.002221	22.214385	0.187429	1135.608276	0.000000	NaN	NaN
423.000194	0.002122	21.224048	0.188026	1136.179321	0.000000	NaN	NaN
424.499280	0.002337	23.369779	0.188850	1136.967651	0.000000	NaN	NaN
425.999366	0.002296	22.957138	0.189548	1137.635132	0.000000	NaN	NaN
427.499451	0.002296	22.957138	0.190268	1138.323486	0.000000	NaN	NaN
428.999537	0.002263	22.627026	0.190958	1138.983398	0.000000	NaN	NaN
430.499623	0.002172	21.719217	0.191676	1139.670410	0.000000	NaN	NaN
431.999709	0.002395	23.947476	0.192380	1140.343018	0.000000	NaN	NaN
433.499795	0.002329	23.287251	0.193068	1141.001587	0.000000	NaN	NaN
434.999881	0.002246	22.461970	0.193784	1141.685669	0.000000	NaN	NaN
436.499966	0.002312	23.122195	0.194495	1142.366211	0.000000	NaN	NaN
438.000052	0.002089	20.893935	0.195237	1143.075317	0.000000	NaN	NaN
439.500138	0.002279	22.792082	0.195917	1143.725586	0.000000	NaN	NaN
441.000224	0.002205	22.049329	0.196615	1144.393066	0.000000	NaN	NaN
442.499309	0.002345	23.452307	0.197322	1145.069336	0.000000	NaN	NaN
443.999395	0.002304	23.039667	0.198034	1145.750610	0.000000	NaN	NaN
445.499481	0.002263	22.627026	0.198744	1146.429932	0.000000	NaN	NaN
446.999567	0.002263	22.627026	0.199398	1147.055298	0.000000	NaN	NaN
448.499653	0.002164	21.636688	0.200107	1147.733521	0.000000	NaN	NaN
449.999738	0.002155	21.554160	0.200786	1148.382080	0.000000	NaN	NaN
451.499824	0.002188	21.884273	0.201456	1149.023071	0.000000	NaN	NaN
452.999910	0.002378	23.782420	0.202190	1149.725342	0.000000	NaN	NaN
454.499996	0.002263	22.627026	0.202927	1150.429932	0.000000	NaN	NaN
456.000082	0.002304	23.039667	0.203560	1151.035522	0.000000	NaN	NaN
457.500167	0.002362	23.617363	0.204247	1151.692749	0.000000	NaN	NaN
459.000253	0.002320	23.204723	0.204956	1152.369995	0.000000	NaN	NaN
460.499339	0.002320	23.204723	0.205709	1153.090454	0.000000	NaN	NaN
461.999425	0.002296	22.957138	0.206399	1153.750732	0.000000	NaN	NaN
463.499511	0.002296	22.957138	0.207081	1154.402954	0.000000	NaN	NaN
464.999596	0.002386	23.864948	0.207728	1155.021118	0.000000	NaN	NaN
466.499682	0.002246	22.461970	0.208464	1155.725708	0.000000	NaN	NaN
467.999768	0.002370	23.699892	0.209157	1156.387939	0.000000	NaN	NaN
469.499854	0.002312	23.122195	0.209853	1157.054077	0.000000	NaN	NaN
470.999940	0.002362	23.617363	0.210551	1157.721680	0.000000	NaN	NaN
472.500025	0.002444	24.442645	0.211198	1158.339722	0.000000	NaN	NaN
474.000111	0.002320	23.204723	0.211935	1159.044434	0.000000	NaN	NaN
475.500197	0.002238	22.379442	0.212621	1159.701294	0.000000	NaN	NaN
476.999283	0.002296	22.957138	0.213326	1160.375244	0.000000	NaN	NaN
478.499369	0.002246	22.461970	0.214113	1161.127686	0.000000	NaN	NaN
479.999454	0.002444	24.442645	0.214758	1161.744629	0.000000	NaN	NaN
481.499540	0.002230	22.296913	0.215463	1162.418457	0.000000	NaN	NaN
482.999626	0.002329	23.287251	0.216111	1163.038940	0.000000	NaN	NaN
484.499712	0.002386	23.864948	0.216878	1163.771973	0.000000	NaN	NaN
485.999798	0.002337	23.369779	0.217531	1164.396729	0.000000	NaN	NaN
487.499883	0.002254	22.544498	0.218276	1165.109131	0.000000	NaN	NaN
488.999969	0.002378	23.782420	0.218955	1165.758545	0.000000	NaN	NaN
490.500055	0.002221	22.214385	0.219688	1166.459839	0.000000	NaN	NaN
492.000141	0.002378	23.782420	0.220368	1167.109375	0.000000	NaN	NaN
493.500227	0.002279	22.792082	0.221015	1167.728516	0.000000	NaN	NaN
494.999312	0.002230	22.296913	0.221825	1168.503662	0.000000	NaN	NaN
496.499398	0.002395	23.947476	0.222508	1169.156860	0.000000	NaN	NaN
497.999484	0.002403	24.030004	0.223208	1169.825928	0.000000	NaN	NaN
499.499570	0.002370	23.699892	0.223899	1170.486450	0.000000	NaN	NaN
500.999656	0.002420	24.195060	0.224655	1171.209717	0.000000	NaN	NaN
502.499741	0.002254	22.544498	0.225374	1171.897827	0.000000	NaN	NaN
503.999827	0.002312	23.122195	0.226053	1172.546387	0.000000	NaN	NaN
505.499913	0.002444	24.442645	0.226749	1173.212769	0.000000	NaN	NaN
506.999999	0.002403	24.030004	0.227458	1173.890137	0.000000	NaN	NaN
508.500084	0.002436	24.360117	0.228152	1174.554443	0.000000	NaN	NaN
510.000170	0.002420	24.195060	0.228969	1175.335083	0.000000	NaN	NaN
511.500256	0.002353	23.534835	0.229608	1175.946289	0.000000	NaN	NaN
512.999342	0.002312	23.122195	0.230264	1176.573975	0.000000	NaN	NaN
514.499428	0.002395	23.947476	0.230921	1177.202026	0.000000	NaN	NaN
515.999513	0.002420	24.195060	0.231657	1177.906494	0.000000	NaN	NaN
517.499599	0.002271	22.709554	0.232338	1178.557251	0.000000	NaN	NaN
518.999685	0.002329	23.287251	0.233071	1179.258911	0.000000	NaN	NaN
520.499771	0.002378	23.782420	0.233801	1179.956665	0.000000	NaN	NaN
521.999857	0.002320	23.204723	0.234495	1180.620483	0.000000	NaN	NaN
523.499942	0.002362	23.617363	0.235196	1181.291138	0.000000	NaN	NaN
525.000028	0.002395	23.947476	0.235820	1181.887329	0.000000	NaN	NaN
526.500114	0.002304	23.039667	0.236516	1182.553223	0.000000	NaN	NaN
528.000200	0.002320	23.204723	0.237267	1183.271362	0.000000	NaN	NaN
529.499286	0.002230	22.296913	0.238007	1183.979492	0.000000	NaN	NaN
530.999371	0.002345	23.452307	0.238648	1184.592163	0.000000	NaN	NaN
532.499457	0.002395	23.947476	0.239297	1185.212524	0.000000	NaN	NaN
533.999543	0.002378	23.782420	0.240076	1185.957886	0.000000	NaN	NaN
535.499629	0.002370	23.699892	0.240787	1186.638062	0.000000	NaN	NaN
536.999715	0.002378	23.782420	0.241484	1187.304077	0.000000	NaN	NaN
538.499800	0.002337	23.369779	0.242181	1187.971313	0.000000	NaN	NaN
539.999886	0.002271	22.709554	0.242873	1188.632446	0.000000	NaN	NaN
541.499972	0.002420	24.195060	0.243546	1189.276367	0.000000	NaN	NaN
543.000058	0.002312	23.122195	0.244196	1189.898071	0.000000	NaN	NaN
544.500144	0.002345	23.452307	0.244937	1190.606689	0.000000	NaN	NaN
546.000229	0.002411	24.112532	0.245677	1191.314087	0.000000	NaN	NaN
547.499315	0.002205	22.049329	0.246364	1191.971680	0.000000	NaN	NaN
548.999401	0.002304	23.039667	0.247038	1192.616333	0.000000	NaN	NaN
550.499487	0.002362	23.617363	0.247852	1193.394165	0.000000	NaN	NaN
551.999572	0.002370	23.699892	0.248517	1194.030640	0.000000	NaN	NaN
553.499658	0.002411	24.112532	0.249151	1194.636719	0.000000	NaN	NaN
554.999744	0.002420	24.195060	0.249926	1195.378052	0.000000	NaN	NaN
556.499830	0.002436	24.360117	0.250605	1196.027222	0.000000	NaN	NaN
557.999916	0.002444	24.442645	0.251283	1196.675903	0.000000	NaN	NaN
559.500001	0.002296	22.957138	0.251954	1197.317139	0.000000	NaN	NaN
561.000087	0.002411	24.112532	0.252663	1197.995850	0.000000	NaN	NaN
562.500173	0.002486	24.855285	0.253380	1198.681030	0.000000	NaN	NaN
564.000259	0.002362	23.617363	0.254081	1199.351929	0.000000	NaN	NaN
565.499345	0.002362	23.617363	0.254741	1199.982788	0.000000	NaN	NaN
566.999431	0.002386	23.864948	0.255433	1200.644287	0.000000	NaN	NaN
568.499516	0.002411	24.112532	0.256174	1201.353394	0.000000	NaN	NaN
569.999602	0.002279	22.792082	0.256860	1202.009277	0.000000	NaN	NaN
571.499688	0.002353	23.534835	0.257552	1202.671387	0.000000	NaN	NaN
572.999774	0.002345	23.452307	0.258241	1203.330322	0.000000	NaN	NaN
574.499859	0.002362	23.617363	0.258976	1204.033325	0.000000	NaN	NaN
575.999945	0.002370	23.699892	0.259616	1204.644897	0.000000	NaN	NaN
577.500031	0.002329	23.287251	0.260309	1205.307617	0.000000	NaN	NaN
579.000117	0.002395	23.947476	0.261057	1206.022827	0.000000	NaN	NaN
580.500203	0.002461	24.607701	0.261753	1206.689087	0.000000	NaN	NaN
581.999288	0.002477	24.772757	0.262556	1207.456665	0.000000	NaN	NaN
583.499374	0.002395	23.947476	0.263169	1208.042603	0.000000	NaN	NaN
584.999460	0.002420	24.195060	0.263821	1208.666016	0.000000	NaN	NaN
586.499546	0.002428	24.277588	0.264561	1209.374634	0.000000	NaN	NaN
587.999632	0.002428	24.277588	0.265213	1209.997559	0.000000	NaN	NaN
589.499717	0.002411	24.112532	0.265956	1210.708252	0.000000	NaN	NaN
590.999803	0.002263	22.627026	0.266639	1211.361084	0.000000	NaN	NaN
592.499889	0.002552	25.515510	0.267351	1212.042480	0.000000	NaN	NaN
593.999975	0.002386	23.864948	0.268078	1212.737549	0.000000	NaN	NaN
595.500061	0.002420	24.195060	0.268778	1213.406982	0.000000	NaN	NaN
597.000146	0.002527	25.267926	0.269465	1214.064575	0.000000	NaN	NaN
598.500232	0.002420	24.195060	0.270181	1214.748901	0.000000	NaN	NaN
599.999318	0.002378	23.782420	0.270780	1215.321411	0.000000	NaN	NaN
601.499404	0.002337	23.369779	0.271487	1215.997925	0.000000	NaN	NaN
602.999490	0.002403	24.030004	0.272203	1216.682373	0.000000	NaN	NaN
604.499575	0.002304	23.039667	0.272923	1217.370850	0.000000	NaN	NaN
605.999661	0.002296	22.957138	0.273610	1218.028076	0.000000	NaN	NaN
607.499747	0.002428	24.277588	0.274329	1218.715820	0.000000	NaN	NaN
608.999833	0.002436	24.360117	0.274927	1219.287842	0.000000	NaN	NaN
610.499919	0.002461	24.607701	0.275657	1219.986084	0.000000	NaN	NaN
612.000004	0.002486	24.855285	0.276332	1220.631104	0.000000	NaN	NaN
613.500090	0.002477	24.772757	0.277017	1221.286743	0.000000	NaN	NaN
615.000176	0.002378	23.782420	0.277744	1221.981567	0.000000	NaN	NaN
616.500262	0.002420	24.195060	0.278370	1222.580322	0.000000	NaN	NaN
617.999347	0.002486	24.855285	0.279039	1223.220581	0.000000	NaN	NaN
619.499433	0.002486	24.855285	0.279771	1223.920898	0.000000	NaN	NaN
620.999519	0.002436	24.360117	0.280539	1224.654907	0.000000	NaN	NaN
622.499605	0.002453	24.525173	0.281129	1225.219116	0.000000	NaN	NaN
623.999691	0.002494	24.937813	0.281841	1225.899658	0.000000	NaN	NaN
625.499776	0.002477	24.772757	0.282558	1226.585693	0.000000	NaN	NaN
626.999862	0.002494	24.937813	0.283246	1227.243896	0.000000	NaN	NaN
628.499948	0.002411	24.112532	0.283923	1227.890869	0.000000	NaN	NaN
630.000034	0.002320	23.204723	0.284588	1228.526855	0.000000	NaN	NaN
631.500120	0.002502	25.020342	0.285344	1229.250732	0.000000	NaN	NaN
633.000205	0.002436	24.360117	0.286053	1229.928467	0.000000	NaN	NaN
634.499291	0.002436	24.360117	0.286669	1230.517578	0.000000	NaN	NaN
635.999377	0.002535	25.350454	0.287351	1231.169922	0.000000	NaN	NaN
637.499463	0.002453	24.525173	0.288098	1231.883911	0.000000	NaN	NaN
638.999549	0.002411	24.112532	0.288794	1232.549683	0.000000	NaN	NaN
640.499634	0.002535	25.350454	0.289500	1233.224365	0.000000	NaN	NaN
641.999720	0.002494	24.937813	0.290149	1233.845947	0.000000	NaN	NaN
643.499806	0.002436	24.360117	0.290828	1234.495239	0.000000	NaN	NaN
644.999892	0.002436	24.360117	0.291512	1235.148560	0.000000	NaN	NaN
646.499978	0.002469	24.690229	0.292166	1235.774048	0.000000	NaN	NaN
648.000063	0.002444	24.442645	0.292944	1236.518799	0.000000	NaN	NaN
649.500149	0.002535	25.350454	0.293569	1237.116333	0.000000	NaN	NaN
651.000235	0.002469	24.690229	0.294165	1237.686401	0.000000	NaN	NaN
652.499321	0.002543	25.432982	0.294924	1238.412109	0.000000	NaN	NaN
653.999407	0.002370	23.699892	0.295609	1239.067017	0.000000	NaN	NaN
655.499492	0.002502	25.020342	0.296275	1239.704224	0.000000	NaN	NaN
656.999578	0.002461	24.607701	0.297027	1240.423218	0.000000	NaN	NaN
658.499664	0.002494	24.937813	0.297595	1240.966675	0.000000	NaN	NaN
659.999750	0.002486	24.855285	0.298296	1241.636597	0.000000	NaN	NaN
661.499836	0.002510	25.102870	0.298983	1242.293823	0.000000	NaN	NaN
662.999921	0.002403	24.030004	0.299720	1242.999268	0.000000	NaN	NaN
664.500007	0.002386	23.864948	0.300445	1243.692261	0.000000	NaN	NaN
666.000093	0.002428	24.277588	0.301169	1244.384277	0.000000	NaN	NaN
667.500179	0.002411	24.112532	0.301755	1244.945312	0.000000	NaN	NaN
669.000265	0.002411	24.112532	0.302386	1245.548340	0.000000	NaN	NaN
670.499350	0.002510	25.102870	0.303118	1246.248169	0.000000	NaN	NaN
671.999436	0.002461	24.607701	0.303823	1246.922363	0.000000	NaN	NaN
673.499522	0.002477	24.772757	0.304448	1247.520264	0.000000	NaN	NaN
674.999608	0.002345	23.452307	0.305172	1248.213379	0.000000	NaN	NaN
676.499693	0.002486	24.855285	0.305759	1248.774658	0.000000	NaN	NaN
677.999779	0.002436	24.360117	0.306457	1249.441406	0.000000	NaN	NaN
679.499865	0.002453	24.525173	0.307033	1249.992676	0.000000	NaN	NaN
680.999951	0.002585	25.845623	0.307754	1250.682495	0.000000	NaN	NaN
682.500037	0.002552	25.515510	0.308446	1251.343994	0.000000	NaN	NaN
684.000122	0.002370	23.699892	0.309155	1252.021606	0.000000	NaN	NaN
685.500208	0.002461	24.607701	0.309855	1252.691772	0.000000	NaN	NaN
686.999294	0.002469	24.690229	0.310429	1253.240723	0.000000	NaN	NaN
688.499380	0.002502	25.020342	0.311166	1253.945557	0.000000	NaN	NaN
689.999466	0.002337	23.369779	0.311905	1254.651855	0.000000	NaN	NaN
691.499551	0.002576	25.763095	0.312569	1255.287109	0.000000	NaN	NaN
692.999637	0.002609	26.093207	0.313255	1255.943237	0.000000	NaN	NaN
694.499723	0.002477	24.772757	0.313890	1256.550781	0.000000	NaN	NaN
695.999809	0.002510	25.102870	0.314580	1257.210815	0.000000	NaN	NaN
697.499895	0.002453	24.525173	0.315372	1257.967407	0.000000	NaN	NaN
698.999980	0.002593	25.928151	0.316024	1258.591675	0.000000	NaN	NaN
700.500066	0.002560	25.598038	0.316822	1259.354248	0.000000	NaN	NaN
702.000152	0.002494	24.937813	0.317393	1259.900146	0.000000	NaN	NaN
703.500238	0.002535	25.350454	0.318037	1260.516602	0.000000	NaN	NaN
704.999324	0.002436	24.360117	0.318781	1261.228027	0.000000	NaN	NaN
706.499409	0.002486	24.855285	0.319440	1261.858643	0.000000	NaN	NaN
707.999495	0.002601	26.010679	0.320089	1262.479004	0.000000	NaN	NaN
709.499581	0.002469	24.690229	0.320842	1263.199097	0.000000	NaN	NaN
710.999667	0.002535	25.350454	0.321472	1263.801147	0.000000	NaN	NaN
712.499753	0.002469	24.690229	0.322240	1264.536377	0.000000	NaN	NaN
713.999838	0.002519	25.185398	0.322906	1265.172974	0.000000	NaN	NaN
715.499924	0.002527	25.267926	0.323546	1265.785156	0.000000	NaN	NaN
717.000010	0.002444	24.442645	0.324217	1266.426514	0.000000	NaN	NaN
718.500096	0.002609	26.093207	0.324929	1267.107788	0.000000	NaN	NaN
720.000182	0.002667	26.670904	0.325632	1267.779785	0.000000	NaN	NaN
721.500267	0.002453	24.525173	0.326205	1268.327637	0.000000	NaN	NaN
722.999353	0.002510	25.102870	0.326931	1269.022095	0.000000	NaN	NaN
724.499439	0.002552	25.515510	0.327598	1269.659912	0.000000	NaN	NaN
725.999525	0.002510	25.102870	0.328241	1270.274780	0.000000	NaN	NaN
727.499611	0.002494	24.937813	0.328921	1270.925293	0.000000	NaN	NaN
728.999696	0.002486	24.855285	0.329709	1271.678833	0.000000	NaN	NaN
730.499782	0.002519	25.185398	0.330325	1272.268311	0.000000	NaN	NaN
731.999868	0.002510	25.102870	0.331018	1272.930908	0.000000	NaN	NaN
733.499954	0.002568	25.680567	0.331758	1273.638794	0.000000	NaN	NaN
735.000040	0.002543	25.432982	0.332404	1274.256226	0.000000	NaN	NaN
736.500125	0.002618	26.175735	0.333068	1274.891113	0.000000	NaN	NaN
738.000211	0.002502	25.020342	0.333749	1275.542603	0.000000	NaN	NaN
739.499297	0.002593	25.928151	0.334415	1276.179932	0.000000	NaN	NaN
740.999383	0.002642	26.423320	0.335067	1276.802856	0.000000	NaN	NaN
742.499468	0.002461	24.607701	0.335781	1277.485962	0.000000	NaN	NaN
743.999554	0.002642	26.423320	0.336418	1278.095093	0.000000	NaN	NaN
745.499640	0.002378	23.782420	0.337095	1278.742676	0.000000	NaN	NaN
746.999726	0.002560	25.598038	0.337695	1279.316162	0.000000	NaN	NaN
748.499812	0.002436	24.360117	0.338353	1279.945923	0.000000	NaN	NaN
749.999897	0.002568	25.680567	0.339025	1280.588623	0.000000	NaN	NaN
751.499983	0.002543	25.432982	0.339748	1281.279785	0.000000	NaN	NaN
753.000069	0.002651	26.505848	0.340322	1281.829346	0.000000	NaN	NaN
754.500155	0.002568	25.680567	0.341009	1282.485596	0.000000	NaN	NaN
756.000241	0.002601	26.010679	0.341544	1282.997925	0.000000	NaN	NaN
757.499326	0.002593	25.928151	0.342296	1283.716675	0.000000	NaN	NaN
758.999412	0.002576	25.763095	0.342940	1284.332642	0.000000	NaN	NaN
760.499498	0.002486	24.855285	0.343549	1284.915161	0.000000	NaN	NaN
761.999584	0.002477	24.772757	0.344250	1285.585815	0.000000	NaN	NaN
763.499670	0.002486	24.855285	0.344905	1286.212402	0.000000	NaN	NaN
764.999755	0.002634	26.340792	0.345616	1286.891479	0.000000	NaN	NaN
766.499841	0.002494	24.937813	0.346184	1287.435059	0.000000	NaN	NaN
767.999927	0.002667	26.670904	0.346889	1288.109131	0.000000	NaN	NaN
769.500013	0.002601	26.010679	0.347510	1288.702881	0.000000	NaN	NaN
771.000099	0.002593	25.928151	0.348228	1289.389404	0.000000	NaN	NaN
772.500184	0.002453	24.525173	0.348801	1289.938232	0.000000	NaN	NaN
774.000270	0.002560	25.598038	0.349408	1290.518799	0.000000	NaN	NaN
775.499356	0.002502	25.020342	0.350045	1291.127197	0.000000	NaN	NaN
776.999442	0.002502	25.020342	0.350741	1291.793579	0.000000	NaN	NaN
778.499528	0.002733	27.331129	0.351395	1292.418701	0.000000	NaN	NaN
779.999613	0.002626	26.258263	0.352040	1293.035522	0.000000	NaN	NaN
781.499699	0.002543	25.432982	0.352696	1293.662598	0.000000	NaN	NaN
782.999785	0.002469	24.690229	0.353310	1294.250122	0.000000	NaN	NaN
784.499871	0.002593	25.928151	0.354051	1294.958618	0.000000	NaN	NaN
785.999957	0.002519	25.185398	0.354710	1295.588501	0.000000	NaN	NaN
787.500042	0.002568	25.680567	0.355193	1296.051270	0.000000	NaN	NaN
789.000128	0.002502	25.020342	0.355827	1296.657104	0.000000	NaN	NaN
790.500214	0.002618	26.175735	0.356543	1297.341675	0.000000	NaN	NaN
791.999300	0.002461	24.607701	0.357228	1297.997070	0.000000	NaN	NaN
793.499385	0.002576	25.763095	0.357864	1298.605591	0.000000	NaN	NaN
794.999471	0.002510	25.102870	0.358424	1299.140503	0.000000	NaN	NaN
796.499557	0.002552	25.515510	0.359079	1299.766968	0.000000	NaN	NaN
797.999643	0.002519	25.185398	0.359718	1300.378418	0.000000	NaN	NaN
799.499729	0.002486	24.855285	0.360295	1300.929932	0.000000	NaN	NaN
800.999814	0.002444	24.442645	0.361019	1301.622681	0.000000	NaN	NaN
802.499900	0.002436	24.360117	0.361644	1302.219971	0.000000	NaN	NaN
803.999986	0.002436	24.360117	0.362269	1302.817749	0.000000	NaN	NaN
805.500072	0.002519	25.185398	0.362922	1303.443115	0.000000	NaN	NaN
807.000158	0.002494	24.937813	0.363562	1304.055176	0.000000	NaN	NaN
808.500243	0.002486	24.855285	0.364155	1304.621582	0.000000	NaN	NaN
809.999329	0.002535	25.350454	0.364815	1305.253418	0.000000	NaN	NaN
811.499415	0.002552	25.515510	0.365385	1305.797974	0.000000	NaN	NaN
812.999501	0.002642	26.423320	0.366025	1306.409912	0.000000	NaN	NaN
814.499587	0.002585	25.845623	0.366645	1307.003174	0.000000	NaN	NaN
815.999672	0.002461	24.607701	0.367246	1307.578003	0.000000	NaN	NaN
817.499758	0.002510	25.102870	0.367820	1308.126587	0.000000	NaN	NaN
818.999844	0.002453	24.525173	0.368408	1308.689087	0.000000	NaN	NaN
820.499930	0.002510	25.102870	0.368965	1309.221558	0.000000	NaN	NaN
822.000016	0.002560	25.598038	0.369637	1309.864624	0.000000	NaN	NaN
823.500101	0.002395	23.947476	0.370147	1310.352539	0.000000	NaN	NaN
825.000187	0.002378	23.782420	0.370800	1310.976440	0.000000	NaN	NaN
826.500273	0.002502	25.020342	0.371417	1311.566528	0.000000	NaN	NaN
827.999359	0.002370	23.699892	0.371847	1311.978394	0.000000	NaN	NaN
829.499445	0.002593	25.928151	0.372428	1312.533936	0.000000	NaN	NaN
830.999530	0.002510	25.102870	0.372973	1313.054687	0.000000	NaN	NaN
832.499616	0.002568	25.680567	0.373586	1313.641113	0.000000	NaN	NaN
833.999702	0.002568	25.680567	0.374172	1314.202026	0.000000	NaN	NaN
835.499788	0.002519	25.185398	0.374715	1314.720825	0.000000	NaN	NaN
836.999874	0.002469	24.690229	0.375295	1315.275269	0.000000	NaN	NaN
838.499959	0.002560	25.598038	0.375874	1315.829224	0.000000	NaN	NaN
840.000045	0.002444	24.442645	0.376355	1316.289185	0.000000	NaN	NaN
841.500131	0.002420	24.195060	0.376877	1316.789062	0.000000	NaN	NaN
843.000217	0.002436	24.360117	0.377508	1317.392090	0.000000	NaN	NaN
844.499303	0.002386	23.864948	0.377975	1317.838501	0.000000	NaN	NaN
845.999388	0.002568	25.680567	0.378588	1318.424561	0.000000	NaN	NaN
847.499474	0.002477	24.772757	0.379143	1318.955566	0.000000	NaN	NaN
848.999560	0.002477	24.772757	0.379721	1319.508667	0.000000	NaN	NaN
850.499646	0.002386	23.864948	0.380300	1320.062500	0.000000	NaN	NaN
851.999732	0.002395	23.947476	0.380815	1320.554810	0.000000	NaN	NaN
853.499817	0.002444	24.442645	0.381292	1321.010620	0.000000	NaN	NaN
854.999903	0.002428	24.277588	0.381828	1321.523926	0.000000	NaN	NaN
856.499989	0.002519	25.185398	0.382314	1321.988159	0.000000	NaN	NaN
858.000075	0.002453	24.525173	0.382864	1322.514771	0.000000	NaN	NaN
859.500161	0.002378	23.782420	0.383453	1323.077271	0.000000	NaN	NaN
861.000246	0.002453	24.525173	0.384018	1323.618042	0.000000	NaN	NaN
862.499332	0.002568	25.680567	0.384436	1324.017334	0.000000	NaN	NaN
863.999418	0.002502	25.020342	0.384809	1324.374146	0.000000	NaN	NaN
865.499504	0.002420	24.195060	0.385376	1324.916992	0.000000	NaN	NaN
866.999589	0.002337	23.369779	0.385890	1325.408203	0.000000	NaN	NaN
868.499675	0.002353	23.534835	0.386330	1325.829102	0.000000	NaN	NaN
869.999761	0.002378	23.782420	0.386874	1326.349365	0.000000	NaN	NaN
871.499847	0.002362	23.617363	0.387312	1326.768555	0.000000	NaN	NaN
872.999933	0.002353	23.534835	0.387857	1327.289795	0.000000	NaN	NaN
874.500018	0.002353	23.534835	0.388309	1327.722046	0.000000	NaN	NaN
876.000104	0.002271	22.709554	0.388588	1327.988403	0.000000	NaN	NaN
877.500190	0.002362	23.617363	0.389115	1328.492432	0.000000	NaN	NaN
878.999276	0.002370	23.699892	0.389573	1328.930176	0.000000	NaN	NaN
880.499362	0.002353	23.534835	0.390024	1329.362061	0.000000	NaN	NaN
881.999447	0.002345	23.452307	0.390541	1329.856323	0.000000	NaN	NaN
883.499533	0.002411	24.112532	0.391007	1330.302124	0.000000	NaN	NaN
884.999619	0.002345	23.452307	0.391361	1330.640869	0.000000	NaN	NaN
886.499705	0.002279	22.792082	0.391786	1331.046631	0.000000	NaN	NaN
887.999791	0.002254	22.544498	0.392189	1331.432007	0.000000	NaN	NaN
889.499876	0.002329	23.287251	0.392573	1331.799805	0.000000	NaN	NaN
890.999962	0.002271	22.709554	0.393028	1332.234375	0.000000	NaN	NaN
892.500048	0.002246	22.461970	0.393342	1332.534912	0.000000	NaN	NaN
894.000134	0.002238	22.379442	0.393809	1332.981323	0.000000	NaN	NaN
895.500220	0.002287	22.874610	0.394315	1333.465942	0.000000	NaN	NaN
896.999305	0.002304	23.039667	0.394733	1333.865234	0.000000	NaN	NaN
898.499391	0.002221	22.214385	0.395086	1334.203003	0.000000	NaN	NaN
899.999477	0.002287	22.874610	0.395324	1334.430420	0.000000	NaN	NaN
901.499563	0.002205	22.049329	0.395700	1334.790039	0.000000	NaN	NaN
902.999649	0.002246	22.461970	0.396067	1335.140747	0.000000	NaN	NaN
904.499734	0.002320	23.204723	0.396307	1335.370483	0.000000	NaN	NaN
905.999820	0.002081	20.811407	0.396600	1335.651245	0.000000	NaN	NaN
907.499906	0.002089	20.893935	0.396989	1336.023315	0.000000	NaN	NaN
908.999992	0.002089	20.893935	0.397355	1336.372559	0.000000	NaN	NaN
910.500078	0.002106	21.058992	0.397658	1336.662231	0.000000	NaN	NaN
912.000163	0.002089	20.893935	0.397929	1336.921509	0.000000	NaN	NaN
913.500249	0.002139	21.389104	0.398228	1337.208130	0.000000	NaN	NaN
914.999335	0.002155	21.554160	0.398477	1337.445679	0.000000	NaN	NaN
916.499421	0.002023	20.233710	0.398784	1337.739868	0.000000	NaN	NaN
917.999507	0.001924	19.243373	0.399067	1338.010010	0.000000	NaN	NaN
919.499592	0.001949	19.490957	0.399356	1338.286743	0.000000	NaN	NaN
920.999678	0.001974	19.738542	0.399575	1338.496582	0.000000	NaN	NaN
922.499764	0.001949	19.490957	0.399911	1338.817749	0.000000	NaN	NaN
923.999850	0.001941	19.408429	0.400285	1339.174927	0.000000	NaN	NaN
925.499935	0.001900	18.995789	0.400684	1339.557129	0.000000	NaN	NaN
927.000021	0.001900	18.995789	0.401130	1339.983032	0.000000	NaN	NaN
928.500107	0.001801	18.005451	-0.657042	327.991028	0.000000	NaN	NaN
930.000193	0.001842	18.418092	-0.655370	329.590454	0.000000	NaN	NaN
931.499279	0.001784	17.840395	0.402332	1341.132812	0.000000	NaN	NaN
932.999364	0.001726	17.262698	0.402836	1341.614380	0.000000	NaN	NaN
934.499450	0.001776	17.757867	0.403360	1342.115845	0.000000	NaN	NaN
935.999536	0.001801	18.005451	0.403695	1342.436157	0.000000	NaN	NaN
937.499622	0.001792	17.922923	-0.136371	825.938965	0.000000	NaN	NaN
938.999708	0.001735	17.345226	-0.135950	826.341614	0.000000	NaN	NaN
940.499793	0.001635	16.354889	-0.135709	826.572815	0.000000	NaN	NaN
941.999879	0.001536	15.364551	0.406324	1344.950562	0.000000	NaN	NaN
943.499965	0.001702	17.015114	0.407179	1345.768188	0.000000	NaN	NaN
945.000051	0.001536	15.364551	0.408019	1346.571289	0.000000	NaN	NaN
946.500137	0.001495	14.951910	0.409170	1347.672363	0.000000	NaN	NaN
948.000222	0.001289	12.888707	0.410333	1348.784302	0.000000	NaN	NaN
949.499308	0.001289	12.888707	0.412029	1350.406128	0.000000	NaN	NaN
950.999394	0.000752	7.524379	0.414043	1352.332764	0.000000	NaN	NaN
952.499480	-0.000221	-2.213940	0.452063	1388.693848	0.000000	NaN	NaN
953.999566	-0.000263	-2.626581	0.464259	1400.356812	0.000000	NaN	NaN
955.499651	-0.000263	-2.626581	0.470185	1406.024292	0.000000	NaN	NaN
956.999737	-6.820864E-6	-0.068209	0.474103	1409.771484	0.000000	NaN	NaN
958.499823	-0.000122	-1.223602	0.477355	1412.882080	0.000000	NaN	NaN
959.999909	-0.000386	-3.864503	0.480273	1415.672241	0.000000	NaN	NaN
961.499995	-0.000246	-2.461524	0.482852	1418.138916	0.000000	NaN	NaN
962.500052	-0.000197	-1.966356	0.484418	1419.636719	0.000000	NaN	NaN