File: data/57k_1-3_1 (190415).lvm
LabVIEW Measurement
Writer_Version	2
Reader_Version	2
Separator	Tab
Decimal_Separator	.
Multi_Headings	No
X_Columns	One
Time_Pref	Absolute
Operator	user
Description	Load(N)/Stress(MPa)/Distance A(pixel)/Strain A/Distance B(pixel)/Strain B/Poisson's ratio
Date	2019/04/15
Time	10:27:11.3033933639526367187
***End_of_Header***

Notes	X 값은 오직 다음과 같을 때에만 유효함이 보장됩니다. Dev1/ai0
Channels	7
Samples	1	1	1	1	1	1	1
Date	2019/04/15	2019/04/15	2019/04/15	2019/04/15	2019/04/15	2019/04/15	2019/04/15
Time	10:27:11.303393530034995936	10:27:11.303393530034995936	10:27:11.3033933639526367187	10:27:11.3033933639526367187	10:27:11.3033933639526367187	10:27:11.3033933639526367187	10:27:11.3033933639526367187
Y_Unit_Label	Volts	Volts
X_Dimension	Time	Time	Time	Time	Time	Time	Time
X0	0.0000000000000000E+0	0.0000000000000000E+0	0.0000000000000000E+0	0.0000000000000000E+0	0.0000000000000000E+0	0.0000000000000000E+0	0.0000000000000000E+0
Delta_X	0.000000	0.000000	1.000000	1.000000	1.000000	1.000000	1.000000
***End_of_Header***
X_Value	Dev1/ai0	Dev1/ai0 1	Untitled	Untitled 1	Untitled 2	Untitled 3	Untitled 4	Comment
0.000000	-6.459055E-5	-0.645906	4.780293E-5	995.875671	0.000000	NaN	NaN
1.000057	-0.000164	-1.636243	4.792213E-5	995.875793	0.000000	NaN	NaN
2.000114	-6.820864E-6	-0.068209	0.000164	995.991516	0.000000	NaN	NaN
3.000172	-9.760180E-5	-0.976018	8.296967E-5	995.910645	0.000000	NaN	NaN
4.000229	-8.934899E-5	-0.893490	3.826618E-5	995.866211	0.000000	NaN	NaN
5.000286	-5.633774E-5	-0.563377	0.000327	996.153687	0.000000	NaN	NaN
6.000343	-2.332649E-5	-0.233265	0.000615	996.440125	0.000000	NaN	NaN
6.999400	9.221289E-5	0.922129	0.000709	996.533997	0.000000	NaN	NaN
7.999458	5.094882E-5	0.509488	0.001046	996.869812	0.000000	NaN	NaN
8.999515	3.444320E-5	0.344432	0.001328	997.150391	0.000000	NaN	NaN
9.999572	0.000150	1.499826	0.001654	997.475220	0.000000	NaN	NaN
10.999629	-1.507368E-5	-0.150737	0.001715	997.535950	0.000000	NaN	NaN
11.999686	0.000183	1.829938	0.001962	997.781921	0.000000	NaN	NaN
12.999744	0.000175	1.747410	0.002035	997.854370	0.000000	NaN	NaN
13.999801	0.000233	2.325107	0.002238	998.056824	0.000000	NaN	NaN
14.999858	0.000117	1.169713	0.002493	998.310364	0.000000	NaN	NaN
15.999915	0.000125	1.252241	0.002505	998.322876	0.000000	NaN	NaN
16.999972	0.000208	2.077523	0.002618	998.435425	0.000000	NaN	NaN
18.000030	0.000266	2.655220	0.002875	998.691040	0.000000	NaN	NaN
19.000087	0.000266	2.655220	0.002936	998.751648	0.000000	NaN	NaN
20.000144	0.000249	2.490163	0.003146	998.960571	0.000000	NaN	NaN
21.000201	0.000175	1.747410	0.003283	999.097595	0.000000	NaN	NaN
22.000258	0.000233	2.325107	0.003338	999.152161	0.000000	NaN	NaN
23.000316	0.000373	3.728085	0.003677	999.490234	0.000000	NaN	NaN
23.999373	0.000216	2.160051	0.003753	999.565430	0.000000	NaN	NaN
24.999430	0.000307	3.067860	0.003997	999.808472	0.000000	NaN	NaN
25.999487	0.000274	2.737748	0.004098	999.908569	0.000000	NaN	NaN
26.999544	0.000323	3.232916	0.004252	1000.062683	0.000000	NaN	NaN
27.999602	0.000216	2.160051	0.004230	1000.040466	0.000000	NaN	NaN
28.999659	0.000299	2.985332	0.004606	1000.415100	0.000000	NaN	NaN
29.999716	0.000389	3.893141	0.004573	1000.382385	0.000000	NaN	NaN
30.999773	0.000373	3.728085	0.004774	1000.582458	0.000000	NaN	NaN
31.999830	0.000398	3.975670	0.004714	1000.522400	0.000000	NaN	NaN
32.999887	0.000439	4.388310	0.004943	1000.750183	0.000000	NaN	NaN
33.999945	0.000521	5.213591	0.005166	1000.972534	0.000000	NaN	NaN
35.000002	0.000406	4.058198	0.005422	1001.227112	0.000000	NaN	NaN
36.000059	0.000389	3.893141	0.005474	1001.278870	0.000000	NaN	NaN
37.000116	0.000472	4.718423	0.005664	1001.468628	0.000000	NaN	NaN
38.000174	0.000282	2.820276	0.005954	1001.757629	0.000000	NaN	NaN
39.000231	0.000530	5.296120	0.006027	1001.829651	0.000000	NaN	NaN
40.000288	0.000521	5.213591	0.006288	1002.089905	0.000000	NaN	NaN
41.000345	0.000480	4.800951	0.006381	1002.181946	0.000000	NaN	NaN
41.999402	0.000365	3.645557	0.006529	1002.330139	0.000000	NaN	NaN
42.999460	0.000538	5.378648	0.006622	1002.422363	0.000000	NaN	NaN
43.999517	0.000530	5.296120	0.007070	1002.868591	0.000000	NaN	NaN
44.999574	0.000447	4.470838	0.007145	1002.943054	0.000000	NaN	NaN
45.999631	0.000571	5.708760	0.007365	1003.161926	0.000000	NaN	NaN
46.999688	0.000662	6.616570	0.007606	1003.402161	0.000000	NaN	NaN
47.999746	0.000604	6.038873	0.007730	1003.525818	0.000000	NaN	NaN
48.999803	0.000662	6.616570	0.007929	1003.723877	0.000000	NaN	NaN
49.999860	0.000645	6.451513	0.008159	1003.953308	0.000000	NaN	NaN
50.999917	0.000810	8.102076	0.008516	1004.308655	0.000000	NaN	NaN
51.999974	0.000736	7.359323	0.008641	1004.433044	0.000000	NaN	NaN
53.000031	0.000554	5.543704	0.008859	1004.649841	0.000000	NaN	NaN
54.000089	0.000629	6.286457	0.008996	1004.786438	0.000000	NaN	NaN
55.000146	0.000794	7.937020	0.009428	1005.216614	0.000000	NaN	NaN
56.000203	0.000777	7.771963	0.009603	1005.390686	0.000000	NaN	NaN
57.000260	0.000777	7.771963	0.009746	1005.533569	0.000000	NaN	NaN
58.000318	0.000769	7.689435	0.010304	1006.089050	0.000000	NaN	NaN
58.999375	0.000719	7.194267	0.010616	1006.399719	0.000000	NaN	NaN
59.999432	0.000744	7.441851	0.010971	1006.753479	0.000000	NaN	NaN
60.999489	0.000785	7.854492	0.011185	1006.966370	0.000000	NaN	NaN
61.999546	0.000686	6.864154	0.011483	1007.263123	0.000000	NaN	NaN
62.999603	0.000810	8.102076	0.011913	1007.691528	0.000000	NaN	NaN
63.999661	0.000802	8.019548	0.012303	1008.079712	0.000000	NaN	NaN
64.999718	0.000843	8.432188	0.012609	1008.384399	0.000000	NaN	NaN
65.999775	0.000769	7.689435	0.013035	1008.809143	0.000000	NaN	NaN
66.999832	0.000728	7.276795	0.013422	1009.194580	0.000000	NaN	NaN
67.999889	0.000827	8.267132	0.013611	1009.382141	0.000000	NaN	NaN
68.999947	0.000942	9.422526	0.014052	1009.821045	0.000000	NaN	NaN
70.000004	0.000851	8.514717	0.014537	1010.304504	0.000000	NaN	NaN
71.000061	0.001000	10.000223	0.014661	1010.427551	0.000000	NaN	NaN
72.000118	0.000909	9.092413	0.015064	1010.829529	0.000000	NaN	NaN
73.000175	0.000992	9.917695	0.015509	1011.272095	0.000000	NaN	NaN
74.000233	0.001041	10.412863	0.015941	1011.702759	0.000000	NaN	NaN
75.000290	0.000975	9.752638	0.016370	1012.129395	0.000000	NaN	NaN
76.000347	0.000860	8.597245	0.016587	1012.345947	0.000000	NaN	NaN
76.999404	0.001025	10.247807	0.017066	1012.822449	0.000000	NaN	NaN
77.999461	0.001099	10.990560	0.017443	1013.198059	0.000000	NaN	NaN
78.999519	0.001017	10.165279	0.017884	1013.638000	0.000000	NaN	NaN
79.999576	0.001025	10.247807	0.018263	1014.015198	0.000000	NaN	NaN
80.999633	0.001041	10.412863	0.018757	1014.506592	0.000000	NaN	NaN
81.999690	0.000992	9.917695	0.019047	1014.795715	0.000000	NaN	NaN
82.999747	0.001132	11.320673	0.019537	1015.283325	0.000000	NaN	NaN
83.999805	0.001140	11.403201	0.020218	1015.962036	0.000000	NaN	NaN
84.999862	0.001107	11.073088	0.020497	1016.239441	0.000000	NaN	NaN
85.999919	0.001132	11.320673	0.021124	1016.864136	0.000000	NaN	NaN
86.999976	0.001198	11.980898	0.021519	1017.257629	0.000000	NaN	NaN
88.000033	0.001248	12.476067	0.021897	1017.633545	0.000000	NaN	NaN
89.000091	0.001083	10.825504	0.022239	1017.974243	0.000000	NaN	NaN
90.000148	0.001058	10.577920	0.022807	1018.540161	0.000000	NaN	NaN
91.000205	0.001239	12.393538	0.023185	1018.915833	0.000000	NaN	NaN
92.000262	0.001116	11.155617	0.023501	1019.230774	0.000000	NaN	NaN
93.000319	0.001149	11.485729	0.024127	1019.854492	0.000000	NaN	NaN
93.999376	0.001149	11.485729	0.024524	1020.249756	0.000000	NaN	NaN
94.999434	0.001198	11.980898	0.024919	1020.642944	0.000000	NaN	NaN
95.999491	0.001231	12.311010	0.025499	1021.220215	0.000000	NaN	NaN
96.999548	0.001198	11.980898	0.025952	1021.671753	0.000000	NaN	NaN
97.999605	0.001239	12.393538	0.026273	1021.991577	0.000000	NaN	NaN
98.999662	0.001173	11.733313	0.026892	1022.607544	0.000000	NaN	NaN
99.999720	0.001272	12.723651	0.027269	1022.983215	0.000000	NaN	NaN
100.999777	0.001264	12.641123	0.027787	1023.499268	0.000000	NaN	NaN
101.999834	0.001256	12.558595	0.028314	1024.024414	0.000000	NaN	NaN
102.999891	0.001215	12.145954	0.028818	1024.525513	0.000000	NaN	NaN
103.999949	0.001297	12.971235	0.029067	1024.774048	0.000000	NaN	NaN
105.000006	0.001248	12.476067	0.029665	1025.368774	0.000000	NaN	NaN
106.000063	0.001190	11.898370	0.030099	1025.801636	0.000000	NaN	NaN
107.000120	0.001322	13.218820	0.030533	1026.233765	0.000000	NaN	NaN
108.000177	0.001363	13.631460	0.030933	1026.631714	0.000000	NaN	NaN
109.000235	0.001165	11.650785	0.031568	1027.264038	0.000000	NaN	NaN
110.000292	0.001347	13.466404	0.032010	1027.704224	0.000000	NaN	NaN
111.000349	0.001264	12.641123	0.032478	1028.170166	0.000000	NaN	NaN
111.999406	0.001281	12.806179	0.032902	1028.592529	0.000000	NaN	NaN
112.999463	0.001215	12.145954	0.033478	1029.166016	0.000000	NaN	NaN
113.999520	0.001124	11.238145	0.033840	1029.526855	0.000000	NaN	NaN
114.999578	0.001256	12.558595	0.034395	1030.079468	0.000000	NaN	NaN
115.999635	0.001281	12.806179	0.034881	1030.563843	0.000000	NaN	NaN
116.999692	0.001347	13.466404	0.035104	1030.785156	0.000000	NaN	NaN
117.999749	0.001347	13.466404	0.035674	1031.353271	0.000000	NaN	NaN
118.999806	0.001281	12.806179	0.036338	1032.014771	0.000000	NaN	NaN
119.999864	0.001239	12.393538	0.036779	1032.453735	0.000000	NaN	NaN
120.999921	0.001297	12.971235	0.037156	1032.828857	0.000000	NaN	NaN
121.999978	0.001479	14.786854	0.037790	1033.460083	0.000000	NaN	NaN
123.000035	0.001371	13.713988	0.038105	1033.774048	0.000000	NaN	NaN
124.000092	0.001289	12.888707	0.037709	1033.379395	0.000000	NaN	NaN
125.000150	0.001413	14.126629	0.037914	1033.583496	0.000000	NaN	NaN
126.000207	0.001223	12.228482	0.039622	1035.285156	0.000000	NaN	NaN
127.000264	0.001264	12.641123	0.040058	1035.718872	0.000000	NaN	NaN
128.000321	0.001165	11.650785	0.040603	1036.261230	0.000000	NaN	NaN
128.999378	0.001322	13.218820	0.041061	1036.717651	0.000000	NaN	NaN
129.999436	0.001239	12.393538	0.041585	1037.239258	0.000000	NaN	NaN
130.999493	0.001305	13.053763	0.042108	1037.760376	0.000000	NaN	NaN
131.999550	0.001503	15.034438	0.042562	1038.212769	0.000000	NaN	NaN
132.999607	0.001479	14.786854	0.043013	1038.661499	0.000000	NaN	NaN
133.999664	0.001182	11.815842	0.043522	1039.168701	0.000000	NaN	NaN
134.999722	0.001413	14.126629	0.043954	1039.598511	0.000000	NaN	NaN
135.999779	0.001330	13.301348	0.044467	1040.109253	0.000000	NaN	NaN
136.999836	0.001347	13.466404	0.044967	1040.607056	0.000000	NaN	NaN
137.999893	0.001272	12.723651	0.045440	1041.078247	0.000000	NaN	NaN
138.999950	0.001314	13.136292	0.046029	1041.665405	0.000000	NaN	NaN
140.000008	0.001396	13.961573	0.046361	1041.995605	0.000000	NaN	NaN
141.000065	0.001322	13.218820	0.046914	1042.546387	0.000000	NaN	NaN
142.000122	0.001429	14.291685	0.047502	1043.132202	0.000000	NaN	NaN
143.000179	0.001446	14.456742	0.047901	1043.529419	0.000000	NaN	NaN
144.000236	0.001454	14.539270	0.048373	1043.999756	0.000000	NaN	NaN
145.000294	0.001437	14.374213	0.048835	1044.459595	0.000000	NaN	NaN
146.000351	0.001305	13.053763	0.049421	1045.042725	0.000000	NaN	NaN
146.999408	0.001479	14.786854	0.049930	1045.549683	0.000000	NaN	NaN
147.999465	0.001256	12.558595	0.050354	1045.972290	0.000000	NaN	NaN
148.999522	0.001413	14.126629	0.050697	1046.313477	0.000000	NaN	NaN
149.999580	0.001454	14.539270	0.051454	1047.067383	0.000000	NaN	NaN
150.999637	0.001462	14.621798	0.051933	1047.544678	0.000000	NaN	NaN
151.999694	0.001281	12.806179	0.052445	1048.054077	0.000000	NaN	NaN
152.999751	0.001355	13.548932	0.052888	1048.495239	0.000000	NaN	NaN
153.999808	0.001388	13.879045	0.053412	1049.017456	0.000000	NaN	NaN
154.999865	0.001347	13.466404	0.053848	1049.451416	0.000000	NaN	NaN
155.999923	0.001413	14.126629	0.054462	1050.062866	0.000000	NaN	NaN
156.999980	0.001380	13.796517	0.054991	1050.589722	0.000000	NaN	NaN
158.000037	0.001380	13.796517	0.055454	1051.050293	0.000000	NaN	NaN
159.000094	0.001297	12.971235	0.055951	1051.545776	0.000000	NaN	NaN
160.000151	0.001487	14.869382	0.056445	1052.037964	0.000000	NaN	NaN
161.000209	0.001388	13.879045	0.056977	1052.567749	0.000000	NaN	NaN
162.000266	0.001454	14.539270	0.057584	1053.171753	0.000000	NaN	NaN
163.000323	0.001380	13.796517	0.057922	1053.508545	0.000000	NaN	NaN
163.999380	0.001446	14.456742	0.058550	1054.134155	0.000000	NaN	NaN
164.999437	0.001413	14.126629	0.059157	1054.738281	0.000000	NaN	NaN
165.999495	0.001470	14.704326	0.059537	1055.116211	0.000000	NaN	NaN
166.999552	0.001421	14.209157	0.060107	1055.684570	0.000000	NaN	NaN
167.999609	0.001479	14.786854	0.060616	1056.190674	0.000000	NaN	NaN
168.999666	0.001536	15.364551	0.061152	1056.725220	0.000000	NaN	NaN
169.999723	0.001429	14.291685	0.061625	1057.196289	0.000000	NaN	NaN
170.999781	0.001528	15.282023	0.062151	1057.719482	0.000000	NaN	NaN
171.999838	0.001470	14.704326	0.062670	1058.237061	0.000000	NaN	NaN
172.999895	0.001388	13.879045	0.063126	1058.691162	0.000000	NaN	NaN
173.999952	0.001594	15.942248	0.063760	1059.322021	0.000000	NaN	NaN
175.000010	0.001421	14.209157	0.064312	1059.872192	0.000000	NaN	NaN
176.000067	0.001462	14.621798	0.064827	1060.384521	0.000000	NaN	NaN
177.000124	0.001347	13.466404	0.065273	1060.828491	0.000000	NaN	NaN
178.000181	0.001314	13.136292	0.065742	1061.296143	0.000000	NaN	NaN
179.000238	0.001437	14.374213	0.066418	1061.969360	0.000000	NaN	NaN
180.000295	0.001528	15.282023	0.066926	1062.474487	0.000000	NaN	NaN
181.000353	0.001528	15.282023	0.067301	1062.848511	0.000000	NaN	NaN
181.999410	0.001512	15.116967	0.067965	1063.509644	0.000000	NaN	NaN
182.999467	0.001503	15.034438	0.068530	1064.072388	0.000000	NaN	NaN
183.999524	0.001462	14.621798	0.068912	1064.452393	0.000000	NaN	NaN
184.999581	0.001652	16.519945	0.069411	1064.949463	0.000000	NaN	NaN
185.999639	0.001413	14.126629	0.070099	1065.635132	0.000000	NaN	NaN
186.999696	0.001338	13.383876	0.070482	1066.015991	0.000000	NaN	NaN
187.999753	0.001429	14.291685	0.070998	1066.530029	0.000000	NaN	NaN
188.999810	0.001470	14.704326	0.071491	1067.020630	0.000000	NaN	NaN
189.999867	0.001454	14.539270	0.072083	1067.610840	0.000000	NaN	NaN
190.999925	0.001462	14.621798	0.072662	1068.187378	0.000000	NaN	NaN
191.999982	0.001495	14.951910	0.073266	1068.788696	0.000000	NaN	NaN
193.000039	0.001487	14.869382	0.073715	1069.235962	0.000000	NaN	NaN
194.000096	0.001437	14.374213	0.074291	1069.809082	0.000000	NaN	NaN
195.000153	0.001503	15.034438	0.074648	1070.164795	0.000000	NaN	NaN
196.000211	0.001371	13.713988	0.075123	1070.637695	0.000000	NaN	NaN
197.000268	0.001371	13.713988	0.075494	1071.007568	0.000000	NaN	NaN
198.000325	0.001553	15.529607	0.076084	1071.594238	0.000000	NaN	NaN
198.999382	0.001619	16.189832	0.076538	1072.046509	0.000000	NaN	NaN
199.999439	0.001421	14.209157	0.077110	1072.616333	0.000000	NaN	NaN
200.999497	0.001454	14.539270	0.077592	1073.096680	0.000000	NaN	NaN
201.999554	0.001462	14.621798	0.078122	1073.624512	0.000000	NaN	NaN
202.999611	0.001627	16.272360	0.078676	1074.176025	0.000000	NaN	NaN
203.999668	0.001446	14.456742	0.079177	1074.674805	0.000000	NaN	NaN
204.999725	0.001545	15.447079	0.079614	1075.109863	0.000000	NaN	NaN
205.999783	0.001421	14.209157	0.080184	1075.677856	0.000000	NaN	NaN
206.999840	0.001371	13.713988	0.080716	1076.207520	0.000000	NaN	NaN
207.999897	0.001536	15.364551	0.081251	1076.739624	0.000000	NaN	NaN
208.999954	0.001454	14.539270	0.081784	1077.270752	0.000000	NaN	NaN
210.000011	0.001454	14.539270	0.082351	1077.835449	0.000000	NaN	NaN
211.000069	0.001594	15.942248	0.082851	1078.333374	0.000000	NaN	NaN
212.000126	0.001512	15.116967	0.083292	1078.772705	0.000000	NaN	NaN
213.000183	0.001553	15.529607	0.083875	1079.353394	0.000000	NaN	NaN
214.000240	0.001602	16.024776	0.084362	1079.838501	0.000000	NaN	NaN
215.000297	0.001487	14.869382	0.084877	1080.351074	0.000000	NaN	NaN
216.000355	0.001404	14.044101	0.085441	1080.912964	0.000000	NaN	NaN
216.999412	0.001429	14.291685	0.085852	1081.321777	0.000000	NaN	NaN
217.999469	0.001429	14.291685	0.086422	1081.889771	0.000000	NaN	NaN
218.999526	0.001594	15.942248	0.086939	1082.404785	0.000000	NaN	NaN
219.999583	0.001470	14.704326	0.087535	1082.998047	0.000000	NaN	NaN
220.999640	0.001553	15.529607	0.088053	1083.513184	0.000000	NaN	NaN
221.999698	0.001512	15.116967	0.088505	1083.963379	0.000000	NaN	NaN
222.999755	0.001487	14.869382	0.089036	1084.492187	0.000000	NaN	NaN
223.999812	0.001479	14.786854	0.089526	1084.980835	0.000000	NaN	NaN
224.999869	0.001446	14.456742	0.090066	1085.518188	0.000000	NaN	NaN
225.999926	0.001553	15.529607	0.090490	1085.941040	0.000000	NaN	NaN
226.999984	0.001512	15.116967	0.091099	1086.546997	0.000000	NaN	NaN
228.000041	0.001578	15.777192	0.091614	1087.060303	0.000000	NaN	NaN
229.000098	0.001512	15.116967	0.092101	1087.545044	0.000000	NaN	NaN
230.000155	0.001594	15.942248	0.092704	1088.145386	0.000000	NaN	NaN
231.000213	0.001536	15.364551	0.093134	1088.573608	0.000000	NaN	NaN
232.000270	0.001396	13.961573	0.093725	1089.162476	0.000000	NaN	NaN
233.000327	0.001545	15.447079	0.094280	1089.714722	0.000000	NaN	NaN
233.999384	0.001413	14.126629	0.094822	1090.254150	0.000000	NaN	NaN
234.999441	0.001528	15.282023	0.095383	1090.813232	0.000000	NaN	NaN
235.999498	0.001602	16.024776	0.095873	1091.301392	0.000000	NaN	NaN
236.999556	0.001470	14.704326	0.096343	1091.768799	0.000000	NaN	NaN
237.999613	0.001536	15.364551	0.096819	1092.242920	0.000000	NaN	NaN
238.999670	0.001536	15.364551	0.097466	1092.887451	0.000000	NaN	NaN
239.999727	0.001479	14.786854	0.097833	1093.253174	0.000000	NaN	NaN
240.999784	0.001487	14.869382	0.098379	1093.797119	0.000000	NaN	NaN
241.999842	0.001602	16.024776	0.098870	1094.285645	0.000000	NaN	NaN
242.999899	0.001578	15.777192	0.099358	1094.771118	0.000000	NaN	NaN
243.999956	0.001388	13.879045	0.099929	1095.339966	0.000000	NaN	NaN
245.000013	0.001693	16.932585	0.100480	1095.888794	0.000000	NaN	NaN
246.000070	0.001569	15.694663	0.100939	1096.346313	0.000000	NaN	NaN
247.000128	0.001495	14.951910	0.101490	1096.894653	0.000000	NaN	NaN
248.000185	0.001611	16.107304	0.102047	1097.449585	0.000000	NaN	NaN
249.000242	0.001545	15.447079	0.102542	1097.942505	0.000000	NaN	NaN
250.000299	0.001586	15.859720	0.103076	1098.474121	0.000000	NaN	NaN
251.000356	0.001503	15.034438	0.103554	1098.950317	0.000000	NaN	NaN
251.999414	0.001561	15.612135	0.104099	1099.492432	0.000000	NaN	NaN
252.999471	0.001553	15.529607	0.104562	1099.954102	0.000000	NaN	NaN
253.999528	0.001536	15.364551	0.105187	1100.576172	0.000000	NaN	NaN
254.999585	0.001619	16.189832	0.105720	1101.107300	0.000000	NaN	NaN
255.999642	0.001635	16.354889	0.106065	1101.450073	0.000000	NaN	NaN
256.999700	0.001545	15.447079	0.106740	1102.123047	0.000000	NaN	NaN
257.999757	0.001454	14.539270	0.107103	1102.484131	0.000000	NaN	NaN
258.999814	0.001404	14.044101	0.107653	1103.031738	0.000000	NaN	NaN
259.999871	0.001553	15.529607	0.108304	1103.680664	0.000000	NaN	NaN
260.999928	0.001503	15.034438	0.108815	1104.189331	0.000000	NaN	NaN
261.999986	0.001503	15.034438	0.109411	1104.782837	0.000000	NaN	NaN
263.000043	0.001726	17.262698	0.109943	1105.311890	0.000000	NaN	NaN
264.000100	0.001578	15.777192	0.110515	1105.881470	0.000000	NaN	NaN
265.000157	0.001759	17.592810	0.110877	1106.242920	0.000000	NaN	NaN
266.000214	0.001512	15.116967	0.111382	1106.745483	0.000000	NaN	NaN
267.000272	0.001578	15.777192	0.112041	1107.401978	0.000000	NaN	NaN
268.000329	0.001602	16.024776	0.112517	1107.875488	0.000000	NaN	NaN
268.999386	0.001545	15.447079	0.113003	1108.359131	0.000000	NaN	NaN
269.999443	0.001578	15.777192	0.113607	1108.960937	0.000000	NaN	NaN
270.999500	0.001685	16.850057	0.114030	1109.381958	0.000000	NaN	NaN
271.999557	0.001677	16.767529	0.114599	1109.949463	0.000000	NaN	NaN
272.999615	0.001545	15.447079	0.115146	1110.493408	0.000000	NaN	NaN
273.999672	0.001586	15.859720	0.115644	1110.989746	0.000000	NaN	NaN
274.999729	0.001578	15.777192	0.116135	1111.479004	0.000000	NaN	NaN
275.999786	0.001669	16.685001	0.116840	1112.180786	0.000000	NaN	NaN
276.999843	0.001528	15.282023	0.117245	1112.583740	0.000000	NaN	NaN
277.999901	0.001503	15.034438	0.117810	1113.146362	0.000000	NaN	NaN
278.999958	0.001669	16.685001	0.118219	1113.553467	0.000000	NaN	NaN
280.000015	0.001611	16.107304	0.118819	1114.151245	0.000000	NaN	NaN
281.000072	0.001635	16.354889	0.119433	1114.762451	0.000000	NaN	NaN
282.000130	0.001569	15.694663	0.119960	1115.287964	0.000000	NaN	NaN
283.000187	0.001578	15.777192	0.120426	1115.751587	0.000000	NaN	NaN
284.000244	0.001569	15.694663	0.120878	1116.202026	0.000000	NaN	NaN
285.000301	0.001751	17.510282	0.121558	1116.879150	0.000000	NaN	NaN
286.000358	0.001611	16.107304	0.121900	1117.219116	0.000000	NaN	NaN
286.999415	0.001602	16.024776	0.122462	1117.779297	0.000000	NaN	NaN
287.999473	0.001553	15.529607	0.123008	1118.323120	0.000000	NaN	NaN
288.999530	0.001726	17.262698	0.123474	1118.786499	0.000000	NaN	NaN
289.999587	0.001644	16.437417	0.123973	1119.283936	0.000000	NaN	NaN
290.999644	0.001685	16.850057	0.124424	1119.732422	0.000000	NaN	NaN
291.999702	0.001553	15.529607	0.124881	1120.188232	0.000000	NaN	NaN
292.999759	0.001619	16.189832	0.125402	1120.707031	0.000000	NaN	NaN
293.999816	0.001586	15.859720	0.125813	1121.116089	0.000000	NaN	NaN
294.999873	0.001462	14.621798	0.126508	1121.808350	0.000000	NaN	NaN
295.999930	0.001602	16.024776	0.126889	1122.187866	0.000000	NaN	NaN
296.999987	0.001578	15.777192	0.127522	1122.817993	0.000000	NaN	NaN
298.000045	0.001586	15.859720	0.127887	1123.181641	0.000000	NaN	NaN
299.000102	0.001693	16.932585	0.128469	1123.760742	0.000000	NaN	NaN
300.000159	0.001569	15.694663	0.128876	1124.166504	0.000000	NaN	NaN
301.000216	0.001635	16.354889	0.129538	1124.825928	0.000000	NaN	NaN
302.000273	0.001561	15.612135	0.130039	1125.324829	0.000000	NaN	NaN
303.000331	0.001644	16.437417	0.130473	1125.756592	0.000000	NaN	NaN
303.999388	0.001503	15.034438	0.131018	1126.299561	0.000000	NaN	NaN
304.999445	0.001479	14.786854	0.131594	1126.873413	0.000000	NaN	NaN
305.999502	0.001702	17.015114	0.132094	1127.371094	0.000000	NaN	NaN
306.999559	0.001594	15.942248	0.132637	1127.911743	0.000000	NaN	NaN
307.999617	0.001586	15.859720	0.133001	1128.274048	0.000000	NaN	NaN
308.999674	0.001569	15.694663	0.133557	1128.827515	0.000000	NaN	NaN
309.999731	0.001644	16.437417	0.134060	1129.329102	0.000000	NaN	NaN
310.999788	0.001611	16.107304	0.134663	1129.929443	0.000000	NaN	NaN
311.999845	0.001561	15.612135	0.135134	1130.398560	0.000000	NaN	NaN
312.999903	0.001743	17.427754	0.135523	1130.785278	0.000000	NaN	NaN
313.999960	0.001702	17.015114	0.136167	1131.427002	0.000000	NaN	NaN
315.000017	0.001545	15.447079	0.136633	1131.890747	0.000000	NaN	NaN
316.000074	0.001619	16.189832	0.137224	1132.479736	0.000000	NaN	NaN
317.000131	0.001602	16.024776	0.137603	1132.857178	0.000000	NaN	NaN
318.000189	0.001652	16.519945	0.138240	1133.491577	0.000000	NaN	NaN
319.000246	0.001553	15.529607	0.138711	1133.960693	0.000000	NaN	NaN
320.000303	0.001669	16.685001	0.139225	1134.472534	0.000000	NaN	NaN
321.000360	0.001619	16.189832	0.139694	1134.939697	0.000000	NaN	NaN
321.999417	0.001635	16.354889	0.140255	1135.498047	0.000000	NaN	NaN
322.999475	0.001594	15.942248	0.140756	1135.996826	0.000000	NaN	NaN
323.999532	0.001578	15.777192	0.141302	1136.540649	0.000000	NaN	NaN
324.999589	0.001644	16.437417	0.141843	1137.079346	0.000000	NaN	NaN
325.999646	0.001652	16.519945	0.142265	1137.499634	0.000000	NaN	NaN
326.999703	0.001536	15.364551	0.142753	1137.985229	0.000000	NaN	NaN
327.999761	0.001512	15.116967	0.143350	1138.579956	0.000000	NaN	NaN
328.999818	0.001495	14.951910	0.143701	1138.929565	0.000000	NaN	NaN
329.999875	0.001652	16.519945	0.144307	1139.532837	0.000000	NaN	NaN
330.999932	0.001536	15.364551	0.144772	1139.995850	0.000000	NaN	NaN
331.999989	0.001644	16.437417	0.145279	1140.500854	0.000000	NaN	NaN
333.000047	0.001710	17.097642	0.145764	1140.984131	0.000000	NaN	NaN
334.000104	0.001602	16.024776	0.146154	1141.372070	0.000000	NaN	NaN
335.000161	0.001718	17.180170	0.146657	1141.873657	0.000000	NaN	NaN
336.000218	0.001652	16.519945	0.147297	1142.510742	0.000000	NaN	NaN
337.000275	0.001710	17.097642	0.147844	1143.055420	0.000000	NaN	NaN
338.000333	0.001677	16.767529	0.148273	1143.482910	0.000000	NaN	NaN
338.999390	0.001611	16.107304	0.148758	1143.965088	0.000000	NaN	NaN
339.999447	0.001677	16.767529	0.149191	1144.396362	0.000000	NaN	NaN
340.999504	0.001619	16.189832	0.149838	1145.041260	0.000000	NaN	NaN
341.999561	0.001660	16.602473	0.150394	1145.594360	0.000000	NaN	NaN
342.999618	0.001635	16.354889	0.150900	1146.098755	0.000000	NaN	NaN
343.999676	0.001545	15.447079	0.151313	1146.510132	0.000000	NaN	NaN
344.999733	0.001503	15.034438	0.151902	1147.096191	0.000000	NaN	NaN
345.999790	0.001586	15.859720	0.152392	1147.584595	0.000000	NaN	NaN
346.999847	0.001586	15.859720	0.152861	1148.051636	0.000000	NaN	NaN
347.999905	0.001669	16.685001	0.153357	1148.545044	0.000000	NaN	NaN
348.999962	0.001768	17.675339	0.153861	1149.047485	0.000000	NaN	NaN
350.000019	0.001644	16.437417	0.154167	1149.351562	0.000000	NaN	NaN
351.000076	0.001743	17.427754	0.154345	1149.529053	0.000000	NaN	NaN
352.000133	0.001644	16.437417	0.154838	1150.019775	0.000000	NaN	NaN
353.000190	0.001735	17.345226	0.155076	1150.257324	0.000000	NaN	NaN
354.000248	0.001627	16.272360	0.156292	1151.467896	0.000000	NaN	NaN
355.000305	0.001685	16.850057	0.156798	1151.971680	0.000000	NaN	NaN
356.000362	0.001627	16.272360	0.157300	1152.471558	0.000000	NaN	NaN
356.999419	0.001759	17.592810	0.157823	1152.992432	0.000000	NaN	NaN
357.999476	0.001669	16.685001	0.158342	1153.509644	0.000000	NaN	NaN
358.999534	0.001801	18.005451	0.158879	1154.044678	0.000000	NaN	NaN
359.999591	0.001726	17.262698	0.159390	1154.553101	0.000000	NaN	NaN
360.999648	0.001768	17.675339	0.159843	1155.004517	0.000000	NaN	NaN
361.999705	0.001619	16.189832	0.160396	1155.554565	0.000000	NaN	NaN
362.999762	0.001718	17.180170	0.160867	1156.024292	0.000000	NaN	NaN
363.999820	0.001635	16.354889	0.161435	1156.589233	0.000000	NaN	NaN
364.999877	0.001619	16.189832	0.161999	1157.151367	0.000000	NaN	NaN
365.999934	0.001743	17.427754	0.162477	1157.626831	0.000000	NaN	NaN
366.999991	0.001693	16.932585	0.162987	1158.135376	0.000000	NaN	NaN
368.000048	0.001677	16.767529	0.163406	1158.552856	0.000000	NaN	NaN
369.000106	0.001702	17.015114	0.163976	1159.120361	0.000000	NaN	NaN
370.000163	0.001652	16.519945	0.164445	1159.587402	0.000000	NaN	NaN
371.000220	0.001718	17.180170	0.164942	1160.081543	0.000000	NaN	NaN
372.000277	0.001594	15.942248	0.165328	1160.465942	0.000000	NaN	NaN
373.000334	0.001759	17.592810	0.165976	1161.111328	0.000000	NaN	NaN
373.999392	0.001776	17.757867	0.166478	1161.611450	0.000000	NaN	NaN
374.999449	0.001619	16.189832	0.167020	1162.151001	0.000000	NaN	NaN
375.999506	0.001685	16.850057	0.167503	1162.632080	0.000000	NaN	NaN
376.999563	0.001644	16.437417	0.168003	1163.129883	0.000000	NaN	NaN
377.999620	0.001578	15.777192	0.168409	1163.534180	0.000000	NaN	NaN
378.999678	0.001644	16.437417	0.168931	1164.053833	0.000000	NaN	NaN
379.999735	0.001825	18.253035	0.169556	1164.676880	0.000000	NaN	NaN
380.999792	0.001635	16.354889	0.170041	1165.159546	0.000000	NaN	NaN
381.999849	0.001627	16.272360	0.170475	1165.591919	0.000000	NaN	NaN
382.999906	0.001768	17.675339	0.171118	1166.231934	0.000000	NaN	NaN
383.999964	0.001792	17.922923	0.171636	1166.747803	0.000000	NaN	NaN
385.000021	0.001801	18.005451	0.171992	1167.102661	0.000000	NaN	NaN
386.000078	0.001784	17.840395	0.172578	1167.685913	0.000000	NaN	NaN
387.000135	0.001619	16.189832	0.173120	1168.226318	0.000000	NaN	NaN
388.000192	0.001743	17.427754	0.173688	1168.791016	0.000000	NaN	NaN
389.000250	0.001660	16.602473	0.174160	1169.261230	0.000000	NaN	NaN
390.000307	0.001801	18.005451	0.174733	1169.832153	0.000000	NaN	NaN
391.000364	0.001644	16.437417	0.175118	1170.215698	0.000000	NaN	NaN
391.999421	0.001693	16.932585	0.175754	1170.848877	0.000000	NaN	NaN
392.999478	0.001644	16.437417	0.176260	1171.353027	0.000000	NaN	NaN
393.999535	0.001759	17.592810	0.176781	1171.871582	0.000000	NaN	NaN
394.999593	0.001751	17.510282	0.177325	1172.413452	0.000000	NaN	NaN
395.999650	0.001751	17.510282	0.177752	1172.838501	0.000000	NaN	NaN
396.999707	0.001792	17.922923	0.178391	1173.474854	0.000000	NaN	NaN
397.999764	0.001685	16.850057	0.178883	1173.964844	0.000000	NaN	NaN
398.999821	0.001685	16.850057	0.179383	1174.462646	0.000000	NaN	NaN
399.999879	0.001702	17.015114	0.179829	1174.906860	0.000000	NaN	NaN
400.999936	0.001743	17.427754	0.180388	1175.463257	0.000000	NaN	NaN
401.999993	0.001776	17.757867	0.180887	1175.959961	0.000000	NaN	NaN
403.000050	0.001718	17.180170	0.181431	1176.502197	0.000000	NaN	NaN
404.000108	0.001669	16.685001	0.181926	1176.995117	0.000000	NaN	NaN
405.000165	0.001710	17.097642	0.182401	1177.468384	0.000000	NaN	NaN
406.000222	0.001693	16.932585	0.183062	1178.126831	0.000000	NaN	NaN
407.000279	0.001768	17.675339	0.183565	1178.627075	0.000000	NaN	NaN
408.000336	0.001586	15.859720	0.184033	1179.093506	0.000000	NaN	NaN
408.999393	0.001751	17.510282	0.184476	1179.534668	0.000000	NaN	NaN
409.999451	0.001669	16.685001	0.185067	1180.122925	0.000000	NaN	NaN
410.999508	0.001627	16.272360	0.185562	1180.616211	0.000000	NaN	NaN
411.999565	0.001660	16.602473	0.185942	1180.994019	0.000000	NaN	NaN
412.999622	0.001743	17.427754	0.186511	1181.561035	0.000000	NaN	NaN
413.999680	0.001710	17.097642	0.186925	1181.973511	0.000000	NaN	NaN
414.999737	0.001784	17.840395	0.187455	1182.501099	0.000000	NaN	NaN
415.999794	0.001817	18.170507	0.188074	1183.117554	0.000000	NaN	NaN
416.999851	0.001751	17.510282	0.188468	1183.509644	0.000000	NaN	NaN
417.999908	0.001768	17.675339	0.188890	1183.930420	0.000000	NaN	NaN
418.999965	0.001751	17.510282	0.189404	1184.441528	0.000000	NaN	NaN
420.000023	0.001693	16.932585	0.189965	1185.000488	0.000000	NaN	NaN
421.000080	0.001743	17.427754	0.190400	1185.433838	0.000000	NaN	NaN
422.000137	0.001693	16.932585	0.191000	1186.030762	0.000000	NaN	NaN
423.000194	0.001660	16.602473	0.191408	1186.437744	0.000000	NaN	NaN
424.000251	0.001718	17.180170	0.191916	1186.943115	0.000000	NaN	NaN
425.000309	0.001652	16.519945	0.192433	1187.458618	0.000000	NaN	NaN
426.000366	0.001644	16.437417	0.192850	1187.873535	0.000000	NaN	NaN
426.999423	0.001735	17.345226	0.193382	1188.403076	0.000000	NaN	NaN
427.999480	0.001809	18.087979	0.193834	1188.853394	0.000000	NaN	NaN
428.999537	0.001751	17.510282	0.194372	1189.389404	0.000000	NaN	NaN
429.999595	0.001660	16.602473	0.194961	1189.976074	0.000000	NaN	NaN
430.999652	0.001743	17.427754	0.195482	1190.494629	0.000000	NaN	NaN
431.999709	0.001867	18.665676	0.195947	1190.957764	0.000000	NaN	NaN
432.999766	0.001735	17.345226	0.196320	1191.328857	0.000000	NaN	NaN
433.999823	0.001685	16.850057	0.196985	1191.990845	0.000000	NaN	NaN
434.999881	0.001611	16.107304	0.197473	1192.477417	0.000000	NaN	NaN
435.999938	0.001718	17.180170	0.197995	1192.996582	0.000000	NaN	NaN
436.999995	0.001635	16.354889	0.198479	1193.478760	0.000000	NaN	NaN
438.000052	0.001718	17.180170	0.199019	1194.016846	0.000000	NaN	NaN
439.000109	0.001602	16.024776	0.199507	1194.502563	0.000000	NaN	NaN
440.000167	0.001735	17.345226	0.199954	1194.948242	0.000000	NaN	NaN
441.000224	0.001743	17.427754	0.200535	1195.526855	0.000000	NaN	NaN
442.000281	0.001652	16.519945	0.200927	1195.916382	0.000000	NaN	NaN
443.000338	0.001776	17.757867	0.201566	1196.553345	0.000000	NaN	NaN
443.999395	0.001858	18.583148	0.202012	1196.997070	0.000000	NaN	NaN
444.999453	0.001751	17.510282	0.202590	1197.572754	0.000000	NaN	NaN
445.999510	0.001743	17.427754	0.203007	1197.988525	0.000000	NaN	NaN
446.999567	0.001743	17.427754	0.203519	1198.497681	0.000000	NaN	NaN
447.999624	0.001743	17.427754	0.204065	1199.042114	0.000000	NaN	NaN
448.999681	0.001660	16.602473	0.204592	1199.566772	0.000000	NaN	NaN
449.999739	0.001652	16.519945	0.205044	1200.016357	0.000000	NaN	NaN
450.999796	0.001759	17.592810	0.205533	1200.503174	0.000000	NaN	NaN
451.999853	0.001768	17.675339	0.206116	1201.084229	0.000000	NaN	NaN
452.999910	0.001751	17.510282	0.206638	1201.604370	0.000000	NaN	NaN
453.999967	0.001693	16.932585	0.207161	1202.125000	0.000000	NaN	NaN
455.000025	0.001801	18.005451	0.207534	1202.495850	0.000000	NaN	NaN
456.000082	0.001669	16.685001	0.208048	1203.008423	0.000000	NaN	NaN
457.000139	0.001718	17.180170	0.208622	1203.580078	0.000000	NaN	NaN
458.000196	0.001635	16.354889	0.209154	1204.109741	0.000000	NaN	NaN
459.000253	0.001702	17.015114	0.209636	1204.589844	0.000000	NaN	NaN
460.000311	0.001677	16.767529	0.210134	1205.085083	0.000000	NaN	NaN
460.999368	0.001817	18.170507	0.210575	1205.524536	0.000000	NaN	NaN
461.999425	0.001867	18.665676	0.211168	1206.114868	0.000000	NaN	NaN
462.999482	0.001735	17.345226	0.211686	1206.631348	0.000000	NaN	NaN
463.999539	0.001726	17.262698	0.212134	1207.077515	0.000000	NaN	NaN
464.999596	0.001768	17.675339	0.212745	1207.685913	0.000000	NaN	NaN
465.999654	0.001834	18.335564	0.213339	1208.277344	0.000000	NaN	NaN
466.999711	0.001792	17.922923	0.213811	1208.746948	0.000000	NaN	NaN
467.999768	0.001883	18.830732	0.214249	1209.183472	0.000000	NaN	NaN
468.999825	0.001677	16.767529	0.214853	1209.784668	0.000000	NaN	NaN
469.999883	0.001784	17.840395	0.215314	1210.244019	0.000000	NaN	NaN
470.999940	0.001702	17.015114	0.215862	1210.789307	0.000000	NaN	NaN
471.999997	0.001743	17.427754	0.216263	1211.188354	0.000000	NaN	NaN
473.000054	0.001817	18.170507	0.216848	1211.771240	0.000000	NaN	NaN
474.000111	0.001677	16.767529	0.217397	1212.317871	0.000000	NaN	NaN
475.000168	0.001726	17.262698	0.217766	1212.685181	0.000000	NaN	NaN
476.000226	0.001776	17.757867	0.218456	1213.372681	0.000000	NaN	NaN
477.000283	0.001743	17.427754	0.218956	1213.870728	0.000000	NaN	NaN
478.000340	0.001776	17.757867	0.219447	1214.359985	0.000000	NaN	NaN
478.999397	0.001809	18.087979	0.220022	1214.932495	0.000000	NaN	NaN
479.999454	0.001809	18.087979	0.220680	1215.587646	0.000000	NaN	NaN
480.999512	0.001784	17.840395	0.221221	1216.126343	0.000000	NaN	NaN
481.999569	0.001718	17.180170	0.221611	1216.514404	0.000000	NaN	NaN
482.999626	0.001801	18.005451	0.221996	1216.897827	0.000000	NaN	NaN
483.999683	0.001792	17.922923	0.222718	1217.617187	0.000000	NaN	NaN
484.999740	0.001660	16.602473	0.223278	1218.174316	0.000000	NaN	NaN
485.999798	0.001726	17.262698	0.223682	1218.577271	0.000000	NaN	NaN
486.999855	0.001916	19.160845	0.224126	1219.018921	0.000000	NaN	NaN
487.999912	0.001784	17.840395	0.224811	1219.701538	0.000000	NaN	NaN
488.999969	0.001561	15.612135	0.225272	1220.160522	0.000000	NaN	NaN
490.000026	0.001817	18.170507	0.225861	1220.746704	0.000000	NaN	NaN
491.000084	0.001809	18.087979	0.226255	1221.139160	0.000000	NaN	NaN
492.000141	0.001602	16.024776	0.226689	1221.571167	0.000000	NaN	NaN
493.000198	0.001735	17.345226	0.227362	1222.241333	0.000000	NaN	NaN
494.000255	0.001784	17.840395	0.227997	1222.874023	0.000000	NaN	NaN
495.000312	0.001702	17.015114	0.228327	1223.202759	0.000000	NaN	NaN
495.999370	0.001825	18.253035	0.228883	1223.755981	0.000000	NaN	NaN
496.999427	0.001759	17.592810	0.229345	1224.216309	0.000000	NaN	NaN
497.999484	0.001635	16.354889	0.229821	1224.690186	0.000000	NaN	NaN
498.999541	0.001702	17.015114	0.230412	1225.278931	0.000000	NaN	NaN
499.999598	0.001768	17.675339	0.230929	1225.794189	0.000000	NaN	NaN
500.999656	0.001726	17.262698	0.231444	1226.306274	0.000000	NaN	NaN
501.999713	0.001735	17.345226	0.231780	1226.641357	0.000000	NaN	NaN
502.999770	0.001685	16.850057	0.232523	1227.381470	0.000000	NaN	NaN
503.999827	0.001735	17.345226	0.232932	1227.788696	0.000000	NaN	NaN
504.999884	0.001726	17.262698	0.233497	1228.350464	0.000000	NaN	NaN
505.999942	0.001759	17.592810	0.233906	1228.758423	0.000000	NaN	NaN
506.999999	0.001743	17.427754	0.234564	1229.413208	0.000000	NaN	NaN
508.000056	0.001768	17.675339	0.235176	1230.022705	0.000000	NaN	NaN
509.000113	0.001759	17.592810	0.235409	1230.255249	0.000000	NaN	NaN
510.000170	0.001858	18.583148	0.234887	1229.735596	0.000000	NaN	NaN
511.000228	0.001660	16.602473	0.235430	1230.275757	0.000000	NaN	NaN
512.000285	0.001809	18.087979	0.235800	1230.644287	0.000000	NaN	NaN
513.000342	0.001751	17.510282	0.236356	1231.197510	0.000000	NaN	NaN
513.999399	0.001635	16.354889	0.236755	1231.595093	0.000000	NaN	NaN
514.999456	0.001743	17.427754	0.237267	1232.105347	0.000000	NaN	NaN
515.999514	0.001817	18.170507	0.237746	1232.582153	0.000000	NaN	NaN
516.999571	0.001726	17.262698	0.238361	1233.194214	0.000000	NaN	NaN
517.999628	0.001743	17.427754	0.238965	1233.796387	0.000000	NaN	NaN
518.999685	0.001801	18.005451	0.239363	1234.192505	0.000000	NaN	NaN
519.999742	0.001702	17.015114	0.240128	1234.954712	0.000000	NaN	NaN
520.999799	0.001817	18.170507	0.240554	1235.378418	0.000000	NaN	NaN
521.999857	0.001644	16.437417	0.241168	1235.989624	0.000000	NaN	NaN
522.999914	0.001792	17.922923	0.241616	1236.435913	0.000000	NaN	NaN
523.999971	0.001602	16.024776	0.242218	1237.035034	0.000000	NaN	NaN
525.000028	0.001685	16.850057	0.242828	1237.643311	0.000000	NaN	NaN
526.000085	0.001825	18.253035	0.243289	1238.101807	0.000000	NaN	NaN
527.000143	0.001578	15.777192	0.243746	1238.556885	0.000000	NaN	NaN
528.000200	0.001669	16.685001	0.244352	1239.160889	0.000000	NaN	NaN
529.000257	0.001759	17.592810	0.244956	1239.761963	0.000000	NaN	NaN
530.000314	0.001677	16.767529	0.245398	1240.202393	0.000000	NaN	NaN
530.999372	0.001792	17.922923	0.246048	1240.849854	0.000000	NaN	NaN
531.999429	0.001726	17.262698	0.246503	1241.302368	0.000000	NaN	NaN
532.999486	0.001578	15.777192	0.247011	1241.808228	0.000000	NaN	NaN
533.999543	0.001718	17.180170	0.247493	1242.288940	0.000000	NaN	NaN
534.999600	0.001635	16.354889	0.248136	1242.929199	0.000000	NaN	NaN
535.999658	0.001652	16.519945	0.248731	1243.521118	0.000000	NaN	NaN
536.999715	0.001726	17.262698	0.249058	1243.847290	0.000000	NaN	NaN
537.999772	0.001693	16.932585	0.249624	1244.410400	0.000000	NaN	NaN
538.999829	0.001677	16.767529	0.250215	1244.998779	0.000000	NaN	NaN
539.999886	0.001652	16.519945	0.250786	1245.567505	0.000000	NaN	NaN
540.999943	0.001718	17.180170	0.251277	1246.057251	0.000000	NaN	NaN
542.000001	0.001652	16.519945	0.251701	1246.478638	0.000000	NaN	NaN
543.000058	0.001718	17.180170	0.252346	1247.121094	0.000000	NaN	NaN
544.000115	0.001743	17.427754	0.252805	1247.578125	0.000000	NaN	NaN
545.000172	0.001710	17.097642	0.253381	1248.151978	0.000000	NaN	NaN
546.000230	0.001702	17.015114	0.254022	1248.789917	0.000000	NaN	NaN
547.000287	0.001710	17.097642	0.254379	1249.145874	0.000000	NaN	NaN
548.000344	0.001602	16.024776	0.254855	1249.619995	0.000000	NaN	NaN
548.999401	0.001792	17.922923	0.255463	1250.225708	0.000000	NaN	NaN
549.999458	0.001718	17.180170	0.255775	1250.535645	0.000000	NaN	NaN
550.999515	0.001751	17.510282	0.256555	1251.312378	0.000000	NaN	NaN
551.999573	0.001702	17.015114	0.257084	1251.839478	0.000000	NaN	NaN
552.999630	0.001735	17.345226	0.257519	1252.273071	0.000000	NaN	NaN
553.999687	0.001545	15.447079	0.258002	1252.753418	0.000000	NaN	NaN
554.999744	0.001652	16.519945	0.258538	1253.286987	0.000000	NaN	NaN
555.999801	0.001635	16.354889	0.258923	1253.671265	0.000000	NaN	NaN
556.999859	0.001660	16.602473	0.259328	1254.074341	0.000000	NaN	NaN
557.999916	0.001669	16.685001	0.259924	1254.667358	0.000000	NaN	NaN
558.999973	0.001718	17.180170	0.260293	1255.035522	0.000000	NaN	NaN
560.000030	0.001627	16.272360	0.260882	1255.622192	0.000000	NaN	NaN
561.000087	0.001652	16.519945	0.261359	1256.096436	0.000000	NaN	NaN
562.000145	0.001743	17.427754	0.261826	1256.562134	0.000000	NaN	NaN
563.000202	0.001652	16.519945	0.262310	1257.043945	0.000000	NaN	NaN
564.000259	0.001553	15.529607	0.262803	1257.534668	0.000000	NaN	NaN
565.000316	0.001669	16.685001	0.263154	1257.884521	0.000000	NaN	NaN
565.999373	0.001768	17.675339	0.263680	1258.408081	0.000000	NaN	NaN
566.999431	0.001569	15.694663	0.264250	1258.975464	0.000000	NaN	NaN
567.999488	0.001635	16.354889	0.264623	1259.347046	0.000000	NaN	NaN
568.999545	0.001512	15.116967	0.265113	1259.834717	0.000000	NaN	NaN
569.999602	0.001677	16.767529	0.265398	1260.119141	0.000000	NaN	NaN
570.999659	0.001652	16.519945	0.265927	1260.645264	0.000000	NaN	NaN
571.999717	0.001619	16.189832	0.266012	1260.729980	0.000000	NaN	NaN
572.999774	0.001602	16.024776	0.266717	1261.432373	0.000000	NaN	NaN
573.999831	0.001619	16.189832	0.266894	1261.609009	0.000000	NaN	NaN
574.999888	0.001553	15.529607	0.267265	1261.978271	0.000000	NaN	NaN
575.999945	0.001479	14.786854	0.267826	1262.536865	0.000000	NaN	NaN
577.000003	0.001569	15.694663	0.267999	1262.708862	0.000000	NaN	NaN
578.000060	0.001561	15.612135	0.268509	1263.216797	0.000000	NaN	NaN
579.000117	0.001437	14.374213	0.268940	1263.646362	0.000000	NaN	NaN
580.000174	0.001429	14.291685	0.269082	1263.787720	0.000000	NaN	NaN
581.000231	0.001396	13.961573	0.269642	1264.344971	0.000000	NaN	NaN
582.000289	0.001446	14.456742	0.269904	1264.606201	0.000000	NaN	NaN
583.000346	0.001314	13.136292	0.270196	1264.897095	0.000000	NaN	NaN
583.999403	0.001446	14.456742	0.270459	1265.158813	0.000000	NaN	NaN
584.999460	0.001487	14.869382	0.270673	1265.371338	0.000000	NaN	NaN
585.999517	0.001446	14.456742	0.270804	1265.502686	0.000000	NaN	NaN
586.999574	0.001413	14.126629	0.270987	1265.684204	0.000000	NaN	NaN
587.999632	0.001396	13.961573	0.271294	1265.989868	0.000000	NaN	NaN
588.999689	0.001388	13.879045	0.271295	1265.991577	0.000000	NaN	NaN
589.999746	0.001322	13.218820	0.271380	1266.076050	0.000000	NaN	NaN
590.999803	0.001396	13.961573	0.271325	1266.020996	0.000000	NaN	NaN
591.999860	0.001305	13.053763	0.271237	1265.933960	0.000000	NaN	NaN
592.999918	0.001256	12.558595	0.271024	1265.721436	0.000000	NaN	NaN
593.999975	0.001371	13.713988	0.270827	1265.525146	0.000000	NaN	NaN
595.000032	0.001132	11.320673	0.270790	1265.488281	0.000000	NaN	NaN
596.000089	0.001264	12.641123	0.270449	1265.149048	0.000000	NaN	NaN
597.000147	0.001116	11.155617	0.270061	1264.762451	0.000000	NaN	NaN
598.000204	0.001190	11.898370	0.269622	1264.325073	0.000000	NaN	NaN
599.000261	0.001116	11.155617	0.268947	1263.653198	0.000000	NaN	NaN
600.000318	0.000959	9.587582	0.268318	1263.026978	0.000000	NaN	NaN
600.999375	0.000926	9.257470	0.267832	1262.542480	0.000000	NaN	NaN
601.999432	0.000959	9.587582	0.266992	1261.706421	0.000000	NaN	NaN
602.999490	0.000959	9.587582	0.266204	1260.921631	0.000000	NaN	NaN
603.999547	0.000934	9.339998	0.265507	1260.227173	0.000000	NaN	NaN
604.999604	0.000893	8.927357	0.264250	1258.975464	0.000000	NaN	NaN
605.999661	0.000876	8.762301	0.263236	1257.965576	0.000000	NaN	NaN
606.999718	0.000719	7.194267	0.261848	1256.583374	0.000000	NaN	NaN
607.999776	0.000612	6.121401	0.260245	1254.987183	0.000000	NaN	NaN
608.999833	0.000728	7.276795	0.258491	1253.240967	0.000000	NaN	NaN
609.999890	0.000472	4.718423	0.256860	1251.616943	0.000000	NaN	NaN
610.999947	0.000571	5.708760	0.255258	1250.020996	0.000000	NaN	NaN
612.000004	0.000472	4.718423	0.253259	1248.030640	0.000000	NaN	NaN
613.000062	0.000571	5.708760	0.250890	1245.671875	0.000000	NaN	NaN
614.000119	0.000398	3.975670	0.249123	1243.911987	0.000000	NaN	NaN
615.000176	0.000356	3.563029	0.246718	1241.516479	0.000000	NaN	NaN
616.000233	0.000447	4.470838	0.244960	1239.765991	0.000000	NaN	NaN
617.000290	0.000356	3.563029	0.243225	1238.038696	0.000000	NaN	NaN
618.000348	0.000224	2.242579	0.241228	1236.049683	0.000000	NaN	NaN
618.999405	0.000307	3.067860	0.238868	1233.699463	0.000000	NaN	NaN
619.999462	0.000257	2.572691	0.237001	1231.840576	0.000000	NaN	NaN
620.999519	0.000373	3.728085	0.235106	1229.953003	0.000000	NaN	NaN
621.999576	0.000274	2.737748	0.233094	1227.949097	0.000000	NaN	NaN
622.999634	0.000216	2.160051	0.230737	1225.602539	0.000000	NaN	NaN
623.999691	0.000150	1.499826	0.229446	1224.317261	0.000000	NaN	NaN
624.999748	0.000100	1.004657	0.228965	1223.838135	0.000000	NaN	NaN
625.999805	0.000191	1.912466	0.228252	1223.127441	0.000000	NaN	NaN
626.999862	0.000315	3.150388	0.225272	1220.160522	0.000000	NaN	NaN
627.999920	0.000109	1.087185	0.223682	1218.576782	0.000000	NaN	NaN
628.999977	0.000166	1.664882	0.222277	1217.177612	0.000000	NaN	NaN
630.000034	0.000125	1.252241	0.220643	1215.550781	0.000000	NaN	NaN
631.000091	0.000133	1.334770	0.219071	1213.984741	0.000000	NaN	NaN
632.000148	0.000158	1.582354	0.217901	1212.819458	0.000000	NaN	NaN
633.000206	0.000150	1.499826	0.216648	1211.571899	0.000000	NaN	NaN
634.000263	0.000241	2.407635	0.215644	1210.571899	0.000000	NaN	NaN
635.000320	4.269601E-5	0.426960	0.214659	1209.591919	0.000000	NaN	NaN
635.999377	0.000199	1.994995	0.213665	1208.601318	0.000000	NaN	NaN
636.999434	5.094882E-5	0.509488	0.212935	1207.874512	0.000000	NaN	NaN
637.999491	0.000109	1.087185	0.212045	1206.988159	0.000000	NaN	NaN
638.999549	9.221289E-5	0.922129	0.211048	1205.995850	0.000000	NaN	NaN
639.999606	-1.507368E-5	-0.150737	0.210251	1205.201538	0.000000	NaN	NaN
640.999663	-3.157930E-5	-0.315793	0.209755	1204.708008	0.000000	NaN	NaN
641.999720	0.000150	1.499826	0.209478	1204.431763	0.000000	NaN	NaN
642.999778	-3.157930E-5	-0.315793	0.209413	1204.366943	0.000000	NaN	NaN
643.999835	-1.507368E-5	-0.150737	0.209803	1204.755493	0.000000	NaN	NaN
644.999892	9.684761E-6	0.096848	0.210727	1205.675659	0.000000	NaN	NaN
645.999949	-5.633774E-5	-0.563377	0.212412	1207.353760	0.000000	NaN	NaN
647.000006	-0.000155	-1.553715	0.214748	1209.679810	0.000000	NaN	NaN
648.000064	-5.633774E-5	-0.563377	0.217437	1212.358276	0.000000	NaN	NaN
649.000121	-8.109618E-5	-0.810962	0.220442	1215.349976	0.000000	NaN	NaN
650.000178	-0.000147	-1.471187	0.223910	1218.803589	0.000000	NaN	NaN
651.000235	-6.820864E-6	-0.068209	0.228712	1223.585571	0.000000	NaN	NaN
652.000292	-0.000106	-1.058546	0.235411	1230.256714	0.000000	NaN	NaN
653.000349	-5.633774E-5	-0.563377	0.242117	1236.935181	0.000000	NaN	NaN
653.999407	-0.000188	-1.883827	0.251401	1246.179932	0.000000	NaN	NaN
654.999464	-0.000164	-1.636243	0.320480	1314.970825	0.000000	NaN	NaN
655.999521	-0.000122	-1.223602	0.327731	1322.191406	0.000000	NaN	NaN
656.999578	-0.000155	-1.553715	0.333213	1327.651001	0.000000	NaN	NaN
657.999635	-0.000147	-1.471187	0.337239	1331.660278	0.000000	NaN	NaN
658.999693	-0.000106	-1.058546	0.338098	1332.515259	0.000000	NaN	NaN
659.999750	-0.000164	-1.636243	0.339045	1333.458252	0.000000	NaN	NaN
660.999807	-8.109618E-5	-0.810962	0.339939	1334.348877	0.000000	NaN	NaN
661.999864	0.000117	1.169713	0.340593	1334.999756	0.000000	NaN	NaN
662.499893	-0.000164	-1.636243	0.340927	1335.332886	0.000000	NaN	NaN