File: data/57k_1-1_2 (190315).lvm
LabVIEW Measurement
Writer_Version	2
Reader_Version	2
Separator	Tab
Decimal_Separator	.
Multi_Headings	No
X_Columns	One
Time_Pref	Absolute
Operator	user
Description	Load(N)/Stress(MPa)/Distance A(pixel)/Strain A/Distance B(pixel)/Strain B/Poisson's ratio
Date	2019/03/15
Time	14:37:29.3127093315124511719
***End_of_Header***

Notes	X 값은 오직 다음과 같을 때에만 유효함이 보장됩니다. Dev1/ai0
Channels	7
Samples	1	1	1	1	1	1	1
Date	2019/03/15	2019/03/15	2019/03/15	2019/03/15	2019/03/15	2019/03/15	2019/03/15
Time	15:59:53.3124900300349912258	15:59:53.3124900300349912258	15:59:53.3124899864196777344	15:59:53.3124899864196777344	15:59:53.3124899864196777344	15:59:53.3124899864196777344	15:59:53.3124899864196777344
Y_Unit_Label	Volts	Volts
X_Dimension	Time	Time	Time	Time	Time	Time	Time
X0	0.0000000000000000E+0	0.0000000000000000E+0	0.0000000000000000E+0	0.0000000000000000E+0	0.0000000000000000E+0	0.0000000000000000E+0	0.0000000000000000E+0
Delta_X	0.000000	0.000000	1.000000	1.000000	1.000000	1.000000	1.000000
***End_of_Header***
X_Value	Dev1/ai0	Dev1/ai0 1	Untitled	Untitled 1	Untitled 2	Untitled 3	Untitled 4	Comment
0.000000	-6.459055E-5	-0.645906	-1.949072E-5	975.958069	0.000000	NaN	NaN
1.000057	-4.808493E-5	-0.480849	5.257130E-5	976.028442	0.000000	NaN	NaN
2.000114	1.793757E-5	0.179376	8.583069E-6	975.985535	0.000000	NaN	NaN
3.000172	-6.820864E-6	-0.068209	2.336502E-5	975.999939	0.000000	NaN	NaN
4.000229	5.920164E-5	0.592016	0.000128	976.102295	0.000000	NaN	NaN
5.000286	-6.820864E-6	-0.068209	0.000391	976.359070	0.000000	NaN	NaN
6.000343	4.269601E-5	0.426960	0.000617	976.578857	0.000000	NaN	NaN
7.000400	2.619039E-5	0.261904	0.000896	976.851624	0.000000	NaN	NaN
8.000458	0.000109	1.087185	0.001186	977.134521	0.000000	NaN	NaN
9.000515	0.000142	1.417298	0.001524	977.464783	0.000000	NaN	NaN
9.999572	0.000150	1.499826	0.001809	977.742371	0.000000	NaN	NaN
10.999629	0.000249	2.490163	0.002073	977.999878	0.000000	NaN	NaN
11.999686	0.000100	1.004657	0.002381	978.301147	0.000000	NaN	NaN
12.999744	0.000158	1.582354	0.002651	978.564758	0.000000	NaN	NaN
13.999801	0.000307	3.067860	0.002966	978.871460	0.000000	NaN	NaN
14.999858	0.000299	2.985332	0.003223	979.122681	0.000000	NaN	NaN
15.999915	0.000249	2.490163	0.003527	979.418945	0.000000	NaN	NaN
16.999972	0.000389	3.893141	0.003855	979.739502	0.000000	NaN	NaN
18.000030	0.000381	3.810613	0.004142	980.019714	0.000000	NaN	NaN
19.000087	0.000431	4.305782	0.004430	980.301025	0.000000	NaN	NaN
20.000144	0.000356	3.563029	0.004773	980.635864	0.000000	NaN	NaN
21.000201	0.000373	3.728085	0.005037	980.892944	0.000000	NaN	NaN
22.000258	0.000381	3.810613	0.005337	981.186035	0.000000	NaN	NaN
23.000316	0.000447	4.470838	0.005638	981.479431	0.000000	NaN	NaN
24.000373	0.000480	4.800951	0.005824	981.661560	0.000000	NaN	NaN
25.000430	0.000530	5.296120	0.006107	981.937683	0.000000	NaN	NaN
26.000487	0.000538	5.378648	0.006543	982.363220	0.000000	NaN	NaN
27.000544	0.000505	5.048535	0.007012	982.820435	0.000000	NaN	NaN
27.999602	0.000505	5.048535	0.007321	983.122681	0.000000	NaN	NaN
28.999659	0.000571	5.708760	0.007910	983.696899	0.000000	NaN	NaN
29.999716	0.000596	5.956345	0.008200	983.979675	0.000000	NaN	NaN
30.999773	0.000612	6.121401	0.008577	984.347839	0.000000	NaN	NaN
31.999830	0.000571	5.708760	0.008980	984.741272	0.000000	NaN	NaN
32.999887	0.000785	7.854492	0.009459	985.208984	0.000000	NaN	NaN
33.999945	0.000736	7.359323	0.009895	985.634705	0.000000	NaN	NaN
35.000002	0.000785	7.854492	0.010281	986.010925	0.000000	NaN	NaN
36.000059	0.000604	6.038873	0.010607	986.329468	0.000000	NaN	NaN
37.000116	0.000761	7.606907	0.011096	986.807068	0.000000	NaN	NaN
38.000174	0.000695	6.946682	0.011386	987.089172	0.000000	NaN	NaN
39.000231	0.000686	6.864154	0.011860	987.552124	0.000000	NaN	NaN
40.000288	0.000752	7.524379	0.012266	987.948853	0.000000	NaN	NaN
41.000345	0.000769	7.689435	0.012637	988.310791	0.000000	NaN	NaN
42.000402	0.000703	7.029210	0.013003	988.667725	0.000000	NaN	NaN
43.000459	0.000802	8.019548	0.013486	989.139282	0.000000	NaN	NaN
44.000517	0.000835	8.349660	0.014022	989.662170	0.000000	NaN	NaN
44.999574	0.000744	7.441851	0.014534	990.162109	0.000000	NaN	NaN
45.999631	0.000926	9.257470	0.014571	990.198547	0.000000	NaN	NaN
46.999688	0.000794	7.937020	0.015118	990.732300	0.000000	NaN	NaN
47.999745	0.000835	8.349660	0.015565	991.167725	0.000000	NaN	NaN
48.999803	0.000876	8.762301	0.016006	991.598083	0.000000	NaN	NaN
49.999860	0.000893	8.927357	0.016451	992.032776	0.000000	NaN	NaN
50.999917	0.000860	8.597245	0.016914	992.484741	0.000000	NaN	NaN
51.999974	0.000843	8.432188	0.017471	993.028320	0.000000	NaN	NaN
53.000031	0.000868	8.679773	0.017630	993.183167	0.000000	NaN	NaN
54.000089	0.001058	10.577920	0.018113	993.655090	0.000000	NaN	NaN
55.000146	0.000884	8.844829	0.018598	994.127991	0.000000	NaN	NaN
56.000203	0.000876	8.762301	0.019065	994.583923	0.000000	NaN	NaN
57.000260	0.000934	9.339998	0.019619	995.124756	0.000000	NaN	NaN
58.000317	0.001041	10.412863	0.020082	995.577087	0.000000	NaN	NaN
59.000375	0.002733	27.331129	0.020699	996.179260	0.000000	NaN	NaN
60.000432	0.001124	11.238145	0.021225	996.692261	0.000000	NaN	NaN
61.000489	0.000934	9.339998	0.021424	996.885986	0.000000	NaN	NaN
62.000546	0.000951	9.505054	0.021927	997.377380	0.000000	NaN	NaN
62.999603	0.000901	9.009885	0.022416	997.854492	0.000000	NaN	NaN
63.999661	0.001025	10.247807	0.023027	998.450989	0.000000	NaN	NaN
64.999718	0.000901	9.009885	0.023556	998.967163	0.000000	NaN	NaN
65.999775	0.000942	9.422526	0.024102	999.500061	0.000000	NaN	NaN
66.999832	0.000893	8.927357	0.025015	1000.391235	0.000000	NaN	NaN
67.999889	0.001033	10.330335	0.025632	1000.992981	0.000000	NaN	NaN
68.999947	0.001000	10.000223	0.025902	1001.256836	0.000000	NaN	NaN
70.000004	0.001074	10.742976	0.025790	1001.147705	0.000000	NaN	NaN
71.000061	0.001190	11.898370	0.026439	1001.781006	0.000000	NaN	NaN
72.000118	0.001058	10.577920	0.027274	1002.595764	0.000000	NaN	NaN
73.000175	0.001107	11.073088	0.027814	1003.123169	0.000000	NaN	NaN
74.000233	0.001099	10.990560	0.028303	1003.599792	0.000000	NaN	NaN
75.000290	0.001083	10.825504	0.028977	1004.257812	0.000000	NaN	NaN
76.000347	0.001017	10.165279	0.029448	1004.717957	0.000000	NaN	NaN
77.000404	0.000909	9.092413	0.029590	1004.856262	0.000000	NaN	NaN
78.000461	0.001074	10.742976	0.030154	1005.406738	0.000000	NaN	NaN
79.000519	0.001066	10.660448	0.031050	1006.280884	0.000000	NaN	NaN
79.999576	0.001091	10.908032	0.031312	1006.537415	0.000000	NaN	NaN
80.999633	0.001157	11.568257	0.031173	1006.400879	0.000000	NaN	NaN
81.999690	0.001132	11.320673	0.031686	1006.902283	0.000000	NaN	NaN
82.999747	0.001165	11.650785	0.032196	1007.399292	0.000000	NaN	NaN
83.999804	0.001182	11.815842	0.032806	1007.994934	0.000000	NaN	NaN
84.999862	0.001157	11.568257	0.033118	1008.300049	0.000000	NaN	NaN
85.999919	0.001025	10.247807	0.033809	1008.973694	0.000000	NaN	NaN
86.999976	0.001157	11.568257	0.033604	1008.774109	0.000000	NaN	NaN
88.000033	0.001025	10.247807	0.034145	1009.301575	0.000000	NaN	NaN
89.000090	0.001149	11.485729	0.034706	1009.849487	0.000000	NaN	NaN
90.000148	0.001198	11.980898	0.035279	1010.408325	0.000000	NaN	NaN
91.000205	0.001140	11.403201	0.034710	1009.853271	0.000000	NaN	NaN
92.000262	0.001206	12.063426	0.035042	1010.177368	0.000000	NaN	NaN
93.000319	0.001124	11.238145	0.035778	1010.895630	0.000000	NaN	NaN
94.000377	0.001198	11.980898	0.036126	1011.234863	0.000000	NaN	NaN
95.000434	0.001124	11.238145	0.036669	1011.765564	0.000000	NaN	NaN
96.000491	0.001190	11.898370	0.037259	1012.341370	0.000000	NaN	NaN
97.000548	0.001008	10.082751	0.036565	1011.664185	0.000000	NaN	NaN
97.999605	0.001198	11.980898	0.037238	1012.320679	0.000000	NaN	NaN
98.999662	0.001165	11.650785	0.037518	1012.593384	0.000000	NaN	NaN
99.999720	0.001149	11.485729	0.038069	1013.131958	0.000000	NaN	NaN
100.999777	0.001198	11.980898	0.038525	1013.576965	0.000000	NaN	NaN
101.999834	0.001215	12.145954	0.039084	1014.121765	0.000000	NaN	NaN
102.999891	0.001281	12.806179	0.039348	1014.379822	0.000000	NaN	NaN
103.999949	0.001140	11.403201	0.039889	1014.907410	0.000000	NaN	NaN
105.000006	0.001074	10.742976	0.040495	1015.499268	0.000000	NaN	NaN
106.000063	0.001099	10.990560	0.041257	1016.243042	0.000000	NaN	NaN
107.000120	0.001124	11.238145	0.041547	1016.526184	0.000000	NaN	NaN
108.000177	0.001239	12.393538	0.042170	1017.134399	0.000000	NaN	NaN
109.000235	0.001173	11.733313	0.043014	1017.957581	0.000000	NaN	NaN
110.000292	0.001264	12.641123	0.042957	1017.902527	0.000000	NaN	NaN
111.000349	0.001272	12.723651	0.043737	1018.663879	0.000000	NaN	NaN
112.000406	0.001239	12.393538	0.044283	1019.195923	0.000000	NaN	NaN
113.000463	0.001248	12.476067	0.044856	1019.755249	0.000000	NaN	NaN
114.000520	0.001223	12.228482	0.045434	1020.319763	0.000000	NaN	NaN
114.999578	0.001239	12.393538	0.045828	1020.704651	0.000000	NaN	NaN
115.999635	0.001173	11.733313	0.046011	1020.882385	0.000000	NaN	NaN
116.999692	0.001404	14.044101	0.047750	1022.580017	0.000000	NaN	NaN
117.999749	0.001322	13.218820	0.047020	1021.867187	0.000000	NaN	NaN
118.999806	0.001297	12.971235	0.047740	1022.569824	0.000000	NaN	NaN
119.999864	0.001198	11.980898	0.048311	1023.127380	0.000000	NaN	NaN
120.999921	0.001041	10.412863	0.048311	1023.127380	0.000000	NaN	NaN
121.999978	0.001157	11.568257	0.048654	1023.462769	0.000000	NaN	NaN
123.000035	0.001198	11.980898	0.049138	1023.934998	0.000000	NaN	NaN
124.000092	0.001215	12.145954	0.049705	1024.488281	0.000000	NaN	NaN
125.000150	0.001182	11.815842	0.050201	1024.971802	0.000000	NaN	NaN
126.000207	0.001149	11.485729	0.050687	1025.446167	0.000000	NaN	NaN
127.000264	0.001182	11.815842	0.051295	1026.040161	0.000000	NaN	NaN
128.000321	0.001338	13.383876	0.051760	1026.493530	0.000000	NaN	NaN
129.000378	0.001074	10.742976	0.052340	1027.059814	0.000000	NaN	NaN
130.000436	0.001347	13.466404	0.052884	1027.590576	0.000000	NaN	NaN
131.000493	0.001256	12.558595	0.053509	1028.200928	0.000000	NaN	NaN
132.000550	0.001165	11.650785	0.053883	1028.565674	0.000000	NaN	NaN
132.999607	0.001157	11.568257	0.054372	1029.042603	0.000000	NaN	NaN
133.999664	0.001347	13.466404	0.054873	1029.531372	0.000000	NaN	NaN
134.999722	0.001289	12.888707	0.055400	1030.045898	0.000000	NaN	NaN
135.999779	0.001099	10.990560	0.055979	1030.610962	0.000000	NaN	NaN
136.999836	0.001165	11.650785	0.056494	1031.113525	0.000000	NaN	NaN
137.999893	0.001083	10.825504	0.057003	1031.611206	0.000000	NaN	NaN
138.999950	0.001066	10.660448	0.057531	1032.125610	0.000000	NaN	NaN
140.000008	0.001421	14.209157	0.058023	1032.606323	0.000000	NaN	NaN
141.000065	0.001124	11.238145	0.058593	1033.162964	0.000000	NaN	NaN
142.000122	0.001289	12.888707	0.059107	1033.664429	0.000000	NaN	NaN
143.000179	0.001256	12.558595	0.059568	1034.113647	0.000000	NaN	NaN
144.000236	0.001198	11.980898	0.060079	1034.613159	0.000000	NaN	NaN
145.000294	0.001198	11.980898	0.060608	1035.129150	0.000000	NaN	NaN
146.000351	0.001041	10.412863	0.061131	1035.639648	0.000000	NaN	NaN
147.000408	0.001314	13.136292	0.061698	1036.193115	0.000000	NaN	NaN
148.000465	0.001256	12.558595	0.062104	1036.589233	0.000000	NaN	NaN
149.000522	0.001281	12.806179	0.062684	1037.154907	0.000000	NaN	NaN
149.999580	0.001140	11.403201	0.063161	1037.621338	0.000000	NaN	NaN
150.999637	0.001248	12.476067	0.063604	1038.053101	0.000000	NaN	NaN
151.999694	0.001223	12.228482	0.064201	1038.635864	0.000000	NaN	NaN
152.999751	0.001371	13.713988	0.064668	1039.091431	0.000000	NaN	NaN
153.999808	0.001231	12.311010	0.065263	1039.672119	0.000000	NaN	NaN
154.999865	0.001256	12.558595	0.065660	1040.059814	0.000000	NaN	NaN
155.999923	0.001289	12.888707	0.066200	1040.586548	0.000000	NaN	NaN
156.999980	0.001239	12.393538	0.066681	1041.055786	0.000000	NaN	NaN
158.000037	0.001223	12.228482	0.067263	1041.623779	0.000000	NaN	NaN
159.000094	0.001314	13.136292	0.067631	1041.983765	0.000000	NaN	NaN
160.000151	0.001182	11.815842	0.068190	1042.528564	0.000000	NaN	NaN
161.000209	0.001289	12.888707	0.068660	1042.987549	0.000000	NaN	NaN
162.000266	0.001305	13.053763	0.069163	1043.478394	0.000000	NaN	NaN
163.000323	0.001157	11.568257	0.069754	1044.055908	0.000000	NaN	NaN
164.000380	0.001190	11.898370	0.070201	1044.491699	0.000000	NaN	NaN
165.000438	0.000125	1.252241	0.070631	1044.911377	0.000000	NaN	NaN
166.000495	0.001223	12.228482	0.071126	1045.393921	0.000000	NaN	NaN
167.000552	0.001330	13.301348	0.071577	1045.834351	0.000000	NaN	NaN
167.999609	0.001314	13.136292	0.072168	1046.411377	0.000000	NaN	NaN
168.999666	0.001264	12.641123	0.072659	1046.890991	0.000000	NaN	NaN
169.999723	0.001157	11.568257	0.073158	1047.377197	0.000000	NaN	NaN
170.999781	0.001281	12.806179	0.073667	1047.874756	0.000000	NaN	NaN
171.999838	0.001371	13.713988	0.074114	1048.310303	0.000000	NaN	NaN
172.999895	0.001281	12.806179	0.074726	1048.907837	0.000000	NaN	NaN
173.999952	0.001248	12.476067	0.075155	1049.326416	0.000000	NaN	NaN
175.000009	0.001248	12.476067	0.075707	1049.864990	0.000000	NaN	NaN
176.000067	0.001404	14.044101	0.076227	1050.373169	0.000000	NaN	NaN
177.000124	0.001396	13.961573	0.076779	1050.911743	0.000000	NaN	NaN
178.000181	0.001322	13.218820	0.077217	1051.339233	0.000000	NaN	NaN
179.000238	0.001421	14.209157	0.077794	1051.902344	0.000000	NaN	NaN
180.000295	0.001503	15.034438	0.078234	1052.331787	0.000000	NaN	NaN
181.000353	0.001330	13.301348	0.078760	1052.844727	0.000000	NaN	NaN
182.000410	0.001347	13.466404	0.079358	1053.428711	0.000000	NaN	NaN
183.000467	0.001215	12.145954	0.079913	1053.970093	0.000000	NaN	NaN
184.000524	0.001462	14.621798	0.080311	1054.358643	0.000000	NaN	NaN
184.999581	0.001297	12.971235	0.080847	1054.881592	0.000000	NaN	NaN
185.999639	0.001355	13.548932	0.081306	1055.329834	0.000000	NaN	NaN
186.999696	0.001404	14.044101	0.081771	1055.784058	0.000000	NaN	NaN
187.999753	0.001305	13.053763	0.082410	1056.406860	0.000000	NaN	NaN
188.999810	0.001437	14.374213	0.082748	1056.736938	0.000000	NaN	NaN
189.999867	0.001404	14.044101	0.083249	1057.225952	0.000000	NaN	NaN
190.999925	0.001388	13.879045	0.083861	1057.823853	0.000000	NaN	NaN
191.999982	0.001256	12.558595	0.084355	1058.305664	0.000000	NaN	NaN
193.000039	0.001206	12.063426	0.084798	1058.737549	0.000000	NaN	NaN
194.000096	0.001322	13.218820	0.085263	1059.191528	0.000000	NaN	NaN
195.000153	0.001248	12.476067	0.085893	1059.806641	0.000000	NaN	NaN
196.000211	0.001363	13.631460	0.086433	1060.333740	0.000000	NaN	NaN
197.000268	0.001388	13.879045	0.086820	1060.710937	0.000000	NaN	NaN
198.000325	0.001355	13.548932	0.087433	1061.309814	0.000000	NaN	NaN
199.000382	0.001396	13.961573	0.087813	1061.680664	0.000000	NaN	NaN
200.000439	0.001371	13.713988	0.088463	1062.314819	0.000000	NaN	NaN
201.000497	0.001281	12.806179	0.088949	1062.789673	0.000000	NaN	NaN
202.000554	0.001347	13.466404	0.089494	1063.321289	0.000000	NaN	NaN
202.999611	0.001322	13.218820	0.090033	1063.847290	0.000000	NaN	NaN
203.999668	0.001355	13.548932	0.090467	1064.270630	0.000000	NaN	NaN
204.999725	0.001338	13.383876	0.091083	1064.872070	0.000000	NaN	NaN
205.999783	0.001347	13.466404	0.091497	1065.276245	0.000000	NaN	NaN
206.999840	0.001437	14.374213	0.092026	1065.791992	0.000000	NaN	NaN
207.999897	0.001413	14.126629	0.092546	1066.299927	0.000000	NaN	NaN
208.999954	0.001404	14.044101	0.092960	1066.703613	0.000000	NaN	NaN
210.000011	0.001528	15.282023	0.093590	1067.319214	0.000000	NaN	NaN
211.000068	0.001314	13.136292	0.094162	1067.877319	0.000000	NaN	NaN
212.000126	0.001322	13.218820	0.094533	1068.239136	0.000000	NaN	NaN
213.000183	0.001413	14.126629	0.095042	1068.736084	0.000000	NaN	NaN
214.000240	0.001256	12.558595	0.095656	1069.335327	0.000000	NaN	NaN
215.000297	0.001338	13.383876	0.096122	1069.790039	0.000000	NaN	NaN
216.000354	0.001470	14.704326	0.096591	1070.247559	0.000000	NaN	NaN
217.000412	0.001347	13.466404	0.097102	1070.746704	0.000000	NaN	NaN
218.000469	0.001272	12.723651	0.097646	1071.277588	0.000000	NaN	NaN
219.000526	0.001446	14.456742	0.098212	1071.830200	0.000000	NaN	NaN
219.999583	0.001396	13.961573	0.098711	1072.316284	0.000000	NaN	NaN
220.999640	0.001446	14.456742	0.099207	1072.801147	0.000000	NaN	NaN
221.999698	0.001347	13.466404	0.099740	1073.320801	0.000000	NaN	NaN
223.062758	0.001355	13.548932	0.100253	1073.821655	0.000000	NaN	NaN
223.999812	0.001322	13.218820	0.100712	1074.269897	0.000000	NaN	NaN
224.999869	0.001297	12.971235	0.101207	1074.752563	0.000000	NaN	NaN
225.999926	0.001421	14.209157	0.101840	1075.370972	0.000000	NaN	NaN
226.999984	0.001314	13.136292	0.102178	1075.700195	0.000000	NaN	NaN
228.000041	0.001355	13.548932	0.102818	1076.325562	0.000000	NaN	NaN
229.000098	0.001429	14.291685	0.103297	1076.792969	0.000000	NaN	NaN
230.000155	0.001347	13.466404	0.103670	1077.156372	0.000000	NaN	NaN
231.000213	0.001297	12.971235	0.104161	1077.635498	0.000000	NaN	NaN
232.000270	0.001322	13.218820	0.104752	1078.212402	0.000000	NaN	NaN
233.000327	0.001380	13.796517	0.105154	1078.604980	0.000000	NaN	NaN
234.000384	0.001462	14.621798	0.105737	1079.174438	0.000000	NaN	NaN
235.000441	0.001305	13.053763	0.106202	1079.628174	0.000000	NaN	NaN
236.000498	0.001404	14.044101	0.106669	1080.083496	0.000000	NaN	NaN
237.000556	0.001347	13.466404	0.107179	1080.581299	0.000000	NaN	NaN
237.999613	0.001371	13.713988	0.107814	1081.200928	0.000000	NaN	NaN
238.999670	0.001380	13.796517	0.108130	1081.509521	0.000000	NaN	NaN
239.999727	0.001396	13.961573	0.108616	1081.983643	0.000000	NaN	NaN
240.999784	0.001305	13.053763	0.109061	1082.418335	0.000000	NaN	NaN
241.999842	0.001289	12.888707	0.109639	1082.982300	0.000000	NaN	NaN
242.999899	0.001421	14.209157	0.110074	1083.406738	0.000000	NaN	NaN
243.999956	0.001512	15.116967	0.110547	1083.868408	0.000000	NaN	NaN
245.000013	0.001363	13.631460	0.111113	1084.420654	0.000000	NaN	NaN
246.000070	0.001470	14.704326	0.111455	1084.755005	0.000000	NaN	NaN
247.000128	0.001281	12.806179	0.112105	1085.389526	0.000000	NaN	NaN
248.000185	0.001404	14.044101	0.112659	1085.929199	0.000000	NaN	NaN
249.000242	0.001437	14.374213	0.113163	1086.421143	0.000000	NaN	NaN
250.000299	0.001363	13.631460	0.113577	1086.825195	0.000000	NaN	NaN
251.000356	0.001363	13.631460	0.114213	1087.446411	0.000000	NaN	NaN
252.000414	0.001479	14.786854	0.114779	1087.999146	0.000000	NaN	NaN
253.000471	0.001338	13.383876	0.115115	1088.326538	0.000000	NaN	NaN
254.000528	0.001429	14.291685	0.115657	1088.855713	0.000000	NaN	NaN
254.999585	0.001429	14.291685	0.116088	1089.276245	0.000000	NaN	NaN
255.999642	0.001380	13.796517	0.116702	1089.875488	0.000000	NaN	NaN
256.999700	0.001380	13.796517	0.117093	1090.257080	0.000000	NaN	NaN
257.999757	0.001437	14.374213	0.117628	1090.779663	0.000000	NaN	NaN
258.999814	0.001479	14.786854	0.117439	1090.594849	0.000000	NaN	NaN
259.999871	0.001454	14.539270	0.117970	1091.112671	0.000000	NaN	NaN
260.999928	0.001437	14.374213	0.118497	1091.627197	0.000000	NaN	NaN
261.999986	0.001495	14.951910	0.119085	1092.201660	0.000000	NaN	NaN
263.000043	0.001462	14.621798	0.119541	1092.645996	0.000000	NaN	NaN
264.000100	0.001396	13.961573	0.120080	1093.172119	0.000000	NaN	NaN
265.000157	0.001520	15.199495	0.120617	1093.696167	0.000000	NaN	NaN
266.000214	0.001297	12.971235	0.121004	1094.074341	0.000000	NaN	NaN
267.000272	0.001396	13.961573	0.121556	1094.613037	0.000000	NaN	NaN
268.000329	0.001454	14.539270	0.122035	1095.080322	0.000000	NaN	NaN
269.000386	0.001363	13.631460	0.122509	1095.542969	0.000000	NaN	NaN
270.000443	0.001421	14.209157	0.123168	1096.186157	0.000000	NaN	NaN
271.000500	0.001396	13.961573	0.123590	1096.598389	0.000000	NaN	NaN
271.999557	0.001305	13.053763	0.123983	1096.981812	0.000000	NaN	NaN
272.999615	0.001454	14.539270	0.124609	1097.593140	0.000000	NaN	NaN
273.999672	0.001404	14.044101	0.125075	1098.047119	0.000000	NaN	NaN
274.999729	0.001454	14.539270	0.125662	1098.620361	0.000000	NaN	NaN
275.999786	0.001503	15.034438	0.126222	1099.166626	0.000000	NaN	NaN
276.999843	0.001388	13.879045	0.126711	1099.644165	0.000000	NaN	NaN
277.999901	0.001512	15.116967	0.127220	1100.141113	0.000000	NaN	NaN
278.999958	0.001347	13.466404	0.127697	1100.606201	0.000000	NaN	NaN
280.000015	0.001355	13.548932	0.128281	1101.176514	0.000000	NaN	NaN
281.000072	0.001495	14.951910	0.128668	1101.554565	0.000000	NaN	NaN
282.000130	0.001396	13.961573	0.129233	1102.105713	0.000000	NaN	NaN
283.000187	0.001586	15.859720	0.129684	1102.545410	0.000000	NaN	NaN
284.000244	0.001512	15.116967	0.130135	1102.985596	0.000000	NaN	NaN
285.000301	0.001454	14.539270	0.130644	1103.482910	0.000000	NaN	NaN
286.000358	0.001446	14.456742	0.131148	1103.974487	0.000000	NaN	NaN
287.000415	0.001371	13.713988	0.131610	1104.425781	0.000000	NaN	NaN
288.000473	0.001421	14.209157	0.132216	1105.016968	0.000000	NaN	NaN
289.000530	0.001446	14.456742	0.132708	1105.496948	0.000000	NaN	NaN
289.999587	0.001454	14.539270	0.133160	1105.938477	0.000000	NaN	NaN
290.999644	0.001602	16.024776	0.133682	1106.447266	0.000000	NaN	NaN
291.999701	0.001421	14.209157	0.134169	1106.922974	0.000000	NaN	NaN
292.999759	0.001495	14.951910	0.134712	1107.453369	0.000000	NaN	NaN
293.999816	0.001479	14.786854	0.135168	1107.897827	0.000000	NaN	NaN
294.999873	0.001454	14.539270	0.135726	1108.442627	0.000000	NaN	NaN
295.999930	0.001462	14.621798	0.136198	1108.903198	0.000000	NaN	NaN
296.999987	0.001512	15.116967	0.136789	1109.479980	0.000000	NaN	NaN
298.000045	0.001446	14.456742	0.137255	1109.935059	0.000000	NaN	NaN
299.000102	0.001388	13.879045	0.137657	1110.327637	0.000000	NaN	NaN
300.000159	0.001380	13.796517	0.138157	1110.815674	0.000000	NaN	NaN
301.000216	0.001404	14.044101	0.138619	1111.266235	0.000000	NaN	NaN
302.000273	0.001338	13.383876	0.139192	1111.825806	0.000000	NaN	NaN
303.000331	0.001413	14.126629	0.139666	1112.287720	0.000000	NaN	NaN
304.000388	0.001396	13.961573	0.140191	1112.799927	0.000000	NaN	NaN
305.000445	0.001553	15.529607	0.140577	1113.176636	0.000000	NaN	NaN
306.000502	0.001512	15.116967	0.141257	1113.840576	0.000000	NaN	NaN
306.999559	0.001487	14.869382	0.141726	1114.298096	0.000000	NaN	NaN
307.999617	0.001470	14.704326	0.142132	1114.694580	0.000000	NaN	NaN
308.999674	0.001627	16.272360	0.142581	1115.132446	0.000000	NaN	NaN
309.999731	0.001569	15.694663	0.143073	1115.612915	0.000000	NaN	NaN
310.999788	0.001454	14.539270	0.143521	1116.050171	0.000000	NaN	NaN
311.999845	0.001404	14.044101	0.144165	1116.678711	0.000000	NaN	NaN
312.999903	0.001446	14.456742	0.144534	1117.039185	0.000000	NaN	NaN
313.999960	0.001380	13.796517	0.145032	1117.525391	0.000000	NaN	NaN
315.000017	0.001437	14.374213	0.145526	1118.007080	0.000000	NaN	NaN
316.000074	0.001437	14.374213	0.146106	1118.572754	0.000000	NaN	NaN
317.000131	0.001487	14.869382	0.146625	1119.080200	0.000000	NaN	NaN
318.000189	0.001528	15.282023	0.147138	1119.580322	0.000000	NaN	NaN
319.000246	0.001569	15.694663	0.147676	1120.104980	0.000000	NaN	NaN
320.000303	0.001644	16.437417	0.148087	1120.506592	0.000000	NaN	NaN
321.000360	0.001503	15.034438	0.148703	1121.107666	0.000000	NaN	NaN
322.000417	0.001528	15.282023	0.149197	1121.589844	0.000000	NaN	NaN
323.000475	0.001462	14.621798	0.149655	1122.037109	0.000000	NaN	NaN
324.000532	0.001470	14.704326	0.150203	1122.571411	0.000000	NaN	NaN
324.999589	0.001503	15.034438	0.150697	1123.054443	0.000000	NaN	NaN
325.999646	0.001512	15.116967	0.151273	1123.616211	0.000000	NaN	NaN
326.999703	0.001421	14.209157	0.151785	1124.115723	0.000000	NaN	NaN
327.999760	0.001619	16.189832	0.152232	1124.551880	0.000000	NaN	NaN
328.999818	0.001569	15.694663	0.152608	1124.918945	0.000000	NaN	NaN
329.999875	0.001512	15.116967	0.153276	1125.571045	0.000000	NaN	NaN
330.999932	0.001437	14.374213	0.153770	1126.053101	0.000000	NaN	NaN
331.999989	0.001380	13.796517	0.154227	1126.499023	0.000000	NaN	NaN
333.000046	0.001470	14.704326	0.154698	1126.958740	0.000000	NaN	NaN
334.000104	0.001545	15.447079	0.155244	1127.492065	0.000000	NaN	NaN
335.000161	0.001512	15.116967	0.155749	1127.984497	0.000000	NaN	NaN
336.000218	0.001627	16.272360	0.156279	1128.502319	0.000000	NaN	NaN
337.000275	0.001479	14.786854	0.156790	1129.000366	0.000000	NaN	NaN
338.000333	0.001380	13.796517	0.157292	1129.490723	0.000000	NaN	NaN
339.000390	0.001421	14.209157	0.157697	1129.885742	0.000000	NaN	NaN
340.000447	0.001462	14.621798	0.158250	1130.425171	0.000000	NaN	NaN
341.000504	0.001512	15.116967	0.158731	1130.894897	0.000000	NaN	NaN
341.999561	0.001462	14.621798	0.159265	1131.416016	0.000000	NaN	NaN
342.999618	0.001553	15.529607	0.159835	1131.972168	0.000000	NaN	NaN
343.999676	0.001437	14.374213	0.160420	1132.543823	0.000000	NaN	NaN
344.999733	0.001569	15.694663	0.160843	1132.956421	0.000000	NaN	NaN
345.999790	0.001437	14.374213	0.161245	1133.348267	0.000000	NaN	NaN
346.999847	0.001495	14.951910	0.161767	1133.858032	0.000000	NaN	NaN
347.999905	0.001462	14.621798	0.162325	1134.402100	0.000000	NaN	NaN
348.999962	0.001553	15.529607	0.162731	1134.798950	0.000000	NaN	NaN
350.000019	0.001536	15.364551	0.163314	1135.368042	0.000000	NaN	NaN
351.000076	0.001536	15.364551	0.163314	1135.368042	0.000000	NaN	NaN
352.000133	0.001512	15.116967	0.164267	1136.297485	0.000000	NaN	NaN
353.000190	0.001528	15.282023	0.164795	1136.813110	0.000000	NaN	NaN
354.000248	0.001479	14.786854	0.165216	1137.224121	0.000000	NaN	NaN
355.000305	0.001536	15.364551	0.165747	1137.742554	0.000000	NaN	NaN
356.000362	0.001553	15.529607	0.166198	1138.182251	0.000000	NaN	NaN
357.000419	0.001586	15.859720	0.166722	1138.694092	0.000000	NaN	NaN
358.000476	0.001545	15.447079	0.167210	1139.170410	0.000000	NaN	NaN
359.000534	0.001429	14.291685	0.167704	1139.652222	0.000000	NaN	NaN
359.999591	0.001602	16.024776	0.168124	1140.062378	0.000000	NaN	NaN
360.999648	0.001520	15.199495	0.168695	1140.619629	0.000000	NaN	NaN
361.999705	0.001536	15.364551	0.169208	1141.120239	0.000000	NaN	NaN
362.999762	0.001487	14.869382	0.169707	1141.606934	0.000000	NaN	NaN
363.999820	0.001512	15.116967	0.170159	1142.048706	0.000000	NaN	NaN
364.999877	0.001545	15.447079	0.170674	1142.551025	0.000000	NaN	NaN
365.999934	0.001495	14.951910	0.171138	1143.003784	0.000000	NaN	NaN
366.999991	0.001470	14.704326	0.171708	1143.560059	0.000000	NaN	NaN
368.000048	0.001495	14.951910	0.172208	1144.048340	0.000000	NaN	NaN
369.000106	0.001479	14.786854	0.172669	1144.498169	0.000000	NaN	NaN
370.000163	0.001371	13.713988	0.173145	1144.963013	0.000000	NaN	NaN
371.000220	0.001413	14.126629	0.173635	1145.440552	0.000000	NaN	NaN
372.000277	0.001495	14.951910	0.174135	1145.928955	0.000000	NaN	NaN
373.000334	0.001495	14.951910	0.174701	1146.481079	0.000000	NaN	NaN
374.000392	0.001503	15.034438	0.175188	1146.957031	0.000000	NaN	NaN
375.000449	0.001520	15.199495	0.175656	1147.413574	0.000000	NaN	NaN
376.000506	0.001479	14.786854	0.176154	1147.899048	0.000000	NaN	NaN
376.999563	0.001545	15.447079	0.176651	1148.384644	0.000000	NaN	NaN
377.999620	0.001561	15.612135	0.177149	1148.870117	0.000000	NaN	NaN
378.999678	0.001520	15.199495	0.177671	1149.379883	0.000000	NaN	NaN
379.999735	0.001446	14.456742	0.178183	1149.879272	0.000000	NaN	NaN
380.999792	0.001404	14.044101	0.178647	1150.332886	0.000000	NaN	NaN
381.999849	0.001545	15.447079	0.179157	1150.830200	0.000000	NaN	NaN
382.999906	0.001503	15.034438	0.179551	1151.214966	0.000000	NaN	NaN
383.999964	0.001528	15.282023	0.180109	1151.759399	0.000000	NaN	NaN
385.000021	0.001545	15.447079	0.180553	1152.192383	0.000000	NaN	NaN
386.000078	0.001644	16.437417	0.181092	1152.718506	0.000000	NaN	NaN
387.000135	0.001545	15.447079	0.181565	1153.180786	0.000000	NaN	NaN
388.000192	0.001611	16.107304	0.182123	1153.724731	0.000000	NaN	NaN
389.000250	0.001388	13.879045	0.182472	1154.065674	0.000000	NaN	NaN
390.000307	0.001330	13.301348	0.183071	1154.650024	0.000000	NaN	NaN
391.000364	0.001586	15.859720	0.183589	1155.156128	0.000000	NaN	NaN
392.000421	0.001602	16.024776	0.184030	1155.586548	0.000000	NaN	NaN
393.000478	0.001536	15.364551	0.184469	1156.015015	0.000000	NaN	NaN
394.000536	0.001429	14.291685	0.184986	1156.519287	0.000000	NaN	NaN
394.999593	0.001512	15.116967	0.185494	1157.015259	0.000000	NaN	NaN
395.999650	0.001487	14.869382	0.186061	1157.568237	0.000000	NaN	NaN
396.999707	0.001619	16.189832	0.186519	1158.015259	0.000000	NaN	NaN
397.999764	0.001454	14.539270	0.186957	1158.443359	0.000000	NaN	NaN
398.999821	0.001437	14.374213	0.187428	1158.902344	0.000000	NaN	NaN
399.999879	0.001503	15.034438	0.188062	1159.521362	0.000000	NaN	NaN
400.999936	0.001495	14.951910	0.188445	1159.895386	0.000000	NaN	NaN
401.999993	0.001569	15.694663	0.188921	1160.359375	0.000000	NaN	NaN
403.000050	0.001503	15.034438	0.189391	1160.818848	0.000000	NaN	NaN
404.000108	0.001528	15.282023	0.189973	1161.386108	0.000000	NaN	NaN
405.000165	0.001644	16.437417	0.190360	1161.763916	0.000000	NaN	NaN
406.000222	0.001528	15.282023	0.190838	1162.230957	0.000000	NaN	NaN
407.000279	0.001652	16.519945	0.191380	1162.759766	0.000000	NaN	NaN
408.000336	0.001437	14.374213	0.191826	1163.194702	0.000000	NaN	NaN
409.000393	0.001470	14.704326	0.192440	1163.794434	0.000000	NaN	NaN
410.000451	0.001503	15.034438	0.192864	1164.208374	0.000000	NaN	NaN
411.000508	0.001594	15.942248	0.193365	1164.697388	0.000000	NaN	NaN
411.999565	0.001561	15.612135	0.193900	1165.219116	0.000000	NaN	NaN
412.999622	0.001569	15.694663	0.194398	1165.705444	0.000000	NaN	NaN
413.999679	0.001545	15.447079	0.194926	1166.220215	0.000000	NaN	NaN
414.999737	0.001520	15.199495	0.195394	1166.677124	0.000000	NaN	NaN
415.999794	0.001470	14.704326	0.195862	1167.134155	0.000000	NaN	NaN
416.999851	0.001545	15.447079	0.196390	1167.649536	0.000000	NaN	NaN
417.999908	0.001462	14.621798	0.196936	1168.182373	0.000000	NaN	NaN
418.999965	0.001512	15.116967	0.197408	1168.642700	0.000000	NaN	NaN
420.000023	0.001446	14.456742	0.197783	1169.009155	0.000000	NaN	NaN
421.000080	0.001446	14.456742	0.198293	1169.506836	0.000000	NaN	NaN
422.000137	0.001669	16.685001	0.198837	1170.037354	0.000000	NaN	NaN
423.000194	0.001644	16.437417	0.199303	1170.492065	0.000000	NaN	NaN
424.000251	0.001553	15.529607	0.199779	1170.956909	0.000000	NaN	NaN
425.000309	0.001487	14.869382	0.200320	1171.484863	0.000000	NaN	NaN
426.000366	0.001594	15.942248	0.200727	1171.881836	0.000000	NaN	NaN
427.000423	0.001561	15.612135	0.201331	1172.471191	0.000000	NaN	NaN
428.000480	0.001528	15.282023	0.201747	1172.877563	0.000000	NaN	NaN
429.000537	0.001479	14.786854	0.202216	1173.335449	0.000000	NaN	NaN
429.999595	0.001545	15.447079	0.202683	1173.791016	0.000000	NaN	NaN
430.999652	0.001520	15.199495	0.203145	1174.241943	0.000000	NaN	NaN
431.999709	0.001487	14.869382	0.203617	1174.702515	0.000000	NaN	NaN
432.999766	0.001528	15.282023	0.204089	1175.163452	0.000000	NaN	NaN
433.999823	0.001586	15.859720	0.204544	1175.607544	0.000000	NaN	NaN
434.999881	0.001545	15.447079	0.205122	1176.171387	0.000000	NaN	NaN
435.999938	0.001569	15.694663	0.205461	1176.502686	0.000000	NaN	NaN
436.999995	0.001602	16.024776	0.205962	1176.991333	0.000000	NaN	NaN
438.000052	0.001569	15.694663	0.206346	1177.366089	0.000000	NaN	NaN
439.000109	0.001545	15.447079	0.206874	1177.881714	0.000000	NaN	NaN
440.000167	0.001561	15.612135	0.207344	1178.339966	0.000000	NaN	NaN
441.000224	0.001528	15.282023	0.207779	1178.764648	0.000000	NaN	NaN
442.000281	0.001677	16.767529	0.208399	1179.369873	0.000000	NaN	NaN
443.000338	0.001578	15.777192	0.208783	1179.744629	0.000000	NaN	NaN
444.000395	0.001528	15.282023	0.209329	1180.277832	0.000000	NaN	NaN
445.000453	0.001512	15.116967	0.209751	1180.689331	0.000000	NaN	NaN
446.000510	0.001454	14.539270	0.210335	1181.259277	0.000000	NaN	NaN
446.999567	0.001602	16.024776	0.210685	1181.601318	0.000000	NaN	NaN
447.999624	0.001545	15.447079	0.211257	1182.158691	0.000000	NaN	NaN
448.999681	0.001726	17.262698	0.211710	1182.601440	0.000000	NaN	NaN
449.999738	0.001520	15.199495	0.212194	1183.073730	0.000000	NaN	NaN
450.999796	0.001602	16.024776	0.212747	1183.613770	0.000000	NaN	NaN
451.999853	0.001495	14.951910	0.213192	1184.047241	0.000000	NaN	NaN
452.999910	0.001586	15.859720	0.213664	1184.508301	0.000000	NaN	NaN
453.999967	0.001594	15.942248	0.214039	1184.874756	0.000000	NaN	NaN
455.000024	0.001569	15.694663	0.214573	1185.395630	0.000000	NaN	NaN
456.000082	0.001297	12.971235	0.215037	1185.848511	0.000000	NaN	NaN
457.000139	0.001487	14.869382	0.215465	1186.265869	0.000000	NaN	NaN
458.000196	0.001528	15.282023	0.216010	1186.798340	0.000000	NaN	NaN
459.000253	0.001693	16.932585	0.216415	1187.193481	0.000000	NaN	NaN
460.000311	0.001503	15.034438	0.216976	1187.740845	0.000000	NaN	NaN
461.000368	0.001470	14.704326	0.217455	1188.208618	0.000000	NaN	NaN
462.000425	0.001545	15.447079	0.218020	1188.759766	0.000000	NaN	NaN
463.000482	0.001528	15.282023	0.217710	1188.456909	0.000000	NaN	NaN
464.000539	0.001602	16.024776	0.218003	1188.743042	0.000000	NaN	NaN
464.999596	0.001553	15.529607	0.218490	1189.218140	0.000000	NaN	NaN
465.999654	0.001561	15.612135	0.218995	1189.711548	0.000000	NaN	NaN
466.999711	0.001528	15.282023	0.220513	1191.192871	0.000000	NaN	NaN
467.999768	0.001635	16.354889	0.220949	1191.618408	0.000000	NaN	NaN
468.999825	0.001611	16.107304	0.221466	1192.122437	0.000000	NaN	NaN
469.999883	0.001652	16.519945	0.221880	1192.526733	0.000000	NaN	NaN
470.999940	0.001602	16.024776	0.221957	1192.601807	0.000000	NaN	NaN
471.999997	0.001553	15.529607	0.222440	1193.073730	0.000000	NaN	NaN
473.000054	0.001627	16.272360	0.222854	1193.477905	0.000000	NaN	NaN
474.000111	0.001553	15.529607	0.223377	1193.987427	0.000000	NaN	NaN
475.000168	0.001578	15.777192	0.223814	1194.414307	0.000000	NaN	NaN
476.000226	0.001586	15.859720	0.224300	1194.888306	0.000000	NaN	NaN
477.000283	0.001487	14.869382	0.224832	1195.407837	0.000000	NaN	NaN
478.000340	0.001528	15.282023	0.225185	1195.752441	0.000000	NaN	NaN
479.000397	0.001553	15.529607	0.225632	1196.189087	0.000000	NaN	NaN
480.000454	0.001594	15.942248	0.226135	1196.680054	0.000000	NaN	NaN
481.000512	0.001479	14.786854	0.226517	1197.052979	0.000000	NaN	NaN
481.999569	0.001718	17.180170	0.227059	1197.581909	0.000000	NaN	NaN
482.999626	0.001479	14.786854	0.227577	1198.087036	0.000000	NaN	NaN
483.999683	0.001536	15.364551	0.227990	1198.490112	0.000000	NaN	NaN
484.999740	0.001512	15.116967	0.228428	1198.918091	0.000000	NaN	NaN
485.999798	0.001520	15.199495	0.228856	1199.335327	0.000000	NaN	NaN
486.999855	0.001553	15.529607	0.229352	1199.819458	0.000000	NaN	NaN
487.999912	0.001487	14.869382	0.229859	1200.313843	0.000000	NaN	NaN
488.999969	0.001512	15.116967	0.230336	1200.779663	0.000000	NaN	NaN
490.000026	0.001569	15.694663	0.230716	1201.150391	0.000000	NaN	NaN
491.000084	0.001611	16.107304	0.231153	1201.576782	0.000000	NaN	NaN
492.000141	0.001627	16.272360	0.231549	1201.963501	0.000000	NaN	NaN
493.000198	0.001611	16.107304	0.232143	1202.543335	0.000000	NaN	NaN
494.000255	0.001602	16.024776	0.232562	1202.952271	0.000000	NaN	NaN
495.000312	0.001735	17.345226	0.233018	1203.397583	0.000000	NaN	NaN
496.000370	0.001652	16.519945	0.233435	1203.803955	0.000000	NaN	NaN
497.000427	0.001454	14.539270	0.233945	1204.302368	0.000000	NaN	NaN
498.000484	0.001693	16.932585	0.234423	1204.768799	0.000000	NaN	NaN
499.000541	0.001437	14.374213	0.234816	1205.151978	0.000000	NaN	NaN
499.999598	0.001536	15.364551	0.235266	1205.591064	0.000000	NaN	NaN
500.999656	0.001611	16.107304	0.235721	1206.035522	0.000000	NaN	NaN
501.999713	0.001644	16.437417	0.236239	1206.540527	0.000000	NaN	NaN
502.999770	0.001520	15.199495	0.236680	1206.971802	0.000000	NaN	NaN
503.999827	0.001487	14.869382	0.237128	1207.408691	0.000000	NaN	NaN
504.999884	0.001437	14.374213	0.237529	1207.799561	0.000000	NaN	NaN
505.999942	0.001611	16.107304	0.237983	1208.243042	0.000000	NaN	NaN
506.999999	0.001685	16.850057	0.238573	1208.819336	0.000000	NaN	NaN
508.000056	0.001528	15.282023	0.239003	1209.238159	0.000000	NaN	NaN
509.000113	0.001644	16.437417	0.239450	1209.675293	0.000000	NaN	NaN
510.000170	0.001578	15.777192	0.239897	1210.111206	0.000000	NaN	NaN
511.000228	0.001578	15.777192	0.240411	1210.613037	0.000000	NaN	NaN
512.000285	0.001602	16.024776	0.240783	1210.976074	0.000000	NaN	NaN
513.000342	0.001594	15.942248	0.241182	1211.364868	0.000000	NaN	NaN
514.000399	0.001561	15.612135	0.241771	1211.939819	0.000000	NaN	NaN
515.000456	0.001578	15.777192	0.242187	1212.346313	0.000000	NaN	NaN
516.000514	0.001545	15.447079	0.242650	1212.797974	0.000000	NaN	NaN
516.999571	0.001594	15.942248	0.243172	1213.307251	0.000000	NaN	NaN
517.999628	0.001520	15.199495	0.243580	1213.705811	0.000000	NaN	NaN
518.999685	0.001553	15.529607	0.244020	1214.135132	0.000000	NaN	NaN
519.999742	0.001652	16.519945	0.244608	1214.709229	0.000000	NaN	NaN
520.999799	0.001627	16.272360	0.244969	1215.061279	0.000000	NaN	NaN
521.999857	0.001602	16.024776	0.245525	1215.603516	0.000000	NaN	NaN
522.999914	0.001561	15.612135	0.245967	1216.035522	0.000000	NaN	NaN
523.999971	0.001594	15.942248	0.246392	1216.449585	0.000000	NaN	NaN
525.000028	0.001685	16.850057	0.246980	1217.024414	0.000000	NaN	NaN
526.000085	0.001619	16.189832	0.247315	1217.351196	0.000000	NaN	NaN
527.000143	0.001578	15.777192	0.247831	1217.854370	0.000000	NaN	NaN
528.000200	0.001644	16.437417	0.248182	1218.196777	0.000000	NaN	NaN
529.000257	0.001644	16.437417	0.248704	1218.706421	0.000000	NaN	NaN
530.000314	0.001784	17.840395	0.249204	1219.194092	0.000000	NaN	NaN
531.000372	0.001611	16.107304	0.249592	1219.572876	0.000000	NaN	NaN
532.000429	0.001545	15.447079	0.250194	1220.160278	0.000000	NaN	NaN
533.000486	0.001635	16.354889	0.250630	1220.586548	0.000000	NaN	NaN
534.000543	0.001611	16.107304	0.251079	1221.024292	0.000000	NaN	NaN
534.999600	0.001586	15.859720	0.251437	1221.373901	0.000000	NaN	NaN
535.999657	0.001652	16.519945	0.251676	1221.606934	0.000000	NaN	NaN
536.999715	0.001479	14.786854	0.252194	1222.112549	0.000000	NaN	NaN
537.999772	0.001652	16.519945	0.252650	1222.557495	0.000000	NaN	NaN
538.999829	0.001586	15.859720	0.253077	1222.974731	0.000000	NaN	NaN
539.999886	0.001561	15.612135	0.253816	1223.695435	0.000000	NaN	NaN
540.999943	0.001644	16.437417	0.254111	1223.983643	0.000000	NaN	NaN
542.000001	0.001677	16.767529	0.254593	1224.453857	0.000000	NaN	NaN
543.000058	0.001437	14.374213	0.255087	1224.936035	0.000000	NaN	NaN
544.000115	0.001602	16.024776	0.255543	1225.380859	0.000000	NaN	NaN
545.000172	0.001487	14.869382	0.255982	1225.809570	0.000000	NaN	NaN
546.000229	0.001528	15.282023	0.255563	1225.400513	0.000000	NaN	NaN
547.000287	0.001685	16.850057	0.256101	1225.925537	0.000000	NaN	NaN
548.000344	0.001569	15.694663	0.256515	1226.330078	0.000000	NaN	NaN
549.000401	0.001602	16.024776	0.256952	1226.756104	0.000000	NaN	NaN
550.000458	0.001842	18.418092	0.257411	1227.204468	0.000000	NaN	NaN
551.000515	0.001611	16.107304	0.257815	1227.598999	0.000000	NaN	NaN
551.999573	0.001602	16.024776	0.258218	1227.991943	0.000000	NaN	NaN
552.999630	0.001594	15.942248	0.258720	1228.481445	0.000000	NaN	NaN
553.999687	0.001602	16.024776	0.259133	1228.885376	0.000000	NaN	NaN
554.999744	0.001553	15.529607	0.259552	1229.293579	0.000000	NaN	NaN
555.999801	0.001404	14.044101	0.260085	1229.814331	0.000000	NaN	NaN
556.999859	0.001520	15.199495	0.260008	1229.738647	0.000000	NaN	NaN
557.999916	0.001512	15.116967	0.260429	1230.150146	0.000000	NaN	NaN
558.999973	0.001669	16.685001	0.260864	1230.574097	0.000000	NaN	NaN
560.000030	0.001652	16.519945	0.262014	1231.697021	0.000000	NaN	NaN
561.000087	0.001586	15.859720	0.262330	1232.005493	0.000000	NaN	NaN
562.000145	0.001553	15.529607	0.262857	1232.519897	0.000000	NaN	NaN
563.000202	0.001660	16.602473	0.263295	1232.947388	0.000000	NaN	NaN
564.000259	0.001710	17.097642	0.263786	1233.426270	0.000000	NaN	NaN
565.000316	0.001578	15.777192	0.264303	1233.930786	0.000000	NaN	NaN
566.000373	0.001536	15.364551	0.264400	1234.025391	0.000000	NaN	NaN
567.000431	0.001561	15.612135	0.264621	1234.241211	0.000000	NaN	NaN
568.000488	0.001561	15.612135	0.265018	1234.628784	0.000000	NaN	NaN
569.000545	0.001702	17.015114	0.265794	1235.386108	0.000000	NaN	NaN
569.999602	0.001652	16.519945	0.266508	1236.083008	0.000000	NaN	NaN
570.999659	0.001627	16.272360	0.267037	1236.598999	0.000000	NaN	NaN
571.999716	0.001635	16.354889	0.267453	1237.005127	0.000000	NaN	NaN
572.999774	0.001759	17.592810	0.267846	1237.388794	0.000000	NaN	NaN
573.999831	0.001669	16.685001	0.268246	1237.778687	0.000000	NaN	NaN
574.999888	0.001619	16.189832	0.268743	1238.264038	0.000000	NaN	NaN
575.999945	0.001652	16.519945	0.269218	1238.728027	0.000000	NaN	NaN
577.000003	0.001536	15.364551	0.269350	1238.856079	0.000000	NaN	NaN
578.000060	0.001545	15.447079	0.269702	1239.200562	0.000000	NaN	NaN
579.000117	0.001545	15.447079	0.270075	1239.564087	0.000000	NaN	NaN
580.000174	0.001503	15.034438	0.270504	1239.982300	0.000000	NaN	NaN
581.000231	0.001462	14.621798	0.270990	1240.457275	0.000000	NaN	NaN
582.000289	0.001619	16.189832	0.271442	1240.898071	0.000000	NaN	NaN
583.000346	0.001611	16.107304	0.272299	1241.734863	0.000000	NaN	NaN
584.000403	0.001586	15.859720	0.272569	1241.998169	0.000000	NaN	NaN
585.000460	0.001553	15.529607	0.273227	1242.640747	0.000000	NaN	NaN
586.000517	0.001495	14.951910	0.273575	1242.980225	0.000000	NaN	NaN
586.999574	0.001817	18.170507	0.274095	1243.487427	0.000000	NaN	NaN
587.999632	0.001553	15.529607	0.274584	1243.964478	0.000000	NaN	NaN
588.999689	0.001602	16.024776	0.274969	1244.340576	0.000000	NaN	NaN
589.999746	0.001586	15.859720	0.274873	1244.246704	0.000000	NaN	NaN
590.999803	0.001528	15.282023	0.275332	1244.694824	0.000000	NaN	NaN
591.999860	0.001660	16.602473	0.275769	1245.121216	0.000000	NaN	NaN
592.999918	0.001627	16.272360	0.276270	1245.610352	0.000000	NaN	NaN
593.999975	0.001627	16.272360	0.276619	1245.951050	0.000000	NaN	NaN
595.000032	0.001569	15.694663	0.277076	1246.397095	0.000000	NaN	NaN
596.000089	0.001578	15.777192	0.277602	1246.910767	0.000000	NaN	NaN
597.000147	0.001586	15.859720	0.277963	1247.262695	0.000000	NaN	NaN
598.000204	0.001512	15.116967	0.278334	1247.624634	0.000000	NaN	NaN
599.000261	0.001743	17.427754	0.278907	1248.183716	0.000000	NaN	NaN
600.000318	0.001660	16.602473	0.279252	1248.520508	0.000000	NaN	NaN
601.000375	0.001462	14.621798	0.279701	1248.958496	0.000000	NaN	NaN
602.000432	0.001545	15.447079	0.280111	1249.359497	0.000000	NaN	NaN
603.000490	0.001693	16.932585	0.280553	1249.790771	0.000000	NaN	NaN
604.000547	0.001726	17.262698	0.281186	1250.407837	0.000000	NaN	NaN
604.999604	0.001594	15.942248	0.281516	1250.730225	0.000000	NaN	NaN
605.999661	0.001545	15.447079	0.281371	1250.588501	0.000000	NaN	NaN
606.999718	0.001611	16.107304	0.281680	1250.890259	0.000000	NaN	NaN
607.999776	0.001578	15.777192	0.282080	1251.280640	0.000000	NaN	NaN
608.999833	0.001561	15.612135	0.282397	1251.589722	0.000000	NaN	NaN
609.999890	0.001602	16.024776	0.283131	1252.306641	0.000000	NaN	NaN
610.999947	0.001677	16.767529	0.283278	1252.450073	0.000000	NaN	NaN
612.000004	0.001693	16.932585	0.284577	1253.718140	0.000000	NaN	NaN
613.000062	0.001660	16.602473	0.285027	1254.157227	0.000000	NaN	NaN
614.000119	0.001660	16.602473	0.285322	1254.444458	0.000000	NaN	NaN
615.000176	0.001726	17.262698	0.285773	1254.885010	0.000000	NaN	NaN
616.000233	0.001710	17.097642	0.286249	1255.349609	0.000000	NaN	NaN
617.000290	0.001635	16.354889	0.286693	1255.783081	0.000000	NaN	NaN
618.000348	0.001693	16.932585	0.287137	1256.216064	0.000000	NaN	NaN
619.000405	0.001578	15.777192	0.287483	1256.554321	0.000000	NaN	NaN
620.000462	0.001454	14.539270	0.287972	1257.030762	0.000000	NaN	NaN
621.000519	0.001553	15.529607	0.288340	1257.390747	0.000000	NaN	NaN
621.999576	0.001536	15.364551	0.288954	1257.989746	0.000000	NaN	NaN
622.999634	0.001693	16.932585	0.289192	1258.222290	0.000000	NaN	NaN
623.999691	0.001635	16.354889	0.289706	1258.723267	0.000000	NaN	NaN
624.999748	0.001586	15.859720	0.290083	1259.091675	0.000000	NaN	NaN
625.999805	0.001611	16.107304	0.290599	1259.594971	0.000000	NaN	NaN
626.999862	0.001611	16.107304	0.291103	1260.086914	0.000000	NaN	NaN
627.999920	0.001669	16.685001	0.291347	1260.325439	0.000000	NaN	NaN
628.999977	0.001586	15.859720	0.291907	1260.871460	0.000000	NaN	NaN
630.000034	0.001528	15.282023	0.292042	1261.003784	0.000000	NaN	NaN
631.000091	0.001578	15.777192	0.292071	1261.031982	0.000000	NaN	NaN
632.000148	0.001553	15.529607	0.292635	1261.581909	0.000000	NaN	NaN
633.000206	0.001512	15.116967	0.293300	1262.231445	0.000000	NaN	NaN
634.000263	0.001561	15.612135	0.293386	1262.314819	0.000000	NaN	NaN
635.000320	0.001602	16.024776	0.293790	1262.709473	0.000000	NaN	NaN
636.000377	0.001446	14.456742	0.294435	1263.339233	0.000000	NaN	NaN
637.000434	0.001627	16.272360	0.294792	1263.687134	0.000000	NaN	NaN
638.000492	0.001743	17.427754	0.294802	1263.697266	0.000000	NaN	NaN
639.000549	0.001627	16.272360	0.296323	1265.181396	0.000000	NaN	NaN
639.999606	0.001495	14.951910	0.296771	1265.619141	0.000000	NaN	NaN
640.999663	0.001594	15.942248	0.297345	1266.178711	0.000000	NaN	NaN
641.999720	0.001503	15.034438	0.297701	1266.526367	0.000000	NaN	NaN
642.999778	0.001404	14.044101	0.297553	1266.381836	0.000000	NaN	NaN
643.999835	0.001528	15.282023	0.297655	1266.481567	0.000000	NaN	NaN
644.999892	0.001602	16.024776	0.297925	1266.744995	0.000000	NaN	NaN
645.999949	0.001536	15.364551	0.298544	1267.349609	0.000000	NaN	NaN
647.000006	0.001602	16.024776	0.299329	1268.115479	0.000000	NaN	NaN
648.000064	0.001619	16.189832	0.300458	1269.217041	0.000000	NaN	NaN
649.000121	0.001693	16.932585	0.300772	1269.524170	0.000000	NaN	NaN
650.000178	0.001693	16.932585	0.301468	1270.202759	0.000000	NaN	NaN
651.000235	0.001594	15.942248	0.301930	1270.654175	0.000000	NaN	NaN
652.000292	0.001611	16.107304	0.302328	1271.042725	0.000000	NaN	NaN
653.000349	0.001586	15.859720	0.302923	1271.623047	0.000000	NaN	NaN
654.000407	0.001553	15.529607	0.303064	1271.760132	0.000000	NaN	NaN
655.000464	0.001602	16.024776	0.303208	1271.901123	0.000000	NaN	NaN
656.000521	0.001421	14.209157	0.303737	1272.417603	0.000000	NaN	NaN
656.999578	0.001611	16.107304	0.304130	1272.801270	0.000000	NaN	NaN
657.999635	0.001569	15.694663	0.304539	1273.200684	0.000000	NaN	NaN
658.999693	0.001462	14.621798	0.305026	1273.675537	0.000000	NaN	NaN
659.999750	0.001363	13.631460	0.305644	1274.279053	0.000000	NaN	NaN
660.999807	0.001635	16.354889	0.305988	1274.614746	0.000000	NaN	NaN
661.999864	0.001470	14.704326	0.306637	1275.247681	0.000000	NaN	NaN
662.999921	0.001545	15.447079	0.307072	1275.671997	0.000000	NaN	NaN
663.999979	0.001503	15.034438	0.307391	1275.983521	0.000000	NaN	NaN
665.000036	0.001619	16.189832	0.307876	1276.457153	0.000000	NaN	NaN
666.000093	0.001479	14.786854	0.308221	1276.793823	0.000000	NaN	NaN
667.000150	0.001503	15.034438	0.308752	1277.312134	0.000000	NaN	NaN
668.000207	0.001553	15.529607	0.309248	1277.795776	0.000000	NaN	NaN
669.000265	0.001528	15.282023	0.309779	1278.314575	0.000000	NaN	NaN
670.000322	0.001437	14.374213	0.310360	1278.881592	0.000000	NaN	NaN
671.000379	0.001602	16.024776	0.311139	1279.641479	0.000000	NaN	NaN
672.000436	0.001619	16.189832	0.312017	1280.498535	0.000000	NaN	NaN
673.000493	0.001462	14.621798	0.312569	1281.037109	0.000000	NaN	NaN
674.000551	0.001528	15.282023	0.313160	1281.613770	0.000000	NaN	NaN
674.999608	0.001520	15.199495	0.313741	1282.181030	0.000000	NaN	NaN
675.999665	0.001503	15.034438	0.314296	1282.722534	0.000000	NaN	NaN
676.999722	0.001545	15.447079	0.314912	1283.323975	0.000000	NaN	NaN
677.999779	0.001586	15.859720	0.315652	1284.045776	0.000000	NaN	NaN
678.999837	0.001495	14.951910	0.316127	1284.509644	0.000000	NaN	NaN
679.999894	0.001553	15.529607	0.316575	1284.947266	0.000000	NaN	NaN
680.999951	0.001553	15.529607	0.317368	1285.721436	0.000000	NaN	NaN
682.000008	0.001520	15.199495	0.318021	1286.358398	0.000000	NaN	NaN
683.000065	0.001413	14.126629	0.318471	1286.797485	0.000000	NaN	NaN
684.000123	0.001520	15.199495	0.318925	1287.240845	0.000000	NaN	NaN
685.000180	0.001446	14.456742	0.319592	1287.892090	0.000000	NaN	NaN
686.000237	0.001586	15.859720	0.319914	1288.205322	0.000000	NaN	NaN
687.000294	0.001528	15.282023	0.321211	1289.472046	0.000000	NaN	NaN
688.000351	0.001479	14.786854	0.321756	1290.003662	0.000000	NaN	NaN
689.000409	0.001413	14.126629	0.322646	1290.872437	0.000000	NaN	NaN
690.000466	0.001462	14.621798	0.323380	1291.588257	0.000000	NaN	NaN
691.000523	0.001528	15.282023	0.324122	1292.312378	0.000000	NaN	NaN
691.999580	0.001413	14.126629	0.324937	1293.107788	0.000000	NaN	NaN
692.999637	0.001355	13.548932	0.325775	1293.926025	0.000000	NaN	NaN
693.999695	0.001429	14.291685	0.326540	1294.672729	0.000000	NaN	NaN
694.999752	0.001363	13.631460	0.327350	1295.463623	0.000000	NaN	NaN
695.999809	0.001421	14.209157	0.327883	1295.983643	0.000000	NaN	NaN
696.999866	0.001536	15.364551	0.328819	1296.897339	0.000000	NaN	NaN
697.999923	0.001545	15.447079	0.329603	1297.661743	0.000000	NaN	NaN
698.999980	0.001281	12.806179	0.330523	1298.559937	0.000000	NaN	NaN
700.000038	0.001380	13.796517	0.331397	1299.413086	0.000000	NaN	NaN
701.000095	0.001248	12.476067	0.332309	1300.303467	0.000000	NaN	NaN
702.000152	0.001297	12.971235	0.333261	1301.232422	0.000000	NaN	NaN
703.000209	0.001355	13.548932	0.334254	1302.201416	0.000000	NaN	NaN
704.001267	0.001297	12.971235	0.335093	1303.020752	0.000000	NaN	NaN
705.000324	0.001355	13.548932	0.336066	1303.969604	0.000000	NaN	NaN
706.000381	0.001437	14.374213	0.337209	1305.085815	0.000000	NaN	NaN
707.000438	0.001512	15.116967	0.338670	1306.511719	0.000000	NaN	NaN
708.000495	0.001578	15.777192	0.341583	1309.354004	0.000000	NaN	NaN
709.000553	0.001404	14.044101	0.345420	1313.098633	0.000000	NaN	NaN
709.999610	0.001388	13.879045	0.350569	1318.124512	0.000000	NaN	NaN
710.999667	0.001116	11.155617	0.357806	1325.187500	0.000000	NaN	NaN
711.999724	0.000992	9.917695	0.365128	1332.334106	0.000000	NaN	NaN
712.999781	0.000752	7.524379	0.098037	1071.658813	0.000000	NaN	NaN
713.999839	0.000620	6.203929	0.100347	1073.913452	0.000000	NaN	NaN
714.999896	0.000249	2.490163	0.103278	1076.773804	0.000000	NaN	NaN
715.999953	0.000183	1.829938	-0.564988	424.561981	0.000000	NaN	NaN
717.000010	-3.983212E-5	-0.398321	-0.565618	423.946686	0.000000	NaN	NaN
718.000067	-2.332649E-5	-0.233265	-0.566012	423.562836	0.000000	NaN	NaN
719.000124	-0.000106	-1.058546	-0.565058	424.493927	0.000000	NaN	NaN
720.000182	-1.507368E-5	-0.150737	-0.565440	424.120392	0.000000	NaN	NaN
721.000239	-0.000164	-1.636243	-0.565815	423.754974	0.000000	NaN	NaN
722.000296	-0.000131	-1.306131	-0.566569	423.018555	0.000000	NaN	NaN
723.000353	-0.000172	-1.718771	-0.566476	423.109467	0.000000	NaN	NaN
724.000411	-3.157930E-5	-0.315793	-0.567010	422.588257	0.000000	NaN	NaN
725.000468	-0.000164	-1.636243	0.112984	1086.247070	0.000000	NaN	NaN
726.000525	-0.000271	-2.709109	0.112492	1085.767090	0.000000	NaN	NaN
726.999582	-0.000213	-2.131412	0.113486	1086.736450	0.000000	NaN	NaN
727.999639	-0.000287	-2.874165	0.113733	1086.978027	0.000000	NaN	NaN
728.999696	-0.000320	-3.204278	0.114449	1087.676758	0.000000	NaN	NaN
729.999754	-0.000296	-2.956693	0.112454	1085.729736	0.000000	NaN	NaN
730.999811	-0.000263	-2.626581	0.113321	1086.576050	0.000000	NaN	NaN
731.999868	-0.000197	-1.966356	0.114501	1087.727905	0.000000	NaN	NaN
732.999925	-0.000296	-2.956693	0.114306	1087.536743	0.000000	NaN	NaN