File: data/9k_1-1_3 (181102).lvm
LabVIEW Measurement
Writer_Version	2
Reader_Version	2
Separator	Tab
Decimal_Separator	.
Multi_Headings	No
X_Columns	One
Time_Pref	Absolute
Operator	user
Description	Load(N)/Stress(MPa)/Distance A(pixel)/Strain A/Distance B(pixel)/Strain B/Poisson's ratio
Date	2018/11/02
Time	13:39:46.3050932884216308594
***End_of_Header***

Notes	X 값은 오직 다음과 같을 때에만 유효함이 보장됩니다. Dev1/ai0
Channels	7
Samples	1	1	1	1	1	1	1
Date	2018/11/02	2018/11/02	2018/11/02	2018/11/02	2018/11/02	2018/11/02	2018/11/02
Time	13:59:35.8041287300347366582	13:59:35.8041287300347366582	13:59:35.8041286468505859375	13:59:35.8041286468505859375	13:59:35.8041286468505859375	13:59:35.8041286468505859375	13:59:35.8041286468505859375
Y_Unit_Label	Volts	Volts
X_Dimension	Time	Time	Time	Time	Time	Time	Time
X0	0.0000000000000000E+0	0.0000000000000000E+0	0.0000000000000000E+0	0.0000000000000000E+0	0.0000000000000000E+0	0.0000000000000000E+0	0.0000000000000000E+0
Delta_X	0.000000	0.000000	1.000000	1.000000	1.000000	1.000000	1.000000
***End_of_Header***
X_Value	Dev1/ai0	Dev1/ai0 1	Untitled	Untitled 1	Untitled 2	Untitled 3	Untitled 4	Comment
0.000000	-0.000131	-1.310072	1.358986E-5	957.959717	0.000000	NaN	NaN
1.000057	-0.000139	-1.392849	6.067753E-5	958.017822	0.000000	NaN	NaN
2.000114	-3.167459E-5	-0.316746	1.978874E-5	957.978638	0.000000	NaN	NaN
3.000172	-2.339687E-5	-0.233969	-2.306700E-5	957.937622	0.000000	NaN	NaN
4.000229	-7.306316E-5	-0.730632	0.000217	958.167969	0.000000	NaN	NaN
5.000286	-8.134088E-5	-0.813409	0.000500	958.438293	0.000000	NaN	NaN
6.000343	0.000101	1.007688	0.000721	958.650146	0.000000	NaN	NaN
7.000400	6.765799E-5	0.676580	0.001010	958.926941	0.000000	NaN	NaN
8.000458	-2.339687E-5	-0.233969	0.001270	959.176331	0.000000	NaN	NaN
9.000515	5.110256E-5	0.511026	0.001369	959.271362	0.000000	NaN	NaN
9.999572	0.000167	1.669906	0.001746	959.632202	0.000000	NaN	NaN
11.000629	0.000126	1.256020	0.001904	959.784119	0.000000	NaN	NaN
12.000686	9.713984E-6	0.097140	0.002188	960.056213	0.000000	NaN	NaN
13.000744	0.000142	1.421574	0.002504	960.358948	0.000000	NaN	NaN
14.000801	0.000250	2.497677	0.002765	960.608643	0.000000	NaN	NaN
15.000858	0.000241	2.414900	0.002991	960.824890	0.000000	NaN	NaN
16.000915	0.000233	2.332123	0.003273	961.094849	0.000000	NaN	NaN
17.000972	0.000142	1.421574	0.003649	961.455444	0.000000	NaN	NaN
18.001030	0.000184	1.835460	0.003854	961.651245	0.000000	NaN	NaN
19.001087	0.000159	1.587128	0.004120	961.906067	0.000000	NaN	NaN
20.000144	0.000184	1.835460	0.004383	962.158936	0.000000	NaN	NaN
21.000201	9.249113E-5	0.924911	0.004662	962.425293	0.000000	NaN	NaN
21.999258	0.000407	4.070443	0.004874	962.628479	0.000000	NaN	NaN
23.000316	0.000349	3.491003	0.005078	962.824158	0.000000	NaN	NaN
23.999373	0.000341	3.408226	0.005380	963.113281	0.000000	NaN	NaN
25.000430	0.000241	2.414900	0.005691	963.411255	0.000000	NaN	NaN
25.999487	0.000324	3.242671	0.005922	963.632874	0.000000	NaN	NaN
27.000544	0.000333	3.325449	0.006372	964.063538	0.000000	NaN	NaN
27.999602	0.000299	2.994340	0.006570	964.253052	0.000000	NaN	NaN
28.999659	0.000366	3.656557	0.006847	964.518677	0.000000	NaN	NaN
30.000716	0.000440	4.401551	0.007064	964.726257	0.000000	NaN	NaN
31.000773	0.000399	3.987666	0.007398	965.046387	0.000000	NaN	NaN
32.000830	0.000399	3.987666	0.007637	965.275330	0.000000	NaN	NaN
33.000888	0.000440	4.401551	0.008022	965.644287	0.000000	NaN	NaN
34.000945	0.000291	2.911563	0.008196	965.810852	0.000000	NaN	NaN
35.001002	0.000308	3.077117	0.008683	966.277771	0.000000	NaN	NaN
36.001059	0.000490	4.898214	0.008774	966.365051	0.000000	NaN	NaN
36.999116	0.000647	6.470980	0.009210	966.782043	0.000000	NaN	NaN
38.000174	0.000515	5.146546	0.009548	967.106262	0.000000	NaN	NaN
38.999231	0.000482	4.815437	0.009890	967.434387	0.000000	NaN	NaN
40.000288	0.000523	5.229323	0.010286	967.812927	0.000000	NaN	NaN
40.999345	0.000490	4.898214	0.010472	967.991394	0.000000	NaN	NaN
42.000402	0.000556	5.560431	0.010925	968.425781	0.000000	NaN	NaN
43.000459	0.000448	4.484329	0.011320	968.803955	0.000000	NaN	NaN
44.000517	0.000573	5.725986	0.011560	969.033447	0.000000	NaN	NaN
45.000574	0.000705	7.050420	0.011958	969.414734	0.000000	NaN	NaN
46.000631	0.000622	6.222649	0.012432	969.869324	0.000000	NaN	NaN
46.999688	0.000556	5.560431	0.012771	970.194153	0.000000	NaN	NaN
48.000746	0.000564	5.643209	0.013254	970.656250	0.000000	NaN	NaN
49.000803	0.000515	5.146546	0.013487	970.880188	0.000000	NaN	NaN
50.000860	0.000614	6.139871	0.013850	971.227295	0.000000	NaN	NaN
51.000917	0.000531	5.312100	0.014434	971.786560	0.000000	NaN	NaN
52.000974	0.000647	6.470980	0.014602	971.947754	0.000000	NaN	NaN
53.001031	0.000680	6.802089	0.015002	972.330994	0.000000	NaN	NaN
54.000089	0.000589	5.891540	0.015487	972.795776	0.000000	NaN	NaN
55.000146	0.000655	6.553757	0.015871	973.163086	0.000000	NaN	NaN
56.000203	0.000564	5.643209	0.016263	973.538940	0.000000	NaN	NaN
57.000260	0.000796	7.960969	0.016741	973.997192	0.000000	NaN	NaN
57.999317	0.000614	6.139871	0.017176	974.413391	0.000000	NaN	NaN
58.999375	0.000548	5.477654	0.017695	974.910706	0.000000	NaN	NaN
60.000432	0.000622	6.222649	0.018124	975.321533	0.000000	NaN	NaN
61.000489	0.000564	5.643209	0.018522	975.702881	0.000000	NaN	NaN
62.000546	0.000804	8.043746	0.018959	976.121277	0.000000	NaN	NaN
63.000603	0.000713	7.133197	0.019457	976.598511	0.000000	NaN	NaN
63.999661	0.000614	6.139871	0.019791	976.918640	0.000000	NaN	NaN
64.999718	0.000597	5.974317	0.020305	977.411133	0.000000	NaN	NaN
66.001775	0.000763	7.629860	0.020826	977.910339	0.000000	NaN	NaN
66.999832	0.000804	8.043746	0.021326	978.388916	0.000000	NaN	NaN
68.000889	0.000639	6.388203	0.021671	978.719788	0.000000	NaN	NaN
68.999947	0.000738	7.381529	0.022045	979.078186	0.000000	NaN	NaN
70.001004	0.000929	9.285403	0.022763	979.765320	0.000000	NaN	NaN
71.001061	0.000854	8.540409	0.023308	980.287781	0.000000	NaN	NaN
72.000118	0.000763	7.629860	0.023497	980.468628	0.000000	NaN	NaN
73.000175	0.000763	7.629860	0.024109	981.055420	0.000000	NaN	NaN
74.000233	0.000614	6.139871	0.024659	981.581726	0.000000	NaN	NaN
74.999290	0.000780	7.795414	0.025324	982.219543	0.000000	NaN	NaN
76.000347	0.000738	7.381529	0.025637	982.518982	0.000000	NaN	NaN
77.000404	0.000854	8.540409	0.026277	983.131592	0.000000	NaN	NaN
78.000461	0.000846	8.457631	0.026715	983.551208	0.000000	NaN	NaN
79.000519	0.000647	6.470980	0.027104	983.924072	0.000000	NaN	NaN
80.000576	0.000780	7.795414	-1.000000	0.000000	0.000000	NaN	NaN
81.000633	0.000887	8.871517	0.028725	985.477173	0.000000	NaN	NaN
82.000690	0.000746	7.464306	0.029089	985.826172	0.000000	NaN	NaN
82.999747	0.000738	7.381529	0.029674	986.385803	0.000000	NaN	NaN
84.000805	0.000755	7.547083	0.030303	986.988403	0.000000	NaN	NaN
85.000862	0.000829	8.292077	0.030718	987.386353	0.000000	NaN	NaN
86.000919	0.000887	8.871517	0.031224	987.871460	0.000000	NaN	NaN
87.000976	0.000755	7.547083	0.031768	988.392273	0.000000	NaN	NaN
88.000033	0.000846	8.457631	0.032215	988.820374	0.000000	NaN	NaN
88.999090	0.000862	8.623186	0.032996	989.568909	0.000000	NaN	NaN
90.000148	0.000788	7.878191	0.033402	989.957703	0.000000	NaN	NaN
90.999205	0.000780	7.795414	0.033945	990.478027	0.000000	NaN	NaN
92.000262	0.000821	8.209300	0.034362	990.877258	0.000000	NaN	NaN
93.000319	0.000929	9.285403	0.034890	991.382568	0.000000	NaN	NaN
94.000377	0.000804	8.043746	0.035440	991.909668	0.000000	NaN	NaN
95.000434	0.000738	7.381529	0.036005	992.450745	0.000000	NaN	NaN
95.999491	0.000970	9.699289	0.036452	992.879211	0.000000	NaN	NaN
96.999548	0.000854	8.540409	0.037037	993.439514	0.000000	NaN	NaN
98.000605	0.000780	7.795414	0.037574	993.953857	0.000000	NaN	NaN
99.000663	0.000804	8.043746	0.038150	994.505554	0.000000	NaN	NaN
100.000720	0.000804	8.043746	0.038473	994.815186	0.000000	NaN	NaN
100.999777	0.000821	8.209300	0.039153	995.466553	0.000000	NaN	NaN
101.999834	0.000755	7.547083	0.039633	995.926819	0.000000	NaN	NaN
103.000891	0.000895	8.954294	0.040286	996.552368	0.000000	NaN	NaN
104.000948	0.000920	9.202626	0.040720	996.968201	0.000000	NaN	NaN
105.000006	0.000771	7.712637	0.041265	997.490051	0.000000	NaN	NaN
106.001063	0.000688	6.884866	0.041821	998.022217	0.000000	NaN	NaN
107.000120	0.000804	8.043746	0.042246	998.429749	0.000000	NaN	NaN
107.999177	0.000804	8.043746	0.042875	999.032654	0.000000	NaN	NaN
109.000235	0.000879	8.788740	0.043530	999.659302	0.000000	NaN	NaN
110.000292	0.000920	9.202626	0.043930	1000.042725	0.000000	NaN	NaN
111.000349	0.000821	8.209300	0.044446	1000.536865	0.000000	NaN	NaN
112.000406	0.000804	8.043746	0.045055	1001.120605	0.000000	NaN	NaN
113.000463	0.000796	7.960969	0.045420	1001.470337	0.000000	NaN	NaN
114.000520	0.000804	8.043746	0.045884	1001.914246	0.000000	NaN	NaN
115.000578	0.000920	9.202626	0.046456	1002.462280	0.000000	NaN	NaN
116.000635	0.000755	7.547083	0.047050	1003.031738	0.000000	NaN	NaN
117.000692	0.000879	8.788740	0.047559	1003.519836	0.000000	NaN	NaN
118.000749	0.000738	7.381529	0.048115	1004.051514	0.000000	NaN	NaN
119.000806	0.001011	10.113174	0.048635	1004.549988	0.000000	NaN	NaN
120.000864	0.000879	8.788740	0.049285	1005.173096	0.000000	NaN	NaN
121.000921	0.000887	8.871517	0.049734	1005.602966	0.000000	NaN	NaN
122.000978	0.000746	7.464306	0.050290	1006.135132	0.000000	NaN	NaN
123.000035	0.000920	9.202626	0.050744	1006.570129	0.000000	NaN	NaN
124.000092	0.000862	8.623186	0.051396	1007.194702	0.000000	NaN	NaN
124.999150	0.000788	7.878191	0.051880	1007.658447	0.000000	NaN	NaN
126.000207	0.000780	7.795414	0.052542	1008.293091	0.000000	NaN	NaN
127.000264	0.000846	8.457631	0.052881	1008.617371	0.000000	NaN	NaN
128.000321	0.000895	8.954294	0.053572	1009.279419	0.000000	NaN	NaN
128.999378	0.000945	9.450957	0.054144	1009.827087	0.000000	NaN	NaN
130.000436	0.000763	7.629860	0.054574	1010.238953	0.000000	NaN	NaN
130.999493	0.001036	10.361506	0.055429	1011.058533	0.000000	NaN	NaN
131.999550	0.000821	8.209300	0.055902	1011.511230	0.000000	NaN	NaN
133.000607	0.000895	8.954294	0.056228	1011.823730	0.000000	NaN	NaN
133.999664	0.000871	8.705963	0.056724	1012.299255	0.000000	NaN	NaN
135.000722	0.000912	9.119849	0.057338	1012.887573	0.000000	NaN	NaN
136.000779	0.000854	8.540409	0.057911	1013.436096	0.000000	NaN	NaN
137.000836	0.000821	8.209300	0.058386	1013.891541	0.000000	NaN	NaN
138.000893	0.000796	7.960969	0.059037	1014.514954	0.000000	NaN	NaN
138.999950	0.000796	7.960969	0.059556	1015.011841	0.000000	NaN	NaN
140.001008	0.000804	8.043746	0.060013	1015.449890	0.000000	NaN	NaN
141.001065	0.000904	9.037071	1.166062	2074.999756	0.000000	NaN	NaN
142.000122	0.000904	9.037071	1.166750	2075.659180	0.000000	NaN	NaN
143.000179	0.000796	7.960969	0.060775	1016.180115	0.000000	NaN	NaN
144.000236	0.000846	8.457631	0.061399	1016.777283	0.000000	NaN	NaN
145.000294	0.000879	8.788740	0.062003	1017.356384	0.000000	NaN	NaN
146.000351	0.000821	8.209300	0.062500	1017.832031	0.000000	NaN	NaN
147.000408	0.000912	9.119849	0.063084	1018.391846	0.000000	NaN	NaN
148.000465	0.000813	8.126523	0.063553	1018.840942	0.000000	NaN	NaN
149.000522	0.000813	8.126523	0.064112	1019.376587	0.000000	NaN	NaN
150.000580	0.000986	9.864843	0.064654	1019.895386	0.000000	NaN	NaN
151.000637	0.000879	8.788740	0.065264	1020.479553	0.000000	NaN	NaN
152.000694	0.000929	9.285403	0.065739	1020.935242	0.000000	NaN	NaN
153.000751	0.000854	8.540409	0.066200	1021.376953	0.000000	NaN	NaN
154.000808	0.000788	7.878191	0.066841	1021.990295	0.000000	NaN	NaN
155.000866	0.000746	7.464306	0.067371	1022.498230	0.000000	NaN	NaN
156.000923	0.000904	9.037071	0.067876	1022.982056	0.000000	NaN	NaN
157.000980	0.000953	9.533734	0.068520	1023.599487	0.000000	NaN	NaN
158.001037	0.000796	7.960969	0.068973	1024.032837	0.000000	NaN	NaN
159.000094	0.000746	7.464306	0.069541	1024.576782	0.000000	NaN	NaN
160.000151	0.000804	8.043746	0.070199	1025.208008	0.000000	NaN	NaN
160.999209	0.000846	8.457631	0.070683	1025.671387	0.000000	NaN	NaN
162.000266	0.000813	8.126523	0.071275	1026.238403	0.000000	NaN	NaN
163.000323	0.000962	9.616511	0.071715	1026.660034	0.000000	NaN	NaN
164.000380	0.000804	8.043746	0.072338	1027.256348	0.000000	NaN	NaN
165.000438	0.000755	7.547083	0.072860	1027.756226	0.000000	NaN	NaN
166.000495	0.000887	8.871517	0.073288	1028.166504	0.000000	NaN	NaN
166.999552	0.000804	8.043746	0.073916	1028.768433	0.000000	NaN	NaN
168.000609	0.000929	9.285403	0.074492	1029.320312	0.000000	NaN	NaN
168.999666	0.000920	9.202626	0.075110	1029.911743	0.000000	NaN	NaN
170.000723	0.000879	8.788740	0.075559	1030.342285	0.000000	NaN	NaN
170.999781	0.000705	7.050420	0.076129	1030.888306	0.000000	NaN	NaN
172.000838	0.000813	8.126523	0.076598	1031.337280	0.000000	NaN	NaN
173.000895	0.000837	8.374854	0.077194	1031.908447	0.000000	NaN	NaN
174.000952	0.000796	7.960969	0.077788	1032.477173	0.000000	NaN	NaN
175.001010	0.000763	7.629860	0.078237	1032.907959	0.000000	NaN	NaN
176.001067	0.000846	8.457631	0.078770	1033.418213	0.000000	NaN	NaN
176.999124	0.000912	9.119849	0.079370	1033.993408	0.000000	NaN	NaN
178.000181	0.001003	10.030397	0.079931	1034.530151	0.000000	NaN	NaN
178.999238	0.000929	9.285403	0.080490	1035.065918	0.000000	NaN	NaN
180.000295	0.000829	8.292077	0.080878	1035.437378	0.000000	NaN	NaN
181.000353	0.000705	7.050420	0.081423	1035.959839	0.000000	NaN	NaN
182.000410	0.000837	8.374854	0.082030	1036.541016	0.000000	NaN	NaN
183.000467	0.000804	8.043746	0.082513	1037.003906	0.000000	NaN	NaN
184.000524	0.000804	8.043746	0.082879	1037.354492	0.000000	NaN	NaN
185.000582	0.000730	7.298751	0.083577	1038.023315	0.000000	NaN	NaN
186.000639	0.000879	8.788740	0.084066	1038.491943	0.000000	NaN	NaN
187.000696	0.000953	9.533734	0.084718	1039.115845	0.000000	NaN	NaN
188.000753	0.000995	9.947620	0.085140	1039.520264	0.000000	NaN	NaN
189.000810	0.000953	9.533734	0.085740	1040.095581	0.000000	NaN	NaN
190.000867	0.000763	7.629860	0.086258	1040.591797	0.000000	NaN	NaN
191.000925	0.000829	8.292077	0.086835	1041.144531	0.000000	NaN	NaN
192.000982	0.000862	8.623186	0.087230	1041.522949	0.000000	NaN	NaN
193.001039	0.000821	8.209300	0.087788	1042.057007	0.000000	NaN	NaN
193.999096	0.000763	7.629860	0.088371	1042.615356	0.000000	NaN	NaN
195.000153	0.000879	8.788740	0.088905	1043.127075	0.000000	NaN	NaN
195.999211	0.000771	7.712637	0.089423	1043.623047	0.000000	NaN	NaN
197.000268	0.000879	8.788740	0.089832	1044.015381	0.000000	NaN	NaN
197.999325	0.000804	8.043746	0.090476	1044.632202	0.000000	NaN	NaN
198.999382	0.000738	7.381529	0.091044	1045.176636	0.000000	NaN	NaN
199.999439	0.000821	8.209300	0.091494	1045.607422	0.000000	NaN	NaN
201.000497	0.000879	8.788740	0.092142	1046.228516	0.000000	NaN	NaN
201.999554	0.000722	7.215974	0.092633	1046.698242	0.000000	NaN	NaN
203.000611	0.001020	10.195951	0.093277	1047.315674	0.000000	NaN	NaN
204.000668	0.000895	8.954294	0.093678	1047.698975	0.000000	NaN	NaN
204.999725	0.000962	9.616511	0.094253	1048.250244	0.000000	NaN	NaN
206.000783	0.000846	8.457631	0.094864	1048.835449	0.000000	NaN	NaN
206.999840	0.000821	8.209300	0.095397	1049.346191	0.000000	NaN	NaN
208.000897	0.000862	8.623186	0.095924	1049.851318	0.000000	NaN	NaN
209.000954	0.000937	9.368180	0.096609	1050.506836	0.000000	NaN	NaN
210.001011	0.001003	10.030397	0.097139	1051.015137	0.000000	NaN	NaN
211.001069	0.000945	9.450957	0.097544	1051.402954	0.000000	NaN	NaN
212.000126	0.000879	8.788740	0.098107	1051.942017	0.000000	NaN	NaN
213.000183	0.001028	10.278729	0.098653	1052.465210	0.000000	NaN	NaN
214.000240	0.000829	8.292077	0.099078	1052.872803	0.000000	NaN	NaN
214.999297	0.000937	9.368180	0.099798	1053.562256	0.000000	NaN	NaN
216.000354	0.000904	9.037071	0.100203	1053.950317	0.000000	NaN	NaN
217.000412	0.000895	8.954294	0.100894	1054.612305	0.000000	NaN	NaN
218.000469	0.000887	8.871517	0.101558	1055.248047	0.000000	NaN	NaN
218.999526	0.000738	7.381529	0.101934	1055.608521	0.000000	NaN	NaN
220.000583	0.000929	9.285403	0.102489	1056.140015	0.000000	NaN	NaN
220.999640	0.000837	8.374854	0.103009	1056.638306	0.000000	NaN	NaN
222.000698	0.000871	8.705963	0.103546	1057.152588	0.000000	NaN	NaN
222.999755	0.000854	8.540409	0.104115	1057.697266	0.000000	NaN	NaN
224.000812	0.000871	8.705963	0.104775	1058.330322	0.000000	NaN	NaN
224.999869	0.000829	8.292077	0.105137	1058.676514	0.000000	NaN	NaN
225.999926	0.000904	9.037071	0.105801	1059.312378	0.000000	NaN	NaN
227.000984	0.000879	8.788740	0.106219	1059.713135	0.000000	NaN	NaN
228.001041	0.000945	9.450957	0.106763	1060.234619	0.000000	NaN	NaN
229.000098	0.000862	8.623186	0.107239	1060.690308	0.000000	NaN	NaN
230.000155	0.000804	8.043746	0.107855	1061.280640	0.000000	NaN	NaN
230.999212	0.000945	9.450957	0.108314	1061.719971	0.000000	NaN	NaN
232.000270	0.000837	8.374854	0.108915	1062.295654	0.000000	NaN	NaN
233.000327	0.000978	9.782066	0.109399	1062.759399	0.000000	NaN	NaN
234.000384	0.001020	10.195951	0.109930	1063.268433	0.000000	NaN	NaN
235.000441	0.000813	8.126523	0.110641	1063.949097	0.000000	NaN	NaN
236.000498	0.000862	8.623186	0.111096	1064.385132	0.000000	NaN	NaN
236.999556	0.000846	8.457631	0.111726	1064.988403	0.000000	NaN	NaN
238.000613	0.000755	7.547083	0.112267	1065.506958	0.000000	NaN	NaN
238.999670	0.000837	8.374854	0.112822	1066.038330	0.000000	NaN	NaN
239.999727	0.000837	8.374854	0.113386	1066.579224	0.000000	NaN	NaN
241.000785	0.000912	9.119849	0.113928	1067.098267	0.000000	NaN	NaN
241.999842	0.000821	8.209300	0.114445	1067.593262	0.000000	NaN	NaN
243.000899	0.000763	7.629860	0.115053	1068.175903	0.000000	NaN	NaN
243.999956	0.000804	8.043746	0.115501	1068.604614	0.000000	NaN	NaN
245.001013	0.000929	9.285403	0.116077	1069.157227	0.000000	NaN	NaN
246.001070	0.000978	9.782066	0.116795	1069.844604	0.000000	NaN	NaN
247.000128	0.000912	9.119849	0.117417	1070.440063	0.000000	NaN	NaN
248.000185	0.000929	9.285403	0.117865	1070.869263	0.000000	NaN	NaN
249.000242	0.001011	10.113174	0.118436	1071.416260	0.000000	NaN	NaN
249.999299	0.000978	9.782066	0.118944	1071.903198	0.000000	NaN	NaN
251.000356	0.000995	9.947620	0.119553	1072.486938	0.000000	NaN	NaN
252.000414	0.000970	9.699289	0.120201	1073.107666	0.000000	NaN	NaN
253.000471	0.000970	9.699289	0.120644	1073.531982	0.000000	NaN	NaN
254.000528	0.000995	9.947620	0.121138	1074.004761	0.000000	NaN	NaN
255.000585	0.000945	9.450957	0.121609	1074.456055	0.000000	NaN	NaN
256.000642	0.000813	8.126523	0.122390	1075.204834	0.000000	NaN	NaN
256.999700	0.000945	9.450957	0.122777	1075.574707	0.000000	NaN	NaN
258.000757	0.000978	9.782066	0.123384	1076.156128	0.000000	NaN	NaN
259.000814	0.000788	7.878191	0.124031	1076.776855	0.000000	NaN	NaN
260.000871	0.000829	8.292077	0.124518	1077.242676	0.000000	NaN	NaN
260.999928	0.000680	6.802089	0.125099	1077.799683	0.000000	NaN	NaN
262.000986	0.000746	7.464306	0.125704	1078.379517	0.000000	NaN	NaN
263.000043	0.000962	9.616511	0.126246	1078.898071	0.000000	NaN	NaN
264.000100	0.000879	8.788740	0.126826	1079.453857	0.000000	NaN	NaN
264.999157	0.000953	9.533734	0.127452	1080.053345	0.000000	NaN	NaN
266.000214	0.000887	8.871517	0.127820	1080.406494	0.000000	NaN	NaN
266.999272	0.000879	8.788740	0.128401	1080.962280	0.000000	NaN	NaN
268.000329	0.000937	9.368180	0.129073	1081.606689	0.000000	NaN	NaN
268.999386	0.000970	9.699289	0.129530	1082.044556	0.000000	NaN	NaN
269.999443	0.000953	9.533734	0.129910	1082.408081	0.000000	NaN	NaN
271.000500	0.000962	9.616511	0.130670	1083.135986	0.000000	NaN	NaN
271.999557	0.000755	7.547083	0.131051	1083.501099	0.000000	NaN	NaN
272.999615	0.000722	7.215974	0.131560	1083.989136	0.000000	NaN	NaN
273.999672	0.000895	8.954294	0.132462	1084.852783	0.000000	NaN	NaN
275.000729	0.000912	9.119849	0.132835	1085.209961	0.000000	NaN	NaN
275.999786	0.000895	8.954294	0.133277	1085.633789	0.000000	NaN	NaN
276.999843	0.000871	8.705963	0.133903	1086.232910	0.000000	NaN	NaN
277.999901	0.001036	10.361506	0.134404	1086.712891	0.000000	NaN	NaN
279.000958	0.000895	8.954294	0.135042	1087.324951	0.000000	NaN	NaN
280.000015	0.000912	9.119849	0.135636	1087.893921	0.000000	NaN	NaN
281.000072	0.000763	7.629860	0.136038	1088.278564	0.000000	NaN	NaN
282.000130	0.000945	9.450957	0.136580	1088.797729	0.000000	NaN	NaN
282.999187	0.000862	8.623186	0.137112	1089.307373	0.000000	NaN	NaN
283.999244	0.001053	10.527060	0.137698	1089.868652	0.000000	NaN	NaN
285.000301	0.000995	9.947620	0.138181	1090.331421	0.000000	NaN	NaN
285.999358	0.000920	9.202626	0.138811	1090.935303	0.000000	NaN	NaN
287.000415	0.000995	9.947620	0.139260	1091.365479	0.000000	NaN	NaN
287.999473	0.000978	9.782066	0.139956	1092.031616	0.000000	NaN	NaN
289.000530	0.000837	8.374854	0.140358	1092.417114	0.000000	NaN	NaN
289.999587	0.000887	8.871517	0.140939	1092.973755	0.000000	NaN	NaN
291.000644	0.000978	9.782066	0.141481	1093.492798	0.000000	NaN	NaN
291.999702	0.000962	9.616511	0.141928	1093.921021	0.000000	NaN	NaN
292.999759	0.000995	9.947620	0.142518	1094.486328	0.000000	NaN	NaN
294.000816	0.001044	10.444283	0.143253	1095.190063	0.000000	NaN	NaN
295.000873	0.000920	9.202626	0.143648	1095.568359	0.000000	NaN	NaN
296.000930	0.001003	10.030397	0.144127	1096.027344	0.000000	NaN	NaN
297.000988	0.001086	10.858169	0.144614	1096.494263	0.000000	NaN	NaN
298.001045	0.000978	9.782066	0.145176	1097.032227	0.000000	NaN	NaN
299.000102	0.000887	8.871517	0.145681	1097.516235	0.000000	NaN	NaN
299.999159	0.000837	8.374854	0.146315	1098.123779	0.000000	NaN	NaN
300.999216	0.000904	9.037071	0.146765	1098.555054	0.000000	NaN	NaN
301.999273	0.000846	8.457631	0.147281	1099.048706	0.000000	NaN	NaN
302.999331	0.000887	8.871517	0.147860	1099.603394	0.000000	NaN	NaN
303.999388	0.000995	9.947620	0.148322	1100.046387	0.000000	NaN	NaN
305.000445	0.000920	9.202626	0.148986	1100.682007	0.000000	NaN	NaN
306.000502	0.000854	8.540409	0.149421	1101.099243	0.000000	NaN	NaN
306.999559	0.000937	9.368180	0.149876	1101.534790	0.000000	NaN	NaN
308.000617	0.000995	9.947620	0.150454	1102.088257	0.000000	NaN	NaN
308.999674	0.000887	8.871517	0.150972	1102.584839	0.000000	NaN	NaN
309.999731	0.000837	8.374854	0.151506	1103.096069	0.000000	NaN	NaN
310.999788	0.000879	8.788740	0.152062	1103.629150	0.000000	NaN	NaN
312.000846	0.000746	7.464306	0.152641	1104.183716	0.000000	NaN	NaN
312.999903	0.001011	10.113174	0.153145	1104.666382	0.000000	NaN	NaN
314.000960	0.000953	9.533734	0.153762	1105.257812	0.000000	NaN	NaN
315.000017	0.000796	7.960969	0.154181	1105.658569	0.000000	NaN	NaN
316.001074	0.000796	7.960969	0.154904	1106.351929	0.000000	NaN	NaN
316.999131	0.000937	9.368180	0.155413	1106.838989	0.000000	NaN	NaN
318.000189	0.000821	8.209300	0.155796	1107.206055	0.000000	NaN	NaN
318.999246	0.000986	9.864843	-1.000000	0.000000	0.000000	NaN	NaN
320.000303	0.000978	9.782066	0.156001	1107.402344	0.000000	NaN	NaN
321.000360	0.001011	10.113174	0.156526	1107.904907	0.000000	NaN	NaN
322.000417	0.000962	9.616511	0.157027	1108.385498	0.000000	NaN	NaN
323.000475	0.000854	8.540409	0.157574	1108.909668	0.000000	NaN	NaN
323.999532	0.000912	9.119849	0.158102	1109.414673	0.000000	NaN	NaN
324.999589	0.000953	9.533734	0.158883	1110.162964	0.000000	NaN	NaN
325.999646	0.000920	9.202626	0.159183	1110.450562	0.000000	NaN	NaN
327.000703	0.000879	8.788740	0.159796	1111.037964	0.000000	NaN	NaN
327.999760	0.000846	8.457631	0.160298	1111.519043	0.000000	NaN	NaN
329.000818	0.000904	9.037071	0.160878	1112.074585	0.000000	NaN	NaN
329.999875	0.000953	9.533734	0.159594	1110.844727	0.000000	NaN	NaN
331.000932	0.000871	8.705963	0.160267	1111.488647	0.000000	NaN	NaN
332.000989	0.000920	9.202626	0.160592	1111.800415	0.000000	NaN	NaN
333.001047	0.000920	9.202626	0.161208	1112.390015	0.000000	NaN	NaN
333.999104	0.000912	9.119849	0.161792	1112.950317	0.000000	NaN	NaN
334.999161	0.000854	8.540409	0.162341	1113.476074	0.000000	NaN	NaN
335.999218	0.000920	9.202626	0.162771	1113.887939	0.000000	NaN	NaN
337.000275	0.000846	8.457631	0.163233	1114.330566	0.000000	NaN	NaN
337.999332	0.000986	9.864843	0.163772	1114.846802	0.000000	NaN	NaN
339.000390	0.001011	10.113174	0.164329	1115.380493	0.000000	NaN	NaN
340.000447	0.001020	10.195951	0.164827	1115.856934	0.000000	NaN	NaN
341.000504	0.000854	8.540409	0.165421	1116.425903	0.000000	NaN	NaN
342.000561	0.000862	8.623186	0.165896	1116.881348	0.000000	NaN	NaN
342.999618	0.000962	9.616511	0.166383	1117.347778	0.000000	NaN	NaN
343.999676	0.000995	9.947620	0.167034	1117.971313	0.000000	NaN	NaN
344.999733	0.000887	8.871517	0.167513	1118.429932	0.000000	NaN	NaN
346.000790	0.000978	9.782066	0.167888	1118.789673	0.000000	NaN	NaN
346.999847	0.000937	9.368180	0.168472	1119.349365	0.000000	NaN	NaN
348.000904	0.001069	10.692614	0.168974	1119.830200	0.000000	NaN	NaN
348.999962	0.000962	9.616511	0.169474	1120.308838	0.000000	NaN	NaN
350.001019	0.000631	6.305426	0.170083	1120.892456	0.000000	NaN	NaN
351.001076	0.000705	7.050420	0.170653	1121.438354	0.000000	NaN	NaN
352.000133	0.000953	9.533734	0.171062	1121.830688	0.000000	NaN	NaN
352.999190	0.000953	9.533734	0.171757	1122.495850	0.000000	NaN	NaN
354.000248	0.000904	9.037071	0.172280	1122.996704	0.000000	NaN	NaN
354.999305	0.000821	8.209300	0.172809	1123.504272	0.000000	NaN	NaN
356.000362	0.000895	8.954294	0.173280	1123.954468	0.000000	NaN	NaN
356.999419	0.000978	9.782066	0.173815	1124.467163	0.000000	NaN	NaN
358.000476	0.000970	9.699289	0.174460	1125.085693	0.000000	NaN	NaN
358.999534	0.000929	9.285403	0.175069	1125.669067	0.000000	NaN	NaN
360.000591	0.000780	7.795414	0.175469	1126.052002	0.000000	NaN	NaN
360.999648	0.000929	9.285403	0.175982	1126.543213	0.000000	NaN	NaN
362.000705	0.001069	10.692614	0.176412	1126.954956	0.000000	NaN	NaN
363.000763	0.001036	10.361506	0.177006	1127.524658	0.000000	NaN	NaN
364.000820	0.000962	9.616511	0.177457	1127.956421	0.000000	NaN	NaN
364.999877	0.000929	9.285403	0.177940	1128.419434	0.000000	NaN	NaN
366.000934	0.000937	9.368180	0.178552	1129.005127	0.000000	NaN	NaN
367.000991	0.000995	9.947620	0.179201	1129.627319	0.000000	NaN	NaN
368.001049	0.001011	10.113174	0.179655	1130.062256	0.000000	NaN	NaN
369.000106	0.000763	7.629860	0.180210	1130.593628	0.000000	NaN	NaN
369.999163	0.000920	9.202626	0.180712	1131.074829	0.000000	NaN	NaN
371.000220	0.000953	9.533734	0.181205	1131.546509	0.000000	NaN	NaN
372.000277	0.000871	8.705963	0.181776	1132.093750	0.000000	NaN	NaN
373.000334	0.000970	9.699289	0.182267	1132.563965	0.000000	NaN	NaN
373.999392	0.000929	9.285403	0.182798	1133.072876	0.000000	NaN	NaN
375.000449	0.000945	9.450957	0.183366	1133.616821	0.000000	NaN	NaN
375.999506	0.000945	9.450957	0.183885	1134.114258	0.000000	NaN	NaN
377.000563	0.001086	10.858169	0.184354	1134.563843	0.000000	NaN	NaN
377.999620	0.000904	9.037071	0.185024	1135.205078	0.000000	NaN	NaN
378.999678	0.000862	8.623186	0.185431	1135.594971	0.000000	NaN	NaN
379.999735	0.001003	10.030397	0.185993	1136.133423	0.000000	NaN	NaN
380.999792	0.000962	9.616511	0.186596	1136.711060	0.000000	NaN	NaN
382.000849	0.000829	8.292077	0.187108	1137.201172	0.000000	NaN	NaN
383.000906	0.000953	9.533734	0.187621	1137.693359	0.000000	NaN	NaN
383.999964	0.000970	9.699289	0.188142	1138.191772	0.000000	NaN	NaN
385.001021	0.000821	8.209300	0.188702	1138.728149	0.000000	NaN	NaN
386.001078	0.000829	8.292077	0.189269	1139.271362	0.000000	NaN	NaN
387.000135	0.000912	9.119849	0.189720	1139.704102	0.000000	NaN	NaN
388.000192	0.000937	9.368180	0.190156	1140.121460	0.000000	NaN	NaN
388.999250	0.000937	9.368180	0.190708	1140.650513	0.000000	NaN	NaN
390.000307	0.000945	9.450957	0.191205	1141.125977	0.000000	NaN	NaN
391.000364	0.000929	9.285403	0.191701	1141.601562	0.000000	NaN	NaN
392.000421	0.000920	9.202626	0.192291	1142.166870	0.000000	NaN	NaN
393.000478	0.000895	8.954294	0.192783	1142.637573	0.000000	NaN	NaN
394.000536	0.000879	8.788740	0.193309	1143.141602	0.000000	NaN	NaN
395.000593	0.000920	9.202626	0.194075	1143.876221	0.000000	NaN	NaN
396.000650	0.000879	8.788740	0.194459	1144.243286	0.000000	NaN	NaN
397.000707	0.000904	9.037071	0.195026	1144.786865	0.000000	NaN	NaN
398.000764	0.000986	9.864843	0.195499	1145.240234	0.000000	NaN	NaN
399.000822	0.000920	9.202626	0.195925	1145.647949	0.000000	NaN	NaN
400.000879	0.000837	8.374854	0.196670	1146.361450	0.000000	NaN	NaN
401.000936	0.000879	8.788740	0.197128	1146.800171	0.000000	NaN	NaN
402.000993	0.000904	9.037071	0.197615	1147.266479	0.000000	NaN	NaN
403.001050	0.000937	9.368180	0.198065	1147.698364	0.000000	NaN	NaN
404.000108	0.000829	8.292077	0.198541	1148.153931	0.000000	NaN	NaN
404.999165	0.000887	8.871517	0.199093	1148.682983	0.000000	NaN	NaN
406.000222	0.000879	8.788740	0.199545	1149.115723	0.000000	NaN	NaN
406.999279	0.000937	9.368180	0.200092	1149.639771	0.000000	NaN	NaN
408.000336	0.000904	9.037071	0.200800	1150.318115	0.000000	NaN	NaN
409.000393	0.000986	9.864843	0.201177	1150.678711	0.000000	NaN	NaN
409.999451	0.000862	8.623186	0.201656	1151.138306	0.000000	NaN	NaN
410.999508	0.000912	9.119849	0.202204	1151.662964	0.000000	NaN	NaN
412.000565	0.000953	9.533734	0.202605	1152.047241	0.000000	NaN	NaN
413.000622	0.000920	9.202626	0.203264	1152.678711	0.000000	NaN	NaN
413.999680	0.000871	8.705963	0.203814	1153.204834	0.000000	NaN	NaN
415.000737	0.000929	9.285403	0.204348	1153.717285	0.000000	NaN	NaN
415.999794	0.000854	8.540409	0.204888	1154.234497	0.000000	NaN	NaN
416.999851	0.000953	9.533734	0.205392	1154.717407	0.000000	NaN	NaN
418.000908	0.001020	10.195951	0.205988	1155.288086	0.000000	NaN	NaN
419.000966	0.000887	8.871517	0.206564	1155.839844	0.000000	NaN	NaN
420.001023	0.000978	9.782066	0.206909	1156.170410	0.000000	NaN	NaN
421.001080	0.001044	10.444283	0.207430	1156.669067	0.000000	NaN	NaN
421.999137	0.000937	9.368180	0.207898	1157.117432	0.000000	NaN	NaN
423.000194	0.001028	10.278729	0.208455	1157.651611	0.000000	NaN	NaN
423.999251	0.000986	9.864843	0.208977	1158.151611	0.000000	NaN	NaN
425.000309	0.000887	8.871517	0.209554	1158.703979	0.000000	NaN	NaN
425.999366	0.001011	10.113174	0.209960	1159.093384	0.000000	NaN	NaN
427.000423	0.000945	9.450957	0.210525	1159.633789	0.000000	NaN	NaN
428.000480	0.001011	10.113174	0.211196	1160.277100	0.000000	NaN	NaN
429.000538	0.000962	9.616511	0.211613	1160.676270	0.000000	NaN	NaN
429.999595	0.000970	9.699289	0.212167	1161.207031	0.000000	NaN	NaN
431.000652	0.000978	9.782066	0.212758	1161.773560	0.000000	NaN	NaN
432.000709	0.000862	8.623186	0.213274	1162.267822	0.000000	NaN	NaN
433.000766	0.001003	10.030397	0.213794	1162.765991	0.000000	NaN	NaN
434.000824	0.000945	9.450957	0.214353	1163.300903	0.000000	NaN	NaN
435.000881	0.000887	8.871517	0.214861	1163.788086	0.000000	NaN	NaN
436.000938	0.000887	8.871517	0.215608	1164.503540	0.000000	NaN	NaN
437.000995	0.000895	8.954294	0.215959	1164.840088	0.000000	NaN	NaN
438.001052	0.000920	9.202626	0.216543	1165.399658	0.000000	NaN	NaN
439.000109	0.001011	10.113174	0.217088	1165.920898	0.000000	NaN	NaN
439.999167	0.000912	9.119849	0.217592	1166.403809	0.000000	NaN	NaN
441.000224	0.000796	7.960969	0.218230	1167.015747	0.000000	NaN	NaN
442.000281	0.000904	9.037071	0.218641	1167.408936	0.000000	NaN	NaN
443.000338	0.000986	9.864843	0.219162	1167.908325	0.000000	NaN	NaN
444.000395	0.000978	9.782066	0.219697	1168.421021	0.000000	NaN	NaN
444.999453	0.000862	8.623186	0.220140	1168.844727	0.000000	NaN	NaN
446.000510	0.000904	9.037071	0.220929	1169.600830	0.000000	NaN	NaN
446.999567	0.000904	9.037071	0.221453	1170.102661	0.000000	NaN	NaN
448.000624	0.001036	10.361506	0.222017	1170.643066	0.000000	NaN	NaN
448.999681	0.000945	9.450957	0.222539	1171.143311	0.000000	NaN	NaN
449.999738	0.000887	8.871517	0.223060	1171.641846	0.000000	NaN	NaN
450.999796	0.000937	9.368180	0.223780	1172.332031	0.000000	NaN	NaN
451.999853	0.000970	9.699289	0.224240	1172.772827	0.000000	NaN	NaN
452.999910	0.000962	9.616511	0.224780	1173.289917	0.000000	NaN	NaN
453.999967	0.001020	10.195951	0.225408	1173.891968	0.000000	NaN	NaN
455.001025	0.000937	9.368180	0.225817	1174.283447	0.000000	NaN	NaN
456.001082	0.000995	9.947620	0.226295	1174.741211	0.000000	NaN	NaN
457.002139	0.000879	8.788740	0.227086	1175.498901	0.000000	NaN	NaN
458.000196	0.000854	8.540409	0.227475	1175.871460	0.000000	NaN	NaN
459.003253	0.001053	10.527060	0.228119	1176.488770	0.000000	NaN	NaN
460.000311	0.000862	8.623186	0.228860	1177.198608	0.000000	NaN	NaN
461.004368	0.000945	9.450957	0.229043	1177.373413	0.000000	NaN	NaN
462.000425	0.001003	10.030397	0.229741	1178.042114	0.000000	NaN	NaN
463.005482	0.000837	8.374854	0.230500	1178.769897	0.000000	NaN	NaN
464.000539	0.000962	9.616511	0.230900	1179.152710	0.000000	NaN	NaN
465.006597	0.001053	10.527060	0.231589	1179.812988	0.000000	NaN	NaN
466.000654	0.000912	9.119849	0.232234	1180.430054	0.000000	NaN	NaN
467.007711	0.000945	9.450957	0.232791	1180.964111	0.000000	NaN	NaN
467.999768	0.000920	9.202626	0.233315	1181.466553	0.000000	NaN	NaN
469.008826	0.000929	9.285403	0.233922	1182.047607	0.000000	NaN	NaN
470.000882	0.001053	10.527060	0.234307	1182.416016	0.000000	NaN	NaN
471.009940	0.000871	8.705963	0.235050	1183.128418	0.000000	NaN	NaN
472.000997	0.000945	9.450957	0.235604	1183.658691	0.000000	NaN	NaN
473.011055	0.000978	9.782066	0.236177	1184.207886	0.000000	NaN	NaN
473.999111	0.000953	9.533734	0.236698	1184.707153	0.000000	NaN	NaN
475.012169	0.000929	9.285403	0.237305	1185.288086	0.000000	NaN	NaN
476.000226	0.000978	9.782066	0.237969	1185.924316	0.000000	NaN	NaN
477.013284	0.000995	9.947620	0.238340	1186.279663	0.000000	NaN	NaN
478.000340	0.000879	8.788740	0.238972	1186.885254	0.000000	NaN	NaN
479.014398	0.000953	9.533734	0.239775	1187.654419	0.000000	NaN	NaN
480.000454	0.000953	9.533734	0.240460	1188.310669	0.000000	NaN	NaN
481.014512	0.000970	9.699289	0.240845	1188.679687	0.000000	NaN	NaN
482.000569	0.000945	9.450957	0.241423	1189.233521	0.000000	NaN	NaN
483.015627	0.000879	8.788740	0.242167	1189.945923	0.000000	NaN	NaN
484.000683	0.000970	9.699289	0.242625	1190.385132	0.000000	NaN	NaN
485.000741	0.000895	8.954294	0.243166	1190.902588	0.000000	NaN	NaN
486.000798	0.000937	9.368180	0.243861	1191.568726	0.000000	NaN	NaN
487.000855	0.000970	9.699289	0.244204	1191.897461	0.000000	NaN	NaN
487.999912	0.000978	9.782066	0.244845	1192.511719	0.000000	NaN	NaN
488.999969	0.000895	8.954294	0.245395	1193.038452	0.000000	NaN	NaN
490.001027	0.001044	10.444283	0.245969	1193.588379	0.000000	NaN	NaN
491.227097	0.000879	8.788740	0.246513	1194.109009	0.000000	NaN	NaN
492.000141	0.001069	10.692614	0.247143	1194.713135	0.000000	NaN	NaN
492.999198	0.000945	9.450957	0.247512	1195.066284	0.000000	NaN	NaN
494.000255	0.000920	9.202626	0.248087	1195.617432	0.000000	NaN	NaN
495.000312	0.000895	8.954294	0.248812	1196.311157	0.000000	NaN	NaN
496.000370	0.000945	9.450957	0.249341	1196.818359	0.000000	NaN	NaN
497.000427	0.000871	8.705963	0.249931	1197.384033	0.000000	NaN	NaN
498.000484	0.000829	8.292077	0.250602	1198.026123	0.000000	NaN	NaN
498.999541	0.001011	10.113174	0.251097	1198.500488	0.000000	NaN	NaN
500.000598	0.000970	9.699289	0.251657	1199.037354	0.000000	NaN	NaN
501.000656	0.000829	8.292077	0.252356	1199.706787	0.000000	NaN	NaN
502.000713	0.000995	9.947620	0.253099	1200.418213	0.000000	NaN	NaN
503.000770	0.001053	10.527060	0.253626	1200.923462	0.000000	NaN	NaN
504.000827	0.000978	9.782066	0.254152	1201.427002	0.000000	NaN	NaN
505.000884	0.000945	9.450957	0.254739	1201.989136	0.000000	NaN	NaN
506.000942	0.000945	9.450957	0.255142	1202.375488	0.000000	NaN	NaN
507.000999	0.000978	9.782066	-1.000000	0.000000	0.000000	NaN	NaN
508.001056	0.000962	9.616511	0.258183	1205.288330	0.000000	NaN	NaN
509.000113	0.000937	9.368180	0.258628	1205.714966	0.000000	NaN	NaN
509.999170	0.000937	9.368180	0.259289	1206.348389	0.000000	NaN	NaN
511.000228	0.000962	9.616511	0.260019	1207.047119	0.000000	NaN	NaN
512.000285	0.001086	10.858169	0.260618	1207.621094	0.000000	NaN	NaN
513.000342	0.000895	8.954294	0.261148	1208.129028	0.000000	NaN	NaN
513.999399	0.000804	8.043746	0.261720	1208.677002	0.000000	NaN	NaN
515.000456	0.000887	8.871517	0.262450	1209.375732	0.000000	NaN	NaN
516.000514	0.000920	9.202626	0.263117	1210.015381	0.000000	NaN	NaN
517.000571	0.000796	7.960969	0.263559	1210.438721	0.000000	NaN	NaN
518.000628	0.000920	9.202626	0.264187	1211.040283	0.000000	NaN	NaN
519.000685	0.000912	9.119849	0.264822	1211.648437	0.000000	NaN	NaN
520.062746	0.001020	10.195951	0.265460	1212.259766	0.000000	NaN	NaN
521.000800	0.000895	8.954294	0.266125	1212.897095	0.000000	NaN	NaN
521.999857	0.000904	9.037071	0.266759	1213.503784	0.000000	NaN	NaN
522.999914	0.000821	8.209300	0.267497	1214.210693	0.000000	NaN	NaN
523.999971	0.000879	8.788740	0.268003	1214.695312	0.000000	NaN	NaN
525.000028	0.000871	8.705963	0.268776	1215.436157	0.000000	NaN	NaN
526.000085	0.001003	10.030397	0.269476	1216.107300	0.000000	NaN	NaN
527.000143	0.000937	9.368180	0.270200	1216.800537	0.000000	NaN	NaN
528.000200	0.000871	8.705963	0.270604	1217.187622	0.000000	NaN	NaN
529.000257	0.000871	8.705963	0.271348	1217.900635	0.000000	NaN	NaN
530.000314	0.000829	8.292077	0.272055	1218.577637	0.000000	NaN	NaN
531.000372	0.000829	8.292077	0.270677	1217.257202	0.000000	NaN	NaN
532.000429	0.000920	9.202626	0.271379	1217.929687	0.000000	NaN	NaN
533.000486	0.000986	9.864843	0.271995	1218.520264	0.000000	NaN	NaN
534.000543	0.000920	9.202626	0.272683	1219.179199	0.000000	NaN	NaN
535.000600	0.001011	10.113174	0.273355	1219.822388	0.000000	NaN	NaN
536.000657	0.000879	8.788740	0.273961	1220.403687	0.000000	NaN	NaN
537.000715	0.001044	10.444283	0.274621	1221.035156	0.000000	NaN	NaN
538.000772	0.000962	9.616511	0.275379	1221.761597	0.000000	NaN	NaN
539.000829	0.000970	9.699289	0.276049	1222.403076	0.000000	NaN	NaN
540.000886	0.000995	9.947620	0.276902	1223.220947	0.000000	NaN	NaN
541.000943	0.001003	10.030397	0.277370	1223.668823	0.000000	NaN	NaN
542.001001	0.000912	9.119849	0.278085	1224.353638	0.000000	NaN	NaN
543.001058	0.000978	9.782066	0.278874	1225.110107	0.000000	NaN	NaN
544.000115	0.000871	8.705963	0.279504	1225.713501	0.000000	NaN	NaN
545.000172	0.000920	9.202626	0.280102	1226.285889	0.000000	NaN	NaN
546.000230	0.000887	8.871517	0.280984	1227.130859	0.000000	NaN	NaN
547.000287	0.000788	7.878191	0.281579	1227.700684	0.000000	NaN	NaN
548.000344	0.000879	8.788740	0.282522	1228.604004	0.000000	NaN	NaN
549.000401	0.000887	8.871517	0.283155	1229.210693	0.000000	NaN	NaN
550.000458	0.000912	9.119849	0.284027	1230.046509	0.000000	NaN	NaN
551.000516	0.000904	9.037071	0.284718	1230.708496	0.000000	NaN	NaN
552.000573	0.000962	9.616511	0.285373	1231.335205	0.000000	NaN	NaN
553.000630	0.000887	8.871517	0.286263	1232.188354	0.000000	NaN	NaN
553.999687	0.000796	7.960969	0.286947	1232.842896	0.000000	NaN	NaN
555.000744	0.000804	8.043746	0.287718	1233.581665	0.000000	NaN	NaN
556.000801	0.000887	8.871517	0.288491	1234.322510	0.000000	NaN	NaN
557.000859	0.000978	9.782066	0.289301	1235.098389	0.000000	NaN	NaN
557.999916	0.001135	11.354832	0.290084	1235.848389	0.000000	NaN	NaN
559.000973	0.000962	9.616511	0.290831	1236.563721	0.000000	NaN	NaN
560.001030	0.000953	9.533734	0.291628	1237.327271	0.000000	NaN	NaN
561.001088	0.000937	9.368180	0.292490	1238.153687	0.000000	NaN	NaN
562.000145	0.000854	8.540409	0.293304	1238.932983	0.000000	NaN	NaN
563.000202	0.000829	8.292077	0.294091	1239.686890	0.000000	NaN	NaN
564.000259	0.000953	9.533734	0.294978	1240.536987	0.000000	NaN	NaN
565.000316	0.000821	8.209300	0.295709	1241.236816	0.000000	NaN	NaN
566.000373	0.000953	9.533734	0.296426	1241.924072	0.000000	NaN	NaN
567.000431	0.000821	8.209300	0.297397	1242.854126	0.000000	NaN	NaN
568.000488	0.000821	8.209300	0.298317	1243.735840	0.000000	NaN	NaN
569.000545	0.000722	7.215974	0.299139	1244.522583	0.000000	NaN	NaN
570.000602	0.000796	7.960969	0.300061	1245.406128	0.000000	NaN	NaN
571.000659	0.000970	9.699289	0.300961	1246.267822	0.000000	NaN	NaN
572.000717	0.000945	9.450957	0.301801	1247.073364	0.000000	NaN	NaN
573.000774	0.000978	9.782066	0.302611	1247.848755	0.000000	NaN	NaN
574.000831	0.000862	8.623186	0.303504	1248.704590	0.000000	NaN	NaN
574.999888	0.000904	9.037071	0.304346	1249.510498	0.000000	NaN	NaN
576.000945	0.000962	9.616511	0.305413	1250.532837	0.000000	NaN	NaN
577.001003	0.000796	7.960969	0.306178	1251.265503	0.000000	NaN	NaN
578.001060	0.000895	8.954294	0.307279	1252.320190	0.000000	NaN	NaN
579.000117	0.000854	8.540409	0.308173	1253.176880	0.000000	NaN	NaN
580.000174	0.000771	7.712637	0.309211	1254.171021	0.000000	NaN	NaN
581.000231	0.000879	8.788740	0.310293	1255.208374	0.000000	NaN	NaN
582.000289	0.000846	8.457631	0.311222	1256.098267	0.000000	NaN	NaN
583.000346	0.000738	7.381529	0.312195	1257.030151	0.000000	NaN	NaN
584.000403	0.000871	8.705963	0.313384	1258.169312	0.000000	NaN	NaN
585.000460	0.000796	7.960969	0.314385	1259.127563	0.000000	NaN	NaN
586.000517	0.000871	8.705963	0.315488	1260.184326	0.000000	NaN	NaN
586.999574	0.000788	7.878191	0.316426	1261.083374	0.000000	NaN	NaN
588.000632	0.000904	9.037071	0.317494	1262.105713	0.000000	NaN	NaN
589.000689	0.000771	7.712637	0.318897	1263.450439	0.000000	NaN	NaN
590.000746	0.000871	8.705963	0.319744	1264.261230	0.000000	NaN	NaN
591.000803	0.000854	8.540409	0.320920	1265.387939	0.000000	NaN	NaN
592.000861	0.000796	7.960969	0.322136	1266.552979	0.000000	NaN	NaN
592.999918	0.000854	8.540409	0.323253	1267.623169	0.000000	NaN	NaN
593.999975	0.000755	7.547083	0.324417	1268.738159	0.000000	NaN	NaN
595.001032	0.000763	7.629860	0.325587	1269.858521	0.000000	NaN	NaN
596.000089	0.000664	6.636534	0.326847	1271.065796	0.000000	NaN	NaN
596.999146	0.000622	6.222649	0.327987	1272.157715	0.000000	NaN	NaN
598.000204	0.000688	6.884866	0.329241	1273.358887	0.000000	NaN	NaN
599.000261	0.000672	6.719311	0.330603	1274.664429	0.000000	NaN	NaN
600.000318	0.000606	6.057094	0.331891	1275.897583	0.000000	NaN	NaN
601.000375	0.000688	6.884866	0.333193	1277.145264	0.000000	NaN	NaN
601.999432	0.000631	6.305426	0.334389	1278.290894	0.000000	NaN	NaN
603.000490	0.000738	7.381529	0.335781	1279.624634	0.000000	NaN	NaN
604.000547	0.000780	7.795414	0.337135	1280.921265	0.000000	NaN	NaN
605.000604	0.000606	6.057094	0.338312	1282.049194	0.000000	NaN	NaN
605.999661	0.000573	5.725986	0.339768	1283.443970	0.000000	NaN	NaN
607.000718	0.000349	3.491003	0.341086	1284.706543	0.000000	NaN	NaN
607.999776	0.000564	5.643209	0.342499	1286.060181	0.000000	NaN	NaN
609.000833	0.000589	5.891540	0.343749	1287.256958	0.000000	NaN	NaN
610.000890	0.000531	5.312100	0.345480	1288.915283	0.000000	NaN	NaN
611.000947	0.000606	6.057094	0.346989	1290.360840	0.000000	NaN	NaN
612.001005	0.000531	5.312100	0.348443	1291.754150	0.000000	NaN	NaN
613.001062	0.000506	5.063769	0.349942	1293.189819	0.000000	NaN	NaN
614.000119	0.000614	6.139871	0.351561	1294.741455	0.000000	NaN	NaN
615.000176	0.000622	6.222649	0.353022	1296.140747	0.000000	NaN	NaN
616.000233	0.000523	5.229323	0.354629	1297.680054	0.000000	NaN	NaN
617.000290	0.000424	4.235997	0.356012	1299.005005	0.000000	NaN	NaN
618.000348	0.000473	4.732660	0.358076	1300.982056	0.000000	NaN	NaN
619.000405	0.000573	5.725986	0.359423	1302.272705	0.000000	NaN	NaN
620.000462	0.000482	4.815437	0.360957	1303.741943	0.000000	NaN	NaN
621.000519	0.000498	4.980991	0.362419	1305.142090	0.000000	NaN	NaN
622.000576	0.000324	3.242671	0.259809	1206.846191	0.000000	NaN	NaN
622.999634	0.000465	4.649883	0.262198	1209.135254	0.000000	NaN	NaN
624.000691	0.000457	4.567106	0.264464	1211.305420	0.000000	NaN	NaN
624.999748	0.000407	4.070443	0.266838	1213.579956	0.000000	NaN	NaN
626.000805	0.000407	4.070443	0.268786	1215.445923	0.000000	NaN	NaN
627.000862	0.000390	3.904889	0.271358	1217.909546	0.000000	NaN	NaN
627.999920	0.000241	2.414900	0.273309	1219.778564	0.000000	NaN	NaN
629.000977	0.000299	2.994340	0.274888	1221.291260	0.000000	NaN	NaN
630.000034	0.000324	3.242671	0.276949	1223.265991	0.000000	NaN	NaN
630.999091	0.000424	4.235997	0.278656	1224.900757	0.000000	NaN	NaN
632.000148	0.000324	3.242671	0.363061	1305.757446	0.000000	NaN	NaN
633.000206	0.000258	2.580454	0.361446	1304.210205	0.000000	NaN	NaN
634.000263	0.000357	3.573780	0.360382	1303.191528	0.000000	NaN	NaN
634.999320	0.000308	3.077117	0.286044	1231.978027	0.000000	NaN	NaN
636.000377	0.000374	3.739334	0.288304	1234.143799	0.000000	NaN	NaN
637.000434	0.000208	2.083791	0.290046	1235.811890	0.000000	NaN	NaN
638.000492	0.000266	2.663231	0.292265	1237.937378	0.000000	NaN	NaN
638.999549	0.000142	1.421574	0.294107	1239.702026	0.000000	NaN	NaN
640.000606	0.000175	1.752683	0.296084	1241.596191	0.000000	NaN	NaN
641.000663	6.765799E-5	0.676580	0.298015	1243.445923	0.000000	NaN	NaN
641.999720	0.000200	2.001014	0.300041	1245.386719	0.000000	NaN	NaN
643.000778	0.000250	2.497677	0.302070	1247.330811	0.000000	NaN	NaN
643.999835	0.000208	2.083791	0.303855	1249.040771	0.000000	NaN	NaN
645.000892	0.000200	2.001014	0.306674	1251.740723	0.000000	NaN	NaN
645.999949	6.765799E-5	0.676580	0.309838	1254.772461	0.000000	NaN	NaN
647.001006	0.000175	1.752683	0.311620	1256.479492	0.000000	NaN	NaN
648.000064	0.000167	1.669906	0.313546	1258.323730	0.000000	NaN	NaN
649.000121	4.282484E-5	0.428248	0.315163	1259.872925	0.000000	NaN	NaN
649.999178	0.000134	1.338797	0.317106	1261.734009	0.000000	NaN	NaN
650.999235	0.000167	1.669906	0.318825	1263.380859	0.000000	NaN	NaN
651.999292	0.000117	1.173243	0.320828	1265.300049	0.000000	NaN	NaN
653.000349	0.000200	2.001014	0.322404	1266.809326	0.000000	NaN	NaN
653.999407	6.765799E-5	0.676580	0.323884	1268.227051	0.000000	NaN	NaN
655.000464	0.000101	1.007688	0.326114	1270.363403	0.000000	NaN	NaN
656.000521	0.000150	1.504351	0.327658	1271.843262	0.000000	NaN	NaN
657.000578	8.421341E-5	0.842134	0.329535	1273.640625	0.000000	NaN	NaN