File: data/9k_1-1_1 (180904).lvm
LabVIEW Measurement
Writer_Version	2
Reader_Version	2
Separator	Tab
Decimal_Separator	.
Multi_Headings	No
X_Columns	One
Time_Pref	Absolute
Operator	user
Description	Load(N)/Stress(MPa)/Distance A(pixel)/Strain A/Distance B(pixel)/Strain B/Poisson's ratio
Date	2018/09/04
Time	16:29:30.8052419300347360818
***End_of_Header***

Notes	X 값은 오직 다음과 같을 때에만 유효함이 보장됩니다. Dev1/ai0
Channels	7
Samples	1	1	1	1	1	1	1
Date	2018/09/04	2018/09/04	2018/09/04	2018/09/04	2018/09/04	2018/09/04	2018/09/04
Time	16:29:30.8052419300347360818	16:29:30.8052419300347360818	16:29:30.8052420616149902344	16:29:30.8052420616149902344	16:29:30.8052420616149902344	16:29:30.8052420616149902344	16:29:30.8052420616149902344
Y_Unit_Label	Volts	Volts
X_Dimension	Time	Time	Time	Time	Time	Time	Time
X0	0.0000000000000000E+0	0.0000000000000000E+0	0.0000000000000000E+0	0.0000000000000000E+0	0.0000000000000000E+0	0.0000000000000000E+0	0.0000000000000000E+0
Delta_X	0.000000	0.000000	1.000000	1.000000	1.000000	1.000000	1.000000
***End_of_Header***
X_Value	Dev1/ai0	Dev1/ai0 1	Untitled	Untitled 1	Untitled 2	Untitled 3	Untitled 4	Comment
0.000000	-1.511916E-5	-0.030238	-7.784367E-5	981.811523	0.000000	NaN	NaN
1.001057	-3.167459E-5	-0.063349	3.540516E-5	981.922729	0.000000	NaN	NaN
2.001114	1.436269E-6	0.002873	-0.000110	981.780396	0.000000	NaN	NaN
3.000172	-0.000106	-0.212348	0.000161	982.045898	0.000000	NaN	NaN
4.001229	-0.000156	-0.311681	0.000427	982.306702	0.000000	NaN	NaN
5.000286	9.713984E-6	0.019428	0.000663	982.539124	0.000000	NaN	NaN
6.000343	-4.823002E-5	-0.096460	0.000781	982.655151	0.000000	NaN	NaN
6.999400	1.799170E-5	0.035983	0.001225	983.090820	0.000000	NaN	NaN
8.000458	7.593570E-5	0.151871	0.001523	983.383606	0.000000	NaN	NaN
9.000515	8.421341E-5	0.168427	0.001835	983.690186	0.000000	NaN	NaN
10.000572	0.000101	0.201538	0.001979	983.830933	0.000000	NaN	NaN
10.999629	9.249113E-5	0.184982	0.002341	984.186523	0.000000	NaN	NaN
12.000686	9.713984E-6	0.019428	0.002507	984.349304	0.000000	NaN	NaN
13.000744	0.000150	0.300870	0.002874	984.710266	0.000000	NaN	NaN
14.000801	0.000134	0.267759	0.003149	984.980103	0.000000	NaN	NaN
14.999858	0.000184	0.367092	0.003520	985.343872	0.000000	NaN	NaN
16.000915	0.000126	0.251204	0.003624	985.446411	0.000000	NaN	NaN
16.999972	0.000109	0.218093	0.004041	985.855469	0.000000	NaN	NaN
18.001030	0.000217	0.433314	0.004277	986.087280	0.000000	NaN	NaN
19.000087	0.000175	0.350537	0.004454	986.261292	0.000000	NaN	NaN
20.001144	0.000217	0.433314	0.004899	986.698364	0.000000	NaN	NaN
21.001201	5.938027E-5	0.118761	0.004859	986.658569	0.000000	NaN	NaN
22.001258	0.000208	0.416758	0.005316	987.107361	0.000000	NaN	NaN
23.001316	0.000200	0.400203	0.005446	987.235107	0.000000	NaN	NaN
24.000373	0.000175	0.350537	0.005617	987.403625	0.000000	NaN	NaN
25.000430	0.000225	0.449869	0.006039	987.817444	0.000000	NaN	NaN
26.000487	0.000217	0.433314	0.006133	987.910217	0.000000	NaN	NaN
26.999544	9.249113E-5	0.184982	0.006552	988.321350	0.000000	NaN	NaN
28.000601	0.000200	0.400203	0.006627	988.394470	0.000000	NaN	NaN
29.000659	0.000275	0.549202	0.006901	988.664368	0.000000	NaN	NaN
29.999716	0.000291	0.582313	0.007064	988.824402	0.000000	NaN	NaN
31.000773	0.000192	0.383647	0.007527	989.278442	0.000000	NaN	NaN
32.000830	0.000349	0.698201	0.007553	989.304016	0.000000	NaN	NaN
33.000887	0.000275	0.549202	0.008060	989.802429	0.000000	NaN	NaN
33.999945	0.000192	0.383647	0.008065	989.807129	0.000000	NaN	NaN
35.001002	0.000291	0.582313	0.008320	990.057251	0.000000	NaN	NaN
36.001059	0.000299	0.598868	0.008601	990.333557	0.000000	NaN	NaN
37.001116	0.000308	0.615423	0.008967	990.692078	0.000000	NaN	NaN
38.001174	0.000291	0.582313	0.009128	990.850403	0.000000	NaN	NaN
39.000231	0.000341	0.681645	0.009331	991.050171	0.000000	NaN	NaN
40.001288	0.000283	0.565757	0.009745	991.456543	0.000000	NaN	NaN
41.000345	0.000357	0.714756	0.009928	991.635925	0.000000	NaN	NaN
42.000402	0.000275	0.549202	0.010038	991.743835	0.000000	NaN	NaN
42.999459	0.000275	0.549202	0.010245	991.947144	0.000000	NaN	NaN
44.000517	0.000407	0.814089	0.010624	992.319214	0.000000	NaN	NaN
45.000574	0.000341	0.681645	0.010901	992.591614	0.000000	NaN	NaN
45.999631	0.000357	0.714756	0.011147	992.833496	0.000000	NaN	NaN
47.000688	0.000357	0.714756	0.011443	993.123779	0.000000	NaN	NaN
48.000746	0.000366	0.731311	0.011467	993.146790	0.000000	NaN	NaN
48.999803	0.000382	0.764422	0.011813	993.487061	0.000000	NaN	NaN
50.000860	0.000366	0.731311	0.012003	993.673889	0.000000	NaN	NaN
51.000917	0.000506	1.012754	0.012304	993.968689	0.000000	NaN	NaN
52.000974	0.000490	0.979643	0.012488	994.149475	0.000000	NaN	NaN
53.000031	0.000308	0.615423	0.012852	994.507080	0.000000	NaN	NaN
54.001089	0.000407	0.814089	0.013065	994.715820	0.000000	NaN	NaN
55.001146	0.000366	0.731311	0.013365	995.010437	0.000000	NaN	NaN
56.001203	0.000515	1.029309	0.013575	995.217529	0.000000	NaN	NaN
57.000260	0.000482	0.963087	0.013602	995.243225	0.000000	NaN	NaN
58.001317	0.000440	0.880310	0.014120	995.752258	0.000000	NaN	NaN
59.000375	0.000448	0.896866	0.014499	996.124146	0.000000	NaN	NaN
60.000432	0.000275	0.549202	0.014685	996.306519	0.000000	NaN	NaN
60.999489	0.000366	0.731311	0.014913	996.531006	0.000000	NaN	NaN
62.000546	0.000399	0.797533	0.015198	996.811035	0.000000	NaN	NaN
62.999603	0.000424	0.847199	0.015303	996.914307	0.000000	NaN	NaN
64.000661	0.000498	0.996198	0.015575	997.181091	0.000000	NaN	NaN
64.999718	0.000523	1.045865	0.015857	997.457336	0.000000	NaN	NaN
65.999775	0.000490	0.979643	0.016038	997.635620	0.000000	NaN	NaN
66.999832	0.000366	0.731311	0.016631	998.218140	0.000000	NaN	NaN
67.999889	0.000498	0.996198	0.016972	998.552551	0.000000	NaN	NaN
69.000947	0.000506	1.012754	0.017129	998.706543	0.000000	NaN	NaN
70.000004	0.000457	0.913421	0.017439	999.010986	0.000000	NaN	NaN
71.001061	0.000506	1.012754	0.017640	999.208374	0.000000	NaN	NaN
72.000118	0.000523	1.045865	0.018133	999.692200	0.000000	NaN	NaN
73.001175	0.000473	0.946532	0.018382	999.937439	0.000000	NaN	NaN
74.000232	0.000548	1.095531	0.018763	1000.311218	0.000000	NaN	NaN
75.001290	0.000639	1.277641	0.019030	1000.573181	0.000000	NaN	NaN
75.999347	0.000531	1.062420	0.019320	1000.858398	0.000000	NaN	NaN
77.000404	0.000606	1.211419	0.019755	1001.285339	0.000000	NaN	NaN
78.000461	0.000490	0.979643	0.019910	1001.436890	0.000000	NaN	NaN
79.000518	0.000606	1.211419	0.020505	1002.021240	0.000000	NaN	NaN
79.999576	0.000564	1.128642	-1.000000	0.000000	0.000000	NaN	NaN
81.000633	0.000606	1.211419	0.022167	1003.653198	0.000000	NaN	NaN
82.000690	0.000589	1.178308	0.022658	1004.135681	0.000000	NaN	NaN
83.000747	0.000564	1.128642	0.023125	1004.594116	0.000000	NaN	NaN
83.999804	0.000457	0.913421	0.023513	1004.975281	0.000000	NaN	NaN
84.999862	0.000589	1.178308	0.023971	1005.424377	0.000000	NaN	NaN
86.000919	0.000498	0.996198	0.024463	1005.907715	0.000000	NaN	NaN
87.000976	0.000672	1.343862	0.024810	1006.248230	0.000000	NaN	NaN
88.229046	0.000531	1.062420	0.025146	1006.578247	0.000000	NaN	NaN
89.000090	0.000523	1.045865	0.025576	1007.000549	0.000000	NaN	NaN
90.001148	0.000655	1.310751	0.025959	1007.376770	0.000000	NaN	NaN
91.001205	0.000515	1.029309	0.026488	1007.896545	0.000000	NaN	NaN
92.001262	0.000515	1.029309	0.026875	1008.276428	0.000000	NaN	NaN
93.000319	0.000614	1.227974	0.027015	1008.413513	0.000000	NaN	NaN
94.000377	0.000589	1.178308	0.027799	1009.183594	0.000000	NaN	NaN
94.999434	0.000581	1.161753	0.028131	1009.508972	0.000000	NaN	NaN
95.999491	0.000655	1.310751	0.028533	1009.904175	0.000000	NaN	NaN
96.999548	0.000589	1.178308	0.029127	1010.487549	0.000000	NaN	NaN
98.000605	0.000597	1.194863	0.029440	1010.794373	0.000000	NaN	NaN
98.999662	0.000614	1.227974	0.030057	1011.400208	0.000000	NaN	NaN
100.000720	0.000556	1.112086	0.030518	1011.853394	0.000000	NaN	NaN
100.999777	0.000697	1.393529	0.030899	1012.226868	0.000000	NaN	NaN
102.000834	0.000614	1.227974	0.031439	1012.757629	0.000000	NaN	NaN
102.999891	0.000573	1.145197	0.031878	1013.188171	0.000000	NaN	NaN
104.000948	0.000523	1.045865	0.032480	1013.780029	0.000000	NaN	NaN
105.001006	0.000556	1.112086	0.032688	1013.983704	0.000000	NaN	NaN
106.001063	0.000606	1.211419	0.033256	1014.541504	0.000000	NaN	NaN
107.000120	0.000664	1.327307	0.032392	1013.692810	0.000000	NaN	NaN
108.000177	0.000597	1.194863	0.032819	1014.112671	0.000000	NaN	NaN
109.000234	0.000631	1.261085	0.033407	1014.689514	0.000000	NaN	NaN
110.000292	0.000548	1.095531	0.034047	1015.318542	0.000000	NaN	NaN
110.999349	0.000639	1.277641	0.034385	1015.650635	0.000000	NaN	NaN
111.999406	0.000664	1.327307	0.034782	1016.040283	0.000000	NaN	NaN
112.999463	0.000697	1.393529	0.035237	1016.487000	0.000000	NaN	NaN
113.999520	0.000581	1.161753	0.035844	1017.082764	0.000000	NaN	NaN
115.000578	0.000813	1.625305	0.036300	1017.530396	0.000000	NaN	NaN
116.000635	0.000771	1.542527	0.036850	1018.070984	0.000000	NaN	NaN
117.000692	0.000639	1.277641	0.037324	1018.535706	0.000000	NaN	NaN
117.999749	0.000680	1.360418	0.037592	1018.799316	0.000000	NaN	NaN
119.000806	0.000573	1.145197	0.038280	1019.475098	0.000000	NaN	NaN
119.999864	0.000432	0.863755	0.038777	1019.962280	0.000000	NaN	NaN
120.999921	0.000631	1.261085	0.039178	1020.356079	0.000000	NaN	NaN
121.999978	0.000655	1.310751	0.039758	1020.925903	0.000000	NaN	NaN
123.001035	0.000631	1.261085	0.040284	1021.442322	0.000000	NaN	NaN
124.001092	0.000655	1.310751	0.040836	1021.983887	0.000000	NaN	NaN
125.001150	0.000680	1.360418	0.041340	1022.478821	0.000000	NaN	NaN
126.000207	0.000688	1.376973	-1.000000	0.000000	0.000000	NaN	NaN
127.000264	0.000672	1.343862	0.042964	1024.074097	0.000000	NaN	NaN
127.999321	0.000589	1.178308	0.043400	1024.501831	0.000000	NaN	NaN
129.000378	0.000697	1.393529	0.043978	1025.069092	0.000000	NaN	NaN
129.999436	0.000597	1.194863	0.044447	1025.530029	0.000000	NaN	NaN
131.000493	0.000705	1.410084	0.045040	1026.112427	0.000000	NaN	NaN
131.999550	0.000614	1.227974	0.045569	1026.631226	0.000000	NaN	NaN
133.000607	0.000697	1.393529	0.046118	1027.170898	0.000000	NaN	NaN
134.000664	0.000622	1.244530	0.046589	1027.632812	0.000000	NaN	NaN
135.000722	0.000680	1.360418	0.047114	1028.149048	0.000000	NaN	NaN
136.000779	0.000763	1.525972	0.047648	1028.672729	0.000000	NaN	NaN
136.999836	0.000680	1.360418	0.048290	1029.303711	0.000000	NaN	NaN
138.000893	0.000655	1.310751	0.048872	1029.875122	0.000000	NaN	NaN
138.999950	0.000581	1.161753	0.049432	1030.424194	0.000000	NaN	NaN
140.001008	0.000622	1.244530	0.049928	1030.911621	0.000000	NaN	NaN
141.000065	0.000515	1.029309	0.050565	1031.536621	0.000000	NaN	NaN
142.001122	0.000647	1.294196	0.051079	1032.041504	0.000000	NaN	NaN
143.001179	0.000614	1.227974	0.051555	1032.509033	0.000000	NaN	NaN
144.001236	0.000647	1.294196	0.052193	1033.135620	0.000000	NaN	NaN
145.000293	0.000722	1.443195	0.052646	1033.580322	0.000000	NaN	NaN
146.000351	0.000713	1.426639	0.053204	1034.127930	0.000000	NaN	NaN
147.000408	0.000713	1.426639	0.053853	1034.765137	0.000000	NaN	NaN
147.999465	0.000589	1.178308	0.054287	1035.191650	0.000000	NaN	NaN
148.999522	0.000639	1.277641	0.055023	1035.914673	0.000000	NaN	NaN
150.000579	0.000763	1.525972	0.055561	1036.442993	0.000000	NaN	NaN
151.000637	0.000688	1.376973	0.056074	1036.946411	0.000000	NaN	NaN
152.000694	0.000705	1.410084	0.056610	1037.472290	0.000000	NaN	NaN
153.000751	0.000672	1.343862	0.057293	1038.143311	0.000000	NaN	NaN
153.999808	0.000573	1.145197	0.057791	1038.632080	0.000000	NaN	NaN
155.000866	0.000672	1.343862	0.058440	1039.269897	0.000000	NaN	NaN
155.999923	0.000738	1.476306	0.058944	1039.763916	0.000000	NaN	NaN
157.000980	0.000614	1.227974	0.059534	1040.343384	0.000000	NaN	NaN
158.000037	0.000639	1.277641	0.060123	1040.921753	0.000000	NaN	NaN
159.001094	0.000614	1.227974	0.060681	1041.469971	0.000000	NaN	NaN
160.001151	0.000688	1.376973	0.061218	1041.997314	0.000000	NaN	NaN
161.001209	0.000730	1.459750	0.061833	1042.600586	0.000000	NaN	NaN
162.000266	0.000705	1.410084	0.062366	1043.124146	0.000000	NaN	NaN
163.000323	0.000655	1.310751	0.062894	1043.642578	0.000000	NaN	NaN
163.999380	0.000647	1.294196	0.063538	1044.275513	0.000000	NaN	NaN
165.000438	0.000573	1.145197	-1.000000	0.000000	0.000000	NaN	NaN
165.999495	0.000606	1.211419	0.063535	1044.272461	0.000000	NaN	NaN
166.999552	0.000722	1.443195	0.064171	1044.896729	0.000000	NaN	NaN
168.000609	0.000515	1.029309	0.064657	1045.373779	0.000000	NaN	NaN
168.999666	0.000655	1.310751	0.065359	1046.062744	0.000000	NaN	NaN
170.000723	0.000680	1.360418	0.065967	1046.660034	0.000000	NaN	NaN
170.999781	0.000672	1.343862	0.066519	1047.202026	0.000000	NaN	NaN
172.000838	0.000655	1.310751	0.067041	1047.714844	0.000000	NaN	NaN
173.000895	0.000722	1.443195	0.067583	1048.246582	0.000000	NaN	NaN
173.999952	0.000705	1.410084	0.068337	1048.987305	0.000000	NaN	NaN
175.000009	0.000680	1.360418	0.068891	1049.530762	0.000000	NaN	NaN
176.106073	0.000614	1.227974	0.069505	1050.133911	0.000000	NaN	NaN
177.000124	0.000664	1.327307	0.070045	1050.663818	0.000000	NaN	NaN
178.001181	0.000581	1.161753	0.070687	1051.294434	0.000000	NaN	NaN
179.001238	0.000622	1.244530	-1.000000	0.000000	0.000000	NaN	NaN
180.001295	0.000722	1.443195	0.072603	1053.175537	0.000000	NaN	NaN
181.000353	0.000589	1.178308	0.073169	1053.731689	0.000000	NaN	NaN
182.000410	0.000647	1.294196	0.073777	1054.328857	0.000000	NaN	NaN
182.999467	0.000539	1.078975	0.074451	1054.990601	0.000000	NaN	NaN
184.000524	0.000631	1.261085	0.075006	1055.535400	0.000000	NaN	NaN
184.999581	0.000631	1.261085	0.075577	1056.096313	0.000000	NaN	NaN
186.000639	0.000589	1.178308	0.076277	1056.783569	0.000000	NaN	NaN
187.000696	0.000746	1.492861	0.076808	1057.305176	0.000000	NaN	NaN
188.000753	0.000647	1.294196	0.077448	1057.933716	0.000000	NaN	NaN
189.000810	0.000713	1.426639	0.078042	1058.516357	0.000000	NaN	NaN
190.000867	0.000655	1.310751	0.078639	1059.102539	0.000000	NaN	NaN
191.000925	0.000688	1.376973	0.079239	1059.691284	0.000000	NaN	NaN
191.999982	0.000738	1.476306	0.079850	1060.291260	0.000000	NaN	NaN
193.001039	0.000606	1.211419	0.080479	1060.908813	0.000000	NaN	NaN
194.001096	0.000697	1.393529	0.081044	1061.463623	0.000000	NaN	NaN
195.001153	0.000664	1.327307	0.081736	1062.143188	0.000000	NaN	NaN
196.001211	0.000722	1.443195	0.082208	1062.607178	0.000000	NaN	NaN
197.001268	0.000647	1.294196	0.082870	1063.256958	0.000000	NaN	NaN
197.999325	0.000597	1.194863	0.083486	1063.861938	0.000000	NaN	NaN
199.000382	0.000664	1.327307	0.084019	1064.385376	0.000000	NaN	NaN
200.000439	0.000680	1.360418	0.084641	1064.995605	0.000000	NaN	NaN
201.000496	0.000573	1.145197	0.085262	1065.605347	0.000000	NaN	NaN
201.999554	0.000597	1.194863	0.085895	1066.226929	0.000000	NaN	NaN
203.000611	0.000722	1.443195	0.086507	1066.828247	0.000000	NaN	NaN
203.999668	0.000556	1.112086	0.087074	1067.385254	0.000000	NaN	NaN
205.000725	0.000515	1.029309	0.087608	1067.909302	0.000000	NaN	NaN
205.999783	0.000606	1.211419	0.088268	1068.557007	0.000000	NaN	NaN
206.999840	0.000589	1.178308	0.088915	1069.192139	0.000000	NaN	NaN
207.999897	0.000680	1.360418	0.089494	1069.760986	0.000000	NaN	NaN
209.000954	0.000639	1.277641	0.089985	1070.242676	0.000000	NaN	NaN
210.001011	0.000597	1.194863	0.090617	1070.863281	0.000000	NaN	NaN
211.000068	0.000697	1.393529	0.091295	1071.529053	0.000000	NaN	NaN
212.037128	0.000622	1.244530	0.091837	1072.061401	0.000000	NaN	NaN
213.001183	0.000639	1.277641	0.092446	1072.659424	0.000000	NaN	NaN
214.000240	0.000622	1.244530	0.093086	1073.287842	0.000000	NaN	NaN
215.000297	0.000655	1.310751	0.093761	1073.950317	0.000000	NaN	NaN
215.999354	0.000680	1.360418	0.094211	1074.392578	0.000000	NaN	NaN
217.000412	0.000614	1.227974	0.094883	1075.052002	0.000000	NaN	NaN
218.000469	0.000482	0.963087	0.095462	1075.620605	0.000000	NaN	NaN
218.999526	0.000614	1.227974	0.096005	1076.154419	0.000000	NaN	NaN
220.000583	0.000672	1.343862	0.096536	1076.675415	0.000000	NaN	NaN
220.999640	0.000713	1.426639	0.097194	1077.322021	0.000000	NaN	NaN
222.000698	0.000713	1.426639	0.097777	1077.894409	0.000000	NaN	NaN
223.000755	0.000655	1.310751	0.098417	1078.522217	0.000000	NaN	NaN
224.000812	0.000622	1.244530	0.098933	1079.029419	0.000000	NaN	NaN
224.999869	0.000680	1.360418	0.099645	1079.728271	0.000000	NaN	NaN
226.000926	0.000655	1.310751	0.100185	1080.258667	0.000000	NaN	NaN
226.999984	0.000713	1.426639	0.100897	1080.957642	0.000000	NaN	NaN
228.001041	0.000639	1.277641	0.101359	1081.410645	0.000000	NaN	NaN
229.000098	0.000647	1.294196	0.101969	1082.010498	0.000000	NaN	NaN
230.001155	0.000697	1.393529	0.102519	1082.549805	0.000000	NaN	NaN
231.000212	0.000647	1.294196	-1.000000	0.000000	0.000000	NaN	NaN
232.001270	0.000655	1.310751	0.102359	1082.392822	0.000000	NaN	NaN
233.000327	0.000688	1.376973	0.102910	1082.933716	0.000000	NaN	NaN
233.999384	0.000589	1.178308	0.103576	1083.588013	0.000000	NaN	NaN
235.000441	0.000912	1.823970	0.104177	1084.178101	0.000000	NaN	NaN
236.000498	0.000581	1.161753	0.104733	1084.724243	0.000000	NaN	NaN
237.000556	0.000631	1.261085	0.105291	1085.271851	0.000000	NaN	NaN
238.000613	0.000730	1.459750	0.105833	1085.804199	0.000000	NaN	NaN
239.000670	0.000631	1.261085	0.106520	1086.478271	0.000000	NaN	NaN
240.000727	0.000672	1.343862	0.107163	1087.110229	0.000000	NaN	NaN
241.000784	0.000597	1.194863	0.107749	1087.685303	0.000000	NaN	NaN
241.999842	0.000622	1.244530	0.108309	1088.235352	0.000000	NaN	NaN
243.000899	0.000746	1.492861	0.108952	1088.866943	0.000000	NaN	NaN
244.000956	0.000655	1.310751	0.109560	1089.463501	0.000000	NaN	NaN
245.001013	0.000564	1.128642	0.110114	1090.007324	0.000000	NaN	NaN
246.001070	0.000664	1.327307	0.110664	1090.547119	0.000000	NaN	NaN
247.000128	0.000589	1.178308	0.111198	1091.072388	0.000000	NaN	NaN
248.001185	0.000622	1.244530	0.111895	1091.756592	0.000000	NaN	NaN
249.001242	0.000622	1.244530	0.112459	1092.309814	0.000000	NaN	NaN
250.000299	0.000597	1.194863	0.113087	1092.927002	0.000000	NaN	NaN
251.000356	0.000672	1.343862	0.113606	1093.436279	0.000000	NaN	NaN
251.999414	0.000755	1.509417	0.114160	1093.980225	0.000000	NaN	NaN
253.000471	0.000713	1.426639	0.114965	1094.770386	0.000000	NaN	NaN
254.000528	0.000556	1.112086	0.115506	1095.302246	0.000000	NaN	NaN
255.000585	0.000664	1.327307	0.116024	1095.810913	0.000000	NaN	NaN
256.000642	0.000589	1.178308	0.116571	1096.347534	0.000000	NaN	NaN
256.999700	0.000713	1.426639	0.117242	1097.006592	0.000000	NaN	NaN
257.999757	0.000705	1.410084	0.117882	1097.634521	0.000000	NaN	NaN
258.999814	0.000614	1.227974	0.118367	1098.111450	0.000000	NaN	NaN
259.999871	0.000780	1.559083	0.118915	1098.649292	0.000000	NaN	NaN
260.999928	0.000722	1.443195	0.119528	1099.251099	0.000000	NaN	NaN
261.999985	0.000697	1.393529	0.120136	1099.847534	0.000000	NaN	NaN
263.000043	0.000631	1.261085	0.120758	1100.458496	0.000000	NaN	NaN
264.001100	0.000581	1.161753	0.121359	1101.048828	0.000000	NaN	NaN
265.000157	0.000713	1.426639	0.121915	1101.594360	0.000000	NaN	NaN
266.001214	0.000697	1.393529	0.122571	1102.238770	0.000000	NaN	NaN
267.000271	0.000705	1.410084	0.123144	1102.801758	0.000000	NaN	NaN
268.000329	0.000722	1.443195	-1.000000	0.000000	0.000000	NaN	NaN
268.999386	0.000688	1.376973	0.123223	1102.879395	0.000000	NaN	NaN
270.000443	0.000647	1.294196	0.123793	1103.439087	0.000000	NaN	NaN
271.000500	0.000688	1.376973	0.124377	1104.012329	0.000000	NaN	NaN
272.000558	0.000639	1.277641	0.124980	1104.603882	0.000000	NaN	NaN
273.000615	0.000672	1.343862	0.125546	1105.160522	0.000000	NaN	NaN
274.000672	0.000589	1.178308	0.126124	1105.727783	0.000000	NaN	NaN
275.000729	0.000573	1.145197	0.126747	1106.339722	0.000000	NaN	NaN
276.000786	0.000631	1.261085	0.127441	1107.020386	0.000000	NaN	NaN
277.000843	0.000556	1.112086	0.127952	1107.522217	0.000000	NaN	NaN
278.000901	0.000622	1.244530	0.128488	1108.048340	0.000000	NaN	NaN
279.000958	0.000581	1.161753	0.129109	1108.658813	0.000000	NaN	NaN
280.000015	0.000589	1.178308	0.129718	1109.256348	0.000000	NaN	NaN
281.001072	0.000631	1.261085	0.130256	1109.785034	0.000000	NaN	NaN
282.000130	0.000755	1.509417	0.130913	1110.429443	0.000000	NaN	NaN
283.001187	0.000688	1.376973	0.131404	1110.911987	0.000000	NaN	NaN
284.000244	0.000548	1.095531	0.132004	1111.500854	0.000000	NaN	NaN
285.001301	0.000564	1.128642	0.132611	1112.097046	0.000000	NaN	NaN
286.000358	0.000606	1.211419	0.133236	1112.710937	0.000000	NaN	NaN
287.000415	0.000788	1.575638	0.133841	1113.304321	0.000000	NaN	NaN
287.999473	0.000639	1.277641	0.134344	1113.798706	0.000000	NaN	NaN
289.000530	0.000589	1.178308	0.134907	1114.351562	0.000000	NaN	NaN
290.000587	0.000697	1.393529	0.135511	1114.944824	0.000000	NaN	NaN
291.000644	0.000639	1.277641	0.136013	1115.437622	0.000000	NaN	NaN
292.000701	0.000631	1.261085	0.136692	1116.104492	0.000000	NaN	NaN
293.000759	0.000705	1.410084	0.137210	1116.612671	0.000000	NaN	NaN
294.000816	0.000639	1.277641	0.137716	1117.109253	0.000000	NaN	NaN
295.000873	0.000688	1.376973	0.138348	1117.730347	0.000000	NaN	NaN
296.000930	0.000573	1.145197	0.138990	1118.360962	0.000000	NaN	NaN
297.000988	0.000622	1.244530	0.139499	1118.860596	0.000000	NaN	NaN
298.001045	0.000672	1.343862	0.140129	1119.479370	0.000000	NaN	NaN
299.001102	0.000589	1.178308	0.140725	1120.063965	0.000000	NaN	NaN
300.001159	0.000697	1.393529	0.141310	1120.638550	0.000000	NaN	NaN
301.001216	0.000664	1.327307	0.141803	1121.122437	0.000000	NaN	NaN
302.001274	0.000655	1.310751	0.142502	1121.809204	0.000000	NaN	NaN
303.000331	0.000597	1.194863	0.143021	1122.318115	0.000000	NaN	NaN
304.000388	0.000672	1.343862	0.143546	1122.834106	0.000000	NaN	NaN
305.000445	0.000688	1.376973	0.144218	1123.493652	0.000000	NaN	NaN
306.000502	0.000788	1.575638	0.144753	1124.019531	0.000000	NaN	NaN
306.999559	0.000647	1.294196	0.145307	1124.562988	0.000000	NaN	NaN
308.000617	0.000647	1.294196	0.145921	1125.166504	0.000000	NaN	NaN
309.000674	0.000564	1.128642	0.146524	1125.758545	0.000000	NaN	NaN
310.000731	0.000631	1.261085	0.147071	1126.294800	0.000000	NaN	NaN
311.000788	0.000622	1.244530	0.147622	1126.835693	0.000000	NaN	NaN
312.000845	0.000705	1.410084	0.148205	1127.408691	0.000000	NaN	NaN
313.000903	0.000639	1.277641	0.148851	1128.043335	0.000000	NaN	NaN
314.000960	0.000788	1.575638	0.149337	1128.520508	0.000000	NaN	NaN
315.001017	0.000763	1.525972	0.150003	1129.174316	0.000000	NaN	NaN
316.001074	0.000664	1.327307	0.150487	1129.649780	0.000000	NaN	NaN
317.001131	0.000639	1.277641	0.151185	1130.334229	0.000000	NaN	NaN
318.000188	0.000788	1.575638	0.151742	1130.881104	0.000000	NaN	NaN
319.001246	0.000730	1.459750	0.152744	1131.865845	0.000000	NaN	NaN
320.001303	0.000697	1.393529	0.153592	1132.697632	0.000000	NaN	NaN
321.000360	0.000631	1.261085	0.154238	1133.331909	0.000000	NaN	NaN
321.999417	0.000664	1.327307	0.154940	1134.021851	0.000000	NaN	NaN
323.000474	0.000697	1.393529	0.155509	1134.580444	0.000000	NaN	NaN
323.999532	0.000672	1.343862	0.156189	1135.248169	0.000000	NaN	NaN
325.000589	0.000614	1.227974	0.156831	1135.878784	0.000000	NaN	NaN
326.000646	0.000556	1.112086	0.157474	1136.509888	0.000000	NaN	NaN
327.000703	0.000664	1.327307	0.158097	1137.121338	0.000000	NaN	NaN
328.000761	0.000647	1.294196	0.158618	1137.633179	0.000000	NaN	NaN
329.000818	0.000589	1.178308	0.159026	1138.033813	0.000000	NaN	NaN
329.999875	0.000589	1.178308	0.159332	1138.333862	0.000000	NaN	NaN
331.000932	0.000573	1.145197	0.159649	1138.644897	0.000000	NaN	NaN
332.000989	0.000490	0.979643	0.160195	1139.181519	0.000000	NaN	NaN
333.001046	0.000548	1.095531	0.160741	1139.717529	0.000000	NaN	NaN
334.000104	0.000655	1.310751	0.161126	1140.095337	0.000000	NaN	NaN
335.001161	0.000631	1.261085	0.161750	1140.708740	0.000000	NaN	NaN
336.001218	0.000589	1.178308	0.162423	1141.369263	0.000000	NaN	NaN
337.000275	0.000639	1.277641	0.162913	1141.850586	0.000000	NaN	NaN
337.999332	0.000664	1.327307	0.163446	1142.373291	0.000000	NaN	NaN
339.000390	0.000655	1.310751	0.164135	1143.050171	0.000000	NaN	NaN
339.999447	0.000672	1.343862	0.164549	1143.456787	0.000000	NaN	NaN
341.000504	0.000539	1.078975	0.165168	1144.064575	0.000000	NaN	NaN
342.000561	0.000664	1.327307	0.165747	1144.633179	0.000000	NaN	NaN
342.999618	0.000631	1.261085	0.166366	1145.240845	0.000000	NaN	NaN
344.000676	0.000722	1.443195	0.166869	1145.734497	0.000000	NaN	NaN
345.000733	0.000647	1.294196	0.167586	1146.438599	0.000000	NaN	NaN
346.000790	0.000672	1.343862	0.168151	1146.993408	0.000000	NaN	NaN
346.999847	0.000672	1.343862	0.168655	1147.488159	0.000000	NaN	NaN
348.000904	0.000589	1.178308	0.169255	1148.077759	0.000000	NaN	NaN
348.999962	0.000697	1.393529	0.169834	1148.646362	0.000000	NaN	NaN
350.001019	0.000631	1.261085	0.170279	1149.082764	0.000000	NaN	NaN
351.001076	0.000664	1.327307	0.170856	1149.649658	0.000000	NaN	NaN
352.001133	0.000788	1.575638	0.171462	1150.244019	0.000000	NaN	NaN
353.001191	0.000631	1.261085	0.171993	1150.765747	0.000000	NaN	NaN
354.001248	0.000631	1.261085	0.172601	1151.363037	0.000000	NaN	NaN
355.001305	0.000730	1.459750	0.173263	1152.013184	0.000000	NaN	NaN
356.000362	0.000622	1.244530	0.173850	1152.588989	0.000000	NaN	NaN
356.999419	0.000639	1.277641	0.174378	1153.107910	0.000000	NaN	NaN
358.000476	0.000705	1.410084	0.174837	1153.558716	0.000000	NaN	NaN
359.000534	0.000581	1.161753	0.175504	1154.213379	0.000000	NaN	NaN
360.000591	0.000531	1.062420	0.176085	1154.783447	0.000000	NaN	NaN
361.000648	0.000548	1.095531	0.176628	1155.316650	0.000000	NaN	NaN
362.000705	0.000664	1.327307	0.177132	1155.811279	0.000000	NaN	NaN
363.000762	0.000639	1.277641	0.177779	1156.447388	0.000000	NaN	NaN
364.000820	0.000697	1.393529	0.178407	1157.064087	0.000000	NaN	NaN
365.000877	0.000564	1.128642	0.178931	1157.578613	0.000000	NaN	NaN
366.000934	0.000755	1.509417	0.179517	1158.153931	0.000000	NaN	NaN
367.000991	0.000655	1.310751	0.180146	1158.771484	0.000000	NaN	NaN
368.000048	0.000622	1.244530	0.180675	1159.290161	0.000000	NaN	NaN
369.001106	0.000655	1.310751	0.181171	1159.777954	0.000000	NaN	NaN
370.001163	0.000631	1.261085	0.181875	1160.468750	0.000000	NaN	NaN
371.001220	0.000755	1.509417	0.182424	1161.008057	0.000000	NaN	NaN
372.000277	0.000639	1.277641	-1.000000	0.000000	0.000000	NaN	NaN
373.000334	0.000688	1.376973	0.182262	1160.849243	0.000000	NaN	NaN
373.999392	0.000655	1.310751	0.182769	1161.346924	0.000000	NaN	NaN
375.000449	0.000655	1.310751	0.183383	1161.949463	0.000000	NaN	NaN
375.999506	0.000664	1.327307	0.183948	1162.504272	0.000000	NaN	NaN
377.000563	0.000688	1.376973	0.184436	1162.983276	0.000000	NaN	NaN
378.000620	0.000688	1.376973	0.185088	1163.623535	0.000000	NaN	NaN
379.000678	0.000722	1.443195	0.185691	1164.215332	0.000000	NaN	NaN
380.000735	0.000581	1.161753	0.186283	1164.796997	0.000000	NaN	NaN
381.000792	0.000564	1.128642	0.186841	1165.345215	0.000000	NaN	NaN
382.000849	0.000631	1.261085	0.187462	1165.954712	0.000000	NaN	NaN
383.000906	0.000655	1.310751	0.188066	1166.547729	0.000000	NaN	NaN
384.000964	0.000697	1.393529	0.188651	1167.121826	0.000000	NaN	NaN
385.001021	0.000672	1.343862	0.189136	1167.598633	0.000000	NaN	NaN
386.001078	0.000713	1.426639	0.189772	1168.222778	0.000000	NaN	NaN
387.000135	0.000639	1.277641	0.190413	1168.852173	0.000000	NaN	NaN
388.001192	0.000647	1.294196	0.190985	1169.413940	0.000000	NaN	NaN
389.000249	0.000688	1.376973	0.191602	1170.020142	0.000000	NaN	NaN
390.001307	0.000664	1.327307	0.192176	1170.583252	0.000000	NaN	NaN
391.000364	0.000606	1.211419	0.192735	1171.132446	0.000000	NaN	NaN
392.000421	0.000531	1.062420	0.193355	1171.740967	0.000000	NaN	NaN
392.999478	0.000697	1.393529	0.193934	1172.309082	0.000000	NaN	NaN
394.000536	0.000697	1.393529	0.194535	1172.899536	0.000000	NaN	NaN
394.999593	0.000399	0.797533	0.195064	1173.418823	0.000000	NaN	NaN
396.000650	0.000705	1.410084	0.195740	1174.082275	0.000000	NaN	NaN
396.999707	0.000539	1.078975	0.196314	1174.646118	0.000000	NaN	NaN
398.000764	0.000606	1.211419	0.196964	1175.284424	0.000000	NaN	NaN
398.999821	0.000664	1.327307	0.197566	1175.875977	0.000000	NaN	NaN
400.000879	0.000771	1.542527	0.198080	1176.380005	0.000000	NaN	NaN
401.000936	0.000680	1.360418	0.198730	1177.018555	0.000000	NaN	NaN
402.000993	0.000631	1.261085	0.199254	1177.533325	0.000000	NaN	NaN
403.000050	0.000606	1.211419	0.199859	1178.127441	0.000000	NaN	NaN
404.001107	0.000713	1.426639	0.200434	1178.691284	0.000000	NaN	NaN
405.001165	0.000713	1.426639	0.200899	1179.148193	0.000000	NaN	NaN
406.001222	0.000680	1.360418	0.201629	1179.864990	0.000000	NaN	NaN
407.001279	0.000738	1.476306	0.202191	1180.416626	0.000000	NaN	NaN
408.000336	0.000730	1.459750	0.202836	1181.050049	0.000000	NaN	NaN
408.999393	0.000622	1.244530	0.203383	1181.587646	0.000000	NaN	NaN
410.001451	0.000564	1.128642	0.203961	1182.155273	0.000000	NaN	NaN
411.000508	0.000589	1.178308	0.204594	1182.775879	0.000000	NaN	NaN
412.003565	0.000631	1.261085	0.205162	1183.334229	0.000000	NaN	NaN
413.000622	0.000680	1.360418	0.205709	1183.871582	0.000000	NaN	NaN
414.004680	0.000688	1.376973	0.206309	1184.460449	0.000000	NaN	NaN
415.000737	0.000688	1.376973	0.206985	1185.123901	0.000000	NaN	NaN
416.005794	0.000680	1.360418	0.207411	1185.542603	0.000000	NaN	NaN
416.999851	0.000581	1.161753	0.208054	1186.173584	0.000000	NaN	NaN
418.005908	0.000655	1.310751	0.208682	1186.789917	0.000000	NaN	NaN
419.000966	0.000688	1.376973	0.209234	1187.332764	0.000000	NaN	NaN
420.007023	0.000680	1.360418	0.209785	1187.873291	0.000000	NaN	NaN
421.001080	0.000713	1.426639	0.210321	1188.399536	0.000000	NaN	NaN
422.008137	0.000631	1.261085	0.210910	1188.978271	0.000000	NaN	NaN
423.000194	0.000713	1.426639	0.211472	1189.529419	0.000000	NaN	NaN
424.009252	0.000606	1.211419	0.212095	1190.140991	0.000000	NaN	NaN
425.000309	0.000804	1.608749	0.212664	1190.700195	0.000000	NaN	NaN
426.011366	0.000672	1.343862	0.213192	1191.218628	0.000000	NaN	NaN
427.000423	0.000614	1.227974	-1.000000	0.000000	0.000000	NaN	NaN
428.011481	0.000688	1.376973	0.214393	1192.397827	0.000000	NaN	NaN
428.999537	0.000738	1.476306	0.215032	1193.025269	0.000000	NaN	NaN
430.013595	0.000655	1.310751	0.215452	1193.437622	0.000000	NaN	NaN
431.000652	0.000730	1.459750	0.216015	1193.990601	0.000000	NaN	NaN
432.013710	0.000655	1.310751	0.216619	1194.583618	0.000000	NaN	NaN
432.999766	0.000573	1.145197	0.217245	1195.198364	0.000000	NaN	NaN
434.015824	0.000655	1.310751	0.217855	1195.796753	0.000000	NaN	NaN
435.000881	0.000614	1.227974	0.218408	1196.340332	0.000000	NaN	NaN
436.000938	0.000664	1.327307	0.218900	1196.822998	0.000000	NaN	NaN
436.999995	0.000672	1.343862	0.219460	1197.373413	0.000000	NaN	NaN
438.001052	0.000713	1.426639	0.220101	1198.002563	0.000000	NaN	NaN
439.001109	0.000697	1.393529	0.220652	1198.543945	0.000000	NaN	NaN
440.001167	0.000738	1.476306	0.221232	1199.112549	0.000000	NaN	NaN
441.000224	0.000688	1.376973	0.221812	1199.682373	0.000000	NaN	NaN
442.001281	0.000631	1.261085	0.222377	1200.237671	0.000000	NaN	NaN
442.999338	0.000763	1.525972	0.223001	1200.849976	0.000000	NaN	NaN
443.999395	0.000639	1.277641	0.223562	1201.401001	0.000000	NaN	NaN
444.999453	0.000746	1.492861	0.224054	1201.883423	0.000000	NaN	NaN
446.000510	0.000697	1.393529	0.224646	1202.465088	0.000000	NaN	NaN
447.000567	0.000722	1.443195	0.225273	1203.080322	0.000000	NaN	NaN
447.999624	0.000631	1.261085	0.225880	1203.677002	0.000000	NaN	NaN
448.999681	0.000688	1.376973	0.226389	1204.176514	0.000000	NaN	NaN
449.999738	0.000647	1.294196	0.226951	1204.728760	0.000000	NaN	NaN
451.000796	0.000622	1.244530	0.227567	1205.333252	0.000000	NaN	NaN
451.999853	0.000622	1.244530	0.228196	1205.950684	0.000000	NaN	NaN
453.000910	0.000796	1.592194	0.228749	1206.493774	0.000000	NaN	NaN
453.999967	0.000647	1.294196	0.229286	1207.020752	0.000000	NaN	NaN
455.001024	0.000688	1.376973	0.229920	1207.643311	0.000000	NaN	NaN
456.000082	0.000746	1.492861	0.230454	1208.168091	0.000000	NaN	NaN
457.000139	0.000556	1.112086	0.231092	1208.794800	0.000000	NaN	NaN
458.001196	0.000722	1.443195	0.231613	1209.306152	0.000000	NaN	NaN
459.001253	0.000581	1.161753	0.232146	1209.829346	0.000000	NaN	NaN
460.000311	0.000697	1.393529	0.232745	1210.417358	0.000000	NaN	NaN
461.000368	0.000688	1.376973	0.233379	1211.040283	0.000000	NaN	NaN
462.000425	0.000854	1.708082	0.233918	1211.569214	0.000000	NaN	NaN
463.000482	0.000581	1.161753	0.234480	1212.120850	0.000000	NaN	NaN
463.999539	0.000730	1.459750	0.235073	1212.703613	0.000000	NaN	NaN
465.000596	0.000813	1.625305	0.235641	1213.260620	0.000000	NaN	NaN
466.000654	0.000655	1.310751	0.236299	1213.907471	0.000000	NaN	NaN
467.000711	0.000705	1.410084	0.236830	1214.428467	0.000000	NaN	NaN
467.999768	0.000664	1.327307	0.237406	1214.994141	0.000000	NaN	NaN
469.000825	0.000821	1.641860	0.237974	1215.551758	0.000000	NaN	NaN
470.000882	0.000655	1.310751	0.238523	1216.090698	0.000000	NaN	NaN
471.000940	0.000771	1.542527	0.239171	1216.726685	0.000000	NaN	NaN
472.000997	0.000688	1.376973	0.239766	1217.310913	0.000000	NaN	NaN
473.001054	0.000606	1.211419	0.240388	1217.922119	0.000000	NaN	NaN
474.001111	0.000639	1.277641	0.240927	1218.451660	0.000000	NaN	NaN
475.000168	0.000746	1.492861	0.241503	1219.016602	0.000000	NaN	NaN
476.001226	0.000796	1.592194	0.242103	1219.605713	0.000000	NaN	NaN
477.000283	0.000730	1.459750	0.242720	1220.212280	0.000000	NaN	NaN
478.000340	0.000664	1.327307	0.243323	1220.803467	0.000000	NaN	NaN
478.999397	0.000697	1.393529	0.243912	1221.381958	0.000000	NaN	NaN
480.000454	0.000738	1.476306	0.244516	1221.975708	0.000000	NaN	NaN
480.999512	0.000664	1.327307	0.245052	1222.501465	0.000000	NaN	NaN
482.000569	0.000647	1.294196	0.245685	1223.122803	0.000000	NaN	NaN
482.999626	0.000614	1.227974	0.246154	1223.583984	0.000000	NaN	NaN
484.000683	0.000713	1.426639	0.246867	1224.283447	0.000000	NaN	NaN
484.999740	0.000722	1.443195	0.247414	1224.820801	0.000000	NaN	NaN
486.000798	0.000738	1.476306	0.247954	1225.351074	0.000000	NaN	NaN
486.999855	0.000722	1.443195	0.248554	1225.939941	0.000000	NaN	NaN
488.000912	0.000697	1.393529	0.249157	1226.532593	0.000000	NaN	NaN
489.000969	0.000730	1.459750	0.249778	1227.142090	0.000000	NaN	NaN
490.000026	0.000746	1.492861	0.250320	1227.673950	0.000000	NaN	NaN
491.000084	0.000746	1.492861	0.250887	1228.230957	0.000000	NaN	NaN
492.000141	0.000680	1.360418	0.251410	1228.744629	0.000000	NaN	NaN
493.001198	0.000614	1.227974	0.252021	1229.344482	0.000000	NaN	NaN
494.000255	0.000680	1.360418	0.252681	1229.992676	0.000000	NaN	NaN
495.001312	0.000788	1.575638	0.253100	1230.403809	0.000000	NaN	NaN
495.999369	0.000730	1.459750	0.253736	1231.027954	0.000000	NaN	NaN
497.000427	0.000780	1.559083	0.254277	1231.559326	0.000000	NaN	NaN
497.999484	0.000606	1.211419	0.254994	1232.263916	0.000000	NaN	NaN
498.999541	0.000763	1.525972	0.255555	1232.814697	0.000000	NaN	NaN
499.999598	0.000722	1.443195	0.256120	1233.369019	0.000000	NaN	NaN
501.000656	0.000688	1.376973	0.256631	1233.871338	0.000000	NaN	NaN
501.999713	0.000672	1.343862	0.257153	1234.383179	0.000000	NaN	NaN
502.999770	0.000763	1.525972	0.257800	1235.018677	0.000000	NaN	NaN
503.999827	0.000722	1.443195	0.258439	1235.645630	0.000000	NaN	NaN
505.000884	0.000614	1.227974	0.258872	1236.071533	0.000000	NaN	NaN
505.999941	0.000688	1.376973	0.259495	1236.683105	0.000000	NaN	NaN
507.000999	0.000755	1.509417	0.260044	1237.221802	0.000000	NaN	NaN
508.001056	0.000722	1.443195	0.260628	1237.795532	0.000000	NaN	NaN
509.001113	0.000655	1.310751	0.261263	1238.418579	0.000000	NaN	NaN
510.000170	0.000730	1.459750	0.261893	1239.037476	0.000000	NaN	NaN
511.001228	0.000597	1.194863	0.262339	1239.474976	0.000000	NaN	NaN
512.001285	0.000523	1.045865	0.262993	1240.117676	0.000000	NaN	NaN
513.000342	0.000713	1.426639	0.263600	1240.713501	0.000000	NaN	NaN
513.999399	0.000688	1.376973	0.264120	1241.223877	0.000000	NaN	NaN
514.999456	0.000639	1.277641	0.264702	1241.796021	0.000000	NaN	NaN
515.999514	0.000705	1.410084	0.265192	1242.276489	0.000000	NaN	NaN
516.999571	0.000697	1.393529	0.265846	1242.919067	0.000000	NaN	NaN
518.000628	0.000664	1.327307	0.266407	1243.469971	0.000000	NaN	NaN
518.999685	0.000763	1.525972	0.266891	1243.944946	0.000000	NaN	NaN
520.000742	0.000713	1.426639	0.267495	1244.538452	0.000000	NaN	NaN
520.999799	0.000730	1.459750	0.268081	1245.113403	0.000000	NaN	NaN
522.000857	0.000697	1.393529	0.268697	1245.718506	0.000000	NaN	NaN
522.999914	0.000730	1.459750	-1.000000	0.000000	0.000000	NaN	NaN
524.000971	0.000705	1.410084	0.269970	1246.968506	0.000000	NaN	NaN
525.000028	0.000804	1.608749	0.270512	1247.500122	0.000000	NaN	NaN
526.001086	0.000763	1.525972	0.271115	1248.092041	0.000000	NaN	NaN
527.001143	0.000680	1.360418	0.271672	1248.639282	0.000000	NaN	NaN
528.001200	0.000688	1.376973	0.272271	1249.227295	0.000000	NaN	NaN
529.000257	0.000763	1.525972	0.272844	1249.790649	0.000000	NaN	NaN
530.000314	0.000713	1.426639	0.273404	1250.339600	0.000000	NaN	NaN
531.000372	0.000763	1.525972	0.274092	1251.015869	0.000000	NaN	NaN
532.000429	0.000730	1.459750	0.274559	1251.473877	0.000000	NaN	NaN
532.999486	0.000639	1.277641	0.275174	1252.077881	0.000000	NaN	NaN
534.000543	0.000738	1.476306	0.275746	1252.639282	0.000000	NaN	NaN
535.000600	0.000589	1.178308	0.276321	1253.204224	0.000000	NaN	NaN
536.000657	0.000746	1.492861	0.276876	1253.749268	0.000000	NaN	NaN
536.999715	0.000672	1.343862	0.277496	1254.357666	0.000000	NaN	NaN
537.999772	0.000655	1.310751	0.277962	1254.815063	0.000000	NaN	NaN
539.000829	0.000631	1.261085	0.278629	1255.470581	0.000000	NaN	NaN
539.999886	0.000697	1.393529	0.279254	1256.083984	0.000000	NaN	NaN
541.000943	0.000763	1.525972	0.279850	1256.669556	0.000000	NaN	NaN
542.000001	0.000688	1.376973	0.280415	1257.224243	0.000000	NaN	NaN
543.001058	0.000697	1.393529	0.280955	1257.754639	0.000000	NaN	NaN
544.000115	0.000730	1.459750	0.281597	1258.385132	0.000000	NaN	NaN
545.001172	0.000697	1.393529	0.282269	1259.044434	0.000000	NaN	NaN
546.001230	0.000722	1.443195	0.282770	1259.536255	0.000000	NaN	NaN
547.001287	0.000713	1.426639	0.283406	1260.161255	0.000000	NaN	NaN
547.999344	0.000631	1.261085	0.283855	1260.601440	0.000000	NaN	NaN
549.000401	0.000655	1.310751	0.284588	1261.321533	0.000000	NaN	NaN
549.999458	0.000655	1.310751	0.285232	1261.953369	0.000000	NaN	NaN
551.000515	0.000746	1.492861	0.285750	1262.462402	0.000000	NaN	NaN
551.999572	0.000622	1.244530	0.286266	1262.969238	0.000000	NaN	NaN
552.999630	0.000763	1.525972	0.286940	1263.630493	0.000000	NaN	NaN
554.000687	0.000788	1.575638	0.287519	1264.199463	0.000000	NaN	NaN
554.999744	0.000573	1.145197	0.288020	1264.690796	0.000000	NaN	NaN
556.000801	0.000647	1.294196	0.288741	1265.399658	0.000000	NaN	NaN
557.000859	0.000664	1.327307	0.289182	1265.832031	0.000000	NaN	NaN
557.999916	0.000763	1.525972	0.289821	1266.459595	0.000000	NaN	NaN
559.000973	0.000680	1.360418	0.290463	1267.089722	0.000000	NaN	NaN
560.001030	0.000796	1.592194	0.291030	1267.647217	0.000000	NaN	NaN
561.001087	0.000523	1.045865	0.291607	1268.213135	0.000000	NaN	NaN
562.001145	0.000631	1.261085	0.292203	1268.798340	0.000000	NaN	NaN
563.001202	0.000606	1.211419	0.292887	1269.469971	0.000000	NaN	NaN
564.001259	0.000606	1.211419	0.293418	1269.991211	0.000000	NaN	NaN
565.000316	0.000705	1.410084	0.294105	1270.666260	0.000000	NaN	NaN
566.000373	0.000854	1.708082	0.294644	1271.195679	0.000000	NaN	NaN
566.999431	0.000763	1.525972	0.295200	1271.741211	0.000000	NaN	NaN
568.000488	0.000688	1.376973	0.295850	1272.379883	0.000000	NaN	NaN
568.999545	0.000647	1.294196	0.296503	1273.020752	0.000000	NaN	NaN
570.000602	0.000655	1.310751	0.297073	1273.579956	0.000000	NaN	NaN
570.999659	0.000821	1.641860	0.297691	1274.186646	0.000000	NaN	NaN
572.000716	0.000697	1.393529	0.298241	1274.727417	0.000000	NaN	NaN
573.000774	0.000697	1.393529	0.299011	1275.482910	0.000000	NaN	NaN
574.000831	0.000647	1.294196	0.299552	1276.014893	0.000000	NaN	NaN
574.999888	0.000755	1.509417	0.300107	1276.558960	0.000000	NaN	NaN
576.000945	0.000738	1.476306	0.300748	1277.188599	0.000000	NaN	NaN
577.001003	0.000688	1.376973	0.301332	1277.761841	0.000000	NaN	NaN
578.001060	0.000705	1.410084	0.302032	1278.449097	0.000000	NaN	NaN
579.001117	0.000705	1.410084	0.302587	1278.994507	0.000000	NaN	NaN
580.001174	0.000763	1.525972	0.303197	1279.593750	0.000000	NaN	NaN
581.001231	0.000647	1.294196	0.303855	1280.239136	0.000000	NaN	NaN
582.000289	0.000622	1.244530	0.304522	1280.894287	0.000000	NaN	NaN
583.000346	0.000664	1.327307	0.305116	1281.477783	0.000000	NaN	NaN
584.000403	0.000713	1.426639	0.305766	1282.115479	0.000000	NaN	NaN
585.000460	0.000647	1.294196	0.306322	1282.661499	0.000000	NaN	NaN
585.999517	0.000688	1.376973	0.307076	1283.401855	0.000000	NaN	NaN
587.000574	0.000664	1.327307	0.307640	1283.955811	0.000000	NaN	NaN
587.999632	0.000705	1.410084	0.308195	1284.500610	0.000000	NaN	NaN
589.000689	0.000614	1.227974	0.308816	1285.110596	0.000000	NaN	NaN
589.999746	0.000713	1.426639	0.309408	1285.691895	0.000000	NaN	NaN
591.000803	0.000713	1.426639	0.310095	1286.366455	0.000000	NaN	NaN
592.000861	0.000680	1.360418	0.310672	1286.932739	0.000000	NaN	NaN
593.000918	0.000672	1.343862	0.311344	1287.592651	0.000000	NaN	NaN
593.999975	0.000730	1.459750	0.311926	1288.164185	0.000000	NaN	NaN
595.001032	0.000622	1.244530	0.312600	1288.826050	0.000000	NaN	NaN
596.001089	0.000796	1.592194	0.313190	1289.405396	0.000000	NaN	NaN
597.001147	0.000688	1.376973	0.313822	1290.025757	0.000000	NaN	NaN
598.001204	0.000722	1.443195	0.314378	1290.571533	0.000000	NaN	NaN
599.001261	0.000796	1.592194	0.315043	1291.225098	0.000000	NaN	NaN
600.001318	0.000688	1.376973	0.315680	1291.850098	0.000000	NaN	NaN
601.000375	0.000730	1.459750	0.316266	1292.425537	0.000000	NaN	NaN
602.000432	0.000531	1.062420	0.316928	1293.075439	0.000000	NaN	NaN
603.000490	0.000622	1.244530	0.317660	1293.794312	0.000000	NaN	NaN
603.999547	0.000672	1.343862	0.318245	1294.368408	0.000000	NaN	NaN
604.999604	0.000688	1.376973	0.318905	1295.017090	0.000000	NaN	NaN
606.000661	0.000614	1.227974	0.319528	1295.628662	0.000000	NaN	NaN
606.999718	0.000722	1.443195	0.320168	1296.257324	0.000000	NaN	NaN
608.000776	0.000780	1.559083	0.320791	1296.868530	0.000000	NaN	NaN
608.999833	0.000780	1.559083	0.321413	1297.479492	0.000000	NaN	NaN
610.000890	0.000796	1.592194	0.322064	1298.118286	0.000000	NaN	NaN
611.000947	0.000746	1.492861	0.322632	1298.676392	0.000000	NaN	NaN
612.001004	0.000680	1.360418	0.323266	1299.298462	0.000000	NaN	NaN
613.000062	0.000738	1.476306	0.323961	1299.980835	0.000000	NaN	NaN
614.001119	0.000631	1.261085	0.324677	1300.683960	0.000000	NaN	NaN
615.001176	0.000664	1.327307	0.325275	1301.271729	0.000000	NaN	NaN
616.001233	0.000664	1.327307	0.325896	1301.880859	0.000000	NaN	NaN
617.000290	0.000713	1.426639	0.326538	1302.511597	0.000000	NaN	NaN
618.000348	0.000664	1.327307	0.327142	1303.104980	0.000000	NaN	NaN
619.000405	0.000746	1.492861	0.327839	1303.789185	0.000000	NaN	NaN
620.000462	0.000523	1.045865	0.328509	1304.447021	0.000000	NaN	NaN
621.000519	0.000664	1.327307	0.329151	1305.077515	0.000000	NaN	NaN
622.000576	0.000672	1.343862	0.329697	1305.613892	0.000000	NaN	NaN
623.000634	0.000631	1.261085	0.330352	1306.256348	0.000000	NaN	NaN
623.999691	0.000722	1.443195	0.331101	1306.991821	0.000000	NaN	NaN
625.000748	0.000688	1.376973	0.331704	1307.583740	0.000000	NaN	NaN
626.000805	0.000722	1.443195	0.332358	1308.226196	0.000000	NaN	NaN
627.000862	0.000713	1.426639	0.332904	1308.762085	0.000000	NaN	NaN
627.999920	0.000639	1.277641	0.333570	1309.416382	0.000000	NaN	NaN
629.000977	0.000639	1.277641	0.334305	1310.138062	0.000000	NaN	NaN
630.000034	0.000622	1.244530	0.334916	1310.738159	0.000000	NaN	NaN
631.001091	0.000680	1.360418	0.335602	1311.411255	0.000000	NaN	NaN
632.000148	0.000606	1.211419	0.336246	1312.043457	0.000000	NaN	NaN
633.001206	0.000722	1.443195	0.336895	1312.680908	0.000000	NaN	NaN
634.001263	0.000705	1.410084	0.337624	1313.396606	0.000000	NaN	NaN
635.001320	0.000614	1.227974	0.338265	1314.026245	0.000000	NaN	NaN
635.999377	0.000738	1.476306	0.338798	1314.550049	0.000000	NaN	NaN
637.000434	0.000755	1.509417	0.339364	1315.105469	0.000000	NaN	NaN
637.999491	0.000597	1.194863	0.340123	1315.850342	0.000000	NaN	NaN
639.000549	0.000730	1.459750	0.340826	1316.540405	0.000000	NaN	NaN
639.999606	0.000713	1.426639	0.341480	1317.183228	0.000000	NaN	NaN
641.000663	0.000664	1.327307	0.342124	1317.815308	0.000000	NaN	NaN
642.000720	0.000622	1.244530	0.342845	1318.523193	0.000000	NaN	NaN
642.999778	0.000763	1.525972	0.343467	1319.133789	0.000000	NaN	NaN
643.999835	0.000664	1.327307	0.344176	1319.830444	0.000000	NaN	NaN
645.000892	0.000639	1.277641	0.344774	1320.417236	0.000000	NaN	NaN
646.000949	0.000697	1.393529	0.345489	1321.119507	0.000000	NaN	NaN
647.000006	0.000664	1.327307	0.346117	1321.735718	0.000000	NaN	NaN
648.001063	0.000862	1.724637	0.346850	1322.456055	0.000000	NaN	NaN
649.000121	0.000606	1.211419	0.347544	1323.137207	0.000000	NaN	NaN
650.001178	0.000597	1.194863	0.348168	1323.750244	0.000000	NaN	NaN
651.000235	0.000664	1.327307	0.348846	1324.415405	0.000000	NaN	NaN
652.001292	0.000606	1.211419	0.349495	1325.052979	0.000000	NaN	NaN
653.000349	0.000697	1.393529	0.350169	1325.714722	0.000000	NaN	NaN
653.999407	0.000763	1.525972	0.350803	1326.337524	0.000000	NaN	NaN
654.999464	0.000738	1.476306	0.351517	1327.038330	0.000000	NaN	NaN
655.999521	0.000589	1.178308	0.352275	1327.782349	0.000000	NaN	NaN
656.999578	0.000705	1.410084	0.352946	1328.441406	0.000000	NaN	NaN
657.999635	0.000763	1.525972	0.353681	1329.162842	0.000000	NaN	NaN
658.999693	0.000589	1.178308	0.354351	1329.820435	0.000000	NaN	NaN
660.000750	0.000622	1.244530	0.354973	1330.431274	0.000000	NaN	NaN
661.000807	0.000506	1.012754	0.355762	1331.206543	0.000000	NaN	NaN
661.999864	0.000589	1.178308	0.356491	1331.922607	0.000000	NaN	NaN
662.999921	0.000664	1.327307	0.357208	1332.625732	0.000000	NaN	NaN
664.000979	0.000655	1.310751	0.357838	1333.244751	0.000000	NaN	NaN
665.001036	0.000697	1.393529	0.358582	1333.974976	0.000000	NaN	NaN
666.000093	0.000548	1.095531	0.359320	1334.700073	0.000000	NaN	NaN
667.000150	0.000655	1.310751	0.360029	1335.396118	0.000000	NaN	NaN
668.001207	0.000531	1.062420	0.360613	1335.969482	0.000000	NaN	NaN
669.001265	0.000746	1.492861	0.361298	1336.642456	0.000000	NaN	NaN
669.999322	0.000730	1.459750	0.362110	1337.439697	0.000000	NaN	NaN
671.000379	0.000664	1.327307	0.362777	1338.094238	0.000000	NaN	NaN
671.999436	0.000614	1.227974	0.363563	1338.866089	0.000000	NaN	NaN
673.000493	0.000672	1.343862	0.364177	1339.468506	0.000000	NaN	NaN
673.999551	0.000539	1.078975	0.364935	1340.213013	0.000000	NaN	NaN
675.000608	0.000581	1.161753	0.365711	1340.975586	0.000000	NaN	NaN
676.000665	0.000647	1.294196	0.366483	1341.733521	0.000000	NaN	NaN
677.000722	0.000631	1.261085	0.367209	1342.445679	0.000000	NaN	NaN
677.999779	0.000581	1.161753	0.367943	1343.166382	0.000000	NaN	NaN
679.000837	0.000730	1.459750	0.368765	1343.974243	0.000000	NaN	NaN
680.000894	0.000639	1.277641	0.369482	1344.677612	0.000000	NaN	NaN
681.000951	0.000597	1.194863	0.370243	1345.425049	0.000000	NaN	NaN
682.001008	0.000581	1.161753	0.370937	1346.106812	0.000000	NaN	NaN
683.001065	0.000697	1.393529	0.371759	1346.913208	0.000000	NaN	NaN
684.001123	0.000597	1.194863	0.372584	1347.723145	0.000000	NaN	NaN
685.001180	0.000606	1.211419	0.373303	1348.429321	0.000000	NaN	NaN
686.001237	0.000564	1.128642	0.374046	1349.159546	0.000000	NaN	NaN
687.001294	0.000606	1.211419	0.374849	1349.947266	0.000000	NaN	NaN
688.000351	0.000614	1.227974	0.375606	1350.690918	0.000000	NaN	NaN
689.000409	0.000573	1.145197	0.376531	1351.599487	0.000000	NaN	NaN
689.999466	0.000631	1.261085	0.377354	1352.406982	0.000000	NaN	NaN
691.000523	0.000647	1.294196	0.378070	1353.110474	0.000000	NaN	NaN
692.000580	0.000556	1.112086	0.378873	1353.898804	0.000000	NaN	NaN
692.999637	0.000581	1.161753	0.379765	1354.774536	0.000000	NaN	NaN
694.000695	0.000614	1.227974	0.380692	1355.685059	0.000000	NaN	NaN
695.000752	0.000581	1.161753	0.381564	1356.541016	0.000000	NaN	NaN
696.000809	0.000506	1.012754	0.382397	1357.359253	0.000000	NaN	NaN
697.000866	0.000581	1.161753	0.383216	1358.162720	0.000000	NaN	NaN
697.999923	0.000465	0.929977	0.384392	1359.317749	0.000000	NaN	NaN
699.000980	0.000515	1.029309	0.385297	1360.206299	0.000000	NaN	NaN
700.001038	0.000548	1.095531	0.386404	1361.293701	0.000000	NaN	NaN
701.001095	0.000606	1.211419	0.387468	1362.338501	0.000000	NaN	NaN
702.001152	0.000415	0.830644	0.389247	1364.084595	0.000000	NaN	NaN
703.001209	0.000374	0.747867	0.390892	1365.699829	0.000000	NaN	NaN
704.001267	0.000432	0.863755	-1.000000	0.000000	0.000000	NaN	NaN
705.000324	0.000407	0.814089	0.394703	1369.442383	0.000000	NaN	NaN
706.000381	0.000316	0.631979	0.396373	1371.082031	0.000000	NaN	NaN
707.000438	0.000333	0.665090	0.398332	1373.005615	0.000000	NaN	NaN
708.000495	0.000250	0.499535	0.400199	1374.838379	0.000000	NaN	NaN
709.000553	0.000382	0.764422	0.402161	1376.765137	0.000000	NaN	NaN
710.000610	0.000159	0.317426	0.404579	1379.139282	0.000000	NaN	NaN
711.000667	-6.841446E-6	-0.013683	0.408534	1383.022339	0.000000	NaN	NaN
712.000724	-0.000114	-0.228903	0.426268	1400.434937	0.000000	NaN	NaN
713.000781	-0.000114	-0.228903	0.434262	1408.284912	0.000000	NaN	NaN
714.000838	-0.000139	-0.278570	0.438485	1412.430908	0.000000	NaN	NaN
715.000896	-4.823002E-5	-0.096460	0.441627	1415.516235	0.000000	NaN	NaN
715.999953	-0.000214	-0.427569	0.444360	1418.199951	0.000000	NaN	NaN
717.001010	-0.000131	-0.262014	0.446591	1420.389893	0.000000	NaN	NaN
718.000067	-0.000164	-0.328236	0.448382	1422.148926	0.000000	NaN	NaN
719.001124	-6.841446E-6	-0.013683	0.450220	1423.953857	0.000000	NaN	NaN
719.501153	-7.306316E-5	-0.146126	0.451134	1424.850952	0.000000	NaN	NaN