File: data/9k_1-1_2 (181102).lvm
LabVIEW Measurement
Writer_Version	2
Reader_Version	2
Separator	Tab
Decimal_Separator	.
Multi_Headings	No
X_Columns	One
Time_Pref	Absolute
Operator	user
Description	Load(N)/Stress(MPa)/Distance A(pixel)/Strain A/Distance B(pixel)/Strain B/Poisson's ratio
Date	2018/11/02
Time	13:39:46.3050932884216308594
***End_of_Header***

Notes	X 값은 오직 다음과 같을 때에만 유효함이 보장됩니다. Dev1/ai0
Channels	7
Samples	1	1	1	1	1	1	1
Date	2018/11/02	2018/11/02	2018/11/02	2018/11/02	2018/11/02	2018/11/02	2018/11/02
Time	13:39:46.3050933300349950558	13:39:46.3050933300349950558	13:39:46.3050932884216308594	13:39:46.3050932884216308594	13:39:46.3050932884216308594	13:39:46.3050932884216308594	13:39:46.3050932884216308594
Y_Unit_Label	Volts	Volts
X_Dimension	Time	Time	Time	Time	Time	Time	Time
X0	0.0000000000000000E+0	0.0000000000000000E+0	0.0000000000000000E+0	0.0000000000000000E+0	0.0000000000000000E+0	0.0000000000000000E+0	0.0000000000000000E+0
Delta_X	0.000000	0.000000	1.000000	1.000000	1.000000	1.000000	1.000000
***End_of_Header***
X_Value	Dev1/ai0	Dev1/ai0 1	Untitled	Untitled 1	Untitled 2	Untitled 3	Untitled 4	Comment
0.000000	1.436269E-6	0.014363	-1.317263E-5	972.008179	0.000000	NaN	NaN
1.000057	-8.134088E-5	-0.813409	8.344650E-6	972.029114	0.000000	NaN	NaN
2.000114	-5.650773E-5	-0.565077	7.736683E-5	972.096191	0.000000	NaN	NaN
2.999172	-6.841446E-6	-0.068414	5.483627E-5	972.074341	0.000000	NaN	NaN
3.999229	-7.306316E-5	-0.730632	0.000286	972.298706	0.000000	NaN	NaN
4.999286	-5.650773E-5	-0.565077	0.000538	972.544006	0.000000	NaN	NaN
5.998343	5.938027E-5	0.593803	0.000976	972.969910	0.000000	NaN	NaN
6.999400	3.454713E-5	0.345471	0.001267	973.252258	0.000000	NaN	NaN
7.998458	0.000167	1.669906	0.001496	973.475281	0.000000	NaN	NaN
8.999515	6.765799E-5	0.676580	0.001837	973.806335	0.000000	NaN	NaN
9.999572	0.000150	1.504351	0.002040	974.004028	0.000000	NaN	NaN
10.999629	0.000117	1.173243	0.002504	974.455200	0.000000	NaN	NaN
11.998686	0.000101	1.007688	0.002771	974.714661	0.000000	NaN	NaN
12.999744	0.000101	1.007688	0.003104	975.038086	0.000000	NaN	NaN
13.999801	4.282484E-5	0.428248	0.003301	975.229980	0.000000	NaN	NaN
14.999858	0.000109	1.090466	0.003597	975.517273	0.000000	NaN	NaN
15.999915	0.000117	1.173243	0.004060	975.967468	0.000000	NaN	NaN
16.999972	0.000308	3.077117	0.004160	976.065002	0.000000	NaN	NaN
18.000030	0.000184	1.835460	0.004431	976.327515	0.000000	NaN	NaN
19.000087	0.000126	1.256020	0.004745	976.633179	0.000000	NaN	NaN
19.999144	0.000291	2.911563	0.004906	976.789978	0.000000	NaN	NaN
20.999201	0.000341	3.408226	0.005121	976.998657	0.000000	NaN	NaN
21.998258	0.000167	1.669906	0.005354	977.224976	0.000000	NaN	NaN
22.999316	0.000200	2.001014	0.005719	977.579773	0.000000	NaN	NaN
23.999373	0.000283	2.828786	0.005977	977.830933	0.000000	NaN	NaN
24.998430	0.000283	2.828786	0.006141	977.990234	0.000000	NaN	NaN
25.999487	0.000250	2.497677	0.006358	978.200928	0.000000	NaN	NaN
26.998544	0.000258	2.580454	0.006500	978.339050	0.000000	NaN	NaN
27.999602	0.000291	2.911563	0.006948	978.774353	0.000000	NaN	NaN
28.998659	0.000415	4.153220	0.007102	978.923950	0.000000	NaN	NaN
29.998716	0.000399	3.987666	0.007424	979.236816	0.000000	NaN	NaN
30.998773	0.000225	2.249346	0.007629	979.436279	0.000000	NaN	NaN
31.999830	0.000308	3.077117	0.007782	979.585388	0.000000	NaN	NaN
32.999887	0.000333	3.325449	0.007915	979.714355	0.000000	NaN	NaN
33.999945	0.000357	3.573780	0.008518	980.301086	0.000000	NaN	NaN
34.999002	0.000357	3.573780	0.008670	980.448669	0.000000	NaN	NaN
36.000059	0.000349	3.491003	0.008839	980.613159	0.000000	NaN	NaN
37.000116	0.000432	4.318774	0.009174	980.937988	0.000000	NaN	NaN
37.999173	0.000349	3.491003	0.009313	981.073120	0.000000	NaN	NaN
38.998230	0.000465	4.649883	0.009610	981.361816	0.000000	NaN	NaN
39.999288	0.000531	5.312100	0.009839	981.584778	0.000000	NaN	NaN
40.999345	0.000523	5.229323	0.010154	981.890442	0.000000	NaN	NaN
41.999402	0.000573	5.725986	0.010583	982.308167	0.000000	NaN	NaN
42.999459	0.000523	5.229323	0.010798	982.516602	0.000000	NaN	NaN
43.999517	0.000448	4.484329	0.011013	982.726196	0.000000	NaN	NaN
44.999574	0.000407	4.070443	0.011191	982.899231	0.000000	NaN	NaN
45.999631	0.000515	5.146546	0.011378	983.080261	0.000000	NaN	NaN
46.999688	0.000564	5.643209	0.011753	983.445496	0.000000	NaN	NaN
47.999745	0.000473	4.732660	0.012150	983.831299	0.000000	NaN	NaN
48.999803	0.000639	6.388203	0.012563	984.232910	0.000000	NaN	NaN
49.999860	0.000539	5.394877	0.012720	984.385559	0.000000	NaN	NaN
50.999917	0.000531	5.312100	0.012967	984.625000	0.000000	NaN	NaN
51.999974	0.000482	4.815437	0.013207	984.858521	0.000000	NaN	NaN
53.000031	0.000556	5.560431	0.013709	985.346558	0.000000	NaN	NaN
53.999088	0.000738	7.381529	0.013851	985.484375	0.000000	NaN	NaN
54.999146	0.000788	7.878191	0.014205	985.828247	0.000000	NaN	NaN
55.999203	0.000597	5.974317	0.014552	986.165649	0.000000	NaN	NaN
56.999260	0.000531	5.312100	0.014911	986.514771	0.000000	NaN	NaN
57.999317	0.000515	5.146546	0.015160	986.756409	0.000000	NaN	NaN
58.998375	0.000564	5.643209	0.015437	987.025757	0.000000	NaN	NaN
59.999432	0.000631	6.305426	0.015749	987.329651	0.000000	NaN	NaN
60.999489	0.000606	6.057094	0.016109	987.678955	0.000000	NaN	NaN
61.999546	0.000672	6.719311	0.016366	987.928894	0.000000	NaN	NaN
62.998603	0.000606	6.057094	0.016755	988.307556	0.000000	NaN	NaN
63.998660	0.000705	7.050420	0.017124	988.666138	0.000000	NaN	NaN
64.999718	0.000672	6.719311	0.017372	988.906799	0.000000	NaN	NaN
65.998775	0.000622	6.222649	0.017841	989.362976	0.000000	NaN	NaN
66.999832	0.000697	6.967643	0.018090	989.604370	0.000000	NaN	NaN
67.999889	0.000680	6.802089	0.018422	989.927856	0.000000	NaN	NaN
68.999946	0.000688	6.884866	0.018825	990.319336	0.000000	NaN	NaN
70.000004	0.000680	6.802089	0.019255	990.737244	0.000000	NaN	NaN
71.000061	0.000821	8.209300	0.019632	991.103333	0.000000	NaN	NaN
72.000118	0.000796	7.960969	0.019904	991.368286	0.000000	NaN	NaN
72.999175	0.000722	7.215974	0.020266	991.720154	0.000000	NaN	NaN
73.999233	0.000705	7.050420	0.020705	992.146484	0.000000	NaN	NaN
74.999290	0.000688	6.884866	0.021128	992.557922	0.000000	NaN	NaN
75.999347	0.000622	6.222649	0.021478	992.898376	0.000000	NaN	NaN
76.998404	0.000688	6.884866	0.021881	993.289490	0.000000	NaN	NaN
77.999461	0.000746	7.464306	0.022336	993.731934	0.000000	NaN	NaN
78.999518	0.000738	7.381529	0.022721	994.106262	0.000000	NaN	NaN
79.999576	0.000672	6.719311	0.023027	994.404114	0.000000	NaN	NaN
80.999633	0.000738	7.381529	0.023372	994.738647	0.000000	NaN	NaN
81.999690	0.000722	7.215974	0.024127	995.473083	0.000000	NaN	NaN
82.999747	0.000705	7.050420	0.024396	995.734741	0.000000	NaN	NaN
83.999804	0.000846	8.457631	0.024683	996.013000	0.000000	NaN	NaN
84.999862	0.000730	7.298751	0.025346	996.657532	0.000000	NaN	NaN
85.999919	0.000846	8.457631	0.025726	997.027039	0.000000	NaN	NaN
86.999976	0.000738	7.381529	0.026141	997.430908	0.000000	NaN	NaN
87.999033	0.000920	9.202626	0.026661	997.936035	0.000000	NaN	NaN
89.000090	0.000655	6.553757	0.027134	998.395752	0.000000	NaN	NaN
89.998148	0.000804	8.043746	0.027566	998.815979	0.000000	NaN	NaN
90.999205	0.000755	7.547083	0.028078	999.313538	0.000000	NaN	NaN
91.999262	0.000804	8.043746	0.028589	999.810120	0.000000	NaN	NaN
92.999319	0.000829	8.292077	0.029124	1000.330322	0.000000	NaN	NaN
93.998376	0.000804	8.043746	0.029572	1000.765686	0.000000	NaN	NaN
94.999434	0.000796	7.960969	0.029972	1001.154053	0.000000	NaN	NaN
95.999491	0.000622	6.222649	0.030515	1001.682495	0.000000	NaN	NaN
96.999548	0.000788	7.878191	0.030896	1002.052490	0.000000	NaN	NaN
97.998605	0.000697	6.967643	0.031383	1002.526184	0.000000	NaN	NaN
98.998662	0.000854	8.540409	0.031808	1002.938843	0.000000	NaN	NaN
99.998720	0.000763	7.629860	0.032504	1003.615906	0.000000	NaN	NaN
100.998777	0.000796	7.960969	0.032897	1003.997437	0.000000	NaN	NaN
101.998834	0.000879	8.788740	0.033311	1004.399902	0.000000	NaN	NaN
102.998891	0.000846	8.457631	0.033801	1004.876465	0.000000	NaN	NaN
103.999948	0.000738	7.381529	0.034275	1005.337341	0.000000	NaN	NaN
105.000006	0.000755	7.547083	0.034935	1005.978760	0.000000	NaN	NaN
106.000063	0.000780	7.795414	0.035309	1006.341797	0.000000	NaN	NaN
107.000120	0.000829	8.292077	0.036034	1007.046997	0.000000	NaN	NaN
107.999177	0.000821	8.209300	0.036627	1007.623596	0.000000	NaN	NaN
108.999234	0.000871	8.705963	0.037048	1008.032104	0.000000	NaN	NaN
109.999292	0.000763	7.629860	0.037559	1008.529480	0.000000	NaN	NaN
110.999349	0.000746	7.464306	0.037921	1008.881470	0.000000	NaN	NaN
111.999406	0.000895	8.954294	0.038534	1009.476807	0.000000	NaN	NaN
112.999463	0.000846	8.457631	0.039015	1009.944214	0.000000	NaN	NaN
113.999520	0.000904	9.037071	0.039332	1010.252380	0.000000	NaN	NaN
114.998577	0.000879	8.788740	0.038717	1009.654419	0.000000	NaN	NaN
115.998635	0.000821	8.209300	0.039204	1010.128540	0.000000	NaN	NaN
116.998692	0.000854	8.540409	0.039788	1010.695984	0.000000	NaN	NaN
117.999749	0.000846	8.457631	0.040197	1011.093140	0.000000	NaN	NaN
118.998806	0.000837	8.374854	0.040649	1011.532593	0.000000	NaN	NaN
119.999864	0.000705	7.050420	0.041341	1012.205627	0.000000	NaN	NaN
120.998921	0.000887	8.871517	0.041861	1012.711060	0.000000	NaN	NaN
121.999978	0.000837	8.374854	0.042452	1013.284973	0.000000	NaN	NaN
122.999035	0.000846	8.457631	0.043013	1013.830566	0.000000	NaN	NaN
124.000092	0.000978	9.782066	0.043537	1014.339905	0.000000	NaN	NaN
124.998149	0.000755	7.547083	0.044011	1014.800781	0.000000	NaN	NaN
125.998207	0.000738	7.381529	0.044497	1015.272705	0.000000	NaN	NaN
126.998264	0.000895	8.954294	0.045152	1015.909851	0.000000	NaN	NaN
127.998321	0.000722	7.215974	0.045642	1016.386414	0.000000	NaN	NaN
128.998378	0.000730	7.298751	0.046237	1016.964355	0.000000	NaN	NaN
129.998435	0.000755	7.547083	0.046713	1017.426514	0.000000	NaN	NaN
130.999493	0.000895	8.954294	0.047282	1017.980530	0.000000	NaN	NaN
131.999550	0.000854	8.540409	0.047825	1018.507812	0.000000	NaN	NaN
132.999607	0.000854	8.540409	0.048406	1019.072632	0.000000	NaN	NaN
133.998664	0.000937	9.368180	0.048810	1019.465027	0.000000	NaN	NaN
134.998721	0.000995	9.947620	0.049532	1020.166687	0.000000	NaN	NaN
135.998779	0.000738	7.381529	0.870563	1818.226929	0.000000	NaN	NaN
136.998836	0.000763	7.629860	0.050384	1020.995361	0.000000	NaN	NaN
137.998893	0.000912	9.119849	0.051201	1021.789429	0.000000	NaN	NaN
138.998950	0.000920	9.202626	0.878413	1825.857300	0.000000	NaN	NaN
140.000008	0.000854	8.540409	0.887852	1835.032104	0.000000	NaN	NaN
141.000065	0.000606	6.057094	-1.000000	0.000000	0.000000	NaN	NaN
142.000122	0.000887	8.871517	0.057809	1028.212402	0.000000	NaN	NaN
142.999179	0.000862	8.623186	0.058422	1028.808105	0.000000	NaN	NaN
143.998236	0.000837	8.374854	0.058835	1029.209961	0.000000	NaN	NaN
144.999293	0.000763	7.629860	0.059545	1029.900391	0.000000	NaN	NaN
145.998351	0.000912	9.119849	0.059955	1030.298340	0.000000	NaN	NaN
146.999408	0.000722	7.215974	0.060521	1030.848999	0.000000	NaN	NaN
147.999465	0.000813	8.126523	0.061054	1031.367187	0.000000	NaN	NaN
148.999522	0.000813	8.126523	0.061658	1031.953613	0.000000	NaN	NaN
149.999580	0.000887	8.871517	0.062161	1032.442993	0.000000	NaN	NaN
150.999637	0.000962	9.616511	0.062748	1033.013184	0.000000	NaN	NaN
151.999694	0.000887	8.871517	0.063214	1033.466553	0.000000	NaN	NaN
152.999751	0.000763	7.629860	0.063770	1034.007080	0.000000	NaN	NaN
153.999808	0.000887	8.871517	0.064424	1034.642700	0.000000	NaN	NaN
154.998865	0.000953	9.533734	0.064950	1035.153564	0.000000	NaN	NaN
155.998923	0.000879	8.788740	0.065251	1035.446045	0.000000	NaN	NaN
156.998980	0.000788	7.878191	0.065909	1036.085815	0.000000	NaN	NaN
158.000037	0.000887	8.871517	0.066530	1036.689697	0.000000	NaN	NaN
159.000094	0.000871	8.705963	0.067084	1037.228516	0.000000	NaN	NaN
159.999151	0.000705	7.050420	0.067559	1037.689575	0.000000	NaN	NaN
160.999209	0.000846	8.457631	0.068130	1038.244873	0.000000	NaN	NaN
161.999266	0.000945	9.450957	0.068568	1038.670288	0.000000	NaN	NaN
162.999323	0.000722	7.215974	0.069310	1039.391357	0.000000	NaN	NaN
163.999380	0.000871	8.705963	0.069944	1040.007690	0.000000	NaN	NaN
164.998437	0.000804	8.043746	0.070549	1040.596069	0.000000	NaN	NaN
165.999495	0.000821	8.209300	0.071083	1041.114746	0.000000	NaN	NaN
166.998552	0.000796	7.960969	0.071586	1041.604614	0.000000	NaN	NaN
167.999609	0.000887	8.871517	0.072202	1042.203247	0.000000	NaN	NaN
168.998666	0.000871	8.705963	0.072679	1042.666382	0.000000	NaN	NaN
169.998723	0.000821	8.209300	0.073292	1043.262329	0.000000	NaN	NaN
170.998781	0.000722	7.215974	0.073936	1043.888306	0.000000	NaN	NaN
171.998838	0.000887	8.871517	0.074498	1044.434814	0.000000	NaN	NaN
172.999895	0.000929	9.285403	0.075011	1044.933105	0.000000	NaN	NaN
173.998952	0.000912	9.119849	0.075531	1045.439087	0.000000	NaN	NaN
175.000009	0.000871	8.705963	0.076097	1045.988892	0.000000	NaN	NaN
175.999066	0.000713	7.133197	0.076641	1046.517578	0.000000	NaN	NaN
176.999124	0.000895	8.954294	0.077335	1047.192505	0.000000	NaN	NaN
177.998181	0.000887	8.871517	0.077864	1047.706299	0.000000	NaN	NaN
178.999238	0.000780	7.795414	0.078404	1048.230957	0.000000	NaN	NaN
179.998295	0.000862	8.623186	0.078948	1048.760010	0.000000	NaN	NaN
180.999352	0.000895	8.954294	0.079427	1049.225708	0.000000	NaN	NaN
181.999410	0.000821	8.209300	0.079973	1049.755981	0.000000	NaN	NaN
182.999467	0.000920	9.202626	0.080575	1050.341553	0.000000	NaN	NaN
183.998524	0.000945	9.450957	0.081021	1050.775024	0.000000	NaN	NaN
184.998581	0.000837	8.374854	0.081706	1051.440552	0.000000	NaN	NaN
185.998638	0.000879	8.788740	0.082215	1051.936157	0.000000	NaN	NaN
186.999696	0.000837	8.374854	0.082770	1052.474976	0.000000	NaN	NaN
187.998753	0.000722	7.215974	0.083389	1053.077026	0.000000	NaN	NaN
188.999810	0.000821	8.209300	0.083851	1053.525391	0.000000	NaN	NaN
189.999867	0.000879	8.788740	0.084437	1054.095703	0.000000	NaN	NaN
190.999924	0.000821	8.209300	0.085050	1054.691162	0.000000	NaN	NaN
191.999982	0.000846	8.457631	0.085589	1055.215698	0.000000	NaN	NaN
193.000039	0.000821	8.209300	0.086234	1055.842407	0.000000	NaN	NaN
194.000096	0.000970	9.699289	0.086680	1056.275391	0.000000	NaN	NaN
194.998153	0.000837	8.374854	0.087093	1056.677612	0.000000	NaN	NaN
195.999211	0.000796	7.960969	0.087800	1057.364868	0.000000	NaN	NaN
196.998268	0.000887	8.871517	0.088414	1057.960815	0.000000	NaN	NaN
197.999325	0.000738	7.381529	0.088883	1058.417480	0.000000	NaN	NaN
198.998382	0.000904	9.037071	0.089481	1058.998291	0.000000	NaN	NaN
199.999439	0.000962	9.616511	0.089937	1059.441895	0.000000	NaN	NaN
200.999496	0.000821	8.209300	0.090485	1059.974609	0.000000	NaN	NaN
201.999554	0.000887	8.871517	0.091035	1060.508911	0.000000	NaN	NaN
202.998611	0.000614	6.139871	0.091496	1060.957397	0.000000	NaN	NaN
203.998668	0.000862	8.623186	0.092173	1061.615234	0.000000	NaN	NaN
204.998725	0.000837	8.374854	0.092766	1062.191650	0.000000	NaN	NaN
205.999783	0.000986	9.864843	0.093329	1062.739136	0.000000	NaN	NaN
206.998840	0.000821	8.209300	0.093956	1063.347900	0.000000	NaN	NaN
207.999897	0.000862	8.623186	0.094462	1063.839600	0.000000	NaN	NaN
208.999954	0.000788	7.878191	0.095035	1064.397461	0.000000	NaN	NaN
210.000011	0.000895	8.954294	0.095411	1064.762939	0.000000	NaN	NaN
210.999068	0.000854	8.540409	0.096027	1065.361206	0.000000	NaN	NaN
211.999126	0.001036	10.361506	0.096565	1065.884644	0.000000	NaN	NaN
212.999183	0.000862	8.623186	0.097033	1066.339233	0.000000	NaN	NaN
213.998240	0.000912	9.119849	0.097764	1067.049316	0.000000	NaN	NaN
214.999297	0.000912	9.119849	0.098281	1067.552002	0.000000	NaN	NaN
215.998354	0.000953	9.533734	0.098831	1068.087036	0.000000	NaN	NaN
216.999412	0.000780	7.795414	0.099283	1068.526245	0.000000	NaN	NaN
217.999469	0.000788	7.878191	0.099966	1069.190063	0.000000	NaN	NaN
218.999526	0.000887	8.871517	0.100457	1069.667114	0.000000	NaN	NaN
219.999583	0.000929	9.285403	0.101065	1070.258667	0.000000	NaN	NaN
220.999640	0.000862	8.623186	0.101655	1070.832031	0.000000	NaN	NaN
221.998698	0.000929	9.285403	0.102082	1071.246338	0.000000	NaN	NaN
222.999755	0.000837	8.374854	0.102707	1071.854370	0.000000	NaN	NaN
223.999812	0.000986	9.864843	0.103211	1072.343994	0.000000	NaN	NaN
224.999869	0.000846	8.457631	0.103726	1072.844971	0.000000	NaN	NaN
225.998926	0.000829	8.292077	0.104251	1073.355103	0.000000	NaN	NaN
226.999984	0.000846	8.457631	0.104888	1073.974609	0.000000	NaN	NaN
228.000041	0.000829	8.292077	0.105345	1074.419067	0.000000	NaN	NaN
229.000098	0.000763	7.629860	0.105881	1074.939331	0.000000	NaN	NaN
229.998155	0.000771	7.712637	0.106355	1075.400757	0.000000	NaN	NaN
230.999212	0.000829	8.292077	0.107008	1076.034668	0.000000	NaN	NaN
231.999270	0.000887	8.871517	0.107484	1076.497314	0.000000	NaN	NaN
232.999327	0.000796	7.960969	0.108209	1077.202271	0.000000	NaN	NaN
233.999384	0.000887	8.871517	0.108680	1077.660278	0.000000	NaN	NaN
234.999441	0.000780	7.795414	0.109118	1078.086182	0.000000	NaN	NaN
235.999498	0.000920	9.202626	0.109571	1078.526001	0.000000	NaN	NaN
236.999556	0.000829	8.292077	0.110376	1079.309082	0.000000	NaN	NaN
237.999613	0.000871	8.705963	0.110987	1079.902832	0.000000	NaN	NaN
238.998670	0.000871	8.705963	0.111608	1080.506226	0.000000	NaN	NaN
239.999727	0.000821	8.209300	0.112107	1080.990967	0.000000	NaN	NaN
240.999784	0.000895	8.954294	0.112548	1081.420288	0.000000	NaN	NaN
241.998841	0.000788	7.878191	0.113018	1081.877197	0.000000	NaN	NaN
242.998899	0.000962	9.616511	0.113583	1082.425659	0.000000	NaN	NaN
243.999956	0.000953	9.533734	0.114033	1082.863892	0.000000	NaN	NaN
244.999013	0.000970	9.699289	0.114711	1083.522827	0.000000	NaN	NaN
245.999070	0.000895	8.954294	0.115229	1084.025513	0.000000	NaN	NaN
246.999128	0.000912	9.119849	0.115837	1084.617432	0.000000	NaN	NaN
247.999185	0.000862	8.623186	0.116332	1085.098267	0.000000	NaN	NaN
248.998242	0.000829	8.292077	0.116761	1085.515015	0.000000	NaN	NaN
249.999299	0.000854	8.540409	0.117401	1086.137207	0.000000	NaN	NaN
250.999356	0.000912	9.119849	0.117978	1086.698486	0.000000	NaN	NaN
251.999414	0.001020	10.195951	0.118479	1087.185303	0.000000	NaN	NaN
252.998471	0.000763	7.629860	0.118986	1087.678345	0.000000	NaN	NaN
253.999528	0.000854	8.540409	0.119581	1088.255737	0.000000	NaN	NaN
254.999585	0.000945	9.450957	0.120123	1088.783203	0.000000	NaN	NaN
255.999642	0.000904	9.037071	0.120762	1089.404053	0.000000	NaN	NaN
256.999700	0.000937	9.368180	0.121154	1089.785278	0.000000	NaN	NaN
257.999757	0.000813	8.126523	0.121708	1090.324097	0.000000	NaN	NaN
258.999814	0.001078	10.775392	0.122402	1090.998413	0.000000	NaN	NaN
259.999871	0.000871	8.705963	0.122955	1091.536133	0.000000	NaN	NaN
260.999928	0.000829	8.292077	0.123566	1092.129395	0.000000	NaN	NaN
261.999985	0.000929	9.285403	0.124037	1092.587524	0.000000	NaN	NaN
262.999043	0.000887	8.871517	0.124518	1093.054687	0.000000	NaN	NaN
263.999100	0.000929	9.285403	0.124955	1093.479858	0.000000	NaN	NaN
264.999157	0.000904	9.037071	0.125679	1094.183838	0.000000	NaN	NaN
265.998214	0.000837	8.374854	0.126129	1094.621338	0.000000	NaN	NaN
266.999272	0.000920	9.202626	0.126765	1095.239258	0.000000	NaN	NaN
267.998329	0.000813	8.126523	0.127167	1095.630127	0.000000	NaN	NaN
268.999386	0.000904	9.037071	0.127822	1096.266602	0.000000	NaN	NaN
269.998443	0.000821	8.209300	0.128419	1096.847046	0.000000	NaN	NaN
270.998500	0.000796	7.960969	0.128823	1097.239258	0.000000	NaN	NaN
271.998557	0.000895	8.954294	0.129376	1097.777588	0.000000	NaN	NaN
272.998615	0.000846	8.457631	0.129902	1098.288940	0.000000	NaN	NaN
273.999672	0.000912	9.119849	0.130456	1098.827026	0.000000	NaN	NaN
274.998729	0.000871	8.705963	0.131019	1099.374146	0.000000	NaN	NaN
275.998786	0.000904	9.037071	0.131541	1099.881226	0.000000	NaN	NaN
276.999843	0.000895	8.954294	0.132011	1100.338623	0.000000	NaN	NaN
277.999901	0.000962	9.616511	0.132604	1100.915283	0.000000	NaN	NaN
278.998958	0.000929	9.285403	0.132858	1101.161987	0.000000	NaN	NaN
280.000015	0.001086	10.858169	0.133374	1101.663696	0.000000	NaN	NaN
280.999072	0.000904	9.037071	0.133839	1102.114990	0.000000	NaN	NaN
281.999129	0.000986	9.864843	0.134321	1102.583618	0.000000	NaN	NaN
282.998186	0.000995	9.947620	0.135012	1103.255737	0.000000	NaN	NaN
283.999244	0.000854	8.540409	0.135429	1103.660767	0.000000	NaN	NaN
284.999301	0.000904	9.037071	0.136043	1104.257202	0.000000	NaN	NaN
285.999358	0.001003	10.030397	0.136565	1104.765015	0.000000	NaN	NaN
286.998415	0.000953	9.533734	0.137005	1105.193115	0.000000	NaN	NaN
287.999473	0.000937	9.368180	0.137568	1105.740356	0.000000	NaN	NaN
288.999530	0.000846	8.457631	0.138215	1106.368652	0.000000	NaN	NaN
289.998587	0.000920	9.202626	0.138556	1106.699951	0.000000	NaN	NaN
290.999644	0.000730	7.298751	0.139197	1107.323730	0.000000	NaN	NaN
291.999701	0.001061	10.609837	0.139648	1107.762207	0.000000	NaN	NaN
292.998759	0.001028	10.278729	0.140259	1108.355469	0.000000	NaN	NaN
293.999816	0.000887	8.871517	0.140831	1108.911499	0.000000	NaN	NaN
294.998873	0.000796	7.960969	0.141227	1109.296753	0.000000	NaN	NaN
295.999930	0.000854	8.540409	0.141769	1109.823730	0.000000	NaN	NaN
296.999987	0.000895	8.954294	0.142419	1110.455444	0.000000	NaN	NaN
297.999045	0.000829	8.292077	0.142945	1110.966187	0.000000	NaN	NaN
299.000102	0.000887	8.871517	0.143478	1111.484863	0.000000	NaN	NaN
299.999159	0.000920	9.202626	0.143946	1111.939209	0.000000	NaN	NaN
300.999216	0.000837	8.374854	0.144338	1112.320190	0.000000	NaN	NaN
301.999273	0.000804	8.043746	0.145029	1112.992310	0.000000	NaN	NaN
302.999330	0.000829	8.292077	0.145599	1113.546509	0.000000	NaN	NaN
303.999388	0.000920	9.202626	0.146039	1113.973999	0.000000	NaN	NaN
304.999445	0.001044	10.444283	0.146548	1114.469116	0.000000	NaN	NaN
305.998502	0.000904	9.037071	0.147113	1115.018066	0.000000	NaN	NaN
306.999559	0.001086	10.858169	0.147572	1115.464111	0.000000	NaN	NaN
307.998617	0.000846	8.457631	0.148178	1116.052612	0.000000	NaN	NaN
308.999674	0.000986	9.864843	0.148791	1116.648682	0.000000	NaN	NaN
309.998731	0.001003	10.030397	0.149237	1117.082031	0.000000	NaN	NaN
310.998788	0.000953	9.533734	0.149794	1117.623535	0.000000	NaN	NaN
311.998845	0.000937	9.368180	0.150415	1118.227173	0.000000	NaN	NaN
312.998902	0.000904	9.037071	0.150975	1118.772217	0.000000	NaN	NaN
313.998960	0.000945	9.450957	0.151475	1119.258057	0.000000	NaN	NaN
314.999017	0.000887	8.871517	0.151877	1119.649048	0.000000	NaN	NaN
316.000074	0.001011	10.113174	0.152467	1120.222534	0.000000	NaN	NaN
316.999131	0.000879	8.788740	0.152869	1120.613159	0.000000	NaN	NaN
317.998188	0.001011	10.113174	0.153646	1121.368042	0.000000	NaN	NaN
318.999246	0.000904	9.037071	0.154013	1121.724609	0.000000	NaN	NaN
319.999303	0.000780	7.795414	0.154611	1122.306641	0.000000	NaN	NaN
320.998360	0.000929	9.285403	0.155288	1122.964233	0.000000	NaN	NaN
321.999417	0.000953	9.533734	0.155772	1123.434570	0.000000	NaN	NaN
322.999475	0.000978	9.782066	0.156235	1123.885010	0.000000	NaN	NaN
323.999532	0.000846	8.457631	0.156747	1124.381836	0.000000	NaN	NaN
324.998589	0.000813	8.126523	0.157440	1125.056152	0.000000	NaN	NaN
325.999646	0.001053	10.527060	0.157868	1125.471802	0.000000	NaN	NaN
326.999703	0.000821	8.209300	0.158453	1126.041138	0.000000	NaN	NaN
327.999760	0.001028	10.278729	0.158984	1126.556519	0.000000	NaN	NaN
328.998818	0.000813	8.126523	0.159430	1126.990601	0.000000	NaN	NaN
329.999875	0.000937	9.368180	0.160184	1127.723022	0.000000	NaN	NaN
330.999932	0.000796	7.960969	0.160785	1128.307495	0.000000	NaN	NaN
331.999989	0.000937	9.368180	0.161140	1128.652832	0.000000	NaN	NaN
332.999046	0.000813	8.126523	0.161631	1129.129395	0.000000	NaN	NaN
334.000104	0.000862	8.623186	0.162019	1129.507324	0.000000	NaN	NaN
334.999161	0.000871	8.705963	0.162617	1130.088135	0.000000	NaN	NaN
335.999218	0.000796	7.960969	0.163064	1130.522583	0.000000	NaN	NaN
336.998275	0.000895	8.954294	0.163761	1131.200439	0.000000	NaN	NaN
337.999332	0.000846	8.457631	0.164303	1131.726807	0.000000	NaN	NaN
338.999390	0.000813	8.126523	0.164803	1132.213257	0.000000	NaN	NaN
339.999447	0.000904	9.037071	0.165526	1132.915405	0.000000	NaN	NaN
340.999504	0.000871	8.705963	0.165871	1133.250854	0.000000	NaN	NaN
341.999561	0.000978	9.782066	0.166458	1133.821533	0.000000	NaN	NaN
342.999618	0.000871	8.705963	0.166941	1134.291382	0.000000	NaN	NaN
343.998676	0.000953	9.533734	0.167661	1134.991211	0.000000	NaN	NaN
344.999733	0.000879	8.788740	0.168187	1135.502563	0.000000	NaN	NaN
345.998790	0.000920	9.202626	0.168595	1135.898682	0.000000	NaN	NaN
346.999847	0.001061	10.609837	0.169104	1136.393188	0.000000	NaN	NaN
347.998904	0.001028	10.278729	0.169646	1136.920532	0.000000	NaN	NaN
348.998962	0.000929	9.285403	0.170278	1137.534912	0.000000	NaN	NaN
349.999019	0.000879	8.788740	0.170851	1138.091675	0.000000	NaN	NaN
351.000076	0.001011	10.113174	0.171432	1138.656372	0.000000	NaN	NaN
351.998133	0.000978	9.782066	0.171984	1139.192871	0.000000	NaN	NaN
352.999190	0.000912	9.119849	0.172473	1139.668823	0.000000	NaN	NaN
353.999248	0.000978	9.782066	0.172970	1140.151611	0.000000	NaN	NaN
354.999305	0.000904	9.037071	0.173657	1140.818848	0.000000	NaN	NaN
355.998362	0.001003	10.030397	0.174127	1141.275879	0.000000	NaN	NaN
356.999419	0.000937	9.368180	0.174653	1141.787476	0.000000	NaN	NaN
357.999476	0.000862	8.623186	0.175337	1142.452148	0.000000	NaN	NaN
358.999534	0.000846	8.457631	0.175810	1142.911865	0.000000	NaN	NaN
359.999591	0.000837	8.374854	0.176447	1143.531128	0.000000	NaN	NaN
360.999648	0.000895	8.954294	0.176943	1144.012939	0.000000	NaN	NaN
361.999705	0.000953	9.533734	0.177539	1144.592163	0.000000	NaN	NaN
362.998762	0.000837	8.374854	0.177943	1144.985229	0.000000	NaN	NaN
363.999820	0.000953	9.533734	0.178681	1145.703125	0.000000	NaN	NaN
364.999877	0.001028	10.278729	0.179063	1146.074341	0.000000	NaN	NaN
365.999934	0.000854	8.540409	0.179663	1146.656860	0.000000	NaN	NaN
366.998991	0.000978	9.782066	0.180169	1147.149536	0.000000	NaN	NaN
368.000048	0.000945	9.450957	0.180702	1147.666870	0.000000	NaN	NaN
368.999105	0.000904	9.037071	0.181160	1148.112061	0.000000	NaN	NaN
369.999163	0.000862	8.623186	0.181713	1148.649536	0.000000	NaN	NaN
370.998220	0.000887	8.871517	0.182351	1149.270142	0.000000	NaN	NaN
371.999277	0.000829	8.292077	0.182986	1149.887207	0.000000	NaN	NaN
372.998334	0.000804	8.043746	0.183416	1150.305664	0.000000	NaN	NaN
373.999392	0.000904	9.037071	0.183879	1150.755127	0.000000	NaN	NaN
374.999449	0.000970	9.699289	0.184370	1151.232910	0.000000	NaN	NaN
375.999506	0.000862	8.623186	0.184979	1151.824707	0.000000	NaN	NaN
376.999563	0.000937	9.368180	0.185524	1152.354126	0.000000	NaN	NaN
377.999620	0.000945	9.450957	0.186119	1152.932983	0.000000	NaN	NaN
378.999678	0.000953	9.533734	0.186622	1153.421265	0.000000	NaN	NaN
379.999735	0.000953	9.533734	0.187153	1153.937256	0.000000	NaN	NaN
380.999792	0.000846	8.457631	0.187542	1154.315674	0.000000	NaN	NaN
381.999849	0.000970	9.699289	0.188142	1154.899170	0.000000	NaN	NaN
382.998906	0.000862	8.623186	0.188697	1155.438232	0.000000	NaN	NaN
383.998964	0.001061	10.609837	0.189274	1155.998901	0.000000	NaN	NaN
384.999021	0.000771	7.712637	0.189645	1156.360229	0.000000	NaN	NaN
386.000078	0.000871	8.705963	0.190478	1157.169678	0.000000	NaN	NaN
386.999135	0.000970	9.699289	0.190893	1157.573120	0.000000	NaN	NaN
387.999192	0.000945	9.450957	0.191317	1157.985596	0.000000	NaN	NaN
388.999250	0.000953	9.533734	0.191872	1158.524292	0.000000	NaN	NaN
389.998307	0.000920	9.202626	0.192397	1159.034912	0.000000	NaN	NaN
390.999364	0.000953	9.533734	0.192801	1159.427246	0.000000	NaN	NaN
391.999421	0.000854	8.540409	0.193202	1159.817871	0.000000	NaN	NaN
392.999478	0.000862	8.623186	0.193603	1160.207520	0.000000	NaN	NaN
393.999535	0.000780	7.795414	0.194227	1160.813721	0.000000	NaN	NaN
394.999593	0.000937	9.368180	0.194630	1161.205200	0.000000	NaN	NaN
395.999650	0.001011	10.113174	0.195152	1161.712769	0.000000	NaN	NaN
396.999707	0.000829	8.292077	0.195640	1162.186768	0.000000	NaN	NaN
397.999764	0.000771	7.712637	0.196054	1162.589844	0.000000	NaN	NaN
398.999821	0.000755	7.547083	0.196656	1163.174805	0.000000	NaN	NaN
399.999879	0.000929	9.285403	0.197274	1163.775391	0.000000	NaN	NaN
400.999936	0.000879	8.788740	0.197784	1164.270874	0.000000	NaN	NaN
401.999993	0.000879	8.788740	0.198211	1164.686157	0.000000	NaN	NaN
403.000050	0.000854	8.540409	0.198678	1165.140503	0.000000	NaN	NaN
404.000108	0.000929	9.285403	0.199249	1165.694946	0.000000	NaN	NaN
404.999165	0.000730	7.298751	0.199747	1166.179687	0.000000	NaN	NaN
405.999222	0.000713	7.133197	0.200161	1166.581787	0.000000	NaN	NaN
406.999279	0.000722	7.215974	0.200721	1167.126221	0.000000	NaN	NaN
407.999336	0.000846	8.457631	0.201293	1167.681641	0.000000	NaN	NaN
408.999393	0.000854	8.540409	0.201951	1168.321289	0.000000	NaN	NaN
409.999451	0.000837	8.374854	0.202458	1168.813965	0.000000	NaN	NaN
410.999508	0.000788	7.878191	0.203007	1169.347534	0.000000	NaN	NaN
411.999565	0.000829	8.292077	0.203430	1169.759277	0.000000	NaN	NaN
412.998622	0.000945	9.450957	0.203979	1170.293335	0.000000	NaN	NaN
413.999679	0.000713	7.133197	0.204573	1170.870117	0.000000	NaN	NaN
414.998737	0.000796	7.960969	0.204995	1171.280273	0.000000	NaN	NaN
415.999794	0.000730	7.298751	0.205596	1171.865112	0.000000	NaN	NaN
416.999851	0.000713	7.133197	0.206135	1172.388916	0.000000	NaN	NaN
417.999908	0.000904	9.037071	0.206721	1172.958130	0.000000	NaN	NaN
418.999965	0.000804	8.043746	0.207141	1173.366333	0.000000	NaN	NaN
419.999023	0.000655	6.553757	0.207765	1173.972778	0.000000	NaN	NaN
420.999080	0.000871	8.705963	0.208425	1174.614258	0.000000	NaN	NaN
421.999137	0.000887	8.871517	0.208842	1175.020020	0.000000	NaN	NaN
422.999194	0.000664	6.636534	0.209399	1175.560913	0.000000	NaN	NaN
423.999251	0.000837	8.374854	0.209923	1176.070801	0.000000	NaN	NaN
424.999308	0.000780	7.795414	0.210445	1176.578369	0.000000	NaN	NaN
425.999366	0.000804	8.043746	0.211103	1177.217407	0.000000	NaN	NaN
426.999423	0.000780	7.795414	0.211587	1177.688232	0.000000	NaN	NaN
427.999480	0.000804	8.043746	0.212210	1178.293579	0.000000	NaN	NaN
428.999537	0.000655	6.553757	0.212868	1178.933105	0.000000	NaN	NaN
429.999595	0.000639	6.388203	0.213448	1179.496582	0.000000	NaN	NaN
430.999652	0.000788	7.878191	0.214035	1180.067871	0.000000	NaN	NaN
431.999709	0.000755	7.547083	0.214605	1180.621216	0.000000	NaN	NaN
432.999766	0.000614	6.139871	0.215090	1181.092896	0.000000	NaN	NaN
433.999823	0.000705	7.050420	0.215752	1181.736450	0.000000	NaN	NaN
434.999881	0.000755	7.547083	0.216315	1182.283813	0.000000	NaN	NaN
435.999938	0.000722	7.215974	0.216854	1182.807373	0.000000	NaN	NaN
436.999995	0.000639	6.388203	0.217605	1183.537354	0.000000	NaN	NaN
438.000052	0.000746	7.464306	0.218364	1184.275024	0.000000	NaN	NaN
439.000109	0.000647	6.470980	0.218747	1184.648071	0.000000	NaN	NaN
439.999167	0.000688	6.884866	0.219496	1185.375854	0.000000	NaN	NaN
440.999224	0.000821	8.209300	0.220156	1186.017334	0.000000	NaN	NaN
441.999281	0.000655	6.553757	0.220674	1186.520630	0.000000	NaN	NaN
442.999338	0.000688	6.884866	0.221467	1187.291992	0.000000	NaN	NaN
443.999395	0.000871	8.705963	0.221859	1187.672852	0.000000	NaN	NaN
444.999453	0.000763	7.629860	0.222520	1188.315552	0.000000	NaN	NaN
445.999510	0.000688	6.884866	0.223388	1189.159180	0.000000	NaN	NaN
446.999567	0.000697	6.967643	0.224011	1189.764526	0.000000	NaN	NaN
447.999624	0.000664	6.636534	0.224737	1190.470337	0.000000	NaN	NaN
448.999681	0.000680	6.802089	0.225429	1191.142334	0.000000	NaN	NaN
449.999738	0.000672	6.719311	0.226076	1191.771240	0.000000	NaN	NaN
450.999796	0.000672	6.719311	0.226821	1192.495972	0.000000	NaN	NaN
451.999853	0.000556	5.560431	0.227462	1193.119263	0.000000	NaN	NaN
452.998910	0.000631	6.305426	0.228147	1193.784790	0.000000	NaN	NaN
453.999967	0.000639	6.388203	0.228913	1194.528809	0.000000	NaN	NaN
455.000024	0.000606	6.057094	0.229584	1195.181519	0.000000	NaN	NaN
456.000082	0.000688	6.884866	0.230364	1195.939941	0.000000	NaN	NaN
456.998139	0.000705	7.050420	0.231187	1196.739502	0.000000	NaN	NaN
457.999196	0.000548	5.477654	0.232046	1197.574463	0.000000	NaN	NaN
458.998253	0.000515	5.146546	0.232824	1198.331177	0.000000	NaN	NaN
459.999310	0.000606	6.057094	0.233635	1199.118774	0.000000	NaN	NaN
460.998368	0.000432	4.318774	0.234463	1199.924072	0.000000	NaN	NaN
461.999425	0.000655	6.553757	0.235173	1200.614502	0.000000	NaN	NaN
462.999482	0.000606	6.057094	0.235999	1201.416870	0.000000	NaN	NaN
463.999539	0.000655	6.553757	0.236803	1202.198608	0.000000	NaN	NaN
464.999596	0.000424	4.235997	0.237926	1203.290161	0.000000	NaN	NaN
465.999654	0.000589	5.891540	0.238632	1203.976440	0.000000	NaN	NaN
466.999711	0.000548	5.477654	0.239330	1204.655151	0.000000	NaN	NaN
467.999768	0.000548	5.477654	0.240235	1205.534790	0.000000	NaN	NaN
468.999825	0.000664	6.636534	0.241259	1206.529785	0.000000	NaN	NaN
469.999882	0.000581	5.808763	0.242104	1207.351318	0.000000	NaN	NaN
470.999940	0.000448	4.484329	0.242872	1208.098022	0.000000	NaN	NaN
471.999997	0.000680	6.802089	0.243905	1209.101685	0.000000	NaN	NaN
473.000054	0.000440	4.401551	0.244749	1209.921875	0.000000	NaN	NaN
473.999111	0.000506	5.063769	0.245764	1210.909058	0.000000	NaN	NaN
474.999168	0.000639	6.388203	0.246655	1211.775146	0.000000	NaN	NaN
475.999226	0.000515	5.146546	0.247632	1212.724609	0.000000	NaN	NaN
476.999283	0.000448	4.484329	0.248459	1213.528320	0.000000	NaN	NaN
477.999340	0.000415	4.153220	0.249682	1214.716797	0.000000	NaN	NaN
478.999397	0.000548	5.477654	0.250605	1215.614502	0.000000	NaN	NaN
479.998454	0.000465	4.649883	0.251640	1216.620605	0.000000	NaN	NaN
480.999512	0.000424	4.235997	0.252539	1217.494629	0.000000	NaN	NaN
481.999569	0.000333	3.325449	0.253552	1218.479126	0.000000	NaN	NaN
482.999626	0.000440	4.401551	0.254589	1219.486572	0.000000	NaN	NaN
483.999683	0.000200	2.001014	0.255446	1220.319824	0.000000	NaN	NaN
484.999740	0.000399	3.987666	0.256671	1221.510620	0.000000	NaN	NaN
485.999798	0.000341	3.408226	0.257900	1222.705566	0.000000	NaN	NaN
486.999855	0.000424	4.235997	0.259079	1223.851440	0.000000	NaN	NaN
487.999912	0.000316	3.159894	0.260359	1225.094971	0.000000	NaN	NaN
488.998969	0.000299	2.994340	0.261937	1226.629028	0.000000	NaN	NaN
490.000026	0.000316	3.159894	0.263357	1228.009521	0.000000	NaN	NaN
490.999083	0.000266	2.663231	0.264851	1229.462036	0.000000	NaN	NaN
491.999141	0.000225	2.249346	0.266559	1231.122437	0.000000	NaN	NaN
492.998198	0.000266	2.663231	0.268052	1232.572632	0.000000	NaN	NaN
493.999255	0.000241	2.414900	0.269521	1234.001465	0.000000	NaN	NaN
494.999312	0.000101	1.007688	0.270974	1235.413208	0.000000	NaN	NaN
495.999369	0.000266	2.663231	0.272633	1237.025757	0.000000	NaN	NaN
496.998427	0.000241	2.414900	0.274228	1238.576172	0.000000	NaN	NaN
497.999484	0.000117	1.173243	0.275836	1240.139038	0.000000	NaN	NaN
498.998541	0.000117	1.173243	0.277607	1241.861206	0.000000	NaN	NaN
499.999598	0.000159	1.587128	0.279254	1243.461548	0.000000	NaN	NaN
500.999656	5.938027E-5	0.593803	0.280833	1244.996094	0.000000	NaN	NaN
501.999713	0.000175	1.752683	0.283175	1247.272583	0.000000	NaN	NaN
502.999770	-8.134088E-5	-0.813409	0.289037	1252.971191	0.000000	NaN	NaN
503.999827	-0.000106	-1.061740	0.301869	1265.444092	0.000000	NaN	NaN
504.999884	-8.134088E-5	-0.813409	0.307217	1270.641968	0.000000	NaN	NaN
505.998942	-0.000263	-2.634506	0.310833	1274.157471	0.000000	NaN	NaN
506.999999	-0.000189	-1.889512	0.313344	1276.598389	0.000000	NaN	NaN
508.000056	-8.134088E-5	-0.813409	0.315644	1278.833984	0.000000	NaN	NaN
508.999113	-0.000114	-1.144517	0.317755	1280.885986	0.000000	NaN	NaN